Workbook

Sheet Ensamble
C1: SERVICIOS DE PASTELERIA S.A. | H1: CÓDIGO:
C2: ESPECIFICACION DE RECETA | H2: REVISIÓN:
C3: Torta Choys | H3: FECHA DE APROBACIÓN:
C4: Elaborado | D4: Mariela Barrantes Sánchez, Chef
C5: Aprobado | D5: Sebastian Díaz, Gte Manufactura
A6: AREA QUE PRODUCE: | D6: Decoración | G6: AREA QUE EMPACA: | I6: Decoración
A7: # Código | B7: # Código Netsuite | C7: Descripción del ingrediente | D7: Marca | E7: Unidad Internacional | G7: Medida alternativa | I7: Costo - Referencia
E8: Cantidad | F8: Unidad medida | G8: Cantidad | H8: Unidad medida | I8: Colones
C9: Ensamble
A10: 907000287 | B10: SE00454 | C10: ROSQUETE EASY VAINILLA BC 310 G | D10: FAS | E10: 430 | F10: g | H10: 1,5 de rosquete
B11: SE00254 | C11: Leches Pasteurizada Con Agua | D11: FAS | E11: 90 | F11: g | G11: 30g x capa
B12: NUEVO | C12: Crema Dulce de Caramelo | D12: FAS | E12: 300 | F12: g | G12: 150x capa | H12: 1 taza y 1/2 taza
A13: 11700002 | B13: MP10176 | C13: Dulce Leche La Ciabata | D13: LA CIABATA | E13: 140 | F13: g | G13: 70g x capa | H13: 1/2 taza
B14: NUEVO | C14: Procesado Chocolate con mani y arroz inflado | E14: 60 | F14: g | G14: 30g x capa | H14: 1/4 taza
C17: Decoración
B18: SE00032 | C18: Crema Dulce Leche | D18: FAS | E18: 150 | F18: g | H18: ENCREMAR
B19: SE00032 | C19: Crema Dulce Leche | D19: FAS | E19: 55 | F19: g | G19: COLOCHO Boquilla 7FT
B20: NUEVO | C20: Mezcla mani y arroz inflado | D20: FAS | E20: 15 | F20: g | H20: BORDES
B21: SE00051 | C21: Ganache Chocolate Blanco | D21: FAS | E21: 12 | F21: g | H21: HILOS
B22: SE00001 | C22: Ganache Chocolate Oscuro | D22: FAS | E22: 12 | F22: g | H22: HILOS
B23: SE00298 | C23: Ganache De Dulce Leche | D23: FAS | E23: 12 | F23: g | H23: HILOS
B24: NUEVO | C24: Pelado Chocolate Choclate Choys | D24: FAS | E24: 26 | F24: g | G24: 13g cada chocolate | H24: 2 unidades
C27: EMPAQUE
A28: 121603 | B28: EM10009 | C28: Quequera Red Base/Domo 10 | D28: Export pmt | E28: 1 | F28: ud
A29: 1952875 | B29: EM10084 | C29: Orla # 10 Bucca | E29: 1 | F29: UD
A30: 2172411 | B30: EM10112 | C30: ET. TORTA BUCCA GENERICA | D30: Litografia CR | E30: 1 | F30: ud
A31: 0702007 | B31: EM10004 | C31: ETIQ.FECHA VENCIMIENTO | D31: Etiplast | E31: 1 | F31: ud
A32: 0702069 | B32: EM10002 | C32: ETIQ.BLANCA 1 1/4 * 3/4 | D32: Cemusa | E32: 1 | F32: ud
A33: 0702123 | B33: EM10011 | C33: ETIQUETA BLANCA 2 5/8X1 15/16 PRE BLANCA | D33: Etiplast | E33: 1 | F33: ud
A34: Nuevo | B34: Nueva | C34: ETIQUETA ESPECIAL | E34: 1 | F34: ud
D41: Cantidad | E41: Unidad
A42: PESO TOTAL OBTENIDO | D42: 1220 | E42: g | F42: Tiempo de Horneo: | J42: =5000/349 -> 14.326648
A43: TIEMPO TOTAL DE PREPARACION | D43: 5 | E43: min | F43: Horno:
A44: CANTIDAD DE PORCIONES OBTENIDAS | D44: 1 | E44: ud | F44: Temperatura de Horneo:
A45: PESO DE CADA PORCIÓN | D45: 1220 | E45: g | F45: Otros
A46: MERMA | D46: =SUM(E10:E24)-D42 -> 82 | E46: g
A47: PROCEDIMIENTO DE PREPARACION DE LA RECETA
A48: 1, Cortas los rosquete utilizando 1,5 de rosquete y humedecerlos con las leches con agua.
A49: 2, Coloca medio rosquete, agregar el dulce de leche, la crema dulce de caramelo, el chocolate con mani y arroz inflado, colocar otra mitad de rosquete, agrega dulce de leche, crema de dulce de leche, el chooclate con mani y arroz inflado y tapar con la ultima mitad de rosquete.
A50: 3, Encrema con la crema dulce y colocarle en la parte inferior de la torta la mezcla de mani y arroz inflado.
...

Sheet Rosquete Easy Vainilla 
C1: SERVICIOS DE PASTELERIA S.A. | H1: CÓDIGO: | I1: ESP-RE-BAF-013
C2: ESPECIFICACION DE RECETA | H2: REVISIÓN: | I2: 01
C3: 907000287(SE00454) Rosquete easy vainilla BC 310g | H3: FECHA DE APROBACIÓN: | I3: 45618
C4: Elaborado | D4: Javier Tong, Chef
C5: Aprobado | D5: Esteban Cartin, Gte Manufactura
A6: AREA QUE PRODUCE: | D6: Batidos | G6: AREA QUE EMPACA: | I6: Batidos
A7: # Código | B7: # Código Netsuite | C7: Descripción del ingrediente | D7: Marca | E7: Unidad Internacional | G7: Medida alternativa | I7: Costo - Referencia
E8: Cantidad | F8: Unidad medida | G8: Cantidad | H8: Unidad medida | I8: Colones
C9: Ensamble
A10: 907000286 | B10: SE00437 | C10: BATIDO EASY VAINILLA BC | D10: FAS | E10: 46000 | F10: g | K10: =+E10/D41 -> 313.40659 | L10: =+K10/1000 -> 0.31340659
A11: 902000019 | C11: MEZCLA P/ENGRASE MOLDES KILO | D11: FAS | E11: 2600 | F11: g | K11: =+E11/D41 -> 17.714286
K19: =SUM(E10:E11) -> 48600
C21: Decoración
C28: Empaque
A29: 702007 | B29: EM10004 | C29: ETIQ.FECHA VENCIMIENTO BLANCO (ROLLO) | D29: ETIPLAST | E29: 11.821429 | F29: ud
A30: 702123 | B30: EM10011 | C30: ETIQUETA BLANCA 2 5/8X1 15/16 (UND) | D30: FAS | E30: 10 | F30: ud
B31: EM10259 | C31: Plastico Autoaderible 1/ 18*2000 | E31: 17 | F31: metros
D38: Cantidad | E38: Unidad
A39: PESO TOTAL OBTENIDO | D39: 45500 | E39: g | F39: Tiempo de Horneo:
A40: TIEMPO TOTAL DE PREPARACION | D40: 50 | E40: min | F40: Horno:
A41: CANTIDAD DE PORCIONES OBTENIDAS | D41: =D39/D42 -> 146.77419 | E41: ud | F41: Temperatura de Horneo:
A42: PESO DE CADA PORCIÓN | D42: 310 | E42: g | F42: Otros
A43: MERMA | D43: =SUM(E10:E11)-D39 -> 3100 | E43: g
A44: PROCEDIMIENTO DE PREPARACION DE LA RECETA
A45: 1.- Dosificar en moldes engrasados 350g de mezcla.
A46: 2.- Hornear por 30 minutos en el Dicte 1 a 175°C, en el Dicte 2 por 20 minutos a 175°C, en el Argental por 20 minutos a 175°C, en el Marshall por 18 minutos a 175°C, en el vulcan a 325°F por 25 minutos y en el Curitiba a 130°C por 28.
A47: 3.- Enfriar, desmoldar, colocar las bandejas en el coche y rapearlo con el plastico, dejando solamente la bandeja superior en bolsa plastica.
A48: 4, Etiquetar
A55: CONTROL DE CAMBIOS
A56: 2, Se actualizan pesos, datos receta y procedimiento.

Sheet Batido
C1: SERVICIOS DE PASTELERIA S.A. | H1: CÓDIGO: | I1: ESP-RE-BAF-031
C2: ESPECIFICACION DE RECETA | H2: REVISIÓN: | I2: 02
C3: SE00437 Batido Easy Vainilla BC | H3: FECHA DE APROBACIÓN: | I3: 45980
C4: Elaborado | D4: Javier Tong, Chef
C5: Aprobado | D5: Esteban Cartin, Gte Manufactura
A6: AREA QUE PRODUCE: | D6: Batidos | G6: AREA QUE EMPACA: | I6: Batidos
A7: # Código | B7: # Código Netsuite | C7: Descripción del ingrediente | D7: Marca | E7: Unidad Internacional | G7: Medida alternativa | I7: Costo - Referencia
E8: Cantidad | F8: Unidad medida | G8: Cantidad | H8: Unidad medida | I8: Colones
C9: Ensamble
A10: 906000136 | B10: SE00436 | C10: PREMEZCLA EASY VAINILLA BC | D10: FAS | E10: 26860 | F10: g | J10: =+E10/$D$20 -> 0.57763441
A11: 1210482 | B11: MP10005 | C11: HUEVO LIQUIDO ESPECIAL INNOV (CAJA:10 K) | D11: INNOVO | E11: 4700 | F11: g | J11: =+E11/$D$20 -> 0.10107527 | K11: =+J11*1000 -> 101.07527
A12: 10415 | C12: AGUA POTABLE (PLANTA) | D12: FAS | E12: 13395 | F12: g | J12: =+E12/$D$20 -> 0.28806452 | K12: =+J12*1000 -> 288.06452
A13: 10100050 | B13: MP10002 | C13: ACEITE CAPULLO RBD (UND:17 L) | D13: CAPULLO | E13: 1400 | F13: g | J13: =+E13/$D$20 -> 0.030107527 | K13: =+J13*1000 -> 30.107527
A14: 1212437 | B14: MP10315 | C14: PRESERVANTE MIXTO | D14: PURATOS | E14: 370 | F14: g | J14: =+E14/$D$20 -> 0.0079569892 | K14: =+J14*1000 -> 7.9569892
D19: Cantidad | E19: Unidad
A20: PESO TOTAL OBTENIDO | D20: 46500 | E20: g | F20: Tiempo de Horneo:
A21: TIEMPO TOTAL DE PREPARACION | D21: 11 | E21: min | F21: Horno:
A22: CANTIDAD DE PORCIONES OBTENIDAS | D22: 1 | E22: ud | F22: Temperatura de Horneo:
A23: PESO DE CADA PORCIÓN | D23: 46500 | E23: g | F23: Otros
A24: MERMA | D24: 230 | E24: g
A25: PROCEDIMIENTO DE PREPARACION DE LA RECETA
A26: 1.- Agregar todos los liquidos a la batidora, luego todos los polvos. Batir 1 min en velocidada 1. Usar paleta.
A27: 2.- Subir a velocidad 2 y batir por 4 min.
A28: 3.- Dosificar.
A31: CONTROL DE CAMBIOS
A32: Revision #2: Cambio en el peso del huevo y el agua.

Sheet Premezcla 
C1: SERVICIOS DE PASTELERIA S.A. | H1: CÓDIGO: | I1: ESP-RE-PRES-023
C2: ESPECIFICACION DE RECETA | H2: REVISIÓN: | I2: 03
C3: SE00436 Premezcla Easy vainilla BC (provisional) | H3: FECHA DE APROBACIÓN: | I3: 45617
C4: Elaborado | D4: Juan Pablo Brenes, Chef
C5: Aprobado | D5: Esteban Cartin, Gte Manufactura
A6: AREA QUE PRODUCE: | D6: Premezclas | G6: AREA QUE EMPACA: | I6: Premezclas
A7: # Código | B7: # Código Netsuite | C7: Descripción del ingrediente | D7: Marca | E7: Unidad Internacional | G7: Medida alternativa | I7: Costo - Referencia
E8: Cantidad | F8: Unidad medida | G8: Cantidad | H8: Unidad medida | I8: Colones
C9: Ensamble
A10: 11200080 | B10: MP10491 | C10: EASY VAINILLA BC | D10: PURATOS | E10: 4600 | F10: g | J10: =+E10/$D$35 -> 0.17125838 | K10: =+J10*1000 -> 171.25838
A11: 510301 | B11: MP10074 | C11: AZUCAR BLANCO INDUSTRIAL (SACO:50 K) | D11: LAYCA | E11: 11000 | F11: g | J11: =+E11/$D$35 -> 0.4095309 | K11: =+J11*1000 -> 409.5309
A12: 11200072 | B12: MP10478 | C12: HARINA SILVER CAKE (SACO: 25K) | D12: FHACASA | E12: 7500 | F12: g | J12: =+E12/$D$35 -> 0.27922561 | K12: =+J12*1000 -> 279.22561
A13: 0510107 | B13: MP10036 | C13: HARINA HARISOL WINTER | D13: FHACASA | E13: 1900 | F13: g | J13: =+E13/$D$35 -> 0.070737156 | K13: =+J13*1000 -> 70.737156
B14: MP10566 | C14: PROPIONATO DE CALCIO | D14: IQS | E14: 117 | F14: g | J14: =+E14/$D$35 -> 0.0043559196 | K14: =+J14*1000 -> 4.3559196
A15: 10100046 | B15: MP10304 | C15: POLVO HORNEAR FLEISHMAN (PAQ:2.5 K) | D15: FLEISHMAN | E15: 150 | F15: g | J15: =+E15/$D$35 -> 0.0055845123 | K15: =+J15*1000 -> 5.5845123
A16: 1210445 | B16: MP10142 | C16: CLARA DE HUEVO DESHIDRATADA | E16: 450 | F16: g | J16: =+E16/$D$35 -> 0.016753537 | K16: =+J16*1000 -> 16.753537
A17: 11300012 | B17: MP10517 | C17: ACTI EGG | D17: PURATOS | E17: 360 | F17: g | J17: =+E17/$D$35 -> 0.013402829 | K17: =+J17*1000 -> 13.402829
B18: MP10481 | C18: Goma Xantana | E18: 60 | F18: g | J18: =+E18/$D$35 -> 0.0022338049 | K18: =+J18*1000 -> 2.2338049
B19: MP10769 | C19: HUEVO EN POLVO | D19: EPKMARKET | E19: 705 | F19: g | J19: =+E19/$D$35 -> 0.026247208 | K19: =+J19*1000 -> 26.247208
C21: Empaque
A22: 1950708 | B22: EM10013 | C22: BOLSA 17x25 TRANSP KILO | E22: 1 | F22: ud
A23: 503000042 | B23: EM10258 | C23: BOLSA TRANSP 20x30x2000 | E23: 1 | F23: ud
A24: 0702123 | B24: EM10011 | C24: ETIQUETA BLANCA 2 5/8X1 15/16 (UND) | E24: 2 | F24: ud
A25: 1950705 | B25: EM10037 | C25: BOLSA 8x12 TRANSPARENTE KILO | E25: 1 | F25: ud
A26: 60100010 | B26: EM10133 | C26: ETIQUETA ROJA LETRA ALERJENO (UND) | E26: 1 | F26: ud
D34: Cantidad | E34: Unidad
A35: PESO TOTAL OBTENIDO | D35: 26860 | E35: g | F35: Tiempo de Horneo:
A36: TIEMPO TOTAL DE PREPARACION | D36: 4 | E36: min | F36: Horno:
A37: CANTIDAD DE PORCIONES OBTENIDAS | D37: 1 | E37: tanda | F37: Temperatura de Horneo:
A38: PESO DE CADA PORCIÓN | D38: 26860 | E38: g | F38: Otros
A39: MERMA | D39: 0 | E39: g
A40: PROCEDIMIENTO DE PREPARACION DE LA RECETA
A41: 1.- En una bolsa 20x30 empacar el nucleo easy con el harina y el actiegg. En una bolsa 17x25 empacar el azucar, y etiquetar.
A42: 2.- En la otra bolsa 8x12 empacar el preservante, polvo de hornear. Colocar en la misma bolsa del harina.
A45: CONTROL DE CAMBIOS
A46: Revision #2: Se baja a la mitad el polvo de hornear y se agrega goma xantana
A47: Revision #3: Actualizacion por adicion de huevo en polvo.
A48: Provisional: Se elimina el preservante Aseal 1047 y se agrega propionato de calcio

Sheet Leches Pasteurizada con Agua
C1: SERVICIOS DE PASTELERIA S.A. | H1: CÓDIGO: | I1: ESP-RE-DES-026
C2: ESPECIFICACION DE RECETA | H2: REVISIÓN: | I2: 01
C3: Leches pasteurizadas con Agua 320g Spoon 910000003(SE00254) | H3: FECHA DE APROBACIÓN: | I3: 45613
C4: Elaborado | D4: Javier Tong, Chef
C5: Aprobado | D5: Esteban Cartin, Gte Manufactura
A6: AREA QUE PRODUCE: | D6: Decoración | G6: AREA QUE EMPACA: | I6: Decoracion
A7: # Código | B7: # Código Netsuite | C7: Descripción del ingrediente | D7: Marca | E7: Unidad Internacional | G7: Medida alternativa | I7: Costo - Referencia
E8: Cantidad | F8: Unidad medida | G8: Cantidad | H8: Unidad medida | I8: Colones
C9: Ensamble
A10: 907000001 | B10: SE00031 | C10: MEZCLA DE LECHE PASTEURIZADA | D10: FAS | E10: 1600 | F10: g
C11: AGUA | D11: FAS | E11: 1600 | F11: g
A12: 1212412 | B12: MP10025 | C12: PRESERVANTE 1017 (PAQ=5 KILO) | D12: Aseal | E12: 3 | F12: g
C20: Decoración
C29: Empaque
D40: Cantidad | E40: Unidad
A41: PESO TOTAL OBTENIDO | D41: 3200 | E41: g | F41: Tiempo de Horneo:
A42: TIEMPO TOTAL DE PREPARACION | D42: 5 | E42: Minutos | F42: Horno:
A43: CANTIDAD DE PORCIONES OBTENIDAS | D43: 10 | E43: Tortas | F43: Temperatura de Horneo:
A44: PESO DE CADA PORCIÓN | D44: 320 | E44: g | F44: Otros
A45: MERMA | D45: 3 | E45: g
A46: PROCEDIMIENTO DE PREPARACION DE LA RECETA
A47: 1.- Colocar la mezcla de leches con agua y preservante en un balde.
A56: CONTROL DE CAMBIOS

Sheet Mezcla leche Pasteurizada 
C1: SERVICIOS DE PASTELERIA S.A. | H1: CÓDIGO: | I1: ESP-RE-POS-020
C2: ESPECIFICACION DE RECETA | H2: REVISIÓN: | I2: 02
C3: Mezcla para Tres Leches Pasteurizada SE00031 | H3: FECHA DE APROBACIÓN: | I3: 45615
C4: Elaborado | D4: Javier Tong, Chef
C5: Aprobado | D5: Esteban Cartin, Gte Manufactura
A6: AREA QUE PRODUCE: | D6: Postres | G6: AREA QUE EMPACA: | I6: Postres
A7: # Código | B7: # Código Netsuite | C7: Descripción del ingrediente | D7: Marca | E7: Unidad Internacional | G7: Medida alternativa | I7: Costo - Referencia
E8: Cantidad | F8: Unidad medida | G8: Cantidad | H8: Unidad medida | I8: Colones
C9: Ensamble
A10: 11400047 | B10: MP10030 | C10: LECHE 2% PASTEURIZADA (UND) | D10: DOS PINOS | E10: 12230 | F10: g
A11: 1110414 | B11: MP10024 | C11: LECHE EVAPORADA (LITRO) | D11: NESTLE | E11: 17430 | F11: g
A12: 11400046 | B12: MP10050 | C12: LECHE CONDENSADA | D12: NESTLE | E12: 17430 | F12: g
A13: 11400031 | B13: MP10048 | C13: CREMA PRESTIGE GRAND | D13: RICH | E13: 14000 | F13: g
A14: 90100131 | B14: SE00016 | C14: AZUCAR BLANCO INDUSTRIAL KILO | D14: FAS | E14: 1475 | F14: g
A15: 1212410 | B15: MP10008 | C15: PRESERVANTE 1047S (PAQ=5 KILO) | D15: ASEAL | E15: 140 | F15: g
C21: Decoración
C30: Empaque
D43: Cantidad | E43: Unidad
A44: PESO TOTAL OBTENIDO | D44: 62500 | E44: g | F44: Tiempo de Horneo:
A45: TIEMPO TOTAL DE PREPARACION | D45: 11 | E45: Min. | F45: Horno:
A46: CANTIDAD DE PORCIONES OBTENIDAS | D46: 1 | E46: tanda | F46: Temperatura de Horneo:
A47: PESO DE CADA PORCIÓN | D47: 62500 | E47: g | F47: Otros
A48: MERMA | D48: 205 | E48: g
A49: PROCEDIMIENTO DE PREPARACION DE LA RECETA
A50: 1. Disolver completamente el preservante en un litro de leche estandar empleando el homogenizador manual.
A51: 2. Colocar en un bolw con una paleta manual, la leche fluida, la leche evaporada, el litro de leche con el preservante ya disuelto, el azúcar, la crema prestige líquida y la leche condensada.
A52: 3. Dosificar la mezcla pasteurizada en recipientes de acero inoxidable previamente lavado de acuerdo a INS-LMP-019 Recipiente para el Almacenamiento de Leche Pasteurizada, tapar el recipiente hermeticamente y reservar hasta su uso.
A53: 4. Identificar los recipientes con nombre del producto, fecha de producción y responsable.
A54: 5. Esta mezcla tiene una vida útil de 2 días envasada en recipientes de acero inoxidable herméticamente cerrados y mantenida en refrigeración
A55: 0ºC y 5ªC. Terminado el proceso proceder a la limpieza del equipo y a la sanitización.
A58: CONTROL DE CAMBIOS
A59: 2Actualización procedimiento

Sheet Crema Dulce de leche 
C1: SERVICIOS DE PASTELERIA S.A. | H1: CÓDIGO: | I1: ESP-RE-DES-020
C2: ESPECIFICACION DE RECETA | H2: REVISIÓN: | I2: 02
C3: Crema de Dulce de Leche(24500g) SE00032 | H3: FECHA DE APROBACIÓN: | I3: 45613
C4: Elaborado | D4: Javier Tong, Chef
C5: Aprobado | D5: Esteban Cartin, Gte Manufactura
A6: AREA QUE PRODUCE: | D6: Decoración | G6: AREA QUE EMPACA: | I6: Decoracion
A7: # Código | B7: # Código Netsuite | C7: Descripción del ingrediente | D7: Marca | E7: Unidad Internacional | G7: Medida alternativa | I7: Costo - Referencia
E8: Cantidad | F8: Unidad medida | G8: Cantidad | H8: Unidad medida | I8: Colones
C9: Ensamble
A10: 11400029 | B10: MP10165 | C10: CREMA BETTER DULCE LECHE RICH (UND:4 K) | D10: RICHS | E10: 16000 | F10: g | H10: 4 GALON
A11: 11400031 | B11: MP10048 | C11: CREMA PRESTIGE GRAND (UND:4 K) | D11: RICHS | E11: 8000 | F11: g | H11: 2 GALON
A12: 10415 | C12: AGUA POTABLE (PLANTA) | D12: FAS | E12: 1000 | F12: g
A13: 1212410 | B13: MP10008 | C13: PRESERVANTE 1047S (PAQ=5 KILO) | D13: ASEAL | E13: 22 | F13: g
C20: Decoración
C29: Empaque
A30: 702123 | B30: EM10011 | C30: ETIQUETA BLANCA 2 5/8X1 15/16 (UND) | E30: 1 | F30: ud
D40: Cantidad | E40: Unidad
A41: PESO TOTAL OBTENIDO | D41: 24500 | E41: g | F41: Tiempo de Horneo:
A42: TIEMPO TOTAL DE PREPARACION | D42: 21 | E42: min | F42: Horno:
A43: CANTIDAD DE PORCIONES OBTENIDAS | D43: 1 | E43: ud | F43: Temperatura de Horneo:
A44: PESO DE CADA PORCIÓN | D44: 24500 | E44: g | F44: Otros
A45: MERMA | D45: 500 | E45: g
A46: PROCEDIMIENTO DE PREPARACION DE LA RECETA
A47: 1.- Colocar en la top cream, la crema de dulce de leche y la prestige y el agua con el preservante. (Cumpliendo un temperatura de 5° liquida)
A48: 2.- Batir por 21 minutos.
A49: 3,- Una vez lista a una temperatura de 18° batida, retirar, etiquetar y guardar hasta que sean usadas.
A57: 2, Actualización tiempo de preparación y procedimiento

Sheet Ganache Chocolate Blanco
C1: SERVICIOS DE PASTELERIA S.A. | H1: CÓDIGO: | I1: ESP-RE-COCS-025
C2: ESPECIFICACION DE RECETA | H2: REVISIÓN: | I2: 01
C3: Ganache De Chocolate Blanco 37380g SE00051 | H3: FECHA DE APROBACIÓN: | I3: 45609
C4: Elaborado | D4: Javier Tong, Chef
C5: Aprobado | D5: Esteban Cartin, Gte Manufactura
A6: AREA QUE PRODUCE: | D6: Cocina | G6: AREA QUE EMPACA: | I6: Cocina
A7: # Código | B7: # Código Netsuite | C7: Descripción del ingrediente | D7: Marca | E7: Unidad Internacional | G7: Medida alternativa | I7: Costo - Referencia
E8: Cantidad | F8: Unidad medida | G8: Cantidad | H8: Unidad medida | I8: Colones
C9: Ensamble
A10: 1210387 | B10: MP10143 | C10: COBERTURA DE CHOCOLATE BLANCO ( PAQ=5 K ) | D10: NACIONAL CH | E10: 20000
A11: 11400031 | B11: MP10048 | C11: CREMA PRESTIGE GRAND | D11: RICH | E11: 20000
C13: Decoración
C15: Empaque
D19: Cantidad | E19: Unidad
A20: PESO TOTAL OBTENIDO | D20: 37380 | E20: g | F20: Tiempo de Horneo:
A21: TIEMPO TOTAL DE PREPARACION | D21: 25 | E21: Minutos | F21: Horno:
A22: CANTIDAD DE PORCIONES OBTENIDAS | D22: 1 | E22: Tanda | F22: Temperatura de Horneo:
A23: PESO DE CADA PORCIÓN | D23: 37380 | E23: g | F23: Otros
A24: MERMA | D24: 2620 | E24: g
A25: PROCEDIMIENTO DE PREPARACION DE LA RECETA
A26: 1.- Colocar la crema en una olla llegar a 65 grados , mover, no hervir, agregar los trozos de chocolate y mover hasta que se derritan.
A27: 2.- Mezclar bien, con cuidado de no quemar,cuando este todo derretido, mezlcar con ayuda de un batidor de globo de mano, para asegurarse que no queden grumos
A29: 3.- Colocar en bandejas, enfriar.
A31: CONTROL DE CAMBIOS

Sheet Ganache Chocolate Oscuro
C1: SERVICIOS DE PASTELERIA S.A. | H1: CÓDIGO: | I1: ESP-RE-COCS-019
C2: ESPECIFICACION DE RECETA | H2: REVISIÓN: | I2: 01
C3: 908000032(SE00001) Ganache De chocolate Oscuro 40700g | H3: FECHA DE APROBACIÓN: | I3: 45608
C4: Elaborado | D4: Javier Tong, Chef
C5: Aprobado | D5: Esteban Cartin, Gte Manufactura
A6: AREA QUE PRODUCE: | D6: Cocina | G6: AREA QUE EMPACA: | I6: Cocina
A7: # Código | B7: # Código Netsuite | C7: Descripción del ingrediente | D7: Marca | E7: Unidad Internacional | G7: Medida alternativa | I7: Costo - Referencia
E8: Cantidad | F8: Unidad medida | G8: Cantidad | H8: Unidad medida | I8: Colones
C9: Ensamble
A10: 1210386 | B10: MP10001 | C10: COBERTURA CHOCOLATE LECHE ( 5KG ) | D10: Nacional Chocolate | E10: 22000 | F10: g
A11: 11400027 | B11: MP10006 | C11: CREMA BETTERCREAM DOBLE CHOCO 4K | D11: Richs | E11: 20000 | F11: g
C13: Decoración
C15: Empaque
A16: 0702069 | B16: EM10002 | C16: ETIQ.BLANCA 1 1/4 * 3/4 | D16: Cemusa | E16: 1 | F16: ud
D20: Cantidad | E20: Unidad
A21: PESO TOTAL OBTENIDO | D21: 40700 | E21: g | F21: Tiempo de Horneo:
A22: TIEMPO TOTAL DE PREPARACION | D22: 30 | E22: Minutos | F22: Horno:
A23: CANTIDAD DE PORCIONES OBTENIDAS | D23: 1 | E23: Tanda | F23: Temperatura de Horneo:
A24: PESO DE CADA PORCIÓN | D24: 40700 | E24: g | F24: Otros
A25: MERMA | D25: 1300 | E25: g
A26: PROCEDIMIENTO DE PREPARACION DE LA RECETA
A27: 1- Colocar la crema de chocolate en una olla y calentar hasta 55 grados hasta hervir, agregar primero la mitad del chocolate. Mezclar hasta derretir.
A28: 2.- Añadir luego la mitad restante de chocolate, mezclar bien hasta derretir completamente el chocolate.
A29: 3- Pasar el ganache caliente por un colador para evitar que queden grumos de chocolate.
A30: 4.- Colocar en cheffing de acero y enfriar.
A32: CONTROL DE CAMBIOS

Sheet Ganache Dulce leche
C1: SERVICIOS DE PASTELERIA S.A. | H1: CÓDIGO: | I1: ESP-RE-COCS-034
C2: ESPECIFICACION DE RECETA | H2: REVISIÓN: | I2: 01
C3: Ganage de dulce de leche 4800g Spoon 901000111(SE00298) | H3: FECHA DE APROBACIÓN: | I3: 45609
C4: Elaborado | D4: Javier Tong, Chef
C5: Aprobado | D5: Esteban Cartin, Gte Manufactura | K5: Actializado 27/06/2025
A6: AREA QUE PRODUCE: | D6: Cocina | G6: AREA QUE EMPACA: | I6: Cocina
A7: # Código | B7: # Código Netsuite | C7: Descripción del ingrediente | D7: Marca | E7: Unidad Internacional | G7: Medida alternativa | I7: Costo - Referencia
E8: Cantidad | F8: Unidad medida | G8: Cantidad | H8: Unidad medida | I8: Colones
C9: Ensamble
A10: 11400029 | B10: MP10165 | C10: CREMA BETTER DULCE LECHE RICH (UND:4 K) | D10: RICH | E10: 2500 | F10: g | J10: =+E10/$D$47 -> 0.46296296 | K10: =+J10*1000 -> 462.96296
A11: 1210387 | B11: MP10143 | C11: COBERTURA CHOCOLATE BLANCO (PAQ:5 K) | D11: NACIONAL C | E11: 3250 | F11: g | J11: =+E11/$D$47 -> 0.60185185 | K11: =+J11*1000 -> 601.85185
C29: Decoración
C35: Empaque
A36: 702123 | B36: EM10011 | C36: ETIQUETA BLANCA 2 5/8X1 15/16 (UND) | D36: Mayca | E36: 1 | F36: ud
A37: 512000002 | B37: EM10259 | C37: PLAST. AUTOAD 18 * 2000 | D37: Cemusa | E37: 30 | F37: cm
D46: Cantidad | E46: Unidad
A47: PESO TOTAL OBTENIDO | D47: 5400 | E47: g | F47: Tiempo de Horneo:
A48: TIEMPO TOTAL DE PREPARACION | D48: 10 | E48: Min. | F48: Horno:
A49: CANTIDAD DE PORCIONES OBTENIDAS | D49: 1 | E49: Tanda | F49: Temperatura de Horneo:
A50: PESO DE CADA PORCIÓN | D50: 5400 | E50: g | F50: Otros
A51: MERMA | D51: =SUM(E10:E11)-D47 -> 350 | E51: g
A52: PROCEDIMIENTO DE PREPARACION DE LA RECETA
A53: 1.- Calentar la crema hastsa 55°C - 60°C. Apagar el fuego. Luego agregar el chocolate blanco en trozos lo mas pequeñas posible, ir moviendo constantemete con ayuda de un batidor de globo. Hasta que se derrita. Temp final 40°C aprox.
A54: 2.- Colocar en badnejas tapadas, etiquetar con fecha de produccion y vencimiento.
A64: CONTROL DE CAMBIOS
A65: 2, Se le aumenta chocolate blanco. Se actualiza procedimiento

Sheet Costo Ensamble 
E1: Precio Local | F1: Costo MP | G1: Costo EM | H1: Costo MO
E2: =IFERROR(O80,"") -> 4643.5538 | F2: =IFERROR(H71,"") -> 2562.2149 | G2: =IFERROR(H72,"") -> 1006.28 | H2: =IFERROR(H74,"") -> 517.37209
A5: ESTRUCTURA DE COSTOS
F6: Fecha: | H6: =TODAY() -> 46148
A7: UNIDADES | B7: DESCRIPCION MAT.PRIMA | C7: UNIDADES | D7: UND MEDIDA | E7: COSTO UNITARIO | F7: TOTAL COSTO | G7: % PREC. DEFINIDO | H7: CODIGOS
A8: 100 | B8: =IFERROR(VLOOKUP(H8,'[1]Consolidado MP Planta'!$A$2:$M$823,3,0),"") -> DULCE LECHE LA CIABATA (UND:5 K ) | C8: =+A8 -> 100 | D8: =IFERROR(VLOOKUP(H8,'[1]Consolidado MP Planta'!$A$2:$M$823,13,0),"") -> Gramos | E8: 1.96 | F8: =IFERROR(C8*E8,"") -> 196 | G8: =IFERROR(F8/$F$84,"") -> 0.048942013 | H8: 11700002
B9: =IFERROR(VLOOKUP(H9,'[1]Consolidado MP Planta'!$A$2:$M$823,3,0),"") | C9: =+A9 -> 0 | D9: =IFERROR(VLOOKUP(H9,'[1]Consolidado MP Planta'!$A$2:$M$823,13,0),"") | E9: =IFERROR(VLOOKUP(H9,'[1]Consolidado MP Planta'!$A$2:$M$823,12,0),"") | F9: =IFERROR(C9*E9,"") | G9: =IFERROR(F9/$F$84,"")
B10: =IFERROR(VLOOKUP(H10,'[1]Consolidado MP Planta'!$A$2:$M$823,3,0),"") | C10: =+A10 -> 0 | D10: =IFERROR(VLOOKUP(H10,'[1]Consolidado MP Planta'!$A$2:$M$823,13,0),"") | E10: =IFERROR(VLOOKUP(H10,'[1]Consolidado MP Planta'!$A$2:$M$823,12,0),"") | F10: =IFERROR(C10*E10,"") | G10: =IFERROR(F10/$F$84,"")
B11: =IFERROR(VLOOKUP(H11,'[1]Consolidado MP Planta'!$A$2:$M$823,3,0),"") | C11: =+A11 -> 0 | D11: =IFERROR(VLOOKUP(H11,'[1]Consolidado MP Planta'!$A$2:$M$823,13,0),"") | E11: =IFERROR(VLOOKUP(H11,'[1]Consolidado MP Planta'!$A$2:$M$823,12,0),"") | F11: =IFERROR(C11*E11,"") | G11: =IFERROR(F11/$F$84,"")
B12: =IFERROR(VLOOKUP(H12,'[1]Consolidado MP Planta'!$A$2:$M$823,3,0),"") | C12: =+A12 -> 0 | D12: =IFERROR(VLOOKUP(H12,'[1]Consolidado MP Planta'!$A$2:$M$823,13,0),"") | E12: =IFERROR(VLOOKUP(H12,'[1]Consolidado MP Planta'!$A$2:$M$823,12,0),"") | F12: =IFERROR(C12*E12,"") | G12: =IFERROR(F12/$F$84,"")
B13: =IFERROR(VLOOKUP(H13,'[1]Consolidado MP Planta'!$A$2:$M$823,3,0),"") | C13: =+A13 -> 0 | D13: =IFERROR(VLOOKUP(H13,'[1]Consolidado MP Planta'!$A$2:$M$823,13,0),"") | E13: =IFERROR(VLOOKUP(H13,'[1]Consolidado MP Planta'!$A$2:$M$823,12,0),"") | F13: =IFERROR(C13*E13,"") | G13: =IFERROR(F13/$F$84,"")
B14: =IFERROR(VLOOKUP(H14,'[1]Consolidado MP Planta'!$A$2:$M$823,3,0),"") | C14: =+A14 -> 0 | D14: =IFERROR(VLOOKUP(H14,'[1]Consolidado MP Planta'!$A$2:$M$823,13,0),"") | E14: =IFERROR(VLOOKUP(H14,'[1]Consolidado MP Planta'!$A$2:$M$823,12,0),"") | F14: =IFERROR(C14*E14,"") | G14: =IFERROR(F14/$F$84,"")
B15: =IFERROR(VLOOKUP(H15,[2]Hoja2!$A$2:$G$589,2,0),"")
A16: UNIDADES | B16: MATERIA PRIMA SEMIELABORADOS | C16: UNIDADES | D16: UND MEDIDA | E16: COSTO UNITARIO | F16: TOTAL COSTO | G16: % PREC. DEFINIDO | H16: CODIGOS
A17: 1.5 | B17: ROSQUETE EASY VAINILLA BC 310 G | C17: =+A17 -> 1.5 | D17: UND | E17: 391 | F17: =IFERROR(E17*C17,"") -> 586.5 | G17: =IFERROR(F17/$F$84,"") -> 0.14645148 | H17: 907000287
A18: 90 | B18: Leches Pasteurizada Con Agua | C18: =+A18 -> 90 | D18: Gramos | E18: 1.11 | F18: =IFERROR(E18*C18,"") -> 99.9 | G18: =IFERROR(F18/$F$84,"") -> 0.024945444 | H18: SE00254
A19: 200 | B19: Crema Dulce de Caramelo | C19: =+A19 -> 200 | D19: Gramos | E19: =+'Costo Crema Dulce Caramelo'!E69 -> 2.31899 | F19: =IFERROR(E19*C19,"") -> 463.798 | G19: =IFERROR(F19/$F$84,"") -> 0.11581228 | H19: NUEVO
A20: 60 | B20: Procesado Chocolate con mani y arroz inflado | C20: =+A20 -> 60 | D20: Gramos | E20: =+'Costo Procesado'!E69 -> 6.0421053 | F20: =IFERROR(E20*C20,"") -> 362.52632 | G20: =IFERROR(F20/$F$84,"") -> 0.090524325 | H20: NUEVO
A21: 205 | B21: Crema Dulce Leche | C21: =+A21 -> 205 | D21: Gramos | E21: 2.3 | F21: =IFERROR(E21*C21,"") -> 471.5 | G21: =IFERROR(F21/$F$84,"") -> 0.11773551 | H21: SE00032
A22: 15 | B22: Mezcla mani y arroz inflado | C22: =+A22 -> 15 | D22: Gramos | E22: =+'Costo Mezcla Mani Arroz'!E69 -> 3.04878 | F22: =IFERROR(E22*C22,"") -> 45.7317 | G22: =IFERROR(F22/$F$84,"") -> 0.011419395 | H22: NUEVO
A23: 10 | B23: Ganache Chocolate Blanco | C23: =+A23 -> 10 | D23: Gramos | E23: 3.14 | F23: =IFERROR(E23*C23,"") -> 31.4 | G23: =IFERROR(F23/$F$84,"") -> 0.0078407103 | H23: SE00051
A24: 10 | B24: Ganache Chocolate Oscuro | C24: =+A24 -> 10 | D24: Gramos | E24: 4.69 | F24: =IFERROR(E24*C24,"") -> 46.9 | G24: =IFERROR(F24/$F$84,"") -> 0.011711125 | H24: SE00001
A25: 10 | B25: Ganache De Dulce Leche | C25: =+A25 -> 10 | D25: Gramos | E25: 3.42 | F25: =IFERROR(E25*C25,"") -> 34.2 | G25: =IFERROR(F25/$F$84,"") -> 0.0085398819 | H25: SE00298
A26: 26 | B26: Pelado Chocolate Choclate Choys | C26: =+A26 -> 26 | D26: Gramos | E26: =+'Costo Pelado choco Choys'!E69 -> 8.6061111 | F26: =IFERROR(E26*C26,"") -> 223.75889 | G26: =IFERROR(F26/$F$84,"") -> 0.055873523 | H26: NUEVO
B27: =IFERROR(VLOOKUP(H27,[1]SEMIELABORADOS!$A$2:$M$6000,2,0),"") | C27: =+A27 -> 0 | D27: =IFERROR(VLOOKUP(H27,[1]SEMIELABORADOS!$A$2:$M$6000,6,0),"") | E27: =IFERROR(VLOOKUP(H27,[1]SEMIELABORADOS!$A$2:$H$65536,8,0),"") | F27: =IFERROR(E27*C27,"") | G27: =IFERROR(F27/$F$84,"")
B28: =IFERROR(VLOOKUP(H28,[1]SEMIELABORADOS!$A$2:$M$6000,2,0),"") | C28: =+A28 -> 0 | D28: =IFERROR(VLOOKUP(H28,[1]SEMIELABORADOS!$A$2:$M$6000,6,0),"") | E28: =IFERROR(VLOOKUP(H28,[1]SEMIELABORADOS!$A$2:$H$65536,8,0),"") | F28: =IFERROR(E28*C28,"") | G28: =IFERROR(F28/$F$84,"")
B29: =IFERROR(VLOOKUP(H29,[1]SEMIELABORADOS!$A$2:$M$6000,2,0),"") | C29: =+A29 -> 0 | D29: =IFERROR(VLOOKUP(H29,[1]SEMIELABORADOS!$A$2:$M$6000,6,0),"") | E29: =IFERROR(VLOOKUP(H29,[1]SEMIELABORADOS!$A$2:$H$65536,8,0),"") | F29: =IFERROR(E29*C29,"") | G29: =IFERROR(F29/$F$84,"")
A31: UNIDADES | B31: EMPAQUE | C31: UNIDADES | D31: UND MEDIDA | E31: COSTO UNITARIO | F31: TOTAL COSTO | G31: % PREC. DEFINIDO | H31: CODIGOS
A32: 1 | B32: =IFERROR(VLOOKUP(H32,'[1]Consolidado MP Planta'!$A$2:$M$823,3,0),"") -> QUEQUERA RED BASE/DOMO 10 (CAJA:50) | C32: =+A32 -> 1 | D32: =IFERROR(VLOOKUP(H32,'[1]Consolidado MP Planta'!$A$2:$M$823,13,0),"") -> UND | E32: =IFERROR(VLOOKUP(H32,'[1]Consolidado MP Planta'!$A$2:$M$823,12,0),"") -> 751.04 | F32: =IFERROR(C32*E32,"") -> 751.04 | G32: =IFERROR(F32/$F$84,"") -> 0.1875378 | H32: 121603
A33: 1 | B33: =IFERROR(VLOOKUP(H33,'[1]Consolidado MP Planta'!$A$2:$M$823,3,0),"") -> ORLA # 10 BUCCA (UND) | C33: =+A33 -> 1 | D33: =IFERROR(VLOOKUP(H33,'[1]Consolidado MP Planta'!$A$2:$M$823,13,0),"") -> 0 | E33: =IFERROR(VLOOKUP(H33,'[1]Consolidado MP Planta'!$A$2:$M$823,12,0),"") -> 137 | F33: =IFERROR(C33*E33,"") -> 137 | G33: =IFERROR(F33/$F$84,"") -> 0.034209468 | H33: 1952875
A34: 1 | B34: =IFERROR(VLOOKUP(H34,'[1]Consolidado MP Planta'!$A$2:$M$823,3,0),"") -> ET. TORTA BUCCA GENERICA PEQUEÑA (UND) | C34: =+A34 -> 1 | D34: =IFERROR(VLOOKUP(H34,'[1]Consolidado MP Planta'!$A$2:$M$823,13,0),"") -> Und | E34: 0 | F34: =IFERROR(C34*E34,"") -> 0 | G34: =IFERROR(F34/$F$84,"") -> 0 | H34: 2172411
A35: 1 | B35: =IFERROR(VLOOKUP(H35,'[1]Consolidado MP Planta'!$A$2:$M$823,3,0),"") -> ETIQ.FECHA VENCIMIENTO BLANCO (ROLLO) | C35: =+A35 -> 1 | D35: =IFERROR(VLOOKUP(H35,'[1]Consolidado MP Planta'!$A$2:$M$823,13,0),"") -> Gramos | E35: =IFERROR(VLOOKUP(H35,'[1]Consolidado MP Planta'!$A$2:$M$823,12,0),"") -> 0.33333333 | F35: =IFERROR(C35*E35,"") -> 0.33333333 | G35: =IFERROR(F35/$F$84,"") -> 8.3234716e-05 | H35: 0702007
A36: 1 | B36: =IFERROR(VLOOKUP(H36,'[1]Consolidado MP Planta'!$A$2:$M$823,3,0),"") -> ETIQ.BLANCA 1 1/4 * 3/4 (UND) | C36: =+A36 -> 1 | D36: =IFERROR(VLOOKUP(H36,'[1]Consolidado MP Planta'!$A$2:$M$823,13,0),"") -> Und | E36: =IFERROR(VLOOKUP(H36,'[1]Consolidado MP Planta'!$A$2:$M$823,12,0),"") -> 0.58 | F36: =IFERROR(C36*E36,"") -> 0.58 | G36: =IFERROR(F36/$F$84,"") -> 0.00014482841 | H36: 0702069
A37: 1 | B37: =IFERROR(VLOOKUP(H37,'[1]Consolidado MP Planta'!$A$2:$M$823,3,0),"") -> ETIQUETA BLANCA 2 5/8X1 15/16 (UND) | C37: =+A37 -> 1 | D37: =IFERROR(VLOOKUP(H37,'[1]Consolidado MP Planta'!$A$2:$M$823,13,0),"") -> Und | E37: =IFERROR(VLOOKUP(H37,'[1]Consolidado MP Planta'!$A$2:$M$823,12,0),"") -> 2.128 | F37: =IFERROR(C37*E37,"") -> 2.128 | G37: =IFERROR(F37/$F$84,"") -> 0.00053137043 | H37: 0702123
A38: 1 | B38: Etiqueta Torta Toys | C38: =+A38 -> 1 | D38: UND | E38: 100 | F38: =IFERROR(C38*E38,"") -> 100 | G38: =IFERROR(F38/$F$84,"") -> 0.024970415 | H38: Nuevo
B39: =IFERROR(VLOOKUP(H39,'[1]Consolidado MP Planta'!$A$2:$M$823,3,0),"") | C39: =+A39 -> 0 | D39: =IFERROR(VLOOKUP(H39,'[1]Consolidado MP Planta'!$A$2:$M$823,13,0),"") | E39: =IFERROR(VLOOKUP(H39,'[1]Consolidado MP Planta'!$A$2:$M$823,12,0),"") | F39: =IFERROR(C39*E39,"") | G39: =IFERROR(F39/$F$84,"")
B40: =IFERROR(VLOOKUP(H40,'[1]Consolidado MP Planta'!$A$2:$M$823,3,0),"") | C40: =+A40 -> 0 | D40: =IFERROR(VLOOKUP(H40,'[1]Consolidado MP Planta'!$A$2:$M$823,13,0),"") | E40: =IFERROR(VLOOKUP(H40,'[1]Consolidado MP Planta'!$A$2:$M$823,12,0),"") | F40: =IFERROR(C40*E40,"") | G40: =IFERROR(F40/$F$84,"")
A42: UNIDADES | B42: EMPAQUE SEMIELABORADOS | C42: UNIDADES | D42: UND MEDIDA | E42: COSTO UNITARIO | F42: TOTAL COSTO | G42: % PREC. DEFINIDO | H42: CODIGOS
A43: =+A17 -> 1.5 | B43: ROSQUETE EASY VAINILLA BC 310 G | C43: =+A43 -> 1.5 | D43: UND | E43: 4.89 | F43: =IFERROR(E43*C43,"") -> 7.335 | G43: =IFERROR(F43/$F$84,"") -> 0.0018315799 | H43: 907000287
A44: =+A18 -> 90 | B44: Leches Pasteurizada Con Agua | C44: =+A44 -> 90 | D44: Gramos | E44: 0 | F44: =IFERROR(E44*C44,"") -> 0 | G44: =IFERROR(F44/$F$84,"") -> 0 | H44: SE00254
...

Sheet Costo Mezcla Mani Arroz
E1: Precio Local | F1: Costo MP | G1: Costo EM | H1: Costo MO
E2: =IFERROR(O62,"") -> 3607.5591 | F2: =IFERROR(H53,"") -> 3048.78 | G2: =IFERROR(H54,"") -> 34.27 | H2: =IFERROR(H56,"") -> 252.42
A5: ESTRUCTURA DE COSTOS
F6: Fecha: | H6: =TODAY() -> 46148
A7: UNIDADES | B7: DESCRIPCION MAT.PRIMA | C7: UNIDADES | D7: UND MEDIDA | E7: COSTO UNITARIO | F7: TOTAL COSTO | G7: % PREC. DEFINIDO | H7: CODIGOS
A8: 357 | B8: Arroz Inflado | C8: =+A8 -> 357 | D8: Gramos | E8: 3.82 | F8: =IFERROR(C8*E8,"") -> 1363.74 | G8: =IFERROR(F8/$F$66,"") -> 0.40406805 | H8: NUEVO
B9: =IFERROR(VLOOKUP(H9,'[1]Consolidado MP Planta'!$A$2:$M$823,3,0),"") | C9: =+A9 -> 0 | D9: =IFERROR(VLOOKUP(H9,'[1]Consolidado MP Planta'!$A$2:$M$823,13,0),"") | E9: =IFERROR(VLOOKUP(H9,'[1]Consolidado MP Planta'!$A$2:$M$823,12,0),"") | F9: =IFERROR(C9*E9,"") | G9: =IFERROR(F9/$F$66,"")
B10: =IFERROR(VLOOKUP(H10,'[1]Consolidado MP Planta'!$A$2:$M$823,3,0),"") | C10: =+A10 -> 0 | D10: =IFERROR(VLOOKUP(H10,'[1]Consolidado MP Planta'!$A$2:$M$823,13,0),"") | E10: =IFERROR(VLOOKUP(H10,'[1]Consolidado MP Planta'!$A$2:$M$823,12,0),"") | F10: =IFERROR(C10*E10,"") | G10: =IFERROR(F10/$F$66,"")
B11: =IFERROR(VLOOKUP(H11,'[1]Consolidado MP Planta'!$A$2:$M$823,3,0),"") | C11: =+A11 -> 0 | D11: =IFERROR(VLOOKUP(H11,'[1]Consolidado MP Planta'!$A$2:$M$823,13,0),"") | E11: =IFERROR(VLOOKUP(H11,'[1]Consolidado MP Planta'!$A$2:$M$823,12,0),"") | F11: =IFERROR(C11*E11,"") | G11: =IFERROR(F11/$F$66,"")
B12: =IFERROR(VLOOKUP(H12,'[1]Consolidado MP Planta'!$A$2:$M$823,3,0),"") | C12: =+A12 -> 0 | D12: =IFERROR(VLOOKUP(H12,'[1]Consolidado MP Planta'!$A$2:$M$823,13,0),"") | E12: =IFERROR(VLOOKUP(H12,'[1]Consolidado MP Planta'!$A$2:$M$823,12,0),"") | F12: =IFERROR(C12*E12,"") | G12: =IFERROR(F12/$F$66,"")
B13: =IFERROR(VLOOKUP(H13,'[1]Consolidado MP Planta'!$A$2:$M$823,3,0),"") | C13: =+A13 -> 0 | D13: =IFERROR(VLOOKUP(H13,'[1]Consolidado MP Planta'!$A$2:$M$823,13,0),"") | E13: =IFERROR(VLOOKUP(H13,'[1]Consolidado MP Planta'!$A$2:$M$823,12,0),"") | F13: =IFERROR(C13*E13,"") | G13: =IFERROR(F13/$F$66,"")
B14: =IFERROR(VLOOKUP(H14,'[1]Consolidado MP Planta'!$A$2:$M$823,3,0),"") | C14: =+A14 -> 0 | D14: =IFERROR(VLOOKUP(H14,'[1]Consolidado MP Planta'!$A$2:$M$823,13,0),"") | E14: =IFERROR(VLOOKUP(H14,'[1]Consolidado MP Planta'!$A$2:$M$823,12,0),"") | F14: =IFERROR(C14*E14,"") | G14: =IFERROR(F14/$F$66,"")
B15: =IFERROR(VLOOKUP(H15,[2]Hoja2!$A$2:$G$589,2,0),"")
A16: UNIDADES | B16: MATERIA PRIMA SEMIELABORADOS | C16: UNIDADES | D16: UND MEDIDA | E16: COSTO UNITARIO | F16: TOTAL COSTO | G16: % PREC. DEFINIDO | H16: CODIGOS
A17: 714 | B17: Mani Tostado | C17: =+A17 -> 714 | D17: Gramos | E17: 2.36 | F17: =IFERROR(E17*C17,"") -> 1685.04 | G17: =IFERROR(F17/$F$66,"") -> 0.49926732 | H17: se00820
B18: =IFERROR(VLOOKUP(H18,[1]SEMIELABORADOS!$A$2:$M$6000,2,0),"") | C18: =+A18 -> 0 | D18: =IFERROR(VLOOKUP(H18,[1]SEMIELABORADOS!$A$2:$M$6000,6,0),"") | E18: =IFERROR(VLOOKUP(H18,[1]SEMIELABORADOS!$A$2:$H$65536,8,0),"") | F18: =IFERROR(E18*C18,"") | G18: =IFERROR(F18/$F$66,"")
B19: =IFERROR(VLOOKUP(H19,[1]SEMIELABORADOS!$A$2:$M$6000,2,0),"") | C19: =+A19 -> 0 | D19: =IFERROR(VLOOKUP(H19,[1]SEMIELABORADOS!$A$2:$M$6000,6,0),"") | E19: =IFERROR(VLOOKUP(H19,[1]SEMIELABORADOS!$A$2:$H$65536,8,0),"") | F19: =IFERROR(E19*C19,"") | G19: =IFERROR(F19/$F$66,"")
B20: =IFERROR(VLOOKUP(H20,[1]SEMIELABORADOS!$A$2:$M$6000,2,0),"") | C20: =+A20 -> 0 | D20: =IFERROR(VLOOKUP(H20,[1]SEMIELABORADOS!$A$2:$M$6000,6,0),"") | E20: =IFERROR(VLOOKUP(H20,[1]SEMIELABORADOS!$A$2:$H$65536,8,0),"") | F20: =IFERROR(E20*C20,"") | G20: =IFERROR(F20/$F$66,"")
B21: =IFERROR(VLOOKUP(H21,[1]SEMIELABORADOS!$A$2:$M$6000,2,0),"") | C21: =+A21 -> 0 | D21: =IFERROR(VLOOKUP(H21,[1]SEMIELABORADOS!$A$2:$M$6000,6,0),"") | E21: =IFERROR(VLOOKUP(H21,[1]SEMIELABORADOS!$A$2:$H$65536,8,0),"") | F21: =IFERROR(E21*C21,"") | G21: =IFERROR(F21/$F$66,"")
B22: =IFERROR(VLOOKUP(H22,[1]SEMIELABORADOS!$A$2:$M$6000,2,0),"") | C22: =+A22 -> 0 | D22: =IFERROR(VLOOKUP(H22,[1]SEMIELABORADOS!$A$2:$M$6000,6,0),"") | E22: =IFERROR(VLOOKUP(H22,[1]SEMIELABORADOS!$A$2:$H$65536,8,0),"") | F22: =IFERROR(E22*C22,"") | G22: =IFERROR(F22/$F$66,"")
B23: =IFERROR(VLOOKUP(H23,[1]SEMIELABORADOS!$A$2:$M$6000,2,0),"") | C23: =+A23 -> 0 | D23: =IFERROR(VLOOKUP(H23,[1]SEMIELABORADOS!$A$2:$M$6000,6,0),"") | E23: =IFERROR(VLOOKUP(H23,[1]SEMIELABORADOS!$A$2:$H$65536,8,0),"") | F23: =IFERROR(E23*C23,"") | G23: =IFERROR(F23/$F$66,"")
B24: =IFERROR(VLOOKUP(H24,[1]SEMIELABORADOS!$A$2:$M$6000,2,0),"") | C24: =+A24 -> 0 | D24: =IFERROR(VLOOKUP(H24,[1]SEMIELABORADOS!$A$2:$M$6000,6,0),"") | E24: =IFERROR(VLOOKUP(H24,[1]SEMIELABORADOS!$A$2:$H$65536,8,0),"") | F24: =IFERROR(E24*C24,"") | G24: =IFERROR(F24/$F$66,"")
A26: UNIDADES | B26: EMPAQUE | C26: UNIDADES | D26: UND MEDIDA | E26: COSTO UNITARIO | F26: TOTAL COSTO | G26: % PREC. DEFINIDO | H26: CODIGOS
A27: 1 | B27: ETIQUETA BLANCA 2 5/8X1 15/16 (UND) | C27: =+A27 -> 1 | D27: und | E27: 2.13 | F27: =IFERROR(C27*E27,"") -> 2.13 | G27: =IFERROR(F27/$F$66,"") -> 0.00063110632
A28: 1 | B28: BOLSA 17x25 TRANSP KILO | C28: =+A28 -> 1 | D28: und | E28: 25 | F28: =IFERROR(C28*E28,"") -> 25 | G28: =IFERROR(F28/$F$66,"") -> 0.0074073512
B29: =IFERROR(VLOOKUP(H29,'[1]Consolidado MP Planta'!$A$2:$M$823,3,0),"") | C29: =+A29 -> 0 | D29: =IFERROR(VLOOKUP(H29,'[1]Consolidado MP Planta'!$A$2:$M$823,13,0),"") | E29: =IFERROR(VLOOKUP(H29,'[1]Consolidado MP Planta'!$A$2:$M$823,12,0),"") | F29: =IFERROR(C29*E29,"") | G29: =IFERROR(F29/$F$66,"")
B30: =IFERROR(VLOOKUP(H30,'[1]Consolidado MP Planta'!$A$2:$M$823,3,0),"") | C30: =+A30 -> 0 | D30: =IFERROR(VLOOKUP(H30,'[1]Consolidado MP Planta'!$A$2:$M$823,13,0),"") | E30: =IFERROR(VLOOKUP(H30,'[1]Consolidado MP Planta'!$A$2:$M$823,12,0),"") | F30: =IFERROR(C30*E30,"") | G30: =IFERROR(F30/$F$66,"")
B31: =IFERROR(VLOOKUP(H31,'[1]Consolidado MP Planta'!$A$2:$M$823,3,0),"") | C31: =+A31 -> 0 | D31: =IFERROR(VLOOKUP(H31,'[1]Consolidado MP Planta'!$A$2:$M$823,13,0),"") | E31: =IFERROR(VLOOKUP(H31,'[1]Consolidado MP Planta'!$A$2:$M$823,12,0),"") | F31: =IFERROR(C31*E31,"") | G31: =IFERROR(F31/$F$66,"")
B32: =IFERROR(VLOOKUP(H32,'[1]Consolidado MP Planta'!$A$2:$M$823,3,0),"") | C32: =+A32 -> 0 | D32: =IFERROR(VLOOKUP(H32,'[1]Consolidado MP Planta'!$A$2:$M$823,13,0),"") | E32: =IFERROR(VLOOKUP(H32,'[1]Consolidado MP Planta'!$A$2:$M$823,12,0),"") | F32: =IFERROR(C32*E32,"") | G32: =IFERROR(F32/$F$66,"")
A34: UNIDADES | B34: EMPAQUE SEMIELABORADOS | C34: UNIDADES | D34: UND MEDIDA | E34: COSTO UNITARIO | F34: TOTAL COSTO | G34: % PREC. DEFINIDO | H34: CODIGOS
A35: =+A17 -> 714 | B35: Mani Tostado | C35: =+A35 -> 714 | D35: Gramos | E35: 0.01 | F35: =IFERROR(E35*C35,"") -> 7.14 | G35: =IFERROR(F35/$F$66,"") -> 0.0021155395 | H35: se00820
A36: =+A18 -> 0 | B36: =IFERROR(VLOOKUP(H36,[1]SEMIELABORADOS!$A$2:$M$6000,2,0),"") | C36: =+A36 -> 0 | D36: =IFERROR(VLOOKUP(H36,[1]SEMIELABORADOS!$A$2:$M$6000,6,0),"") | E36: =IFERROR(VLOOKUP(H36,[1]SEMIELABORADOS!$A$2:$M$65536,10,0),"") | F36: =IFERROR(E36*C36,"") | G36: =IFERROR(F36/$F$66,"")
A37: =+A19 -> 0 | B37: =IFERROR(VLOOKUP(H37,[1]SEMIELABORADOS!$A$2:$M$6000,2,0),"") | C37: =+A37 -> 0 | D37: =IFERROR(VLOOKUP(H37,[1]SEMIELABORADOS!$A$2:$M$6000,6,0),"") | E37: =IFERROR(VLOOKUP(H37,[1]SEMIELABORADOS!$A$2:$M$65536,10,0),"") | F37: =IFERROR(E37*C37,"") | G37: =IFERROR(F37/$F$66,"")
A38: =+A20 -> 0 | B38: =IFERROR(VLOOKUP(H38,[1]SEMIELABORADOS!$A$2:$M$6000,2,0),"") | C38: =+A38 -> 0 | D38: =IFERROR(VLOOKUP(H38,[1]SEMIELABORADOS!$A$2:$M$6000,6,0),"") | E38: =IFERROR(VLOOKUP(H38,[1]SEMIELABORADOS!$A$2:$M$65536,10,0),"") | F38: =IFERROR(E38*C38,"") | G38: =IFERROR(F38/$F$66,"")
A39: =+A21 -> 0 | B39: =IFERROR(VLOOKUP(H39,[1]SEMIELABORADOS!$A$2:$M$6000,2,0),"") | C39: =+A39 -> 0 | D39: =IFERROR(VLOOKUP(H39,[1]SEMIELABORADOS!$A$2:$M$6000,6,0),"") | E39: =IFERROR(VLOOKUP(H39,[1]SEMIELABORADOS!$A$2:$M$65536,10,0),"") | F39: =IFERROR(E39*C39,"") | G39: =IFERROR(F39/$F$66,"")
A40: =+A22 -> 0 | B40: =IFERROR(VLOOKUP(H40,[1]SEMIELABORADOS!$A$2:$M$6000,2,0),"") | C40: =+A40 -> 0 | D40: =IFERROR(VLOOKUP(H40,[1]SEMIELABORADOS!$A$2:$M$6000,6,0),"") | E40: =IFERROR(VLOOKUP(H40,[1]SEMIELABORADOS!$A$2:$M$65536,10,0),"") | F40: =IFERROR(E40*C40,"") | G40: =IFERROR(F40/$F$66,"")
A41: =+A23 -> 0 | B41: =IFERROR(VLOOKUP(H41,[1]SEMIELABORADOS!$A$2:$M$6000,2,0),"") | C41: =+A41 -> 0 | D41: =IFERROR(VLOOKUP(H41,[1]SEMIELABORADOS!$A$2:$M$6000,6,0),"") | E41: =IFERROR(VLOOKUP(H41,[1]SEMIELABORADOS!$A$2:$M$65536,10,0),"") | F41: =IFERROR(E41*C41,"") | G41: =IFERROR(F41/$F$66,"")
A43: UNIDADES | B43: MODI | C43: UNIDADES | D43: UND MEDIDA | E43: COSTO UNITARIO | F43: TOTAL COSTO | G43: % PREC. DEFINIDO | H43: CODIGOS
A44: =+A35 -> 714 | B44: Mani Tostado | C44: =+A44 -> 714 | D44: Gramos | E44: 0.03 | F44: =IFERROR(E44*C44,"") -> 21.42 | G44: =IFERROR(F44/$F$66,"") -> 0.0063466185 | H44: se00820
A45: =+A36 -> 0 | B45: =IFERROR(VLOOKUP(H45,[1]SEMIELABORADOS!$A$2:$M$6000,2,0),"") | C45: =+A45 -> 0 | D45: =IFERROR(VLOOKUP(H45,[1]SEMIELABORADOS!$A$2:$M$6000,6,0),"") | E45: =IFERROR(VLOOKUP(H45,[1]SEMIELABORADOS!$A$2:$M$65536,12,0),"") | F45: =IFERROR(E45*C45,"") | G45: =IFERROR(F45/$F$66,"")
...

Sheet Mani tostado
C1: SERVICIOS DE PASTELERIA S.A. | H1: CÓDIGO: | I1: ESP-RE-DES-096
C2: ESPECIFICACION DE RECETA | H2: REVISIÓN: | I2: 01
C3: SE00820 Mani Tostado | H3: FECHA DE APROBACIÓN: | I3: 46066
C4: Elaborado | D4: Mariela Barrantes Sánchez, Chef
C5: Aprobado | D5: Sebastian Díaz, Gte Manufactura
A6: AREA QUE PRODUCE: | D6: Decoración | G6: AREA QUE EMPACA: | I6: Decoración
A7: # Código | B7: # Código Netsuite | C7: Descripción del ingrediente | D7: Marca | E7: Unidad Internacional | G7: Medida alternativa | I7: Costo - Referencia
E8: Cantidad | F8: Unidad medida | G8: Cantidad | H8: Unidad medida | I8: Colones
C9: Ensamble
B10: MP10602 | C10: Mani picado | D10: Nueces Industriales | E10: 5000
C12: DECORACION
C14: EMPAQUE
B15: AS00028 | C15: Bolsa Transparente 56X96X1.80
D18: Cantidad | E18: Unidad
A19: PESO TOTAL OBTENIDO | D19: 4800 | E19: g | F19: Tiempo de Horneo: | J19: =5000/530 -> 9.4339623
A20: TIEMPO TOTAL DE PREPARACION | D20: 10 | E20: min | F20: Horno:
A21: CANTIDAD DE PORCIONES OBTENIDAS | D21: 1 | E21: tanda | F21: Temperatura de Horneo:
A22: PESO DE CADA PORCIÓN | D22: 4800 | E22: g | F22: Otros
A23: MERMA | D23: =SUM(E10:E10)-D19 -> 200 | E23: g
A24: PROCEDIMIENTO DE PREPARACION DE LA RECETA
A25: 1,Colocar en un sarten el mani, hasta que comience a tostarse. (No dejar que se queme)
A26: 2, Endriar y empacar.
A28: CONTROL DE CAMBIOS

Sheet Costo Choco Mani y arroz inf
E1: Precio Local | F1: Costo MP | G1: Costo EM | H1: Costo MO
E2: =IFERROR(O62,"") -> 6265.2144 | F2: =IFERROR(H53,"") -> 5740 | G2: =IFERROR(H54,"") -> 29.63 | H2: =IFERROR(H56,"") -> 238.5
A5: ESTRUCTURA DE COSTOS
F6: Fecha: | H6: =TODAY() -> 46148
A7: UNIDADES | B7: DESCRIPCION MAT.PRIMA | C7: UNIDADES | D7: UND MEDIDA | E7: COSTO UNITARIO | F7: TOTAL COSTO | G7: % PREC. DEFINIDO | H7: CODIGOS
A8: 750 | B8: Cobertura Chocolate Leche | C8: =+A8 -> 750 | D8: Gramos | E8: 6.23 | F8: =IFERROR(C8*E8,"") -> 4672.5 | G8: =IFERROR(F8/$F$66,"") -> 0.76405093 | H8: MP10001
A9: 125 | B9: Arroz Inflado | C9: =+A9 -> 125 | D9: Gramos | E9: 3.82 | F9: =IFERROR(C9*E9,"") -> 477.5 | G9: =IFERROR(F9/$F$66,"") -> 0.078081182 | H9: NUEVO
B10: =IFERROR(VLOOKUP(H10,'[1]Consolidado MP Planta'!$A$2:$M$823,3,0),"") | C10: =+A10 -> 0 | D10: =IFERROR(VLOOKUP(H10,'[1]Consolidado MP Planta'!$A$2:$M$823,13,0),"") | E10: =IFERROR(VLOOKUP(H10,'[1]Consolidado MP Planta'!$A$2:$M$823,12,0),"") | F10: =IFERROR(C10*E10,"") | G10: =IFERROR(F10/$F$66,"")
B11: =IFERROR(VLOOKUP(H11,'[1]Consolidado MP Planta'!$A$2:$M$823,3,0),"") | C11: =+A11 -> 0 | D11: =IFERROR(VLOOKUP(H11,'[1]Consolidado MP Planta'!$A$2:$M$823,13,0),"") | E11: =IFERROR(VLOOKUP(H11,'[1]Consolidado MP Planta'!$A$2:$M$823,12,0),"") | F11: =IFERROR(C11*E11,"") | G11: =IFERROR(F11/$F$66,"")
B12: =IFERROR(VLOOKUP(H12,'[1]Consolidado MP Planta'!$A$2:$M$823,3,0),"") | C12: =+A12 -> 0 | D12: =IFERROR(VLOOKUP(H12,'[1]Consolidado MP Planta'!$A$2:$M$823,13,0),"") | E12: =IFERROR(VLOOKUP(H12,'[1]Consolidado MP Planta'!$A$2:$M$823,12,0),"") | F12: =IFERROR(C12*E12,"") | G12: =IFERROR(F12/$F$66,"")
B13: =IFERROR(VLOOKUP(H13,'[1]Consolidado MP Planta'!$A$2:$M$823,3,0),"") | C13: =+A13 -> 0 | D13: =IFERROR(VLOOKUP(H13,'[1]Consolidado MP Planta'!$A$2:$M$823,13,0),"") | E13: =IFERROR(VLOOKUP(H13,'[1]Consolidado MP Planta'!$A$2:$M$823,12,0),"") | F13: =IFERROR(C13*E13,"") | G13: =IFERROR(F13/$F$66,"")
B14: =IFERROR(VLOOKUP(H14,'[1]Consolidado MP Planta'!$A$2:$M$823,3,0),"") | C14: =+A14 -> 0 | D14: =IFERROR(VLOOKUP(H14,'[1]Consolidado MP Planta'!$A$2:$M$823,13,0),"") | E14: =IFERROR(VLOOKUP(H14,'[1]Consolidado MP Planta'!$A$2:$M$823,12,0),"") | F14: =IFERROR(C14*E14,"") | G14: =IFERROR(F14/$F$66,"")
B15: =IFERROR(VLOOKUP(H15,[2]Hoja2!$A$2:$G$589,2,0),"")
A16: UNIDADES | B16: MATERIA PRIMA SEMIELABORADOS | C16: UNIDADES | D16: UND MEDIDA | E16: COSTO UNITARIO | F16: TOTAL COSTO | G16: % PREC. DEFINIDO | H16: CODIGOS
A17: 250 | B17: Mani Tostado | C17: =+A17 -> 250 | D17: Gramos | E17: 2.36 | F17: =IFERROR(E17*C17,"") -> 590 | G17: =IFERROR(F17/$F$66,"") -> 0.096477271 | H17: se00820
B18: =IFERROR(VLOOKUP(H18,[1]SEMIELABORADOS!$A$2:$M$6000,2,0),"") | C18: =+A18 -> 0 | D18: =IFERROR(VLOOKUP(H18,[1]SEMIELABORADOS!$A$2:$M$6000,6,0),"") | E18: =IFERROR(VLOOKUP(H18,[1]SEMIELABORADOS!$A$2:$H$65536,8,0),"") | F18: =IFERROR(E18*C18,"") | G18: =IFERROR(F18/$F$66,"")
B19: =IFERROR(VLOOKUP(H19,[1]SEMIELABORADOS!$A$2:$M$6000,2,0),"") | C19: =+A19 -> 0 | D19: =IFERROR(VLOOKUP(H19,[1]SEMIELABORADOS!$A$2:$M$6000,6,0),"") | E19: =IFERROR(VLOOKUP(H19,[1]SEMIELABORADOS!$A$2:$H$65536,8,0),"") | F19: =IFERROR(E19*C19,"") | G19: =IFERROR(F19/$F$66,"")
B20: =IFERROR(VLOOKUP(H20,[1]SEMIELABORADOS!$A$2:$M$6000,2,0),"") | C20: =+A20 -> 0 | D20: =IFERROR(VLOOKUP(H20,[1]SEMIELABORADOS!$A$2:$M$6000,6,0),"") | E20: =IFERROR(VLOOKUP(H20,[1]SEMIELABORADOS!$A$2:$H$65536,8,0),"") | F20: =IFERROR(E20*C20,"") | G20: =IFERROR(F20/$F$66,"")
B21: =IFERROR(VLOOKUP(H21,[1]SEMIELABORADOS!$A$2:$M$6000,2,0),"") | C21: =+A21 -> 0 | D21: =IFERROR(VLOOKUP(H21,[1]SEMIELABORADOS!$A$2:$M$6000,6,0),"") | E21: =IFERROR(VLOOKUP(H21,[1]SEMIELABORADOS!$A$2:$H$65536,8,0),"") | F21: =IFERROR(E21*C21,"") | G21: =IFERROR(F21/$F$66,"")
B22: =IFERROR(VLOOKUP(H22,[1]SEMIELABORADOS!$A$2:$M$6000,2,0),"") | C22: =+A22 -> 0 | D22: =IFERROR(VLOOKUP(H22,[1]SEMIELABORADOS!$A$2:$M$6000,6,0),"") | E22: =IFERROR(VLOOKUP(H22,[1]SEMIELABORADOS!$A$2:$H$65536,8,0),"") | F22: =IFERROR(E22*C22,"") | G22: =IFERROR(F22/$F$66,"")
B23: =IFERROR(VLOOKUP(H23,[1]SEMIELABORADOS!$A$2:$M$6000,2,0),"") | C23: =+A23 -> 0 | D23: =IFERROR(VLOOKUP(H23,[1]SEMIELABORADOS!$A$2:$M$6000,6,0),"") | E23: =IFERROR(VLOOKUP(H23,[1]SEMIELABORADOS!$A$2:$H$65536,8,0),"") | F23: =IFERROR(E23*C23,"") | G23: =IFERROR(F23/$F$66,"")
B24: =IFERROR(VLOOKUP(H24,[1]SEMIELABORADOS!$A$2:$M$6000,2,0),"") | C24: =+A24 -> 0 | D24: =IFERROR(VLOOKUP(H24,[1]SEMIELABORADOS!$A$2:$M$6000,6,0),"") | E24: =IFERROR(VLOOKUP(H24,[1]SEMIELABORADOS!$A$2:$H$65536,8,0),"") | F24: =IFERROR(E24*C24,"") | G24: =IFERROR(F24/$F$66,"")
A26: UNIDADES | B26: EMPAQUE | C26: UNIDADES | D26: UND MEDIDA | E26: COSTO UNITARIO | F26: TOTAL COSTO | G26: % PREC. DEFINIDO | H26: CODIGOS
A27: 1 | B27: ETIQUETA BLANCA 2 5/8X1 15/16 (UND) | C27: =+A27 -> 1 | D27: UND | E27: 2.13 | F27: =IFERROR(C27*E27,"") -> 2.13 | G27: =IFERROR(F27/$F$66,"") -> 0.0003482993 | H27: EM10011
A28: 1 | B28: BOLSA 17x25 TRANSP KILO | C28: =+A28 -> 1 | D28: UND | E28: 25 | F28: =IFERROR(C28*E28,"") -> 25 | G28: =IFERROR(F28/$F$66,"") -> 0.00408802 | H28: EM10013
B29: =IFERROR(VLOOKUP(H29,'[1]Consolidado MP Planta'!$A$2:$M$823,3,0),"") | C29: =+A29 -> 0 | D29: =IFERROR(VLOOKUP(H29,'[1]Consolidado MP Planta'!$A$2:$M$823,13,0),"") | E29: =IFERROR(VLOOKUP(H29,'[1]Consolidado MP Planta'!$A$2:$M$823,12,0),"") | F29: =IFERROR(C29*E29,"") | G29: =IFERROR(F29/$F$66,"")
B30: =IFERROR(VLOOKUP(H30,'[1]Consolidado MP Planta'!$A$2:$M$823,3,0),"") | C30: =+A30 -> 0 | D30: =IFERROR(VLOOKUP(H30,'[1]Consolidado MP Planta'!$A$2:$M$823,13,0),"") | E30: =IFERROR(VLOOKUP(H30,'[1]Consolidado MP Planta'!$A$2:$M$823,12,0),"") | F30: =IFERROR(C30*E30,"") | G30: =IFERROR(F30/$F$66,"")
B31: =IFERROR(VLOOKUP(H31,'[1]Consolidado MP Planta'!$A$2:$M$823,3,0),"") | C31: =+A31 -> 0 | D31: =IFERROR(VLOOKUP(H31,'[1]Consolidado MP Planta'!$A$2:$M$823,13,0),"") | E31: =IFERROR(VLOOKUP(H31,'[1]Consolidado MP Planta'!$A$2:$M$823,12,0),"") | F31: =IFERROR(C31*E31,"") | G31: =IFERROR(F31/$F$66,"")
B32: =IFERROR(VLOOKUP(H32,'[1]Consolidado MP Planta'!$A$2:$M$823,3,0),"") | C32: =+A32 -> 0 | D32: =IFERROR(VLOOKUP(H32,'[1]Consolidado MP Planta'!$A$2:$M$823,13,0),"") | E32: =IFERROR(VLOOKUP(H32,'[1]Consolidado MP Planta'!$A$2:$M$823,12,0),"") | F32: =IFERROR(C32*E32,"") | G32: =IFERROR(F32/$F$66,"")
A34: UNIDADES | B34: EMPAQUE SEMIELABORADOS | C34: UNIDADES | D34: UND MEDIDA | E34: COSTO UNITARIO | F34: TOTAL COSTO | G34: % PREC. DEFINIDO | H34: CODIGOS
A35: =+A17 -> 250 | B35: Mani Tostado | C35: =+A35 -> 250 | D35: Gramos | E35: 0.01 | F35: =IFERROR(E35*C35,"") -> 2.5 | G35: =IFERROR(F35/$F$66,"") -> 0.000408802 | H35: se00820
A36: =+A18 -> 0 | B36: =IFERROR(VLOOKUP(H36,[1]SEMIELABORADOS!$A$2:$M$6000,2,0),"") | C36: =+A36 -> 0 | D36: =IFERROR(VLOOKUP(H36,[1]SEMIELABORADOS!$A$2:$M$6000,6,0),"") | E36: =IFERROR(VLOOKUP(H36,[1]SEMIELABORADOS!$A$2:$M$65536,10,0),"") | F36: =IFERROR(E36*C36,"") | G36: =IFERROR(F36/$F$66,"")
A37: =+A19 -> 0 | B37: =IFERROR(VLOOKUP(H37,[1]SEMIELABORADOS!$A$2:$M$6000,2,0),"") | C37: =+A37 -> 0 | D37: =IFERROR(VLOOKUP(H37,[1]SEMIELABORADOS!$A$2:$M$6000,6,0),"") | E37: =IFERROR(VLOOKUP(H37,[1]SEMIELABORADOS!$A$2:$M$65536,10,0),"") | F37: =IFERROR(E37*C37,"") | G37: =IFERROR(F37/$F$66,"")
A38: =+A20 -> 0 | B38: =IFERROR(VLOOKUP(H38,[1]SEMIELABORADOS!$A$2:$M$6000,2,0),"") | C38: =+A38 -> 0 | D38: =IFERROR(VLOOKUP(H38,[1]SEMIELABORADOS!$A$2:$M$6000,6,0),"") | E38: =IFERROR(VLOOKUP(H38,[1]SEMIELABORADOS!$A$2:$M$65536,10,0),"") | F38: =IFERROR(E38*C38,"") | G38: =IFERROR(F38/$F$66,"")
A39: =+A21 -> 0 | B39: =IFERROR(VLOOKUP(H39,[1]SEMIELABORADOS!$A$2:$M$6000,2,0),"") | C39: =+A39 -> 0 | D39: =IFERROR(VLOOKUP(H39,[1]SEMIELABORADOS!$A$2:$M$6000,6,0),"") | E39: =IFERROR(VLOOKUP(H39,[1]SEMIELABORADOS!$A$2:$M$65536,10,0),"") | F39: =IFERROR(E39*C39,"") | G39: =IFERROR(F39/$F$66,"")
A40: =+A22 -> 0 | B40: =IFERROR(VLOOKUP(H40,[1]SEMIELABORADOS!$A$2:$M$6000,2,0),"") | C40: =+A40 -> 0 | D40: =IFERROR(VLOOKUP(H40,[1]SEMIELABORADOS!$A$2:$M$6000,6,0),"") | E40: =IFERROR(VLOOKUP(H40,[1]SEMIELABORADOS!$A$2:$M$65536,10,0),"") | F40: =IFERROR(E40*C40,"") | G40: =IFERROR(F40/$F$66,"")
A41: =+A23 -> 0 | B41: =IFERROR(VLOOKUP(H41,[1]SEMIELABORADOS!$A$2:$M$6000,2,0),"") | C41: =+A41 -> 0 | D41: =IFERROR(VLOOKUP(H41,[1]SEMIELABORADOS!$A$2:$M$6000,6,0),"") | E41: =IFERROR(VLOOKUP(H41,[1]SEMIELABORADOS!$A$2:$M$65536,10,0),"") | F41: =IFERROR(E41*C41,"") | G41: =IFERROR(F41/$F$66,"")
A43: UNIDADES | B43: MODI | C43: UNIDADES | D43: UND MEDIDA | E43: COSTO UNITARIO | F43: TOTAL COSTO | G43: % PREC. DEFINIDO | H43: CODIGOS
A44: =+A35 -> 250 | B44: Mani Tostado | C44: =+A44 -> 250 | D44: Gramos | E44: 0.03 | F44: =IFERROR(E44*C44,"") -> 7.5 | G44: =IFERROR(F44/$F$66,"") -> 0.001226406 | H44: se00820
A45: =+A36 -> 0 | B45: =IFERROR(VLOOKUP(H45,[1]SEMIELABORADOS!$A$2:$M$6000,2,0),"") | C45: =+A45 -> 0 | D45: =IFERROR(VLOOKUP(H45,[1]SEMIELABORADOS!$A$2:$M$6000,6,0),"") | E45: =IFERROR(VLOOKUP(H45,[1]SEMIELABORADOS!$A$2:$M$65536,12,0),"") | F45: =IFERROR(E45*C45,"") | G45: =IFERROR(F45/$F$66,"")
...

Sheet Costo Procesado
E1: Precio Local | F1: Costo MP | G1: Costo EM | H1: Costo MO
E2: =IFERROR(O62,"") -> 6932.3444 | F2: =IFERROR(H53,"") -> 5740 | G2: =IFERROR(H54,"") -> 56.76 | H2: =IFERROR(H56,"") -> 546.5
A5: ESTRUCTURA DE COSTOS
F6: Fecha: | H6: =TODAY() -> 46148
A7: UNIDADES | B7: DESCRIPCION MAT.PRIMA | C7: UNIDADES | D7: UND MEDIDA | E7: COSTO UNITARIO | F7: TOTAL COSTO | G7: % PREC. DEFINIDO | H7: CODIGOS
C8: =+A8 -> 0 | E8: =IFERROR(VLOOKUP(H8,'[1]Consolidado MP Planta'!$A$2:$M$823,12,0),"") | F8: =IFERROR(C8*E8,"") | G8: =IFERROR(F8/$F$66,"")
B9: =IFERROR(VLOOKUP(H9,'[1]Consolidado MP Planta'!$A$2:$M$823,3,0),"") | C9: =+A9 -> 0 | D9: =IFERROR(VLOOKUP(H9,'[1]Consolidado MP Planta'!$A$2:$M$823,13,0),"") | E9: =IFERROR(VLOOKUP(H9,'[1]Consolidado MP Planta'!$A$2:$M$823,12,0),"") | F9: =IFERROR(C9*E9,"") | G9: =IFERROR(F9/$F$66,"")
B10: =IFERROR(VLOOKUP(H10,'[1]Consolidado MP Planta'!$A$2:$M$823,3,0),"") | C10: =+A10 -> 0 | D10: =IFERROR(VLOOKUP(H10,'[1]Consolidado MP Planta'!$A$2:$M$823,13,0),"") | E10: =IFERROR(VLOOKUP(H10,'[1]Consolidado MP Planta'!$A$2:$M$823,12,0),"") | F10: =IFERROR(C10*E10,"") | G10: =IFERROR(F10/$F$66,"")
B11: =IFERROR(VLOOKUP(H11,'[1]Consolidado MP Planta'!$A$2:$M$823,3,0),"") | C11: =+A11 -> 0 | D11: =IFERROR(VLOOKUP(H11,'[1]Consolidado MP Planta'!$A$2:$M$823,13,0),"") | E11: =IFERROR(VLOOKUP(H11,'[1]Consolidado MP Planta'!$A$2:$M$823,12,0),"") | F11: =IFERROR(C11*E11,"") | G11: =IFERROR(F11/$F$66,"")
B12: =IFERROR(VLOOKUP(H12,'[1]Consolidado MP Planta'!$A$2:$M$823,3,0),"") | C12: =+A12 -> 0 | D12: =IFERROR(VLOOKUP(H12,'[1]Consolidado MP Planta'!$A$2:$M$823,13,0),"") | E12: =IFERROR(VLOOKUP(H12,'[1]Consolidado MP Planta'!$A$2:$M$823,12,0),"") | F12: =IFERROR(C12*E12,"") | G12: =IFERROR(F12/$F$66,"")
B13: =IFERROR(VLOOKUP(H13,'[1]Consolidado MP Planta'!$A$2:$M$823,3,0),"") | C13: =+A13 -> 0 | D13: =IFERROR(VLOOKUP(H13,'[1]Consolidado MP Planta'!$A$2:$M$823,13,0),"") | E13: =IFERROR(VLOOKUP(H13,'[1]Consolidado MP Planta'!$A$2:$M$823,12,0),"") | F13: =IFERROR(C13*E13,"") | G13: =IFERROR(F13/$F$66,"")
B14: =IFERROR(VLOOKUP(H14,'[1]Consolidado MP Planta'!$A$2:$M$823,3,0),"") | C14: =+A14 -> 0 | D14: =IFERROR(VLOOKUP(H14,'[1]Consolidado MP Planta'!$A$2:$M$823,13,0),"") | E14: =IFERROR(VLOOKUP(H14,'[1]Consolidado MP Planta'!$A$2:$M$823,12,0),"") | F14: =IFERROR(C14*E14,"") | G14: =IFERROR(F14/$F$66,"")
B15: =IFERROR(VLOOKUP(H15,[2]Hoja2!$A$2:$G$589,2,0),"")
A16: UNIDADES | B16: MATERIA PRIMA SEMIELABORADOS | C16: UNIDADES | D16: UND MEDIDA | E16: COSTO UNITARIO | F16: TOTAL COSTO | G16: % PREC. DEFINIDO | H16: CODIGOS
A17: 1000 | B17: Chocolate con Mani y Arroz Inflado | C17: =+A17 -> 1000 | D17: Gramos | E17: =+'Costo Choco Mani y arroz inf'!E69 -> 5.74 | F17: =IFERROR(E17*C17,"") -> 5740 | G17: =IFERROR(F17/$F$66,"") -> 0.92289487 | H17: nuevo
B18: =IFERROR(VLOOKUP(H18,[1]SEMIELABORADOS!$A$2:$M$6000,2,0),"") | C18: =+A18 -> 0 | D18: =IFERROR(VLOOKUP(H18,[1]SEMIELABORADOS!$A$2:$M$6000,6,0),"") | E18: =IFERROR(VLOOKUP(H18,[1]SEMIELABORADOS!$A$2:$H$65536,8,0),"") | F18: =IFERROR(E18*C18,"") | G18: =IFERROR(F18/$F$66,"")
B19: =IFERROR(VLOOKUP(H19,[1]SEMIELABORADOS!$A$2:$M$6000,2,0),"") | C19: =+A19 -> 0 | D19: =IFERROR(VLOOKUP(H19,[1]SEMIELABORADOS!$A$2:$M$6000,6,0),"") | E19: =IFERROR(VLOOKUP(H19,[1]SEMIELABORADOS!$A$2:$H$65536,8,0),"") | F19: =IFERROR(E19*C19,"") | G19: =IFERROR(F19/$F$66,"")
B20: =IFERROR(VLOOKUP(H20,[1]SEMIELABORADOS!$A$2:$M$6000,2,0),"") | C20: =+A20 -> 0 | D20: =IFERROR(VLOOKUP(H20,[1]SEMIELABORADOS!$A$2:$M$6000,6,0),"") | E20: =IFERROR(VLOOKUP(H20,[1]SEMIELABORADOS!$A$2:$H$65536,8,0),"") | F20: =IFERROR(E20*C20,"") | G20: =IFERROR(F20/$F$66,"")
B21: =IFERROR(VLOOKUP(H21,[1]SEMIELABORADOS!$A$2:$M$6000,2,0),"") | C21: =+A21 -> 0 | D21: =IFERROR(VLOOKUP(H21,[1]SEMIELABORADOS!$A$2:$M$6000,6,0),"") | E21: =IFERROR(VLOOKUP(H21,[1]SEMIELABORADOS!$A$2:$H$65536,8,0),"") | F21: =IFERROR(E21*C21,"") | G21: =IFERROR(F21/$F$66,"")
B22: =IFERROR(VLOOKUP(H22,[1]SEMIELABORADOS!$A$2:$M$6000,2,0),"") | C22: =+A22 -> 0 | D22: =IFERROR(VLOOKUP(H22,[1]SEMIELABORADOS!$A$2:$M$6000,6,0),"") | E22: =IFERROR(VLOOKUP(H22,[1]SEMIELABORADOS!$A$2:$H$65536,8,0),"") | F22: =IFERROR(E22*C22,"") | G22: =IFERROR(F22/$F$66,"")
B23: =IFERROR(VLOOKUP(H23,[1]SEMIELABORADOS!$A$2:$M$6000,2,0),"") | C23: =+A23 -> 0 | D23: =IFERROR(VLOOKUP(H23,[1]SEMIELABORADOS!$A$2:$M$6000,6,0),"") | E23: =IFERROR(VLOOKUP(H23,[1]SEMIELABORADOS!$A$2:$H$65536,8,0),"") | F23: =IFERROR(E23*C23,"") | G23: =IFERROR(F23/$F$66,"")
B24: =IFERROR(VLOOKUP(H24,[1]SEMIELABORADOS!$A$2:$M$6000,2,0),"") | C24: =+A24 -> 0 | D24: =IFERROR(VLOOKUP(H24,[1]SEMIELABORADOS!$A$2:$M$6000,6,0),"") | E24: =IFERROR(VLOOKUP(H24,[1]SEMIELABORADOS!$A$2:$H$65536,8,0),"") | F24: =IFERROR(E24*C24,"") | G24: =IFERROR(F24/$F$66,"")
A26: UNIDADES | B26: EMPAQUE | C26: UNIDADES | D26: UND MEDIDA | E26: COSTO UNITARIO | F26: TOTAL COSTO | G26: % PREC. DEFINIDO | H26: CODIGOS
A27: 1 | B27: ETIQUETA BLANCA 2 5/8X1 15/16 (UND) | C27: =+A27 -> 1 | D27: UND | E27: 2.13 | F27: =IFERROR(C27*E27,"") -> 2.13 | G27: =IFERROR(F27/$F$66,"") -> 0.00034246796 | H27: EM10011
A28: 1 | B28: BOLSA 17x25 TRANSP KILO | C28: =+A28 -> 1 | D28: UND | E28: 25 | F28: =IFERROR(C28*E28,"") -> 25 | G28: =IFERROR(F28/$F$66,"") -> 0.0040195769 | H28: EM10013
B29: =IFERROR(VLOOKUP(H29,'[1]Consolidado MP Planta'!$A$2:$M$823,3,0),"") | C29: =+A29 -> 0 | D29: =IFERROR(VLOOKUP(H29,'[1]Consolidado MP Planta'!$A$2:$M$823,13,0),"") | E29: =IFERROR(VLOOKUP(H29,'[1]Consolidado MP Planta'!$A$2:$M$823,12,0),"") | F29: =IFERROR(C29*E29,"") | G29: =IFERROR(F29/$F$66,"")
B30: =IFERROR(VLOOKUP(H30,'[1]Consolidado MP Planta'!$A$2:$M$823,3,0),"") | C30: =+A30 -> 0 | D30: =IFERROR(VLOOKUP(H30,'[1]Consolidado MP Planta'!$A$2:$M$823,13,0),"") | E30: =IFERROR(VLOOKUP(H30,'[1]Consolidado MP Planta'!$A$2:$M$823,12,0),"") | F30: =IFERROR(C30*E30,"") | G30: =IFERROR(F30/$F$66,"")
B31: =IFERROR(VLOOKUP(H31,'[1]Consolidado MP Planta'!$A$2:$M$823,3,0),"") | C31: =+A31 -> 0 | D31: =IFERROR(VLOOKUP(H31,'[1]Consolidado MP Planta'!$A$2:$M$823,13,0),"") | E31: =IFERROR(VLOOKUP(H31,'[1]Consolidado MP Planta'!$A$2:$M$823,12,0),"") | F31: =IFERROR(C31*E31,"") | G31: =IFERROR(F31/$F$66,"")
B32: =IFERROR(VLOOKUP(H32,'[1]Consolidado MP Planta'!$A$2:$M$823,3,0),"") | C32: =+A32 -> 0 | D32: =IFERROR(VLOOKUP(H32,'[1]Consolidado MP Planta'!$A$2:$M$823,13,0),"") | E32: =IFERROR(VLOOKUP(H32,'[1]Consolidado MP Planta'!$A$2:$M$823,12,0),"") | F32: =IFERROR(C32*E32,"") | G32: =IFERROR(F32/$F$66,"")
A34: UNIDADES | B34: EMPAQUE SEMIELABORADOS | C34: UNIDADES | D34: UND MEDIDA | E34: COSTO UNITARIO | F34: TOTAL COSTO | G34: % PREC. DEFINIDO | H34: CODIGOS
A35: =+A17 -> 1000 | B35: Chocolate con Mani y Arroz Inflado | C35: =+A35 -> 1000 | D35: Gramos | E35: =+'Costo Choco Mani y arroz inf'!E76 -> 0.02963 | F35: =IFERROR(E35*C35,"") -> 29.63 | G35: =IFERROR(F35/$F$66,"") -> 0.0047640026 | H35: nuevo
A36: =+A18 -> 0 | B36: =IFERROR(VLOOKUP(H36,[1]SEMIELABORADOS!$A$2:$M$6000,2,0),"") | C36: =+A36 -> 0 | D36: =IFERROR(VLOOKUP(H36,[1]SEMIELABORADOS!$A$2:$M$6000,6,0),"") | E36: =IFERROR(VLOOKUP(H36,[1]SEMIELABORADOS!$A$2:$M$65536,10,0),"") | F36: =IFERROR(E36*C36,"") | G36: =IFERROR(F36/$F$66,"")
A37: =+A19 -> 0 | B37: =IFERROR(VLOOKUP(H37,[1]SEMIELABORADOS!$A$2:$M$6000,2,0),"") | C37: =+A37 -> 0 | D37: =IFERROR(VLOOKUP(H37,[1]SEMIELABORADOS!$A$2:$M$6000,6,0),"") | E37: =IFERROR(VLOOKUP(H37,[1]SEMIELABORADOS!$A$2:$M$65536,10,0),"") | F37: =IFERROR(E37*C37,"") | G37: =IFERROR(F37/$F$66,"")
A38: =+A20 -> 0 | B38: =IFERROR(VLOOKUP(H38,[1]SEMIELABORADOS!$A$2:$M$6000,2,0),"") | C38: =+A38 -> 0 | D38: =IFERROR(VLOOKUP(H38,[1]SEMIELABORADOS!$A$2:$M$6000,6,0),"") | E38: =IFERROR(VLOOKUP(H38,[1]SEMIELABORADOS!$A$2:$M$65536,10,0),"") | F38: =IFERROR(E38*C38,"") | G38: =IFERROR(F38/$F$66,"")
A39: =+A21 -> 0 | B39: =IFERROR(VLOOKUP(H39,[1]SEMIELABORADOS!$A$2:$M$6000,2,0),"") | C39: =+A39 -> 0 | D39: =IFERROR(VLOOKUP(H39,[1]SEMIELABORADOS!$A$2:$M$6000,6,0),"") | E39: =IFERROR(VLOOKUP(H39,[1]SEMIELABORADOS!$A$2:$M$65536,10,0),"") | F39: =IFERROR(E39*C39,"") | G39: =IFERROR(F39/$F$66,"")
