Workbook

Sheet Torta Zanahoria Local
C1: SERVICIOS DE PASTELERIA S.A. | H1: CÓDIGO:
C2: ESPECIFICACION DE RECETA | H2: REVISIÓN:
C3: Torta Zanahoria | H3: FECHA DE APROBACIÓN:
C4: Elaborado | D4: Mariela Barrantes Sánchez, Chef
C5: Aprobado | D5: Esteban Cartin, Gte Manufactura
A7: AREA QUE PRODUCE: | D7: Postre | G7: AREA QUE EMPACA: | I7: Postre
A8: # Código | B8: # Codigo Netsuite | C8: Descripción del ingrediente | D8: Marca | E8: Unidad Internacional | G8: Medida alternativa | I8: Costo - Referencia
E9: Cantidad | F9: Unidad medida | G9: Cantidad | H9: Unidad medida | I9: Colones
C10: ENSAMBLE
B11: NUEVO | C11: Rosquete Zanahoria 280g | D11: FAS | E11: 720 | F11: g | G11: 3 unidades
B12: SE00005 | C12: Almibar | D12: FAS | E12: 90 | F12: g | G12: 30g x capa
B13: SE00386 | C13: Trasvasado de leche condensada cocinada | D13: FAS | E13: 280 | F13: g | G13: 140g x capa | H13: 1/2 Taza
B14: NUEVO | C14: Relleno de Queso y Leche Condensada | D14: FAS | E14: 224 | F14: g | G14: 112g x capa | H14: 1/2 Taza
B15: NUEVO | C15: Procesado Pecana Tostada | D15: FAS | E15: 60 | F15: g | G15: 30g x capa | H15: 1/4 Taza
C19: DECORACION
A20: 910000018 | B20: SE00069 | C20: Crema Beidge | D20: FAS | E20: 150 | F20: g | H20: 1/3 Taza
B21: NUEVO | C21: Procesado Borrona de Zanahoria | D21: FAS | E21: 30 | F21: g
B22: NUEVO | C22: Relleno de Queso y Leche Condensada | D22: FAS | E22: 60 | F22: g
B23: NUEVO | C23: Procesado Pecana Tostada | D23: FAS | E23: 30 | F23: g | H23: 1/4 Taza
C25: EMPAQUE
B26: EM10025 | C26: ORLA CARTON 8" DORADA | E26: 1 | F26: ud
B27: NUEVA | C27: TAPA Y DOMO G50CT ALTA #9 | D27: ETIPLAST | E27: 1 | F27: ud
B28: EM10002 | C28: ETIQ.BLANCA 1 1/4 * 3/4 | D28: CEMUSA | E28: 2 | F28: ud
B29: EM10124 | C29: ETIQUETA BLANCA R-153 | D29: ETIPLAST | E29: 1 | F29: ud
B30: EM10011 | C30: ETIQUETA BLANCA 2 5/8X1 15/16 PRE BLANCA | D30: ETIPLAST | E30: 1 | F30: ud
D35: Cantidad | E35: Unidad
A36: PESO TOTAL OBTENIDO | D36: 1590 | E36: g
A37: TIEMPO TOTAL DE PREPARACION | D37: 7 | E37: min
A38: CANTIDAD DE PORCIONES OBTENIDAS | D38: 1 | E38: ud
A39: PESO DE CADA PORCIÓN | D39: 1590 | E39: g
A40: MERMA | D40: =SUM(E11:E23)-D36 -> 54 | E40: g
A41: PROCEDIMIENTO DE PREPARACION DE LA RECETA
A42: 1, Colocar 1 rosquete de Zanahoria humedecerlo con almibar, agregar trasvasado de leche condensada cocinada, relleno de queso y leche condensada y pecanas tostadas.
A43: 2, Colocar otro rosquete de Zanahoria humedecido con almibar, agregar otra capa de trasvasadade leche condensada cocinada, relleno de queso y leche condensada y pecanas tostadas.
A44: 3, Tapar con el ultimo rosquete de Zanahoria humedecido.
A45: 4, Encremar con la crema beige, dejando la parte superior sin crema, colocar la boronada de zanahoria en la parte inferior de la torta.
A46: 5, En la parte superior de la torta colocar el relleno de queso y leche condensada ralizando un estilo espejo y colocar los trozos pecana tostada en todo el borde.
A47: 6, Tapar y etiquetar.
A51: Control de cambios

Sheet Costo Torta Zanahoria 
E1: Precio Local | F1: Costo MP | G1: Costo EM | H1: Costo MO
E2: =IFERROR(O62,"") -> 7517.8866 | F2: =IFERROR(H53,"") -> 3982.2409 | G2: =IFERROR(H54,"") -> 816.85856 | H2: =IFERROR(H56,"") -> 1308.4163
A5: ESTRUCTURA DE COSTOS
F6: Fecha: | H6: =TODAY() -> 46063
A7: UNIDADES | B7: DESCRIPCION MAT.PRIMA | C7: UNIDADES | D7: UND MEDIDA | E7: COSTO UNITARIO | F7: TOTAL COSTO | G7: % PREC. DEFINIDO | H7: CODIGOS
B8: =IFERROR(VLOOKUP(H8,'[1]Consolidado MP Planta'!$A$2:$M$823,3,0),"") | C8: =+A8 -> 0 | D8: =IFERROR(VLOOKUP(H8,'[1]Consolidado MP Planta'!$A$2:$M$823,13,0),"") | E8: =IFERROR(VLOOKUP(H8,'[1]Consolidado MP Planta'!$A$2:$M$823,12,0),"") | F8: =IFERROR(C8*E8,"") | G8: =IFERROR(F8/$F$66,"")
B9: =IFERROR(VLOOKUP(H9,'[1]Consolidado MP Planta'!$A$2:$M$823,3,0),"") | C9: =+A9 -> 0 | D9: =IFERROR(VLOOKUP(H9,'[1]Consolidado MP Planta'!$A$2:$M$823,13,0),"") | E9: =IFERROR(VLOOKUP(H9,'[1]Consolidado MP Planta'!$A$2:$M$823,12,0),"") | F9: =IFERROR(C9*E9,"") | G9: =IFERROR(F9/$F$66,"")
B10: =IFERROR(VLOOKUP(H10,'[1]Consolidado MP Planta'!$A$2:$M$823,3,0),"") | C10: =+A10 -> 0 | D10: =IFERROR(VLOOKUP(H10,'[1]Consolidado MP Planta'!$A$2:$M$823,13,0),"") | E10: =IFERROR(VLOOKUP(H10,'[1]Consolidado MP Planta'!$A$2:$M$823,12,0),"") | F10: =IFERROR(C10*E10,"") | G10: =IFERROR(F10/$F$66,"")
B11: =IFERROR(VLOOKUP(H11,'[1]Consolidado MP Planta'!$A$2:$M$823,3,0),"") | C11: =+A11 -> 0 | D11: =IFERROR(VLOOKUP(H11,'[1]Consolidado MP Planta'!$A$2:$M$823,13,0),"") | E11: =IFERROR(VLOOKUP(H11,'[1]Consolidado MP Planta'!$A$2:$M$823,12,0),"") | F11: =IFERROR(C11*E11,"") | G11: =IFERROR(F11/$F$66,"")
B12: =IFERROR(VLOOKUP(H12,'[1]Consolidado MP Planta'!$A$2:$M$823,3,0),"") | C12: =+A12 -> 0 | D12: =IFERROR(VLOOKUP(H12,'[1]Consolidado MP Planta'!$A$2:$M$823,13,0),"") | E12: =IFERROR(VLOOKUP(H12,'[1]Consolidado MP Planta'!$A$2:$M$823,12,0),"") | F12: =IFERROR(C12*E12,"") | G12: =IFERROR(F12/$F$66,"")
B13: =IFERROR(VLOOKUP(H13,'[1]Consolidado MP Planta'!$A$2:$M$823,3,0),"") | C13: =+A13 -> 0 | D13: =IFERROR(VLOOKUP(H13,'[1]Consolidado MP Planta'!$A$2:$M$823,13,0),"") | E13: =IFERROR(VLOOKUP(H13,'[1]Consolidado MP Planta'!$A$2:$M$823,12,0),"") | F13: =IFERROR(C13*E13,"") | G13: =IFERROR(F13/$F$66,"")
B14: =IFERROR(VLOOKUP(H14,'[1]Consolidado MP Planta'!$A$2:$M$823,3,0),"") | C14: =+A14 -> 0 | D14: =IFERROR(VLOOKUP(H14,'[1]Consolidado MP Planta'!$A$2:$M$823,13,0),"") | E14: =IFERROR(VLOOKUP(H14,'[1]Consolidado MP Planta'!$A$2:$M$823,12,0),"") | F14: =IFERROR(C14*E14,"") | G14: =IFERROR(F14/$F$66,"")
B15: =IFERROR(VLOOKUP(H15,[2]Hoja2!$A$2:$G$589,2,0),"")
A16: UNIDADES | B16: MATERIA PRIMA SEMIELABORADOS | C16: UNIDADES | D16: UND MEDIDA | E16: COSTO UNITARIO | F16: TOTAL COSTO | G16: % PREC. DEFINIDO | H16: CODIGOS
A17: 3 | B17: Rosquete Zanahoria 280g | C17: =+A17 -> 3 | D17: UND | E17: =+'Costo Rosquete Zanahoria '!H53 -> 355.96 | F17: =IFERROR(E17*C17,"") -> 1067.88 | G17: =IFERROR(F17/$F$66,"") -> 0.19710786 | H17: Nuevo
A18: 90 | B18: Almibar | C18: =+A18 -> 90 | D18: Gramos | E18: 0.2 | F18: =IFERROR(E18*C18,"") -> 18 | G18: =IFERROR(F18/$F$66,"") -> 0.0033224159 | H18: SE00005
A19: 0 | B19: Trasvasado de leche condensada cocinada | C19: =+A19 -> 0 | D19: Gramos | E19: 1.96 | F19: =IFERROR(E19*C19,"") -> 0 | G19: =IFERROR(F19/$F$66,"") -> 0 | H19: SE00386
A20: 336 | B20: Relleno de Queso y Leche Condensada | C20: =+A20 -> 336 | D20: Gramos | E20: =+'costo relleno Queso '!E69 -> 2.9416718 | F20: =IFERROR(E20*C20,"") -> 988.40172 | G20: =IFERROR(F20/$F$66,"") -> 0.18243787 | H20: Nuevo
A21: 90 | B21: Procesado Pecana Tostada | C21: =+A21 -> 90 | D21: Gramos | E21: =+'costo procesado Pecana'!E69 -> 8.755102 | F21: =IFERROR(E21*C21,"") -> 787.95918 | G21: =IFERROR(F21/$F$66,"") -> 0.14544045 | H21: Nuevo
A22: 0 | B22: Crema Beidge | C22: =+A22 -> 0 | D22: Gramos | E22: 2.3 | F22: =IFERROR(E22*C22,"") -> 0 | G22: =IFERROR(F22/$F$66,"") -> 0 | H22: SE00069
A23: 560 | B23: Leche Cond Cocinada Loc | C23: =+A23 -> 560 | D23: Gramos | E23: 2 | F23: =IFERROR(E23*C23,"") -> 1120 | G23: =IFERROR(F23/$F$66,"") -> 0.2067281
B24: =IFERROR(VLOOKUP(H24,[1]SEMIELABORADOS!$A$2:$M$6000,2,0),"") | C24: =+A24 -> 0 | D24: =IFERROR(VLOOKUP(H24,[1]SEMIELABORADOS!$A$2:$M$6000,6,0),"") | E24: =IFERROR(VLOOKUP(H24,[1]SEMIELABORADOS!$A$2:$H$65536,8,0),"") | F24: =IFERROR(E24*C24,"") | G24: =IFERROR(F24/$F$66,"")
A26: UNIDADES | B26: EMPAQUE | C26: UNIDADES | D26: UND MEDIDA | E26: COSTO UNITARIO | F26: TOTAL COSTO | G26: % PREC. DEFINIDO | H26: CODIGOS
A27: 1 | B27: ORLA CARTON 8" DORADA | C27: =+A27 -> 1 | D27: UND | E27: 78 | F27: =IFERROR(C27*E27,"") -> 78 | G27: =IFERROR(F27/$F$66,"") -> 0.014397136 | H27: EM10025
A28: 1 | B28: TAPA Y DOMO G50CT ALTA #9 | C28: =+A28 -> 1 | D28: UND | E28: 470 | F28: =IFERROR(C28*E28,"") -> 470 | G28: =IFERROR(F28/$F$66,"") -> 0.086751972 | H28: EM10494
A29: 2 | B29: ETIQ.BLANCA 1 1/4 * 3/4 | C29: =+A29 -> 2 | D29: UND | E29: 0.58 | F29: =IFERROR(C29*E29,"") -> 1.16 | G29: =IFERROR(F29/$F$66,"") -> 0.00021411125 | H29: EM10002
A30: 1 | B30: ETIQUETA BLANCA R-153 | C30: =+A30 -> 1 | D30: UND | E30: 0.39 | F30: =IFERROR(C30*E30,"") -> 0.39 | G30: =IFERROR(F30/$F$66,"") -> 7.1985679e-05 | H30: EM10124
A31: 1 | B31: ETIQUETA BLANCA 2 5/8X1 15/16 PRE BLANCA | C31: =+A31 -> 1 | D31: UND | E31: 2.13 | F31: =IFERROR(C31*E31,"") -> 2.13 | G31: =IFERROR(F31/$F$66,"") -> 0.00039315255 | H31: EM10011
A32: 55 | B32: Acetato | C32: =+A32 -> 55 | D32: CM | E32: 4.15 | F32: =IFERROR(C32*E32,"") -> 228.25 | G32: =IFERROR(F32/$F$66,"") -> 0.04213008 | M32: =55+20 -> 75
M33: =+M32*4.15 -> 311.25
A34: UNIDADES | B34: EMPAQUE SEMIELABORADOS | C34: UNIDADES | D34: UND MEDIDA | E34: COSTO UNITARIO | F34: TOTAL COSTO | G34: % PREC. DEFINIDO | H34: CODIGOS | M34: =+M33-F32 -> 83
A35: =+A17 -> 3 | B35: Rosquete Zanahoria 280g | C35: =+A35 -> 3 | D35: UND | E35: =+'Costo Rosquete Zanahoria '!H54 -> 6.3692 | F35: =IFERROR(E35*C35,"") -> 19.1076 | G35: =IFERROR(F35/$F$66,"") -> 0.0035268553
A36: =+A18 -> 90 | B36: Almibar | C36: =+A36 -> 90 | D36: Gramos | E36: 0.01 | F36: =IFERROR(E36*C36,"") -> 0.9 | G36: =IFERROR(F36/$F$66,"") -> 0.0001661208 | H36: SE00005
A37: =+A19 -> 0 | B37: Trasvasado de leche condensada cocinada | C37: =+A37 -> 0 | D37: Gramos | E37: 0 | F37: =IFERROR(E37*C37,"") -> 0 | G37: =IFERROR(F37/$F$66,"") -> 0
A38: =+A20 -> 336 | B38: Relleno de Queso y Leche Condensada | C38: =+A38 -> 336 | D38: Gramos | E38: =+'costo relleno Queso '!E76 -> 0.00036 | F38: =IFERROR(E38*C38,"") -> 0.12096 | G38: =IFERROR(F38/$F$66,"") -> 2.2326635e-05
A39: =+A21 -> 90 | B39: Procesado Pecana Tostada | C39: =+A39 -> 90 | D39: Gramos | E39: =+'costo procesado Pecana'!E76 -> 0 | F39: =IFERROR(E39*C39,"") -> 0 | G39: =IFERROR(F39/$F$66,"") -> 0
A40: =+A22 -> 0 | B40: Crema Beidge | C40: =+A40 -> 0 | D40: Gramos | E40: 0 | F40: =IFERROR(E40*C40,"") -> 0 | G40: =IFERROR(F40/$F$66,"") -> 0
A41: =+A23 -> 560 | B41: Leche Cond Cocinada Loc | C41: =+A41 -> 560 | D41: Gramos | E41: 0.03 | F41: =IFERROR(E41*C41,"") -> 16.8 | G41: =IFERROR(F41/$F$66,"") -> 0.0031009215
A43: UNIDADES | B43: MODI | C43: UNIDADES | D43: UND MEDIDA | E43: COSTO UNITARIO | F43: TOTAL COSTO | G43: % PREC. DEFINIDO | H43: CODIGOS
A44: =+A35 -> 3 | B44: Rosquete Zanahoria 280g | C44: =+A44 -> 3 | D44: UND | E44: =+'Costo Rosquete Zanahoria '!H56 -> 69.04 | F44: =IFERROR(E44*C44,"") -> 207.12 | G44: =IFERROR(F44/$F$66,"") -> 0.038229933
...

Sheet Rosquete Zanahora 280g
C1: SERVICIOS DE PASTELERIA S.A. | H1: CÓDIGO:
C2: ESPECIFICACION DE RECETA | H2: REVISIÓN:
C3: Rosquete zanahoria 280g | H3: FECHA DE APROBACIÓN:
C4: Elaborado | D4: Mariela Barrantes Sánchez, Chef
C5: Aprobado | D5: Esteban Cartin, Gte Manufactura
A6: AREA QUE PRODUCE: | D6: Batidos | G6: AREA QUE EMPACA: | I6: Batidos
A7: # Código | B7: # Código Netsuite | C7: Descripción del ingrediente | D7: Marca | E7: Unidad Internacional | G7: Medida alternativa | I7: Costo - Referencia
E8: Cantidad | F8: Unidad medida | G8: Cantidad | H8: Unidad medida | I8: Colones
C9: Ensamble
B10: SE00577 | C10: BATIDO QUEQUE ZANAHORIA SPOON | D10: FAS | E10: 10500 | F10: g
C21: Decoración
C28: Empaque
A29: 902000019 | B29: SE00701 | C29: MEZCLA P/ENGRASE MOLDES KILO | D29: FAS | E29: 1300 | F29: g
A30: 1950928 | B30: AS00028 | C30: BOLSA TRANSPARENTE 56X96X1.80 KILO | D30: PLASTICOS P | E30: 6 | F30: ud
A31: 0702007 | B31: EM10004 | C31: ETIQ.FECHA VENCIMIENTO BLANCO (ROLLO) | D31: ETIPLAST | E31: 6 | F31: ud
A32: 0702069 | B32: EM10002 | C32: ETIQ.BLANCA 1 1/4 * 3/4 (UND) | D32: CEMUSA | E32: 6 | F32: ud
D38: Cantidad | E38: Unidad
A39: PESO TOTAL OBTENIDO | D39: 10500 | E39: g | F39: Tiempo de Horneo:
A40: TIEMPO TOTAL DE PREPARACION | D40: 29 | E40: min | F40: Horno:
A41: CANTIDAD DE PORCIONES OBTENIDAS | D41: =D39/D42 -> 37.5 | E41: ud | F41: Temperatura de Horneo:
A42: PESO DE CADA PORCIÓN | D42: 280 | E42: g | F42: Otros
A43: MERMA | D43: 0 | E43: g
A44: PROCEDIMIENTO DE PREPARACION DE LA RECETA
A45: 1.- Pesar 280g de mezcla en los moldes previamente engrasados.
A46: 2.- Hornear por Dicte 1 o 2 a 175°C por min
A47: 3.- Enfriar, desmoldar, colocar 22 rosquetes por lata, etiquetar con nombre y fecha de producción.
A55: CONTROL DE CAMBIOS

Sheet Batido QQ Zanahoria 
C1: SERVICIOS DE PASTELERIA S.A. | H1: CÓDIGO: | I1: ESP-RE-BAS-055
C2: ESPECIFICACION DE RECETA | H2: REVISIÓN: | I2: 01
C3: SE00577 Batido queque zanahoria spoon | H3: FECHA DE APROBACIÓN: | I3: 45619
C4: Elaborado | D4: Javier Tong, Chef
C5: Aprobado | D5: Esteban Cartin, Gte Manufactura
A6: AREA QUE PRODUCE: | D6: Batidos | G6: AREA QUE EMPACA: | I6: Batidos
A7: # Código | B7: # Código Netsuite | C7: Descripción del ingrediente | D7: Marca | E7: Unidad Internacional | G7: Medida alternativa | I7: Costo - Referencia
E8: Cantidad | F8: Unidad medida | G8: Cantidad | H8: Unidad medida | I8: Colones
C9: Ensamble
B10: SE00576 | C10: PRREMEZCLA ZANAHORIA SPOON | D10: FAS | E10: 5400 | F10: g
A11: 10100050 | B11: MP10002 | C11: ACEITE CAPULLO RBD | D11: CAPULLO | E11: 1170 | F11: g
A12: 1210482 | B12: MP10005 | C12: HUEVO LIQUIDO REFRIGERADO | D12: INNOVO | E12: 1300 | F12: g
A13: 118000004 | B13: MP10385 | C13: VAINILLA OSCURA | D13: MAYCA | E13: 65 | F13: g
A14: 0101240 | B14: MP10018 | C14: ZANAHORIA ENTERA | D14: PRESTO | E14: 2900 | F14: g
C21: Decoración
C28: Empaque
D38: Cantidad | E38: Unidad
A39: PESO TOTAL OBTENIDO | D39: 10500 | E39: g | F39: Tiempo de Horneo:
A40: TIEMPO TOTAL DE PREPARACION | D40: 8 | E40: min | F40: Horno:
A41: CANTIDAD DE PORCIONES OBTENIDAS | D41: 105 | E41: ud | F41: Temperatura de Horneo:
A42: PESO DE CADA PORCIÓN | D42: 100 | E42: g | F42: Otros
A43: MERMA | D43: 335 | E43: g
A44: PROCEDIMIENTO DE PREPARACION DE LA RECETA
A45: 1.- En la batidora colocar el huevo con los azucares y batir hasta que triplique su volumen.
A46: 2.- Luego en forma de hilo agregar el aceite hasta incorporar.
A47: 3.- Agregar la premezcla con la vianilla y la zanahoria.
A48: 4.- Dosificar de inmediato.
A55: CONTROL DE CAMBIOS

Sheet Costo Rosquete Zanahoria 
E1: Precio Local | F1: Costo MP | G1: Costo EM | H1: Costo MO
E2: =IFERROR(O62,"") -> 365.19839 | F2: =IFERROR(H53,"") -> 355.96 | G2: =IFERROR(H54,"") -> 6.3692 | H2: =IFERROR(H56,"") -> 69.04
A5: ESTRUCTURA DE COSTOS
F6: Fecha: | H6: =TODAY() -> 46063
A7: UNIDADES | B7: DESCRIPCION MAT.PRIMA | C7: UNIDADES | D7: UND MEDIDA | E7: COSTO UNITARIO | F7: TOTAL COSTO | G7: % PREC. DEFINIDO | H7: CODIGOS
B8: =IFERROR(VLOOKUP(H8,'[1]Consolidado MP Planta'!$A$2:$M$823,3,0),"") | C8: =+A8 -> 0 | D8: =IFERROR(VLOOKUP(H8,'[1]Consolidado MP Planta'!$A$2:$M$823,13,0),"") | E8: =IFERROR(VLOOKUP(H8,'[1]Consolidado MP Planta'!$A$2:$M$823,12,0),"") | F8: =IFERROR(C8*E8,"") | G8: =IFERROR(F8/$F$66,"")
B9: =IFERROR(VLOOKUP(H9,'[1]Consolidado MP Planta'!$A$2:$M$823,3,0),"") | C9: =+A9 -> 0 | D9: =IFERROR(VLOOKUP(H9,'[1]Consolidado MP Planta'!$A$2:$M$823,13,0),"") | E9: =IFERROR(VLOOKUP(H9,'[1]Consolidado MP Planta'!$A$2:$M$823,12,0),"") | F9: =IFERROR(C9*E9,"") | G9: =IFERROR(F9/$F$66,"")
B10: =IFERROR(VLOOKUP(H10,'[1]Consolidado MP Planta'!$A$2:$M$823,3,0),"") | C10: =+A10 -> 0 | D10: =IFERROR(VLOOKUP(H10,'[1]Consolidado MP Planta'!$A$2:$M$823,13,0),"") | E10: =IFERROR(VLOOKUP(H10,'[1]Consolidado MP Planta'!$A$2:$M$823,12,0),"") | F10: =IFERROR(C10*E10,"") | G10: =IFERROR(F10/$F$66,"")
B11: =IFERROR(VLOOKUP(H11,'[1]Consolidado MP Planta'!$A$2:$M$823,3,0),"") | C11: =+A11 -> 0 | D11: =IFERROR(VLOOKUP(H11,'[1]Consolidado MP Planta'!$A$2:$M$823,13,0),"") | E11: =IFERROR(VLOOKUP(H11,'[1]Consolidado MP Planta'!$A$2:$M$823,12,0),"") | F11: =IFERROR(C11*E11,"") | G11: =IFERROR(F11/$F$66,"")
B12: =IFERROR(VLOOKUP(H12,'[1]Consolidado MP Planta'!$A$2:$M$823,3,0),"") | C12: =+A12 -> 0 | D12: =IFERROR(VLOOKUP(H12,'[1]Consolidado MP Planta'!$A$2:$M$823,13,0),"") | E12: =IFERROR(VLOOKUP(H12,'[1]Consolidado MP Planta'!$A$2:$M$823,12,0),"") | F12: =IFERROR(C12*E12,"") | G12: =IFERROR(F12/$F$66,"")
B13: =IFERROR(VLOOKUP(H13,'[1]Consolidado MP Planta'!$A$2:$M$823,3,0),"") | C13: =+A13 -> 0 | D13: =IFERROR(VLOOKUP(H13,'[1]Consolidado MP Planta'!$A$2:$M$823,13,0),"") | E13: =IFERROR(VLOOKUP(H13,'[1]Consolidado MP Planta'!$A$2:$M$823,12,0),"") | F13: =IFERROR(C13*E13,"") | G13: =IFERROR(F13/$F$66,"")
B14: =IFERROR(VLOOKUP(H14,'[1]Consolidado MP Planta'!$A$2:$M$823,3,0),"") | C14: =+A14 -> 0 | D14: =IFERROR(VLOOKUP(H14,'[1]Consolidado MP Planta'!$A$2:$M$823,13,0),"") | E14: =IFERROR(VLOOKUP(H14,'[1]Consolidado MP Planta'!$A$2:$M$823,12,0),"") | F14: =IFERROR(C14*E14,"") | G14: =IFERROR(F14/$F$66,"")
B15: =IFERROR(VLOOKUP(H15,[2]Hoja2!$A$2:$G$589,2,0),"")
A16: UNIDADES | B16: MATERIA PRIMA SEMIELABORADOS | C16: UNIDADES | D16: UND MEDIDA | E16: COSTO UNITARIO | F16: TOTAL COSTO | G16: % PREC. DEFINIDO | H16: CODIGOS
A17: 10500 | B17: BATIDO QUEQUE ZANAHORIA SPOON | C17: =+A17 -> 10500 | D17: Gramos | E17: 1.57 | F17: =IFERROR(E17*C17,"") -> 16485 | G17: =IFERROR(F17/$F$66,"") -> 0.79616835 | H17: SE00577
A18: 1300 | B18: MEZCLA P/ENGRASE MOLDES KILO | C18: =+A18 -> 1300 | D18: Gramos | E18: 1.01 | F18: =IFERROR(E18*C18,"") -> 1313 | G18: =IFERROR(F18/$F$66,"") -> 0.063413348 | H18: SE00701
B19: =IFERROR(VLOOKUP(H19,[1]SEMIELABORADOS!$A$2:$M$6000,2,0),"") | C19: =+A19 -> 0 | D19: =IFERROR(VLOOKUP(H19,[1]SEMIELABORADOS!$A$2:$M$6000,6,0),"") | E19: =IFERROR(VLOOKUP(H19,[1]SEMIELABORADOS!$A$2:$H$65536,8,0),"") | F19: =IFERROR(E19*C19,"") | G19: =IFERROR(F19/$F$66,"")
B20: =IFERROR(VLOOKUP(H20,[1]SEMIELABORADOS!$A$2:$M$6000,2,0),"") | C20: =+A20 -> 0 | D20: =IFERROR(VLOOKUP(H20,[1]SEMIELABORADOS!$A$2:$M$6000,6,0),"") | E20: =IFERROR(VLOOKUP(H20,[1]SEMIELABORADOS!$A$2:$H$65536,8,0),"") | F20: =IFERROR(E20*C20,"") | G20: =IFERROR(F20/$F$66,"")
B21: =IFERROR(VLOOKUP(H21,[1]SEMIELABORADOS!$A$2:$M$6000,2,0),"") | C21: =+A21 -> 0 | D21: =IFERROR(VLOOKUP(H21,[1]SEMIELABORADOS!$A$2:$M$6000,6,0),"") | E21: =IFERROR(VLOOKUP(H21,[1]SEMIELABORADOS!$A$2:$H$65536,8,0),"") | F21: =IFERROR(E21*C21,"") | G21: =IFERROR(F21/$F$66,"")
B22: =IFERROR(VLOOKUP(H22,[1]SEMIELABORADOS!$A$2:$M$6000,2,0),"") | C22: =+A22 -> 0 | D22: =IFERROR(VLOOKUP(H22,[1]SEMIELABORADOS!$A$2:$M$6000,6,0),"") | E22: =IFERROR(VLOOKUP(H22,[1]SEMIELABORADOS!$A$2:$H$65536,8,0),"") | F22: =IFERROR(E22*C22,"") | G22: =IFERROR(F22/$F$66,"")
B23: =IFERROR(VLOOKUP(H23,[1]SEMIELABORADOS!$A$2:$M$6000,2,0),"") | C23: =+A23 -> 0 | D23: =IFERROR(VLOOKUP(H23,[1]SEMIELABORADOS!$A$2:$M$6000,6,0),"") | E23: =IFERROR(VLOOKUP(H23,[1]SEMIELABORADOS!$A$2:$H$65536,8,0),"") | F23: =IFERROR(E23*C23,"") | G23: =IFERROR(F23/$F$66,"")
B24: =IFERROR(VLOOKUP(H24,[1]SEMIELABORADOS!$A$2:$M$6000,2,0),"") | C24: =+A24 -> 0 | D24: =IFERROR(VLOOKUP(H24,[1]SEMIELABORADOS!$A$2:$M$6000,6,0),"") | E24: =IFERROR(VLOOKUP(H24,[1]SEMIELABORADOS!$A$2:$H$65536,8,0),"") | F24: =IFERROR(E24*C24,"") | G24: =IFERROR(F24/$F$66,"")
A26: UNIDADES | B26: EMPAQUE | C26: UNIDADES | D26: UND MEDIDA | E26: COSTO UNITARIO | F26: TOTAL COSTO | G26: % PREC. DEFINIDO | H26: CODIGOS
A27: 6 | B27: =IFERROR(VLOOKUP(H27,'[1]Consolidado MP Planta'!$A$2:$M$823,3,0),"") -> BOLSA TRANSPARENTE 56X96X1.80 KILO | C27: =+A27 -> 6 | D27: =IFERROR(VLOOKUP(H27,'[1]Consolidado MP Planta'!$A$2:$M$823,13,0),"") -> Und | E27: 50 | F27: =IFERROR(C27*E27,"") -> 300 | G27: =IFERROR(F27/$F$66,"") -> 0.01448896 | H27: 1950928
A28: 6 | B28: =IFERROR(VLOOKUP(H28,'[1]Consolidado MP Planta'!$A$2:$M$823,3,0),"") -> ETIQ.FECHA VENCIMIENTO BLANCO (ROLLO) | C28: =+A28 -> 6 | D28: =IFERROR(VLOOKUP(H28,'[1]Consolidado MP Planta'!$A$2:$M$823,13,0),"") -> Gramos | E28: 0.33 | F28: =IFERROR(C28*E28,"") -> 1.98 | G28: =IFERROR(F28/$F$66,"") -> 9.5627135e-05 | H28: 0702007
A29: 6 | B29: =IFERROR(VLOOKUP(H29,'[1]Consolidado MP Planta'!$A$2:$M$823,3,0),"") -> ETIQ.BLANCA 1 1/4 * 3/4 (UND) | C29: =+A29 -> 6 | D29: =IFERROR(VLOOKUP(H29,'[1]Consolidado MP Planta'!$A$2:$M$823,13,0),"") -> Und | E29: 0.58 | F29: =IFERROR(C29*E29,"") -> 3.48 | G29: =IFERROR(F29/$F$66,"") -> 0.00016807193 | H29: 0702069
B30: =IFERROR(VLOOKUP(H30,'[1]Consolidado MP Planta'!$A$2:$M$823,3,0),"") | C30: =+A30 -> 0 | D30: =IFERROR(VLOOKUP(H30,'[1]Consolidado MP Planta'!$A$2:$M$823,13,0),"") | E30: =IFERROR(VLOOKUP(H30,'[1]Consolidado MP Planta'!$A$2:$M$823,12,0),"") | F30: =IFERROR(C30*E30,"") | G30: =IFERROR(F30/$F$66,"")
B31: =IFERROR(VLOOKUP(H31,'[1]Consolidado MP Planta'!$A$2:$M$823,3,0),"") | C31: =+A31 -> 0 | D31: =IFERROR(VLOOKUP(H31,'[1]Consolidado MP Planta'!$A$2:$M$823,13,0),"") | E31: =IFERROR(VLOOKUP(H31,'[1]Consolidado MP Planta'!$A$2:$M$823,12,0),"") | F31: =IFERROR(C31*E31,"") | G31: =IFERROR(F31/$F$66,"")
B32: =IFERROR(VLOOKUP(H32,'[1]Consolidado MP Planta'!$A$2:$M$823,3,0),"") | C32: =+A32 -> 0 | D32: =IFERROR(VLOOKUP(H32,'[1]Consolidado MP Planta'!$A$2:$M$823,13,0),"") | E32: =IFERROR(VLOOKUP(H32,'[1]Consolidado MP Planta'!$A$2:$M$823,12,0),"") | F32: =IFERROR(C32*E32,"") | G32: =IFERROR(F32/$F$66,"")
A34: UNIDADES | B34: EMPAQUE SEMIELABORADOS | C34: UNIDADES | D34: UND MEDIDA | E34: COSTO UNITARIO | F34: TOTAL COSTO | G34: % PREC. DEFINIDO | H34: CODIGOS
A35: =+A17 -> 10500 | B35: BATIDO QUEQUE ZANAHORIA SPOON | C35: =+A35 -> 10500 | D35: Gramos | E35: 0 | F35: =IFERROR(E35*C35,"") -> 0 | G35: =IFERROR(F35/$F$66,"") -> 0 | H35: SE00577
A36: =+A18 -> 1300 | B36: MEZCLA P/ENGRASE MOLDES KILO | C36: =+A36 -> 1300 | D36: Gramos | E36: 0.01 | F36: =IFERROR(E36*C36,"") -> 13 | G36: =IFERROR(F36/$F$66,"") -> 0.00062785493 | H36: SE00701
A37: =+A19 -> 0 | B37: =IFERROR(VLOOKUP(H37,[1]SEMIELABORADOS!$A$2:$M$6000,2,0),"") | C37: =+A37 -> 0 | D37: =IFERROR(VLOOKUP(H37,[1]SEMIELABORADOS!$A$2:$M$6000,6,0),"") | E37: =IFERROR(VLOOKUP(H37,[1]SEMIELABORADOS!$A$2:$M$65536,10,0),"") | F37: =IFERROR(E37*C37,"") | G37: =IFERROR(F37/$F$66,"")
A38: =+A20 -> 0 | B38: =IFERROR(VLOOKUP(H38,[1]SEMIELABORADOS!$A$2:$M$6000,2,0),"") | C38: =+A38 -> 0 | D38: =IFERROR(VLOOKUP(H38,[1]SEMIELABORADOS!$A$2:$M$6000,6,0),"") | E38: =IFERROR(VLOOKUP(H38,[1]SEMIELABORADOS!$A$2:$M$65536,10,0),"") | F38: =IFERROR(E38*C38,"") | G38: =IFERROR(F38/$F$66,"")
A39: =+A21 -> 0 | B39: =IFERROR(VLOOKUP(H39,[1]SEMIELABORADOS!$A$2:$M$6000,2,0),"") | C39: =+A39 -> 0 | D39: =IFERROR(VLOOKUP(H39,[1]SEMIELABORADOS!$A$2:$M$6000,6,0),"") | E39: =IFERROR(VLOOKUP(H39,[1]SEMIELABORADOS!$A$2:$M$65536,10,0),"") | F39: =IFERROR(E39*C39,"") | G39: =IFERROR(F39/$F$66,"")
A40: =+A22 -> 0 | B40: =IFERROR(VLOOKUP(H40,[1]SEMIELABORADOS!$A$2:$M$6000,2,0),"") | C40: =+A40 -> 0 | D40: =IFERROR(VLOOKUP(H40,[1]SEMIELABORADOS!$A$2:$M$6000,6,0),"") | E40: =IFERROR(VLOOKUP(H40,[1]SEMIELABORADOS!$A$2:$M$65536,10,0),"") | F40: =IFERROR(E40*C40,"") | G40: =IFERROR(F40/$F$66,"")
A41: =+A23 -> 0 | B41: =IFERROR(VLOOKUP(H41,[1]SEMIELABORADOS!$A$2:$M$6000,2,0),"") | C41: =+A41 -> 0 | D41: =IFERROR(VLOOKUP(H41,[1]SEMIELABORADOS!$A$2:$M$6000,6,0),"") | E41: =IFERROR(VLOOKUP(H41,[1]SEMIELABORADOS!$A$2:$M$65536,10,0),"") | F41: =IFERROR(E41*C41,"") | G41: =IFERROR(F41/$F$66,"")
A43: UNIDADES | B43: MODI | C43: UNIDADES | D43: UND MEDIDA | E43: COSTO UNITARIO | F43: TOTAL COSTO | G43: % PREC. DEFINIDO | H43: CODIGOS
A44: =+A35 -> 10500 | B44: BATIDO QUEQUE ZANAHORIA SPOON | C44: =+A44 -> 10500 | D44: Gramos | E44: 0.1 | F44: =IFERROR(E44*C44,"") -> 1050 | G44: =IFERROR(F44/$F$66,"") -> 0.05071136 | H44: SE00577
A45: =+A36 -> 1300 | B45: MEZCLA P/ENGRASE MOLDES KILO | C45: =+A45 -> 1300 | D45: Gramos | E45: 0.13 | F45: =IFERROR(E45*C45,"") -> 169 | G45: =IFERROR(F45/$F$66,"") -> 0.0081621141 | H45: SE00701
...

Sheet Procesado Borona de Zanahoria
C1: SERVICIOS DE PASTELERIA S.A. | H1: CÓDIGO:
C2: ESPECIFICACION DE RECETA | H2: REVISIÓN:
C3: Procesado de Borona Zanahoria | H3: FECHA DE APROBACIÓN:
C4: Elaborado | D4: Javier Tong, Chef
C5: Aprobado | D5: Esteban Cartin, Gte Manufactura
A6: AREA QUE PRODUCE: | D6: Decoración | G6: AREA QUE EMPACA: | I6: Decoracion
A7: # Código | B7: # Código Netsuite | C7: Descripción del ingrediente | D7: Marca | E7: Unidad Internacional | G7: Medida alternativa | I7: Costo - Referencia
E8: Cantidad | F8: Unidad medida | G8: Cantidad | H8: Unidad medida | I8: Colones
C9: Ensamble
B10: NUEVO | C10: ROSQUETE ZANAHORIA 280g | D10: FAS | E10: =240*4.54 -> 1089.6 | F10: g | G10: 4 unidades
K15: =1000/D41 -> 1
C20: Decoración
C29: Empaque
A30: 512000003 | B30: EM10252 | C30: PLÁSTICO AUTOADERIBLE 1/ 12*2000 | D30: BELCA | E30: 40 | F30: cm
A31: 702123 | B31: EM10011 | C31: ETIQUETA BLANCA 2 5/8X1 15/16 (UND) | D31: CEMUSA | E31: 1 | F31: ud
A32: 702007 | B32: EM10004 | C32: ETIQ.FECHA VENCIMIENTO BLANCO (ROLLO) | D32: CEMUSA | E32: 1 | F32: ud
D40: Cantidad | E40: Unidad
A41: PESO TOTAL OBTENIDO | D41: 1000 | E41: g | F41: Tiempo de Horneo:
A42: TIEMPO TOTAL DE PREPARACION | D42: 7 | E42: min | F42: Horno:
A43: CANTIDAD DE PORCIONES OBTENIDAS | D43: 1 | E43: tanda | F43: Temperatura de Horneo:
A44: PESO DE CADA PORCIÓN | D44: 1000 | E44: g | F44: Otros
A45: MERMA | D45: =SUM(E10)-D41 -> 89.6 | E45: g
A46: PROCEDIMIENTO DE PREPARACION DE LA RECETA
A47: 1-. Colocar los rosquetes en una bandeja limpia, en pedazos y bien separados unos de otros
A48: 2-. Hornear por 25 minutos a 175°C en el Marshall o 20 minutos a 300°F en el Vulcan. Sacar y enfriar
A49: 3-. Colocar el producto en el procesador y procesar por impulsos hasta formar la borona o deshacer el rosquete
A50: 4-. Colocar en baldes sellados y sanitizados. No procesar grandes cantidades para evitar la formación de moho
A56: CONTROL DE CAMBIOS

Sheet Costo procesado Borona
E1: Precio Local | F1: Costo MP | G1: Costo EM | H1: Costo MO
E2: =IFERROR(O62,"") -> 3145.6171 | F2: =IFERROR(H53,"") -> 1423.84 | G2: =IFERROR(H54,"") -> 27.938133 | H2: =IFERROR(H56,"") -> 815.16
A5: ESTRUCTURA DE COSTOS
F6: Fecha: | H6: =TODAY() -> 46063
A7: UNIDADES | B7: DESCRIPCION MAT.PRIMA | C7: UNIDADES | D7: UND MEDIDA | E7: COSTO UNITARIO | F7: TOTAL COSTO | G7: % PREC. DEFINIDO | H7: CODIGOS
B8: =IFERROR(VLOOKUP(H8,'[1]Consolidado MP Planta'!$A$2:$M$823,3,0),"") | C8: =+A8 -> 0 | D8: =IFERROR(VLOOKUP(H8,'[1]Consolidado MP Planta'!$A$2:$M$823,13,0),"") | E8: =IFERROR(VLOOKUP(H8,'[1]Consolidado MP Planta'!$A$2:$M$823,12,0),"") | F8: =IFERROR(C8*E8,"") | G8: =IFERROR(F8/$F$66,"")
B9: =IFERROR(VLOOKUP(H9,'[1]Consolidado MP Planta'!$A$2:$M$823,3,0),"") | C9: =+A9 -> 0 | D9: =IFERROR(VLOOKUP(H9,'[1]Consolidado MP Planta'!$A$2:$M$823,13,0),"") | E9: =IFERROR(VLOOKUP(H9,'[1]Consolidado MP Planta'!$A$2:$M$823,12,0),"") | F9: =IFERROR(C9*E9,"") | G9: =IFERROR(F9/$F$66,"")
B10: =IFERROR(VLOOKUP(H10,'[1]Consolidado MP Planta'!$A$2:$M$823,3,0),"") | C10: =+A10 -> 0 | D10: =IFERROR(VLOOKUP(H10,'[1]Consolidado MP Planta'!$A$2:$M$823,13,0),"") | E10: =IFERROR(VLOOKUP(H10,'[1]Consolidado MP Planta'!$A$2:$M$823,12,0),"") | F10: =IFERROR(C10*E10,"") | G10: =IFERROR(F10/$F$66,"")
B11: =IFERROR(VLOOKUP(H11,'[1]Consolidado MP Planta'!$A$2:$M$823,3,0),"") | C11: =+A11 -> 0 | D11: =IFERROR(VLOOKUP(H11,'[1]Consolidado MP Planta'!$A$2:$M$823,13,0),"") | E11: =IFERROR(VLOOKUP(H11,'[1]Consolidado MP Planta'!$A$2:$M$823,12,0),"") | F11: =IFERROR(C11*E11,"") | G11: =IFERROR(F11/$F$66,"")
B12: =IFERROR(VLOOKUP(H12,'[1]Consolidado MP Planta'!$A$2:$M$823,3,0),"") | C12: =+A12 -> 0 | D12: =IFERROR(VLOOKUP(H12,'[1]Consolidado MP Planta'!$A$2:$M$823,13,0),"") | E12: =IFERROR(VLOOKUP(H12,'[1]Consolidado MP Planta'!$A$2:$M$823,12,0),"") | F12: =IFERROR(C12*E12,"") | G12: =IFERROR(F12/$F$66,"")
B13: =IFERROR(VLOOKUP(H13,'[1]Consolidado MP Planta'!$A$2:$M$823,3,0),"") | C13: =+A13 -> 0 | D13: =IFERROR(VLOOKUP(H13,'[1]Consolidado MP Planta'!$A$2:$M$823,13,0),"") | E13: =IFERROR(VLOOKUP(H13,'[1]Consolidado MP Planta'!$A$2:$M$823,12,0),"") | F13: =IFERROR(C13*E13,"") | G13: =IFERROR(F13/$F$66,"")
B14: =IFERROR(VLOOKUP(H14,'[1]Consolidado MP Planta'!$A$2:$M$823,3,0),"") | C14: =+A14 -> 0 | D14: =IFERROR(VLOOKUP(H14,'[1]Consolidado MP Planta'!$A$2:$M$823,13,0),"") | E14: =IFERROR(VLOOKUP(H14,'[1]Consolidado MP Planta'!$A$2:$M$823,12,0),"") | F14: =IFERROR(C14*E14,"") | G14: =IFERROR(F14/$F$66,"")
B15: =IFERROR(VLOOKUP(H15,[2]Hoja2!$A$2:$G$589,2,0),"")
A16: UNIDADES | B16: MATERIA PRIMA SEMIELABORADOS | C16: UNIDADES | D16: UND MEDIDA | E16: COSTO UNITARIO | F16: TOTAL COSTO | G16: % PREC. DEFINIDO | H16: CODIGOS
A17: 4 | B17: ROSQUETE ZANAHORIA 280g | C17: =+A17 -> 4 | D17: UND | E17: =+'Costo Rosquete Zanahoria '!H53 -> 355.96 | F17: =IFERROR(E17*C17,"") -> 1423.84 | G17: =IFERROR(F17/$F$66,"") -> 0.70513137 | H17: nuevo
B18: =IFERROR(VLOOKUP(H18,[1]SEMIELABORADOS!$A$2:$M$6000,2,0),"") | C18: =+A18 -> 0 | D18: =IFERROR(VLOOKUP(H18,[1]SEMIELABORADOS!$A$2:$M$6000,6,0),"") | E18: =IFERROR(VLOOKUP(H18,[1]SEMIELABORADOS!$A$2:$H$65536,8,0),"") | F18: =IFERROR(E18*C18,"") | G18: =IFERROR(F18/$F$66,"")
B19: =IFERROR(VLOOKUP(H19,[1]SEMIELABORADOS!$A$2:$M$6000,2,0),"") | C19: =+A19 -> 0 | D19: =IFERROR(VLOOKUP(H19,[1]SEMIELABORADOS!$A$2:$M$6000,6,0),"") | E19: =IFERROR(VLOOKUP(H19,[1]SEMIELABORADOS!$A$2:$H$65536,8,0),"") | F19: =IFERROR(E19*C19,"") | G19: =IFERROR(F19/$F$66,"")
B20: =IFERROR(VLOOKUP(H20,[1]SEMIELABORADOS!$A$2:$M$6000,2,0),"") | C20: =+A20 -> 0 | D20: =IFERROR(VLOOKUP(H20,[1]SEMIELABORADOS!$A$2:$M$6000,6,0),"") | E20: =IFERROR(VLOOKUP(H20,[1]SEMIELABORADOS!$A$2:$H$65536,8,0),"") | F20: =IFERROR(E20*C20,"") | G20: =IFERROR(F20/$F$66,"")
B21: =IFERROR(VLOOKUP(H21,[1]SEMIELABORADOS!$A$2:$M$6000,2,0),"") | C21: =+A21 -> 0 | D21: =IFERROR(VLOOKUP(H21,[1]SEMIELABORADOS!$A$2:$M$6000,6,0),"") | E21: =IFERROR(VLOOKUP(H21,[1]SEMIELABORADOS!$A$2:$H$65536,8,0),"") | F21: =IFERROR(E21*C21,"") | G21: =IFERROR(F21/$F$66,"")
B22: =IFERROR(VLOOKUP(H22,[1]SEMIELABORADOS!$A$2:$M$6000,2,0),"") | C22: =+A22 -> 0 | D22: =IFERROR(VLOOKUP(H22,[1]SEMIELABORADOS!$A$2:$M$6000,6,0),"") | E22: =IFERROR(VLOOKUP(H22,[1]SEMIELABORADOS!$A$2:$H$65536,8,0),"") | F22: =IFERROR(E22*C22,"") | G22: =IFERROR(F22/$F$66,"")
B23: =IFERROR(VLOOKUP(H23,[1]SEMIELABORADOS!$A$2:$M$6000,2,0),"") | C23: =+A23 -> 0 | D23: =IFERROR(VLOOKUP(H23,[1]SEMIELABORADOS!$A$2:$M$6000,6,0),"") | E23: =IFERROR(VLOOKUP(H23,[1]SEMIELABORADOS!$A$2:$H$65536,8,0),"") | F23: =IFERROR(E23*C23,"") | G23: =IFERROR(F23/$F$66,"")
B24: =IFERROR(VLOOKUP(H24,[1]SEMIELABORADOS!$A$2:$M$6000,2,0),"") | C24: =+A24 -> 0 | D24: =IFERROR(VLOOKUP(H24,[1]SEMIELABORADOS!$A$2:$M$6000,6,0),"") | E24: =IFERROR(VLOOKUP(H24,[1]SEMIELABORADOS!$A$2:$H$65536,8,0),"") | F24: =IFERROR(E24*C24,"") | G24: =IFERROR(F24/$F$66,"")
A26: UNIDADES | B26: EMPAQUE | C26: UNIDADES | D26: UND MEDIDA | E26: COSTO UNITARIO | F26: TOTAL COSTO | G26: % PREC. DEFINIDO | H26: CODIGOS
A27: 0 | B27: =IFERROR(VLOOKUP(H27,'[1]Consolidado MP Planta'!$A$2:$M$823,3,0),"") | C27: =+A27 -> 0 | D27: =IFERROR(VLOOKUP(H27,'[1]Consolidado MP Planta'!$A$2:$M$823,13,0),"") | E27: =IFERROR(VLOOKUP(H27,'[1]Consolidado MP Planta'!$A$2:$M$823,12,0),"") | F27: =IFERROR(C27*E27,"") | G27: =IFERROR(F27/$F$66,"")
A28: 1 | B28: =IFERROR(VLOOKUP(H28,'[1]Consolidado MP Planta'!$A$2:$M$823,3,0),"") -> ETIQUETA BLANCA 2 5/8X1 15/16 (UND) | C28: =+A28 -> 1 | D28: =IFERROR(VLOOKUP(H28,'[1]Consolidado MP Planta'!$A$2:$M$823,13,0),"") -> Und | E28: =IFERROR(VLOOKUP(H28,'[1]Consolidado MP Planta'!$A$2:$M$823,12,0),"") -> 2.128 | F28: =IFERROR(C28*E28,"") -> 2.128 | G28: =IFERROR(F28/$F$66,"") -> 0.0010538541 | H28: 0702123
A29: 1 | B29: =IFERROR(VLOOKUP(H29,'[1]Consolidado MP Planta'!$A$2:$M$823,3,0),"") -> ETIQ.FECHA VENCIMIENTO BLANCO (ROLLO) | C29: =+A29 -> 1 | D29: =IFERROR(VLOOKUP(H29,'[1]Consolidado MP Planta'!$A$2:$M$823,13,0),"") -> Gramos | E29: =IFERROR(VLOOKUP(H29,'[1]Consolidado MP Planta'!$A$2:$M$823,12,0),"") -> 0.33333333 | F29: =IFERROR(C29*E29,"") -> 0.33333333 | G29: =IFERROR(F29/$F$66,"") -> 0.00016507739 | H29: 0702007
B30: =IFERROR(VLOOKUP(H30,'[1]Consolidado MP Planta'!$A$2:$M$823,3,0),"") | C30: =+A30 -> 0 | D30: =IFERROR(VLOOKUP(H30,'[1]Consolidado MP Planta'!$A$2:$M$823,13,0),"") | E30: =IFERROR(VLOOKUP(H30,'[1]Consolidado MP Planta'!$A$2:$M$823,12,0),"") | F30: =IFERROR(C30*E30,"") | G30: =IFERROR(F30/$F$66,"")
B31: =IFERROR(VLOOKUP(H31,'[1]Consolidado MP Planta'!$A$2:$M$823,3,0),"") | C31: =+A31 -> 0 | D31: =IFERROR(VLOOKUP(H31,'[1]Consolidado MP Planta'!$A$2:$M$823,13,0),"") | E31: =IFERROR(VLOOKUP(H31,'[1]Consolidado MP Planta'!$A$2:$M$823,12,0),"") | F31: =IFERROR(C31*E31,"") | G31: =IFERROR(F31/$F$66,"")
B32: =IFERROR(VLOOKUP(H32,'[1]Consolidado MP Planta'!$A$2:$M$823,3,0),"") | C32: =+A32 -> 0 | D32: =IFERROR(VLOOKUP(H32,'[1]Consolidado MP Planta'!$A$2:$M$823,13,0),"") | E32: =IFERROR(VLOOKUP(H32,'[1]Consolidado MP Planta'!$A$2:$M$823,12,0),"") | F32: =IFERROR(C32*E32,"") | G32: =IFERROR(F32/$F$66,"")
A34: UNIDADES | B34: EMPAQUE SEMIELABORADOS | C34: UNIDADES | D34: UND MEDIDA | E34: COSTO UNITARIO | F34: TOTAL COSTO | G34: % PREC. DEFINIDO | H34: CODIGOS
A35: =+A17 -> 4 | B35: ROSQUETE ZANAHORIA 280g | C35: =+A35 -> 4 | D35: UND | E35: =+'Costo Rosquete Zanahoria '!H54 -> 6.3692 | F35: =IFERROR(E35*C35,"") -> 25.4768 | G35: =IFERROR(F35/$F$66,"") -> 0.012616931 | H35: nuevo
A36: =+A18 -> 0 | B36: =IFERROR(VLOOKUP(H36,[1]SEMIELABORADOS!$A$2:$M$6000,2,0),"") | C36: =+A36 -> 0 | D36: =IFERROR(VLOOKUP(H36,[1]SEMIELABORADOS!$A$2:$M$6000,6,0),"") | E36: =IFERROR(VLOOKUP(H36,[1]SEMIELABORADOS!$A$2:$M$65536,10,0),"") | F36: =IFERROR(E36*C36,"") | G36: =IFERROR(F36/$F$66,"")
A37: =+A19 -> 0 | B37: =IFERROR(VLOOKUP(H37,[1]SEMIELABORADOS!$A$2:$M$6000,2,0),"") | C37: =+A37 -> 0 | D37: =IFERROR(VLOOKUP(H37,[1]SEMIELABORADOS!$A$2:$M$6000,6,0),"") | E37: =IFERROR(VLOOKUP(H37,[1]SEMIELABORADOS!$A$2:$M$65536,10,0),"") | F37: =IFERROR(E37*C37,"") | G37: =IFERROR(F37/$F$66,"")
A38: =+A20 -> 0 | B38: =IFERROR(VLOOKUP(H38,[1]SEMIELABORADOS!$A$2:$M$6000,2,0),"") | C38: =+A38 -> 0 | D38: =IFERROR(VLOOKUP(H38,[1]SEMIELABORADOS!$A$2:$M$6000,6,0),"") | E38: =IFERROR(VLOOKUP(H38,[1]SEMIELABORADOS!$A$2:$M$65536,10,0),"") | F38: =IFERROR(E38*C38,"") | G38: =IFERROR(F38/$F$66,"")
A39: =+A21 -> 0 | B39: =IFERROR(VLOOKUP(H39,[1]SEMIELABORADOS!$A$2:$M$6000,2,0),"") | C39: =+A39 -> 0 | D39: =IFERROR(VLOOKUP(H39,[1]SEMIELABORADOS!$A$2:$M$6000,6,0),"") | E39: =IFERROR(VLOOKUP(H39,[1]SEMIELABORADOS!$A$2:$M$65536,10,0),"") | F39: =IFERROR(E39*C39,"") | G39: =IFERROR(F39/$F$66,"")
A40: =+A22 -> 0 | B40: =IFERROR(VLOOKUP(H40,[1]SEMIELABORADOS!$A$2:$M$6000,2,0),"") | C40: =+A40 -> 0 | D40: =IFERROR(VLOOKUP(H40,[1]SEMIELABORADOS!$A$2:$M$6000,6,0),"") | E40: =IFERROR(VLOOKUP(H40,[1]SEMIELABORADOS!$A$2:$M$65536,10,0),"") | F40: =IFERROR(E40*C40,"") | G40: =IFERROR(F40/$F$66,"")
A41: =+A23 -> 0 | B41: =IFERROR(VLOOKUP(H41,[1]SEMIELABORADOS!$A$2:$M$6000,2,0),"") | C41: =+A41 -> 0 | D41: =IFERROR(VLOOKUP(H41,[1]SEMIELABORADOS!$A$2:$M$6000,6,0),"") | E41: =IFERROR(VLOOKUP(H41,[1]SEMIELABORADOS!$A$2:$M$65536,10,0),"") | F41: =IFERROR(E41*C41,"") | G41: =IFERROR(F41/$F$66,"")
A43: UNIDADES | B43: MODI | C43: UNIDADES | D43: UND MEDIDA | E43: COSTO UNITARIO | F43: TOTAL COSTO | G43: % PREC. DEFINIDO | H43: CODIGOS
A44: =+A35 -> 4 | B44: ROSQUETE ZANAHORIA 280g | C44: =+A44 -> 4 | D44: UND | E44: =+'Costo Rosquete Zanahoria '!H56 -> 69.04 | F44: =IFERROR(E44*C44,"") -> 276.16 | G44: =IFERROR(F44/$F$66,"") -> 0.13676332 | H44: nuevo
A45: =+A36 -> 0 | B45: =IFERROR(VLOOKUP(H45,[1]SEMIELABORADOS!$A$2:$M$6000,2,0),"") | C45: =+A45 -> 0 | D45: =IFERROR(VLOOKUP(H45,[1]SEMIELABORADOS!$A$2:$M$6000,6,0),"") | E45: =IFERROR(VLOOKUP(H45,[1]SEMIELABORADOS!$A$2:$M$65536,12,0),"") | F45: =IFERROR(E45*C45,"") | G45: =IFERROR(F45/$F$66,"")
...

Sheet Premezcla QQ Zanahoria 
C1: SERVICIOS DE PASTELERIA S.A. | H1: CÓDIGO: | I1: ESP-RE-PRES-032
C2: ESPECIFICACION DE RECETA | H2: REVISIÓN: | I2: 01
C3: SE00576 Premezcla zanahoria spoon | H3: FECHA DE APROBACIÓN: | I3: 45617
C4: Elaborado | D4: Javier Tong, Chef
C5: Aprobado | D5: Esteban Cartin, Gte Manufactura
A6: AREA QUE PRODUCE: | D6: Premezclas | G6: AREA QUE EMPACA: | I6: Premezclas
A7: # Código | B7: # Código Netsuite | C7: Descripción del ingrediente | D7: Marca | E7: Unidad Internacional | G7: Medida alternativa | I7: Costo - Referencia
E8: Cantidad | F8: Unidad medida | G8: Cantidad | H8: Unidad medida | I8: Colones
C9: Ensamble
A10: 11200064 | B10: MP10051 | C10: HARINA TRIGO NACARINA | D10: NACARINA | E10: 2275 | F10: g
A11: 503000036 | B11: MP10085 | C11: BICARBONATO DE SODIO | D11: PASTELERO | E11: 50 | F11: g
A12: 10100046 | B12: MP10304 | C12: POLVO HORNEAR | D12: ROYAL | E12: 50 | F12: g
A13: 10100122 | B13: MP10096 | C13: CANELA EN POLVO | D13: BADIA | E13: 50 | F13: g
A14: 5000001 | B14: MP10027 | C14: SAL INDUSTRIAL | D14: ATLANTIDA | E14: 50 | F14: g
A15: 0512262 | B15: MP10566 | C15: PROPIANATO DE CALCIO | D15: CRYSTAL PRO | E15: 7 | F15: g
A16: 512261 | B16: MP10579 | C16: ACIDO SORBICO | D16: BEYCO | E16: 7 | F16: g
A18: 10100045 | B18: MP10075 | C18: AZUCAR CARAMELO | D18: ZUKRA | E18: 1100 | F18: g
A19: 510301 | B19: MP10074 | C19: AZUCAR BLANCO INDUSTRIAL | D19: MARIA | E19: 1100 | F19: g
A21: 11900028 | B21: MP10562 | C21: PECANA ENTERA | D21: NUECES IND | E21: 800 | F21: g
C24: Decoración
C32: Empaque
A33: 1950702 | B33: EM10016 | C33: BOLSA 12X18 TRANSPARENTE | D33: PLASTICOS P | E33: 1 | F33: ud
A34: 1950708 | B34: EM10013 | C34: BOLSA 17X25 TRANSPARENTE | D34: PLASTICOS P | E34: 2 | F34: ud
A35: 60100010 | B35: EM10133 | C35: ETIQUETA ROJA LETRA ALERGENO | D35: ETIPLAST | E35: 2 | F35: ud
A36: 0702123 | B36: EM10011 | C36: ETIQUETA BLANCA 2 5/8X1 15/16 | D36: ETIPLAST | E36: 2 | F36: ud
D45: Cantidad | E45: Unidad
A46: PESO TOTAL OBTENIDO | D46: 5400 | E46: g | F46: Tiempo de Horneo:
A47: TIEMPO TOTAL DE PREPARACION | D47: 4 | E47: min | F47: Horno:
A48: CANTIDAD DE PORCIONES OBTENIDAS | D48: 1 | E48: ud | F48: Temperatura de Horneo:
A49: PESO DE CADA PORCIÓN | D49: 5400 | E49: g | F49: Otros
A50: MERMA | D50: 89 | E50: g
A51: PROCEDIMIENTO DE PREPARACION DE LA RECETA
A52: 1.- Pesar en la bolsa 12x18 el harina, bicarbonato, polvo de hornear, canela, sal, propionato y acido sorbico.
A53: 2.- En una bolsa 17x25 pesar los azucares y en otra la pecana.
A54: 3.- Etiquetar
A56: CONTROL DE CAMBIOS

Sheet Pecana Tostada
C1: SERVICIOS DE PASTELERIA S.A. | H1: CÓDIGO: | I1: ESP-RE-POS-082
C2: ESPECIFICACION DE RECETA | H2: REVISIÓN: | I2: 06
C3: SE00707 PECANA TOSTADA | H3: FECHA DE APROBACIÓN: | I3: 45783
C4: Elaborado | D4: Javier Tong, Chef
C5: Aprobado | D5: Esteban Cartin, Gte Manufactura
A7: AREA QUE PRODUCE: | D7: Postres | G7: AREA QUE EMPACA: | I7: Postres
A8: # Código | B8: # Codigo Netsuite | C8: Descripción del ingrediente | D8: Marca | E8: Unidad Internacional | G8: Medida alternativa | I8: Costo - Referencia
E9: Cantidad | F9: Unidad medida | G9: Cantidad | H9: Unidad medida | I9: Colones
A10: MP10562 | B10: 11900028 | C10: Pecana Entera | D10: Nueces Industriales | E10: 10000 | F10: g
D16: Cantidad | E16: Unidad
A17: PESO TOTAL OBTENIDO | D17: 9800 | E17: g
A18: TIEMPO TOTAL DE PREPARACION | D18: 3 | E18: min
A19: CANTIDAD DE PORCIONES OBTENIDAS | D19: 1 | E19: ud
A20: PESO DE CADA PORCIÓN | D20: =+D17 -> 9800 | E20: g
A21: MERMA | D21: =SUM(E10:E15)-D17 -> 200 | E21: g
A22: PROCEDIMIENTO DE PREPARACION DE LA RECETA
A23: 1.- Colocar la pecana en bandejas y hornear por 5 min a 175°C.
A24: 2.- Enfriar y utilizar de inmediato
A32: Control de cambios
A33: 2, Correcciones post corridas
A34: 3, Cambio en procedimiento
A35: 4, Cambio de etiqueta Spoon
A36: 5, Se le quita etiqueta spooners y codigo QR
A37: 6, Cambio de manjar

Sheet costo procesado Pecana
E1: Precio Local | F1: Costo MP | G1: Costo EM | H1: Costo MO
E2: =IFERROR(O62,"") -> 10327.532 | F2: =IFERROR(H53,"") -> 8580 | G2: =IFERROR(H54,"") -> 0 | H2: =IFERROR(H56,"") -> 841
A5: ESTRUCTURA DE COSTOS
F6: Fecha: | H6: =TODAY() -> 46063
A7: UNIDADES | B7: DESCRIPCION MAT.PRIMA | C7: UNIDADES | D7: UND MEDIDA | E7: COSTO UNITARIO | F7: TOTAL COSTO | G7: % PREC. DEFINIDO | H7: CODIGOS
B8: =IFERROR(VLOOKUP(H8,'[1]Consolidado MP Planta'!$A$2:$M$823,3,0),"") | C8: =+A8 -> 0 | D8: =IFERROR(VLOOKUP(H8,'[1]Consolidado MP Planta'!$A$2:$M$823,13,0),"") | E8: =IFERROR(VLOOKUP(H8,'[1]Consolidado MP Planta'!$A$2:$M$823,12,0),"") | F8: =IFERROR(C8*E8,"") | G8: =IFERROR(F8/$F$66,"")
B9: =IFERROR(VLOOKUP(H9,'[1]Consolidado MP Planta'!$A$2:$M$823,3,0),"") | C9: =+A9 -> 0 | D9: =IFERROR(VLOOKUP(H9,'[1]Consolidado MP Planta'!$A$2:$M$823,13,0),"") | E9: =IFERROR(VLOOKUP(H9,'[1]Consolidado MP Planta'!$A$2:$M$823,12,0),"") | F9: =IFERROR(C9*E9,"") | G9: =IFERROR(F9/$F$66,"")
B10: =IFERROR(VLOOKUP(H10,'[1]Consolidado MP Planta'!$A$2:$M$823,3,0),"") | C10: =+A10 -> 0 | D10: =IFERROR(VLOOKUP(H10,'[1]Consolidado MP Planta'!$A$2:$M$823,13,0),"") | E10: =IFERROR(VLOOKUP(H10,'[1]Consolidado MP Planta'!$A$2:$M$823,12,0),"") | F10: =IFERROR(C10*E10,"") | G10: =IFERROR(F10/$F$66,"")
B11: =IFERROR(VLOOKUP(H11,'[1]Consolidado MP Planta'!$A$2:$M$823,3,0),"") | C11: =+A11 -> 0 | D11: =IFERROR(VLOOKUP(H11,'[1]Consolidado MP Planta'!$A$2:$M$823,13,0),"") | E11: =IFERROR(VLOOKUP(H11,'[1]Consolidado MP Planta'!$A$2:$M$823,12,0),"") | F11: =IFERROR(C11*E11,"") | G11: =IFERROR(F11/$F$66,"")
B12: =IFERROR(VLOOKUP(H12,'[1]Consolidado MP Planta'!$A$2:$M$823,3,0),"") | C12: =+A12 -> 0 | D12: =IFERROR(VLOOKUP(H12,'[1]Consolidado MP Planta'!$A$2:$M$823,13,0),"") | E12: =IFERROR(VLOOKUP(H12,'[1]Consolidado MP Planta'!$A$2:$M$823,12,0),"") | F12: =IFERROR(C12*E12,"") | G12: =IFERROR(F12/$F$66,"")
B13: =IFERROR(VLOOKUP(H13,'[1]Consolidado MP Planta'!$A$2:$M$823,3,0),"") | C13: =+A13 -> 0 | D13: =IFERROR(VLOOKUP(H13,'[1]Consolidado MP Planta'!$A$2:$M$823,13,0),"") | E13: =IFERROR(VLOOKUP(H13,'[1]Consolidado MP Planta'!$A$2:$M$823,12,0),"") | F13: =IFERROR(C13*E13,"") | G13: =IFERROR(F13/$F$66,"")
B14: =IFERROR(VLOOKUP(H14,'[1]Consolidado MP Planta'!$A$2:$M$823,3,0),"") | C14: =+A14 -> 0 | D14: =IFERROR(VLOOKUP(H14,'[1]Consolidado MP Planta'!$A$2:$M$823,13,0),"") | E14: =IFERROR(VLOOKUP(H14,'[1]Consolidado MP Planta'!$A$2:$M$823,12,0),"") | F14: =IFERROR(C14*E14,"") | G14: =IFERROR(F14/$F$66,"")
B15: =IFERROR(VLOOKUP(H15,[2]Hoja2!$A$2:$G$589,2,0),"")
A16: UNIDADES | B16: MATERIA PRIMA SEMIELABORADOS | C16: UNIDADES | D16: UND MEDIDA | E16: COSTO UNITARIO | F16: TOTAL COSTO | G16: % PREC. DEFINIDO | H16: CODIGOS
A17: 1000 | B17: Pecana Tostada | C17: =+A17 -> 1000 | D17: Gramos | E17: 8.58 | F17: =IFERROR(E17*C17,"") -> 8580 | G17: =IFERROR(F17/$F$66,"") -> 0.95518001 | H17: SE00707
B18: =IFERROR(VLOOKUP(H18,[1]SEMIELABORADOS!$A$2:$M$6000,2,0),"") | C18: =+A18 -> 0 | D18: =IFERROR(VLOOKUP(H18,[1]SEMIELABORADOS!$A$2:$M$6000,6,0),"") | E18: =IFERROR(VLOOKUP(H18,[1]SEMIELABORADOS!$A$2:$H$65536,8,0),"") | F18: =IFERROR(E18*C18,"") | G18: =IFERROR(F18/$F$66,"")
B19: =IFERROR(VLOOKUP(H19,[1]SEMIELABORADOS!$A$2:$M$6000,2,0),"") | C19: =+A19 -> 0 | D19: =IFERROR(VLOOKUP(H19,[1]SEMIELABORADOS!$A$2:$M$6000,6,0),"") | E19: =IFERROR(VLOOKUP(H19,[1]SEMIELABORADOS!$A$2:$H$65536,8,0),"") | F19: =IFERROR(E19*C19,"") | G19: =IFERROR(F19/$F$66,"")
B20: =IFERROR(VLOOKUP(H20,[1]SEMIELABORADOS!$A$2:$M$6000,2,0),"") | C20: =+A20 -> 0 | D20: =IFERROR(VLOOKUP(H20,[1]SEMIELABORADOS!$A$2:$M$6000,6,0),"") | E20: =IFERROR(VLOOKUP(H20,[1]SEMIELABORADOS!$A$2:$H$65536,8,0),"") | F20: =IFERROR(E20*C20,"") | G20: =IFERROR(F20/$F$66,"")
B21: =IFERROR(VLOOKUP(H21,[1]SEMIELABORADOS!$A$2:$M$6000,2,0),"") | C21: =+A21 -> 0 | D21: =IFERROR(VLOOKUP(H21,[1]SEMIELABORADOS!$A$2:$M$6000,6,0),"") | E21: =IFERROR(VLOOKUP(H21,[1]SEMIELABORADOS!$A$2:$H$65536,8,0),"") | F21: =IFERROR(E21*C21,"") | G21: =IFERROR(F21/$F$66,"")
B22: =IFERROR(VLOOKUP(H22,[1]SEMIELABORADOS!$A$2:$M$6000,2,0),"") | C22: =+A22 -> 0 | D22: =IFERROR(VLOOKUP(H22,[1]SEMIELABORADOS!$A$2:$M$6000,6,0),"") | E22: =IFERROR(VLOOKUP(H22,[1]SEMIELABORADOS!$A$2:$H$65536,8,0),"") | F22: =IFERROR(E22*C22,"") | G22: =IFERROR(F22/$F$66,"")
B23: =IFERROR(VLOOKUP(H23,[1]SEMIELABORADOS!$A$2:$M$6000,2,0),"") | C23: =+A23 -> 0 | D23: =IFERROR(VLOOKUP(H23,[1]SEMIELABORADOS!$A$2:$M$6000,6,0),"") | E23: =IFERROR(VLOOKUP(H23,[1]SEMIELABORADOS!$A$2:$H$65536,8,0),"") | F23: =IFERROR(E23*C23,"") | G23: =IFERROR(F23/$F$66,"")
B24: =IFERROR(VLOOKUP(H24,[1]SEMIELABORADOS!$A$2:$M$6000,2,0),"") | C24: =+A24 -> 0 | D24: =IFERROR(VLOOKUP(H24,[1]SEMIELABORADOS!$A$2:$M$6000,6,0),"") | E24: =IFERROR(VLOOKUP(H24,[1]SEMIELABORADOS!$A$2:$H$65536,8,0),"") | F24: =IFERROR(E24*C24,"") | G24: =IFERROR(F24/$F$66,"")
A26: UNIDADES | B26: EMPAQUE | C26: UNIDADES | D26: UND MEDIDA | E26: COSTO UNITARIO | F26: TOTAL COSTO | G26: % PREC. DEFINIDO | H26: CODIGOS
A27: 0 | B27: =IFERROR(VLOOKUP(H27,'[1]Consolidado MP Planta'!$A$2:$M$823,3,0),"") | C27: =+A27 -> 0 | D27: =IFERROR(VLOOKUP(H27,'[1]Consolidado MP Planta'!$A$2:$M$823,13,0),"") | E27: =IFERROR(VLOOKUP(H27,'[1]Consolidado MP Planta'!$A$2:$M$823,12,0),"") | F27: =IFERROR(C27*E27,"") | G27: =IFERROR(F27/$F$66,"")
B28: =IFERROR(VLOOKUP(H28,'[1]Consolidado MP Planta'!$A$2:$M$823,3,0),"") | C28: =+A28 -> 0 | D28: =IFERROR(VLOOKUP(H28,'[1]Consolidado MP Planta'!$A$2:$M$823,13,0),"") | E28: =IFERROR(VLOOKUP(H28,'[1]Consolidado MP Planta'!$A$2:$M$823,12,0),"") | F28: =IFERROR(C28*E28,"") | G28: =IFERROR(F28/$F$66,"")
B29: =IFERROR(VLOOKUP(H29,'[1]Consolidado MP Planta'!$A$2:$M$823,3,0),"") | C29: =+A29 -> 0 | D29: =IFERROR(VLOOKUP(H29,'[1]Consolidado MP Planta'!$A$2:$M$823,13,0),"") | E29: =IFERROR(VLOOKUP(H29,'[1]Consolidado MP Planta'!$A$2:$M$823,12,0),"") | F29: =IFERROR(C29*E29,"") | G29: =IFERROR(F29/$F$66,"")
B30: =IFERROR(VLOOKUP(H30,'[1]Consolidado MP Planta'!$A$2:$M$823,3,0),"") | C30: =+A30 -> 0 | D30: =IFERROR(VLOOKUP(H30,'[1]Consolidado MP Planta'!$A$2:$M$823,13,0),"") | E30: =IFERROR(VLOOKUP(H30,'[1]Consolidado MP Planta'!$A$2:$M$823,12,0),"") | F30: =IFERROR(C30*E30,"") | G30: =IFERROR(F30/$F$66,"")
B31: =IFERROR(VLOOKUP(H31,'[1]Consolidado MP Planta'!$A$2:$M$823,3,0),"") | C31: =+A31 -> 0 | D31: =IFERROR(VLOOKUP(H31,'[1]Consolidado MP Planta'!$A$2:$M$823,13,0),"") | E31: =IFERROR(VLOOKUP(H31,'[1]Consolidado MP Planta'!$A$2:$M$823,12,0),"") | F31: =IFERROR(C31*E31,"") | G31: =IFERROR(F31/$F$66,"")
B32: =IFERROR(VLOOKUP(H32,'[1]Consolidado MP Planta'!$A$2:$M$823,3,0),"") | C32: =+A32 -> 0 | D32: =IFERROR(VLOOKUP(H32,'[1]Consolidado MP Planta'!$A$2:$M$823,13,0),"") | E32: =IFERROR(VLOOKUP(H32,'[1]Consolidado MP Planta'!$A$2:$M$823,12,0),"") | F32: =IFERROR(C32*E32,"") | G32: =IFERROR(F32/$F$66,"")
A34: UNIDADES | B34: EMPAQUE SEMIELABORADOS | C34: UNIDADES | D34: UND MEDIDA | E34: COSTO UNITARIO | F34: TOTAL COSTO | G34: % PREC. DEFINIDO | H34: CODIGOS
A35: =+A17 -> 1000 | B35: Pecana Tostada | C35: =+A35 -> 1000 | D35: Gramos | E35: 0 | F35: =IFERROR(E35*C35,"") -> 0 | G35: =IFERROR(F35/$F$66,"") -> 0 | H35: SE00707
A36: =+A18 -> 0 | B36: =IFERROR(VLOOKUP(H36,[1]SEMIELABORADOS!$A$2:$M$6000,2,0),"") | C36: =+A36 -> 0 | D36: =IFERROR(VLOOKUP(H36,[1]SEMIELABORADOS!$A$2:$M$6000,6,0),"") | E36: =IFERROR(VLOOKUP(H36,[1]SEMIELABORADOS!$A$2:$M$65536,10,0),"") | F36: =IFERROR(E36*C36,"") | G36: =IFERROR(F36/$F$66,"")
A37: =+A19 -> 0 | B37: =IFERROR(VLOOKUP(H37,[1]SEMIELABORADOS!$A$2:$M$6000,2,0),"") | C37: =+A37 -> 0 | D37: =IFERROR(VLOOKUP(H37,[1]SEMIELABORADOS!$A$2:$M$6000,6,0),"") | E37: =IFERROR(VLOOKUP(H37,[1]SEMIELABORADOS!$A$2:$M$65536,10,0),"") | F37: =IFERROR(E37*C37,"") | G37: =IFERROR(F37/$F$66,"")
A38: =+A20 -> 0 | B38: =IFERROR(VLOOKUP(H38,[1]SEMIELABORADOS!$A$2:$M$6000,2,0),"") | C38: =+A38 -> 0 | D38: =IFERROR(VLOOKUP(H38,[1]SEMIELABORADOS!$A$2:$M$6000,6,0),"") | E38: =IFERROR(VLOOKUP(H38,[1]SEMIELABORADOS!$A$2:$M$65536,10,0),"") | F38: =IFERROR(E38*C38,"") | G38: =IFERROR(F38/$F$66,"")
A39: =+A21 -> 0 | B39: =IFERROR(VLOOKUP(H39,[1]SEMIELABORADOS!$A$2:$M$6000,2,0),"") | C39: =+A39 -> 0 | D39: =IFERROR(VLOOKUP(H39,[1]SEMIELABORADOS!$A$2:$M$6000,6,0),"") | E39: =IFERROR(VLOOKUP(H39,[1]SEMIELABORADOS!$A$2:$M$65536,10,0),"") | F39: =IFERROR(E39*C39,"") | G39: =IFERROR(F39/$F$66,"")
A40: =+A22 -> 0 | B40: =IFERROR(VLOOKUP(H40,[1]SEMIELABORADOS!$A$2:$M$6000,2,0),"") | C40: =+A40 -> 0 | D40: =IFERROR(VLOOKUP(H40,[1]SEMIELABORADOS!$A$2:$M$6000,6,0),"") | E40: =IFERROR(VLOOKUP(H40,[1]SEMIELABORADOS!$A$2:$M$65536,10,0),"") | F40: =IFERROR(E40*C40,"") | G40: =IFERROR(F40/$F$66,"")
A41: =+A23 -> 0 | B41: =IFERROR(VLOOKUP(H41,[1]SEMIELABORADOS!$A$2:$M$6000,2,0),"") | C41: =+A41 -> 0 | D41: =IFERROR(VLOOKUP(H41,[1]SEMIELABORADOS!$A$2:$M$6000,6,0),"") | E41: =IFERROR(VLOOKUP(H41,[1]SEMIELABORADOS!$A$2:$M$65536,10,0),"") | F41: =IFERROR(E41*C41,"") | G41: =IFERROR(F41/$F$66,"")
A43: UNIDADES | B43: MODI | C43: UNIDADES | D43: UND MEDIDA | E43: COSTO UNITARIO | F43: TOTAL COSTO | G43: % PREC. DEFINIDO | H43: CODIGOS
A44: =+A35 -> 1000 | B44: Pecana Tostada | C44: =+A44 -> 1000 | D44: Gramos | E44: 0.61 | F44: =IFERROR(E44*C44,"") -> 610 | G44: =IFERROR(F44/$F$66,"") -> 0.067909069 | H44: SE00707
A45: =+A36 -> 0 | B45: =IFERROR(VLOOKUP(H45,[1]SEMIELABORADOS!$A$2:$M$6000,2,0),"") | C45: =+A45 -> 0 | D45: =IFERROR(VLOOKUP(H45,[1]SEMIELABORADOS!$A$2:$M$6000,6,0),"") | E45: =IFERROR(VLOOKUP(H45,[1]SEMIELABORADOS!$A$2:$M$65536,12,0),"") | F45: =IFERROR(E45*C45,"") | G45: =IFERROR(F45/$F$66,"")
...

Sheet Relleno de Queso y Condensada
C1: SERVICIOS DE PASTELERIA S.A. | H1: CÓDIGO: | I1: ESP-RE-POS-133
C2: ESPECIFICACION DE RECETA | H2: REVISIÓN: | I2: 01
C3: SE00806 Relleno de Queso y Leche Condensada | H3: FECHA DE APROBACIÓN: | I3: 46063
C4: Elaborado | D4: Javier Tong, Chef
C5: Aprobado | D5: Esteban Cartin, Gte Manufactura
A6: AREA QUE PRODUCE: | D6: Postres | G6: AREA QUE EMPACA: | I6: Postres
A7: # Código | B7: # Código Netsuite | C7: Descripción del ingrediente | D7: Marca | E7: Unidad Internacional | G7: Medida alternativa | I7: Costo - Referencia
E8: Cantidad | F8: Unidad medida | G8: Cantidad | H8: Unidad medida | I8: Colones
C9: Ensamble
B10: MP10046 | C10: Queso Crema Panadero | E10: =760*10.63 -> 8078.8 | F10: g
B11: MP10050 | C11: Leche Condensada | D11: Nestle | E11: =160*10.63 -> 1700.8 | F11: g
B12: MP10041 | C12: Azucar Glass Molida | D12: La Ciabatta | E12: =40*10.63 -> 425.2 | F12: g
B13: MP10008 | C13: PRESERVANTE 1047S(PAQ=5 KILO) | E13: =1*10.63 -> 10.63 | F13: g
C16: Decoración
C18: Empaque
A19: 702067 | B19: EM10120 | C19: ETIQ.BLANCA 1 13/16 * 1 7/8 | D19: ETIPLAST | E19: 2 | F19: ud | K19: =10000/940 -> 10.638298
D23: Cantidad | E23: Unidad
A24: PESO TOTAL OBTENIDO | D24: 10000 | E24: g | F24: Tiempo de Horneo:
A25: TIEMPO TOTAL DE PREPARACION | D25: 10 | E25: min | F25: Horno:
A26: CANTIDAD DE PORCIONES OBTENIDAS | D26: 1 | E26: tanda | F26: Temperatura de Horneo:
A27: PESO DE CADA PORCIÓN | D27: 10000 | E27: g | F27: Otros
A28: MERMA | D28: =SUM(E10:E13)-D24 -> 215.43 | E28: g
A29: PROCEDIMIENTO DE PREPARACION DE LA RECETA
A30: 1, Colocar en la batidora el queso crema con la leche condensada y mezclar con la paleta (Apenas este todo incorporado)
A31: 2, Agregar la leche condensada y mezclar dejando todo bien incorporado (No batir de más)
A32: 3, Colocar el relleno en una tina, tapar y etiquetar.
A34: CONTROL DE CAMBIOS

Sheet costo relleno Queso 
E1: Precio Local | F1: Costo MP | G1: Costo EM | H1: Costo MO
E2: =IFERROR(O62,"") -> 31020.318 | F2: =IFERROR(H53,"") -> 29416.718 | G2: =IFERROR(H54,"") -> 3.6 | H2: =IFERROR(H56,"") -> 770
A5: ESTRUCTURA DE COSTOS
F6: Fecha: | H6: =TODAY() -> 46063
A7: UNIDADES | B7: DESCRIPCION MAT.PRIMA | C7: UNIDADES | D7: UND MEDIDA | E7: COSTO UNITARIO | F7: TOTAL COSTO | G7: % PREC. DEFINIDO | H7: CODIGOS
A8: 8078.8 | B8: Queso Crema Panadero | C8: =+A8 -> 8078.8 | D8: Gramos | E8: 3.07 | F8: =IFERROR(C8*E8,"") -> 24801.916 | G8: =IFERROR(F8/$F$66,"") -> 0.80581553 | H8: MP10046
A9: 1700.8 | B9: Leche Condensada | C9: =+A9 -> 1700.8 | D9: Gramos | E9: 2.22 | F9: =IFERROR(C9*E9,"") -> 3775.776 | G9: =IFERROR(F9/$F$66,"") -> 0.12267516 | H9: MP10050
A10: 425.2 | B10: Azucar Glass Molida | C10: =+A10 -> 425.2 | D10: Gramos | E10: 1.79 | F10: =IFERROR(C10*E10,"") -> 761.108 | G10: =IFERROR(F10/$F$66,"") -> 0.024728438 | H10: MP10041
A11: 10.63 | B11: PRESERVANTE 1047S(PAQ=5 KILO) | C11: =+A11 -> 10.63 | D11: Gramos | E11: 7.33 | F11: =IFERROR(C11*E11,"") -> 77.9179 | G11: =IFERROR(F11/$F$66,"") -> 0.0025315566 | H11: MP10008
B12: =IFERROR(VLOOKUP(H12,'[1]Consolidado MP Planta'!$A$2:$M$823,3,0),"") | C12: =+A12 -> 0 | D12: =IFERROR(VLOOKUP(H12,'[1]Consolidado MP Planta'!$A$2:$M$823,13,0),"") | E12: =IFERROR(VLOOKUP(H12,'[1]Consolidado MP Planta'!$A$2:$M$823,12,0),"") | F12: =IFERROR(C12*E12,"") | G12: =IFERROR(F12/$F$66,"")
B13: =IFERROR(VLOOKUP(H13,'[1]Consolidado MP Planta'!$A$2:$M$823,3,0),"") | C13: =+A13 -> 0 | D13: =IFERROR(VLOOKUP(H13,'[1]Consolidado MP Planta'!$A$2:$M$823,13,0),"") | E13: =IFERROR(VLOOKUP(H13,'[1]Consolidado MP Planta'!$A$2:$M$823,12,0),"") | F13: =IFERROR(C13*E13,"") | G13: =IFERROR(F13/$F$66,"")
B14: =IFERROR(VLOOKUP(H14,'[1]Consolidado MP Planta'!$A$2:$M$823,3,0),"") | C14: =+A14 -> 0 | D14: =IFERROR(VLOOKUP(H14,'[1]Consolidado MP Planta'!$A$2:$M$823,13,0),"") | E14: =IFERROR(VLOOKUP(H14,'[1]Consolidado MP Planta'!$A$2:$M$823,12,0),"") | F14: =IFERROR(C14*E14,"") | G14: =IFERROR(F14/$F$66,"")
B15: =IFERROR(VLOOKUP(H15,[2]Hoja2!$A$2:$G$589,2,0),"")
A16: UNIDADES | B16: MATERIA PRIMA SEMIELABORADOS | C16: UNIDADES | D16: UND MEDIDA | E16: COSTO UNITARIO | F16: TOTAL COSTO | G16: % PREC. DEFINIDO | H16: CODIGOS
B17: =IFERROR(VLOOKUP(H17,[1]SEMIELABORADOS!$A$2:$M$6000,2,0),"") | C17: =+A17 -> 0 | D17: =IFERROR(VLOOKUP(H17,[1]SEMIELABORADOS!$A$2:$M$6000,6,0),"") | E17: =IFERROR(VLOOKUP(H17,[1]SEMIELABORADOS!$A$2:$H$65536,8,0),"") | F17: =IFERROR(E17*C17,"") | G17: =IFERROR(F17/$F$66,"")
B18: =IFERROR(VLOOKUP(H18,[1]SEMIELABORADOS!$A$2:$M$6000,2,0),"") | C18: =+A18 -> 0 | D18: =IFERROR(VLOOKUP(H18,[1]SEMIELABORADOS!$A$2:$M$6000,6,0),"") | E18: =IFERROR(VLOOKUP(H18,[1]SEMIELABORADOS!$A$2:$H$65536,8,0),"") | F18: =IFERROR(E18*C18,"") | G18: =IFERROR(F18/$F$66,"")
B19: =IFERROR(VLOOKUP(H19,[1]SEMIELABORADOS!$A$2:$M$6000,2,0),"") | C19: =+A19 -> 0 | D19: =IFERROR(VLOOKUP(H19,[1]SEMIELABORADOS!$A$2:$M$6000,6,0),"") | E19: =IFERROR(VLOOKUP(H19,[1]SEMIELABORADOS!$A$2:$H$65536,8,0),"") | F19: =IFERROR(E19*C19,"") | G19: =IFERROR(F19/$F$66,"")
B20: =IFERROR(VLOOKUP(H20,[1]SEMIELABORADOS!$A$2:$M$6000,2,0),"") | C20: =+A20 -> 0 | D20: =IFERROR(VLOOKUP(H20,[1]SEMIELABORADOS!$A$2:$M$6000,6,0),"") | E20: =IFERROR(VLOOKUP(H20,[1]SEMIELABORADOS!$A$2:$H$65536,8,0),"") | F20: =IFERROR(E20*C20,"") | G20: =IFERROR(F20/$F$66,"")
B21: =IFERROR(VLOOKUP(H21,[1]SEMIELABORADOS!$A$2:$M$6000,2,0),"") | C21: =+A21 -> 0 | D21: =IFERROR(VLOOKUP(H21,[1]SEMIELABORADOS!$A$2:$M$6000,6,0),"") | E21: =IFERROR(VLOOKUP(H21,[1]SEMIELABORADOS!$A$2:$H$65536,8,0),"") | F21: =IFERROR(E21*C21,"") | G21: =IFERROR(F21/$F$66,"")
B22: =IFERROR(VLOOKUP(H22,[1]SEMIELABORADOS!$A$2:$M$6000,2,0),"") | C22: =+A22 -> 0 | D22: =IFERROR(VLOOKUP(H22,[1]SEMIELABORADOS!$A$2:$M$6000,6,0),"") | E22: =IFERROR(VLOOKUP(H22,[1]SEMIELABORADOS!$A$2:$H$65536,8,0),"") | F22: =IFERROR(E22*C22,"") | G22: =IFERROR(F22/$F$66,"")
B23: =IFERROR(VLOOKUP(H23,[1]SEMIELABORADOS!$A$2:$M$6000,2,0),"") | C23: =+A23 -> 0 | D23: =IFERROR(VLOOKUP(H23,[1]SEMIELABORADOS!$A$2:$M$6000,6,0),"") | E23: =IFERROR(VLOOKUP(H23,[1]SEMIELABORADOS!$A$2:$H$65536,8,0),"") | F23: =IFERROR(E23*C23,"") | G23: =IFERROR(F23/$F$66,"")
B24: =IFERROR(VLOOKUP(H24,[1]SEMIELABORADOS!$A$2:$M$6000,2,0),"") | C24: =+A24 -> 0 | D24: =IFERROR(VLOOKUP(H24,[1]SEMIELABORADOS!$A$2:$M$6000,6,0),"") | E24: =IFERROR(VLOOKUP(H24,[1]SEMIELABORADOS!$A$2:$H$65536,8,0),"") | F24: =IFERROR(E24*C24,"") | G24: =IFERROR(F24/$F$66,"")
A26: UNIDADES | B26: EMPAQUE | C26: UNIDADES | D26: UND MEDIDA | E26: COSTO UNITARIO | F26: TOTAL COSTO | G26: % PREC. DEFINIDO | H26: CODIGOS
A27: 2 | B27: =IFERROR(VLOOKUP(H27,'[1]Consolidado MP Planta'!$A$2:$M$823,3,0),"") -> ETIQ.BLANCA 1 13/16 * 1 7/8 (UND) | C27: =+A27 -> 2 | D27: =IFERROR(VLOOKUP(H27,'[1]Consolidado MP Planta'!$A$2:$M$823,13,0),"") -> Und | E27: 1.8 | F27: =IFERROR(C27*E27,"") -> 3.6 | G27: =IFERROR(F27/$F$66,"") -> 0.00011696419 | H27: 0702067
B28: =IFERROR(VLOOKUP(H28,'[1]Consolidado MP Planta'!$A$2:$M$823,3,0),"") | C28: =+A28 -> 0 | D28: =IFERROR(VLOOKUP(H28,'[1]Consolidado MP Planta'!$A$2:$M$823,13,0),"") | E28: =IFERROR(VLOOKUP(H28,'[1]Consolidado MP Planta'!$A$2:$M$823,12,0),"") | F28: =IFERROR(C28*E28,"") | G28: =IFERROR(F28/$F$66,"")
B29: =IFERROR(VLOOKUP(H29,'[1]Consolidado MP Planta'!$A$2:$M$823,3,0),"") | C29: =+A29 -> 0 | D29: =IFERROR(VLOOKUP(H29,'[1]Consolidado MP Planta'!$A$2:$M$823,13,0),"") | E29: =IFERROR(VLOOKUP(H29,'[1]Consolidado MP Planta'!$A$2:$M$823,12,0),"") | F29: =IFERROR(C29*E29,"") | G29: =IFERROR(F29/$F$66,"")
B30: =IFERROR(VLOOKUP(H30,'[1]Consolidado MP Planta'!$A$2:$M$823,3,0),"") | C30: =+A30 -> 0 | D30: =IFERROR(VLOOKUP(H30,'[1]Consolidado MP Planta'!$A$2:$M$823,13,0),"") | E30: =IFERROR(VLOOKUP(H30,'[1]Consolidado MP Planta'!$A$2:$M$823,12,0),"") | F30: =IFERROR(C30*E30,"") | G30: =IFERROR(F30/$F$66,"")
B31: =IFERROR(VLOOKUP(H31,'[1]Consolidado MP Planta'!$A$2:$M$823,3,0),"") | C31: =+A31 -> 0 | D31: =IFERROR(VLOOKUP(H31,'[1]Consolidado MP Planta'!$A$2:$M$823,13,0),"") | E31: =IFERROR(VLOOKUP(H31,'[1]Consolidado MP Planta'!$A$2:$M$823,12,0),"") | F31: =IFERROR(C31*E31,"") | G31: =IFERROR(F31/$F$66,"")
B32: =IFERROR(VLOOKUP(H32,'[1]Consolidado MP Planta'!$A$2:$M$823,3,0),"") | C32: =+A32 -> 0 | D32: =IFERROR(VLOOKUP(H32,'[1]Consolidado MP Planta'!$A$2:$M$823,13,0),"") | E32: =IFERROR(VLOOKUP(H32,'[1]Consolidado MP Planta'!$A$2:$M$823,12,0),"") | F32: =IFERROR(C32*E32,"") | G32: =IFERROR(F32/$F$66,"")
A34: UNIDADES | B34: EMPAQUE SEMIELABORADOS | C34: UNIDADES | D34: UND MEDIDA | E34: COSTO UNITARIO | F34: TOTAL COSTO | G34: % PREC. DEFINIDO | H34: CODIGOS
A35: =+A17 -> 0 | B35: =IFERROR(VLOOKUP(H35,[1]SEMIELABORADOS!$A$2:$M$6000,2,0),"") | C35: =+A35 -> 0 | D35: =IFERROR(VLOOKUP(H35,[1]SEMIELABORADOS!$A$2:$M$6000,6,0),"") | E35: =IFERROR(VLOOKUP(H35,[1]SEMIELABORADOS!$A$2:$M$65536,10,0),"") | F35: =IFERROR(E35*C35,"") | G35: =IFERROR(F35/$F$66,"")
A36: =+A18 -> 0 | B36: =IFERROR(VLOOKUP(H36,[1]SEMIELABORADOS!$A$2:$M$6000,2,0),"") | C36: =+A36 -> 0 | D36: =IFERROR(VLOOKUP(H36,[1]SEMIELABORADOS!$A$2:$M$6000,6,0),"") | E36: =IFERROR(VLOOKUP(H36,[1]SEMIELABORADOS!$A$2:$M$65536,10,0),"") | F36: =IFERROR(E36*C36,"") | G36: =IFERROR(F36/$F$66,"")
A37: =+A19 -> 0 | B37: =IFERROR(VLOOKUP(H37,[1]SEMIELABORADOS!$A$2:$M$6000,2,0),"") | C37: =+A37 -> 0 | D37: =IFERROR(VLOOKUP(H37,[1]SEMIELABORADOS!$A$2:$M$6000,6,0),"") | E37: =IFERROR(VLOOKUP(H37,[1]SEMIELABORADOS!$A$2:$M$65536,10,0),"") | F37: =IFERROR(E37*C37,"") | G37: =IFERROR(F37/$F$66,"")
A38: =+A20 -> 0 | B38: =IFERROR(VLOOKUP(H38,[1]SEMIELABORADOS!$A$2:$M$6000,2,0),"") | C38: =+A38 -> 0 | D38: =IFERROR(VLOOKUP(H38,[1]SEMIELABORADOS!$A$2:$M$6000,6,0),"") | E38: =IFERROR(VLOOKUP(H38,[1]SEMIELABORADOS!$A$2:$M$65536,10,0),"") | F38: =IFERROR(E38*C38,"") | G38: =IFERROR(F38/$F$66,"")
A39: =+A21 -> 0 | B39: =IFERROR(VLOOKUP(H39,[1]SEMIELABORADOS!$A$2:$M$6000,2,0),"") | C39: =+A39 -> 0 | D39: =IFERROR(VLOOKUP(H39,[1]SEMIELABORADOS!$A$2:$M$6000,6,0),"") | E39: =IFERROR(VLOOKUP(H39,[1]SEMIELABORADOS!$A$2:$M$65536,10,0),"") | F39: =IFERROR(E39*C39,"") | G39: =IFERROR(F39/$F$66,"")
A40: =+A22 -> 0 | B40: =IFERROR(VLOOKUP(H40,[1]SEMIELABORADOS!$A$2:$M$6000,2,0),"") | C40: =+A40 -> 0 | D40: =IFERROR(VLOOKUP(H40,[1]SEMIELABORADOS!$A$2:$M$6000,6,0),"") | E40: =IFERROR(VLOOKUP(H40,[1]SEMIELABORADOS!$A$2:$M$65536,10,0),"") | F40: =IFERROR(E40*C40,"") | G40: =IFERROR(F40/$F$66,"")
A41: =+A23 -> 0 | B41: =IFERROR(VLOOKUP(H41,[1]SEMIELABORADOS!$A$2:$M$6000,2,0),"") | C41: =+A41 -> 0 | D41: =IFERROR(VLOOKUP(H41,[1]SEMIELABORADOS!$A$2:$M$6000,6,0),"") | E41: =IFERROR(VLOOKUP(H41,[1]SEMIELABORADOS!$A$2:$M$65536,10,0),"") | F41: =IFERROR(E41*C41,"") | G41: =IFERROR(F41/$F$66,"")
A43: UNIDADES | B43: MODI | C43: UNIDADES | D43: UND MEDIDA | E43: COSTO UNITARIO | F43: TOTAL COSTO | G43: % PREC. DEFINIDO | H43: CODIGOS
A44: =+A35 -> 0 | B44: =IFERROR(VLOOKUP(H44,[1]SEMIELABORADOS!$A$2:$M$6000,2,0),"") | C44: =+A44 -> 0 | D44: =IFERROR(VLOOKUP(H44,[1]SEMIELABORADOS!$A$2:$M$6000,6,0),"") | E44: =IFERROR(VLOOKUP(H44,[1]SEMIELABORADOS!$A$2:$M$65536,12,0),"") | F44: =IFERROR(E44*C44,"") | G44: =IFERROR(F44/$F$66,"")
