Workbook

Sheet Relleno Framb y arand
C1: SERVICIOS DE PASTELERIA S.A. | H1: CÓDIGO: | I1: ESP-RE-COCS-061
C2: ESPECIFICACION DE RECETA | H2: REVISIÓN: | I2: 01
C3: (SE00541) RELLENO ARANDANO FRAMBUESA | H3: FECHA DE APROBACIÓN: | I3: 45609
C4: Elaborado | D4: Javier Tong, Chef
C5: Aprobado | D5: Esteban Cartin, Gte Manufactura
A6: AREA QUE PRODUCE: | D6: Cocina | G6: AREA QUE EMPACA: | I6: Cocina
A7: # Código | B7: # Código Netsuite | C7: Descripción del ingrediente | D7: Marca | E7: Unidad Internacional | G7: Medida alternativa | I7: Costo - Referencia
E8: Cantidad | F8: Unidad medida | G8: Cantidad | H8: Unidad medida | I8: Colones
C9: Ensamble
A10: 10100230 | B10: MP10191 | C10: FRESA CONGELADA BEGRO (PAQ:1 K) | D10: BEGRO | E10: 13000 | F10: g
A11: 109000158 | B11: MP10549 | C11: MORA FRESCA (1 KG) | D11: MAYCA | E11: 2800 | F11: g
A12: 109000157 | B12: MP10548 | C12: ARANDANO CONGELADO (2.5 K) | D12: MAYCA | E12: 2800 | F12: g
B13: MP10687 | C13: SMOOBEES BLUEBERRY 1 KG | D13: PURATOS | E13: 1000 | F13: g
A14: 102000066 | B14: MP10547 | C14: CONCENTRADO FRAMBUESA (946 ML) | D14: ISLAND OASIS | E14: 5600 | F14: g
A15: 90100131 | B15: SE00016 | C15: AZUCAR BLANCO INDUSTRIAL KILO | D15: FAS | E15: 5600 | F15: g
A16: 90100139 | B16: MP10239 | C16: LIMON EN POLVO (BOLSA:1000G) | D16: FAS | E16: 180 | F16: g
A17: 1212412 | B17: MP10025 | C17: PRESERVANTE 1017S (PAQ=5 KILO) | D17: MAYCA | E17: 32 | F17: g
A18: 10415 | C18: AGUA | D18: FAS | E18: 4000 | F18: g
A19: 510215 | B19: MP10026 | C19: ALMIDON MODIFICADO (SACO:25 K) | D19: MAYCA | E19: 1600 | F19: g
C27: Decoración
C33: Empaque
A34: 512000002 | B34: EM10259 | C34: PLASTICO AUTOAD (UND: 18 * 2000 M) | D34: MAYCA | E34: 1 | F34: m
D44: Cantidad | E44: Unidad
A45: PESO TOTAL OBTENIDO | D45: 33000 | E45: g | F45: Tiempo de Horneo:
A46: TIEMPO TOTAL DE PREPARACION | D46: 30 | E46: min | F46: Horno:
A47: CANTIDAD DE PORCIONES OBTENIDAS | D47: 1 | E47: g | F47: Temperatura de Horneo:
A48: PESO DE CADA PORCIÓN | D48: 33000 | E48: g | F48: Otros
A49: MERMA | D49: 3612 | E49: g
A50: PROCEDIMIENTO DE PREPARACION DE LA RECETA
A51: 1.- Colocar la fresa, mora, pulpa de frambuesa, azúcar, limon en polvo, y preservante.
A52: 2.- Cocinar a fuego alto hasta hervir, mover cada 5 minutos para evitar que el relleno se pegue en el fondo de la olla.
A53: 3.- Una vez que el relleno este hirviendo agregar el almidon disuelto en el agua. Y los smoobies
A54: 4.- Hervir hasta que el relleno este bien espeso y con la textura deseada.
A55: 5.- Enfriar y colocar en baldes, cubir con plastico y rotular.
A62: CONTROL DE CAMBIOS

Sheet Batido
C1: SERVICIOS DE PASTELERIA S.A. | H1: CÓDIGO: | I1: ESP-RE-BAS-193
C2: ESPECIFICACION DE RECETA | H2: REVISIÓN: | I2: 1
C3: 907000273 (SE00517) BATIDO RED VELVET | H3: FECHA DE APROBACIÓN: | I3: 45160
C4: Elaborado | D4: Juan Pablo Brenes, Chef
C5: Aprobado | D5: Esteban Cartin, Gte Manufactura
A6: AREA QUE PRODUCE: | D6: Cocina | G6: AREA QUE EMPACA: | I6: Cocina
A7: # Código | B7: # Código Netsuite | C7: Descripción del ingrediente | D7: Marca | E7: Unidad Internacional | G7: Medida alternativa | I7: Costo - Referencia
E8: Cantidad | F8: Unidad medida | G8: Cantidad | H8: Unidad medida | I8: Colones
A9: 512259 | B9: MP10627 | C9: PREMEZCLA RED VELVET | D9: PURATOS | E9: 6665 | F9: g
A10: 10415 | C10: AGUA POTABLE (PLANTA) | D10: FAS | E10: 1650 | F10: g
A11: 10100050 | B11: MP10002 | C11: ACEITE CAPULLO RBD (UND:17 L) | D11: CAPULLO | E11: 2000 | F11: g
A12: 1210482 | B12: MP10005 | C12: HUEVO ENTERO PASTERI INNOVO (CAJA:10 K) | D12: INNOVO | E12: 2350 | F12: g
A13: 1212410 | B13: MP10008 | C13: PRESERVANTE 1047S KILO | D13: Aseal | E13: 18 | F13: g
D16: Cantidad | E16: Unidad
A17: PESO TOTAL OBTENIDO | D17: 12018 | E17: g | F17: Tiempo de Horneo:
A18: TIEMPO TOTAL DE PREPARACION | D18: 8 | E18: min | F18: Horno:
A19: CANTIDAD DE PORCIONES OBTENIDAS | D19: 1 | E19: ud | F19: Temperatura de Horneo:
A20: PESO DE CADA PORCIÓN | D20: 12018 | E20: g | F20: Otros
A21: MERMA | D21: 665 | E21: g
A22: PROCEDIMIENTO DE PREPARACION DE LA RECETA
A23: 1.- Colocar el huevo, agua y aceite en la batidora, añadir la pre mezcla y batir con paleta 1 minuto en velocidad 1.
A24: 2.- Limpiar los bordes y batir 4 minutos en velocidad 2 (media).
A25: 3.- Utilizar de inmediato.
A31: Control de cambios
A32: 2: Actualizacion codigos Netsuit

Sheet Costo Batido
E1: Precio Local | F1: Costo MP | G1: Costo EM | H1: Costo MO
E2: =IFERROR(O61,"") -> 22147.13 | F2: =IFERROR(H52,"") -> 21019.13 | G2: =IFERROR(H53,"") -> 0 | H2: =IFERROR(H55,"") -> 616
A5: ESTRUCTURA DE COSTOS
F6: Fecha: | H6: =TODAY() -> 46034
A7: UNIDADES | B7: DESCRIPCION MAT.PRIMA | C7: UNIDADES | D7: UND MEDIDA | E7: COSTO UNITARIO | F7: TOTAL COSTO | G7: % PREC. DEFINIDO | H7: CODIGOS
A8: 6665 | B8: PREMEZCLA RED VELVET | C8: =+A8 -> 6665 | D8: Gramos | E8: 2.07 | F8: =IFERROR(C8*E8,"") -> 13796.55 | G8: =IFERROR(F8/$F$65,"") -> 0.62553749 | H8: 512259
A9: 2000 | B9: =IFERROR(VLOOKUP(H9,'[1]Consolidado MP Planta'!$A$2:$M$823,3,0),"") -> ACEITE CAPULLO RBD (UND:17 L) | C9: =+A9 -> 2000 | D9: =IFERROR(VLOOKUP(H9,'[1]Consolidado MP Planta'!$A$2:$M$823,13,0),"") -> Mililitros | E9: 0.89 | F9: =IFERROR(C9*E9,"") -> 1780 | G9: =IFERROR(F9/$F$65,"") -> 0.080705447 | H9: 10100050
A10: 2350 | B10: =IFERROR(VLOOKUP(H10,'[1]Consolidado MP Planta'!$A$2:$M$823,3,0),"") -> HUEVO ENTERO PASTERI INNOVO (CAJA:10 K) | C10: =+A10 -> 2350 | D10: =IFERROR(VLOOKUP(H10,'[1]Consolidado MP Planta'!$A$2:$M$823,13,0),"") -> Gramos | E10: 2.26 | F10: =IFERROR(C10*E10,"") -> 5311 | G10: =IFERROR(F10/$F$65,"") -> 0.24080148 | H10: 1210482
A11: 18 | B11: =IFERROR(VLOOKUP(H11,'[1]Consolidado MP Planta'!$A$2:$M$823,3,0),"") -> PRESERVANTE 1047S (PAQ=5 KILO) | C11: =+A11 -> 18 | D11: =IFERROR(VLOOKUP(H11,'[1]Consolidado MP Planta'!$A$2:$M$823,13,0),"") -> Gramos | E11: 7.31 | F11: =IFERROR(C11*E11,"") -> 131.58 | G11: =IFERROR(F11/$F$65,"") -> 0.0059658554 | H11: 1212410
B12: =IFERROR(VLOOKUP(H12,'[1]Consolidado MP Planta'!$A$2:$M$823,3,0),"") | C12: =+A12 -> 0 | D12: =IFERROR(VLOOKUP(H12,'[1]Consolidado MP Planta'!$A$2:$M$823,13,0),"") | E12: =IFERROR(VLOOKUP(H12,'[1]Consolidado MP Planta'!$A$2:$M$823,12,0),"") | F12: =IFERROR(C12*E12,"") | G12: =IFERROR(F12/$F$65,"")
B13: =IFERROR(VLOOKUP(H13,'[1]Consolidado MP Planta'!$A$2:$M$823,3,0),"") | C13: =+A13 -> 0 | D13: =IFERROR(VLOOKUP(H13,'[1]Consolidado MP Planta'!$A$2:$M$823,13,0),"") | E13: =IFERROR(VLOOKUP(H13,'[1]Consolidado MP Planta'!$A$2:$M$823,12,0),"") | F13: =IFERROR(C13*E13,"") | G13: =IFERROR(F13/$F$65,"")
B14: =IFERROR(VLOOKUP(H14,'[2]ARTICULOS MP PLANTA'!$A$2:$G$589,2,0),"")
A15: UNIDADES | B15: MATERIA PRIMA SEMIELABORADOS | C15: UNIDADES | D15: UND MEDIDA | E15: COSTO UNITARIO | F15: TOTAL COSTO | G15: % PREC. DEFINIDO | H15: CODIGOS
B16: =IFERROR(VLOOKUP(H16,[1]SEMIELABORADOS!$A$2:$M$6000,2,0),"") | C16: =+A16 -> 0 | D16: =IFERROR(VLOOKUP(H16,[1]SEMIELABORADOS!$A$2:$M$6000,6,0),"") | E16: =IFERROR(VLOOKUP(H16,[1]SEMIELABORADOS!$A$2:$H$65536,8,0),"") | F16: =IFERROR(E16*C16,"") | G16: =IFERROR(F16/$F$65,"")
B17: =IFERROR(VLOOKUP(H17,[1]SEMIELABORADOS!$A$2:$M$6000,2,0),"") | C17: =+A17 -> 0 | D17: =IFERROR(VLOOKUP(H17,[1]SEMIELABORADOS!$A$2:$M$6000,6,0),"") | E17: =IFERROR(VLOOKUP(H17,[1]SEMIELABORADOS!$A$2:$H$65536,8,0),"") | F17: =IFERROR(E17*C17,"") | G17: =IFERROR(F17/$F$65,"")
B18: =IFERROR(VLOOKUP(H18,[1]SEMIELABORADOS!$A$2:$M$6000,2,0),"") | C18: =+A18 -> 0 | D18: =IFERROR(VLOOKUP(H18,[1]SEMIELABORADOS!$A$2:$M$6000,6,0),"") | E18: =IFERROR(VLOOKUP(H18,[1]SEMIELABORADOS!$A$2:$H$65536,8,0),"") | F18: =IFERROR(E18*C18,"") | G18: =IFERROR(F18/$F$65,"")
B19: =IFERROR(VLOOKUP(H19,[1]SEMIELABORADOS!$A$2:$M$6000,2,0),"") | C19: =+A19 -> 0 | D19: =IFERROR(VLOOKUP(H19,[1]SEMIELABORADOS!$A$2:$M$6000,6,0),"") | E19: =IFERROR(VLOOKUP(H19,[1]SEMIELABORADOS!$A$2:$H$65536,8,0),"") | F19: =IFERROR(E19*C19,"") | G19: =IFERROR(F19/$F$65,"")
B20: =IFERROR(VLOOKUP(H20,[1]SEMIELABORADOS!$A$2:$M$6000,2,0),"") | C20: =+A20 -> 0 | D20: =IFERROR(VLOOKUP(H20,[1]SEMIELABORADOS!$A$2:$M$6000,6,0),"") | E20: =IFERROR(VLOOKUP(H20,[1]SEMIELABORADOS!$A$2:$H$65536,8,0),"") | F20: =IFERROR(E20*C20,"") | G20: =IFERROR(F20/$F$65,"")
B21: =IFERROR(VLOOKUP(H21,[1]SEMIELABORADOS!$A$2:$M$6000,2,0),"") | C21: =+A21 -> 0 | D21: =IFERROR(VLOOKUP(H21,[1]SEMIELABORADOS!$A$2:$M$6000,6,0),"") | E21: =IFERROR(VLOOKUP(H21,[1]SEMIELABORADOS!$A$2:$H$65536,8,0),"") | F21: =IFERROR(E21*C21,"") | G21: =IFERROR(F21/$F$65,"")
B22: =IFERROR(VLOOKUP(H22,[1]SEMIELABORADOS!$A$2:$M$6000,2,0),"") | C22: =+A22 -> 0 | D22: =IFERROR(VLOOKUP(H22,[1]SEMIELABORADOS!$A$2:$M$6000,6,0),"") | E22: =IFERROR(VLOOKUP(H22,[1]SEMIELABORADOS!$A$2:$H$65536,8,0),"") | F22: =IFERROR(E22*C22,"") | G22: =IFERROR(F22/$F$65,"")
B23: =IFERROR(VLOOKUP(H23,[1]SEMIELABORADOS!$A$2:$M$6000,2,0),"") | C23: =+A23 -> 0 | D23: =IFERROR(VLOOKUP(H23,[1]SEMIELABORADOS!$A$2:$M$6000,6,0),"") | E23: =IFERROR(VLOOKUP(H23,[1]SEMIELABORADOS!$A$2:$H$65536,8,0),"") | F23: =IFERROR(E23*C23,"") | G23: =IFERROR(F23/$F$65,"")
A25: UNIDADES | B25: EMPAQUE | C25: UNIDADES | D25: UND MEDIDA | E25: COSTO UNITARIO | F25: TOTAL COSTO | G25: % PREC. DEFINIDO | H25: CODIGOS
A26: 0 | B26: =IFERROR(VLOOKUP(H26,'[1]Consolidado MP Planta'!$A$2:$M$823,3,0),"") | C26: =+A26 -> 0 | D26: =IFERROR(VLOOKUP(H26,'[1]Consolidado MP Planta'!$A$2:$M$823,13,0),"") | E26: =IFERROR(VLOOKUP(H26,'[1]Consolidado MP Planta'!$A$2:$M$823,12,0),"") | F26: =IFERROR(C26*E26,"") | G26: =IFERROR(F26/$F$65,"")
B27: =IFERROR(VLOOKUP(H27,'[1]Consolidado MP Planta'!$A$2:$M$823,3,0),"") | C27: =+A27 -> 0 | D27: =IFERROR(VLOOKUP(H27,'[1]Consolidado MP Planta'!$A$2:$M$823,13,0),"") | E27: =IFERROR(VLOOKUP(H27,'[1]Consolidado MP Planta'!$A$2:$M$823,12,0),"") | F27: =IFERROR(C27*E27,"") | G27: =IFERROR(F27/$F$65,"")
B28: =IFERROR(VLOOKUP(H28,'[1]Consolidado MP Planta'!$A$2:$M$823,3,0),"") | C28: =+A28 -> 0 | D28: =IFERROR(VLOOKUP(H28,'[1]Consolidado MP Planta'!$A$2:$M$823,13,0),"") | E28: =IFERROR(VLOOKUP(H28,'[1]Consolidado MP Planta'!$A$2:$M$823,12,0),"") | F28: =IFERROR(C28*E28,"") | G28: =IFERROR(F28/$F$65,"")
B29: =IFERROR(VLOOKUP(H29,'[1]Consolidado MP Planta'!$A$2:$M$823,3,0),"") | C29: =+A29 -> 0 | D29: =IFERROR(VLOOKUP(H29,'[1]Consolidado MP Planta'!$A$2:$M$823,13,0),"") | E29: =IFERROR(VLOOKUP(H29,'[1]Consolidado MP Planta'!$A$2:$M$823,12,0),"") | F29: =IFERROR(C29*E29,"") | G29: =IFERROR(F29/$F$65,"")
B30: =IFERROR(VLOOKUP(H30,'[1]Consolidado MP Planta'!$A$2:$M$823,3,0),"") | C30: =+A30 -> 0 | D30: =IFERROR(VLOOKUP(H30,'[1]Consolidado MP Planta'!$A$2:$M$823,13,0),"") | E30: =IFERROR(VLOOKUP(H30,'[1]Consolidado MP Planta'!$A$2:$M$823,12,0),"") | F30: =IFERROR(C30*E30,"") | G30: =IFERROR(F30/$F$65,"")
B31: =IFERROR(VLOOKUP(H31,'[1]Consolidado MP Planta'!$A$2:$M$823,3,0),"") | C31: =+A31 -> 0 | D31: =IFERROR(VLOOKUP(H31,'[1]Consolidado MP Planta'!$A$2:$M$823,13,0),"") | E31: =IFERROR(VLOOKUP(H31,'[1]Consolidado MP Planta'!$A$2:$M$823,12,0),"") | F31: =IFERROR(C31*E31,"") | G31: =IFERROR(F31/$F$65,"")
A33: UNIDADES | B33: EMPAQUE SEMIELABORADOS | C33: UNIDADES | D33: UND MEDIDA | E33: COSTO UNITARIO | F33: TOTAL COSTO | G33: % PREC. DEFINIDO | H33: CODIGOS
A34: =+A16 -> 0 | B34: =IFERROR(VLOOKUP(H34,[1]SEMIELABORADOS!$A$2:$M$6000,2,0),"") | C34: =+A34 -> 0 | D34: =IFERROR(VLOOKUP(H34,[1]SEMIELABORADOS!$A$2:$M$6000,6,0),"") | E34: =IFERROR(VLOOKUP(H34,[1]SEMIELABORADOS!$A$2:$M$65536,10,0),"") | F34: =IFERROR(E34*C34,"") | G34: =IFERROR(F34/$F$65,"")
A35: =+A17 -> 0 | B35: =IFERROR(VLOOKUP(H35,[1]SEMIELABORADOS!$A$2:$M$6000,2,0),"") | C35: =+A35 -> 0 | D35: =IFERROR(VLOOKUP(H35,[1]SEMIELABORADOS!$A$2:$M$6000,6,0),"") | E35: =IFERROR(VLOOKUP(H35,[1]SEMIELABORADOS!$A$2:$M$65536,10,0),"") | F35: =IFERROR(E35*C35,"") | G35: =IFERROR(F35/$F$65,"")
A36: =+A18 -> 0 | B36: =IFERROR(VLOOKUP(H36,[1]SEMIELABORADOS!$A$2:$M$6000,2,0),"") | C36: =+A36 -> 0 | D36: =IFERROR(VLOOKUP(H36,[1]SEMIELABORADOS!$A$2:$M$6000,6,0),"") | E36: =IFERROR(VLOOKUP(H36,[1]SEMIELABORADOS!$A$2:$M$65536,10,0),"") | F36: =IFERROR(E36*C36,"") | G36: =IFERROR(F36/$F$65,"")
A37: =+A19 -> 0 | B37: =IFERROR(VLOOKUP(H37,[1]SEMIELABORADOS!$A$2:$M$6000,2,0),"") | C37: =+A37 -> 0 | D37: =IFERROR(VLOOKUP(H37,[1]SEMIELABORADOS!$A$2:$M$6000,6,0),"") | E37: =IFERROR(VLOOKUP(H37,[1]SEMIELABORADOS!$A$2:$M$65536,10,0),"") | F37: =IFERROR(E37*C37,"") | G37: =IFERROR(F37/$F$65,"")
A38: =+A20 -> 0 | B38: =IFERROR(VLOOKUP(H38,[1]SEMIELABORADOS!$A$2:$M$6000,2,0),"") | C38: =+A38 -> 0 | D38: =IFERROR(VLOOKUP(H38,[1]SEMIELABORADOS!$A$2:$M$6000,6,0),"") | E38: =IFERROR(VLOOKUP(H38,[1]SEMIELABORADOS!$A$2:$M$65536,10,0),"") | F38: =IFERROR(E38*C38,"") | G38: =IFERROR(F38/$F$65,"")
A39: =+A21 -> 0 | B39: =IFERROR(VLOOKUP(H39,[1]SEMIELABORADOS!$A$2:$M$6000,2,0),"") | C39: =+A39 -> 0 | D39: =IFERROR(VLOOKUP(H39,[1]SEMIELABORADOS!$A$2:$M$6000,6,0),"") | E39: =IFERROR(VLOOKUP(H39,[1]SEMIELABORADOS!$A$2:$M$65536,10,0),"") | F39: =IFERROR(E39*C39,"") | G39: =IFERROR(F39/$F$65,"")
A40: =+A22 -> 0 | B40: =IFERROR(VLOOKUP(H40,[1]SEMIELABORADOS!$A$2:$M$6000,2,0),"") | C40: =+A40 -> 0 | D40: =IFERROR(VLOOKUP(H40,[1]SEMIELABORADOS!$A$2:$M$6000,6,0),"") | E40: =IFERROR(VLOOKUP(H40,[1]SEMIELABORADOS!$A$2:$M$65536,10,0),"") | F40: =IFERROR(E40*C40,"") | G40: =IFERROR(F40/$F$65,"")
A42: UNIDADES | B42: MODI | C42: UNIDADES | D42: UND MEDIDA | E42: COSTO UNITARIO | F42: TOTAL COSTO | G42: % PREC. DEFINIDO | H42: CODIGOS
A43: =+A34 -> 0 | B43: =IFERROR(VLOOKUP(H43,[1]SEMIELABORADOS!$A$2:$M$6000,2,0),"") | C43: =+A43 -> 0 | D43: =IFERROR(VLOOKUP(H43,[1]SEMIELABORADOS!$A$2:$M$6000,6,0),"") | E43: =IFERROR(VLOOKUP(H43,[1]SEMIELABORADOS!$A$2:$M$65536,12,0),"") | F43: =IFERROR(E43*C43,"") | G43: =IFERROR(F43/$F$65,"")
A44: =+A35 -> 0 | B44: =IFERROR(VLOOKUP(H44,[1]SEMIELABORADOS!$A$2:$M$6000,2,0),"") | C44: =+A44 -> 0 | D44: =IFERROR(VLOOKUP(H44,[1]SEMIELABORADOS!$A$2:$M$6000,6,0),"") | E44: =IFERROR(VLOOKUP(H44,[1]SEMIELABORADOS!$A$2:$M$65536,12,0),"") | F44: =IFERROR(E44*C44,"") | G44: =IFERROR(F44/$F$65,"")
A45: =+A36 -> 0 | B45: =IFERROR(VLOOKUP(H45,[1]SEMIELABORADOS!$A$2:$M$6000,2,0),"") | C45: =+A45 -> 0 | D45: =IFERROR(VLOOKUP(H45,[1]SEMIELABORADOS!$A$2:$M$6000,6,0),"") | E45: =IFERROR(VLOOKUP(H45,[1]SEMIELABORADOS!$A$2:$M$65536,12,0),"") | F45: =IFERROR(E45*C45,"") | G45: =IFERROR(F45/$F$65,"")
...

Sheet Rosquete
C1: SERVICIOS DE PASTELERIA S.A. | H1: CÓDIGO: | I1: ESP-RE-BAS-192
C2: ESPECIFICACION DE RECETA | H2: REVISIÓN: | I2: 2
C3: 907000333 (SE00519) Rosquete Red Velvet 300g | H3: FECHA DE APROBACIÓN: | I3: 45160
C4: Elaborado | D4: Javier Tong, Chef
C5: Aprobado | D5: Esteban Cartin, Gte Manufactura
A6: AREA QUE PRODUCE: | D6: Cocina | G6: AREA QUE EMPACA: | I6: Cocina
A7: # Código | B7: # Código Netsuite | C7: Descripción del ingrediente | D7: Marca | E7: Unidad Internacional | G7: Medida alternativa | I7: Costo - Referencia
E8: Cantidad | F8: Unidad medida | G8: Cantidad | H8: Unidad medida | I8: Colones
A9: 907000273 | B9: SE00517 | C9: BATIDO RED VELVET | D9: FAS | E9: 12000 | F9: g
A10: 902000019 | C10: MEZCLA P/ENGRASE MOLDES KILO | D10: FAS | E10: 1000 | F10: g
C11: EMPAQUE
A12: 1950928 | B12: AS00028 | C12: BOLSA TRANSPARENTE 56X96X1.80 KILO | D12: Plasticos P | E12: 3 | F12: ud
A13: 702007 | B13: EM10004 | C13: ETIQ.FECHA VENCIMIENTO BLANCO (ROLLO) | D13: Etiplast | E13: 3 | F13: ud
A14: 702069 | B14: EM10002 | C14: ETIQ.BLANCA 1 1/4 * 3/4 (UND) | D14: Cemusa | E14: 3 | F14: ud
D17: Cantidad | E17: Unidad
A18: PESO TOTAL OBTENIDO | D18: 11700 | E18: g | F18: Tiempo de Horneo: | H18: 17 Minutos
A19: TIEMPO TOTAL DE PREPARACION | D19: 16 | E19: min | F19: Horno: | H19: Vulcan
A20: CANTIDAD DE PORCIONES OBTENIDAS | D20: 39 | E20: ud | F20: Temperatura de Horneo: | H20: 160°C
A21: PESO DE CADA PORCIÓN | D21: 300 | E21: g | F21: Otros
A22: MERMA | D22: 300 | E22: g
A23: PROCEDIMIENTO DE PREPARACION DE LA RECETA
A24: 1.- Pesar 300g de mezcla en los moldes previamente engrasados.
A25: 2.- Hornear en cualquiera de los Dicte a 175°C por 45 a 50 minutos.
A26: 3.- Enfriar y empacar en lata, cubrir con bolsa y etiquetar con fecha de produccion.
A32: CONTROL DE CAMBIOS

Sheet Costo Rosquete
E1: Precio Local | F1: Costo MP | G1: Costo EM | H1: Costo MO
E2: =IFERROR(O62,"") -> 596.59268 | F2: =IFERROR(H53,"") -> 590.45253 | G2: =IFERROR(H54,"") -> 3.9164103 | H2: =IFERROR(H56,"") -> 47.360959
A5: ESTRUCTURA DE COSTOS
F6: Fecha: | H6: =TODAY() -> 46034
A7: UNIDADES | B7: DESCRIPCION MAT.PRIMA | C7: UNIDADES | D7: UND MEDIDA | E7: COSTO UNITARIO | F7: TOTAL COSTO | G7: % PREC. DEFINIDO | H7: CODIGOS
B8: =IFERROR(VLOOKUP(H8,'[1]Consolidado MP Planta'!$A$2:$M$823,3,0),"") | C8: =+A8 -> 0 | D8: =IFERROR(VLOOKUP(H8,'[1]Consolidado MP Planta'!$A$2:$M$823,13,0),"") | E8: =IFERROR(VLOOKUP(H8,'[1]Consolidado MP Planta'!$A$2:$M$823,12,0),"") | F8: =IFERROR(C8*E8,"") | G8: =IFERROR(F8/$F$66,"")
B9: =IFERROR(VLOOKUP(H9,'[1]Consolidado MP Planta'!$A$2:$M$823,3,0),"") | C9: =+A9 -> 0 | D9: =IFERROR(VLOOKUP(H9,'[1]Consolidado MP Planta'!$A$2:$M$823,13,0),"") | E9: =IFERROR(VLOOKUP(H9,'[1]Consolidado MP Planta'!$A$2:$M$823,12,0),"") | F9: =IFERROR(C9*E9,"") | G9: =IFERROR(F9/$F$66,"")
B10: =IFERROR(VLOOKUP(H10,'[1]Consolidado MP Planta'!$A$2:$M$823,3,0),"") | C10: =+A10 -> 0 | D10: =IFERROR(VLOOKUP(H10,'[1]Consolidado MP Planta'!$A$2:$M$823,13,0),"") | E10: =IFERROR(VLOOKUP(H10,'[1]Consolidado MP Planta'!$A$2:$M$823,12,0),"") | F10: =IFERROR(C10*E10,"") | G10: =IFERROR(F10/$F$66,"")
B11: =IFERROR(VLOOKUP(H11,'[1]Consolidado MP Planta'!$A$2:$M$823,3,0),"") | C11: =+A11 -> 0 | D11: =IFERROR(VLOOKUP(H11,'[1]Consolidado MP Planta'!$A$2:$M$823,13,0),"") | E11: =IFERROR(VLOOKUP(H11,'[1]Consolidado MP Planta'!$A$2:$M$823,12,0),"") | F11: =IFERROR(C11*E11,"") | G11: =IFERROR(F11/$F$66,"")
B12: =IFERROR(VLOOKUP(H12,'[1]Consolidado MP Planta'!$A$2:$M$823,3,0),"") | C12: =+A12 -> 0 | D12: =IFERROR(VLOOKUP(H12,'[1]Consolidado MP Planta'!$A$2:$M$823,13,0),"") | E12: =IFERROR(VLOOKUP(H12,'[1]Consolidado MP Planta'!$A$2:$M$823,12,0),"") | F12: =IFERROR(C12*E12,"") | G12: =IFERROR(F12/$F$66,"")
B13: =IFERROR(VLOOKUP(H13,'[1]Consolidado MP Planta'!$A$2:$M$823,3,0),"") | C13: =+A13 -> 0 | D13: =IFERROR(VLOOKUP(H13,'[1]Consolidado MP Planta'!$A$2:$M$823,13,0),"") | E13: =IFERROR(VLOOKUP(H13,'[1]Consolidado MP Planta'!$A$2:$M$823,12,0),"") | F13: =IFERROR(C13*E13,"") | G13: =IFERROR(F13/$F$66,"")
B14: =IFERROR(VLOOKUP(H14,'[1]Consolidado MP Planta'!$A$2:$M$823,3,0),"") | C14: =+A14 -> 0 | D14: =IFERROR(VLOOKUP(H14,'[1]Consolidado MP Planta'!$A$2:$M$823,13,0),"") | E14: =IFERROR(VLOOKUP(H14,'[1]Consolidado MP Planta'!$A$2:$M$823,12,0),"") | F14: =IFERROR(C14*E14,"") | G14: =IFERROR(F14/$F$66,"")
B15: =IFERROR(VLOOKUP(H15,'[2]ARTICULOS MP PLANTA'!$A$2:$G$589,2,0),"")
A16: UNIDADES | B16: MATERIA PRIMA SEMIELABORADOS | C16: UNIDADES | D16: UND MEDIDA | E16: COSTO UNITARIO | F16: TOTAL COSTO | G16: % PREC. DEFINIDO | H16: CODIGOS
A17: 12000 | B17: BATIDO RED VELVET | C17: =+A17 -> 12000 | D17: Gramos | E17: =+'Costo Batido'!E68 -> 1.7489707 | F17: =IFERROR(E17*C17,"") -> 20987.649 | G17: =IFERROR(F17/$F$66,"") -> 0.84379439 | H17: 907000273
A18: 1000 | B18: MEZCLA P/ENGRASE MOLDES KILO | C18: =+A18 -> 1000 | D18: Gramos | E18: 2.04 | F18: =IFERROR(E18*C18,"") -> 2040 | G18: =IFERROR(F18/$F$66,"") -> 0.082016837
B19: =IFERROR(VLOOKUP(H19,[1]SEMIELABORADOS!$A$2:$M$6000,2,0),"") | C19: =+A19 -> 0 | D19: =IFERROR(VLOOKUP(H19,[1]SEMIELABORADOS!$A$2:$M$6000,6,0),"") | E19: =IFERROR(VLOOKUP(H19,[1]SEMIELABORADOS!$A$2:$H$65536,8,0),"") | F19: =IFERROR(E19*C19,"") | G19: =IFERROR(F19/$F$66,"")
B20: =IFERROR(VLOOKUP(H20,[1]SEMIELABORADOS!$A$2:$M$6000,2,0),"") | C20: =+A20 -> 0 | D20: =IFERROR(VLOOKUP(H20,[1]SEMIELABORADOS!$A$2:$M$6000,6,0),"") | E20: =IFERROR(VLOOKUP(H20,[1]SEMIELABORADOS!$A$2:$H$65536,8,0),"") | F20: =IFERROR(E20*C20,"") | G20: =IFERROR(F20/$F$66,"")
B21: =IFERROR(VLOOKUP(H21,[1]SEMIELABORADOS!$A$2:$M$6000,2,0),"") | C21: =+A21 -> 0 | D21: =IFERROR(VLOOKUP(H21,[1]SEMIELABORADOS!$A$2:$M$6000,6,0),"") | E21: =IFERROR(VLOOKUP(H21,[1]SEMIELABORADOS!$A$2:$H$65536,8,0),"") | F21: =IFERROR(E21*C21,"") | G21: =IFERROR(F21/$F$66,"")
B22: =IFERROR(VLOOKUP(H22,[1]SEMIELABORADOS!$A$2:$M$6000,2,0),"") | C22: =+A22 -> 0 | D22: =IFERROR(VLOOKUP(H22,[1]SEMIELABORADOS!$A$2:$M$6000,6,0),"") | E22: =IFERROR(VLOOKUP(H22,[1]SEMIELABORADOS!$A$2:$H$65536,8,0),"") | F22: =IFERROR(E22*C22,"") | G22: =IFERROR(F22/$F$66,"")
B23: =IFERROR(VLOOKUP(H23,[1]SEMIELABORADOS!$A$2:$M$6000,2,0),"") | C23: =+A23 -> 0 | D23: =IFERROR(VLOOKUP(H23,[1]SEMIELABORADOS!$A$2:$M$6000,6,0),"") | E23: =IFERROR(VLOOKUP(H23,[1]SEMIELABORADOS!$A$2:$H$65536,8,0),"") | F23: =IFERROR(E23*C23,"") | G23: =IFERROR(F23/$F$66,"")
B24: =IFERROR(VLOOKUP(H24,[1]SEMIELABORADOS!$A$2:$M$6000,2,0),"") | C24: =+A24 -> 0 | D24: =IFERROR(VLOOKUP(H24,[1]SEMIELABORADOS!$A$2:$M$6000,6,0),"") | E24: =IFERROR(VLOOKUP(H24,[1]SEMIELABORADOS!$A$2:$H$65536,8,0),"") | F24: =IFERROR(E24*C24,"") | G24: =IFERROR(F24/$F$66,"")
A26: UNIDADES | B26: EMPAQUE | C26: UNIDADES | D26: UND MEDIDA | E26: COSTO UNITARIO | F26: TOTAL COSTO | G26: % PREC. DEFINIDO | H26: CODIGOS
A27: 3 | B27: =IFERROR(VLOOKUP(H27,'[1]Consolidado MP Planta'!$A$2:$M$823,3,0),"") -> BOLSA TRANSPARENTE 56X96X1.80 KILO | C27: =+A27 -> 3 | D27: =IFERROR(VLOOKUP(H27,'[1]Consolidado MP Planta'!$A$2:$M$823,13,0),"") -> Und | E27: =IFERROR(VLOOKUP(H27,'[1]Consolidado MP Planta'!$A$2:$M$823,12,0),"") -> 50 | F27: =IFERROR(C27*E27,"") -> 150 | G27: =IFERROR(F27/$F$66,"") -> 0.0060306498 | H27: 1950928
A28: 3 | B28: =IFERROR(VLOOKUP(H28,'[1]Consolidado MP Planta'!$A$2:$M$823,3,0),"") -> ETIQ.FECHA VENCIMIENTO BLANCO (ROLLO) | C28: =+A28 -> 3 | D28: =IFERROR(VLOOKUP(H28,'[1]Consolidado MP Planta'!$A$2:$M$823,13,0),"") -> Gramos | E28: =IFERROR(VLOOKUP(H28,'[1]Consolidado MP Planta'!$A$2:$M$823,12,0),"") -> 0.33333333 | F28: =IFERROR(C28*E28,"") -> 1 | G28: =IFERROR(F28/$F$66,"") -> 4.0204332e-05 | H28: 0702007
A29: 3 | B29: =IFERROR(VLOOKUP(H29,'[1]Consolidado MP Planta'!$A$2:$M$823,3,0),"") -> ETIQ.BLANCA 1 1/4 * 3/4 (UND) | C29: =+A29 -> 3 | D29: =IFERROR(VLOOKUP(H29,'[1]Consolidado MP Planta'!$A$2:$M$823,13,0),"") -> Und | E29: =IFERROR(VLOOKUP(H29,'[1]Consolidado MP Planta'!$A$2:$M$823,12,0),"") -> 0.58 | F29: =IFERROR(C29*E29,"") -> 1.74 | G29: =IFERROR(F29/$F$66,"") -> 6.9955538e-05 | H29: 0702069
B30: =IFERROR(VLOOKUP(H30,'[1]Consolidado MP Planta'!$A$2:$M$823,3,0),"") | C30: =+A30 -> 0 | D30: =IFERROR(VLOOKUP(H30,'[1]Consolidado MP Planta'!$A$2:$M$823,13,0),"") | E30: =IFERROR(VLOOKUP(H30,'[1]Consolidado MP Planta'!$A$2:$M$823,12,0),"") | F30: =IFERROR(C30*E30,"") | G30: =IFERROR(F30/$F$66,"")
B31: =IFERROR(VLOOKUP(H31,'[1]Consolidado MP Planta'!$A$2:$M$823,3,0),"") | C31: =+A31 -> 0 | D31: =IFERROR(VLOOKUP(H31,'[1]Consolidado MP Planta'!$A$2:$M$823,13,0),"") | E31: =IFERROR(VLOOKUP(H31,'[1]Consolidado MP Planta'!$A$2:$M$823,12,0),"") | F31: =IFERROR(C31*E31,"") | G31: =IFERROR(F31/$F$66,"")
B32: =IFERROR(VLOOKUP(H32,'[1]Consolidado MP Planta'!$A$2:$M$823,3,0),"") | C32: =+A32 -> 0 | D32: =IFERROR(VLOOKUP(H32,'[1]Consolidado MP Planta'!$A$2:$M$823,13,0),"") | E32: =IFERROR(VLOOKUP(H32,'[1]Consolidado MP Planta'!$A$2:$M$823,12,0),"") | F32: =IFERROR(C32*E32,"") | G32: =IFERROR(F32/$F$66,"")
A34: UNIDADES | B34: EMPAQUE SEMIELABORADOS | C34: UNIDADES | D34: UND MEDIDA | E34: COSTO UNITARIO | F34: TOTAL COSTO | G34: % PREC. DEFINIDO | H34: CODIGOS
A35: =+A17 -> 12000 | B35: BATIDO RED VELVET | C35: =+A35 -> 12000 | D35: Gramos | E35: =+'Costo Batido'!E75 -> 0 | F35: =IFERROR(E35*C35,"") -> 0 | G35: =IFERROR(F35/$F$66,"") -> 0 | H35: 907000273
A36: =+A18 -> 1000 | B36: MEZCLA P/ENGRASE MOLDES KILO | C36: =+A36 -> 1000 | D36: Gramos | E36: 0 | F36: =IFERROR(E36*C36,"") -> 0 | G36: =IFERROR(F36/$F$66,"") -> 0
A37: =+A19 -> 0 | B37: =IFERROR(VLOOKUP(H37,[1]SEMIELABORADOS!$A$2:$M$6000,2,0),"") | C37: =+A37 -> 0 | D37: =IFERROR(VLOOKUP(H37,[1]SEMIELABORADOS!$A$2:$M$6000,6,0),"") | E37: =IFERROR(VLOOKUP(H37,[1]SEMIELABORADOS!$A$2:$M$65536,10,0),"") | F37: =IFERROR(E37*C37,"") | G37: =IFERROR(F37/$F$66,"")
A38: =+A20 -> 0 | B38: =IFERROR(VLOOKUP(H38,[1]SEMIELABORADOS!$A$2:$M$6000,2,0),"") | C38: =+A38 -> 0 | D38: =IFERROR(VLOOKUP(H38,[1]SEMIELABORADOS!$A$2:$M$6000,6,0),"") | E38: =IFERROR(VLOOKUP(H38,[1]SEMIELABORADOS!$A$2:$M$65536,10,0),"") | F38: =IFERROR(E38*C38,"") | G38: =IFERROR(F38/$F$66,"")
A39: =+A21 -> 0 | B39: =IFERROR(VLOOKUP(H39,[1]SEMIELABORADOS!$A$2:$M$6000,2,0),"") | C39: =+A39 -> 0 | D39: =IFERROR(VLOOKUP(H39,[1]SEMIELABORADOS!$A$2:$M$6000,6,0),"") | E39: =IFERROR(VLOOKUP(H39,[1]SEMIELABORADOS!$A$2:$M$65536,10,0),"") | F39: =IFERROR(E39*C39,"") | G39: =IFERROR(F39/$F$66,"")
A40: =+A22 -> 0 | B40: =IFERROR(VLOOKUP(H40,[1]SEMIELABORADOS!$A$2:$M$6000,2,0),"") | C40: =+A40 -> 0 | D40: =IFERROR(VLOOKUP(H40,[1]SEMIELABORADOS!$A$2:$M$6000,6,0),"") | E40: =IFERROR(VLOOKUP(H40,[1]SEMIELABORADOS!$A$2:$M$65536,10,0),"") | F40: =IFERROR(E40*C40,"") | G40: =IFERROR(F40/$F$66,"")
A41: =+A23 -> 0 | B41: =IFERROR(VLOOKUP(H41,[1]SEMIELABORADOS!$A$2:$M$6000,2,0),"") | C41: =+A41 -> 0 | D41: =IFERROR(VLOOKUP(H41,[1]SEMIELABORADOS!$A$2:$M$6000,6,0),"") | E41: =IFERROR(VLOOKUP(H41,[1]SEMIELABORADOS!$A$2:$M$65536,10,0),"") | F41: =IFERROR(E41*C41,"") | G41: =IFERROR(F41/$F$66,"")
A43: UNIDADES | B43: MODI | C43: UNIDADES | D43: UND MEDIDA | E43: COSTO UNITARIO | F43: TOTAL COSTO | G43: % PREC. DEFINIDO | H43: CODIGOS
A44: =+A35 -> 12000 | B44: BATIDO RED VELVET | C44: =+A44 -> 12000 | D44: Gramos | E44: =+'Costo Batido'!E73 -> 0.051256449 | F44: =IFERROR(E44*C44,"") -> 615.07738 | G44: =IFERROR(F44/$F$66,"") -> 0.024728775 | H44: 907000273
A45: =+A36 -> 1000 | B45: MEZCLA P/ENGRASE MOLDES KILO | C45: =+A45 -> 1000 | D45: Gramos | E45: 0 | F45: =IFERROR(E45*C45,"") -> 0 | G45: =IFERROR(F45/$F$66,"") -> 0
...

Sheet Crema Chantilly 
C1: SERVICIOS DE PASTELERIA S.A. | H1: CÓDIGO: | I1: ESP-RE-DES-018
C2: ESPECIFICACION DE RECETA | H2: REVISIÓN: | I2: 02
C3: Crema Blanca Spoon (20800g) SE00010 | H3: FECHA DE APROBACIÓN: | I3: 45613
C4: Elaborado | D4: Javier Tong, Chef
C5: Aprobado | D5: Esteban Cartin, Gte Manufactura
A6: AREA QUE PRODUCE: | D6: Decoración | G6: AREA QUE EMPACA: | I6: Decoracion
A7: # Código | B7: # Código Netsuite | C7: Descripción del ingrediente | D7: Marca | E7: Unidad Internacional | G7: Medida alternativa | I7: Costo - Referencia
E8: Cantidad | F8: Unidad medida | G8: Cantidad | H8: Unidad medida | I8: Colones
C9: Ensamble
A10: 310148 | B10: MP10047 | C10: BETTERCREME SUPREMO (UND:4 K) | D10: RICHS | E10: 12800 | F10: g
A11: 11400031 | B11: MP10048 | C11: CREMA PRESTIGE GRAND (UND:4 K) | D11: RICHS | E11: 3200 | F11: g
A12: 10415 | C12: AGUA POTABLE (PLANTA) | D12: AYA | E12: 800 | F12: g
A13: 1212410 | B13: MP10008 | C13: PRESERVANTE 1047S (PAQ=5 KILO) | D13: ASEAL | E13: 12 | F13: g
C20: Decoración
C29: Empaque
A30: 702123 | B30: EM10011 | C30: ETIQUETA BLANCA 2 5/8X1 15/16 (UND) | D30: Etiplas | E30: 1 | F30: ud
D40: Cantidad | E40: Unidad
A41: PESO TOTAL OBTENIDO | D41: 16597 | E41: g | F41: Tiempo de Horneo:
A42: TIEMPO TOTAL DE PREPARACION | D42: 17 | E42: min | F42: Horno:
A43: CANTIDAD DE PORCIONES OBTENIDAS | D43: 1 | E43: Tanda | F43: Temperatura de Horneo:
A44: PESO DE CADA PORCIÓN | D44: 16597 | E44: g | F44: Otros
A45: MERMA | D45: 215 | E45: g
A46: PROCEDIMIENTO DE PREPARACION DE LA RECETA
A47: 1.- Abrir los galones de crema y verter dentro de la top cream. (Temperatura 5° liquida )
A48: 2.- Disolver el preservante en el agua. Agregar a la top cream.
A49: 3.- Batir por 17 minutos. Una ves lista (Temperatura 18° batida) Colocar en una tina plastica, tapar.
A50: 4.- Etiquetar con nombre y fecha de vencimiento.
A51: 5.- Mantener en refrigeración hasta su uso.
A56: CONTROL DE CAMBIOS
A57: 2, Actualización tiempo de preparación y procedimiento

Sheet costo Mouse Queso
E1: Precio Local | F1: Costo MP | G1: Costo EM | H1: Costo MO
E2: =IFERROR(O59,"") -> 17544.67 | F2: =IFERROR(H50,"") -> 16850.8 | G2: =IFERROR(H51,"") -> 20 | H2: =IFERROR(H53,"") -> 368
A5: ESTRUCTURA DE COSTOS
F6: Fecha: | H6: =TODAY() -> 46034
A7: UNIDADES | B7: DESCRIPCION MAT.PRIMA | C7: UNIDADES | D7: UND MEDIDA | E7: COSTO UNITARIO | F7: TOTAL COSTO | G7: % PREC. DEFINIDO | H7: CODIGOS
A8: 3000 | B8: Queso Crema Panadero | C8: =+A8 -> 3000 | D8: Gramos | E8: 3.07 | F8: =IFERROR(C8*E8,"") -> 9210 | G8: =IFERROR(F8/$F$63,"") -> 0.5258105 | H8: MP10046
A9: 10 | B9: Limon En Polvo | C9: =+A9 -> 10 | D9: Gramos | E9: 6 | F9: =IFERROR(C9*E9,"") -> 60 | G9: =IFERROR(F9/$F$63,"") -> 0.0034254756 | H9: MP10239
A10: 1000 | B10: Leche Condensada | C10: =+A10 -> 1000 | D10: Gramos | E10: 2.2 | F10: =IFERROR(C10*E10,"") -> 2200 | G10: =IFERROR(F10/$F$63,"") -> 0.12560077 | H10: MP10050
A11: 80 | B11: Gelatina Pura | C11: =+A11 -> 80 | D11: Gramos | E11: 13.01 | F11: =IFERROR(C11*E11,"") -> 1040.8 | G11: =IFERROR(F11/$F$63,"") -> 0.059420583 | H11: MP10043
B12: =IFERROR(VLOOKUP(H12,'[2]ARTICULOS MP PLANTA'!$A$2:$G$589,2,0),"")
A13: UNIDADES | B13: MATERIA PRIMA SEMIELABORADOS | C13: UNIDADES | D13: UND MEDIDA | E13: COSTO UNITARIO | F13: TOTAL COSTO | G13: % PREC. DEFINIDO | H13: CODIGOS
A14: 2000 | B14: Crema Chantilly Blanca (Spoon-Ind) | C14: =+A14 -> 2000 | D14: Gramos | E14: 2.17 | F14: =IFERROR(E14*C14,"") -> 4340 | G14: =IFERROR(F14/$F$63,"") -> 0.24777607 | H14: SE00010
B15: =IFERROR(VLOOKUP(H15,[1]SEMIELABORADOS!$A$2:$M$6000,2,0),"") | C15: =+A15 -> 0 | D15: =IFERROR(VLOOKUP(H15,[1]SEMIELABORADOS!$A$2:$M$6000,6,0),"") | E15: =IFERROR(VLOOKUP(H15,[1]SEMIELABORADOS!$A$2:$H$65536,8,0),"") | F15: =IFERROR(E15*C15,"") | G15: =IFERROR(F15/$F$63,"")
B16: =IFERROR(VLOOKUP(H16,[1]SEMIELABORADOS!$A$2:$M$6000,2,0),"") | C16: =+A16 -> 0 | D16: =IFERROR(VLOOKUP(H16,[1]SEMIELABORADOS!$A$2:$M$6000,6,0),"") | E16: =IFERROR(VLOOKUP(H16,[1]SEMIELABORADOS!$A$2:$H$65536,8,0),"") | F16: =IFERROR(E16*C16,"") | G16: =IFERROR(F16/$F$63,"")
B17: =IFERROR(VLOOKUP(H17,[1]SEMIELABORADOS!$A$2:$M$6000,2,0),"") | C17: =+A17 -> 0 | D17: =IFERROR(VLOOKUP(H17,[1]SEMIELABORADOS!$A$2:$M$6000,6,0),"") | E17: =IFERROR(VLOOKUP(H17,[1]SEMIELABORADOS!$A$2:$H$65536,8,0),"") | F17: =IFERROR(E17*C17,"") | G17: =IFERROR(F17/$F$63,"")
B18: =IFERROR(VLOOKUP(H18,[1]SEMIELABORADOS!$A$2:$M$6000,2,0),"") | C18: =+A18 -> 0 | D18: =IFERROR(VLOOKUP(H18,[1]SEMIELABORADOS!$A$2:$M$6000,6,0),"") | E18: =IFERROR(VLOOKUP(H18,[1]SEMIELABORADOS!$A$2:$H$65536,8,0),"") | F18: =IFERROR(E18*C18,"") | G18: =IFERROR(F18/$F$63,"")
B19: =IFERROR(VLOOKUP(H19,[1]SEMIELABORADOS!$A$2:$M$6000,2,0),"") | C19: =+A19 -> 0 | D19: =IFERROR(VLOOKUP(H19,[1]SEMIELABORADOS!$A$2:$M$6000,6,0),"") | E19: =IFERROR(VLOOKUP(H19,[1]SEMIELABORADOS!$A$2:$H$65536,8,0),"") | F19: =IFERROR(E19*C19,"") | G19: =IFERROR(F19/$F$63,"")
B20: =IFERROR(VLOOKUP(H20,[1]SEMIELABORADOS!$A$2:$M$6000,2,0),"") | C20: =+A20 -> 0 | D20: =IFERROR(VLOOKUP(H20,[1]SEMIELABORADOS!$A$2:$M$6000,6,0),"") | E20: =IFERROR(VLOOKUP(H20,[1]SEMIELABORADOS!$A$2:$H$65536,8,0),"") | F20: =IFERROR(E20*C20,"") | G20: =IFERROR(F20/$F$63,"")
B21: =IFERROR(VLOOKUP(H21,[1]SEMIELABORADOS!$A$2:$M$6000,2,0),"") | C21: =+A21 -> 0 | D21: =IFERROR(VLOOKUP(H21,[1]SEMIELABORADOS!$A$2:$M$6000,6,0),"") | E21: =IFERROR(VLOOKUP(H21,[1]SEMIELABORADOS!$A$2:$H$65536,8,0),"") | F21: =IFERROR(E21*C21,"") | G21: =IFERROR(F21/$F$63,"")
A23: UNIDADES | B23: EMPAQUE | C23: UNIDADES | D23: UND MEDIDA | E23: COSTO UNITARIO | F23: TOTAL COSTO | G23: % PREC. DEFINIDO | H23: CODIGOS
A24: 0 | B24: =IFERROR(VLOOKUP(H24,'[1]Consolidado MP Planta'!$A$2:$M$823,3,0),"") | C24: =+A24 -> 0 | D24: =IFERROR(VLOOKUP(H24,'[1]Consolidado MP Planta'!$A$2:$M$823,13,0),"") | E24: =IFERROR(VLOOKUP(H24,'[1]Consolidado MP Planta'!$A$2:$M$823,12,0),"") | F24: =IFERROR(C24*E24,"") | G24: =IFERROR(F24/$F$63,"")
B25: =IFERROR(VLOOKUP(H25,'[1]Consolidado MP Planta'!$A$2:$M$823,3,0),"") | C25: =+A25 -> 0 | D25: =IFERROR(VLOOKUP(H25,'[1]Consolidado MP Planta'!$A$2:$M$823,13,0),"") | E25: =IFERROR(VLOOKUP(H25,'[1]Consolidado MP Planta'!$A$2:$M$823,12,0),"") | F25: =IFERROR(C25*E25,"") | G25: =IFERROR(F25/$F$63,"")
B26: =IFERROR(VLOOKUP(H26,'[1]Consolidado MP Planta'!$A$2:$M$823,3,0),"") | C26: =+A26 -> 0 | D26: =IFERROR(VLOOKUP(H26,'[1]Consolidado MP Planta'!$A$2:$M$823,13,0),"") | E26: =IFERROR(VLOOKUP(H26,'[1]Consolidado MP Planta'!$A$2:$M$823,12,0),"") | F26: =IFERROR(C26*E26,"") | G26: =IFERROR(F26/$F$63,"")
B27: =IFERROR(VLOOKUP(H27,'[1]Consolidado MP Planta'!$A$2:$M$823,3,0),"") | C27: =+A27 -> 0 | D27: =IFERROR(VLOOKUP(H27,'[1]Consolidado MP Planta'!$A$2:$M$823,13,0),"") | E27: =IFERROR(VLOOKUP(H27,'[1]Consolidado MP Planta'!$A$2:$M$823,12,0),"") | F27: =IFERROR(C27*E27,"") | G27: =IFERROR(F27/$F$63,"")
B28: =IFERROR(VLOOKUP(H28,'[1]Consolidado MP Planta'!$A$2:$M$823,3,0),"") | C28: =+A28 -> 0 | D28: =IFERROR(VLOOKUP(H28,'[1]Consolidado MP Planta'!$A$2:$M$823,13,0),"") | E28: =IFERROR(VLOOKUP(H28,'[1]Consolidado MP Planta'!$A$2:$M$823,12,0),"") | F28: =IFERROR(C28*E28,"") | G28: =IFERROR(F28/$F$63,"")
B29: =IFERROR(VLOOKUP(H29,'[1]Consolidado MP Planta'!$A$2:$M$823,3,0),"") | C29: =+A29 -> 0 | D29: =IFERROR(VLOOKUP(H29,'[1]Consolidado MP Planta'!$A$2:$M$823,13,0),"") | E29: =IFERROR(VLOOKUP(H29,'[1]Consolidado MP Planta'!$A$2:$M$823,12,0),"") | F29: =IFERROR(C29*E29,"") | G29: =IFERROR(F29/$F$63,"")
A31: UNIDADES | B31: EMPAQUE SEMIELABORADOS | C31: UNIDADES | D31: UND MEDIDA | E31: COSTO UNITARIO | F31: TOTAL COSTO | G31: % PREC. DEFINIDO | H31: CODIGOS
A32: =+A14 -> 2000 | B32: Crema Chantilly Blanca (Spoon-Ind) | C32: =+A32 -> 2000 | D32: Gramos | E32: 0.01 | F32: =IFERROR(E32*C32,"") -> 20 | G32: =IFERROR(F32/$F$63,"") -> 0.0011418252 | H32: SE00010
A33: =+A15 -> 0 | B33: =IFERROR(VLOOKUP(H33,[1]SEMIELABORADOS!$A$2:$M$6000,2,0),"") | C33: =+A33 -> 0 | D33: =IFERROR(VLOOKUP(H33,[1]SEMIELABORADOS!$A$2:$M$6000,6,0),"") | E33: =IFERROR(VLOOKUP(H33,[1]SEMIELABORADOS!$A$2:$M$65536,10,0),"") | F33: =IFERROR(E33*C33,"") | G33: =IFERROR(F33/$F$63,"")
A34: =+A16 -> 0 | B34: =IFERROR(VLOOKUP(H34,[1]SEMIELABORADOS!$A$2:$M$6000,2,0),"") | C34: =+A34 -> 0 | D34: =IFERROR(VLOOKUP(H34,[1]SEMIELABORADOS!$A$2:$M$6000,6,0),"") | E34: =IFERROR(VLOOKUP(H34,[1]SEMIELABORADOS!$A$2:$M$65536,10,0),"") | F34: =IFERROR(E34*C34,"") | G34: =IFERROR(F34/$F$63,"")
A35: =+A17 -> 0 | B35: =IFERROR(VLOOKUP(H35,[1]SEMIELABORADOS!$A$2:$M$6000,2,0),"") | C35: =+A35 -> 0 | D35: =IFERROR(VLOOKUP(H35,[1]SEMIELABORADOS!$A$2:$M$6000,6,0),"") | E35: =IFERROR(VLOOKUP(H35,[1]SEMIELABORADOS!$A$2:$M$65536,10,0),"") | F35: =IFERROR(E35*C35,"") | G35: =IFERROR(F35/$F$63,"")
A36: =+A18 -> 0 | B36: =IFERROR(VLOOKUP(H36,[1]SEMIELABORADOS!$A$2:$M$6000,2,0),"") | C36: =+A36 -> 0 | D36: =IFERROR(VLOOKUP(H36,[1]SEMIELABORADOS!$A$2:$M$6000,6,0),"") | E36: =IFERROR(VLOOKUP(H36,[1]SEMIELABORADOS!$A$2:$M$65536,10,0),"") | F36: =IFERROR(E36*C36,"") | G36: =IFERROR(F36/$F$63,"")
A37: =+A19 -> 0 | B37: =IFERROR(VLOOKUP(H37,[1]SEMIELABORADOS!$A$2:$M$6000,2,0),"") | C37: =+A37 -> 0 | D37: =IFERROR(VLOOKUP(H37,[1]SEMIELABORADOS!$A$2:$M$6000,6,0),"") | E37: =IFERROR(VLOOKUP(H37,[1]SEMIELABORADOS!$A$2:$M$65536,10,0),"") | F37: =IFERROR(E37*C37,"") | G37: =IFERROR(F37/$F$63,"")
A38: =+A20 -> 0 | B38: =IFERROR(VLOOKUP(H38,[1]SEMIELABORADOS!$A$2:$M$6000,2,0),"") | C38: =+A38 -> 0 | D38: =IFERROR(VLOOKUP(H38,[1]SEMIELABORADOS!$A$2:$M$6000,6,0),"") | E38: =IFERROR(VLOOKUP(H38,[1]SEMIELABORADOS!$A$2:$M$65536,10,0),"") | F38: =IFERROR(E38*C38,"") | G38: =IFERROR(F38/$F$63,"")
A40: UNIDADES | B40: MODI | C40: UNIDADES | D40: UND MEDIDA | E40: COSTO UNITARIO | F40: TOTAL COSTO | G40: % PREC. DEFINIDO | H40: CODIGOS
A41: =+A32 -> 2000 | B41: Crema Chantilly Blanca (Spoon-Ind) | C41: =+A41 -> 2000 | D41: Gramos | E41: 0.03 | F41: =IFERROR(E41*C41,"") -> 60 | G41: =IFERROR(F41/$F$63,"") -> 0.0034254756 | H41: SE00010
A42: =+A33 -> 0 | B42: =IFERROR(VLOOKUP(H42,[1]SEMIELABORADOS!$A$2:$M$6000,2,0),"") | C42: =+A42 -> 0 | D42: =IFERROR(VLOOKUP(H42,[1]SEMIELABORADOS!$A$2:$M$6000,6,0),"") | E42: =IFERROR(VLOOKUP(H42,[1]SEMIELABORADOS!$A$2:$M$65536,12,0),"") | F42: =IFERROR(E42*C42,"") | G42: =IFERROR(F42/$F$63,"")
A43: =+A34 -> 0 | B43: =IFERROR(VLOOKUP(H43,[1]SEMIELABORADOS!$A$2:$M$6000,2,0),"") | C43: =+A43 -> 0 | D43: =IFERROR(VLOOKUP(H43,[1]SEMIELABORADOS!$A$2:$M$6000,6,0),"") | E43: =IFERROR(VLOOKUP(H43,[1]SEMIELABORADOS!$A$2:$M$65536,12,0),"") | F43: =IFERROR(E43*C43,"") | G43: =IFERROR(F43/$F$63,"")
A44: =+A35 -> 0 | B44: =IFERROR(VLOOKUP(H44,[1]SEMIELABORADOS!$A$2:$M$6000,2,0),"") | C44: =+A44 -> 0 | D44: =IFERROR(VLOOKUP(H44,[1]SEMIELABORADOS!$A$2:$M$6000,6,0),"") | E44: =IFERROR(VLOOKUP(H44,[1]SEMIELABORADOS!$A$2:$M$65536,12,0),"") | F44: =IFERROR(E44*C44,"") | G44: =IFERROR(F44/$F$63,"")
A45: =+A36 -> 0 | B45: =IFERROR(VLOOKUP(H45,[1]SEMIELABORADOS!$A$2:$M$6000,2,0),"") | C45: =+A45 -> 0 | D45: =IFERROR(VLOOKUP(H45,[1]SEMIELABORADOS!$A$2:$M$6000,6,0),"") | E45: =IFERROR(VLOOKUP(H45,[1]SEMIELABORADOS!$A$2:$M$65536,12,0),"") | F45: =IFERROR(E45*C45,"") | G45: =IFERROR(F45/$F$63,"")
...

Sheet Ensamble
C1: SERVICIOS DE PASTELERIA S.A. | H1: CÓDIGO: | I1: ESP-RE-POS-116
C2: ESPECIFICACION DE RECETA | H2: REVISIÓN: | I2: 01
C3: PTI00265 Postre velvet frutos rojos | H3: FECHA DE APROBACIÓN: | I3: 45985
C4: Elaborado | D4: Juan Pablo Brenes, Chef
C5: Aprobado | D5: Esteban Cartin, Gte Manufactura
A6: AREA QUE PRODUCE: | D6: POSTRES | G6: AREA QUE EMPACA: | I6: POSTRES
A7: # Código | B7: # Código Netsuite | C7: Descripción del ingrediente | D7: Marca | E7: Unidad Internacional | G7: Medida alternativa | I7: Costo - Referencia
E8: Cantidad | F8: Unidad medida | G8: Cantidad | H8: Unidad medida | I8: Colones | K8: x
B9: SE00519 | C9: Rosquete Red Velvet 300g | D9: FAS | E9: 132 | F9: g | H9: 1/2 unidad
B10: SE00769 | C10: MOUSSE QUESO VELVET | D10: FAS | E10: 280 | F10: g
B11: MP10007 | C11: Manjar Leche Condensada | D11: Nestle | E11: 95 | F11: g | H11: 1/3 taza
B12: SE00541 | C12: RELLENO FRAMBUESA Y ARANDANO | D12: fas | E12: 95 | F12: g | H12: 1/3 taza
C14: Decoracion
B15: MP10007 | C15: Manjar Leche Condensada | D15: Nestle | E15: 70 | F15: g | H15: Boquilla 805
B16: SE00541 | C16: RELLENO FRAMBUESA Y ARANDANO | D16: Fas | E16: 150 | F16: g | H16: 1/2 taza
C18: Empaque
B19: EM10455 | C19: QUEQUERA REDONDA CON BASE 7 ALTA | E19: 1 | F19: ud
B20: NUEVO | C20: ETIQUETA POSTRE | E20: 1 | F20: ud
A21: 702069 | B21: EM10002 | C21: ETIQ.BLANCA 1 1/4 * 3/4 | D21: ETIPLAST | E21: 1 | F21: ud
A22: 703020 | B22: EM10248 | C22: CINTA ADHESIVA TRANSPARENT 2*100 M (UND) | D22: MAYCA | E22: 60 | F22: cm
A23: 701096 | B23: EM10124 | C23: ETIQUETA BLANCA R-153 (UND) | D23: CEMUSA | E23: 1 | F23: ud
A24: 702123 | B24: EM10011 | C24: ETIQUETA BLANCA 2 5/8X1 15/16 (UND) | D24: ETIPLAST | E24: 1 | F24: ud
D26: Cantidad | E26: Unidad
A27: PESO TOTAL OBTENIDO | D27: 820 | E27: g | F27: Tiempo de Horneo:
A28: TIEMPO TOTAL DE PREPARACION | D28: 8 | E28: min | F28: Horno:
A29: CANTIDAD DE PORCIONES OBTENIDAS | D29: 1 | E29: ud | F29: Temperatura de Horneo:
A30: PESO DE CADA PORCIÓN | D30: 820 | E30: g | F30: Otros
A31: MERMA | D31: =SUM(E9:E16)-D27 -> 2 | E31: g
A32: PROCEDIMIENTO DE PREPARACION DE LA RECETA
A33: 1.- En el molde mini engrasado colocar el medio rosquete de velvet.
A34: 2.- Luego colocar 1/3 taza de manjar y 1/3 taza de relleno frutos rojos, y por ultimo 280g de mousse queso
A35: 3.- Desmoldar y decorar con colochos de manjar al borde y el relleno de frutos rojos al centro.
A36: 4.- Tapar y etiquetar
A38: CONTROL DE CAMBIOS

Sheet Costo Ensamble
E1: Precio Local | F1: Costo MP | G1: Costo EM | H1: Costo MO
E2: =IFERROR(O62,"") -> 3583.7495 | F2: =IFERROR(H53,"") -> 2058.2827 | G2: =IFERROR(H54,"") -> 338.17006 | H2: =IFERROR(H56,"") -> 648.38188
A5: ESTRUCTURA DE COSTOS
F6: Fecha: | H6: =TODAY() -> 46034
A7: UNIDADES | B7: DESCRIPCION MAT.PRIMA | C7: UNIDADES | D7: UND MEDIDA | E7: COSTO UNITARIO | F7: TOTAL COSTO | G7: % PREC. DEFINIDO | H7: CODIGOS
A8: 165 | B8: Manjar Leche Condensada | C8: =+A8 -> 165 | D8: Gramos | E8: 2.56 | F8: =IFERROR(C8*E8,"") -> 422.4 | G8: =IFERROR(F8/$F$66,"") -> 0.13832769 | H8: MP10007
B9: =IFERROR(VLOOKUP(H9,'[1]Consolidado MP Planta'!$A$2:$M$823,3,0),"") | C9: =+A9 -> 0 | D9: =IFERROR(VLOOKUP(H9,'[1]Consolidado MP Planta'!$A$2:$M$823,13,0),"") | E9: =IFERROR(VLOOKUP(H9,'[1]Consolidado MP Planta'!$A$2:$M$823,12,0),"") | F9: =IFERROR(C9*E9,"") | G9: =IFERROR(F9/$F$66,"")
B10: =IFERROR(VLOOKUP(H10,'[1]Consolidado MP Planta'!$A$2:$M$823,3,0),"") | C10: =+A10 -> 0 | D10: =IFERROR(VLOOKUP(H10,'[1]Consolidado MP Planta'!$A$2:$M$823,13,0),"") | E10: =IFERROR(VLOOKUP(H10,'[1]Consolidado MP Planta'!$A$2:$M$823,12,0),"") | F10: =IFERROR(C10*E10,"") | G10: =IFERROR(F10/$F$66,"")
B11: =IFERROR(VLOOKUP(H11,'[1]Consolidado MP Planta'!$A$2:$M$823,3,0),"") | C11: =+A11 -> 0 | D11: =IFERROR(VLOOKUP(H11,'[1]Consolidado MP Planta'!$A$2:$M$823,13,0),"") | E11: =IFERROR(VLOOKUP(H11,'[1]Consolidado MP Planta'!$A$2:$M$823,12,0),"") | F11: =IFERROR(C11*E11,"") | G11: =IFERROR(F11/$F$66,"")
B12: =IFERROR(VLOOKUP(H12,'[1]Consolidado MP Planta'!$A$2:$M$823,3,0),"") | C12: =+A12 -> 0 | D12: =IFERROR(VLOOKUP(H12,'[1]Consolidado MP Planta'!$A$2:$M$823,13,0),"") | E12: =IFERROR(VLOOKUP(H12,'[1]Consolidado MP Planta'!$A$2:$M$823,12,0),"") | F12: =IFERROR(C12*E12,"") | G12: =IFERROR(F12/$F$66,"")
B13: =IFERROR(VLOOKUP(H13,'[1]Consolidado MP Planta'!$A$2:$M$823,3,0),"") | C13: =+A13 -> 0 | D13: =IFERROR(VLOOKUP(H13,'[1]Consolidado MP Planta'!$A$2:$M$823,13,0),"") | E13: =IFERROR(VLOOKUP(H13,'[1]Consolidado MP Planta'!$A$2:$M$823,12,0),"") | F13: =IFERROR(C13*E13,"") | G13: =IFERROR(F13/$F$66,"")
B14: =IFERROR(VLOOKUP(H14,'[1]Consolidado MP Planta'!$A$2:$M$823,3,0),"") | C14: =+A14 -> 0 | D14: =IFERROR(VLOOKUP(H14,'[1]Consolidado MP Planta'!$A$2:$M$823,13,0),"") | E14: =IFERROR(VLOOKUP(H14,'[1]Consolidado MP Planta'!$A$2:$M$823,12,0),"") | F14: =IFERROR(C14*E14,"") | G14: =IFERROR(F14/$F$66,"")
B15: =IFERROR(VLOOKUP(H15,'[2]ARTICULOS MP PLANTA'!$A$2:$G$589,2,0),"")
A16: UNIDADES | B16: MATERIA PRIMA SEMIELABORADOS | C16: UNIDADES | D16: UND MEDIDA | E16: COSTO UNITARIO | F16: TOTAL COSTO | G16: % PREC. DEFINIDO | H16: CODIGOS
A17: 0.5 | B17: Rosquete Red Velvet 300g | C17: =+A17 -> 0.5 | D17: UND | E17: =+'Costo Rosquete'!H53 -> 590.45253 | F17: =IFERROR(E17*C17,"") -> 295.22626 | G17: =IFERROR(F17/$F$66,"") -> 0.096680796 | H17: SE00519
A18: 280 | B18: MOUSSE QUESO VELVET | C18: =+A18 -> 280 | D18: Gramos | E18: =+'costo Mouse Queso'!E66 -> 2.4780588 | F18: =IFERROR(E18*C18,"") -> 693.85647 | G18: =IFERROR(F18/$F$66,"") -> 0.22722435 | H18: nuevo
A19: 245 | B19: RELLENO FRAMBUESA Y ARANDANO | C19: =+A19 -> 245 | D19: Gramos | E19: 2.64 | F19: =IFERROR(E19*C19,"") -> 646.8 | G19: =IFERROR(F19/$F$66,"") -> 0.21181428 | H19: SE00541
B20: =IFERROR(VLOOKUP(H20,[1]SEMIELABORADOS!$A$2:$M$6000,2,0),"") | C20: =+A20 -> 0 | D20: =IFERROR(VLOOKUP(H20,[1]SEMIELABORADOS!$A$2:$M$6000,6,0),"") | E20: =IFERROR(VLOOKUP(H20,[1]SEMIELABORADOS!$A$2:$H$65536,8,0),"") | F20: =IFERROR(E20*C20,"") | G20: =IFERROR(F20/$F$66,"")
B21: =IFERROR(VLOOKUP(H21,[1]SEMIELABORADOS!$A$2:$M$6000,2,0),"") | C21: =+A21 -> 0 | D21: =IFERROR(VLOOKUP(H21,[1]SEMIELABORADOS!$A$2:$M$6000,6,0),"") | E21: =IFERROR(VLOOKUP(H21,[1]SEMIELABORADOS!$A$2:$H$65536,8,0),"") | F21: =IFERROR(E21*C21,"") | G21: =IFERROR(F21/$F$66,"")
B22: =IFERROR(VLOOKUP(H22,[1]SEMIELABORADOS!$A$2:$M$6000,2,0),"") | C22: =+A22 -> 0 | D22: =IFERROR(VLOOKUP(H22,[1]SEMIELABORADOS!$A$2:$M$6000,6,0),"") | E22: =IFERROR(VLOOKUP(H22,[1]SEMIELABORADOS!$A$2:$H$65536,8,0),"") | F22: =IFERROR(E22*C22,"") | G22: =IFERROR(F22/$F$66,"")
B23: =IFERROR(VLOOKUP(H23,[1]SEMIELABORADOS!$A$2:$M$6000,2,0),"") | C23: =+A23 -> 0 | D23: =IFERROR(VLOOKUP(H23,[1]SEMIELABORADOS!$A$2:$M$6000,6,0),"") | E23: =IFERROR(VLOOKUP(H23,[1]SEMIELABORADOS!$A$2:$H$65536,8,0),"") | F23: =IFERROR(E23*C23,"") | G23: =IFERROR(F23/$F$66,"")
B24: =IFERROR(VLOOKUP(H24,[1]SEMIELABORADOS!$A$2:$M$6000,2,0),"") | C24: =+A24 -> 0 | D24: =IFERROR(VLOOKUP(H24,[1]SEMIELABORADOS!$A$2:$M$6000,6,0),"") | E24: =IFERROR(VLOOKUP(H24,[1]SEMIELABORADOS!$A$2:$H$65536,8,0),"") | F24: =IFERROR(E24*C24,"") | G24: =IFERROR(F24/$F$66,"")
A26: UNIDADES | B26: EMPAQUE | C26: UNIDADES | D26: UND MEDIDA | E26: COSTO UNITARIO | F26: TOTAL COSTO | G26: % PREC. DEFINIDO | H26: CODIGOS
A27: 1 | B27: QUEQUERA 8 PEQUEÑA | C27: =+A27 -> 1 | D27: UND | E27: 245.63 | F27: =IFERROR(C27*E27,"") -> 245.63 | G27: =IFERROR(F27/$F$66,"") -> 0.080438995 | H27: NUEVO
A28: 1 | B28: ETIQUETA POSTRE | C28: =+A28 -> 1 | D28: UND | E28: 85 | F28: =IFERROR(C28*E28,"") -> 85 | G28: =IFERROR(F28/$F$66,"") -> 0.027835829 | H28: NUEVO | M28: Se coloca precio de etiqueta postre día del padre
A29: 1 | B29: ETIQ.BLANCA 1 1/4 * 3/4 | C29: =+A29 -> 1 | D29: UND | E29: 1.74 | F29: =IFERROR(C29*E29,"") -> 1.74 | G29: =IFERROR(F29/$F$66,"") -> 0.00056981579 | H29: EM10002
A30: 1 | B30: CINTA ADHESIVA TRANSPARENT 2*100 M (UND) | C30: =+A30 -> 1 | D30: UND | E30: 0 | F30: =IFERROR(C30*E30,"") -> 0 | G30: =IFERROR(F30/$F$66,"") -> 0 | H30: EM10248 | T30: =24562.62/100 -> 245.6262
A31: 1 | B31: ETIQUETA BLANCA R-153 (UND) | C31: =+A31 -> 1 | D31: UND | E31: 0.39 | F31: =IFERROR(C31*E31,"") -> 0.39 | G31: =IFERROR(F31/$F$66,"") -> 0.00012771733 | H31: EM10124
A32: 1 | B32: ETIQUETA BLANCA 2 5/8X1 15/16 (UND) | C32: =+A32 -> 1 | D32: UND | E32: 2.13 | F32: =IFERROR(C32*E32,"") -> 2.13 | G32: =IFERROR(F32/$F$66,"") -> 0.00069753312 | H32: EM10011
A34: UNIDADES | B34: EMPAQUE SEMIELABORADOS | C34: UNIDADES | D34: UND MEDIDA | E34: COSTO UNITARIO | F34: TOTAL COSTO | G34: % PREC. DEFINIDO | H34: CODIGOS
A35: =+A17 -> 0.5 | B35: Rosquete Red Velvet 300g | C35: =+A35 -> 0.5 | D35: UND | E35: =+'Costo Rosquete'!E76 -> 0.013054701 | F35: =IFERROR(E35*C35,"") -> 0.0065273504 | G35: =IFERROR(F35/$F$66,"") -> 2.1375789e-06 | H35: SE00519
A36: =+A18 -> 280 | B36: MOUSSE QUESO VELVET | C36: =+A36 -> 280 | D36: Gramos | E36: =+'costo Mouse Queso'!E73 -> 0.0029411765 | F36: =IFERROR(E36*C36,"") -> 0.82352941 | G36: =IFERROR(F36/$F$66,"") -> 0.00026968969
A37: =+A19 -> 245 | B37: RELLENO FRAMBUESA Y ARANDANO | C37: =+A37 -> 245 | D37: Gramos | E37: 0.01 | F37: =IFERROR(E37*C37,"") -> 2.45 | G37: =IFERROR(F37/$F$66,"") -> 0.00080232683 | H37: SE00541
A38: =+A20 -> 0 | B38: =IFERROR(VLOOKUP(H38,[1]SEMIELABORADOS!$A$2:$M$6000,2,0),"") | C38: =+A38 -> 0 | D38: =IFERROR(VLOOKUP(H38,[1]SEMIELABORADOS!$A$2:$M$6000,6,0),"") | E38: =IFERROR(VLOOKUP(H38,[1]SEMIELABORADOS!$A$2:$M$65536,10,0),"") | F38: =IFERROR(E38*C38,"") | G38: =IFERROR(F38/$F$66,"")
A39: =+A21 -> 0 | B39: =IFERROR(VLOOKUP(H39,[1]SEMIELABORADOS!$A$2:$M$6000,2,0),"") | C39: =+A39 -> 0 | D39: =IFERROR(VLOOKUP(H39,[1]SEMIELABORADOS!$A$2:$M$6000,6,0),"") | E39: =IFERROR(VLOOKUP(H39,[1]SEMIELABORADOS!$A$2:$M$65536,10,0),"") | F39: =IFERROR(E39*C39,"") | G39: =IFERROR(F39/$F$66,"")
A40: =+A22 -> 0 | B40: =IFERROR(VLOOKUP(H40,[1]SEMIELABORADOS!$A$2:$M$6000,2,0),"") | C40: =+A40 -> 0 | D40: =IFERROR(VLOOKUP(H40,[1]SEMIELABORADOS!$A$2:$M$6000,6,0),"") | E40: =IFERROR(VLOOKUP(H40,[1]SEMIELABORADOS!$A$2:$M$65536,10,0),"") | F40: =IFERROR(E40*C40,"") | G40: =IFERROR(F40/$F$66,"")
A41: =+A23 -> 0 | B41: =IFERROR(VLOOKUP(H41,[1]SEMIELABORADOS!$A$2:$M$6000,2,0),"") | C41: =+A41 -> 0 | D41: =IFERROR(VLOOKUP(H41,[1]SEMIELABORADOS!$A$2:$M$6000,6,0),"") | E41: =IFERROR(VLOOKUP(H41,[1]SEMIELABORADOS!$A$2:$M$65536,10,0),"") | F41: =IFERROR(E41*C41,"") | G41: =IFERROR(F41/$F$66,"")
A43: UNIDADES | B43: MODI | C43: UNIDADES | D43: UND MEDIDA | E43: COSTO UNITARIO | F43: TOTAL COSTO | G43: % PREC. DEFINIDO | H43: CODIGOS
A44: =+A35 -> 0.5 | B44: Rosquete Red Velvet 300g | C44: =+A44 -> 0.5 | D44: UND | E44: =+'Costo Rosquete'!E74 -> 0.15786986 | F44: =IFERROR(E44*C44,"") -> 0.078934931 | G44: =IFERROR(F44/$F$66,"") -> 2.5849638e-05 | H44: SE00519
A45: =+A36 -> 280 | B45: MOUSSE QUESO VELVET | C45: =+A45 -> 280 | D45: Gramos | E45: =+'costo Mouse Queso'!E71 -> 0.054117647 | F45: =IFERROR(E45*C45,"") -> 15.152941 | G45: =IFERROR(F45/$F$66,"") -> 0.0049622903
...
