Workbook

Sheet Hoja1
C1: SERVICIOS DE PASTELERIA S.A. | H1: CÓDIGO: | I1: ESP-RE-COCS-041
C2: ESPECIFICACION DE RECETA | H2: REVISIÓN: | I2: 01
C3: SE00354 Relleno de fresa Espesa PLANTA | H3: FECHA DE APROBACIÓN: | I3: 45609
C4: Elaborado | D4: Javier Tong, Chef
C5: Aprobado | D5: Esteban Cartin, Gte Manufactura
A6: AREA QUE PRODUCE: | D6: Cocina | G6: AREA QUE EMPACA: | I6: Empaque
A7: # Código | B7: # Código Netsuite | C7: Descripción del ingrediente | D7: Marca | E7: Unidad Internacional | G7: Medida alternativa | I7: Costo - Referencia
E8: Cantidad | F8: Unidad medida | G8: Cantidad | H8: Unidad medida | I8: Colones
C9: Ensamble
A10: 10100230 | B10: MP10191 | C10: FRESA CONGELADA BEGRO (PAQ:1 K) | D10: BEGRO | E10: 23000 | F10: g
A11: 1212412 | B11: MP10025 | C11: PRESERVANTE 1017S (PAQ=5 KILO) | D11: ASEAL | E11: 62 | F11: g
A12: 0510215 | B12: MP10026 | C12: ALMIDON MODIFICADO ( 25 KG ) | D12: ASEAL | E12: 1350 | F12: g
A13: 10415 | C13: AGUA POTABLE (PLANTA) | D13: FAS | E13: 810 | F13: g
A14: 10400009 | B14: MP10157 | C14: COLORANTE GEL SUPER RED | D14: AMERICOLOR | E14: 2 | F14: g | H14: GOTAS
A15: 10400010 | B15: MP10509 | C15: COLORANTE ROJO (50ML) | D15: ANCLA | E15: 2 | F15: g | H15: GOTAS
A16: 90100131 | B16: SE00016 | C16: AZUCAR BLANCO INDUSTRIAL (BOLSAS:1500g) | D16: FAS | E16: 7130 | F16: g
A17: 908000036 | B17: SE00015 | C17: JUGO LIMON (KILO) | D17: FAS | E17: 920 | F17: g
C25: Decoración
C31: Empaque
A32: 0702123 | B32: EM10011 | C32: ETIQUETA BLANCA 2 5/8X1 15/16 (UND) | D32: CEMUSA | E32: 1 | F32: ud
D42: Cantidad | E42: Unidad
A43: PESO TOTAL OBTENIDO | D43: 31300 | E43: g | F43: Tiempo de Horneo:
A44: TIEMPO TOTAL DE PREPARACION | D44: 35 | E44: min | F44: Horno:
A45: CANTIDAD DE PORCIONES OBTENIDAS | D45: 6.26 | E45: bolsas | F45: Temperatura de Horneo:
A46: PESO DE CADA PORCIÓN | D46: 5000 | E46: g | F46: Otros
A47: MERMA | D47: 1976 | E47: g
A48: PROCEDIMIENTO DE PREPARACION DE LA RECETA
A49: 1, Colocar la fresa congelada en la olla junto con el azucar, el agua y el colorante. Hervir
A50: 2, Mezclar el almidon con el preservante, juego de limon . Agregar a la mezcla anterior. Hervir
A51: 3, Colocar en bandejas y hacer choque termico.
A60: CONTROL DE CAMBIOS

Sheet Costo Relleno 6-04-2020
E1: Precio Local | F1: Costo MP | G1: Costo EM | H1: Costo MO
E2: =IFERROR(O55,"") -> 10571.061 | F2: =IFERROR(H46,"") -> 7599.5931 | G2: =IFERROR(H47,"") -> 26.809523 | H2: =IFERROR(H49,"") -> 351.47497
A5: ESTRUCTURA DE COSTOS
F6: Fecha: | H6: =TODAY() -> 45701
A7: UNIDADES | B7: DESCRIPCION MAT.PRIMA | C7: UNIDADES | D7: UND MEDIDA | E7: COSTO UNITARIO | F7: TOTAL COSTO | G7: % PREC. DEFINIDO | H7: CODIGOS
A8: 23000 | B8: =IFERROR(VLOOKUP(H8,'[1]ARTICULOS MP PLANTA'!$A$2:$G$589,2,0),"") -> FRESA CONGELADA BEGRO (PAQ:1 K) | C8: =+A8 -> 23000 | D8: =IFERROR(VLOOKUP(H8,'[1]ARTICULOS MP PLANTA'!$A$2:$G$589,6,0),"") -> Gramo | E8: =IFERROR(VLOOKUP(H8,'[1]ARTICULOS MP PLANTA'!$A$2:$G$589,7,0),"") -> 1.861 | F8: =IFERROR(C8*E8,"") -> 42803 | G8: =IFERROR(F8/$F$59,"") -> 0.84561246 | H8: 10100230
A9: 34.5 | B9: =IFERROR(VLOOKUP(H9,'[1]ARTICULOS MP PLANTA'!$A$2:$G$589,2,0),"") -> PRESERVANTE 1017S (PAQ=5 KILO) | C9: =+A9 -> 34.5 | D9: =IFERROR(VLOOKUP(H9,'[1]ARTICULOS MP PLANTA'!$A$2:$G$589,6,0),"") -> Gramo | E9: =IFERROR(VLOOKUP(H9,'[1]ARTICULOS MP PLANTA'!$A$2:$G$589,7,0),"") -> 6.32148 | F9: =IFERROR(C9*E9,"") -> 218.09106 | G9: =IFERROR(F9/$F$59,"") -> 0.0043085886 | H9: 1212412
A10: 1062.5 | B10: ALMIDON MODIFICADO ( 25 KG ) | C10: =+A10 -> 1062.5 | D10: Gramo | E10: 1.16 | F10: =IFERROR(C10*E10,"") -> 1232.5 | G10: =IFERROR(F10/$F$59,"") -> 0.024349166 | H10: 0510215
A11: 810 | B11: AGUA POTABLE (PLANTA) | C11: =+A11 -> 810 | D11: Mililitro | E11: 0.1 | F11: =IFERROR(C11*E11,"") -> 81 | G11: =IFERROR(F11/$F$59,"") -> 0.0016002292 | H11: 10415
A12: 2 | B12: =IFERROR(VLOOKUP(H12,'[1]ARTICULOS MP PLANTA'!$A$2:$G$589,2,0),"") -> COLORANTE GEL SUPER RED | C12: =+A12 -> 2 | D12: Mililitro | E12: =IFERROR(VLOOKUP(H12,'[1]ARTICULOS MP PLANTA'!$A$2:$G$589,7,0),"") -> 18.461538 | F12: =IFERROR(C12*E12,"") -> 36.923077 | G12: =IFERROR(F12/$F$59,"") -> 0.0007294492 | H12: 10400009
A13: 2 | B13: =IFERROR(VLOOKUP(H13,'[1]ARTICULOS MP PLANTA'!$A$2:$G$589,2,0),"") -> COLORANTE ROJO (50ML) | C13: =+A13 -> 2 | D13: =IFERROR(VLOOKUP(H13,'[1]ARTICULOS MP PLANTA'!$A$2:$G$589,6,0),"") -> Mililitro | E13: =IFERROR(VLOOKUP(H13,'[1]ARTICULOS MP PLANTA'!$A$2:$G$589,7,0),"") -> 26.0348 | F13: =IFERROR(C13*E13,"") -> 52.0696 | G13: =IFERROR(F13/$F$59,"") -> 0.0010286826 | H13: 10400010
B14: =IFERROR(VLOOKUP(H14,'[1]ARTICULOS MP PLANTA'!$A$2:$G$589,2,0),"") | C14: =+A14 -> 0 | D14: =IFERROR(VLOOKUP(H14,'[1]ARTICULOS MP PLANTA'!$A$2:$G$589,6,0),"") | E14: =IFERROR(VLOOKUP(H14,'[1]ARTICULOS MP PLANTA'!$A$2:$G$589,7,0),"") | F14: =IFERROR(C14*E14,"") | G14: =IFERROR(F14/$F$59,"")
B15: =IFERROR(VLOOKUP(H15,'[1]ARTICULOS MP PLANTA'!$A$2:$G$589,2,0),"")
A16: UNIDADES | B16: MATERIA PRIMA SEMIELABORADOS | C16: UNIDADES | D16: UND MEDIDA | E16: COSTO UNITARIO | F16: TOTAL COSTO | G16: % PREC. DEFINIDO | H16: CODIGOS
A17: 7130 | B17: AZUCAR BLANCO INDUSTRIAL (BOLSAS:1500g) | C17: =+A17 -> 7130 | D17: Gramo | E17: =+'[2]COSTEO EMP'!$E$62 -> 0.39 | F17: =IFERROR(E17*C17,"") -> 2780.7 | G17: =IFERROR(F17/$F$59,"") -> 0.054935275 | H17: 90100131
A18: 920 | B18: JUGO LIMON (KILO) | C18: =+A18 -> 920 | D18: Mililitro | E18: =+'[3]COSTEO JUGO'!$E$34 -> 0.40127091 | F18: =IFERROR(E18*C18,"") -> 369.16924 | G18: =IFERROR(F18/$F$59,"") -> 0.0072932763 | H18: 908000036
B19: =IFERROR(VLOOKUP($H19,[4]SEMIELABORADOS!$A$1:$J$998,2,0),"") | C19: =+A19 -> 0 | D19: =IFERROR(VLOOKUP($H19,[4]SEMIELABORADOS!$A$1:$J$998,4,0),"") | E19: =IFERROR(VLOOKUP($H19,[4]SEMIELABORADOS!$A$1:$J$998,6,0),"") | F19: =IFERROR(E19*C19,"") | G19: =IFERROR(F19/$F$59,"")
B20: =IFERROR(VLOOKUP($H20,[4]SEMIELABORADOS!$A$1:$J$998,2,0),"") | C20: =+A20 -> 0 | D20: =IFERROR(VLOOKUP($H20,[4]SEMIELABORADOS!$A$1:$J$998,4,0),"") | E20: =IFERROR(VLOOKUP($H20,[4]SEMIELABORADOS!$A$1:$J$998,6,0),"") | F20: =IFERROR(E20*C20,"") | G20: =IFERROR(F20/$F$59,"")
B21: =IFERROR(VLOOKUP($H21,[4]SEMIELABORADOS!$A$1:$J$998,2,0),"") | C21: =+A21 -> 0 | D21: =IFERROR(VLOOKUP($H21,[4]SEMIELABORADOS!$A$1:$J$998,4,0),"") | E21: =IFERROR(VLOOKUP($H21,[4]SEMIELABORADOS!$A$1:$J$998,6,0),"") | F21: =IFERROR(E21*C21,"") | G21: =IFERROR(F21/$F$59,"")
A23: UNIDADES | B23: EMPAQUE | C23: UNIDADES | D23: UND MEDIDA | E23: COSTO UNITARIO | F23: TOTAL COSTO | G23: % PREC. DEFINIDO | H23: CODIGOS
A24: 1 | B24: ETIQUETA BLANCA 2 5/8X1 15/16 (UND) | C24: =+A24 -> 1 | D24: UND | E24: 2.13 | F24: =IFERROR(E24*C24,"") -> 2.13 | G24: =IFERROR(F24/$F$59,"") -> 4.2080101e-05 | H24: 0702123
B25: =IFERROR(VLOOKUP(H25,'[1]EMPAQUE PLANTA'!$A$2:$H$176,2,0),"") | C25: =+A25 -> 0 | D25: =IFERROR(VLOOKUP(H25,'[1]EMPAQUE PLANTA'!$A$2:$H$176,7,0),"") | E25: =IFERROR(VLOOKUP($H25,'[4]EMP PLANTA'!$A$2:$F$500,6,0),"") | F25: =IFERROR(E25*C25,"") | G25: =IFERROR(F25/$F$59,"")
B26: =IFERROR(VLOOKUP(H26,'[1]EMPAQUE PLANTA'!$A$2:$H$176,2,0),"") | C26: =+A26 -> 0 | D26: =IFERROR(VLOOKUP(H26,'[1]EMPAQUE PLANTA'!$A$2:$H$176,7,0),"") | E26: =IFERROR(VLOOKUP($H26,'[4]EMP PLANTA'!$A$2:$F$500,6,0),"") | F26: =IFERROR(E26*C26,"") | G26: =IFERROR(F26/$F$59,"")
B27: =IFERROR(VLOOKUP(H27,'[1]EMPAQUE PLANTA'!$A$2:$H$176,2,0),"") | C27: =+A27 -> 0 | D27: =IFERROR(VLOOKUP(H27,'[1]EMPAQUE PLANTA'!$A$2:$H$176,7,0),"") | E27: =IFERROR(VLOOKUP($H27,'[4]EMP PLANTA'!$A$2:$F$500,6,0),"") | F27: =IFERROR(E27*C27,"") | G27: =IFERROR(F27/$F$59,"")
B28: =IFERROR(VLOOKUP(H28,'[1]EMPAQUE PLANTA'!$A$2:$H$176,2,0),"") | C28: =+A28 -> 0 | D28: =IFERROR(VLOOKUP(H28,'[1]EMPAQUE PLANTA'!$A$2:$H$176,7,0),"") | E28: =IFERROR(VLOOKUP($H28,'[4]EMP PLANTA'!$A$2:$F$500,6,0),"") | F28: =IFERROR(E28*C28,"") | G28: =IFERROR(F28/$F$59,"")
B29: =IFERROR(VLOOKUP(H29,'[1]EMPAQUE PLANTA'!$A$2:$H$176,2,0),"") | C29: =+A29 -> 0 | D29: =IFERROR(VLOOKUP(H29,'[1]EMPAQUE PLANTA'!$A$2:$H$176,7,0),"") | E29: =IFERROR(VLOOKUP($H29,'[4]EMP PLANTA'!$A$2:$F$500,6,0),"") | F29: =IFERROR(E29*C29,"") | G29: =IFERROR(F29/$F$59,"")
B30: =IFERROR(VLOOKUP(H30,'[1]EMPAQUE PLANTA'!$A$2:$H$176,2,0),"")
A31: UNIDADES | B31: EMPAQUE SEMIELABORADOS | C31: UNIDADES | D31: UND MEDIDA | E31: COSTO UNITARIO | F31: TOTAL COSTO | G31: % PREC. DEFINIDO | H31: CODIGOS
A32: =+A17 -> 7130 | B32: AZUCAR BLANCO INDUSTRIAL (BOLSAS:1500g) | C32: =+A32 -> 7130 | D32: N/A | E32: =+'[2]COSTEO EMP'!$E$69 -> 0.022945905 | F32: =IFERROR(E32*C32,"") -> 163.6043 | G32: =IFERROR(F32/$F$58,"") -> 0.084989247
A33: =+A18 -> 920 | B33: JUGO LIMON (KILO) | C33: =+A33 -> 920 | D33: N/A | E33: =+'[3]COSTEO JUGO'!$E$41 -> 0.0022753401 | F33: =IFERROR(E33*C33,"") -> 2.0933129 | G33: =IFERROR(F33/$F$58,"") -> 0.0010874353
A34: =+A19 -> 0 | C34: =+A34 -> 0 | D34: N/A | E34: =IFERROR(VLOOKUP($H34,[4]SEMIELABORADOS!$A$1:$J$998,8,0),"") | F34: =IFERROR(E34*C34,"") | G34: =IFERROR(F34/$F$58,"")
A35: =+A20 -> 0 | C35: =+A35 -> 0 | D35: N/A | E35: =IFERROR(VLOOKUP($H35,[4]SEMIELABORADOS!$A$1:$J$998,8,0),"") | F35: =IFERROR(E35*C35,"") | G35: =IFERROR(F35/$F$58,"")
A36: =+A21 -> 0 | C36: =+A36 -> 0 | D36: N/A | E36: =IFERROR(VLOOKUP($H36,[4]SEMIELABORADOS!$A$1:$J$998,8,0),"") | F36: =IFERROR(E36*C36,"") | G36: =IFERROR(F36/$F$58,"")
A38: UNIDADES | B38: MODI | C38: UNIDADES | E38: COSTO UNITARIO | F38: TOTAL COSTO | G38: % PREC. DEFINIDO | H38: CODIGOS
A39: =+A17 -> 7130 | B39: AZUCAR BLANCO INDUSTRIAL (BOLSAS:1500g) | C39: =+A39 -> 7130 | D39: N/A | E39: =+'[2]COSTEO EMP'!$E$67 -> 0.036666667 | F39: =IFERROR(C39*E39,"") -> 261.43333 | G39: =IFERROR(F39/$F$59,"") -> 0.0051648549
A40: =+A18 -> 920 | B40: JUGO LIMON (KILO) | C40: =+A40 -> 920 | D40: N/A | E40: =+'[3]COSTEO JUGO'!$E$39 -> 0.015 | F40: =IFERROR(C40*E40,"") -> 13.8 | G40: =IFERROR(F40/$F$59,"") -> 0.00027263164
A41: =+A19 -> 0 | C41: =+A41 -> 0 | D41: N/A | E41: =IFERROR(VLOOKUP($H41,[4]SEMIELABORADOS!$A$1:$J$998,10,0),"") | F41: =IFERROR(C41*E41,"") | G41: =IFERROR(F41/$F$59,"")
A42: =+A20 -> 0 | C42: =+A42 -> 0 | D42: N/A | E42: =IFERROR(VLOOKUP($H42,[4]SEMIELABORADOS!$A$1:$J$998,10,0),"") | F42: =IFERROR(C42*E42,"") | G42: =IFERROR(F42/$F$59,"")
A43: =+A21 -> 0 | C43: =+A43 -> 0 | D43: N/A | E43: =IFERROR(VLOOKUP($H43,[4]SEMIELABORADOS!$A$1:$J$998,10,0),"") | F43: =IFERROR(C43*E43,"") | G43: =IFERROR(F43/$F$59,"")
A44: 1 | B44: MODI PREPARACION | C44: =+A44 -> 1 | D44: N/A | E44: =+F58 -> 1925 | F44: =IFERROR(C44*E44,"") -> 1925 | G44: =IFERROR(F44/$F$59,"") -> 0.038030138
...

Sheet COSTEO RELL
E1: Precio Local | F1: Costo MP | G1: Costo EM | H1: Costo MO
E2: =IFERROR(O53,"") -> 53419.795 | F2: =IFERROR(H42,"") -> 1342.5618 | G2: =IFERROR(H43,"") -> 3.1293822 | H2: =IFERROR(H45,"") -> 63.060703
A4: RELLENO FRESA
A5: ESTRUCTURA DE COSTOS
F6: Fecha: | H6: =TODAY() -> 45701
A7: UNIDADES | B7: DESCRIPCION MAT.PRIMA | C7: UNIDADES | D7: UND MEDIDA | E7: COSTO UNITARIO | F7: TOTAL COSTO | G7: % PREC. DEFINIDO | H7: CODIGOS
A8: 7130 | B8: =IFERROR(VLOOKUP($H8,'[4]MP PLANTA'!$A$2:$F$500,2,0),"") -> AZUCAR BLANCO (INDUSTRIAL) | C8: =+A8 -> 7130 | D8: =IFERROR(VLOOKUP($H8,'[4]MP PLANTA'!$A$2:$F$500,5,0),"") -> Gramo | E8: =IFERROR(VLOOKUP($H8,'[4]MP PLANTA'!$A$2:$F$500,6,0),"") -> 0.378959 | F8: =IFERROR(C8*E8,"") -> 2701.9777 | G8: =IFERROR(F8/$F$55,"") -> 0.060150109 | H8: 510301
A9: 35 | B9: =IFERROR(VLOOKUP($H9,'[4]MP PLANTA'!$A$2:$F$500,2,0),"") -> PRESERVANTE 1047S(PAQ=5 KILO) | C9: =+A9 -> 35 | D9: =IFERROR(VLOOKUP($H9,'[4]MP PLANTA'!$A$2:$F$500,5,0),"") -> Gramo | E9: =IFERROR(VLOOKUP($H9,'[4]MP PLANTA'!$A$2:$F$500,6,0),"") -> 4.791778 | F9: =IFERROR(C9*E9,"") -> 167.71223 | G9: =IFERROR(F9/$F$55,"") -> 0.0037335278 | H9: 1212410
A10: 850 | B10: =IFERROR(VLOOKUP($H10,'[4]MP PLANTA'!$A$2:$F$500,2,0),"") -> ALMIDON MODIFICADO ( 25 KG ) | C10: =+A10 -> 850 | D10: =IFERROR(VLOOKUP($H10,'[4]MP PLANTA'!$A$2:$F$500,5,0),"") -> Gramo | E10: =IFERROR(VLOOKUP($H10,'[4]MP PLANTA'!$A$2:$F$500,6,0),"") -> 1.683318 | F10: =IFERROR(C10*E10,"") -> 1430.8203 | G10: =IFERROR(F10/$F$55,"") -> 0.031852223 | H10: 0510215
A11: 810 | B11: =IFERROR(VLOOKUP($H11,'[4]MP PLANTA'!$A$2:$F$500,2,0),"") -> AGUA | C11: =+A11 -> 810 | D11: =IFERROR(VLOOKUP($H11,'[4]MP PLANTA'!$A$2:$F$500,5,0),"") -> Mililitro | E11: =IFERROR(VLOOKUP($H11,'[4]MP PLANTA'!$A$2:$F$500,6,0),"") | F11: =IFERROR(C11*E11,"") | G11: =IFERROR(F11/$F$55,"") | H11: 99999
A12: 2 | B12: =IFERROR(VLOOKUP($H12,'[4]MP PLANTA'!$A$2:$F$500,2,0),"") -> COLORANTE/PASTA 4 ONZ | C12: =+A12 -> 2 | D12: =IFERROR(VLOOKUP($H12,'[4]MP PLANTA'!$A$2:$F$500,5,0),"") -> Gramo | E12: =IFERROR(VLOOKUP($H12,'[4]MP PLANTA'!$A$2:$F$500,6,0),"") -> 20.151508 | F12: =IFERROR(C12*E12,"") -> 40.303017 | G12: =IFERROR(F12/$F$55,"") -> 0.00089720609 | H12: 0807003
A13: 2 | B13: =IFERROR(VLOOKUP($H13,'[4]MP PLANTA'!$A$2:$F$500,2,0),"") -> COLORANTE ROJO ( 50 ml ) | C13: =+A13 -> 2 | D13: =IFERROR(VLOOKUP($H13,'[4]MP PLANTA'!$A$2:$F$500,5,0),"") -> Mililitro | E13: =IFERROR(VLOOKUP($H13,'[4]MP PLANTA'!$A$2:$F$500,6,0),"") -> 26.101288 | F13: =IFERROR(C13*E13,"") -> 52.202576 | G13: =IFERROR(F13/$F$55,"") -> 0.0011621083 | H13: 1212383
A14: 23000 | B14: FRESAS CONGELADAS | C14: =+A14 -> 23000 | D14: Gramo | E14: 1.62 | F14: =IFERROR(C14*E14,"") -> 37260 | G14: =IFERROR(F14/$F$55,"") -> 0.82946394 | H14: Nuevo
A16: UNIDADES | B16: MATERIA PRIMA SEMIELABORADOS | C16: UNIDADES | D16: UND MEDIDA | E16: COSTO UNITARIO | F16: TOTAL COSTO | G16: % PREC. DEFINIDO | H16: CODIGOS
A17: 920 | B17: =IFERROR(VLOOKUP($H17,[4]SEMIELABORADOS!$A$1:$J$999,2,0),"") -> JUGO DE LIMON (11 LIT) | C17: =+A17 -> 920 | D17: =IFERROR(VLOOKUP($H17,[4]SEMIELABORADOS!$A$1:$J$999,4,0),"") -> Mililitro | E17: =IFERROR(VLOOKUP($H17,[4]SEMIELABORADOS!$A$1:$J$999,6,0),"") -> 0.40127091 | F17: =IFERROR(E17*C17,"") -> 369.16924 | G17: =IFERROR(F17/$F$55,"") -> 0.0082182654 | H17: 95692
B18: =IFERROR(VLOOKUP($H18,[4]SEMIELABORADOS!$A$1:$J$999,2,0),"") | C18: =+A18 -> 0 | D18: =IFERROR(VLOOKUP($H18,[4]SEMIELABORADOS!$A$1:$J$999,4,0),"") | E18: =IFERROR(VLOOKUP($H18,[4]SEMIELABORADOS!$A$1:$J$999,6,0),"") | F18: =IFERROR(E18*C18,"") | G18: =IFERROR(F18/$F$55,"")
B19: =IFERROR(VLOOKUP($H19,[4]SEMIELABORADOS!$A$1:$J$999,2,0),"") | C19: =+A19 -> 0 | D19: =IFERROR(VLOOKUP($H19,[4]SEMIELABORADOS!$A$1:$J$999,4,0),"") | E19: =IFERROR(VLOOKUP($H19,[4]SEMIELABORADOS!$A$1:$J$999,6,0),"") | F19: =IFERROR(E19*C19,"") | G19: =IFERROR(F19/$F$55,"")
B20: =IFERROR(VLOOKUP($H20,[4]SEMIELABORADOS!$A$1:$J$999,2,0),"") | C20: =+A20 -> 0 | D20: =IFERROR(VLOOKUP($H20,[4]SEMIELABORADOS!$A$1:$J$999,4,0),"") | E20: =IFERROR(VLOOKUP($H20,[4]SEMIELABORADOS!$A$1:$J$999,6,0),"") | F20: =IFERROR(E20*C20,"") | G20: =IFERROR(F20/$F$55,"")
B21: =IFERROR(VLOOKUP($H21,[4]SEMIELABORADOS!$A$1:$J$999,2,0),"") | C21: =+A21 -> 0 | D21: =IFERROR(VLOOKUP($H21,[4]SEMIELABORADOS!$A$1:$J$999,4,0),"") | E21: =IFERROR(VLOOKUP($H21,[4]SEMIELABORADOS!$A$1:$J$999,6,0),"") | F21: =IFERROR(E21*C21,"") | G21: =IFERROR(F21/$F$55,"")
A23: UNIDADES | B23: EMPAQUE | C23: UNIDADES | D23: UND MEDIDA | E23: COSTO UNITARIO | F23: TOTAL COSTO | G23: % PREC. DEFINIDO | H23: CODIGOS
A24: 200 | B24: =IFERROR(VLOOKUP($H24,'[4]EMP PLANTA'!$A$2:$F$500,2,0),"") -> PLAST. AUTOAD 18 * 2000 | C24: =+A24 -> 200 | D24: =IFERROR(VLOOKUP($H24,'[4]EMP PLANTA'!$A$2:$F$500,5,0),"") -> Centimetros | E24: =IFERROR(VLOOKUP($H24,'[4]EMP PLANTA'!$A$2:$F$500,6,0),"") -> 0.47620175 | F24: =IFERROR(E24*C24,"") -> 95.24035 | G24: =IFERROR(F24/$F$55,"") -> 0.0021201942 | H24: 1950765
A25: 1 | B25: =IFERROR(VLOOKUP($H25,'[4]EMP PLANTA'!$A$2:$F$500,2,0),"") -> ETIQ.BLANCA 1 1/4 * 3/4 | C25: =+A25 -> 1 | D25: =IFERROR(VLOOKUP($H25,'[4]EMP PLANTA'!$A$2:$F$500,5,0),"") -> UND | E25: =IFERROR(VLOOKUP($H25,'[4]EMP PLANTA'!$A$2:$F$500,6,0),"") -> 0.616 | F25: =IFERROR(E25*C25,"") -> 0.616 | G25: =IFERROR(F25/$F$55,"") -> 1.3713091e-05 | H25: 0702069
B26: =IFERROR(VLOOKUP($H26,'[4]EMP PLANTA'!$A$2:$F$500,2,0),"") | C26: =+A26 -> 0 | D26: =IFERROR(VLOOKUP($H26,'[4]EMP PLANTA'!$A$2:$F$500,5,0),"") | E26: =IFERROR(VLOOKUP($H26,'[4]EMP PLANTA'!$A$2:$F$500,6,0),"") | F26: =IFERROR(E26*C26,"") | G26: =IFERROR(F26/$F$55,"")
B27: =IFERROR(VLOOKUP($H27,'[4]EMP PLANTA'!$A$2:$F$500,2,0),"") | C27: =+A27 -> 0 | D27: =IFERROR(VLOOKUP($H27,'[4]EMP PLANTA'!$A$2:$F$500,5,0),"") | E27: =IFERROR(VLOOKUP($H27,'[4]EMP PLANTA'!$A$2:$F$500,6,0),"") | F27: =IFERROR(E27*C27,"") | G27: =IFERROR(F27/$F$55,"")
B28: =IFERROR(VLOOKUP($H28,'[4]EMP PLANTA'!$A$2:$F$500,2,0),"") | C28: =+A28 -> 0 | D28: =IFERROR(VLOOKUP($H28,'[4]EMP PLANTA'!$A$2:$F$500,5,0),"") | E28: =IFERROR(VLOOKUP($H28,'[4]EMP PLANTA'!$A$2:$F$500,6,0),"") | F28: =IFERROR(E28*C28,"") | G28: =IFERROR(F28/$F$55,"")
B29: =IFERROR(VLOOKUP($H29,'[4]EMP PLANTA'!$A$2:$F$500,2,0),"") | C29: =+A29 -> 0 | D29: =IFERROR(VLOOKUP($H29,'[4]EMP PLANTA'!$A$2:$F$500,5,0),"") | E29: =IFERROR(VLOOKUP($H29,'[4]EMP PLANTA'!$A$2:$F$500,6,0),"") | F29: =IFERROR(E29*C29,"") | G29: =IFERROR(F29/$F$55,"")
A31: UNIDADES | B31: EMPAQUE SEMIELABORADOS | C31: UNIDADES | D31: UND MEDIDA | E31: COSTO UNITARIO | F31: TOTAL COSTO | G31: % PREC. DEFINIDO | H31: CODIGOS
A32: =+A17 -> 920 | B32: JUGO DE LIMON (7.9 Litros) | C32: =+A32 -> 920 | D32: N/A | E32: =IFERROR(VLOOKUP($H32,[4]SEMIELABORADOS!$A$1:$J$999,8,0),"") -> 0.0022753401 | F32: =IFERROR(E32*C32,"") -> 2.0933129 | G32: =IFERROR(F32/$F$54,"") -> 0.0010680168 | H32: 95692
A33: =+A18 -> 0 | C33: =+A33 -> 0 | D33: N/A | E33: =IFERROR(VLOOKUP($H33,[4]SEMIELABORADOS!$A$1:$J$999,8,0),"") | F33: =IFERROR(E33*C33,"") | G33: =IFERROR(F33/$F$54,"")
A34: =+A19 -> 0 | C34: =+A34 -> 0 | D34: N/A | E34: =IFERROR(VLOOKUP($H34,[4]SEMIELABORADOS!$A$1:$J$999,8,0),"") | F34: =IFERROR(E34*C34,"") | G34: =IFERROR(F34/$F$54,"")
A35: =+A20 -> 0 | C35: =+A35 -> 0 | D35: N/A | E35: =IFERROR(VLOOKUP($H35,[4]SEMIELABORADOS!$A$1:$J$999,8,0),"") | F35: =IFERROR(E35*C35,"") | G35: =IFERROR(F35/$F$54,"")
A36: =+A21 -> 0 | C36: =+A36 -> 0 | D36: N/A | E36: =IFERROR(VLOOKUP($H36,[4]SEMIELABORADOS!$A$1:$J$999,8,0),"") | F36: =IFERROR(E36*C36,"") | G36: =IFERROR(F36/$F$54,"")
A38: UNIDADES | B38: MODI | C38: UNIDADES | E38: COSTO UNITARIO | F38: TOTAL COSTO | G38: % PREC. DEFINIDO | H38: CODIGOS
A39: =+A17 -> 920 | B39: JUGO DE LIMON (7.9 Litros) | C39: =+A39 -> 920 | D39: N/A | E39: =IFERROR(VLOOKUP($H39,[4]SEMIELABORADOS!$A$1:$J$999,10,0),"") -> 0.015 | F39: =IFERROR(C39*E39,"") -> 13.8 | G39: =IFERROR(F39/$F$55,"") -> 0.00030720887 | H39: 95692
A40: 1 | B40: MODI PREPARACION | C40: =+A40 -> 1 | D40: N/A | E40: =+F54 -> 1960 | F40: =IFERROR(C40*E40,"") -> 1960 | G40: =IFERROR(F40/$F$55,"") -> 0.043632564
B42: TOTAL MATERIA PRIMA | F42: =SUM(F8:F14,F17:F21) -> 42022.185 | G42: =+F42/$F$55 -> 0.93547738 | H42: =+F42/$D$48*1000 -> 1342.5618
B43: TOTAL EMPAQUE | F43: =SUM(F24:F29,F32:F36) -> 97.949663 | G43: =+F43/$F$55 -> 0.0021805076 | H43: =+F43/$D$48*1000 -> 3.1293822 | K43: TOTAL MATERIA PRIMA + EMPAQUE | O43: =+F44 -> 42120.135
B44: TOTAL MATERIAS P. + EMPAQUES | F44: =+F42+F43 -> 42120.135 | G44: =+F44/$F$55 -> 0.93765789 | H44: =+F44/$D$48*1000 -> 1345.6912 | L44: MODI PLANTA | O44: =+F45 -> 1973.8
C45: TOTAL MODI | F45: =SUM(F39:F40) -> 1973.8 | G45: =+F45/$F$55 -> 0.043939773 | H45: =+F45/$D$48*1000 -> 63.060703 | L45: DESECHO | N45: 0.02 | O45: =+(O43+O44)*N45 -> 881.87869
L46: GAF | N46: =230%*0.85 -> 1.955 | O46: =+O44*N46 -> 3858.779
...

Sheet costo empaque 06-04-2020
E1: Precio Local | F1: Costo MP | G1: Costo EM | H1: Costo MO
E2: =IFERROR(O55,"") -> 10688.556 | F2: =IFERROR(H46,"") -> 7599.5931 | G2: =IFERROR(H47,"") -> 60.987636 | H2: =IFERROR(H49,"") -> 406.47497
A5: ESTRUCTURA DE COSTOS
F6: Fecha: | H6: =TODAY() -> 45701
A7: UNIDADES | B7: DESCRIPCION MAT.PRIMA | C7: UNIDADES | D7: UND MEDIDA | E7: COSTO UNITARIO | F7: TOTAL COSTO | G7: % PREC. DEFINIDO | H7: CODIGOS
B8: =IFERROR(VLOOKUP(H8,'[1]ARTICULOS MP PLANTA'!$A$2:$G$589,2,0),"") | C8: =+A8 -> 0 | D8: =IFERROR(VLOOKUP(H8,'[1]ARTICULOS MP PLANTA'!$A$2:$G$589,6,0),"") | E8: =IFERROR(VLOOKUP(H8,'[1]ARTICULOS MP PLANTA'!$A$2:$G$589,7,0),"") | F8: =IFERROR(C8*E8,"") | G8: =IFERROR(F8/$F$59,"")
B9: =IFERROR(VLOOKUP(H9,'[1]ARTICULOS MP PLANTA'!$A$2:$G$589,2,0),"") | C9: =+A9 -> 0 | D9: =IFERROR(VLOOKUP(H9,'[1]ARTICULOS MP PLANTA'!$A$2:$G$589,6,0),"") | E9: =IFERROR(VLOOKUP(H9,'[1]ARTICULOS MP PLANTA'!$A$2:$G$589,7,0),"") | F9: =IFERROR(C9*E9,"") | G9: =IFERROR(F9/$F$59,"")
B10: =IFERROR(VLOOKUP(H10,'[1]ARTICULOS MP PLANTA'!$A$2:$G$589,2,0),"") | C10: =+A10 -> 0 | D10: =IFERROR(VLOOKUP(H10,'[1]ARTICULOS MP PLANTA'!$A$2:$G$589,6,0),"") | E10: =IFERROR(VLOOKUP(H10,'[1]ARTICULOS MP PLANTA'!$A$2:$G$589,7,0),"") | F10: =IFERROR(C10*E10,"") | G10: =IFERROR(F10/$F$59,"")
B11: =IFERROR(VLOOKUP(H11,'[1]ARTICULOS MP PLANTA'!$A$2:$G$589,2,0),"") | C11: =+A11 -> 0 | D11: =IFERROR(VLOOKUP(H11,'[1]ARTICULOS MP PLANTA'!$A$2:$G$589,6,0),"") | E11: =IFERROR(VLOOKUP(H11,'[1]ARTICULOS MP PLANTA'!$A$2:$G$589,7,0),"") | F11: =IFERROR(C11*E11,"") | G11: =IFERROR(F11/$F$59,"")
B12: =IFERROR(VLOOKUP(H12,'[1]ARTICULOS MP PLANTA'!$A$2:$G$589,2,0),"") | C12: =+A12 -> 0 | D12: =IFERROR(VLOOKUP(H12,'[1]ARTICULOS MP PLANTA'!$A$2:$G$589,6,0),"") | E12: =IFERROR(VLOOKUP(H12,'[1]ARTICULOS MP PLANTA'!$A$2:$G$589,7,0),"") | F12: =IFERROR(C12*E12,"") | G12: =IFERROR(F12/$F$59,"")
B13: =IFERROR(VLOOKUP(H13,'[1]ARTICULOS MP PLANTA'!$A$2:$G$589,2,0),"") | C13: =+A13 -> 0 | D13: =IFERROR(VLOOKUP(H13,'[1]ARTICULOS MP PLANTA'!$A$2:$G$589,6,0),"") | E13: =IFERROR(VLOOKUP(H13,'[1]ARTICULOS MP PLANTA'!$A$2:$G$589,7,0),"") | F13: =IFERROR(C13*E13,"") | G13: =IFERROR(F13/$F$59,"")
B14: =IFERROR(VLOOKUP(H14,'[1]ARTICULOS MP PLANTA'!$A$2:$G$589,2,0),"") | C14: =+A14 -> 0 | D14: =IFERROR(VLOOKUP(H14,'[1]ARTICULOS MP PLANTA'!$A$2:$G$589,6,0),"") | E14: =IFERROR(VLOOKUP(H14,'[1]ARTICULOS MP PLANTA'!$A$2:$G$589,7,0),"") | F14: =IFERROR(C14*E14,"") | G14: =IFERROR(F14/$F$59,"")
B15: =IFERROR(VLOOKUP(H15,'[1]ARTICULOS MP PLANTA'!$A$2:$G$589,2,0),"")
A16: UNIDADES | B16: MATERIA PRIMA SEMIELABORADOS | C16: UNIDADES | D16: UND MEDIDA | E16: COSTO UNITARIO | F16: TOTAL COSTO | G16: % PREC. DEFINIDO | H16: CODIGOS
A17: 5000 | B17: RELLENO DE FRESA ESPESA PLANTA | C17: =+A17 -> 5000 | D17: GRAMOS | E17: =+'Costo Relleno 6-04-2020'!E62 -> 1.5199186 | F17: =IFERROR(E17*C17,"") -> 7599.5931 | G17: =IFERROR(F17/$F$59,"") -> 0.96593873
B18: =IFERROR(VLOOKUP($H18,[4]SEMIELABORADOS!$A$1:$J$998,2,0),"") | C18: =+A18 -> 0 | D18: =IFERROR(VLOOKUP($H18,[4]SEMIELABORADOS!$A$1:$J$998,4,0),"") | E18: =IFERROR(VLOOKUP($H18,[4]SEMIELABORADOS!$A$1:$J$998,6,0),"") | F18: =IFERROR(E18*C18,"") | G18: =IFERROR(F18/$F$59,"")
B19: =IFERROR(VLOOKUP($H19,[4]SEMIELABORADOS!$A$1:$J$998,2,0),"") | C19: =+A19 -> 0 | D19: =IFERROR(VLOOKUP($H19,[4]SEMIELABORADOS!$A$1:$J$998,4,0),"") | E19: =IFERROR(VLOOKUP($H19,[4]SEMIELABORADOS!$A$1:$J$998,6,0),"") | F19: =IFERROR(E19*C19,"") | G19: =IFERROR(F19/$F$59,"")
B20: =IFERROR(VLOOKUP($H20,[4]SEMIELABORADOS!$A$1:$J$998,2,0),"") | C20: =+A20 -> 0 | D20: =IFERROR(VLOOKUP($H20,[4]SEMIELABORADOS!$A$1:$J$998,4,0),"") | E20: =IFERROR(VLOOKUP($H20,[4]SEMIELABORADOS!$A$1:$J$998,6,0),"") | F20: =IFERROR(E20*C20,"") | G20: =IFERROR(F20/$F$59,"")
B21: =IFERROR(VLOOKUP($H21,[4]SEMIELABORADOS!$A$1:$J$998,2,0),"") | C21: =+A21 -> 0 | D21: =IFERROR(VLOOKUP($H21,[4]SEMIELABORADOS!$A$1:$J$998,4,0),"") | E21: =IFERROR(VLOOKUP($H21,[4]SEMIELABORADOS!$A$1:$J$998,6,0),"") | F21: =IFERROR(E21*C21,"") | G21: =IFERROR(F21/$F$59,"")
A23: UNIDADES | B23: EMPAQUE | C23: UNIDADES | D23: UND MEDIDA | E23: COSTO UNITARIO | F23: TOTAL COSTO | G23: % PREC. DEFINIDO | H23: CODIGOS
A24: 1 | B24: =IFERROR(VLOOKUP(H24,'[1]EMPAQUE PLANTA'!$A$2:$H$176,2,0),"") -> BOLSA 17x25 TRANSP KILO | C24: =+A24 -> 1 | D24: =IFERROR(VLOOKUP(H24,'[1]EMPAQUE PLANTA'!$A$2:$H$176,7,0),"") -> UND | E24: =IFERROR(VLOOKUP(H24,'[1]EMPAQUE PLANTA'!$A$2:$H$176,8,0),"") -> 33.333333 | F24: =IFERROR(E24*C24,"") -> 33.333333 | G24: =IFERROR(F24/$F$59,"") -> 0.0042368002 | H24: 1950708
A25: 1 | B25: ETIQ.BLANCA 1 1/4 * 3/4 (UND) | C25: =+A25 -> 1 | D25: UND | E25: =IFERROR(VLOOKUP($H25,'[4]EMP PLANTA'!$A$2:$F$500,6,0),"") -> 0.616 | F25: =IFERROR(E25*C25,"") -> 0.616 | G25: =IFERROR(F25/$F$59,"") -> 7.8296068e-05 | H25: 0702069
A26: 1 | B26: ETIQ.FECHA VENCIMIENTO BLANCO (ROLLO) | C26: =+A26 -> 1 | D26: UND | E26: =IFERROR(VLOOKUP($H26,'[4]EMP PLANTA'!$A$2:$F$500,6,0),"") -> 0.22878 | F26: =IFERROR(E26*C26,"") -> 0.22878 | G26: =IFERROR(F26/$F$59,"") -> 2.9078855e-05 | H26: 0702007
B27: =IFERROR(VLOOKUP(H27,'[1]EMPAQUE PLANTA'!$A$2:$H$176,2,0),"") | C27: =+A27 -> 0 | D27: =IFERROR(VLOOKUP(H27,'[1]EMPAQUE PLANTA'!$A$2:$H$176,7,0),"") | E27: =IFERROR(VLOOKUP($H27,'[4]EMP PLANTA'!$A$2:$F$500,6,0),"") | F27: =IFERROR(E27*C27,"") | G27: =IFERROR(F27/$F$59,"")
B28: =IFERROR(VLOOKUP(H28,'[1]EMPAQUE PLANTA'!$A$2:$H$176,2,0),"") | C28: =+A28 -> 0 | D28: =IFERROR(VLOOKUP(H28,'[1]EMPAQUE PLANTA'!$A$2:$H$176,7,0),"") | E28: =IFERROR(VLOOKUP($H28,'[4]EMP PLANTA'!$A$2:$F$500,6,0),"") | F28: =IFERROR(E28*C28,"") | G28: =IFERROR(F28/$F$59,"")
B29: =IFERROR(VLOOKUP(H29,'[1]EMPAQUE PLANTA'!$A$2:$H$176,2,0),"") | C29: =+A29 -> 0 | D29: =IFERROR(VLOOKUP(H29,'[1]EMPAQUE PLANTA'!$A$2:$H$176,7,0),"") | E29: =IFERROR(VLOOKUP($H29,'[4]EMP PLANTA'!$A$2:$F$500,6,0),"") | F29: =IFERROR(E29*C29,"") | G29: =IFERROR(F29/$F$59,"")
B30: =IFERROR(VLOOKUP(H30,'[1]EMPAQUE PLANTA'!$A$2:$H$176,2,0),"")
A31: UNIDADES | B31: EMPAQUE SEMIELABORADOS | C31: UNIDADES | D31: UND MEDIDA | E31: COSTO UNITARIO | F31: TOTAL COSTO | G31: % PREC. DEFINIDO | H31: CODIGOS
A32: =+A17 -> 5000 | B32: RELLENO DE FRESA ESPESA PLANTA | C32: =+A32 -> 5000 | D32: N/A | E32: =+'Costo Relleno 6-04-2020'!E69 -> 0.0053619046 | F32: =IFERROR(E32*C32,"") -> 26.809523 | G32: =IFERROR(F32/$F$58,"") -> 0.48744587
A33: =+A18 -> 0 | C33: =+A33 -> 0 | D33: N/A | E33: =IFERROR(VLOOKUP($H33,[4]SEMIELABORADOS!$A$1:$J$998,8,0),"") | F33: =IFERROR(E33*C33,"") | G33: =IFERROR(F33/$F$58,"")
A34: =+A19 -> 0 | C34: =+A34 -> 0 | D34: N/A | E34: =IFERROR(VLOOKUP($H34,[4]SEMIELABORADOS!$A$1:$J$998,8,0),"") | F34: =IFERROR(E34*C34,"") | G34: =IFERROR(F34/$F$58,"")
A35: =+A20 -> 0 | C35: =+A35 -> 0 | D35: N/A | E35: =IFERROR(VLOOKUP($H35,[4]SEMIELABORADOS!$A$1:$J$998,8,0),"") | F35: =IFERROR(E35*C35,"") | G35: =IFERROR(F35/$F$58,"")
A36: =+A21 -> 0 | C36: =+A36 -> 0 | D36: N/A | E36: =IFERROR(VLOOKUP($H36,[4]SEMIELABORADOS!$A$1:$J$998,8,0),"") | F36: =IFERROR(E36*C36,"") | G36: =IFERROR(F36/$F$58,"")
A38: UNIDADES | B38: MODI | C38: UNIDADES | E38: COSTO UNITARIO | F38: TOTAL COSTO | G38: % PREC. DEFINIDO | H38: CODIGOS
A39: =+A17 -> 5000 | B39: RELLENO DE FRESA ESPESA PLANTA | C39: =+A39 -> 5000 | D39: N/A | E39: =+'Costo Relleno 6-04-2020'!E67 -> 0.070294995 | F39: =IFERROR(C39*E39,"") -> 351.47497 | G39: =IFERROR(F39/$F$59,"") -> 0.044673877
A40: =+A18 -> 0 | C40: =+A40 -> 0 | D40: N/A | E40: =IFERROR(VLOOKUP($H40,[4]SEMIELABORADOS!$A$1:$J$998,10,0),"") | F40: =IFERROR(C40*E40,"") | G40: =IFERROR(F40/$F$59,"")
A41: =+A19 -> 0 | C41: =+A41 -> 0 | D41: N/A | E41: =IFERROR(VLOOKUP($H41,[4]SEMIELABORADOS!$A$1:$J$998,10,0),"") | F41: =IFERROR(C41*E41,"") | G41: =IFERROR(F41/$F$59,"")
A42: =+A20 -> 0 | C42: =+A42 -> 0 | D42: N/A | E42: =IFERROR(VLOOKUP($H42,[4]SEMIELABORADOS!$A$1:$J$998,10,0),"") | F42: =IFERROR(C42*E42,"") | G42: =IFERROR(F42/$F$59,"")
A43: =+A21 -> 0 | C43: =+A43 -> 0 | D43: N/A | E43: =IFERROR(VLOOKUP($H43,[4]SEMIELABORADOS!$A$1:$J$998,10,0),"") | F43: =IFERROR(C43*E43,"") | G43: =IFERROR(F43/$F$59,"")
A44: 1 | B44: MODI PREPARACION | C44: =+A44 -> 1 | D44: N/A | E44: =+F58 -> 55 | F44: =IFERROR(C44*E44,"") -> 55 | G44: =IFERROR(F44/$F$59,"") -> 0.0069907203
...

Sheet COSTEO EMP
E1: Precio Local | F1: Costo MP | G1: Costo EM | H1: Costo MO
E2: =IFERROR(O53,"") -> 8330.634 | F2: =IFERROR(H42,"") -> 1342.5618 | G2: =IFERROR(H43,"") -> 10.009725 | H2: =IFERROR(H45,"") -> 71.460703
A4: EMPAQUE RELLENO FRESA
A5: ESTRUCTURA DE COSTOS
F6: Fecha: | H6: =TODAY() -> 45701
A7: UNIDADES | B7: DESCRIPCION MAT.PRIMA | C7: UNIDADES | D7: UND MEDIDA | E7: COSTO UNITARIO | F7: TOTAL COSTO | G7: % PREC. DEFINIDO | H7: CODIGOS
B8: =IFERROR(VLOOKUP($H8,'[4]MP PLANTA'!$A$2:$F$500,2,0),"") | C8: =+A8 -> 0 | D8: =IFERROR(VLOOKUP($H8,'[4]MP PLANTA'!$A$2:$F$500,5,0),"") | E8: =IFERROR(VLOOKUP($H8,'[4]MP PLANTA'!$A$2:$F$500,6,0),"") | F8: =IFERROR(C8*E8,"") | G8: =IFERROR(F8/$F$55,"")
B9: =IFERROR(VLOOKUP($H9,'[4]MP PLANTA'!$A$2:$F$500,2,0),"") | C9: =+A9 -> 0 | D9: =IFERROR(VLOOKUP($H9,'[4]MP PLANTA'!$A$2:$F$500,5,0),"") | E9: =IFERROR(VLOOKUP($H9,'[4]MP PLANTA'!$A$2:$F$500,6,0),"") | F9: =IFERROR(C9*E9,"") | G9: =IFERROR(F9/$F$55,"")
B10: =IFERROR(VLOOKUP($H10,'[4]MP PLANTA'!$A$2:$F$500,2,0),"") | C10: =+A10 -> 0 | D10: =IFERROR(VLOOKUP($H10,'[4]MP PLANTA'!$A$2:$F$500,5,0),"") | E10: =IFERROR(VLOOKUP($H10,'[4]MP PLANTA'!$A$2:$F$500,6,0),"") | F10: =IFERROR(C10*E10,"") | G10: =IFERROR(F10/$F$55,"")
B11: =IFERROR(VLOOKUP($H11,'[4]MP PLANTA'!$A$2:$F$500,2,0),"") | C11: =+A11 -> 0 | D11: =IFERROR(VLOOKUP($H11,'[4]MP PLANTA'!$A$2:$F$500,5,0),"") | E11: =IFERROR(VLOOKUP($H11,'[4]MP PLANTA'!$A$2:$F$500,6,0),"") | F11: =IFERROR(C11*E11,"") | G11: =IFERROR(F11/$F$55,"")
B12: =IFERROR(VLOOKUP($H12,'[4]MP PLANTA'!$A$2:$F$500,2,0),"") | C12: =+A12 -> 0 | D12: =IFERROR(VLOOKUP($H12,'[4]MP PLANTA'!$A$2:$F$500,5,0),"") | E12: =IFERROR(VLOOKUP($H12,'[4]MP PLANTA'!$A$2:$F$500,6,0),"") | F12: =IFERROR(C12*E12,"") | G12: =IFERROR(F12/$F$55,"")
B13: =IFERROR(VLOOKUP($H13,'[4]MP PLANTA'!$A$2:$F$500,2,0),"") | C13: =+A13 -> 0 | D13: =IFERROR(VLOOKUP($H13,'[4]MP PLANTA'!$A$2:$F$500,5,0),"") | E13: =IFERROR(VLOOKUP($H13,'[4]MP PLANTA'!$A$2:$F$500,6,0),"") | F13: =IFERROR(C13*E13,"") | G13: =IFERROR(F13/$F$55,"")
B14: =IFERROR(VLOOKUP($H14,'[4]MP PLANTA'!$A$2:$F$500,2,0),"") | C14: =+A14 -> 0 | D14: =IFERROR(VLOOKUP($H14,'[4]MP PLANTA'!$A$2:$F$500,5,0),"") | E14: =IFERROR(VLOOKUP($H14,'[4]MP PLANTA'!$A$2:$F$500,6,0),"") | F14: =IFERROR(C14*E14,"") | G14: =IFERROR(F14/$F$55,"")
A16: UNIDADES | B16: MATERIA PRIMA SEMIELABORADOS | C16: UNIDADES | D16: UND MEDIDA | E16: COSTO UNITARIO | F16: TOTAL COSTO | G16: % PREC. DEFINIDO | H16: CODIGOS
A17: 5000 | B17: RELLENO FRESA SPOON | C17: =+A17 -> 5000 | D17: Gramo | E17: =+'COSTEO RELL'!E58 -> 1.3425618 | F17: =IFERROR(E17*C17,"") -> 6712.8091 | G17: =IFERROR(F17/$F$55,"") -> 0.96738707
B18: =IFERROR(VLOOKUP($H18,[4]SEMIELABORADOS!$A$1:$J$999,2,0),"") | C18: =+A18 -> 0 | D18: =IFERROR(VLOOKUP($H18,[4]SEMIELABORADOS!$A$1:$J$999,4,0),"") | E18: =IFERROR(VLOOKUP($H18,[4]SEMIELABORADOS!$A$1:$J$999,6,0),"") | F18: =IFERROR(E18*C18,"") | G18: =IFERROR(F18/$F$55,"")
B19: =IFERROR(VLOOKUP($H19,[4]SEMIELABORADOS!$A$1:$J$999,2,0),"") | C19: =+A19 -> 0 | D19: =IFERROR(VLOOKUP($H19,[4]SEMIELABORADOS!$A$1:$J$999,4,0),"") | E19: =IFERROR(VLOOKUP($H19,[4]SEMIELABORADOS!$A$1:$J$999,6,0),"") | F19: =IFERROR(E19*C19,"") | G19: =IFERROR(F19/$F$55,"")
B20: =IFERROR(VLOOKUP($H20,[4]SEMIELABORADOS!$A$1:$J$999,2,0),"") | C20: =+A20 -> 0 | D20: =IFERROR(VLOOKUP($H20,[4]SEMIELABORADOS!$A$1:$J$999,4,0),"") | E20: =IFERROR(VLOOKUP($H20,[4]SEMIELABORADOS!$A$1:$J$999,6,0),"") | F20: =IFERROR(E20*C20,"") | G20: =IFERROR(F20/$F$55,"")
B21: =IFERROR(VLOOKUP($H21,[4]SEMIELABORADOS!$A$1:$J$999,2,0),"") | C21: =+A21 -> 0 | D21: =IFERROR(VLOOKUP($H21,[4]SEMIELABORADOS!$A$1:$J$999,4,0),"") | E21: =IFERROR(VLOOKUP($H21,[4]SEMIELABORADOS!$A$1:$J$999,6,0),"") | F21: =IFERROR(E21*C21,"") | G21: =IFERROR(F21/$F$55,"")
A23: UNIDADES | B23: EMPAQUE | C23: UNIDADES | D23: UND MEDIDA | E23: COSTO UNITARIO | F23: TOTAL COSTO | G23: % PREC. DEFINIDO | H23: CODIGOS
A24: 1 | B24: =IFERROR(VLOOKUP($H24,'[4]EMP PLANTA'!$A$2:$F$500,2,0),"") -> BOLSA 17x25 TRANSP (KILO) | C24: =+A24 -> 1 | D24: =IFERROR(VLOOKUP($H24,'[4]EMP PLANTA'!$A$2:$F$500,5,0),"") -> UND | E24: =IFERROR(VLOOKUP($H24,'[4]EMP PLANTA'!$A$2:$F$500,6,0),"") -> 32.142857 | F24: =IFERROR(E24*C24,"") -> 32.142857 | G24: =IFERROR(F24/$F$55,"") -> 0.004632127 | H24: 1950708
A25: 1 | B25: =IFERROR(VLOOKUP($H25,'[4]EMP PLANTA'!$A$2:$F$500,2,0),"") -> ETIQ.BLANCA 1 13/16 * 1 7/8 | C25: =+A25 -> 1 | D25: =IFERROR(VLOOKUP($H25,'[4]EMP PLANTA'!$A$2:$F$500,5,0),"") -> UND | E25: =IFERROR(VLOOKUP($H25,'[4]EMP PLANTA'!$A$2:$F$500,6,0),"") -> 2.047 | F25: =IFERROR(E25*C25,"") -> 2.047 | G25: =IFERROR(F25/$F$55,"") -> 0.00029499444 | H25: 0702067
A26: 1 | B26: =IFERROR(VLOOKUP($H26,'[4]EMP PLANTA'!$A$2:$F$500,2,0),"") -> ETIQ.FECHA VENCIMIENTO VERDE | C26: =+A26 -> 1 | D26: =IFERROR(VLOOKUP($H26,'[4]EMP PLANTA'!$A$2:$F$500,5,0),"") -> UND | E26: =IFERROR(VLOOKUP($H26,'[4]EMP PLANTA'!$A$2:$F$500,6,0),"") -> 0.21185444 | F26: =IFERROR(E26*C26,"") -> 0.21185444 | G26: =IFERROR(F26/$F$55,"") -> 3.0530475e-05 | H26: 0702012
B27: =IFERROR(VLOOKUP($H27,'[4]EMP PLANTA'!$A$2:$F$500,2,0),"") | C27: =+A27 -> 0 | D27: =IFERROR(VLOOKUP($H27,'[4]EMP PLANTA'!$A$2:$F$500,5,0),"") | E27: =IFERROR(VLOOKUP($H27,'[4]EMP PLANTA'!$A$2:$F$500,6,0),"") | F27: =IFERROR(E27*C27,"") | G27: =IFERROR(F27/$F$55,"")
B28: =IFERROR(VLOOKUP($H28,'[4]EMP PLANTA'!$A$2:$F$500,2,0),"") | C28: =+A28 -> 0 | D28: =IFERROR(VLOOKUP($H28,'[4]EMP PLANTA'!$A$2:$F$500,5,0),"") | E28: =IFERROR(VLOOKUP($H28,'[4]EMP PLANTA'!$A$2:$F$500,6,0),"") | F28: =IFERROR(E28*C28,"") | G28: =IFERROR(F28/$F$55,"")
B29: =IFERROR(VLOOKUP($H29,'[4]EMP PLANTA'!$A$2:$F$500,2,0),"") | C29: =+A29 -> 0 | D29: =IFERROR(VLOOKUP($H29,'[4]EMP PLANTA'!$A$2:$F$500,5,0),"") | E29: =IFERROR(VLOOKUP($H29,'[4]EMP PLANTA'!$A$2:$F$500,6,0),"") | F29: =IFERROR(E29*C29,"") | G29: =IFERROR(F29/$F$55,"")
A31: UNIDADES | B31: EMPAQUE SEMIELABORADOS | C31: UNIDADES | D31: UND MEDIDA | E31: COSTO UNITARIO | F31: TOTAL COSTO | G31: % PREC. DEFINIDO | H31: CODIGOS
A32: =+A17 -> 5000 | B32: RELLENO FRESA SPOON | C32: =+A32 -> 5000 | D32: N/A | E32: =+'COSTEO RELL'!E65 -> 0.0031293822 | F32: =IFERROR(E32*C32,"") -> 15.646911 | G32: =IFERROR(F32/$F$54,"") -> 0.3725455
A33: =+A18 -> 0 | C33: =+A33 -> 0 | D33: N/A | E33: =IFERROR(VLOOKUP($H33,[4]SEMIELABORADOS!$A$1:$J$999,8,0),"") | F33: =IFERROR(E33*C33,"") | G33: =IFERROR(F33/$F$54,"")
A34: =+A19 -> 0 | C34: =+A34 -> 0 | D34: N/A | E34: =IFERROR(VLOOKUP($H34,[4]SEMIELABORADOS!$A$1:$J$999,8,0),"") | F34: =IFERROR(E34*C34,"") | G34: =IFERROR(F34/$F$54,"")
A35: =+A20 -> 0 | C35: =+A35 -> 0 | D35: N/A | E35: =IFERROR(VLOOKUP($H35,[4]SEMIELABORADOS!$A$1:$J$999,8,0),"") | F35: =IFERROR(E35*C35,"") | G35: =IFERROR(F35/$F$54,"")
A36: =+A21 -> 0 | C36: =+A36 -> 0 | D36: N/A | E36: =IFERROR(VLOOKUP($H36,[4]SEMIELABORADOS!$A$1:$J$999,8,0),"") | F36: =IFERROR(E36*C36,"") | G36: =IFERROR(F36/$F$54,"")
A38: UNIDADES | B38: MODI | C38: UNIDADES | E38: COSTO UNITARIO | F38: TOTAL COSTO | G38: % PREC. DEFINIDO | H38: CODIGOS
A39: =+A17 -> 5000 | B39: RELLENO FRESA SPOON | C39: =+A39 -> 5000 | D39: N/A | E39: =+'COSTEO RELL'!E63 -> 0.063060703 | F39: =IFERROR(C39*E39,"") -> 315.30351 | G39: =IFERROR(F39/$F$55,"") -> 0.045438585
A40: 1 | B40: MODI PREPARACION | C40: =+A40 -> 1 | D40: N/A | E40: =+F54 -> 42 | F40: =IFERROR(C40*E40,"") -> 42 | G40: =IFERROR(F40/$F$55,"") -> 0.006052646
B42: TOTAL MATERIA PRIMA | F42: =SUM(F8:F14,F17:F21) -> 6712.8091 | G42: =+F42/$F$55 -> 0.96738707 | H42: =+F42/$D$48*1000 -> 1342.5618
B43: TOTAL EMPAQUE | F43: =SUM(F24:F29,F32:F36) -> 50.048623 | G43: =+F43/$F$55 -> 0.007212538 | H43: =+F43/$D$48*1000 -> 10.009725 | K43: TOTAL MATERIA PRIMA + EMPAQUE | O43: =+F44 -> 6762.8577
B44: TOTAL MATERIAS P. + EMPAQUES | F44: =+F42+F43 -> 6762.8577 | G44: =+F44/$F$55 -> 0.97459961 | H44: =+F44/$D$48*1000 -> 1352.5715 | L44: MODI PLANTA | O44: =+F45 -> 357.30351
C45: TOTAL MODI | F45: =SUM(F39:F40) -> 357.30351 | G45: =+F45/$F$55 -> 0.051491231 | H45: =+F45/$D$48*1000 -> 71.460703 | L45: DESECHO | N45: 0.02 | O45: =+(O43+O44)*N45 -> 142.40322
L46: GAF | N46: =230%*0.85 -> 1.955 | O46: =+O44*N46 -> 698.52837
...
