Workbook

Sheet Base de Galleta CK
C1: SERVICIOS DE PASTELERIA S.A. | H1: CÓDIGO: | I1: ESP-RE-POS-031
C2: ESPECIFICACION DE RECETA | H2: REVISIÓN: | I2: 15
C3: Base Galleta Cheesecake SE00041 | H3: FECHA DE APROBACIÓN: | I3: 45546
C4: Elaborado | D4: Javier Tong, Chef
C5: Aprobado | D5: Esteban Cartin, Gte Manufactura
A6: AREA QUE PRODUCE: | D6: Postres | G6: AREA QUE EMPACA: | I6: Postres
A7: # Código | B7: # Codigo Netsuite | C7: Descripción del ingrediente | D7: Marca | E7: Unidad Internacional | G7: Medida Costos | I7: Costo - Referencia
E8: Cantidad | F8: Unidad medida | G8: Cantidad | H8: Unidad medida | I8: Colones
A9: 10100344 | B9: MP10523 | C9: GALLETA SODA MOLIDA (PAQ:1 KILO) | D9: POZUELO | E9: 2500 | F9: g
A10: 10100345 | B10: MP10555 | C10: GALLETA YEMITA (KILO) | D10: POZUELO | E10: 1500 | F10: g
A11: 906000002 | B11: SE00204 | C11: Corte Galleta Chilena Grande | D11: FAS | E11: 1000 | F11: g | G11: RECORTE DE CHILENA
A12: 0310107 | B12: MP10022 | C12: LACTOCREMA GRANEL (CAJA:25 KG) | D12: DOS PINOS | E12: 3000 | F12: g
A13: 101000073 | B13: MP10041 | C13: AZUCAR GLASS MOLIDA (PAQ: 4 K) | E13: 1400 | F13: g
A14: 1212410 | B14: MP10008 | C14: PRESERVANTE 1047S (PAQ=5 KILO) | E14: 10 | F14: g
D17: Cantidad | E17: Unidad
A18: PESO TOTAL OBTENIDO | D18: 9000 | E18: g | F18: TIEMPO DE HORNEO
A19: TIEMPO TOTAL DE PREPARACION | D19: 15 | E19: min | F19: HORNO
A20: CANTIDAD DE PORCIONES OBTENIDAS | D20: =D18/D21 -> 1 | E20: Tanda | F20: TEMPERATURA HORNEO | H20: =15/9 -> 1.6666667
A21: PESO DE CADA PORCIÓN | D21: 9000 | E21: g | F21: OTROS
A22: MERMA | D22: =SUM(E9:E15)-D18 -> 410 | E22: g
A23: PROCEDIMIENTO DE PREPARACION DE LA RECETA
A24: 1.- Derretir la lactocrema. No hervir.
A25: 2.- Mezclar todos los ingredientes en un bowl con el azucar en polvo.
A26: 2, Mezclar la galletas procesada con el azucar y la lactocrema, en batidora con paleta, hasta homogeneo.
A28: CONTROL DE CAMBIOS
A30: Revisión #9: Actualización de codigos
A31: Revisión #10: Actualizacion de peso final, y productos de reproceso.
A32: Revisión #11: Actualizacion completa por cambio de galletas y rendimiento.
A33: Revision #12: Actualizacion del peso de la lactocrema y el rendimiento.
A34: Revision #13: Se elimina galleta Maria y se agrega recorte de galleta chilena Spoon
A35: Revision #14: Se le bajo Lactocrema
A36: Revisión# 15:Se le aumenta la cantidad de lactocrema a la receta

Sheet Base galleta Cheese Cake
C1: SERVICIOS DE PASTELERIA S.A. | H1: CÓDIGO: | I1: ESP-RE-POS-011
C2: ESPECIFICACION DE RECETA | H2: REVISIÓN: | I2: 01
C3: Base Galleta Cheesecake SE00041 | H3: FECHA DE APROBACIÓN: | I3: 45615
C4: Elaborado | D4: Javier Tong, Chef
C5: Aprobado | D5: Esteban Cartin, Gte Manufactura
A6: AREA QUE PRODUCE: | D6: Postres | G6: AREA QUE EMPACA: | I6: Postres
A7: # Código | B7: # Código Netsuite | C7: Descripción del ingrediente | D7: Marca | E7: Unidad Internacional | G7: Medida alternativa | I7: Costo - Referencia
E8: Cantidad | F8: Unidad medida | G8: Cantidad | H8: Unidad medida | I8: Colones
C9: Ensamble
A10: 10100344 | B10: MP10523 | C10: GALLETA SODA MOLIDA (PAQ:1 KILO) | D10: POZUELO | E10: 2500 | F10: g
A11: 10100345 | B11: MP10555 | C11: GALLETA YEMITA (KILO) | D11: POZUELO | E11: 1500 | F11: g
A12: 906000002 | B12: SE00204 | C12: CORTE GALLETA CHILENA GRANDE | D12: FAS | E12: 1000 | F12: g
A13: 0310107 | B13: MP10022 | C13: LACTOCREMA GRANEL (CAJA:25 KG) | D13: DOS PINOS | E13: 3000 | F13: g
A14: 101000073 | B14: MP10041 | C14: AZUCAR GLASS MOLIDA (PAQ: 4 K) | E14: 1400 | F14: g
A15: 1212410 | B15: MP10008 | C15: PRESERVANTE 1047S (PAQ=5 KILO) | E15: 10 | F15: g
C18: Decoración
C27: Empaque
D40: Cantidad | E40: Unidad
A41: PESO TOTAL OBTENIDO | D41: 9000 | E41: g | F41: Tiempo de Horneo:
A42: TIEMPO TOTAL DE PREPARACION | D42: 15 | E42: min | F42: Horno:
A43: CANTIDAD DE PORCIONES OBTENIDAS | D43: 1 | E43: Tanda | F43: Temperatura de Horneo:
A44: PESO DE CADA PORCIÓN | D44: 9000 | E44: g | F44: Otros
A45: MERMA | D45: 410 | E45: g
A46: PROCEDIMIENTO DE PREPARACION DE LA RECETA
A47: 1.- Derretir la lactocrema. No hervir.
A48: 2, Mezclar la galletas procesada con el azucar y la lactocrema, en batidora con paleta, hasta homogeneo.
A55: CONTROL DE CAMBIOS

Sheet Corte Galleta Chilena 
C1: SERVICIOS DE PASTELERIA S.A. | H1: CÓDIGO: | I1: ESP-RE-PAPS-002
C2: ESPECIFICACION DE RECETA | H2: REVISIÓN: | I2: 01
C3: Corte Galleta Chilena Grande 143g 906000002(SE00204) | H3: FECHA DE APROBACIÓN: | I3: 45611
C4: Elaborado | D4: Javier Tong, Chef
C5: Aprobado | D5: Esteban Cartin, Gte Manufactura
A6: AREA QUE PRODUCE: | D6: Pastas | G6: AREA QUE EMPACA: | I6: Pastas
A7: # Código | B7: # Código Netsuite | C7: Descripción del ingrediente | D7: Marca | E7: Unidad Internacional | G7: Medida alternativa | I7: Costo - Referencia
E8: Cantidad | F8: Unidad medida | G8: Cantidad | H8: Unidad medida | I8: Colones
C9: Ensamble
A10: 906000035 | B10: SE00177 | C10: PASTA TORTA CHILENA SPOON KILO | D10: FAS | E10: 1001 | F10: g
A11: 90100137 | B11: SE00183 | C11: EMPAQUE HARINA ESTANDAR (KILO) | D11: FAS | E11: 20 | F11: g
C18: Decoración
C24: Empaque
D35: Cantidad | E35: Unidad
A36: PESO TOTAL OBTENIDO | D36: 1001 | E36: g | F36: Tiempo de Horneo:
A37: TIEMPO TOTAL DE PREPARACION | D37: 2 | E37: min | F37: Horno:
A38: CANTIDAD DE PORCIONES OBTENIDAS | D38: 7 | E38: Galletas | F38: Temperatura de Horneo:
A39: PESO DE CADA PORCIÓN | D39: 143 | E39: g | F39: Otros
A40: MERMA | D40: 0 | E40: g
A41: PROCEDIMIENTO DE PREPARACION DE LA RECETA
A42: 1-. Laminar la masa hasta 4 mm con ayuda e la maquina, hacer huecos con el zorro. En la laminadora Rondo a 2.8, en la laminadora Kemplex 3.
A43: 2-. Cortar con cortador redondo de 23 cm diametro y colocar los 7 circulos en la bandeja
A44: 3-. Llevar al horno en Dicte 1 por 23 min a 170°C o Dicte 2 por 22 a 24 min a 170°C.
A45: 4-. Enfriar.
A51: CONTROL DE CAMBIOS

Sheet Pasta torta Chilena 
C1: SERVICIOS DE PASTELERIA S.A. | H1: CÓDIGO: | I1: ESP-RE-PAPS-011
C2: ESPECIFICACION DE RECETA | H2: REVISIÓN: | I2: 01
C3: PASTA TORTA CHILENA SPOON KILO SE00177 | H3: FECHA DE APROBACIÓN: | I3: 45611
C4: Elaborado | D4: Javier Tong, Chef
C5: Aprobado | D5: Esteban Cartin, Gte Manufactura
A6: AREA QUE PRODUCE: | D6: Pastas | G6: AREA QUE EMPACA: | I6: Pastas
A7: # Código | B7: # Código Netsuite | C7: Descripción del ingrediente | D7: Marca | E7: Unidad Internacional | G7: Medida alternativa | I7: Costo - Referencia
E8: Cantidad | F8: Unidad medida | G8: Cantidad | H8: Unidad medida | I8: Colones
C9: Ensamble
A10: 901000014 | B10: SE00178 | C10: PREMEZCLA P/PASTA CHILENA SPOON | D10: Spoon | E10: 23524 | F10: g
C16: Decoración
C22: Empaque
D33: Cantidad | E33: Unidad
A34: PESO TOTAL OBTENIDO | D34: 23300 | E34: g | F34: Tiempo de Horneo: | H34: 60 min
A35: TIEMPO TOTAL DE PREPARACION | D35: 8 | E35: min | F35: Horno: | H35: Dicte 1,2,3
A36: CANTIDAD DE PORCIONES OBTENIDAS | D36: 1 | E36: Tanda | F36: Temperatura de Horneo: | H36: 185 C
A37: PESO DE CADA PORCIÓN | D37: 23300 | E37: g | F37: Otros
A38: MERMA | D38: 224 | E38: g
A39: PROCEDIMIENTO DE PREPARACION DE LA RECETA
A40: 1.- Colocar la margarina, azucar y harina y preservante. Batir en velocidad 1 por 3 minutos, con ayuda de la paleta.
A41: 2.- Utilizar de inmediato.
A49: CONTROL DE CAMBIOS

Sheet Premezca pasta chilena 
C1: SERVICIOS DE PASTELERIA S.A. | H1: CÓDIGO: | I1: ESP-RE-PRES-008
C2: ESPECIFICACION DE RECETA | H2: REVISIÓN: | I2: 01
C3: PREMEZCLA P/PASTA CHILENA SPOON 901000014(SE00178) | H3: FECHA DE APROBACIÓN: | I3: 45616
C4: Elaborado | D4: Javier Tong, Chef
C5: Aprobado | D5: Esteban Cartin, Gte Manufactura
A6: AREA QUE PRODUCE: | D6: Premezclas | G6: AREA QUE EMPACA: | I6: Premezclas
A7: # Código | B7: # Código Netsuite | C7: Descripción del ingrediente | D7: Marca | E7: Unidad Internacional | G7: Medida alternativa | I7: Costo - Referencia
E8: Cantidad | F8: Unidad medida | G8: Cantidad | H8: Unidad medida | I8: Colones
C9: Ensamble
B10: MP10040 | C10: MARGARINA BAKER TABLETA (CAJA: 25 K) | D10: NUMAR | E10: 9000 | F10: g
B11: MP10049 | C11: AZUCAR POLVO P.REAL (PAQ:2.5 Kg) | D11: PASTELERO REAL | E11: 1 | F11: Bolsa
B12: MP10051 | C12: HARINA TRIGO NACARINA (SACO: 25 K) | D12: NACARINA | E12: 12000 | F12: g
B13: MP10008 | C13: PRESERVANTE 1047S (PAQ=5 KILO) | D13: ASEAL | E13: 24 | F13: g
C18: Decoración
C25: Empaque
B26: EM10011 | C26: ETIQUETA BLANCA 2 5/8X1 15/16 (UND) | D26: ETIPLAST | E26: 2 | F26: ud
B27: EM10013 | C27: BOLSA 17x25 TRANSP | D27: PLASTICOS P | E27: 2 | F27: ud
B28: EM10133 | C28: ETIQUETA ROJA LETRA ALERJENO (UND) | D28: ETIPLAST | E28: 1 | F28: ud
B29: AS00020 | C29: GUANTE LATEX CORRIENTE (CAJA:100 UND) | D29: MAYCA | E29: 2 | F29: ud
D38: Cantidad | E38: Unidad
A39: PESO TOTAL OBTENIDO | D39: 23524 | E39: g | F39: Tiempo de Horneo:
A40: TIEMPO TOTAL DE PREPARACION | D40: 0.14583333 | E40: Minutos | F40: Horno:
A41: CANTIDAD DE PORCIONES OBTENIDAS | D41: 1 | E41: Tanda | F41: Temperatura de Horneo:
A42: PESO DE CADA PORCIÓN | D42: 23524 | E42: g | F42: Otros
A43: MERMA | D43: 0 | E43: g
A44: PROCEDIMIENTO DE PREPARACION DE LA RECETA
A45: 1.- Colocar en 1 bolsa 17*25 la margarina. Etiquetar con nombre y alerjeno
A46: 2.- Colocar la harina, preservante en otra bolsa 17*25, enviar 1 bolsa de azucar en polvo entera.
A47: 3.- Etiquetar ambas bolsas con nombre y alerjeno.
A53: CONTROL DE CAMBIOS

Sheet Costo postre Lemon
E1: Precio Local | F1: Costo MP | G1: Costo EM | H1: Costo MO
E2: =IFERROR(O62,"") -> 2671.0358 | F2: =IFERROR(H53,"") -> 1908.8278 | G2: =IFERROR(H54,"") -> 389.28464 | H2: =IFERROR(H56,"") -> 203.6532
A5: ESTRUCTURA DE COSTOS
F6: Fecha: | H6: =TODAY() -> 46064
A7: UNIDADES | B7: DESCRIPCION MAT.PRIMA | C7: UNIDADES | D7: UND MEDIDA | E7: COSTO UNITARIO | F7: TOTAL COSTO | G7: % PREC. DEFINIDO | H7: CODIGOS
A8: 5 | B8: Aceite Capullo Rbd | C8: =+A8 -> 5 | D8: Gramos | E8: 0.89 | F8: =IFERROR(C8*E8,"") -> 4.45 | G8: =IFERROR(F8/$F$66,"") -> 0.0018439566 | H8: MP10002
B9: =IFERROR(VLOOKUP(H9,'[1]Consolidado MP Planta'!$A$2:$M$823,3,0),"") | C9: =+A9 -> 0 | D9: =IFERROR(VLOOKUP(H9,'[1]Consolidado MP Planta'!$A$2:$M$823,13,0),"") | E9: =IFERROR(VLOOKUP(H9,'[1]Consolidado MP Planta'!$A$2:$M$823,12,0),"") | F9: =IFERROR(C9*E9,"") | G9: =IFERROR(F9/$F$66,"")
B10: =IFERROR(VLOOKUP(H10,'[1]Consolidado MP Planta'!$A$2:$M$823,3,0),"") | C10: =+A10 -> 0 | D10: =IFERROR(VLOOKUP(H10,'[1]Consolidado MP Planta'!$A$2:$M$823,13,0),"") | E10: =IFERROR(VLOOKUP(H10,'[1]Consolidado MP Planta'!$A$2:$M$823,12,0),"") | F10: =IFERROR(C10*E10,"") | G10: =IFERROR(F10/$F$66,"")
B11: =IFERROR(VLOOKUP(H11,'[1]Consolidado MP Planta'!$A$2:$M$823,3,0),"") | C11: =+A11 -> 0 | D11: =IFERROR(VLOOKUP(H11,'[1]Consolidado MP Planta'!$A$2:$M$823,13,0),"") | E11: =IFERROR(VLOOKUP(H11,'[1]Consolidado MP Planta'!$A$2:$M$823,12,0),"") | F11: =IFERROR(C11*E11,"") | G11: =IFERROR(F11/$F$66,"")
B12: =IFERROR(VLOOKUP(H12,'[1]Consolidado MP Planta'!$A$2:$M$823,3,0),"") | C12: =+A12 -> 0 | D12: =IFERROR(VLOOKUP(H12,'[1]Consolidado MP Planta'!$A$2:$M$823,13,0),"") | E12: =IFERROR(VLOOKUP(H12,'[1]Consolidado MP Planta'!$A$2:$M$823,12,0),"") | F12: =IFERROR(C12*E12,"") | G12: =IFERROR(F12/$F$66,"")
B13: =IFERROR(VLOOKUP(H13,'[1]Consolidado MP Planta'!$A$2:$M$823,3,0),"") | C13: =+A13 -> 0 | D13: =IFERROR(VLOOKUP(H13,'[1]Consolidado MP Planta'!$A$2:$M$823,13,0),"") | E13: =IFERROR(VLOOKUP(H13,'[1]Consolidado MP Planta'!$A$2:$M$823,12,0),"") | F13: =IFERROR(C13*E13,"") | G13: =IFERROR(F13/$F$66,"")
B14: =IFERROR(VLOOKUP(H14,'[1]Consolidado MP Planta'!$A$2:$M$823,3,0),"") | C14: =+A14 -> 0 | D14: =IFERROR(VLOOKUP(H14,'[1]Consolidado MP Planta'!$A$2:$M$823,13,0),"") | E14: =IFERROR(VLOOKUP(H14,'[1]Consolidado MP Planta'!$A$2:$M$823,12,0),"") | F14: =IFERROR(C14*E14,"") | G14: =IFERROR(F14/$F$66,"")
B15: =IFERROR(VLOOKUP(H15,'[2]ARTICULOS MP PLANTA'!$A$2:$G$589,2,0),"")
A16: UNIDADES | B16: MATERIA PRIMA SEMIELABORADOS | C16: UNIDADES | D16: UND MEDIDA | E16: COSTO UNITARIO | F16: TOTAL COSTO | G16: % PREC. DEFINIDO | H16: CODIGOS
A17: 300 | B17: BASE GALLETA P/CHEESE CAKE (KILO) | C17: =+A17 -> 300 | D17: Gramos | E17: 2.5 | F17: =IFERROR(E17*C17,"") -> 750 | G17: =IFERROR(F17/$F$66,"") -> 0.3107792 | H17: SE00041
A18: 400 | B18: Relleno blanco de Limon | C18: =+A18 -> 400 | D18: Gramos | E18: =+'Costo Relleno Blanco Limon'!E69 -> 2.4364931 | F18: =IFERROR(E18*C18,"") -> 974.59723 | G18: =IFERROR(F18/$F$66,"") -> 0.40384606 | H18: NUEVO
A19: 30 | B19: Crema Chantilly Blanca (Spoon-Ind) | C19: =+A19 -> 30 | D19: Gramos | E19: 2.22 | F19: =IFERROR(E19*C19,"") -> 66.6 | G19: =IFERROR(F19/$F$66,"") -> 0.027597193 | H19: SE00010
A20: 220 | B20: Toping de Lemon Court | C20: =+A20 -> 220 | D20: Gramos | E20: =+'Costo Empaque Lemon Court'!E69 -> 0.51445695 | F20: =IFERROR(E20*C20,"") -> 113.18053 | G20: =IFERROR(F20/$F$66,"") -> 0.046898872 | H20: NUEVO
B21: =IFERROR(VLOOKUP(H21,[1]SEMIELABORADOS!$A$2:$M$6000,2,0),"") | C21: =+A21 -> 0 | D21: =IFERROR(VLOOKUP(H21,[1]SEMIELABORADOS!$A$2:$M$6000,6,0),"") | E21: =IFERROR(VLOOKUP(H21,[1]SEMIELABORADOS!$A$2:$H$65536,8,0),"") | F21: =IFERROR(E21*C21,"") | G21: =IFERROR(F21/$F$66,"")
B22: =IFERROR(VLOOKUP(H22,[1]SEMIELABORADOS!$A$2:$M$6000,2,0),"") | C22: =+A22 -> 0 | D22: =IFERROR(VLOOKUP(H22,[1]SEMIELABORADOS!$A$2:$M$6000,6,0),"") | E22: =IFERROR(VLOOKUP(H22,[1]SEMIELABORADOS!$A$2:$H$65536,8,0),"") | F22: =IFERROR(E22*C22,"") | G22: =IFERROR(F22/$F$66,"")
B23: =IFERROR(VLOOKUP(H23,[1]SEMIELABORADOS!$A$2:$M$6000,2,0),"") | C23: =+A23 -> 0 | D23: =IFERROR(VLOOKUP(H23,[1]SEMIELABORADOS!$A$2:$M$6000,6,0),"") | E23: =IFERROR(VLOOKUP(H23,[1]SEMIELABORADOS!$A$2:$H$65536,8,0),"") | F23: =IFERROR(E23*C23,"") | G23: =IFERROR(F23/$F$66,"")
B24: =IFERROR(VLOOKUP(H24,[1]SEMIELABORADOS!$A$2:$M$6000,2,0),"") | C24: =+A24 -> 0 | D24: =IFERROR(VLOOKUP(H24,[1]SEMIELABORADOS!$A$2:$M$6000,6,0),"") | E24: =IFERROR(VLOOKUP(H24,[1]SEMIELABORADOS!$A$2:$H$65536,8,0),"") | F24: =IFERROR(E24*C24,"") | G24: =IFERROR(F24/$F$66,"")
A26: UNIDADES | B26: EMPAQUE | C26: UNIDADES | D26: UND MEDIDA | E26: COSTO UNITARIO | F26: TOTAL COSTO | G26: % PREC. DEFINIDO | H26: CODIGOS
A27: 1 | B27: TAPA BAND ALUM. DESE 4040) | C27: =+A27 -> 1 | D27: UND | E27: 116.05 | F27: =IFERROR(C27*E27,"") -> 116.05 | G27: =IFERROR(F27/$F$66,"") -> 0.048087901 | H27: EM10015
A28: 1 | B28: BANDEJA ALUM DESE 6 PORC #4040 | C28: =+A28 -> 1 | D28: UND | E28: 253.98 | F28: =IFERROR(C28*E28,"") -> 253.98 | G28: =IFERROR(F28/$F$66,"") -> 0.10524227 | H28: EM10014
A29: 1 | B29: ETIQ.BLANCA 1 1/4 * 3/4 (UND) | C29: =+A29 -> 1 | D29: UND | E29: 0.58 | F29: =IFERROR(C29*E29,"") -> 0.58 | G29: =IFERROR(F29/$F$66,"") -> 0.00024033591 | H29: EM10002
A30: 1 | B30: ETIQ CIRCULO BUCCA DULCE (UND) | C30: =+A30 -> 1 | D30: UND | E30: 10 | F30: =IFERROR(C30*E30,"") -> 10 | G30: =IFERROR(F30/$F$66,"") -> 0.0041437226 | H30: EM10111
A31: 1 | B31: Etiqueta Blanca 2 5/8X1 15/16 | C31: =+A31 -> 1 | D31: UND | E31: 2.13 | F31: =IFERROR(C31*E31,"") -> 2.13 | G31: =IFERROR(F31/$F$66,"") -> 0.00088261291 | H31: EM10011
A32: 1 | B32: Etiqueta Blanca R-153 | C32: =+A32 -> 1 | D32: UND | E32: 0.39 | F32: =IFERROR(C32*E32,"") -> 0.39 | G32: =IFERROR(F32/$F$66,"") -> 0.00016160518 | H32: EM10124
A34: UNIDADES | B34: EMPAQUE SEMIELABORADOS | C34: UNIDADES | D34: UND MEDIDA | E34: COSTO UNITARIO | F34: TOTAL COSTO | G34: % PREC. DEFINIDO | H34: CODIGOS
A35: =+A17 -> 300 | B35: BASE GALLETA P/CHEESE CAKE (KILO) | C35: =+A35 -> 300 | D35: Gramos | E35: 0 | F35: =IFERROR(E35*C35,"") -> 0 | G35: =IFERROR(F35/$F$66,"") -> 0 | H35: SE00041
A36: =+A18 -> 400 | B36: Relleno blanco de Limon | C36: =+A36 -> 400 | D36: Gramos | E36: =+'Costo Relleno Blanco Limon'!E76 -> 0.009042 | F36: =IFERROR(E36*C36,"") -> 3.6168 | G36: =IFERROR(F36/$F$66,"") -> 0.0014987016 | H36: NUEVO
A37: =+A19 -> 30 | B37: Crema Chantilly Blanca (Spoon-Ind) | C37: =+A37 -> 30 | D37: Gramos | E37: 0.01 | F37: =IFERROR(E37*C37,"") -> 0.3 | G37: =IFERROR(F37/$F$66,"") -> 0.00012431168 | H37: SE00010
A38: =+A20 -> 220 | B38: Toping de Lemon Court | C38: =+A38 -> 220 | D38: Gramos | E38: =+'Costo Empaque Lemon Court'!E76 -> 0.010172 | F38: =IFERROR(E38*C38,"") -> 2.23784 | G38: =IFERROR(F38/$F$66,"") -> 0.00092729882 | H38: NUEVO
A39: =+A21 -> 0 | B39: =IFERROR(VLOOKUP(H39,[1]SEMIELABORADOS!$A$2:$M$6000,2,0),"") | C39: =+A39 -> 0 | D39: =IFERROR(VLOOKUP(H39,[1]SEMIELABORADOS!$A$2:$M$6000,6,0),"") | E39: =IFERROR(VLOOKUP(H39,[1]SEMIELABORADOS!$A$2:$M$65536,10,0),"") | F39: =IFERROR(E39*C39,"") | G39: =IFERROR(F39/$F$66,"")
A40: =+A22 -> 0 | B40: =IFERROR(VLOOKUP(H40,[1]SEMIELABORADOS!$A$2:$M$6000,2,0),"") | C40: =+A40 -> 0 | D40: =IFERROR(VLOOKUP(H40,[1]SEMIELABORADOS!$A$2:$M$6000,6,0),"") | E40: =IFERROR(VLOOKUP(H40,[1]SEMIELABORADOS!$A$2:$M$65536,10,0),"") | F40: =IFERROR(E40*C40,"") | G40: =IFERROR(F40/$F$66,"")
A41: =+A23 -> 0 | B41: =IFERROR(VLOOKUP(H41,[1]SEMIELABORADOS!$A$2:$M$6000,2,0),"") | C41: =+A41 -> 0 | D41: =IFERROR(VLOOKUP(H41,[1]SEMIELABORADOS!$A$2:$M$6000,6,0),"") | E41: =IFERROR(VLOOKUP(H41,[1]SEMIELABORADOS!$A$2:$M$65536,10,0),"") | F41: =IFERROR(E41*C41,"") | G41: =IFERROR(F41/$F$66,"")
A43: UNIDADES | B43: MODI | C43: UNIDADES | D43: UND MEDIDA | E43: COSTO UNITARIO | F43: TOTAL COSTO | G43: % PREC. DEFINIDO | H43: CODIGOS
A44: =+A35 -> 300 | B44: BASE GALLETA P/CHEESE CAKE (KILO) | C44: =+A44 -> 300 | D44: Gramos | E44: 0.16 | F44: =IFERROR(E44*C44,"") -> 48 | G44: =IFERROR(F44/$F$66,"") -> 0.019889869 | H44: SE00041
A45: =+A36 -> 400 | B45: Relleno blanco de Limon | C45: =+A45 -> 400 | D45: Gramos | E45: =+'Costo Relleno Blanco Limon'!E74 -> 0.113168 | F45: =IFERROR(E45*C45,"") -> 45.2672 | G45: =IFERROR(F45/$F$66,"") -> 0.018757472 | H45: NUEVO
...

Sheet Costo Topping Lemon Court
E1: Precio Local | F1: Costo MP | G1: Costo EM | H1: Costo MO
E2: =IFERROR(O62,"") -> 7259.5695 | F2: =IFERROR(H53,"") -> 5144.5695 | G2: =IFERROR(H54,"") -> 0 | H2: =IFERROR(H56,"") -> 1155
A5: ESTRUCTURA DE COSTOS
F6: Fecha: | H6: =TODAY() -> 46064
A7: UNIDADES | B7: DESCRIPCION MAT.PRIMA | C7: UNIDADES | D7: UND MEDIDA | E7: COSTO UNITARIO | F7: TOTAL COSTO | G7: % PREC. DEFINIDO | H7: CODIGOS
A8: 4344.85 | B8: Azucar Blanco Industrial | C8: =+A8 -> 4344.85 | D8: Gramos | E8: 0.43 | F8: =IFERROR(C8*E8,"") -> 1868.2855 | G8: =IFERROR(F8/$F$66,"") -> 0.29180741 | H8: MP10074
A9: 692.1 | B9: Almidon Modificado | C9: =+A9 -> 692.1 | D9: Gramos | E9: 2.04 | F9: =IFERROR(C9*E9,"") -> 1411.884 | G9: =IFERROR(F9/$F$66,"") -> 0.22052208 | H9: MP10026
A10: 8 | B10: Limones Maya | C10: =+A10 -> 8 | D10: Gramos | E10: 200 | F10: =IFERROR(C10*E10,"") -> 1600 | G10: =IFERROR(F10/$F$66,"") -> 0.24990391 | H10: MP10240
A11: 8 | B11: Preservante 1017S | C11: =+A11 -> 8 | D11: Gramos | E11: 8.59 | F11: =IFERROR(C11*E11,"") -> 68.72 | G11: =IFERROR(F11/$F$66,"") -> 0.010733373 | H11: MP10025
A12: 8 | B12: Limon En Polvo | C12: =+A12 -> 8 | D12: Gramos | E12: 6 | F12: =IFERROR(C12*E12,"") -> 48 | G12: =IFERROR(F12/$F$66,"") -> 0.0074971173 | H12: MP10239
A13: 8 | B13: Colorante Gel Egg Yellow | C13: =+A13 -> 8 | D13: Gramos | E13: 18.46 | F13: =IFERROR(C13*E13,"") -> 147.68 | G13: =IFERROR(F13/$F$66,"") -> 0.023066131 | H13: MP10150
B14: =IFERROR(VLOOKUP(H14,'[1]Consolidado MP Planta'!$A$2:$M$823,3,0),"") | C14: =+A14 -> 0 | D14: =IFERROR(VLOOKUP(H14,'[1]Consolidado MP Planta'!$A$2:$M$823,13,0),"") | E14: =IFERROR(VLOOKUP(H14,'[1]Consolidado MP Planta'!$A$2:$M$823,12,0),"") | F14: =IFERROR(C14*E14,"") | G14: =IFERROR(F14/$F$66,"")
B15: =IFERROR(VLOOKUP(H15,'[2]ARTICULOS MP PLANTA'!$A$2:$G$589,2,0),"")
A16: UNIDADES | B16: MATERIA PRIMA SEMIELABORADOS | C16: UNIDADES | D16: UND MEDIDA | E16: COSTO UNITARIO | F16: TOTAL COSTO | G16: % PREC. DEFINIDO | H16: CODIGOS
B17: =IFERROR(VLOOKUP(H17,[1]SEMIELABORADOS!$A$2:$M$6000,2,0),"") | C17: =+A17 -> 0 | D17: =IFERROR(VLOOKUP(H17,[1]SEMIELABORADOS!$A$2:$M$6000,6,0),"") | E17: =IFERROR(VLOOKUP(H17,[1]SEMIELABORADOS!$A$2:$H$65536,8,0),"") | F17: =IFERROR(E17*C17,"") | G17: =IFERROR(F17/$F$66,"")
B18: =IFERROR(VLOOKUP(H18,[1]SEMIELABORADOS!$A$2:$M$6000,2,0),"") | C18: =+A18 -> 0 | D18: =IFERROR(VLOOKUP(H18,[1]SEMIELABORADOS!$A$2:$M$6000,6,0),"") | E18: =IFERROR(VLOOKUP(H18,[1]SEMIELABORADOS!$A$2:$H$65536,8,0),"") | F18: =IFERROR(E18*C18,"") | G18: =IFERROR(F18/$F$66,"")
B19: =IFERROR(VLOOKUP(H19,[1]SEMIELABORADOS!$A$2:$M$6000,2,0),"") | C19: =+A19 -> 0 | D19: =IFERROR(VLOOKUP(H19,[1]SEMIELABORADOS!$A$2:$M$6000,6,0),"") | E19: =IFERROR(VLOOKUP(H19,[1]SEMIELABORADOS!$A$2:$H$65536,8,0),"") | F19: =IFERROR(E19*C19,"") | G19: =IFERROR(F19/$F$66,"")
B20: =IFERROR(VLOOKUP(H20,[1]SEMIELABORADOS!$A$2:$M$6000,2,0),"") | C20: =+A20 -> 0 | D20: =IFERROR(VLOOKUP(H20,[1]SEMIELABORADOS!$A$2:$M$6000,6,0),"") | E20: =IFERROR(VLOOKUP(H20,[1]SEMIELABORADOS!$A$2:$H$65536,8,0),"") | F20: =IFERROR(E20*C20,"") | G20: =IFERROR(F20/$F$66,"")
B21: =IFERROR(VLOOKUP(H21,[1]SEMIELABORADOS!$A$2:$M$6000,2,0),"") | C21: =+A21 -> 0 | D21: =IFERROR(VLOOKUP(H21,[1]SEMIELABORADOS!$A$2:$M$6000,6,0),"") | E21: =IFERROR(VLOOKUP(H21,[1]SEMIELABORADOS!$A$2:$H$65536,8,0),"") | F21: =IFERROR(E21*C21,"") | G21: =IFERROR(F21/$F$66,"")
B22: =IFERROR(VLOOKUP(H22,[1]SEMIELABORADOS!$A$2:$M$6000,2,0),"") | C22: =+A22 -> 0 | D22: =IFERROR(VLOOKUP(H22,[1]SEMIELABORADOS!$A$2:$M$6000,6,0),"") | E22: =IFERROR(VLOOKUP(H22,[1]SEMIELABORADOS!$A$2:$H$65536,8,0),"") | F22: =IFERROR(E22*C22,"") | G22: =IFERROR(F22/$F$66,"")
B23: =IFERROR(VLOOKUP(H23,[1]SEMIELABORADOS!$A$2:$M$6000,2,0),"") | C23: =+A23 -> 0 | D23: =IFERROR(VLOOKUP(H23,[1]SEMIELABORADOS!$A$2:$M$6000,6,0),"") | E23: =IFERROR(VLOOKUP(H23,[1]SEMIELABORADOS!$A$2:$H$65536,8,0),"") | F23: =IFERROR(E23*C23,"") | G23: =IFERROR(F23/$F$66,"")
B24: =IFERROR(VLOOKUP(H24,[1]SEMIELABORADOS!$A$2:$M$6000,2,0),"") | C24: =+A24 -> 0 | D24: =IFERROR(VLOOKUP(H24,[1]SEMIELABORADOS!$A$2:$M$6000,6,0),"") | E24: =IFERROR(VLOOKUP(H24,[1]SEMIELABORADOS!$A$2:$H$65536,8,0),"") | F24: =IFERROR(E24*C24,"") | G24: =IFERROR(F24/$F$66,"")
A26: UNIDADES | B26: EMPAQUE | C26: UNIDADES | D26: UND MEDIDA | E26: COSTO UNITARIO | F26: TOTAL COSTO | G26: % PREC. DEFINIDO | H26: CODIGOS
A27: 0 | B27: =IFERROR(VLOOKUP(H27,'[1]Consolidado MP Planta'!$A$2:$M$823,3,0),"") | C27: =+A27 -> 0 | D27: =IFERROR(VLOOKUP(H27,'[1]Consolidado MP Planta'!$A$2:$M$823,13,0),"") | E27: =IFERROR(VLOOKUP(H27,'[1]Consolidado MP Planta'!$A$2:$M$823,12,0),"") | F27: =IFERROR(C27*E27,"") | G27: =IFERROR(F27/$F$66,"")
B28: =IFERROR(VLOOKUP(H28,'[1]Consolidado MP Planta'!$A$2:$M$823,3,0),"") | C28: =+A28 -> 0 | D28: =IFERROR(VLOOKUP(H28,'[1]Consolidado MP Planta'!$A$2:$M$823,13,0),"") | E28: =IFERROR(VLOOKUP(H28,'[1]Consolidado MP Planta'!$A$2:$M$823,12,0),"") | F28: =IFERROR(C28*E28,"") | G28: =IFERROR(F28/$F$66,"")
B29: =IFERROR(VLOOKUP(H29,'[1]Consolidado MP Planta'!$A$2:$M$823,3,0),"") | C29: =+A29 -> 0 | D29: =IFERROR(VLOOKUP(H29,'[1]Consolidado MP Planta'!$A$2:$M$823,13,0),"") | E29: =IFERROR(VLOOKUP(H29,'[1]Consolidado MP Planta'!$A$2:$M$823,12,0),"") | F29: =IFERROR(C29*E29,"") | G29: =IFERROR(F29/$F$66,"")
B30: =IFERROR(VLOOKUP(H30,'[1]Consolidado MP Planta'!$A$2:$M$823,3,0),"") | C30: =+A30 -> 0 | D30: =IFERROR(VLOOKUP(H30,'[1]Consolidado MP Planta'!$A$2:$M$823,13,0),"") | E30: =IFERROR(VLOOKUP(H30,'[1]Consolidado MP Planta'!$A$2:$M$823,12,0),"") | F30: =IFERROR(C30*E30,"") | G30: =IFERROR(F30/$F$66,"")
B31: =IFERROR(VLOOKUP(H31,'[1]Consolidado MP Planta'!$A$2:$M$823,3,0),"") | C31: =+A31 -> 0 | D31: =IFERROR(VLOOKUP(H31,'[1]Consolidado MP Planta'!$A$2:$M$823,13,0),"") | E31: =IFERROR(VLOOKUP(H31,'[1]Consolidado MP Planta'!$A$2:$M$823,12,0),"") | F31: =IFERROR(C31*E31,"") | G31: =IFERROR(F31/$F$66,"")
B32: =IFERROR(VLOOKUP(H32,'[1]Consolidado MP Planta'!$A$2:$M$823,3,0),"") | C32: =+A32 -> 0 | D32: =IFERROR(VLOOKUP(H32,'[1]Consolidado MP Planta'!$A$2:$M$823,13,0),"") | E32: =IFERROR(VLOOKUP(H32,'[1]Consolidado MP Planta'!$A$2:$M$823,12,0),"") | F32: =IFERROR(C32*E32,"") | G32: =IFERROR(F32/$F$66,"")
A34: UNIDADES | B34: EMPAQUE SEMIELABORADOS | C34: UNIDADES | D34: UND MEDIDA | E34: COSTO UNITARIO | F34: TOTAL COSTO | G34: % PREC. DEFINIDO | H34: CODIGOS
A35: =+A17 -> 0 | B35: =IFERROR(VLOOKUP(H35,[1]SEMIELABORADOS!$A$2:$M$6000,2,0),"") | C35: =+A35 -> 0 | D35: =IFERROR(VLOOKUP(H35,[1]SEMIELABORADOS!$A$2:$M$6000,6,0),"") | E35: =IFERROR(VLOOKUP(H35,[1]SEMIELABORADOS!$A$2:$M$65536,10,0),"") | F35: =IFERROR(E35*C35,"") | G35: =IFERROR(F35/$F$66,"")
A36: =+A18 -> 0 | B36: =IFERROR(VLOOKUP(H36,[1]SEMIELABORADOS!$A$2:$M$6000,2,0),"") | C36: =+A36 -> 0 | D36: =IFERROR(VLOOKUP(H36,[1]SEMIELABORADOS!$A$2:$M$6000,6,0),"") | E36: =IFERROR(VLOOKUP(H36,[1]SEMIELABORADOS!$A$2:$M$65536,10,0),"") | F36: =IFERROR(E36*C36,"") | G36: =IFERROR(F36/$F$66,"")
A37: =+A19 -> 0 | B37: =IFERROR(VLOOKUP(H37,[1]SEMIELABORADOS!$A$2:$M$6000,2,0),"") | C37: =+A37 -> 0 | D37: =IFERROR(VLOOKUP(H37,[1]SEMIELABORADOS!$A$2:$M$6000,6,0),"") | E37: =IFERROR(VLOOKUP(H37,[1]SEMIELABORADOS!$A$2:$M$65536,10,0),"") | F37: =IFERROR(E37*C37,"") | G37: =IFERROR(F37/$F$66,"")
A38: =+A20 -> 0 | B38: =IFERROR(VLOOKUP(H38,[1]SEMIELABORADOS!$A$2:$M$6000,2,0),"") | C38: =+A38 -> 0 | D38: =IFERROR(VLOOKUP(H38,[1]SEMIELABORADOS!$A$2:$M$6000,6,0),"") | E38: =IFERROR(VLOOKUP(H38,[1]SEMIELABORADOS!$A$2:$M$65536,10,0),"") | F38: =IFERROR(E38*C38,"") | G38: =IFERROR(F38/$F$66,"")
A39: =+A21 -> 0 | B39: =IFERROR(VLOOKUP(H39,[1]SEMIELABORADOS!$A$2:$M$6000,2,0),"") | C39: =+A39 -> 0 | D39: =IFERROR(VLOOKUP(H39,[1]SEMIELABORADOS!$A$2:$M$6000,6,0),"") | E39: =IFERROR(VLOOKUP(H39,[1]SEMIELABORADOS!$A$2:$M$65536,10,0),"") | F39: =IFERROR(E39*C39,"") | G39: =IFERROR(F39/$F$66,"")
A40: =+A22 -> 0 | B40: =IFERROR(VLOOKUP(H40,[1]SEMIELABORADOS!$A$2:$M$6000,2,0),"") | C40: =+A40 -> 0 | D40: =IFERROR(VLOOKUP(H40,[1]SEMIELABORADOS!$A$2:$M$6000,6,0),"") | E40: =IFERROR(VLOOKUP(H40,[1]SEMIELABORADOS!$A$2:$M$65536,10,0),"") | F40: =IFERROR(E40*C40,"") | G40: =IFERROR(F40/$F$66,"")
A41: =+A23 -> 0 | B41: =IFERROR(VLOOKUP(H41,[1]SEMIELABORADOS!$A$2:$M$6000,2,0),"") | C41: =+A41 -> 0 | D41: =IFERROR(VLOOKUP(H41,[1]SEMIELABORADOS!$A$2:$M$6000,6,0),"") | E41: =IFERROR(VLOOKUP(H41,[1]SEMIELABORADOS!$A$2:$M$65536,10,0),"") | F41: =IFERROR(E41*C41,"") | G41: =IFERROR(F41/$F$66,"")
A43: UNIDADES | B43: MODI | C43: UNIDADES | D43: UND MEDIDA | E43: COSTO UNITARIO | F43: TOTAL COSTO | G43: % PREC. DEFINIDO | H43: CODIGOS
A44: =+A35 -> 0 | B44: =IFERROR(VLOOKUP(H44,[1]SEMIELABORADOS!$A$2:$M$6000,2,0),"") | C44: =+A44 -> 0 | D44: =IFERROR(VLOOKUP(H44,[1]SEMIELABORADOS!$A$2:$M$6000,6,0),"") | E44: =IFERROR(VLOOKUP(H44,[1]SEMIELABORADOS!$A$2:$M$65536,12,0),"") | F44: =IFERROR(E44*C44,"") | G44: =IFERROR(F44/$F$66,"")
A45: =+A36 -> 0 | B45: =IFERROR(VLOOKUP(H45,[1]SEMIELABORADOS!$A$2:$M$6000,2,0),"") | C45: =+A45 -> 0 | D45: =IFERROR(VLOOKUP(H45,[1]SEMIELABORADOS!$A$2:$M$6000,6,0),"") | E45: =IFERROR(VLOOKUP(H45,[1]SEMIELABORADOS!$A$2:$M$65536,12,0),"") | F45: =IFERROR(E45*C45,"") | G45: =IFERROR(F45/$F$66,"")
...

Sheet Costo Empaque Lemon Court
E1: Precio Local | F1: Costo MP | G1: Costo EM | H1: Costo MO
E2: =IFERROR(O62,"") -> 3962.6448 | F2: =IFERROR(H53,"") -> 2572.2848 | G2: =IFERROR(H54,"") -> 50.86 | H2: =IFERROR(H56,"") -> 731.5
A5: ESTRUCTURA DE COSTOS
F6: Fecha: | H6: =TODAY() -> 46064
A7: UNIDADES | B7: DESCRIPCION MAT.PRIMA | C7: UNIDADES | D7: UND MEDIDA | E7: COSTO UNITARIO | F7: TOTAL COSTO | G7: % PREC. DEFINIDO | H7: CODIGOS
B8: =IFERROR(VLOOKUP(H8,'[1]Consolidado MP Planta'!$A$2:$M$823,3,0),"") | C8: =+A8 -> 0 | D8: =IFERROR(VLOOKUP(H8,'[1]Consolidado MP Planta'!$A$2:$M$823,13,0),"") | E8: =IFERROR(VLOOKUP(H8,'[1]Consolidado MP Planta'!$A$2:$M$823,12,0),"") | F8: =IFERROR(C8*E8,"") | G8: =IFERROR(F8/$F$66,"")
B9: =IFERROR(VLOOKUP(H9,'[1]Consolidado MP Planta'!$A$2:$M$823,3,0),"") | C9: =+A9 -> 0 | D9: =IFERROR(VLOOKUP(H9,'[1]Consolidado MP Planta'!$A$2:$M$823,13,0),"") | E9: =IFERROR(VLOOKUP(H9,'[1]Consolidado MP Planta'!$A$2:$M$823,12,0),"") | F9: =IFERROR(C9*E9,"") | G9: =IFERROR(F9/$F$66,"")
B10: =IFERROR(VLOOKUP(H10,'[1]Consolidado MP Planta'!$A$2:$M$823,3,0),"") | C10: =+A10 -> 0 | D10: =IFERROR(VLOOKUP(H10,'[1]Consolidado MP Planta'!$A$2:$M$823,13,0),"") | E10: =IFERROR(VLOOKUP(H10,'[1]Consolidado MP Planta'!$A$2:$M$823,12,0),"") | F10: =IFERROR(C10*E10,"") | G10: =IFERROR(F10/$F$66,"")
B11: =IFERROR(VLOOKUP(H11,'[1]Consolidado MP Planta'!$A$2:$M$823,3,0),"") | C11: =+A11 -> 0 | D11: =IFERROR(VLOOKUP(H11,'[1]Consolidado MP Planta'!$A$2:$M$823,13,0),"") | E11: =IFERROR(VLOOKUP(H11,'[1]Consolidado MP Planta'!$A$2:$M$823,12,0),"") | F11: =IFERROR(C11*E11,"") | G11: =IFERROR(F11/$F$66,"")
B12: =IFERROR(VLOOKUP(H12,'[1]Consolidado MP Planta'!$A$2:$M$823,3,0),"") | C12: =+A12 -> 0 | D12: =IFERROR(VLOOKUP(H12,'[1]Consolidado MP Planta'!$A$2:$M$823,13,0),"") | E12: =IFERROR(VLOOKUP(H12,'[1]Consolidado MP Planta'!$A$2:$M$823,12,0),"") | F12: =IFERROR(C12*E12,"") | G12: =IFERROR(F12/$F$66,"")
B13: =IFERROR(VLOOKUP(H13,'[1]Consolidado MP Planta'!$A$2:$M$823,3,0),"") | C13: =+A13 -> 0 | D13: =IFERROR(VLOOKUP(H13,'[1]Consolidado MP Planta'!$A$2:$M$823,13,0),"") | E13: =IFERROR(VLOOKUP(H13,'[1]Consolidado MP Planta'!$A$2:$M$823,12,0),"") | F13: =IFERROR(C13*E13,"") | G13: =IFERROR(F13/$F$66,"")
B14: =IFERROR(VLOOKUP(H14,'[1]Consolidado MP Planta'!$A$2:$M$823,3,0),"") | C14: =+A14 -> 0 | D14: =IFERROR(VLOOKUP(H14,'[1]Consolidado MP Planta'!$A$2:$M$823,13,0),"") | E14: =IFERROR(VLOOKUP(H14,'[1]Consolidado MP Planta'!$A$2:$M$823,12,0),"") | F14: =IFERROR(C14*E14,"") | G14: =IFERROR(F14/$F$66,"")
B15: =IFERROR(VLOOKUP(H15,'[2]ARTICULOS MP PLANTA'!$A$2:$G$589,2,0),"")
A16: UNIDADES | B16: MATERIA PRIMA SEMIELABORADOS | C16: UNIDADES | D16: UND MEDIDA | E16: COSTO UNITARIO | F16: TOTAL COSTO | G16: % PREC. DEFINIDO | H16: CODIGOS
A17: 5000 | B17: RELLENO LEMON COURT | C17: =+A17 -> 5000 | D17: Gramos | E17: =+'Costo Topping Lemon Court'!E69 -> 0.51445695 | F17: =IFERROR(E17*C17,"") -> 2572.2848 | G17: =IFERROR(F17/$F$66,"") -> 0.90938748
B18: =IFERROR(VLOOKUP(H18,[1]SEMIELABORADOS!$A$2:$M$6000,2,0),"") | C18: =+A18 -> 0 | D18: =IFERROR(VLOOKUP(H18,[1]SEMIELABORADOS!$A$2:$M$6000,6,0),"") | E18: =IFERROR(VLOOKUP(H18,[1]SEMIELABORADOS!$A$2:$H$65536,8,0),"") | F18: =IFERROR(E18*C18,"") | G18: =IFERROR(F18/$F$66,"")
B19: =IFERROR(VLOOKUP(H19,[1]SEMIELABORADOS!$A$2:$M$6000,2,0),"") | C19: =+A19 -> 0 | D19: =IFERROR(VLOOKUP(H19,[1]SEMIELABORADOS!$A$2:$M$6000,6,0),"") | E19: =IFERROR(VLOOKUP(H19,[1]SEMIELABORADOS!$A$2:$H$65536,8,0),"") | F19: =IFERROR(E19*C19,"") | G19: =IFERROR(F19/$F$66,"")
B20: =IFERROR(VLOOKUP(H20,[1]SEMIELABORADOS!$A$2:$M$6000,2,0),"") | C20: =+A20 -> 0 | D20: =IFERROR(VLOOKUP(H20,[1]SEMIELABORADOS!$A$2:$M$6000,6,0),"") | E20: =IFERROR(VLOOKUP(H20,[1]SEMIELABORADOS!$A$2:$H$65536,8,0),"") | F20: =IFERROR(E20*C20,"") | G20: =IFERROR(F20/$F$66,"")
B21: =IFERROR(VLOOKUP(H21,[1]SEMIELABORADOS!$A$2:$M$6000,2,0),"") | C21: =+A21 -> 0 | D21: =IFERROR(VLOOKUP(H21,[1]SEMIELABORADOS!$A$2:$M$6000,6,0),"") | E21: =IFERROR(VLOOKUP(H21,[1]SEMIELABORADOS!$A$2:$H$65536,8,0),"") | F21: =IFERROR(E21*C21,"") | G21: =IFERROR(F21/$F$66,"")
B22: =IFERROR(VLOOKUP(H22,[1]SEMIELABORADOS!$A$2:$M$6000,2,0),"") | C22: =+A22 -> 0 | D22: =IFERROR(VLOOKUP(H22,[1]SEMIELABORADOS!$A$2:$M$6000,6,0),"") | E22: =IFERROR(VLOOKUP(H22,[1]SEMIELABORADOS!$A$2:$H$65536,8,0),"") | F22: =IFERROR(E22*C22,"") | G22: =IFERROR(F22/$F$66,"")
B23: =IFERROR(VLOOKUP(H23,[1]SEMIELABORADOS!$A$2:$M$6000,2,0),"") | C23: =+A23 -> 0 | D23: =IFERROR(VLOOKUP(H23,[1]SEMIELABORADOS!$A$2:$M$6000,6,0),"") | E23: =IFERROR(VLOOKUP(H23,[1]SEMIELABORADOS!$A$2:$H$65536,8,0),"") | F23: =IFERROR(E23*C23,"") | G23: =IFERROR(F23/$F$66,"")
B24: =IFERROR(VLOOKUP(H24,[1]SEMIELABORADOS!$A$2:$M$6000,2,0),"") | C24: =+A24 -> 0 | D24: =IFERROR(VLOOKUP(H24,[1]SEMIELABORADOS!$A$2:$M$6000,6,0),"") | E24: =IFERROR(VLOOKUP(H24,[1]SEMIELABORADOS!$A$2:$H$65536,8,0),"") | F24: =IFERROR(E24*C24,"") | G24: =IFERROR(F24/$F$66,"")
A26: UNIDADES | B26: EMPAQUE | C26: UNIDADES | D26: UND MEDIDA | E26: COSTO UNITARIO | F26: TOTAL COSTO | G26: % PREC. DEFINIDO | H26: CODIGOS
A27: 1 | B27: BOLSA 17x25 TRANSP (KILO) | C27: =+A27 -> 1 | D27: UND | E27: 50 | F27: =IFERROR(C27*E27,"") -> 50 | G27: =IFERROR(F27/$F$66,"") -> 0.017676649 | H27: EM10016
A28: 1 | B28: ETIQ.BLANCA 1 1/4 * 3/4 (UND) | C28: =+A28 -> 1 | D28: UND | E28: 0.58 | F28: =IFERROR(C28*E28,"") -> 0.58 | G28: =IFERROR(F28/$F$66,"") -> 0.00020504913 | H28: EM10002
A29: 1 | B29: ETIQ.FECHA VENCIMIENTO BLANCO (ROLLO) | C29: =+A29 -> 1 | D29: UND | E29: 0.28 | F29: =IFERROR(C29*E29,"") -> 0.28 | G29: =IFERROR(F29/$F$66,"") -> 9.8989233e-05 | H29: EM10004
B30: =IFERROR(VLOOKUP(H30,'[1]Consolidado MP Planta'!$A$2:$M$823,3,0),"") | C30: =+A30 -> 0 | D30: =IFERROR(VLOOKUP(H30,'[1]Consolidado MP Planta'!$A$2:$M$823,13,0),"") | E30: =IFERROR(VLOOKUP(H30,'[1]Consolidado MP Planta'!$A$2:$M$823,12,0),"") | F30: =IFERROR(C30*E30,"") | G30: =IFERROR(F30/$F$66,"")
B31: =IFERROR(VLOOKUP(H31,'[1]Consolidado MP Planta'!$A$2:$M$823,3,0),"") | C31: =+A31 -> 0 | D31: =IFERROR(VLOOKUP(H31,'[1]Consolidado MP Planta'!$A$2:$M$823,13,0),"") | E31: =IFERROR(VLOOKUP(H31,'[1]Consolidado MP Planta'!$A$2:$M$823,12,0),"") | F31: =IFERROR(C31*E31,"") | G31: =IFERROR(F31/$F$66,"")
B32: =IFERROR(VLOOKUP(H32,'[1]Consolidado MP Planta'!$A$2:$M$823,3,0),"") | C32: =+A32 -> 0 | D32: =IFERROR(VLOOKUP(H32,'[1]Consolidado MP Planta'!$A$2:$M$823,13,0),"") | E32: =IFERROR(VLOOKUP(H32,'[1]Consolidado MP Planta'!$A$2:$M$823,12,0),"") | F32: =IFERROR(C32*E32,"") | G32: =IFERROR(F32/$F$66,"")
A34: UNIDADES | B34: EMPAQUE SEMIELABORADOS | C34: UNIDADES | D34: UND MEDIDA | E34: COSTO UNITARIO | F34: TOTAL COSTO | G34: % PREC. DEFINIDO | H34: CODIGOS
A35: =+A17 -> 5000 | B35: RELLENO LEMON COURT | C35: =+A35 -> 5000 | D35: Gramos | E35: =+'Costo Topping Lemon Court'!E76 -> 0 | F35: =IFERROR(E35*C35,"") -> 0 | G35: =IFERROR(F35/$F$66,"") -> 0
A36: =+A18 -> 0 | B36: =IFERROR(VLOOKUP(H36,[1]SEMIELABORADOS!$A$2:$M$6000,2,0),"") | C36: =+A36 -> 0 | D36: =IFERROR(VLOOKUP(H36,[1]SEMIELABORADOS!$A$2:$M$6000,6,0),"") | E36: =IFERROR(VLOOKUP(H36,[1]SEMIELABORADOS!$A$2:$M$65536,10,0),"") | F36: =IFERROR(E36*C36,"") | G36: =IFERROR(F36/$F$66,"")
A37: =+A19 -> 0 | B37: =IFERROR(VLOOKUP(H37,[1]SEMIELABORADOS!$A$2:$M$6000,2,0),"") | C37: =+A37 -> 0 | D37: =IFERROR(VLOOKUP(H37,[1]SEMIELABORADOS!$A$2:$M$6000,6,0),"") | E37: =IFERROR(VLOOKUP(H37,[1]SEMIELABORADOS!$A$2:$M$65536,10,0),"") | F37: =IFERROR(E37*C37,"") | G37: =IFERROR(F37/$F$66,"")
A38: =+A20 -> 0 | B38: =IFERROR(VLOOKUP(H38,[1]SEMIELABORADOS!$A$2:$M$6000,2,0),"") | C38: =+A38 -> 0 | D38: =IFERROR(VLOOKUP(H38,[1]SEMIELABORADOS!$A$2:$M$6000,6,0),"") | E38: =IFERROR(VLOOKUP(H38,[1]SEMIELABORADOS!$A$2:$M$65536,10,0),"") | F38: =IFERROR(E38*C38,"") | G38: =IFERROR(F38/$F$66,"")
A39: =+A21 -> 0 | B39: =IFERROR(VLOOKUP(H39,[1]SEMIELABORADOS!$A$2:$M$6000,2,0),"") | C39: =+A39 -> 0 | D39: =IFERROR(VLOOKUP(H39,[1]SEMIELABORADOS!$A$2:$M$6000,6,0),"") | E39: =IFERROR(VLOOKUP(H39,[1]SEMIELABORADOS!$A$2:$M$65536,10,0),"") | F39: =IFERROR(E39*C39,"") | G39: =IFERROR(F39/$F$66,"")
A40: =+A22 -> 0 | B40: =IFERROR(VLOOKUP(H40,[1]SEMIELABORADOS!$A$2:$M$6000,2,0),"") | C40: =+A40 -> 0 | D40: =IFERROR(VLOOKUP(H40,[1]SEMIELABORADOS!$A$2:$M$6000,6,0),"") | E40: =IFERROR(VLOOKUP(H40,[1]SEMIELABORADOS!$A$2:$M$65536,10,0),"") | F40: =IFERROR(E40*C40,"") | G40: =IFERROR(F40/$F$66,"")
A41: =+A23 -> 0 | B41: =IFERROR(VLOOKUP(H41,[1]SEMIELABORADOS!$A$2:$M$6000,2,0),"") | C41: =+A41 -> 0 | D41: =IFERROR(VLOOKUP(H41,[1]SEMIELABORADOS!$A$2:$M$6000,6,0),"") | E41: =IFERROR(VLOOKUP(H41,[1]SEMIELABORADOS!$A$2:$M$65536,10,0),"") | F41: =IFERROR(E41*C41,"") | G41: =IFERROR(F41/$F$66,"")
A43: UNIDADES | B43: MODI | C43: UNIDADES | D43: UND MEDIDA | E43: COSTO UNITARIO | F43: TOTAL COSTO | G43: % PREC. DEFINIDO | H43: CODIGOS
A44: =+A35 -> 5000 | B44: RELLENO LEMON COURT | C44: =+A44 -> 5000 | D44: Gramos | E44: =+'Costo Topping Lemon Court'!E74 -> 0.1155 | F44: =IFERROR(E44*C44,"") -> 577.5 | G44: =IFERROR(F44/$F$66,"") -> 0.20416529
A45: =+A36 -> 0 | B45: =IFERROR(VLOOKUP(H45,[1]SEMIELABORADOS!$A$2:$M$6000,2,0),"") | C45: =+A45 -> 0 | D45: =IFERROR(VLOOKUP(H45,[1]SEMIELABORADOS!$A$2:$M$6000,6,0),"") | E45: =IFERROR(VLOOKUP(H45,[1]SEMIELABORADOS!$A$2:$M$65536,12,0),"") | F45: =IFERROR(E45*C45,"") | G45: =IFERROR(F45/$F$66,"")
...

Sheet Relleno Blanco de Limon
C1: SERVICIOS DE PASTELERIA S.A. | H1: CÓDIGO: | I1: ESP-RE-POS-415
C2: ESPECIFICACION DE RECETA | H2: REVISIÓN: | I2: 01
C3: Relleno Blanco de Limon | H3: FECHA DE APROBACIÓN: | I3: 45615
C4: Elaborado | D4: Mariela Barrantes Sánchez
C5: Aprobado | D5: Esteban Cartin, Gte Manufactura
A6: AREA QUE PRODUCE: | D6: Postres | G6: AREA QUE EMPACA: | I6: Postres
A7: # Código | B7: # Código Netsuite | C7: Descripción del ingrediente | D7: Marca | E7: Unidad Internacional | G7: Medida alternativa | I7: Costo - Referencia
E8: Cantidad | F8: Unidad medida | G8: Cantidad | H8: Unidad medida | I8: Colones
B9: SE00010 | C9: Crema Chantilly Blanca (Spoon-Ind) | D9: FAS | E9: =1100*8.22 -> 9042 | F9: g
B10: MP10050 | C10: Leche Condensada | D10: Nestle | E10: =120*8.22 -> 986.4 | F10: g
B11: MP10239 | C11: Limon En Polvo | D11: Resoco | E11: =11*8.22 -> 90.42 | F11: g
B12: MP10043 | C12: Gelatina Pura | D12: Mayca | E12: =14*8.22 -> 115.08 | F12: g
C13: Agua | D13: FAS | E13: =42*8.22 -> 345.24 | F13: g | H13: Para Gelatina
B14: MP10008 | C14: Preservante 1047S | E14: =1*18.22 -> 18.22
D19: Cantidad | E19: Unidad
A20: PESO TOTAL OBTENIDO | D20: 10000 | E20: g | F20: Tiempo de Horneo:
A21: TIEMPO TOTAL DE PREPARACION | D21: 10 | E21: min | F21: Horno:
A22: CANTIDAD DE PORCIONES OBTENIDAS | D22: 1 | E22: tanda | F22: Temperatura de Horneo:
A23: PESO DE CADA PORCIÓN | D23: 10000 | E23: g | F23: Otros
A24: MERMA | D24: =SUM(E9:E13)-D20 -> 579.14 | E24: g
A25: PROCEDIMIENTO DE PREPARACION DE LA RECETA
A26: 1. En la Batidora agregar la crema cantilly Blanca montada, agregar la leche condensada, el limon el polvo y revolver.
A27: 2. Hidratar la gelatina con el agua, derretirla y temperarla con la mezcla anterior y agregarla en forma de hilo a la mezcla.
A28: 3. Utilizar inmediatamente.
A33: CONTROL DE CAMBIOS

Sheet Relleno Blanco de Limon 2
C1: SERVICIOS DE PASTELERIA S.A. | H1: CÓDIGO: | I1: ESP-RE-POF-049
C2: ESPECIFICACION DE RECETA | H2: REVISIÓN: | I2: 02
C3: SE00754 Relleno Blanco de Limon | H3: FECHA DE APROBACIÓN: | I3: 45919
C4: Elaborado | D4: Mariela Barrantes Sánchez
C5: Aprobado | D5: Esteban Cartin, Gte Manufactura
A6: AREA QUE PRODUCE: | D6: Postres | G6: AREA QUE EMPACA: | I6: Postres
A7: # Código | B7: # Código Netsuite | C7: Descripción del ingrediente | D7: Marca | E7: Unidad Internacional | G7: Medida alternativa | I7: Costo - Referencia
E8: Cantidad | F8: Unidad medida | G8: Cantidad | H8: Unidad medida | I8: Colones
B9: SE00010 | C9: Crema Chantilly Blanca (Spoon-Ind) | D9: FAS | E9: 9042 | F9: g
B10: MP10050 | C10: Leche Condensada | D10: Nestle | E10: 986.4 | F10: g
B11: MP10239 | C11: Limon En Polvo | D11: Resoco | E11: 90.42 | F11: g
B12: MP10043 | C12: Gelatina Pura | D12: Mayca | E12: 30 | F12: g
C13: Agua | D13: FAS | E13: 400 | F13: g | H13: Para Gelatina
B14: MP10008 | C14: Preservante 1047S | E14: 18.22 | F14: g
B15: MP10150 | C15: Colorante Gel Egg Yellow | E15: 18.22 | F15: g
D19: Cantidad | E19: Unidad
A20: PESO TOTAL OBTENIDO | D20: 10000 | E20: g | F20: Tiempo de Horneo:
A21: TIEMPO TOTAL DE PREPARACION | D21: 10 | E21: min | F21: Horno:
A22: CANTIDAD DE PORCIONES OBTENIDAS | D22: 1 | E22: tanda | F22: Temperatura de Horneo:
A23: PESO DE CADA PORCIÓN | D23: 10000 | E23: g | F23: Otros
A24: MERMA | D24: 579.14 | E24: g
A25: PROCEDIMIENTO DE PREPARACION DE LA RECETA
A26: 1. En la Batidora agregar la crema cantilly Blanca montada, agregar la leche condensada, el limon el polvo, el colorante y revolver.
A27: 2. Hidratar la gelatina con el agua, derretirla y temperarla con la mezcla anterior y agregarla en forma de hilo a la mezcla.
A28: 3. Utilizar inmediatamente.
A33: CONTROL DE CAMBIOS
A34: 2, Se rebaja gelatina y se aumenta agua.

Sheet Crema Chantilly Blanca
C1: SERVICIOS DE PASTELERIA S.A. | H1: CÓDIGO: | I1: ESP-RE-DES-018
C2: ESPECIFICACION DE RECETA | H2: REVISIÓN: | I2: 01
C3: Crema Blanca Spoon (20800g) SE00010 | H3: FECHA DE APROBACIÓN: | I3: 45613
C4: Elaborado | D4: Javier Tong, Chef
C5: Aprobado | D5: Esteban Cartin, Gte Manufactura
A6: AREA QUE PRODUCE: | D6: Decoración | G6: AREA QUE EMPACA: | I6: Decoracion
A7: # Código | B7: # Código Netsuite | C7: Descripción del ingrediente | D7: Marca | E7: Unidad Internacional | G7: Medida alternativa | I7: Costo - Referencia
E8: Cantidad | F8: Unidad medida | G8: Cantidad | H8: Unidad medida | I8: Colones
C9: Ensamble
A10: 310148 | B10: MP10047 | C10: BETTERCREME SUPREMO (UND:4 K) | D10: RICHS | E10: 12800 | F10: g
A11: 11400031 | B11: MP10048 | C11: CREMA PRESTIGE GRAND (UND:4 K) | D11: RICHS | E11: 3200 | F11: g
A12: 10415 | C12: AGUA POTABLE (PLANTA) | D12: AYA | E12: 800 | F12: g
A13: 1212410 | B13: MP10008 | C13: PRESERVANTE 1047S (PAQ=5 KILO) | D13: ASEAL | E13: 12 | F13: g
C20: Decoración
C29: Empaque
A30: 702123 | B30: EM10011 | C30: ETIQUETA BLANCA 2 5/8X1 15/16 (UND) | D30: Etiplas | E30: 1 | F30: ud
D40: Cantidad | E40: Unidad
A41: PESO TOTAL OBTENIDO | D41: 16597 | E41: g | F41: Tiempo de Horneo:
A42: TIEMPO TOTAL DE PREPARACION | D42: 10 | E42: min | F42: Horno:
A43: CANTIDAD DE PORCIONES OBTENIDAS | D43: 1 | E43: Tanda | F43: Temperatura de Horneo:
A44: PESO DE CADA PORCIÓN | D44: 16597 | E44: g | F44: Otros
A45: MERMA | D45: 215 | E45: g
A46: PROCEDIMIENTO DE PREPARACION DE LA RECETA
A47: 1.- Abrir los galones de crema y verter dentro de la top cream.
A48: 2.- Disolver el preservante en el agua. Agregar a la top cream.
A49: 3.- Batir por 12 a 15 minutos. Colocar en una tina plastica, tapar.
A50: 4.- Etiquetar con nombre y fecha de vencimiento.
A51: 5.- Mantener en refrigeración.
A56: CONTROL DE CAMBIOS

Sheet Costo Relleno Blanco Limon
E1: Precio Local | F1: Costo MP | G1: Costo EM | H1: Costo MO
E2: =IFERROR(O62,"") -> 26527.648 | F2: =IFERROR(H53,"") -> 24364.931 | G2: =IFERROR(H54,"") -> 90.42 | H2: =IFERROR(H56,"") -> 1131.68
A5: ESTRUCTURA DE COSTOS
F6: Fecha: | H6: =TODAY() -> 46064
A7: UNIDADES | B7: DESCRIPCION MAT.PRIMA | C7: UNIDADES | D7: UND MEDIDA | E7: COSTO UNITARIO | F7: TOTAL COSTO | G7: % PREC. DEFINIDO | H7: CODIGOS
A8: 986.4 | B8: Leche Condensada | C8: =+A8 -> 986.4 | D8: Gramos | E8: 2.15 | F8: =IFERROR(C8*E8,"") -> 2120.76 | G8: =IFERROR(F8/$F$66,"") -> 0.082479248 | H8: MP10050
A9: 90.42 | B9: Limon En Polvo | C9: =+A9 -> 90.42 | D9: Gramos | E9: 6 | F9: =IFERROR(C9*E9,"") -> 542.52 | G9: =IFERROR(F9/$F$66,"") -> 0.021099343 | H9: MP10239
A10: 115.08 | B10: Gelatina Pura | C10: =+A10 -> 115.08 | D10: Gramos | E10: 13.01 | F10: =IFERROR(C10*E10,"") -> 1497.1908 | G10: =IFERROR(F10/$F$66,"") -> 0.058227792 | H10: MP10043
A11: 18 | B11: Preservante 1047S | C11: =+A11 -> 18 | D11: Gramos | E11: 7.29 | F11: =IFERROR(C11*E11,"") -> 131.22 | G11: =IFERROR(F11/$F$66,"") -> 0.0051033247 | H11: MP10008
B12: =IFERROR(VLOOKUP(H12,'[1]Consolidado MP Planta'!$A$2:$M$823,3,0),"") | C12: =+A12 -> 0 | D12: =IFERROR(VLOOKUP(H12,'[1]Consolidado MP Planta'!$A$2:$M$823,13,0),"") | E12: =IFERROR(VLOOKUP(H12,'[1]Consolidado MP Planta'!$A$2:$M$823,12,0),"") | F12: =IFERROR(C12*E12,"") | G12: =IFERROR(F12/$F$66,"")
B13: =IFERROR(VLOOKUP(H13,'[1]Consolidado MP Planta'!$A$2:$M$823,3,0),"") | C13: =+A13 -> 0 | D13: =IFERROR(VLOOKUP(H13,'[1]Consolidado MP Planta'!$A$2:$M$823,13,0),"") | E13: =IFERROR(VLOOKUP(H13,'[1]Consolidado MP Planta'!$A$2:$M$823,12,0),"") | F13: =IFERROR(C13*E13,"") | G13: =IFERROR(F13/$F$66,"")
B14: =IFERROR(VLOOKUP(H14,'[1]Consolidado MP Planta'!$A$2:$M$823,3,0),"") | C14: =+A14 -> 0 | D14: =IFERROR(VLOOKUP(H14,'[1]Consolidado MP Planta'!$A$2:$M$823,13,0),"") | E14: =IFERROR(VLOOKUP(H14,'[1]Consolidado MP Planta'!$A$2:$M$823,12,0),"") | F14: =IFERROR(C14*E14,"") | G14: =IFERROR(F14/$F$66,"")
B15: =IFERROR(VLOOKUP(H15,'[2]ARTICULOS MP PLANTA'!$A$2:$G$589,2,0),"")
A16: UNIDADES | B16: MATERIA PRIMA SEMIELABORADOS | C16: UNIDADES | D16: UND MEDIDA | E16: COSTO UNITARIO | F16: TOTAL COSTO | G16: % PREC. DEFINIDO | H16: CODIGOS
A17: 9042 | B17: Crema Chantilly Blanca (Spoon-Ind) | C17: =+A17 -> 9042 | D17: Gramos | E17: 2.22 | F17: =IFERROR(E17*C17,"") -> 20073.24 | G17: =IFERROR(F17/$F$66,"") -> 0.78067568 | H17: SE00010
B18: =IFERROR(VLOOKUP(H18,[1]SEMIELABORADOS!$A$2:$M$6000,2,0),"") | C18: =+A18 -> 0 | D18: =IFERROR(VLOOKUP(H18,[1]SEMIELABORADOS!$A$2:$M$6000,6,0),"") | E18: =IFERROR(VLOOKUP(H18,[1]SEMIELABORADOS!$A$2:$H$65536,8,0),"") | F18: =IFERROR(E18*C18,"") | G18: =IFERROR(F18/$F$66,"")
B19: =IFERROR(VLOOKUP(H19,[1]SEMIELABORADOS!$A$2:$M$6000,2,0),"") | C19: =+A19 -> 0 | D19: =IFERROR(VLOOKUP(H19,[1]SEMIELABORADOS!$A$2:$M$6000,6,0),"") | E19: =IFERROR(VLOOKUP(H19,[1]SEMIELABORADOS!$A$2:$H$65536,8,0),"") | F19: =IFERROR(E19*C19,"") | G19: =IFERROR(F19/$F$66,"")
B20: =IFERROR(VLOOKUP(H20,[1]SEMIELABORADOS!$A$2:$M$6000,2,0),"") | C20: =+A20 -> 0 | D20: =IFERROR(VLOOKUP(H20,[1]SEMIELABORADOS!$A$2:$M$6000,6,0),"") | E20: =IFERROR(VLOOKUP(H20,[1]SEMIELABORADOS!$A$2:$H$65536,8,0),"") | F20: =IFERROR(E20*C20,"") | G20: =IFERROR(F20/$F$66,"")
B21: =IFERROR(VLOOKUP(H21,[1]SEMIELABORADOS!$A$2:$M$6000,2,0),"") | C21: =+A21 -> 0 | D21: =IFERROR(VLOOKUP(H21,[1]SEMIELABORADOS!$A$2:$M$6000,6,0),"") | E21: =IFERROR(VLOOKUP(H21,[1]SEMIELABORADOS!$A$2:$H$65536,8,0),"") | F21: =IFERROR(E21*C21,"") | G21: =IFERROR(F21/$F$66,"")
B22: =IFERROR(VLOOKUP(H22,[1]SEMIELABORADOS!$A$2:$M$6000,2,0),"") | C22: =+A22 -> 0 | D22: =IFERROR(VLOOKUP(H22,[1]SEMIELABORADOS!$A$2:$M$6000,6,0),"") | E22: =IFERROR(VLOOKUP(H22,[1]SEMIELABORADOS!$A$2:$H$65536,8,0),"") | F22: =IFERROR(E22*C22,"") | G22: =IFERROR(F22/$F$66,"")
B23: =IFERROR(VLOOKUP(H23,[1]SEMIELABORADOS!$A$2:$M$6000,2,0),"") | C23: =+A23 -> 0 | D23: =IFERROR(VLOOKUP(H23,[1]SEMIELABORADOS!$A$2:$M$6000,6,0),"") | E23: =IFERROR(VLOOKUP(H23,[1]SEMIELABORADOS!$A$2:$H$65536,8,0),"") | F23: =IFERROR(E23*C23,"") | G23: =IFERROR(F23/$F$66,"")
B24: =IFERROR(VLOOKUP(H24,[1]SEMIELABORADOS!$A$2:$M$6000,2,0),"") | C24: =+A24 -> 0 | D24: =IFERROR(VLOOKUP(H24,[1]SEMIELABORADOS!$A$2:$M$6000,6,0),"") | E24: =IFERROR(VLOOKUP(H24,[1]SEMIELABORADOS!$A$2:$H$65536,8,0),"") | F24: =IFERROR(E24*C24,"") | G24: =IFERROR(F24/$F$66,"")
A26: UNIDADES | B26: EMPAQUE | C26: UNIDADES | D26: UND MEDIDA | E26: COSTO UNITARIO | F26: TOTAL COSTO | G26: % PREC. DEFINIDO | H26: CODIGOS
A27: 0 | B27: =IFERROR(VLOOKUP(H27,'[1]Consolidado MP Planta'!$A$2:$M$823,3,0),"") | C27: =+A27 -> 0 | D27: =IFERROR(VLOOKUP(H27,'[1]Consolidado MP Planta'!$A$2:$M$823,13,0),"") | E27: =IFERROR(VLOOKUP(H27,'[1]Consolidado MP Planta'!$A$2:$M$823,12,0),"") | F27: =IFERROR(C27*E27,"") | G27: =IFERROR(F27/$F$66,"")
B28: =IFERROR(VLOOKUP(H28,'[1]Consolidado MP Planta'!$A$2:$M$823,3,0),"") | C28: =+A28 -> 0 | D28: =IFERROR(VLOOKUP(H28,'[1]Consolidado MP Planta'!$A$2:$M$823,13,0),"") | E28: =IFERROR(VLOOKUP(H28,'[1]Consolidado MP Planta'!$A$2:$M$823,12,0),"") | F28: =IFERROR(C28*E28,"") | G28: =IFERROR(F28/$F$66,"")
B29: =IFERROR(VLOOKUP(H29,'[1]Consolidado MP Planta'!$A$2:$M$823,3,0),"") | C29: =+A29 -> 0 | D29: =IFERROR(VLOOKUP(H29,'[1]Consolidado MP Planta'!$A$2:$M$823,13,0),"") | E29: =IFERROR(VLOOKUP(H29,'[1]Consolidado MP Planta'!$A$2:$M$823,12,0),"") | F29: =IFERROR(C29*E29,"") | G29: =IFERROR(F29/$F$66,"")
B30: =IFERROR(VLOOKUP(H30,'[1]Consolidado MP Planta'!$A$2:$M$823,3,0),"") | C30: =+A30 -> 0 | D30: =IFERROR(VLOOKUP(H30,'[1]Consolidado MP Planta'!$A$2:$M$823,13,0),"") | E30: =IFERROR(VLOOKUP(H30,'[1]Consolidado MP Planta'!$A$2:$M$823,12,0),"") | F30: =IFERROR(C30*E30,"") | G30: =IFERROR(F30/$F$66,"")
B31: =IFERROR(VLOOKUP(H31,'[1]Consolidado MP Planta'!$A$2:$M$823,3,0),"") | C31: =+A31 -> 0 | D31: =IFERROR(VLOOKUP(H31,'[1]Consolidado MP Planta'!$A$2:$M$823,13,0),"") | E31: =IFERROR(VLOOKUP(H31,'[1]Consolidado MP Planta'!$A$2:$M$823,12,0),"") | F31: =IFERROR(C31*E31,"") | G31: =IFERROR(F31/$F$66,"")
B32: =IFERROR(VLOOKUP(H32,'[1]Consolidado MP Planta'!$A$2:$M$823,3,0),"") | C32: =+A32 -> 0 | D32: =IFERROR(VLOOKUP(H32,'[1]Consolidado MP Planta'!$A$2:$M$823,13,0),"") | E32: =IFERROR(VLOOKUP(H32,'[1]Consolidado MP Planta'!$A$2:$M$823,12,0),"") | F32: =IFERROR(C32*E32,"") | G32: =IFERROR(F32/$F$66,"")
A34: UNIDADES | B34: EMPAQUE SEMIELABORADOS | C34: UNIDADES | D34: UND MEDIDA | E34: COSTO UNITARIO | F34: TOTAL COSTO | G34: % PREC. DEFINIDO | H34: CODIGOS
A35: =+A17 -> 9042 | B35: Crema Chantilly Blanca (Spoon-Ind) | C35: =+A35 -> 9042 | D35: Gramos | E35: 0.01 | F35: =IFERROR(E35*C35,"") -> 90.42 | G35: =IFERROR(F35/$F$66,"") -> 0.0035165571 | H35: SE00010
A36: =+A18 -> 0 | B36: =IFERROR(VLOOKUP(H36,[1]SEMIELABORADOS!$A$2:$M$6000,2,0),"") | C36: =+A36 -> 0 | D36: =IFERROR(VLOOKUP(H36,[1]SEMIELABORADOS!$A$2:$M$6000,6,0),"") | E36: =IFERROR(VLOOKUP(H36,[1]SEMIELABORADOS!$A$2:$M$65536,10,0),"") | F36: =IFERROR(E36*C36,"") | G36: =IFERROR(F36/$F$66,"")
A37: =+A19 -> 0 | B37: =IFERROR(VLOOKUP(H37,[1]SEMIELABORADOS!$A$2:$M$6000,2,0),"") | C37: =+A37 -> 0 | D37: =IFERROR(VLOOKUP(H37,[1]SEMIELABORADOS!$A$2:$M$6000,6,0),"") | E37: =IFERROR(VLOOKUP(H37,[1]SEMIELABORADOS!$A$2:$M$65536,10,0),"") | F37: =IFERROR(E37*C37,"") | G37: =IFERROR(F37/$F$66,"")
A38: =+A20 -> 0 | B38: =IFERROR(VLOOKUP(H38,[1]SEMIELABORADOS!$A$2:$M$6000,2,0),"") | C38: =+A38 -> 0 | D38: =IFERROR(VLOOKUP(H38,[1]SEMIELABORADOS!$A$2:$M$6000,6,0),"") | E38: =IFERROR(VLOOKUP(H38,[1]SEMIELABORADOS!$A$2:$M$65536,10,0),"") | F38: =IFERROR(E38*C38,"") | G38: =IFERROR(F38/$F$66,"")
A39: =+A21 -> 0 | B39: =IFERROR(VLOOKUP(H39,[1]SEMIELABORADOS!$A$2:$M$6000,2,0),"") | C39: =+A39 -> 0 | D39: =IFERROR(VLOOKUP(H39,[1]SEMIELABORADOS!$A$2:$M$6000,6,0),"") | E39: =IFERROR(VLOOKUP(H39,[1]SEMIELABORADOS!$A$2:$M$65536,10,0),"") | F39: =IFERROR(E39*C39,"") | G39: =IFERROR(F39/$F$66,"")
A40: =+A22 -> 0 | B40: =IFERROR(VLOOKUP(H40,[1]SEMIELABORADOS!$A$2:$M$6000,2,0),"") | C40: =+A40 -> 0 | D40: =IFERROR(VLOOKUP(H40,[1]SEMIELABORADOS!$A$2:$M$6000,6,0),"") | E40: =IFERROR(VLOOKUP(H40,[1]SEMIELABORADOS!$A$2:$M$65536,10,0),"") | F40: =IFERROR(E40*C40,"") | G40: =IFERROR(F40/$F$66,"")
A41: =+A23 -> 0 | B41: =IFERROR(VLOOKUP(H41,[1]SEMIELABORADOS!$A$2:$M$6000,2,0),"") | C41: =+A41 -> 0 | D41: =IFERROR(VLOOKUP(H41,[1]SEMIELABORADOS!$A$2:$M$6000,6,0),"") | E41: =IFERROR(VLOOKUP(H41,[1]SEMIELABORADOS!$A$2:$M$65536,10,0),"") | F41: =IFERROR(E41*C41,"") | G41: =IFERROR(F41/$F$66,"")
A43: UNIDADES | B43: MODI | C43: UNIDADES | D43: UND MEDIDA | E43: COSTO UNITARIO | F43: TOTAL COSTO | G43: % PREC. DEFINIDO | H43: CODIGOS
A44: =+A35 -> 9042 | B44: Crema Chantilly Blanca (Spoon-Ind) | C44: =+A44 -> 9042 | D44: Gramos | E44: 0.04 | F44: =IFERROR(E44*C44,"") -> 361.68 | G44: =IFERROR(F44/$F$66,"") -> 0.014066228 | H44: SE00010
A45: =+A36 -> 0 | B45: =IFERROR(VLOOKUP(H45,[1]SEMIELABORADOS!$A$2:$M$6000,2,0),"") | C45: =+A45 -> 0 | D45: =IFERROR(VLOOKUP(H45,[1]SEMIELABORADOS!$A$2:$M$6000,6,0),"") | E45: =IFERROR(VLOOKUP(H45,[1]SEMIELABORADOS!$A$2:$M$65536,12,0),"") | F45: =IFERROR(E45*C45,"") | G45: =IFERROR(F45/$F$66,"")
...
