Workbook

Sheet Porción Torta Pistacho
C1: SERVICIOS DE PASTELERIA S.A. | H1: CÓDIGO:
C2: ESPECIFICACION DE RECETA | H2: REVISIÓN:
C3: Porción Torta Rosanna Pistacho | H3: FECHA DE APROBACIÓN:
C4: Elaborado | D4: Mariela Barrantes Sánchez, Chef
C5: Aprobado | D5: Esteban Cartin, Gerente de Manofactura
A6: AREA QUE PRODUCE: | D6: Decoración | G6: AREA QUE EMPACA: | I6: Decoración
A7: # Código | B7: # Código | C7: Descripción del ingrediente | D7: Marca | E7: Unidad Internacional | G7: Medida alternativa | I7: Costo - Referencia
E8: Cantidad | F8: Unidad medida | G8: Cantidad | H8: Unidad medida | I8: Colones
B9: NUEVO | C9: ENSAMBLE DISCO PISTACHO | D9: FAS | E9: 795 | F9: g | G9: 1 unidad
C11: DECORACIÓN
B12: NUEVO | C12: CREMA VERDE PISTACHO | D12: FAS | E12: 40 | F12: g | G12: 6g x ud | H12: Encremado
B13: NUEVO | C13: GANACHE DE PISTACHO | D13: FAS | E13: 85 | F13: g | G13: 14g x ud
B14: NUEVO | C14: PISTACHO TOSTADO | D14: FAS | E14: 18 | F14: g | G14: 3g x ud
M16: 1500
C17: EMPAQUE
B18: EM10079 | C18: CONTENEDOR TRIANGU ALTO (CAJA:200 UND) | E18: 6 | F18: ud
B19: EM10124 | C19: Etiqueta Blanca R-153 | D19: Cemusa | E19: 6 | F19: ud
B20: EM10011 | C20: Etiqueta Blanca 2 5/8X1 15/16 | D20: ETIPLAST | E20: 6 | F20: ud
B21: EM10002 | C21: ETIQ.BLANCA 1 1/4 * 3/4 | D21: CEMUSA | E21: 6 | F21: ud
B22: EM10135 | C22: ETIQUETA SELLO SEGURIDAD (ROLLO:1000) | D22: ETIPLAST | E22: 6 | F22: ud
B23: NUEVO | C23: EtTIQUETA ESPECIAL | E23: 1 | F23: ud
D28: Cantidad | E28: Unidad
A29: PESO TOTAL OBTENIDO | D29: 930 | E29: g
A30: TIEMPO TOTAL DE PREPARACIÓN | D30: 5 | E30: min
A31: CANTIDAD DE PORCIONES OBTENIDAS | D31: 1 | E31: ud
A32: PESO DE CADA PORCIÓN | D32: 155 | E32: g
A33: MERMA | D33: =SUM(E9:E14)-D29 -> 8 | E33: g
A34: PROCEDIMIENTO DE PREPARACION DE LA RECETA
A35: 1.- Desmoldar el disco de pistacho en la orla 10.
A36: 2.- Encremar de forma lisa con la crema verde pistacho y
A37: 3.- Colocar el ganache con ayuda de una bolsa y exparcirlo con ayuda de una espatula
A38: 4.- Colocar trozos de pistacho tostado
A39: 5.- Tapar y etiquetar
A42: CONTROL DE CAMBIOS

Sheet Costo Porcion Torta 
E1: Precio Local | F1: Costo MP | G1: Costo EM | H1: Costo MO
E2: =IFERROR(O62,"") -> 5461.8553 | F2: =IFERROR(H53,"") -> 3231.1124 | G2: =IFERROR(H54,"") -> 741.99212 | H2: =IFERROR(H56,"") -> 813.00575
A5: ESTRUCTURA DE COSTOS
F6: Fecha: | H6: =TODAY() -> 45901
A7: UNIDADES | B7: DESCRIPCION MAT.PRIMA | C7: UNIDADES | D7: UND MEDIDA | E7: COSTO UNITARIO | F7: TOTAL COSTO | G7: % PREC. DEFINIDO | H7: CODIGOS
B8: =IFERROR(VLOOKUP(H8,'[1]Consolidado MP Planta'!$A$2:$M$823,3,0),"") | C8: =+A8 -> 0 | D8: =IFERROR(VLOOKUP(H8,'[1]Consolidado MP Planta'!$A$2:$M$823,13,0),"") | E8: =IFERROR(VLOOKUP(H8,'[1]Consolidado MP Planta'!$A$2:$M$823,12,0),"") | F8: =IFERROR(C8*E8,"") | G8: =IFERROR(F8/$F$66,"")
B9: =IFERROR(VLOOKUP(H9,'[1]Consolidado MP Planta'!$A$2:$M$823,3,0),"") | C9: =+A9 -> 0 | D9: =IFERROR(VLOOKUP(H9,'[1]Consolidado MP Planta'!$A$2:$M$823,13,0),"") | E9: =IFERROR(VLOOKUP(H9,'[1]Consolidado MP Planta'!$A$2:$M$823,12,0),"") | F9: =IFERROR(C9*E9,"") | G9: =IFERROR(F9/$F$66,"")
B10: =IFERROR(VLOOKUP(H10,'[1]Consolidado MP Planta'!$A$2:$M$823,3,0),"") | C10: =+A10 -> 0 | D10: =IFERROR(VLOOKUP(H10,'[1]Consolidado MP Planta'!$A$2:$M$823,13,0),"") | E10: =IFERROR(VLOOKUP(H10,'[1]Consolidado MP Planta'!$A$2:$M$823,12,0),"") | F10: =IFERROR(C10*E10,"") | G10: =IFERROR(F10/$F$66,"")
B11: =IFERROR(VLOOKUP(H11,'[1]Consolidado MP Planta'!$A$2:$M$823,3,0),"") | C11: =+A11 -> 0 | D11: =IFERROR(VLOOKUP(H11,'[1]Consolidado MP Planta'!$A$2:$M$823,13,0),"") | E11: =IFERROR(VLOOKUP(H11,'[1]Consolidado MP Planta'!$A$2:$M$823,12,0),"") | F11: =IFERROR(C11*E11,"") | G11: =IFERROR(F11/$F$66,"")
B12: =IFERROR(VLOOKUP(H12,'[1]Consolidado MP Planta'!$A$2:$M$823,3,0),"") | C12: =+A12 -> 0 | D12: =IFERROR(VLOOKUP(H12,'[1]Consolidado MP Planta'!$A$2:$M$823,13,0),"") | E12: =IFERROR(VLOOKUP(H12,'[1]Consolidado MP Planta'!$A$2:$M$823,12,0),"") | F12: =IFERROR(C12*E12,"") | G12: =IFERROR(F12/$F$66,"")
B13: =IFERROR(VLOOKUP(H13,'[1]Consolidado MP Planta'!$A$2:$M$823,3,0),"") | C13: =+A13 -> 0 | D13: =IFERROR(VLOOKUP(H13,'[1]Consolidado MP Planta'!$A$2:$M$823,13,0),"") | E13: =IFERROR(VLOOKUP(H13,'[1]Consolidado MP Planta'!$A$2:$M$823,12,0),"") | F13: =IFERROR(C13*E13,"") | G13: =IFERROR(F13/$F$66,"")
B14: =IFERROR(VLOOKUP(H14,'[1]Consolidado MP Planta'!$A$2:$M$823,3,0),"") | C14: =+A14 -> 0 | D14: =IFERROR(VLOOKUP(H14,'[1]Consolidado MP Planta'!$A$2:$M$823,13,0),"") | E14: =IFERROR(VLOOKUP(H14,'[1]Consolidado MP Planta'!$A$2:$M$823,12,0),"") | F14: =IFERROR(C14*E14,"") | G14: =IFERROR(F14/$F$66,"")
B15: =IFERROR(VLOOKUP(H15,'[2]ARTICULOS MP PLANTA'!$A$2:$G$589,2,0),"")
A16: UNIDADES | B16: MATERIA PRIMA SEMIELABORADOS | C16: UNIDADES | D16: UND MEDIDA | E16: COSTO UNITARIO | F16: TOTAL COSTO | G16: % PREC. DEFINIDO | H16: CODIGOS
A17: 1 | B17: ENSAMBLE DISCO PISTACHO | C17: =+A17 -> 1 | D17: UND | E17: =+'Costo Disco '!H53 -> 2592.3474 | F17: =IFERROR(E17*C17,"") -> 2592.3474 | G17: =IFERROR(F17/$F$66,"") -> 0.58614233
A18: 40 | B18: CREMA VERDE PISTACHO | C18: =+A18 -> 40 | D18: Gramos | E18: =+'[3]Costo Crema verde pistacho'!$E$69 -> 2.18844 | F18: =IFERROR(E18*C18,"") -> 87.5376 | G18: =IFERROR(F18/$F$66,"") -> 0.019792676
A19: 85 | B19: GANACHE DE PISTACHO | C19: =+A19 -> 85 | D19: Gramos | E19: =+'Costo Ganache '!E69 -> 4.590292 | F19: =IFERROR(E19*C19,"") -> 390.17482 | G19: =IFERROR(F19/$F$66,"") -> 0.088220421
A20: 12 | B20: PISTACHO TOSTADO | C20: =+A20 -> 12 | D20: Gramos | E20: =+'[3]Costo Pistacho Tostado'!$E$69 -> 13.421053 | F20: =IFERROR(E20*C20,"") -> 161.05263 | G20: =IFERROR(F20/$F$66,"") -> 0.036414782
B21: =IFERROR(VLOOKUP(H21,[1]SEMIELABORADOS!$A$2:$M$6000,2,0),"") | C21: =+A21 -> 0 | D21: =IFERROR(VLOOKUP(H21,[1]SEMIELABORADOS!$A$2:$M$6000,6,0),"") | E21: =IFERROR(VLOOKUP(H21,[1]SEMIELABORADOS!$A$2:$H$65536,8,0),"") | F21: =IFERROR(E21*C21,"") | G21: =IFERROR(F21/$F$66,"")
B22: =IFERROR(VLOOKUP(H22,[1]SEMIELABORADOS!$A$2:$M$6000,2,0),"") | C22: =+A22 -> 0 | D22: =IFERROR(VLOOKUP(H22,[1]SEMIELABORADOS!$A$2:$M$6000,6,0),"") | E22: =IFERROR(VLOOKUP(H22,[1]SEMIELABORADOS!$A$2:$H$65536,8,0),"") | F22: =IFERROR(E22*C22,"") | G22: =IFERROR(F22/$F$66,"")
B23: =IFERROR(VLOOKUP(H23,[1]SEMIELABORADOS!$A$2:$M$6000,2,0),"") | C23: =+A23 -> 0 | D23: =IFERROR(VLOOKUP(H23,[1]SEMIELABORADOS!$A$2:$M$6000,6,0),"") | E23: =IFERROR(VLOOKUP(H23,[1]SEMIELABORADOS!$A$2:$H$65536,8,0),"") | F23: =IFERROR(E23*C23,"") | G23: =IFERROR(F23/$F$66,"")
B24: =IFERROR(VLOOKUP(H24,[1]SEMIELABORADOS!$A$2:$M$6000,2,0),"") | C24: =+A24 -> 0 | D24: =IFERROR(VLOOKUP(H24,[1]SEMIELABORADOS!$A$2:$M$6000,6,0),"") | E24: =IFERROR(VLOOKUP(H24,[1]SEMIELABORADOS!$A$2:$H$65536,8,0),"") | F24: =IFERROR(E24*C24,"") | G24: =IFERROR(F24/$F$66,"")
A26: UNIDADES | B26: EMPAQUE | C26: UNIDADES | D26: UND MEDIDA | E26: COSTO UNITARIO | F26: TOTAL COSTO | G26: % PREC. DEFINIDO | H26: CODIGOS
A27: 6 | B27: CONTENEDOR TRIANGU ALTO (CAJA:200 UND) | C27: =+A27 -> 6 | D27: UND | E27: 58.84 | F27: =IFERROR(C27*E27,"") -> 353.04 | G27: =IFERROR(F27/$F$66,"") -> 0.079824058 | H27: EM10079
A28: 6 | B28: Etiqueta Blanca R-153 | C28: =+A28 -> 6 | D28: UND | E28: 0.39 | F28: =IFERROR(C28*E28,"") -> 2.34 | G28: =IFERROR(F28/$F$66,"") -> 0.00052908536 | H28: EM10124
A29: 6 | B29: Etiqueta Blanca 2 5/8X1 15/16 | C29: =+A29 -> 6 | D29: UND | E29: 2.13 | F29: =IFERROR(C29*E29,"") -> 12.78 | G29: =IFERROR(F29/$F$66,"") -> 0.0028896201 | H29: EM10011
A30: 6 | B30: ETIQ.BLANCA 1 1/4 * 3/4 | C30: =+A30 -> 6 | D30: UND | E30: 0.58 | F30: =IFERROR(C30*E30,"") -> 3.48 | G30: =IFERROR(F30/$F$66,"") -> 0.0007868449 | H30: EM10002
A31: 6 | B31: ETIQUETA SELLO SEGURIDAD (ROLLO:1000) | C31: =+A31 -> 6 | D31: UND | E31: 6 | F31: =IFERROR(C31*E31,"") -> 36 | G31: =IFERROR(F31/$F$66,"") -> 0.0081397748 | H31: EM10135
A32: 6 | B32: EtTIQUETA ESPECIAL | C32: =+A32 -> 6 | D32: UND | E32: 55 | F32: =IFERROR(C32*E32,"") -> 330 | G32: =IFERROR(F32/$F$66,"") -> 0.074614602 | H32: NUEVO
A34: UNIDADES | B34: EMPAQUE SEMIELABORADOS | C34: UNIDADES | D34: UND MEDIDA | E34: COSTO UNITARIO | F34: TOTAL COSTO | G34: % PREC. DEFINIDO | H34: CODIGOS
A35: =+A17 -> 1 | B35: ENSAMBLE DISCO PISTACHO | C35: =+A35 -> 1 | D35: UND | E35: =+'Costo Disco '!H54 -> 4.351 | F35: =IFERROR(E35*C35,"") -> 4.351 | G35: =IFERROR(F35/$F$66,"") -> 0.00098378223
A36: =+A18 -> 40 | B36: CREMA VERDE PISTACHO | C36: =+A36 -> 40 | D36: Gramos | E36: =+'[3]Costo Crema verde pistacho'!$E$76 -> 2.7884615e-05 | F36: =IFERROR(E36*C36,"") -> 0.0011153846 | G36: =IFERROR(F36/$F$66,"") -> 2.5219388e-07
A37: =+A19 -> 85 | B37: GANACHE DE PISTACHO | C37: =+A37 -> 85 | D37: Gramos | E37: =+'Costo Ganache '!E76 -> 0 | F37: =IFERROR(E37*C37,"") -> 0 | G37: =IFERROR(F37/$F$66,"") -> 0
A38: =+A20 -> 12 | B38: PISTACHO TOSTADO | C38: =+A38 -> 12 | D38: Gramos | E38: =+'[3]Costo Pistacho Tostado'!$E$76 -> 0 | F38: =IFERROR(E38*C38,"") -> 0 | G38: =IFERROR(F38/$F$66,"") -> 0
A39: =+A21 -> 0 | B39: =IFERROR(VLOOKUP(H39,[1]SEMIELABORADOS!$A$2:$M$6000,2,0),"") | C39: =+A39 -> 0 | D39: =IFERROR(VLOOKUP(H39,[1]SEMIELABORADOS!$A$2:$M$6000,6,0),"") | E39: =IFERROR(VLOOKUP(H39,[1]SEMIELABORADOS!$A$2:$M$65536,10,0),"") | F39: =IFERROR(E39*C39,"") | G39: =IFERROR(F39/$F$66,"")
A40: =+A22 -> 0 | B40: =IFERROR(VLOOKUP(H40,[1]SEMIELABORADOS!$A$2:$M$6000,2,0),"") | C40: =+A40 -> 0 | D40: =IFERROR(VLOOKUP(H40,[1]SEMIELABORADOS!$A$2:$M$6000,6,0),"") | E40: =IFERROR(VLOOKUP(H40,[1]SEMIELABORADOS!$A$2:$M$65536,10,0),"") | F40: =IFERROR(E40*C40,"") | G40: =IFERROR(F40/$F$66,"")
A41: =+A23 -> 0 | B41: =IFERROR(VLOOKUP(H41,[1]SEMIELABORADOS!$A$2:$M$6000,2,0),"") | C41: =+A41 -> 0 | D41: =IFERROR(VLOOKUP(H41,[1]SEMIELABORADOS!$A$2:$M$6000,6,0),"") | E41: =IFERROR(VLOOKUP(H41,[1]SEMIELABORADOS!$A$2:$M$65536,10,0),"") | F41: =IFERROR(E41*C41,"") | G41: =IFERROR(F41/$F$66,"")
A43: UNIDADES | B43: MODI | C43: UNIDADES | D43: UND MEDIDA | E43: COSTO UNITARIO | F43: TOTAL COSTO | G43: % PREC. DEFINIDO | H43: CODIGOS
A44: =+A35 -> 1 | B44: ENSAMBLE DISCO PISTACHO | C44: =+A44 -> 1 | D44: UND | E44: =+'Costo Disco '!H56 -> 400.765 | F44: =IFERROR(E44*C44,"") -> 400.765 | G44: =IFERROR(F44/$F$66,"") -> 0.090614913
A45: =+A36 -> 40 | B45: CREMA VERDE PISTACHO | C45: =+A45 -> 40 | D45: Gramos | E45: =+'[3]Costo Crema verde pistacho'!$E$74 -> 0.493078 | F45: =IFERROR(E45*C45,"") -> 19.72312 | G45: =IFERROR(F45/$F$66,"") -> 0.0044594932
...

Sheet Costo Disco 
E1: Precio Local | F1: Costo MP | G1: Costo EM | H1: Costo MO
E2: =IFERROR(O62,"") -> 3330.5667 | F2: =IFERROR(H53,"") -> 2592.3474 | G2: =IFERROR(H54,"") -> 4.351 | H2: =IFERROR(H56,"") -> 400.765
A5: ESTRUCTURA DE COSTOS
F6: Fecha: | H6: =TODAY() -> 45901
A7: UNIDADES | B7: DESCRIPCION MAT.PRIMA | C7: UNIDADES | D7: UND MEDIDA | E7: COSTO UNITARIO | F7: TOTAL COSTO | G7: % PREC. DEFINIDO | H7: CODIGOS
B8: =IFERROR(VLOOKUP(H8,'[1]Consolidado MP Planta'!$A$2:$M$823,3,0),"") | C8: =+A8 -> 0 | D8: =IFERROR(VLOOKUP(H8,'[1]Consolidado MP Planta'!$A$2:$M$823,13,0),"") | E8: =IFERROR(VLOOKUP(H8,'[1]Consolidado MP Planta'!$A$2:$M$823,12,0),"") | F8: =IFERROR(C8*E8,"") | G8: =IFERROR(F8/$F$66,"")
B9: =IFERROR(VLOOKUP(H9,'[1]Consolidado MP Planta'!$A$2:$M$823,3,0),"") | C9: =+A9 -> 0 | D9: =IFERROR(VLOOKUP(H9,'[1]Consolidado MP Planta'!$A$2:$M$823,13,0),"") | E9: =IFERROR(VLOOKUP(H9,'[1]Consolidado MP Planta'!$A$2:$M$823,12,0),"") | F9: =IFERROR(C9*E9,"") | G9: =IFERROR(F9/$F$66,"")
B10: =IFERROR(VLOOKUP(H10,'[1]Consolidado MP Planta'!$A$2:$M$823,3,0),"") | C10: =+A10 -> 0 | D10: =IFERROR(VLOOKUP(H10,'[1]Consolidado MP Planta'!$A$2:$M$823,13,0),"") | E10: =IFERROR(VLOOKUP(H10,'[1]Consolidado MP Planta'!$A$2:$M$823,12,0),"") | F10: =IFERROR(C10*E10,"") | G10: =IFERROR(F10/$F$66,"")
B11: =IFERROR(VLOOKUP(H11,'[1]Consolidado MP Planta'!$A$2:$M$823,3,0),"") | C11: =+A11 -> 0 | D11: =IFERROR(VLOOKUP(H11,'[1]Consolidado MP Planta'!$A$2:$M$823,13,0),"") | E11: =IFERROR(VLOOKUP(H11,'[1]Consolidado MP Planta'!$A$2:$M$823,12,0),"") | F11: =IFERROR(C11*E11,"") | G11: =IFERROR(F11/$F$66,"")
B12: =IFERROR(VLOOKUP(H12,'[1]Consolidado MP Planta'!$A$2:$M$823,3,0),"") | C12: =+A12 -> 0 | D12: =IFERROR(VLOOKUP(H12,'[1]Consolidado MP Planta'!$A$2:$M$823,13,0),"") | E12: =IFERROR(VLOOKUP(H12,'[1]Consolidado MP Planta'!$A$2:$M$823,12,0),"") | F12: =IFERROR(C12*E12,"") | G12: =IFERROR(F12/$F$66,"")
B13: =IFERROR(VLOOKUP(H13,'[1]Consolidado MP Planta'!$A$2:$M$823,3,0),"") | C13: =+A13 -> 0 | D13: =IFERROR(VLOOKUP(H13,'[1]Consolidado MP Planta'!$A$2:$M$823,13,0),"") | E13: =IFERROR(VLOOKUP(H13,'[1]Consolidado MP Planta'!$A$2:$M$823,12,0),"") | F13: =IFERROR(C13*E13,"") | G13: =IFERROR(F13/$F$66,"")
B14: =IFERROR(VLOOKUP(H14,'[1]Consolidado MP Planta'!$A$2:$M$823,3,0),"") | C14: =+A14 -> 0 | D14: =IFERROR(VLOOKUP(H14,'[1]Consolidado MP Planta'!$A$2:$M$823,13,0),"") | E14: =IFERROR(VLOOKUP(H14,'[1]Consolidado MP Planta'!$A$2:$M$823,12,0),"") | F14: =IFERROR(C14*E14,"") | G14: =IFERROR(F14/$F$66,"")
B15: =IFERROR(VLOOKUP(H15,'[2]ARTICULOS MP PLANTA'!$A$2:$G$589,2,0),"")
A16: UNIDADES | B16: MATERIA PRIMA SEMIELABORADOS | C16: UNIDADES | D16: UND MEDIDA | E16: COSTO UNITARIO | F16: TOTAL COSTO | G16: % PREC. DEFINIDO | H16: CODIGOS
A17: 1 | B17: Rosquete nucleo vainilla Dawn redondo 260g | C17: =+A17 -> 1 | D17: UND | E17: 522.51 | F17: =IFERROR(E17*C17,"") -> 522.51 | G17: =IFERROR(F17/$F$66,"") -> 0.17672991 | H17: SE00611
A18: 150 | B18: GANACHE DE PISTACHO | C18: =+A18 -> 150 | D18: Gramos | E18: =+'Costo Ganache '!E69 -> 4.590292 | F18: =IFERROR(E18*C18,"") -> 688.5438 | G18: =IFERROR(F18/$F$66,"") -> 0.23288796 | H18: Nuevo
A19: 140 | B19: LECHES PASTEURIZADA CON AGUA | C19: =+A19 -> 140 | D19: Gramos | E19: 1.1 | F19: =IFERROR(E19*C19,"") -> 154 | G19: =IFERROR(F19/$F$66,"") -> 0.05208782 | H19: SE00254
A20: 240 | B20: MOUSSE PISTACHO | C20: =+A20 -> 240 | D20: Gramos | E20: =+'[3]Costo Mousse Pistacho'!$E$69 -> 4.408044 | F20: =IFERROR(E20*C20,"") -> 1057.9306 | G20: =IFERROR(F20/$F$66,"") -> 0.3578266 | H20: Nuevo
A21: 40 | B21: CARAMELO CON CHOCOLATE BLANCO | C21: =+A21 -> 40 | D21: Gramos | E21: 2.33 | F21: =IFERROR(E21*C21,"") -> 93.2 | G21: =IFERROR(F21/$F$66,"") -> 0.031523278 | H21: SE00682
A22: 0.1 | B22: ROSQUETE TURRON DE ALMENDRA | C22: =+A22 -> 0.1 | D22: UND | E22: 761.63 | F22: =IFERROR(E22*C22,"") -> 76.163 | G22: =IFERROR(F22/$F$66,"") -> 0.025760809 | H22: SE00509
B23: =IFERROR(VLOOKUP(H23,[1]SEMIELABORADOS!$A$2:$M$6000,2,0),"") | C23: =+A23 -> 0 | D23: =IFERROR(VLOOKUP(H23,[1]SEMIELABORADOS!$A$2:$M$6000,6,0),"") | E23: =IFERROR(VLOOKUP(H23,[1]SEMIELABORADOS!$A$2:$H$65536,8,0),"") | F23: =IFERROR(E23*C23,"") | G23: =IFERROR(F23/$F$66,"")
B24: =IFERROR(VLOOKUP(H24,[1]SEMIELABORADOS!$A$2:$M$6000,2,0),"") | C24: =+A24 -> 0 | D24: =IFERROR(VLOOKUP(H24,[1]SEMIELABORADOS!$A$2:$M$6000,6,0),"") | E24: =IFERROR(VLOOKUP(H24,[1]SEMIELABORADOS!$A$2:$H$65536,8,0),"") | F24: =IFERROR(E24*C24,"") | G24: =IFERROR(F24/$F$66,"")
A26: UNIDADES | B26: EMPAQUE | C26: UNIDADES | D26: UND MEDIDA | E26: COSTO UNITARIO | F26: TOTAL COSTO | G26: % PREC. DEFINIDO | H26: CODIGOS
A27: 0 | B27: =IFERROR(VLOOKUP(H27,'[1]Consolidado MP Planta'!$A$2:$M$823,3,0),"") | C27: =+A27 -> 0 | D27: =IFERROR(VLOOKUP(H27,'[1]Consolidado MP Planta'!$A$2:$M$823,13,0),"") | E27: =IFERROR(VLOOKUP(H27,'[1]Consolidado MP Planta'!$A$2:$M$823,12,0),"") | F27: =IFERROR(C27*E27,"") | G27: =IFERROR(F27/$F$66,"")
B28: =IFERROR(VLOOKUP(H28,'[1]Consolidado MP Planta'!$A$2:$M$823,3,0),"") | C28: =+A28 -> 0 | D28: =IFERROR(VLOOKUP(H28,'[1]Consolidado MP Planta'!$A$2:$M$823,13,0),"") | E28: =IFERROR(VLOOKUP(H28,'[1]Consolidado MP Planta'!$A$2:$M$823,12,0),"") | F28: =IFERROR(C28*E28,"") | G28: =IFERROR(F28/$F$66,"")
B29: =IFERROR(VLOOKUP(H29,'[1]Consolidado MP Planta'!$A$2:$M$823,3,0),"") | C29: =+A29 -> 0 | D29: =IFERROR(VLOOKUP(H29,'[1]Consolidado MP Planta'!$A$2:$M$823,13,0),"") | E29: =IFERROR(VLOOKUP(H29,'[1]Consolidado MP Planta'!$A$2:$M$823,12,0),"") | F29: =IFERROR(C29*E29,"") | G29: =IFERROR(F29/$F$66,"")
B30: =IFERROR(VLOOKUP(H30,'[1]Consolidado MP Planta'!$A$2:$M$823,3,0),"") | C30: =+A30 -> 0 | D30: =IFERROR(VLOOKUP(H30,'[1]Consolidado MP Planta'!$A$2:$M$823,13,0),"") | E30: =IFERROR(VLOOKUP(H30,'[1]Consolidado MP Planta'!$A$2:$M$823,12,0),"") | F30: =IFERROR(C30*E30,"") | G30: =IFERROR(F30/$F$66,"")
B31: =IFERROR(VLOOKUP(H31,'[1]Consolidado MP Planta'!$A$2:$M$823,3,0),"") | C31: =+A31 -> 0 | D31: =IFERROR(VLOOKUP(H31,'[1]Consolidado MP Planta'!$A$2:$M$823,13,0),"") | E31: =IFERROR(VLOOKUP(H31,'[1]Consolidado MP Planta'!$A$2:$M$823,12,0),"") | F31: =IFERROR(C31*E31,"") | G31: =IFERROR(F31/$F$66,"")
B32: =IFERROR(VLOOKUP(H32,'[1]Consolidado MP Planta'!$A$2:$M$823,3,0),"") | C32: =+A32 -> 0 | D32: =IFERROR(VLOOKUP(H32,'[1]Consolidado MP Planta'!$A$2:$M$823,13,0),"") | E32: =IFERROR(VLOOKUP(H32,'[1]Consolidado MP Planta'!$A$2:$M$823,12,0),"") | F32: =IFERROR(C32*E32,"") | G32: =IFERROR(F32/$F$66,"")
A34: UNIDADES | B34: EMPAQUE SEMIELABORADOS | C34: UNIDADES | D34: UND MEDIDA | E34: COSTO UNITARIO | F34: TOTAL COSTO | G34: % PREC. DEFINIDO | H34: CODIGOS
A35: =+A17 -> 1 | B35: Rosquete nucleo vainilla Dawn redondo 260g | C35: =+A35 -> 1 | D35: UND | E35: 0.35 | F35: =IFERROR(E35*C35,"") -> 0.35 | G35: =IFERROR(F35/$F$66,"") -> 0.00011838141 | H35: SE00611
A36: =+A18 -> 150 | B36: GANACHE DE PISTACHO | C36: =+A36 -> 150 | D36: Gramos | E36: =+'Costo Ganache '!E76 -> 0 | F36: =IFERROR(E36*C36,"") -> 0 | G36: =IFERROR(F36/$F$66,"") -> 0 | H36: Nuevo
A37: =+A19 -> 140 | B37: LECHES PASTEURIZADA CON AGUA | C37: =+A37 -> 140 | D37: Gramos | E37: 0 | F37: =IFERROR(E37*C37,"") -> 0 | G37: =IFERROR(F37/$F$66,"") -> 0 | H37: SE00254
A38: =+A20 -> 240 | B38: MOUSSE PISTACHO | C38: =+A38 -> 240 | D38: Gramos | E38: =+'[3]Costo Mousse Pistacho'!$E$76 -> 0 | F38: =IFERROR(E38*C38,"") -> 0 | G38: =IFERROR(F38/$F$66,"") -> 0 | H38: Nuevo
A39: =+A21 -> 40 | B39: CARAMELO CON CHOCOLATE BLANCO | C39: =+A39 -> 40 | D39: Gramos | E39: 0.1 | F39: =IFERROR(E39*C39,"") -> 4 | G39: =IFERROR(F39/$F$66,"") -> 0.0013529304
A40: =+A22 -> 0.1 | B40: ROSQUETE TURRON DE ALMENDRA | C40: =+A40 -> 0.1 | D40: UND | E40: 0.01 | F40: =IFERROR(E40*C40,"") -> 0.001 | G40: =IFERROR(F40/$F$66,"") -> 3.382326e-07
A41: =+A23 -> 0 | B41: =IFERROR(VLOOKUP(H41,[1]SEMIELABORADOS!$A$2:$M$6000,2,0),"") | C41: =+A41 -> 0 | D41: =IFERROR(VLOOKUP(H41,[1]SEMIELABORADOS!$A$2:$M$6000,6,0),"") | E41: =IFERROR(VLOOKUP(H41,[1]SEMIELABORADOS!$A$2:$M$65536,10,0),"") | F41: =IFERROR(E41*C41,"") | G41: =IFERROR(F41/$F$66,"")
A43: UNIDADES | B43: MODI | C43: UNIDADES | D43: UND MEDIDA | E43: COSTO UNITARIO | F43: TOTAL COSTO | G43: % PREC. DEFINIDO | H43: CODIGOS
A44: =+A35 -> 1 | B44: Rosquete nucleo vainilla Dawn redondo 260g | C44: =+A44 -> 1 | D44: UND | E44: 20.91 | F44: =IFERROR(E44*C44,"") -> 20.91 | G44: =IFERROR(F44/$F$66,"") -> 0.0070724436 | H44: SE00611
A45: =+A36 -> 150 | B45: GANACHE DE PISTACHO | C45: =+A45 -> 150 | D45: Gramos | E45: =+'Costo Ganache '!E74 -> 0.077 | F45: =IFERROR(E45*C45,"") -> 11.55 | G45: =IFERROR(F45/$F$66,"") -> 0.0039065865 | H45: Nuevo
...

Sheet Ganache de Pistacho
C1: SERVICIOS DE PASTELERIA S.A. | H1: CÓDIGO:
C2: ESPECIFICACION DE RECETA | H2: REVISIÓN:
C3: Ganache De Pistacho | H3: FECHA DE APROBACIÓN:
C4: Elaborado | D4: Mariela Barrantes Sánchez , Chef
C5: Aprobado | D5: Esteban Cartin, Gte Manufactura
A6: AREA QUE PRODUCE: | D6: Cocina | G6: AREA QUE EMPACA: | I6: Empaque
A7: # Código | B7: # Código Netsuite | C7: Descripción del ingrediente | D7: Marca | E7: Unidad Internacional | G7: Medida alternativa | I7: Costo - Referencia
E8: Cantidad | F8: Unidad medida | G8: Cantidad | H8: Unidad medida | I8: Colones
C9: Ensamble
A10: 1210387 | B10: MP10143 | C10: COBERTURA DE CHOCOLATE BLANCO ( PAQ=5 K ) | D10: NACIONAL CH | E10: =800*2.55 -> 2040 | F10: g
A11: 11400031 | B11: MP10048 | C11: CREMA PRESTIGE GRAND | D11: RICH | E11: =1000*2.55 -> 2550 | F11: g
B12: NUEVO | C12: PRALINE DE PISTACHO | E12: =100*2.55 -> 255 | F12: g
B13: NUEVO | C13: SABORIZANTE DE PISTACHO CONCENTRADO | E13: =1*2.55 -> 2.55 | F13: g
B14: NUEVO | C14: Confite Rosanna pistacho | E14: =144*2.55 -> 367.2 | F14: g | G14: 24 ud
C22: Decoración
C28: Empaque
D39: Cantidad | E39: Unidad
A40: PESO TOTAL OBTENIDO | D40: 5000 | E40: g | F40: Tiempo de Horneo:
A41: TIEMPO TOTAL DE PREPARACION | D41: 10 | E41: Minutos | F41: Horno:
A42: CANTIDAD DE PORCIONES OBTENIDAS | D42: 1 | E42: Tanda | F42: Temperatura de Horneo: | J42: =5000/D40 -> 1
A43: PESO DE CADA PORCIÓN | D43: 5000 | E43: g | F43: Otros
A44: MERMA | D44: =SUM(E10:E14)-D40 -> 214.75 | E44: g
A45: PROCEDIMIENTO DE PREPARACION DE LA RECETA
A46: 1, Colocat en una olla, los confites rosanna hasta que derritan (Siempre estar moviendo)
A47: 2, Agregar la crema prestige, el praline de pistacho, y el saborizante hasta que todo se mezcla y comienze a hervir.
A49: 3, Agregar el chocolate en trozos lo más pequeños posibles y mover con un batir globo hasta que todo este completamente derretido.
A50: 4, Retirar, colocar en bandejas y dejar enfriar.
A55: CONTROL DE CAMBIOS

Sheet Ganache de Pistacho 
C1: SERVICIOS DE PASTELERIA S.A. | H1: CÓDIGO: | I1: ESP-RE-COCS-104
C2: ESPECIFICACION DE RECETA | H2: REVISIÓN: | I2: 02
C3: SE00743 Ganache De Pistacho | H3: FECHA DE APROBACIÓN: | I3: 20/08//2025
C4: Elaborado | D4: Mariela Barrantes Sánchez , Chef
C5: Aprobado | D5: Esteban Cartin, Gte Manufactura
A6: AREA QUE PRODUCE: | D6: Cocina | G6: AREA QUE EMPACA: | I6: Empaque
A7: # Código | B7: # Código Netsuite | C7: Descripción del ingrediente | D7: Marca | E7: Unidad Internacional | G7: Medida alternativa | I7: Costo - Referencia
E8: Cantidad | F8: Unidad medida | G8: Cantidad | H8: Unidad medida | I8: Colones
C9: Ensamble
A10: 1210387 | B10: MP10143 | C10: COBERTURA DE CHOCOLATE BLANCO ( PAQ=5 K ) | D10: NACIONAL CH | E10: 4080 | F10: g
A11: 11400031 | B11: MP10048 | C11: CREMA PRESTIGE GRAND | D11: RICH | E11: 5100 | F11: g
B12: MP10776 | C12: PRALINE DE PISTACHO | E12: 480 | F12: g
B13: MP10779 | C13: SABORIZANTE DE PISTACHO CONCENTRADO | E13: 5.1 | F13: g
B14: MP10777 | C14: Confite Rosanna pistacho | E14: 734.4 | F14: g | G14: 122 unidades
C18: Decoración
C24: Empaque
D31: Cantidad | E31: Unidad
A32: PESO TOTAL OBTENIDO | D32: 10000 | E32: g | F32: Tiempo de Horneo:
A33: TIEMPO TOTAL DE PREPARACION | D33: 15 | E33: Minutos | F33: Horno:
A34: CANTIDAD DE PORCIONES OBTENIDAS | D34: 1 | E34: Tanda | F34: Temperatura de Horneo: | J34: 0.5
A35: PESO DE CADA PORCIÓN | D35: 10000 | E35: g | F35: Otros
A36: MERMA | D36: 399.5 | E36: g
A37: PROCEDIMIENTO DE PREPARACION DE LA RECETA
A38: 1, Colocat en una olla, los confites rosanna, la crema prestige, el praline de pistacho y saborizante, hasta que todo este bien incorporado y los confites esten completamente bien derretidos
A39: 2, Una vez que empieze a hervir, agregar el chocolate en trozos lo más pequeños posibles y mover con un batir globo hasta que todo este completamente derretido.
A40: 4, Retirar, colocar en bandejas y dejar enfriar.
A45: CONTROL DE CAMBIOS
A46: 2, Se actualiza procedimiento.

Sheet Costo Ganache 
E1: Precio Local | F1: Costo MP | G1: Costo EM | H1: Costo MO
E2: =IFERROR(O62,"") -> 47312.92 | F2: =IFERROR(H53,"") -> 45902.92 | G2: =IFERROR(H54,"") -> 0 | H2: =IFERROR(H56,"") -> 770
A5: ESTRUCTURA DE COSTOS
F6: Fecha: | H6: =TODAY() -> 45901
A7: UNIDADES | B7: DESCRIPCION MAT.PRIMA | C7: UNIDADES | D7: UND MEDIDA | E7: COSTO UNITARIO | F7: TOTAL COSTO | G7: % PREC. DEFINIDO | H7: CODIGOS
A8: 4080 | B8: =IFERROR(VLOOKUP(H8,'[1]Consolidado MP Planta'!$A$2:$M$823,3,0),"") -> COBERTURA CHOCOLATE BLANCO (PAQ:5 K) | C8: =+A8 -> 4080 | D8: =IFERROR(VLOOKUP(H8,'[1]Consolidado MP Planta'!$A$2:$M$823,13,0),"") -> Gramos | E8: 3.78 | F8: =IFERROR(C8*E8,"") -> 15422.4 | G8: =IFERROR(F8/$F$66,"") -> 0.32406142 | H8: 1210387
A9: 5100 | B9: =IFERROR(VLOOKUP(H9,'[1]Consolidado MP Planta'!$A$2:$M$823,3,0),"") -> CREMA PRESTIGE GRAND (UND:4 K) * | C9: =+A9 -> 5100 | D9: =IFERROR(VLOOKUP(H9,'[1]Consolidado MP Planta'!$A$2:$M$823,13,0),"") -> Gramos | E9: 2.08 | F9: =IFERROR(C9*E9,"") -> 10608 | G9: =IFERROR(F9/$F$66,"") -> 0.22289939 | H9: 11400031
A10: 480 | B10: PRALINE DE PISTACHO | C10: =+A10 -> 480 | D10: Gramos | E10: 34.2 | F10: =IFERROR(C10*E10,"") -> 16416 | G10: =IFERROR(F10/$F$66,"") -> 0.34493933
A11: 5 | B11: SABORIZANTE DE PISTACHO CONCENTRADO | C11: =+A11 -> 5 | D11: Gramos | E11: 5.48 | F11: =IFERROR(C11*E11,"") -> 27.4 | G11: =IFERROR(F11/$F$66,"") -> 0.00057573937
A12: 48 | B12: Confite Rosanna pistacho | C12: =+A12 -> 48 | D12: Gramos | E12: 71.44 | F12: =IFERROR(C12*E12,"") -> 3429.12 | G12: =IFERROR(F12/$F$66,"") -> 0.072053992
B13: =IFERROR(VLOOKUP(H13,'[1]Consolidado MP Planta'!$A$2:$M$823,3,0),"") | C13: =+A13 -> 0 | D13: =IFERROR(VLOOKUP(H13,'[1]Consolidado MP Planta'!$A$2:$M$823,13,0),"") | E13: =IFERROR(VLOOKUP(H13,'[1]Consolidado MP Planta'!$A$2:$M$823,12,0),"") | F13: =IFERROR(C13*E13,"") | G13: =IFERROR(F13/$F$66,"")
B14: =IFERROR(VLOOKUP(H14,'[1]Consolidado MP Planta'!$A$2:$M$823,3,0),"") | C14: =+A14 -> 0 | D14: =IFERROR(VLOOKUP(H14,'[1]Consolidado MP Planta'!$A$2:$M$823,13,0),"") | E14: =IFERROR(VLOOKUP(H14,'[1]Consolidado MP Planta'!$A$2:$M$823,12,0),"") | F14: =IFERROR(C14*E14,"") | G14: =IFERROR(F14/$F$66,"")
B15: =IFERROR(VLOOKUP(H15,'[2]ARTICULOS MP PLANTA'!$A$2:$G$589,2,0),"")
A16: UNIDADES | B16: MATERIA PRIMA SEMIELABORADOS | C16: UNIDADES | D16: UND MEDIDA | E16: COSTO UNITARIO | F16: TOTAL COSTO | G16: % PREC. DEFINIDO | H16: CODIGOS
B17: =IFERROR(VLOOKUP(H17,[1]SEMIELABORADOS!$A$2:$M$6000,2,0),"") | C17: =+A17 -> 0 | D17: =IFERROR(VLOOKUP(H17,[1]SEMIELABORADOS!$A$2:$M$6000,6,0),"") | E17: =IFERROR(VLOOKUP(H17,[1]SEMIELABORADOS!$A$2:$H$65536,8,0),"") | F17: =IFERROR(E17*C17,"") | G17: =IFERROR(F17/$F$66,"")
B18: =IFERROR(VLOOKUP(H18,[1]SEMIELABORADOS!$A$2:$M$6000,2,0),"") | C18: =+A18 -> 0 | D18: =IFERROR(VLOOKUP(H18,[1]SEMIELABORADOS!$A$2:$M$6000,6,0),"") | E18: =IFERROR(VLOOKUP(H18,[1]SEMIELABORADOS!$A$2:$H$65536,8,0),"") | F18: =IFERROR(E18*C18,"") | G18: =IFERROR(F18/$F$66,"")
B19: =IFERROR(VLOOKUP(H19,[1]SEMIELABORADOS!$A$2:$M$6000,2,0),"") | C19: =+A19 -> 0 | D19: =IFERROR(VLOOKUP(H19,[1]SEMIELABORADOS!$A$2:$M$6000,6,0),"") | E19: =IFERROR(VLOOKUP(H19,[1]SEMIELABORADOS!$A$2:$H$65536,8,0),"") | F19: =IFERROR(E19*C19,"") | G19: =IFERROR(F19/$F$66,"")
B20: =IFERROR(VLOOKUP(H20,[1]SEMIELABORADOS!$A$2:$M$6000,2,0),"") | C20: =+A20 -> 0 | D20: =IFERROR(VLOOKUP(H20,[1]SEMIELABORADOS!$A$2:$M$6000,6,0),"") | E20: =IFERROR(VLOOKUP(H20,[1]SEMIELABORADOS!$A$2:$H$65536,8,0),"") | F20: =IFERROR(E20*C20,"") | G20: =IFERROR(F20/$F$66,"")
B21: =IFERROR(VLOOKUP(H21,[1]SEMIELABORADOS!$A$2:$M$6000,2,0),"") | C21: =+A21 -> 0 | D21: =IFERROR(VLOOKUP(H21,[1]SEMIELABORADOS!$A$2:$M$6000,6,0),"") | E21: =IFERROR(VLOOKUP(H21,[1]SEMIELABORADOS!$A$2:$H$65536,8,0),"") | F21: =IFERROR(E21*C21,"") | G21: =IFERROR(F21/$F$66,"")
B22: =IFERROR(VLOOKUP(H22,[1]SEMIELABORADOS!$A$2:$M$6000,2,0),"") | C22: =+A22 -> 0 | D22: =IFERROR(VLOOKUP(H22,[1]SEMIELABORADOS!$A$2:$M$6000,6,0),"") | E22: =IFERROR(VLOOKUP(H22,[1]SEMIELABORADOS!$A$2:$H$65536,8,0),"") | F22: =IFERROR(E22*C22,"") | G22: =IFERROR(F22/$F$66,"")
B23: =IFERROR(VLOOKUP(H23,[1]SEMIELABORADOS!$A$2:$M$6000,2,0),"") | C23: =+A23 -> 0 | D23: =IFERROR(VLOOKUP(H23,[1]SEMIELABORADOS!$A$2:$M$6000,6,0),"") | E23: =IFERROR(VLOOKUP(H23,[1]SEMIELABORADOS!$A$2:$H$65536,8,0),"") | F23: =IFERROR(E23*C23,"") | G23: =IFERROR(F23/$F$66,"")
B24: =IFERROR(VLOOKUP(H24,[1]SEMIELABORADOS!$A$2:$M$6000,2,0),"") | C24: =+A24 -> 0 | D24: =IFERROR(VLOOKUP(H24,[1]SEMIELABORADOS!$A$2:$M$6000,6,0),"") | E24: =IFERROR(VLOOKUP(H24,[1]SEMIELABORADOS!$A$2:$H$65536,8,0),"") | F24: =IFERROR(E24*C24,"") | G24: =IFERROR(F24/$F$66,"")
A26: UNIDADES | B26: EMPAQUE | C26: UNIDADES | D26: UND MEDIDA | E26: COSTO UNITARIO | F26: TOTAL COSTO | G26: % PREC. DEFINIDO | H26: CODIGOS
A27: 0 | B27: =IFERROR(VLOOKUP(H27,'[1]Consolidado MP Planta'!$A$2:$M$823,3,0),"") | C27: =+A27 -> 0 | D27: =IFERROR(VLOOKUP(H27,'[1]Consolidado MP Planta'!$A$2:$M$823,13,0),"") | E27: =IFERROR(VLOOKUP(H27,'[1]Consolidado MP Planta'!$A$2:$M$823,12,0),"") | F27: =IFERROR(C27*E27,"") | G27: =IFERROR(F27/$F$66,"")
B28: =IFERROR(VLOOKUP(H28,'[1]Consolidado MP Planta'!$A$2:$M$823,3,0),"") | C28: =+A28 -> 0 | D28: =IFERROR(VLOOKUP(H28,'[1]Consolidado MP Planta'!$A$2:$M$823,13,0),"") | E28: =IFERROR(VLOOKUP(H28,'[1]Consolidado MP Planta'!$A$2:$M$823,12,0),"") | F28: =IFERROR(C28*E28,"") | G28: =IFERROR(F28/$F$66,"")
B29: =IFERROR(VLOOKUP(H29,'[1]Consolidado MP Planta'!$A$2:$M$823,3,0),"") | C29: =+A29 -> 0 | D29: =IFERROR(VLOOKUP(H29,'[1]Consolidado MP Planta'!$A$2:$M$823,13,0),"") | E29: =IFERROR(VLOOKUP(H29,'[1]Consolidado MP Planta'!$A$2:$M$823,12,0),"") | F29: =IFERROR(C29*E29,"") | G29: =IFERROR(F29/$F$66,"")
B30: =IFERROR(VLOOKUP(H30,'[1]Consolidado MP Planta'!$A$2:$M$823,3,0),"") | C30: =+A30 -> 0 | D30: =IFERROR(VLOOKUP(H30,'[1]Consolidado MP Planta'!$A$2:$M$823,13,0),"") | E30: =IFERROR(VLOOKUP(H30,'[1]Consolidado MP Planta'!$A$2:$M$823,12,0),"") | F30: =IFERROR(C30*E30,"") | G30: =IFERROR(F30/$F$66,"")
B31: =IFERROR(VLOOKUP(H31,'[1]Consolidado MP Planta'!$A$2:$M$823,3,0),"") | C31: =+A31 -> 0 | D31: =IFERROR(VLOOKUP(H31,'[1]Consolidado MP Planta'!$A$2:$M$823,13,0),"") | E31: =IFERROR(VLOOKUP(H31,'[1]Consolidado MP Planta'!$A$2:$M$823,12,0),"") | F31: =IFERROR(C31*E31,"") | G31: =IFERROR(F31/$F$66,"")
B32: =IFERROR(VLOOKUP(H32,'[1]Consolidado MP Planta'!$A$2:$M$823,3,0),"") | C32: =+A32 -> 0 | D32: =IFERROR(VLOOKUP(H32,'[1]Consolidado MP Planta'!$A$2:$M$823,13,0),"") | E32: =IFERROR(VLOOKUP(H32,'[1]Consolidado MP Planta'!$A$2:$M$823,12,0),"") | F32: =IFERROR(C32*E32,"") | G32: =IFERROR(F32/$F$66,"")
A34: UNIDADES | B34: EMPAQUE SEMIELABORADOS | C34: UNIDADES | D34: UND MEDIDA | E34: COSTO UNITARIO | F34: TOTAL COSTO | G34: % PREC. DEFINIDO | H34: CODIGOS
A35: =+A17 -> 0 | B35: =IFERROR(VLOOKUP(H35,[1]SEMIELABORADOS!$A$2:$M$6000,2,0),"") | C35: =+A35 -> 0 | D35: =IFERROR(VLOOKUP(H35,[1]SEMIELABORADOS!$A$2:$M$6000,6,0),"") | E35: =IFERROR(VLOOKUP(H35,[1]SEMIELABORADOS!$A$2:$M$65536,10,0),"") | F35: =IFERROR(E35*C35,"") | G35: =IFERROR(F35/$F$66,"")
A36: =+A18 -> 0 | B36: =IFERROR(VLOOKUP(H36,[1]SEMIELABORADOS!$A$2:$M$6000,2,0),"") | C36: =+A36 -> 0 | D36: =IFERROR(VLOOKUP(H36,[1]SEMIELABORADOS!$A$2:$M$6000,6,0),"") | E36: =IFERROR(VLOOKUP(H36,[1]SEMIELABORADOS!$A$2:$M$65536,10,0),"") | F36: =IFERROR(E36*C36,"") | G36: =IFERROR(F36/$F$66,"")
A37: =+A19 -> 0 | B37: =IFERROR(VLOOKUP(H37,[1]SEMIELABORADOS!$A$2:$M$6000,2,0),"") | C37: =+A37 -> 0 | D37: =IFERROR(VLOOKUP(H37,[1]SEMIELABORADOS!$A$2:$M$6000,6,0),"") | E37: =IFERROR(VLOOKUP(H37,[1]SEMIELABORADOS!$A$2:$M$65536,10,0),"") | F37: =IFERROR(E37*C37,"") | G37: =IFERROR(F37/$F$66,"")
A38: =+A20 -> 0 | B38: =IFERROR(VLOOKUP(H38,[1]SEMIELABORADOS!$A$2:$M$6000,2,0),"") | C38: =+A38 -> 0 | D38: =IFERROR(VLOOKUP(H38,[1]SEMIELABORADOS!$A$2:$M$6000,6,0),"") | E38: =IFERROR(VLOOKUP(H38,[1]SEMIELABORADOS!$A$2:$M$65536,10,0),"") | F38: =IFERROR(E38*C38,"") | G38: =IFERROR(F38/$F$66,"")
A39: =+A21 -> 0 | B39: =IFERROR(VLOOKUP(H39,[1]SEMIELABORADOS!$A$2:$M$6000,2,0),"") | C39: =+A39 -> 0 | D39: =IFERROR(VLOOKUP(H39,[1]SEMIELABORADOS!$A$2:$M$6000,6,0),"") | E39: =IFERROR(VLOOKUP(H39,[1]SEMIELABORADOS!$A$2:$M$65536,10,0),"") | F39: =IFERROR(E39*C39,"") | G39: =IFERROR(F39/$F$66,"")
A40: =+A22 -> 0 | B40: =IFERROR(VLOOKUP(H40,[1]SEMIELABORADOS!$A$2:$M$6000,2,0),"") | C40: =+A40 -> 0 | D40: =IFERROR(VLOOKUP(H40,[1]SEMIELABORADOS!$A$2:$M$6000,6,0),"") | E40: =IFERROR(VLOOKUP(H40,[1]SEMIELABORADOS!$A$2:$M$65536,10,0),"") | F40: =IFERROR(E40*C40,"") | G40: =IFERROR(F40/$F$66,"")
A41: =+A23 -> 0 | B41: =IFERROR(VLOOKUP(H41,[1]SEMIELABORADOS!$A$2:$M$6000,2,0),"") | C41: =+A41 -> 0 | D41: =IFERROR(VLOOKUP(H41,[1]SEMIELABORADOS!$A$2:$M$6000,6,0),"") | E41: =IFERROR(VLOOKUP(H41,[1]SEMIELABORADOS!$A$2:$M$65536,10,0),"") | F41: =IFERROR(E41*C41,"") | G41: =IFERROR(F41/$F$66,"")
A43: UNIDADES | B43: MODI | C43: UNIDADES | D43: UND MEDIDA | E43: COSTO UNITARIO | F43: TOTAL COSTO | G43: % PREC. DEFINIDO | H43: CODIGOS
A44: =+A35 -> 0 | B44: =IFERROR(VLOOKUP(H44,[1]SEMIELABORADOS!$A$2:$M$6000,2,0),"") | C44: =+A44 -> 0 | D44: =IFERROR(VLOOKUP(H44,[1]SEMIELABORADOS!$A$2:$M$6000,6,0),"") | E44: =IFERROR(VLOOKUP(H44,[1]SEMIELABORADOS!$A$2:$M$65536,12,0),"") | F44: =IFERROR(E44*C44,"") | G44: =IFERROR(F44/$F$66,"")
A45: =+A36 -> 0 | B45: =IFERROR(VLOOKUP(H45,[1]SEMIELABORADOS!$A$2:$M$6000,2,0),"") | C45: =+A45 -> 0 | D45: =IFERROR(VLOOKUP(H45,[1]SEMIELABORADOS!$A$2:$M$6000,6,0),"") | E45: =IFERROR(VLOOKUP(H45,[1]SEMIELABORADOS!$A$2:$M$65536,12,0),"") | F45: =IFERROR(E45*C45,"") | G45: =IFERROR(F45/$F$66,"")
...
