Workbook

Sheet Hoja5

Sheet Costo ensamble 
E1: Precio Local | F1: Costo MP | G1: Costo EM | H1: Costo MO
E2: =IFERROR(O65,"") -> 6282.8414 | F2: =IFERROR(H56,"") -> 3805.4877 | G2: =IFERROR(H57,"") -> 686.13996 | H2: =IFERROR(H59,"") -> 862.02163
A5: ESTRUCTURA DE COSTOS
F6: Fecha: | H6: =TODAY() -> 46094
A7: UNIDADES | B7: DESCRIPCION MAT.PRIMA | C7: UNIDADES | D7: UND MEDIDA | E7: COSTO UNITARIO | F7: TOTAL COSTO | G7: % PREC. DEFINIDO | H7: CODIGOS
A8: 35 | B8: Brillo Glit | C8: =+A8 -> 35 | D8: Gramos | E8: 3.82 | F8: =IFERROR(C8*E8,"") -> 133.7 | G8: =IFERROR(F8/$F$69,"") -> 0.025792202 | H8: MP10089
B9: =IFERROR(VLOOKUP(H9,'[1]Consolidado MP Planta'!$A$2:$M$823,3,0),"") | C9: =+A9 -> 0 | D9: =IFERROR(VLOOKUP(H9,'[1]Consolidado MP Planta'!$A$2:$M$823,13,0),"") | E9: =IFERROR(VLOOKUP(H9,'[1]Consolidado MP Planta'!$A$2:$M$823,12,0),"") | F9: =IFERROR(C9*E9,"") | G9: =IFERROR(F9/$F$69,"")
B10: =IFERROR(VLOOKUP(H10,'[1]Consolidado MP Planta'!$A$2:$M$823,3,0),"") | C10: =+A10 -> 0 | D10: =IFERROR(VLOOKUP(H10,'[1]Consolidado MP Planta'!$A$2:$M$823,13,0),"") | E10: =IFERROR(VLOOKUP(H10,'[1]Consolidado MP Planta'!$A$2:$M$823,12,0),"") | F10: =IFERROR(C10*E10,"") | G10: =IFERROR(F10/$F$69,"")
B11: =IFERROR(VLOOKUP(H11,'[1]Consolidado MP Planta'!$A$2:$M$823,3,0),"") | C11: =+A11 -> 0 | D11: =IFERROR(VLOOKUP(H11,'[1]Consolidado MP Planta'!$A$2:$M$823,13,0),"") | E11: =IFERROR(VLOOKUP(H11,'[1]Consolidado MP Planta'!$A$2:$M$823,12,0),"") | F11: =IFERROR(C11*E11,"") | G11: =IFERROR(F11/$F$69,"")
B12: =IFERROR(VLOOKUP(H12,'[1]Consolidado MP Planta'!$A$2:$M$823,3,0),"") | C12: =+A12 -> 0 | D12: =IFERROR(VLOOKUP(H12,'[1]Consolidado MP Planta'!$A$2:$M$823,13,0),"") | E12: =IFERROR(VLOOKUP(H12,'[1]Consolidado MP Planta'!$A$2:$M$823,12,0),"") | F12: =IFERROR(C12*E12,"") | G12: =IFERROR(F12/$F$69,"")
B13: =IFERROR(VLOOKUP(H13,'[1]Consolidado MP Planta'!$A$2:$M$823,3,0),"") | C13: =+A13 -> 0 | D13: =IFERROR(VLOOKUP(H13,'[1]Consolidado MP Planta'!$A$2:$M$823,13,0),"") | E13: =IFERROR(VLOOKUP(H13,'[1]Consolidado MP Planta'!$A$2:$M$823,12,0),"") | F13: =IFERROR(C13*E13,"") | G13: =IFERROR(F13/$F$69,"")
B14: =IFERROR(VLOOKUP(H14,'[1]Consolidado MP Planta'!$A$2:$M$823,3,0),"") | C14: =+A14 -> 0 | D14: =IFERROR(VLOOKUP(H14,'[1]Consolidado MP Planta'!$A$2:$M$823,13,0),"") | E14: =IFERROR(VLOOKUP(H14,'[1]Consolidado MP Planta'!$A$2:$M$823,12,0),"") | F14: =IFERROR(C14*E14,"") | G14: =IFERROR(F14/$F$69,"")
B15: =IFERROR(VLOOKUP(H15,[2]Hoja2!$A$2:$G$589,2,0),"")
A16: UNIDADES | B16: MATERIA PRIMA SEMIELABORADOS | C16: UNIDADES | D16: UND MEDIDA | E16: COSTO UNITARIO | F16: TOTAL COSTO | G16: % PREC. DEFINIDO | H16: CODIGOS
A17: 1 | B17: Rosquete nucleo vainilla Dawn redondo 360g | C17: =+A17 -> 1 | D17: UND | E17: 629 | F17: =IFERROR(E17*C17,"") -> 629 | G17: =IFERROR(F17/$F$69,"") -> 0.12134102 | H17: SE00462
A18: 200 | B18: ALMIBAR (KILO) | C18: =+A18 -> 200 | D18: Gramos | E18: 0.2 | F18: =IFERROR(E18*C18,"") -> 40 | G18: =IFERROR(F18/$F$69,"") -> 0.0077164403 | H18: SE00005 | M18: =203.81/1000 -> 0.20381
A19: 150 | B19: TRASVASADO LECHE CONDENSADA COCINADA | C19: =+A19 -> 150 | D19: Gramos | E19: 1.94 | F19: =IFERROR(E19*C19,"") -> 291 | G19: =IFERROR(F19/$F$69,"") -> 0.056137103 | H19: SE00386
A20: 410 | B20: RELLENO DE FRESA FRAMBUESA | C20: =+A20 -> 410 | D20: Gramos | E20: =+'costo Fresa- Frambuesa'!E69 -> 2.469726 | F20: =IFERROR(E20*C20,"") -> 1012.5877 | G20: =IFERROR(F20/$F$69,"") -> 0.19533931 | H20: Nuevo
A21: 170 | B21: CREMA BEIDGE (KILO) | C21: =+A21 -> 170 | D21: Gramos | E21: 2.3 | F21: =IFERROR(E21*C21,"") -> 391 | G21: =IFERROR(F21/$F$69,"") -> 0.075428204 | H21: SE00069
A22: 20 | B22: Salsa Fresa | C22: =+A22 -> 20 | D22: Gramos | E22: 2.08 | F22: =IFERROR(E22*C22,"") -> 41.6 | G22: =IFERROR(F22/$F$69,"") -> 0.0080250979 | H22: SE00025
A23: 225 | B23: SUSPIRO REDONDO 230G | C23: =+A23 -> 225 | D23: Gramos | E23: =+'Costo suspiro'!G70 -> 2.28 | F23: =IFERROR(E23*C23,"") -> 513 | G23: =IFERROR(F23/$F$69,"") -> 0.098963347
A24: 240 | B24: Ganache Chocolate Blanco | C24: =+A24 -> 240 | D24: Gramos | E24: 3.14 | F24: =IFERROR(E24*C24,"") -> 753.6 | G24: =IFERROR(F24/$F$69,"") -> 0.14537774 | H24: SE00051
A26: UNIDADES | B26: EMPAQUE | C26: UNIDADES | D26: UND MEDIDA | E26: COSTO UNITARIO | F26: TOTAL COSTO | G26: % PREC. DEFINIDO | H26: CODIGOS
A27: 1 | B27: =IFERROR(VLOOKUP(H27,'[1]Consolidado MP Planta'!$A$2:$M$823,3,0),"") -> QUEQUERA RED BASE/DOMO 10 (CAJA:50) | C27: =+A27 -> 1 | D27: =IFERROR(VLOOKUP(H27,'[1]Consolidado MP Planta'!$A$2:$M$823,13,0),"") -> UND | E27: 410 | F27: =IFERROR(C27*E27,"") -> 410 | G27: =IFERROR(F27/$F$69,"") -> 0.079093513 | H27: 121603
A28: 1 | B28: =IFERROR(VLOOKUP(H28,'[1]Consolidado MP Planta'!$A$2:$M$823,3,0),"") -> ORLA CARTON 10" DORADA (UND) | C28: =+A28 -> 1 | D28: =IFERROR(VLOOKUP(H28,'[1]Consolidado MP Planta'!$A$2:$M$823,13,0),"") -> Und | E28: =IFERROR(VLOOKUP(H28,'[1]Consolidado MP Planta'!$A$2:$M$823,12,0),"") -> 137 | F28: =IFERROR(C28*E28,"") -> 137 | G28: =IFERROR(F28/$F$69,"") -> 0.026428808 | H28: 1950692
A29: 1 | B29: =IFERROR(VLOOKUP(H29,'[1]Consolidado MP Planta'!$A$2:$M$823,3,0),"") -> ETIQUETA BLANCA R-153 (UND) | C29: =+A29 -> 1 | D29: =IFERROR(VLOOKUP(H29,'[1]Consolidado MP Planta'!$A$2:$M$823,13,0),"") -> Und | E29: =IFERROR(VLOOKUP(H29,'[1]Consolidado MP Planta'!$A$2:$M$823,12,0),"") -> 0.39 | F29: =IFERROR(C29*E29,"") -> 0.39 | G29: =IFERROR(F29/$F$69,"") -> 7.5235293e-05 | H29: 701096
A30: 1 | B30: =IFERROR(VLOOKUP(H30,'[1]Consolidado MP Planta'!$A$2:$M$823,3,0),"") -> ETIQUETA BLANCA 2 5/8X1 15/16 (UND) | C30: =+A30 -> 1 | D30: =IFERROR(VLOOKUP(H30,'[1]Consolidado MP Planta'!$A$2:$M$823,13,0),"") -> Und | E30: =IFERROR(VLOOKUP(H30,'[1]Consolidado MP Planta'!$A$2:$M$823,12,0),"") -> 2.128 | F30: =IFERROR(C30*E30,"") -> 2.128 | G30: =IFERROR(F30/$F$69,"") -> 0.00041051462 | H30: 0702123
A31: 1 | B31: =IFERROR(VLOOKUP(H31,'[1]Consolidado MP Planta'!$A$2:$M$823,3,0),"") -> ETIQ.BLANCA 1 1/4 * 3/4 (UND) | C31: =+A31 -> 1 | D31: =IFERROR(VLOOKUP(H31,'[1]Consolidado MP Planta'!$A$2:$M$823,13,0),"") -> Und | E31: =IFERROR(VLOOKUP(H31,'[1]Consolidado MP Planta'!$A$2:$M$823,12,0),"") -> 0.58 | F31: =IFERROR(C31*E31,"") -> 0.58 | G31: =IFERROR(F31/$F$69,"") -> 0.00011188838 | H31: 0702069
A32: 1 | B32: ETIQUETA TEMPORADA | C32: =+A32 -> 1 | D32: UND | E32: 100 | F32: =IFERROR(C32*E32,"") -> 100 | G32: =IFERROR(F32/$F$69,"") -> 0.019291101 | H32: NUEVO
B33: =IFERROR(VLOOKUP(H33,'[1]Consolidado MP Planta'!$A$2:$M$823,3,0),"") | C33: =+A33 -> 0 | D33: =IFERROR(VLOOKUP(H33,'[1]Consolidado MP Planta'!$A$2:$M$823,13,0),"") | E33: =IFERROR(VLOOKUP(H33,'[1]Consolidado MP Planta'!$A$2:$M$823,12,0),"") | F33: =IFERROR(C33*E33,"") | G33: =IFERROR(F33/$F$69,"")
A35: UNIDADES | B35: EMPAQUE SEMIELABORADOS | C35: UNIDADES | D35: UND MEDIDA | E35: COSTO UNITARIO | F35: TOTAL COSTO | G35: % PREC. DEFINIDO | H35: CODIGOS
A36: =+A17 -> 1 | B36: Rosquete nucleo vainilla Dawn redondo 360g | C36: =+A36 -> 1 | D36: UND | E36: 6.71 | F36: =IFERROR(E36*C36,"") -> 6.71 | G36: =IFERROR(F36/$F$69,"") -> 0.0012944329 | H36: SE00462
A37: =+A18 -> 200 | B37: ALMIBAR (KILO) | C37: =+A37 -> 200 | D37: Gramos | E37: 0.01 | F37: =IFERROR(E37*C37,"") -> 2 | G37: =IFERROR(F37/$F$69,"") -> 0.00038582201 | H37: SE00005
A38: =+A19 -> 150 | B38: TRASVASADO LECHE CONDENSADA COCINADA | C38: =+A38 -> 150 | D38: Gramos | E38: 0.1 | F38: =IFERROR(E38*C38,"") -> 15 | G38: =IFERROR(F38/$F$69,"") -> 0.0028936651 | H38: SE00386
A39: =+A20 -> 410 | B39: RELLENO DE FRESA FRAMBUESA | C39: =+A39 -> 410 | D39: Gramos | E39: =+'costo Fresa- Frambuesa'!E76 -> 0.00715 | F39: =IFERROR(E39*C39,"") -> 2.9315 | G39: =IFERROR(F39/$F$69,"") -> 0.00056551862 | H39: Nuevo
A40: =+A21 -> 170 | B40: CREMA BEIDGE (KILO) | C40: =+A40 -> 170 | D40: Gramos | E40: 0.01 | F40: =IFERROR(E40*C40,"") -> 1.7 | G40: =IFERROR(F40/$F$69,"") -> 0.00032794871 | H40: SE00069
A41: =+A22 -> 20 | B41: Salsa Fresa | C41: =+A41 -> 20 | D41: Gramos | E41: 0.02 | F41: =IFERROR(E41*C41,"") -> 0.4 | G41: =IFERROR(F41/$F$69,"") -> 7.7164403e-05 | H41: SE00025
A42: =+A23 -> 225 | B42: SUSPIRO REDONDO 230G | C42: =+A42 -> 225 | D42: Gramos | E42: =+'Costo suspiro'!E76 -> 0.011113173 | F42: =IFERROR(E42*C42,"") -> 2.5004638 | G42: =IFERROR(F42/$F$69,"") -> 0.000482367
A43: =+A24 -> 240 | B43: Ganache Chocolate Blanco | C43: =+A43 -> 240 | D43: Gramos | E43: 0.02 | F43: =IFERROR(E43*C43,"") -> 4.8 | G43: =IFERROR(F43/$F$69,"") -> 0.00092597284 | H43: SE00051
A45: UNIDADES | B45: MODI | C45: UNIDADES | D45: UND MEDIDA | E45: COSTO UNITARIO | F45: TOTAL COSTO | G45: % PREC. DEFINIDO | H45: CODIGOS
...

Sheet Rosquete Vainilla Dawn
C1: SERVICIOS DE PASTELERIA S.A. | H1: CÓDIGO: | I1: ESP-RE-BAS-030
C2: ESPECIFICACION DE RECETA | H2: REVISIÓN: | I2: 01
C3: 907000311(SE00462) Rosquete nucleo vainilla Dawn redondo 360g | H3: FECHA DE APROBACIÓN: | I3: 45619
C4: Elaborado | D4: Javier Tong, Chef
C5: Aprobado | D5: Esteban Cartin, Gte Manufactura
A6: AREA QUE PRODUCE: | D6: Batidos | G6: AREA QUE EMPACA: | I6: Batidos
A7: # Código | B7: # Código Netsuite | C7: Descripción del ingrediente | D7: Marca | E7: Unidad Internacional | G7: Medida alternativa | I7: Costo - Referencia
E8: Cantidad | F8: Unidad medida | G8: Cantidad | H8: Unidad medida | I8: Colones
C9: Ensamble
A10: 907000306 | B10: SE00444 | C10: BATIDO NUCLEO VAINILLA DAWN | D10: FAS | E10: 24000 | F10: g
C21: Decoración
C28: Empaque
A29: 902000019 | C29: MEZCLA P/ENGRASE MOLDES KILO | D29: FAS | E29: 650 | F29: g
A30: 1950928 | B30: AS00028 | C30: BOLSA TRANSPARENTE 56X96X1.80 KILO | D30: PLASTICOS P | E30: 6 | F30: ud
A31: 0702007 | B31: EM10004 | C31: ETIQ.FECHA VENCIMIENTO BLANCO (ROLLO) | D31: ETIPLAST | E31: 6 | F31: ud
A32: 702069 | B32: EM10002 | C32: ETIQ.BLANCA 1 1/4 * 3/4 (UND) | D32: CEMUSA | E32: 6 | F32: ud
D38: Cantidad | E38: Unidad
A39: PESO TOTAL OBTENIDO | D39: 23400 | E39: g | F39: Tiempo de Horneo:
A40: TIEMPO TOTAL DE PREPARACION | D40: 14 | E40: Min | F40: Horno:
A41: CANTIDAD DE PORCIONES OBTENIDAS | D41: 65 | E41: ud | F41: Temperatura de Horneo:
A42: PESO DE CADA PORCIÓN | D42: 360 | E42: g | F42: Otros
A43: MERMA | D43: 600 | E43: g
A44: PROCEDIMIENTO DE PREPARACION DE LA RECETA
A45: 1.- Pesar 360g de mezcla en los moldes previamente engrasados.
A46: 2.- Hornear por 31 minutos en el Dicte 1 a 170°C, en el Dicte 2 por 38 minutos a 170°C y en el Marshall por 26 minutos a 175°C.
A47: 3.- Enfriar, desmoldar, colocar 12 rosquetes por lata, etiquetar con nombre y fecha de producción.
A55: CONTROL DE CAMBIOS

Sheet Batido Vainilla Dawn
C1: SERVICIOS DE PASTELERIA S.A. | H1: CÓDIGO: | I1: ESP-RE-BAS-027
C2: ESPECIFICACION DE RECETA | H2: REVISIÓN: | I2: 01
C3: SE00444 Batido Nucleo vainilla Dawn | H3: FECHA DE APROBACIÓN: | I3: 45619
C4: Elaborado | D4: Javier Tong, Chef
C5: Aprobado | D5: Esteban Cartin, Gte Manufactura
A6: AREA QUE PRODUCE: | D6: Batidos | G6: AREA QUE EMPACA: | I6: Batidos
A7: # Código | B7: # Código Netsuite | C7: Descripción del ingrediente | D7: Marca | E7: Unidad Internacional | G7: Medida alternativa | I7: Costo - Referencia
E8: Cantidad | F8: Unidad medida | G8: Cantidad | H8: Unidad medida | I8: Colones
C9: Ensamble
A10: 906000138 | B10: SE00443 | C10: PREMEZCLA BATIDO NUCLEO VAINILLA DAWN | D10: FAS | E10: 14195 | F10: g
A11: 1210482 | B11: MP10005 | C11: HUEVO ENTERO PASTERI INNOVO ( CAJA: 10 K) | D11: INNOVO | E11: 7700 | F11: g
A12: 10415 | C12: AGUA POTABLE (PLANTA) | D12: FAS | E12: 3090 | F12: g
A13: 1212437 | B13: MP10315 | C13: PRESERVANTE MIXTO (UND:17 K) | D13: PURATOS | E13: 390 | F13: g
C21: Decoración
C28: Empaque
D38: Cantidad | E38: Unidad
A39: PESO TOTAL OBTENIDO | D39: 24000 | E39: g | F39: Tiempo de Horneo:
A40: TIEMPO TOTAL DE PREPARACION | D40: 10 | E40: min | F40: Horno:
A41: CANTIDAD DE PORCIONES OBTENIDAS | D41: 1 | E41: Tanda | F41: Temperatura de Horneo:
A42: PESO DE CADA PORCIÓN | D42: 24000 | E42: g | F42: Otros
A43: MERMA | D43: 1375 | E43: g
A44: PROCEDIMIENTO DE PREPARACION DE LA RECETA
A46: 1, Colocar los liquidos en la batidora, posterior agregar los ingredientes secos
A47: 2, Batir por 1 min en velocidad 1. Con paleta
A48: 3, Batir 4 min en velocidad 3. con paleta
A55: CONTROL DE CAMBIOS

Sheet Costo suspiro
E1: Precio Local | F1: Costo MP | G1: Costo EM | H1: Costo MO
E2: =IFERROR(O62,"") -> 24147.418 | F2: =IFERROR(H53,"") -> 20509.8 | G2: =IFERROR(H54,"") -> 119.8 | H2: =IFERROR(H56,"") -> 1692.95
A5: ESTRUCTURA DE COSTOS
F6: Fecha: | H6: =TODAY() -> 46094
A7: UNIDADES | B7: DESCRIPCION MAT.PRIMA | C7: UNIDADES | D7: UND MEDIDA | E7: COSTO UNITARIO | F7: TOTAL COSTO | G7: % PREC. DEFINIDO | H7: CODIGOS
B8: =IFERROR(VLOOKUP(H8,'[1]Consolidado MP Planta'!$A$2:$M$823,3,0),"") | C8: =+A8 -> 0 | D8: =IFERROR(VLOOKUP(H8,'[1]Consolidado MP Planta'!$A$2:$M$823,13,0),"") | E8: =IFERROR(VLOOKUP(H8,'[1]Consolidado MP Planta'!$A$2:$M$823,12,0),"") | F8: =IFERROR(C8*E8,"") | G8: =IFERROR(F8/$F$66,"")
B9: =IFERROR(VLOOKUP(H9,'[1]Consolidado MP Planta'!$A$2:$M$823,3,0),"") | C9: =+A9 -> 0 | D9: =IFERROR(VLOOKUP(H9,'[1]Consolidado MP Planta'!$A$2:$M$823,13,0),"") | E9: =IFERROR(VLOOKUP(H9,'[1]Consolidado MP Planta'!$A$2:$M$823,12,0),"") | F9: =IFERROR(C9*E9,"") | G9: =IFERROR(F9/$F$66,"")
B10: =IFERROR(VLOOKUP(H10,'[1]Consolidado MP Planta'!$A$2:$M$823,3,0),"") | C10: =+A10 -> 0 | D10: =IFERROR(VLOOKUP(H10,'[1]Consolidado MP Planta'!$A$2:$M$823,13,0),"") | E10: =IFERROR(VLOOKUP(H10,'[1]Consolidado MP Planta'!$A$2:$M$823,12,0),"") | F10: =IFERROR(C10*E10,"") | G10: =IFERROR(F10/$F$66,"")
B11: =IFERROR(VLOOKUP(H11,'[1]Consolidado MP Planta'!$A$2:$M$823,3,0),"") | C11: =+A11 -> 0 | D11: =IFERROR(VLOOKUP(H11,'[1]Consolidado MP Planta'!$A$2:$M$823,13,0),"") | E11: =IFERROR(VLOOKUP(H11,'[1]Consolidado MP Planta'!$A$2:$M$823,12,0),"") | F11: =IFERROR(C11*E11,"") | G11: =IFERROR(F11/$F$66,"")
B12: =IFERROR(VLOOKUP(H12,'[1]Consolidado MP Planta'!$A$2:$M$823,3,0),"") | C12: =+A12 -> 0 | D12: =IFERROR(VLOOKUP(H12,'[1]Consolidado MP Planta'!$A$2:$M$823,13,0),"") | E12: =IFERROR(VLOOKUP(H12,'[1]Consolidado MP Planta'!$A$2:$M$823,12,0),"") | F12: =IFERROR(C12*E12,"") | G12: =IFERROR(F12/$F$66,"")
B13: =IFERROR(VLOOKUP(H13,'[1]Consolidado MP Planta'!$A$2:$M$823,3,0),"") | C13: =+A13 -> 0 | D13: =IFERROR(VLOOKUP(H13,'[1]Consolidado MP Planta'!$A$2:$M$823,13,0),"") | E13: =IFERROR(VLOOKUP(H13,'[1]Consolidado MP Planta'!$A$2:$M$823,12,0),"") | F13: =IFERROR(C13*E13,"") | G13: =IFERROR(F13/$F$66,"")
B14: =IFERROR(VLOOKUP(H14,'[1]Consolidado MP Planta'!$A$2:$M$823,3,0),"") | C14: =+A14 -> 0 | D14: =IFERROR(VLOOKUP(H14,'[1]Consolidado MP Planta'!$A$2:$M$823,13,0),"") | E14: =IFERROR(VLOOKUP(H14,'[1]Consolidado MP Planta'!$A$2:$M$823,12,0),"") | F14: =IFERROR(C14*E14,"") | G14: =IFERROR(F14/$F$66,"")
B15: =IFERROR(VLOOKUP(H15,[2]Hoja2!$A$2:$G$589,2,0),"")
A16: UNIDADES | B16: MATERIA PRIMA SEMIELABORADOS | C16: UNIDADES | D16: UND MEDIDA | E16: COSTO UNITARIO | F16: TOTAL COSTO | G16: % PREC. DEFINIDO | H16: CODIGOS
A17: 11250 | B17: MERENGUE P/SUSPIRO DESHIDRATADO KILO | C17: =+A17 -> 11250 | D17: Gramos | E17: 1.79 | F17: =IFERROR(E17*C17,"") -> 20137.5 | G17: =IFERROR(F17/$F$66,"") -> 0.90417046 | H17: SE00022
A18: 365 | B18: MEZCLA P/ENGRASE MOLDES KILO | C18: =+A18 -> 365 | D18: Gramos | E18: 1.02 | F18: =IFERROR(E18*C18,"") -> 372.3 | G18: =IFERROR(F18/$F$66,"") -> 0.016716209
B19: =IFERROR(VLOOKUP(H19,[1]SEMIELABORADOS!$A$2:$M$6000,2,0),"") | C19: =+A19 -> 0 | D19: =IFERROR(VLOOKUP(H19,[1]SEMIELABORADOS!$A$2:$M$6000,6,0),"") | E19: =IFERROR(VLOOKUP(H19,[1]SEMIELABORADOS!$A$2:$H$65536,8,0),"") | F19: =IFERROR(E19*C19,"") | G19: =IFERROR(F19/$F$66,"")
B20: =IFERROR(VLOOKUP(H20,[1]SEMIELABORADOS!$A$2:$M$6000,2,0),"") | C20: =+A20 -> 0 | D20: =IFERROR(VLOOKUP(H20,[1]SEMIELABORADOS!$A$2:$M$6000,6,0),"") | E20: =IFERROR(VLOOKUP(H20,[1]SEMIELABORADOS!$A$2:$H$65536,8,0),"") | F20: =IFERROR(E20*C20,"") | G20: =IFERROR(F20/$F$66,"")
B21: =IFERROR(VLOOKUP(H21,[1]SEMIELABORADOS!$A$2:$M$6000,2,0),"") | C21: =+A21 -> 0 | D21: =IFERROR(VLOOKUP(H21,[1]SEMIELABORADOS!$A$2:$M$6000,6,0),"") | E21: =IFERROR(VLOOKUP(H21,[1]SEMIELABORADOS!$A$2:$H$65536,8,0),"") | F21: =IFERROR(E21*C21,"") | G21: =IFERROR(F21/$F$66,"")
B22: =IFERROR(VLOOKUP(H22,[1]SEMIELABORADOS!$A$2:$M$6000,2,0),"") | C22: =+A22 -> 0 | D22: =IFERROR(VLOOKUP(H22,[1]SEMIELABORADOS!$A$2:$M$6000,6,0),"") | E22: =IFERROR(VLOOKUP(H22,[1]SEMIELABORADOS!$A$2:$H$65536,8,0),"") | F22: =IFERROR(E22*C22,"") | G22: =IFERROR(F22/$F$66,"")
B23: =IFERROR(VLOOKUP(H23,[1]SEMIELABORADOS!$A$2:$M$6000,2,0),"") | C23: =+A23 -> 0 | D23: =IFERROR(VLOOKUP(H23,[1]SEMIELABORADOS!$A$2:$M$6000,6,0),"") | E23: =IFERROR(VLOOKUP(H23,[1]SEMIELABORADOS!$A$2:$H$65536,8,0),"") | F23: =IFERROR(E23*C23,"") | G23: =IFERROR(F23/$F$66,"")
B24: =IFERROR(VLOOKUP(H24,[1]SEMIELABORADOS!$A$2:$M$6000,2,0),"") | C24: =+A24 -> 0 | D24: =IFERROR(VLOOKUP(H24,[1]SEMIELABORADOS!$A$2:$M$6000,6,0),"") | E24: =IFERROR(VLOOKUP(H24,[1]SEMIELABORADOS!$A$2:$H$65536,8,0),"") | F24: =IFERROR(E24*C24,"") | G24: =IFERROR(F24/$F$66,"")
A26: UNIDADES | B26: EMPAQUE | C26: UNIDADES | D26: UND MEDIDA | E26: COSTO UNITARIO | F26: TOTAL COSTO | G26: % PREC. DEFINIDO | H26: CODIGOS
A27: 0 | B27: =IFERROR(VLOOKUP(H27,'[1]Consolidado MP Planta'!$A$2:$M$823,3,0),"") | C27: =+A27 -> 0 | D27: =IFERROR(VLOOKUP(H27,'[1]Consolidado MP Planta'!$A$2:$M$823,13,0),"") | E27: =IFERROR(VLOOKUP(H27,'[1]Consolidado MP Planta'!$A$2:$M$823,12,0),"") | F27: =IFERROR(C27*E27,"") | G27: =IFERROR(F27/$F$66,"")
B28: =IFERROR(VLOOKUP(H28,'[1]Consolidado MP Planta'!$A$2:$M$823,3,0),"") | C28: =+A28 -> 0 | D28: =IFERROR(VLOOKUP(H28,'[1]Consolidado MP Planta'!$A$2:$M$823,13,0),"") | E28: =IFERROR(VLOOKUP(H28,'[1]Consolidado MP Planta'!$A$2:$M$823,12,0),"") | F28: =IFERROR(C28*E28,"") | G28: =IFERROR(F28/$F$66,"")
B29: =IFERROR(VLOOKUP(H29,'[1]Consolidado MP Planta'!$A$2:$M$823,3,0),"") | C29: =+A29 -> 0 | D29: =IFERROR(VLOOKUP(H29,'[1]Consolidado MP Planta'!$A$2:$M$823,13,0),"") | E29: =IFERROR(VLOOKUP(H29,'[1]Consolidado MP Planta'!$A$2:$M$823,12,0),"") | F29: =IFERROR(C29*E29,"") | G29: =IFERROR(F29/$F$66,"")
B30: =IFERROR(VLOOKUP(H30,'[1]Consolidado MP Planta'!$A$2:$M$823,3,0),"") | C30: =+A30 -> 0 | D30: =IFERROR(VLOOKUP(H30,'[1]Consolidado MP Planta'!$A$2:$M$823,13,0),"") | E30: =IFERROR(VLOOKUP(H30,'[1]Consolidado MP Planta'!$A$2:$M$823,12,0),"") | F30: =IFERROR(C30*E30,"") | G30: =IFERROR(F30/$F$66,"")
B31: =IFERROR(VLOOKUP(H31,'[1]Consolidado MP Planta'!$A$2:$M$823,3,0),"") | C31: =+A31 -> 0 | D31: =IFERROR(VLOOKUP(H31,'[1]Consolidado MP Planta'!$A$2:$M$823,13,0),"") | E31: =IFERROR(VLOOKUP(H31,'[1]Consolidado MP Planta'!$A$2:$M$823,12,0),"") | F31: =IFERROR(C31*E31,"") | G31: =IFERROR(F31/$F$66,"")
B32: =IFERROR(VLOOKUP(H32,'[1]Consolidado MP Planta'!$A$2:$M$823,3,0),"") | C32: =+A32 -> 0 | D32: =IFERROR(VLOOKUP(H32,'[1]Consolidado MP Planta'!$A$2:$M$823,13,0),"") | E32: =IFERROR(VLOOKUP(H32,'[1]Consolidado MP Planta'!$A$2:$M$823,12,0),"") | F32: =IFERROR(C32*E32,"") | G32: =IFERROR(F32/$F$66,"")
A34: UNIDADES | B34: EMPAQUE SEMIELABORADOS | C34: UNIDADES | D34: UND MEDIDA | E34: COSTO UNITARIO | F34: TOTAL COSTO | G34: % PREC. DEFINIDO | H34: CODIGOS
A35: =+A17 -> 11250 | B35: MERENGUE P/SUSPIRO DESHIDRATADO KILO | C35: =+A35 -> 11250 | D35: Gramos | E35: 0.01 | F35: =IFERROR(E35*C35,"") -> 112.5 | G35: =IFERROR(F35/$F$66,"") -> 0.0050512316 | H35: SE00022
A36: =+A18 -> 365 | B36: MEZCLA P/ENGRASE MOLDES KILO | C36: =+A36 -> 365 | D36: Gramos | E36: 0.02 | F36: =IFERROR(E36*C36,"") -> 7.3 | G36: =IFERROR(F36/$F$66,"") -> 0.00032776881
A37: =+A19 -> 0 | B37: =IFERROR(VLOOKUP(H37,[1]SEMIELABORADOS!$A$2:$M$6000,2,0),"") | C37: =+A37 -> 0 | D37: =IFERROR(VLOOKUP(H37,[1]SEMIELABORADOS!$A$2:$M$6000,6,0),"") | E37: =IFERROR(VLOOKUP(H37,[1]SEMIELABORADOS!$A$2:$M$65536,10,0),"") | F37: =IFERROR(E37*C37,"") | G37: =IFERROR(F37/$F$66,"")
A38: =+A20 -> 0 | B38: =IFERROR(VLOOKUP(H38,[1]SEMIELABORADOS!$A$2:$M$6000,2,0),"") | C38: =+A38 -> 0 | D38: =IFERROR(VLOOKUP(H38,[1]SEMIELABORADOS!$A$2:$M$6000,6,0),"") | E38: =IFERROR(VLOOKUP(H38,[1]SEMIELABORADOS!$A$2:$M$65536,10,0),"") | F38: =IFERROR(E38*C38,"") | G38: =IFERROR(F38/$F$66,"")
A39: =+A21 -> 0 | B39: =IFERROR(VLOOKUP(H39,[1]SEMIELABORADOS!$A$2:$M$6000,2,0),"") | C39: =+A39 -> 0 | D39: =IFERROR(VLOOKUP(H39,[1]SEMIELABORADOS!$A$2:$M$6000,6,0),"") | E39: =IFERROR(VLOOKUP(H39,[1]SEMIELABORADOS!$A$2:$M$65536,10,0),"") | F39: =IFERROR(E39*C39,"") | G39: =IFERROR(F39/$F$66,"")
A40: =+A22 -> 0 | B40: =IFERROR(VLOOKUP(H40,[1]SEMIELABORADOS!$A$2:$M$6000,2,0),"") | C40: =+A40 -> 0 | D40: =IFERROR(VLOOKUP(H40,[1]SEMIELABORADOS!$A$2:$M$6000,6,0),"") | E40: =IFERROR(VLOOKUP(H40,[1]SEMIELABORADOS!$A$2:$M$65536,10,0),"") | F40: =IFERROR(E40*C40,"") | G40: =IFERROR(F40/$F$66,"")
A41: =+A23 -> 0 | B41: =IFERROR(VLOOKUP(H41,[1]SEMIELABORADOS!$A$2:$M$6000,2,0),"") | C41: =+A41 -> 0 | D41: =IFERROR(VLOOKUP(H41,[1]SEMIELABORADOS!$A$2:$M$6000,6,0),"") | E41: =IFERROR(VLOOKUP(H41,[1]SEMIELABORADOS!$A$2:$M$65536,10,0),"") | F41: =IFERROR(E41*C41,"") | G41: =IFERROR(F41/$F$66,"")
A43: UNIDADES | B43: MODI | C43: UNIDADES | D43: UND MEDIDA | E43: COSTO UNITARIO | F43: TOTAL COSTO | G43: % PREC. DEFINIDO | H43: CODIGOS
A44: =+A35 -> 11250 | B44: MERENGUE P/SUSPIRO DESHIDRATADO KILO | C44: =+A44 -> 11250 | D44: Gramos | E44: 0.04 | F44: =IFERROR(E44*C44,"") -> 450 | G44: =IFERROR(F44/$F$66,"") -> 0.020204926 | H44: SE00022
A45: =+A36 -> 365 | B45: MEZCLA P/ENGRASE MOLDES KILO | C45: =+A45 -> 365 | D45: Gramos | E45: 0.03 | F45: =IFERROR(E45*C45,"") -> 10.95 | G45: =IFERROR(F45/$F$66,"") -> 0.00049165321
...

Sheet Trasvasado Leche Condensada 
C1: SERVICIOS DE PASTELERIA S.A. | H1: CÓDIGO: | I1: ESP-RE-COCS-058
C2: ESPECIFICACION DE RECETA | H2: REVISIÓN: | I2: 01
C3: SE00386 TRASVASADO LECHE CONDENSADA COCINADA | H3: FECHA DE APROBACIÓN: | I3: 45609
C4: Elaborado | D4: Javier Tong, Chef
C5: Aprobado | D5: Esteban Cartin, Gte Manufactura
A6: AREA QUE PRODUCE: | D6: Cocina | G6: AREA QUE EMPACA: | I6: Cocina
A7: # Código | B7: # Código Netsuite | C7: Descripción del ingrediente | D7: Marca | E7: Unidad Internacional | G7: Medida alternativa | I7: Costo - Referencia
E8: Cantidad | F8: Unidad medida | G8: Cantidad | H8: Unidad medida | I8: Colones
C9: Ensamble
A10: 90100409 | B10: SE00572 | C10: LECHE CONDENSADA COCINADA DURA | D10: FAS | E10: 43 | F10: Latas | G10: =+E10*395 -> 16985 | H10: GRAMOS
C27: Decoración
C33: Empaque
A34: 702123 | B34: EM10011 | C34: ETIQUETA BLANCA 2 5/8X1 15/16 (UND) | D34: ETIPLAST | E34: 4 | F34: ud
A35: 51600050 | B35: EM10307 | C35: BOLSA MARMITA 14 x 20 (KILO) | E35: 4 | F35: ud
D44: Cantidad | E44: Unidad
A45: PESO TOTAL OBTENIDO | D45: 16000 | E45: g | F45: Tiempo de Horneo:
A46: TIEMPO TOTAL DE PREPARACION | D46: 15 | E46: min | F46: Horno:
A47: CANTIDAD DE PORCIONES OBTENIDAS | D47: 4 | E47: bolsas | F47: Temperatura de Horneo:
A48: PESO DE CADA PORCIÓN | D48: 4000 | E48: g | F48: Otros
A49: MERMA | D49: 985 | E49: g
A50: PROCEDIMIENTO DE PREPARACION DE LA RECETA
A51: 1, Abril las latas de leche condensada y con ayuda de una espatula colocar el contenido en bolsas de 4 kg.
A52: 2, hacer nudo y etiquetar
A53: =D46/D45 -> 0.0009375
A62: CONTROL DE CAMBIOS

Sheet Leche condensada cocinada 
C1: SERVICIOS DE PASTELERIA S.A. | H1: CÓDIGO: | I1: ESP-RE-COCS-066
C2: ESPECIFICACION DE RECETA | H2: REVISIÓN: | I2: 01
C3: 90100409 (SE00572) Leche condensada cocinada Dura | H3: FECHA DE APROBACIÓN: | I3: 45609
C4: Elaborado | D4: Javier Tong, Chef
C5: Aprobado | D5: Esteban Cartin, Gte Manufactura
A6: AREA QUE PRODUCE: | D6: Cocina | G6: AREA QUE EMPACA: | I6: Empaque
A7: # Código | B7: # Código Netsuite | C7: Descripción del ingrediente | D7: Marca | E7: Unidad Internacional | G7: Medida alternativa | I7: Costo - Referencia
E8: Cantidad | F8: Unidad medida | G8: Cantidad | H8: Unidad medida | I8: Colones
C9: Ensamble
A10: 505605 | B10: MP10477 | C10: LATA LECHE CONDENSADA | D10: NESTLE | E10: 204 | F10: ud
A11: 10415 | C11: AGUA POTABLE (PLANTA) | D11: FAS | E11: 60000 | F11: g
C27: Decoración
C33: Empaque
A34: 702069 | B34: EM10002 | C34: ETIQ.BLANCA 1 1/4 * 3/4 (UND) | E34: 208 | F34: ud
D44: Cantidad | E44: Unidad
A45: PESO TOTAL OBTENIDO | D45: 80580 | E45: ud | F45: Tiempo de Horneo:
A46: TIEMPO TOTAL DE PREPARACION | D46: 75 | E46: min | F46: Horno:
A47: CANTIDAD DE PORCIONES OBTENIDAS | D47: 4.25 | E47: cajas | F47: Temperatura de Horneo:
A48: PESO DE CADA PORCIÓN | D48: 18960 | E48: g | F48: Otros
A49: MERMA | D49: 60000 | E49: g
A50: PROCEDIMIENTO DE PREPARACION DE LA RECETA
A51: 1, Retirar las etiquetas de cada lata de leche condensada
A52: 2, Colocar las latas en la marmita (sin aspas). Cerrar a presion.
A53: #, Cocinar en programa "Leche Cocinada dura"
A54: 4, Retirar con mucho cuidado el tapon para liberar presion. Luego que ya este liberada toda la presion, proceder a abrir la olla.
A55: 5, Con ayuda de una pinza o guantes colocar las latas en una caja esperar a que se sequen, Etiquetar con fecha de vencimiento.
A56: 6, Empacar en las mismas cajas en las que llegaron y etiquetar con fecha de vencimeinto la caja tambien
A62: CONTROL DE CAMBIOS

Sheet Ganache Chocolate Blanco
C1: SERVICIOS DE PASTELERIA S.A. | H1: CÓDIGO: | I1: ESP-RE-COCS-025
C2: ESPECIFICACION DE RECETA | H2: REVISIÓN: | I2: 01
C3: Ganache De Chocolate Blanco 37380g SE00051 | H3: FECHA DE APROBACIÓN: | I3: 45609
C4: Elaborado | D4: Javier Tong, Chef
C5: Aprobado | D5: Esteban Cartin, Gte Manufactura
A6: AREA QUE PRODUCE: | D6: Cocina | G6: AREA QUE EMPACA: | I6: Cocina
A7: # Código | B7: # Código Netsuite | C7: Descripción del ingrediente | D7: Marca | E7: Unidad Internacional | G7: Medida alternativa | I7: Costo - Referencia
E8: Cantidad | F8: Unidad medida | G8: Cantidad | H8: Unidad medida | I8: Colones
C9: Ensamble
A10: 1210387 | B10: MP10143 | C10: COBERTURA DE CHOCOLATE BLANCO ( PAQ=5 K ) | D10: NACIONAL CH | E10: 20000
A11: 11400031 | B11: MP10048 | C11: CREMA PRESTIGE GRAND | D11: RICH | E11: 20000
C29: Decoración
C35: Empaque
D46: Cantidad | E46: Unidad
A47: PESO TOTAL OBTENIDO | D47: 37380 | E47: g | F47: Tiempo de Horneo:
A48: TIEMPO TOTAL DE PREPARACION | D48: 25 | E48: Minutos | F48: Horno:
A49: CANTIDAD DE PORCIONES OBTENIDAS | D49: 1 | E49: Tanda | F49: Temperatura de Horneo:
A50: PESO DE CADA PORCIÓN | D50: 37380 | E50: g | F50: Otros
A51: MERMA | D51: 2620 | E51: g
A52: PROCEDIMIENTO DE PREPARACION DE LA RECETA
A53: 1.- Colocar la crema en una olla llegar a 65 grados , mover, no hervir, agregar los trozos de chocolate y mover hasta que se derritan.
A54: 2.- Mezclar bien, con cuidado de no quemar,cuando este todo derretido, mezlcar con ayuda de un batidor de globo de mano, para asegurarse que no queden grumos
A56: 3.- Colocar en bandejas, enfriar.
A62: CONTROL DE CAMBIOS

Sheet Crema Beidge 
C1: SERVICIOS DE PASTELERIA S.A. | H1: CÓDIGO: | I1: ESP-RE-DES-021
C2: ESPECIFICACION DE RECETA | H2: REVISIÓN: | I2: 03
C3: Crema Beidge SE00069 | H3: FECHA DE APROBACIÓN: | I3: 45663
C4: Elaborado | D4: Javier Tong, Chef
C5: Aprobado | D5: Esteban Cartin, Gte Manufactura
A6: AREA QUE PRODUCE: | D6: Decoración | G6: AREA QUE EMPACA: | I6: Decoracion
A7: # Código | B7: # Código Netsuite | C7: Descripción del ingrediente | D7: Marca | E7: Unidad Internacional | G7: Medida alternativa | I7: Costo - Referencia
E8: Cantidad | F8: Unidad medida | G8: Cantidad | H8: Unidad medida | I8: Colones
C9: Ensamble
B10: SE00670 | C10: CREMA BLANCA SUPREMO | D10: FAS | E10: =16580/16.58 -> 1000 | F10: g
A11: 10400008 | B11: MP10150 | C11: COLORANTE GEL EGG YELLOW (UND= 130 ML) | D11: MASTER PACK | E11: 0.2 | F11: g
C20: Decoración
C29: Empaque
A30: 0702069 | B30: EM10002 | C30: ETIQ.BLANCA 1 1/4 * 3/4 | D30: ETIPLAST | E30: 1 | F30: ud
D40: Cantidad | E40: Unidad
A41: PESO TOTAL OBTENIDO | D41: 1000 | E41: g | F41: Tiempo de Horneo:
A42: TIEMPO TOTAL DE PREPARACION | D42: 3 | E42: Min | F42: Horno:
A43: CANTIDAD DE PORCIONES OBTENIDAS | D43: 1 | E43: Tanda | F43: Temperatura de Horneo:
A44: PESO DE CADA PORCIÓN | D44: 1000 | E44: g | F44: Otros
A45: MERMA | D45: =SUM(E10:E11)-D41 -> 0 | E45: g
A46: PROCEDIMIENTO DE PREPARACION DE LA RECETA
A47: 1, Sacar la crema blanca suprema de la camara (temperatura maxima 18° ya batida).
A48: 2, Agregar el colorantes y mezclar a mano, hasta que este completamente homogeneo.
A49: 3, Colocar plastico para tapar y etiquetar.
A50: 4, Volver a guardar en la camara hasta su uso.
A56: CONTROL DE CAMBIOS
A57: 2, Se actualiza procedimiento y tiempo de preparación
A58: 3, Se actualizan datos de receta y pesos finales

Sheet Crema Blanca supremo
C1: SERVICIOS DE PASTELERIA S.A. | H1: CÓDIGO: | I1: ESP-RE-DES-059
C2: ESPECIFICACION DE RECETA | H2: REVISIÓN: | I2: 04
C3: SE00670 Crema Blanca Supremo | H3: FECHA DE APROBACIÓN: | I3: 45659
C4: Elaborado | D4: Javier Tong, Chef
C5: Aprobado | D5: Esteban Cartin, Gte Manufactura
A6: AREA QUE PRODUCE: | D6: Decoracoración | G6: AREA QUE EMPACA: | I6: Decoración
A7: # Código | B7: # Código Netsuite | C7: Descripción del ingrediente | D7: Marca | E7: Unidad Internacional | G7: Medida alternativa | I7: Costo - Referencia
E8: Cantidad | F8: Unidad medida | G8: Cantidad | H8: Unidad medida | I8: Colones
C9: Ensamble
A10: 310148 | B10: MP10047 | C10: BETTERCREME SUPREMO (UND:4 K) | D10: RICHS | E10: 16150 | F10: g | J10: =+E10/$D$39 -> 0.99299053 | K10: =+J10*1000 -> 992.99053
A11: 10415 | C11: AGUA POTABLE (PLANTA) | D11: AYA | E11: 100 | F11: g | J11: =+E11/$D$39 -> 0.0061485482 | K11: =+J11*1000 -> 6.1485482 | L11: =SUM(E10:E13) -> 16264.002
A12: 1212410 | B12: MP10008 | C12: PRESERVANTE 1047S (PAQ=5 KILO) | D12: ASEAL | E12: 10.002021 | F12: g | J12: =+E12/$D$39 -> 0.00061497906 | K12: =+J12*1000 -> 0.61497906 | L12: =L11-230 -> 16034.002
A13: 10400008 | B13: MP10150 | C13: COLORANTE GEL EGG YELLOW (UND= 130 ML) | D13: MASTER PACK | E13: 4 | F13: g | J13: =+E13/$D$39 -> 0.00024594193 | K13: =+J13*1000 -> 0.24594193
L17: =E10/1000 -> 16.15
C21: Decoración
C28: Empaque
A29: 702123 | B29: EM10011 | C29: ETIQUETA BLANCA 2 5/8X1 15/16 (UND) | D29: Etiplas | E29: 1 | F29: ud
D38: Cantidad | E38: Unidad
A39: PESO TOTAL OBTENIDO | D39: =SUM(E10:E13) -> 16264.002 | E39: g | F39: Tiempo de Horneo:
A40: TIEMPO TOTAL DE PREPARACION | D40: 15 | E40: min | F40: Horno:
A41: CANTIDAD DE PORCIONES OBTENIDAS | D41: 1 | E41: Tanda | F41: Temperatura de Horneo:
A42: PESO DE CADA PORCIÓN | D42: 16263 | E42: g | F42: Otros
A43: MERMA | D43: =SUM(E10:E13)-D39 -> 0 | E43: g
A44: PROCEDIMIENTO DE PREPARACION DE LA RECETA
A45: 1.- Abrir los galones de bettercreme supremo y verter dentro de la top cream, reservando un poco.
A46: 2.- Disolver el preservante con el colorante en el agua, mezclando bien, dejandolo sin grumos (Si hace falta disolver, agregar un poco del bettercream supremo para terminar de disolver)
A47: 3.- Batir por 15 minutos
A48: 4- Una vez lista retirar (Temperatura adecuada 15° a 16°) y colocar en una tina plastica y tapar con plastico
A49: 5.- Etiquetar con nombre y fecha de vencimiento.
A50: 6.- Mantener en refrigeración, hasta su uso.
A56: CONTROL DE CAMBIOS
A57: 2, Se sustituye la crema prestige por crema supremo y procedimiento
A58: 3, Se actualiza tiempo de preparación, se agrega colorante y se actualiza procedimiento.
A59: 4, Se actualiza cantidad de colorante

Sheet Salsa de Fresa
C1: SERVICIOS DE PASTELERIA S.A. | H1: CÓDIGO: | I1: ESP-RE-COCS-062
C2: ESPECIFICACION DE RECETA | H2: REVISIÓN: | I2: 01
C3: Salsa De Fresa 3800g SE00025 | H3: FECHA DE APROBACIÓN: | I3: 45609
C4: Elaborado | D4: Javier Tong, Chef
C5: Aprobado | D5: Esteban Cartin, Gte Manufactura
A6: AREA QUE PRODUCE: | D6: Cocina | G6: AREA QUE EMPACA: | I6: Cocina
A7: # Código | B7: # Código Netsuite | C7: Descripción del ingrediente | D7: Marca | E7: Unidad Internacional | G7: Medida alternativa | I7: Costo - Referencia
E8: Cantidad | F8: Unidad medida | G8: Cantidad | H8: Unidad medida | I8: Colones
C9: Ensamble
A10: 20100115 | B10: SE00354 | C10: EMPAQUE RELLENO DE FRESA ESPESA | D10: FAS | E10: 4000 | F10: g
A11: 10400009 | B11: MP10157 | C11: COLORANTE GEL,SUPER RED (130ML) | D11: LAS TORRES | E11: 5 | F11: g
B12: MP10687 | C12: SMOOBEES BLUEBERRY 1 KG | D12: PURATOS | E12: 500 | F12: g
C27: Decoración
C33: Empaque
D44: Cantidad | E44: Unidad
A45: PESO TOTAL OBTENIDO | D45: 4300 | E45: g | F45: Tiempo de Horneo:
A46: TIEMPO TOTAL DE PREPARACION | D46: 5 | E46: Minutos | F46: Horno:
A47: CANTIDAD DE PORCIONES OBTENIDAS | D47: 1 | E47: ud | F47: Temperatura de Horneo:
A48: PESO DE CADA PORCIÓN | D48: 4300 | E48: g | F48: Otros
A49: MERMA | D49: 205 | E49: g
A50: PROCEDIMIENTO DE PREPARACION DE LA RECETA
A51: 1.- Colocar el relleno en la licuadora con las gotas rojas y los smoobees.
A52: 2.- Presionar ligeramente EN PULSACIONES para obtener una masa homogénea.
A53: 3.- No licuar continuamente para no incorporar aire al relleno perdiendo su color.
A54: 4.- Llevar a empaque.
A55: 5.- Guardar en cámaras de refrigeración a 4ºC
A62: CONTROL DE CAMBIOS

Sheet Relleno Fresa Espesa
C1: SERVICIOS DE PASTELERIA S.A. | H1: CÓDIGO: | I1: ESP-RE-COCS-041
C2: ESPECIFICACION DE RECETA | H2: REVISIÓN: | I2: 02
C3: SE00354 Relleno de fresa Espesa PLANTA | H3: FECHA DE APROBACIÓN: | I3: 45609
C4: Elaborado | D4: Javier Tong, Chef
C5: Aprobado | D5: Esteban Cartin, Gte Manufactura
A6: AREA QUE PRODUCE: | D6: Cocina | G6: AREA QUE EMPACA: | I6: Empaque
A7: # Código | B7: # Código Netsuite | C7: Descripción del ingrediente | D7: Marca | E7: Unidad Internacional | G7: Medida alternativa | I7: Costo - Referencia
E8: Cantidad | F8: Unidad medida | G8: Cantidad | H8: Unidad medida | I8: Colones
C9: Ensamble
A10: 10100230 | B10: MP10191 | C10: FRESA CONGELADA BEGRO (PAQ:1 K) | D10: BEGRO | E10: 46000 | F10: g
A11: 1212412 | B11: MP10025 | C11: PRESERVANTE 1017S (PAQ=5 KILO) | D11: ASEAL | E11: 124 | F11: g
A12: 0510215 | B12: MP10026 | C12: ALMIDON MODIFICADO ( 25 KG ) | D12: ASEAL | E12: 2700 | F12: g
A13: 10415 | C13: AGUA POTABLE (PLANTA) | D13: FAS | E13: 1620 | F13: g
A14: 10400009 | B14: MP10157 | C14: COLORANTE GEL SUPER RED | D14: AMERICOLOR | E14: 4 | F14: g
A15: 10400010 | B15: MP10509 | C15: COLORANTE ROJO (50ML) | D15: ANCLA | E15: 4 | F15: g
A16: 90100131 | B16: SE00016 | C16: AZUCAR BLANCO INDUSTRIAL (BOLSAS:1500g) | D16: FAS | E16: 14260 | F16: g
A17: 908000036 | B17: SE00015 | C17: JUGO LIMON (KILO) | D17: FAS | E17: 1840 | F17: g
C19: Empaque
A20: 0702123 | B20: EM10011 | C20: ETIQUETA BLANCA 2 5/8X1 15/16 (UND) | D20: CEMUSA | E20: 12 | F20: ud
D23: Cantidad | E23: Unidad
A24: PESO TOTAL OBTENIDO | D24: 62600 | E24: g | F24: Tiempo de Horneo:
A25: TIEMPO TOTAL DE PREPARACION | D25: 35 | E25: min | F25: Horno:
A26: CANTIDAD DE PORCIONES OBTENIDAS | D26: =D24/D27 -> 12.52 | E26: bolsas | F26: Temperatura de Horneo:
A27: PESO DE CADA PORCIÓN | D27: 5000 | E27: g | F27: Otros
A28: MERMA | D28: =SUM(E10:E17)-D24 -> 3952 | E28: g
A29: PROCEDIMIENTO DE PREPARACION DE LA RECETA
A30: 1, Colocar la fresa congelada en la olla junto con el azucar, el agua y el colorante. Hervir
A31: 2, Mezclar el almidon con el preservante, juego de limon . Agregar a la mezcla anterior. Hervir
A32: 3, Colocar en bandejas y hacer choque termico.
A35: PROGRAMACION MARMITA
A36: Temperatura del piso 230ºC con la agitacion al maximo de 45 por cada lado y paredes a la mitad con 100ºC.
A37: Tiempo 58 minutos, la preparacion empieza a hervir ente los 55-57 minutos, a los 58 espesamos y mezclamos para incorporar bien.
A38: Sacamos a enfriamiento.
A41: CONTROL DE CAMBIOS
A42: Revision #2: Ajuste de la tanda para la marmita y se agrega la programacion.

Sheet Merengue para suspiro
C1: SERVICIOS DE PASTELERIA S.A. | H1: CÓDIGO: | I1: ESP-RE-BAS-014
C2: ESPECIFICACION DE RECETA | H2: REVISIÓN: | I2: 01
C3: Merengue Para Suspiro Con Claras Deshidratadas 5205g SE00022 | H3: FECHA DE APROBACIÓN: | I3: 45619
C4: Elaborado | D4: Javier Tong, Chef
C5: Aprobado | D5: Esteban Cartin, Gte Manufactura
A6: AREA QUE PRODUCE: | D6: Batidos | G6: AREA QUE EMPACA: | I6: Batidos
A7: # Código | B7: # Código Netsuite | C7: Descripción del ingrediente | D7: Marca | E7: Unidad Internacional | G7: Medida alternativa | I7: Costo - Referencia
E8: Cantidad | F8: Unidad medida | G8: Cantidad | H8: Unidad medida | I8: Colones
C9: Ensamble
A10: 901000015 | B10: SE00023 | C10: PREMEZCLA SUSPIRO CLARAS DESHID KILO | D10: FAS | E10: 9771 | F10: g
A11: 10415 | C11: AGUA | D11: FAS | E11: 3250 | F11: g
C21: Decoración
C28: Empaque
D38: Cantidad | E38: Unidad
A39: PESO TOTAL OBTENIDO | D39: 11250 | E39: g | F39: Tiempo de Horneo:
A40: TIEMPO TOTAL DE PREPARACION | D40: 5 | E40: min | F40: Horno:
A41: CANTIDAD DE PORCIONES OBTENIDAS | D41: 1 | E41: tanda | F41: Temperatura de Horneo:
A42: PESO DE CADA PORCIÓN | D42: 11250 | E42: g | F42: Otros
A43: MERMA | D43: 1771 | E43: g
A44: PROCEDIMIENTO DE PREPARACION DE LA RECETA
A45: 1. Colocar la clara de huevo y el agua, batir en globo en velocidad 4 durante 30 segundos.
A46: 2. Agregar el azucar y batir en velocidad 2 por 30 segundos.
A47: 3. Tapar con bolsa, subir a velocidad 4 y batir por 3 minutos.
A55: CONTROL DE CAMBIOS

Sheet Premezcla suspiro
C1: SERVICIOS DE PASTELERIA S.A. | H1: CÓDIGO: | I1: ESP-RE-PRES-009
C2: ESPECIFICACION DE RECETA | H2: REVISIÓN: | I2: 01
C3: Premezcla Batido Suspiro Claras Deshidratadas 4055g 901000015(SE00023) | H3: FECHA DE APROBACIÓN: | I3: 45616
C4: Elaborado | D4: Javier Tong, Chef
C5: Aprobado | D5: Esteban Cartin, Gte Manufactura
A6: AREA QUE PRODUCE: | D6: Premezclas | G6: AREA QUE EMPACA: | I6: Premezclas
A7: # Código | B7: # Código Netsuite | C7: Descripción del ingrediente | D7: Marca | E7: Unidad Internacional | G7: Medida alternativa | I7: Costo - Referencia
E8: Cantidad | F8: Unidad medida | G8: Cantidad | H8: Unidad medida | I8: Colones
C9: Ensamble
A10: 1210445 | B10: MP10142 | C10: CLARAS DE HUEVO DESHIDRATADAS | D10: RESOCO | E10: 760 | F10: g
A11: 10100003 | B11: MP10049 | C11: AZUCAR POLVO P.REAL (PAQ:2.5 Kg) | D11: PASTELERO REAL | E11: 9000 | F11: g
A12: 1212410 | B12: MP10008 | C12: PRESERVANTE 1047 | D12: ASEAL | E12: 11 | F12: g
C18: Decoración
C25: Empaque
A26: 1950702 | B26: EM10016 | C26: BOLSA 12x18 TRANSP (KILO) | D26: PLASTICOS P | E26: 1 | F26: ud
A27: 0702123 | B27: EM10011 | C27: ETIQUETA BLANCA 2 5/8X1 15/16 (UND) | D27: ETIPLAST | E27: 1 | F27: ud
A28: 60100010 | B28: EM10133 | C28: ETIQUETA ROJA LETRA ALERJENO (UND) | D28: ETIPLAST | E28: 1 | F28: ud
D38: Cantidad | E38: Unidad
A39: PESO TOTAL OBTENIDO | D39: 9771 | E39: g | F39: Tiempo de Horneo:
A40: TIEMPO TOTAL DE PREPARACION | D40: 2 | E40: min | F40: Horno:
A41: CANTIDAD DE PORCIONES OBTENIDAS | D41: 1 | E41: Tanda | F41: Temperatura de Horneo:
A42: PESO DE CADA PORCIÓN | D42: 9771 | E42: g | F42: Otros
A43: MERMA | D43: 0 | E43: g
A44: PROCEDIMIENTO DE PREPARACION DE LA RECETA
A45: 1. En una bolsa pesar la clara y preservante, cerrar con un nudo. Etiquetar con fecha de vencimiento, y etiqueta alerjeno.
A46: 2.- El azucar se pesa en el area de batidos.
A53: CONTROL DE CAMBIOS

Sheet Relleno fresa-frambuesa
C1: SERVICIOS DE PASTELERIA S.A. | H1: CÓDIGO: | I1: ESP-RE-COCS-143
C2: ESPECIFICACION DE RECETA | H2: REVISIÓN: | I2: 01
C3: SE00836 Relleno de fresa frambuesa | H3: FECHA DE APROBACIÓN: | I3: 46094
C4: Elaborado | D4: Juan Pablo Brenes, Chef
C5: Aprobado | D5: Esteban Cartin, Gte Manufactura
A6: AREA QUE PRODUCE: | D6: Cocina | G6: AREA QUE EMPACA: | I6: Empaque
A7: # Código | B7: # Código Netsuite | C7: Descripción del ingrediente | D7: Marca | E7: Unidad Internacional | G7: Medida alternativa | I7: Costo - Referencia
E8: Cantidad | F8: Unidad medida | G8: Cantidad | H8: Unidad medida | I8: Colones
C9: Ensamble
B10: MP10191 | C10: FRESA CONGELADA BEGRO (PAQ:1 K) | D10: BEGRO | E10: 500 | F10: g
B11: MP10896 | C11: FRAMBUESA CONGELADA | E11: 200 | F11: g
B12: MP10547 | C12: Concentrado de Frambuesa | E12: 100 | F12: g
B13: SE00016 | C13: AZUCAR BLANCO INDUSTRIAL (BOLSAS:1500g) | D13: FAS | E13: 100 | F13: g
B14: SE00015 | C14: JUGO LIMON (KILO) | D14: FAS | E14: 2 | F14: g
B15: MP10025 | C15: PRESERVANTE 1017S (PAQ=5 KILO) | D15: ASEAL | E15: 2 | F15: g
B16: MP10157 | C16: COLORANTE GEL SUPER RED | D16: AMERICOLOR | E16: 0.1 | F16: g
B17: MP10026 | C17: ALMIDON MODIFICADO ( 25 KG ) | D17: ASEAL | E17: 50 | F17: g
C18: AGUA POTABLE (PLANTA) | D18: FAS | E18: 70 | F18: g
C20: Decoración
C22: Empaque
A23: 0702123 | B23: EM10011 | C23: ETIQUETA BLANCA 2 5/8X1 15/16 (UND) | D23: CEMUSA | E23: 1 | F23: ud
D26: Cantidad | E26: Unidad
A27: PESO TOTAL OBTENIDO | D27: 1000 | E27: g | F27: Tiempo de Horneo:
A28: TIEMPO TOTAL DE PREPARACION | D28: 3 | E28: min | F28: Horno:
A29: CANTIDAD DE PORCIONES OBTENIDAS | D29: 1 | E29: tanda | F29: Temperatura de Horneo:
A30: PESO DE CADA PORCIÓN | D30: 1000 | E30: g | F30: Otros
A31: MERMA | D31: =SUM(E10:E18)-D27 -> 24 | E31: g
A32: PROCEDIMIENTO DE PREPARACION DE LA RECETA
A33: 1, Colocar la fresa congelada, frambuesa en la olla junto con el azucar,el concentrado de frambuesa el agua y el colorante. Hervir
A34: 2, Mezclar el almidon con el preservante, jugo de limon . Agregar a la mezcla anterior. Hervir
A35: 3, Colocar en bandejas y hacer choque termico.
A38: CONTROL DE CAMBIOS

Sheet costo Fresa- Frambuesa
E1: Precio Local | F1: Costo MP | G1: Costo EM | H1: Costo MO
E2: =IFERROR(O62,"") -> 2959.037 | F2: =IFERROR(H53,"") -> 2469.726 | G2: =IFERROR(H54,"") -> 7.15 | H2: =IFERROR(H56,"") -> 232.04
A5: ESTRUCTURA DE COSTOS
F6: Fecha: | H6: =TODAY() -> 46094
A7: UNIDADES | B7: DESCRIPCION MAT.PRIMA | C7: UNIDADES | D7: UND MEDIDA | E7: COSTO UNITARIO | F7: TOTAL COSTO | G7: % PREC. DEFINIDO | H7: CODIGOS
A8: 500 | B8: FRESA CONGELADA BEGRO (PAQ:1 K) | C8: =+A8 -> 500 | D8: Gramos | E8: 2.3 | F8: =IFERROR(C8*E8,"") -> 1150 | G8: =IFERROR(F8/$F$66,"") -> 0.41707913 | H8: MP10191
A9: 200 | B9: FRAMBUESA CONGELADA | C9: =+A9 -> 200 | D9: Gramos | E9: 3.7 | F9: =IFERROR(C9*E9,"") -> 740 | G9: =IFERROR(F9/$F$66,"") -> 0.26838136 | H9: MP10896
A10: 100 | B10: Concentrado de Frambuesa | C10: =+A10 -> 100 | D10: Gramos | E10: 4.13 | F10: =IFERROR(C10*E10,"") -> 413 | G10: =IFERROR(F10/$F$66,"") -> 0.14978581 | H10: MP10547
A11: 2 | B11: PRESERVANTE 1017S (PAQ=5 KILO) | C11: =+A11 -> 2 | D11: Gramos | E11: 8.39 | F11: =IFERROR(C11*E11,"") -> 16.78 | G11: =IFERROR(F11/$F$66,"") -> 0.0060857286 | H11: MP10025
A12: 0.1 | B12: COLORANTE GEL SUPER RED | C12: =+A12 -> 0.1 | D12: Gramos | E12: 18.46 | F12: =IFERROR(C12*E12,"") -> 1.846 | G12: =IFERROR(F12/$F$66,"") -> 0.00066950268 | H12: MP10157
A13: 50 | B13: ALMIDON MODIFICADO ( 25 KG ) | C13: =+A13 -> 50 | D13: Gramos | E13: 2 | F13: =IFERROR(C13*E13,"") -> 100 | G13: =IFERROR(F13/$F$66,"") -> 0.036267751 | H13: MP10026
B14: =IFERROR(VLOOKUP(H14,'[1]Consolidado MP Planta'!$A$2:$M$823,3,0),"") | C14: =+A14 -> 0 | D14: =IFERROR(VLOOKUP(H14,'[1]Consolidado MP Planta'!$A$2:$M$823,13,0),"") | E14: =IFERROR(VLOOKUP(H14,'[1]Consolidado MP Planta'!$A$2:$M$823,12,0),"") | F14: =IFERROR(C14*E14,"") | G14: =IFERROR(F14/$F$66,"")
B15: =IFERROR(VLOOKUP(H15,[2]Hoja2!$A$2:$G$589,2,0),"")
A16: UNIDADES | B16: MATERIA PRIMA SEMIELABORADOS | C16: UNIDADES | D16: UND MEDIDA | E16: COSTO UNITARIO | F16: TOTAL COSTO | G16: % PREC. DEFINIDO | H16: CODIGOS
A17: 100 | B17: AZUCAR BLANCO INDUSTRIAL (BOLSAS:1500g) | C17: =+A17 -> 100 | D17: Gramos | E17: 0.47 | F17: =IFERROR(E17*C17,"") -> 47 | G17: =IFERROR(F17/$F$66,"") -> 0.017045843 | H17: SE00016
A18: 2 | B18: JUGO LIMON (KILO) | C18: =+A18 -> 2 | D18: Gramos | E18: 0.55 | F18: =IFERROR(E18*C18,"") -> 1.1 | G18: =IFERROR(F18/$F$66,"") -> 0.00039894526 | H18: SE00015
B19: =IFERROR(VLOOKUP(H19,[1]SEMIELABORADOS!$A$2:$M$6000,2,0),"") | C19: =+A19 -> 0 | D19: =IFERROR(VLOOKUP(H19,[1]SEMIELABORADOS!$A$2:$M$6000,6,0),"") | E19: =IFERROR(VLOOKUP(H19,[1]SEMIELABORADOS!$A$2:$H$65536,8,0),"") | F19: =IFERROR(E19*C19,"") | G19: =IFERROR(F19/$F$66,"")
B20: =IFERROR(VLOOKUP(H20,[1]SEMIELABORADOS!$A$2:$M$6000,2,0),"") | C20: =+A20 -> 0 | D20: =IFERROR(VLOOKUP(H20,[1]SEMIELABORADOS!$A$2:$M$6000,6,0),"") | E20: =IFERROR(VLOOKUP(H20,[1]SEMIELABORADOS!$A$2:$H$65536,8,0),"") | F20: =IFERROR(E20*C20,"") | G20: =IFERROR(F20/$F$66,"")
B21: =IFERROR(VLOOKUP(H21,[1]SEMIELABORADOS!$A$2:$M$6000,2,0),"") | C21: =+A21 -> 0 | D21: =IFERROR(VLOOKUP(H21,[1]SEMIELABORADOS!$A$2:$M$6000,6,0),"") | E21: =IFERROR(VLOOKUP(H21,[1]SEMIELABORADOS!$A$2:$H$65536,8,0),"") | F21: =IFERROR(E21*C21,"") | G21: =IFERROR(F21/$F$66,"")
B22: =IFERROR(VLOOKUP(H22,[1]SEMIELABORADOS!$A$2:$M$6000,2,0),"") | C22: =+A22 -> 0 | D22: =IFERROR(VLOOKUP(H22,[1]SEMIELABORADOS!$A$2:$M$6000,6,0),"") | E22: =IFERROR(VLOOKUP(H22,[1]SEMIELABORADOS!$A$2:$H$65536,8,0),"") | F22: =IFERROR(E22*C22,"") | G22: =IFERROR(F22/$F$66,"")
B23: =IFERROR(VLOOKUP(H23,[1]SEMIELABORADOS!$A$2:$M$6000,2,0),"") | C23: =+A23 -> 0 | D23: =IFERROR(VLOOKUP(H23,[1]SEMIELABORADOS!$A$2:$M$6000,6,0),"") | E23: =IFERROR(VLOOKUP(H23,[1]SEMIELABORADOS!$A$2:$H$65536,8,0),"") | F23: =IFERROR(E23*C23,"") | G23: =IFERROR(F23/$F$66,"")
B24: =IFERROR(VLOOKUP(H24,[1]SEMIELABORADOS!$A$2:$M$6000,2,0),"") | C24: =+A24 -> 0 | D24: =IFERROR(VLOOKUP(H24,[1]SEMIELABORADOS!$A$2:$M$6000,6,0),"") | E24: =IFERROR(VLOOKUP(H24,[1]SEMIELABORADOS!$A$2:$H$65536,8,0),"") | F24: =IFERROR(E24*C24,"") | G24: =IFERROR(F24/$F$66,"")
A26: UNIDADES | B26: EMPAQUE | C26: UNIDADES | D26: UND MEDIDA | E26: COSTO UNITARIO | F26: TOTAL COSTO | G26: % PREC. DEFINIDO | H26: CODIGOS
A27: 1 | B27: =IFERROR(VLOOKUP(H27,'[1]Consolidado MP Planta'!$A$2:$M$823,3,0),"") -> ETIQUETA BLANCA 2 5/8X1 15/16 (UND) | C27: =+A27 -> 1 | D27: =IFERROR(VLOOKUP(H27,'[1]Consolidado MP Planta'!$A$2:$M$823,13,0),"") -> Und | E27: 2.13 | F27: =IFERROR(C27*E27,"") -> 2.13 | G27: =IFERROR(F27/$F$66,"") -> 0.00077250309 | H27: 0702123
B28: =IFERROR(VLOOKUP(H28,'[1]Consolidado MP Planta'!$A$2:$M$823,3,0),"") | C28: =+A28 -> 0 | D28: =IFERROR(VLOOKUP(H28,'[1]Consolidado MP Planta'!$A$2:$M$823,13,0),"") | E28: =IFERROR(VLOOKUP(H28,'[1]Consolidado MP Planta'!$A$2:$M$823,12,0),"") | F28: =IFERROR(C28*E28,"") | G28: =IFERROR(F28/$F$66,"")
B29: =IFERROR(VLOOKUP(H29,'[1]Consolidado MP Planta'!$A$2:$M$823,3,0),"") | C29: =+A29 -> 0 | D29: =IFERROR(VLOOKUP(H29,'[1]Consolidado MP Planta'!$A$2:$M$823,13,0),"") | E29: =IFERROR(VLOOKUP(H29,'[1]Consolidado MP Planta'!$A$2:$M$823,12,0),"") | F29: =IFERROR(C29*E29,"") | G29: =IFERROR(F29/$F$66,"")
B30: =IFERROR(VLOOKUP(H30,'[1]Consolidado MP Planta'!$A$2:$M$823,3,0),"") | C30: =+A30 -> 0 | D30: =IFERROR(VLOOKUP(H30,'[1]Consolidado MP Planta'!$A$2:$M$823,13,0),"") | E30: =IFERROR(VLOOKUP(H30,'[1]Consolidado MP Planta'!$A$2:$M$823,12,0),"") | F30: =IFERROR(C30*E30,"") | G30: =IFERROR(F30/$F$66,"")
B31: =IFERROR(VLOOKUP(H31,'[1]Consolidado MP Planta'!$A$2:$M$823,3,0),"") | C31: =+A31 -> 0 | D31: =IFERROR(VLOOKUP(H31,'[1]Consolidado MP Planta'!$A$2:$M$823,13,0),"") | E31: =IFERROR(VLOOKUP(H31,'[1]Consolidado MP Planta'!$A$2:$M$823,12,0),"") | F31: =IFERROR(C31*E31,"") | G31: =IFERROR(F31/$F$66,"")
B32: =IFERROR(VLOOKUP(H32,'[1]Consolidado MP Planta'!$A$2:$M$823,3,0),"") | C32: =+A32 -> 0 | D32: =IFERROR(VLOOKUP(H32,'[1]Consolidado MP Planta'!$A$2:$M$823,13,0),"") | E32: =IFERROR(VLOOKUP(H32,'[1]Consolidado MP Planta'!$A$2:$M$823,12,0),"") | F32: =IFERROR(C32*E32,"") | G32: =IFERROR(F32/$F$66,"")
A34: UNIDADES | B34: EMPAQUE SEMIELABORADOS | C34: UNIDADES | D34: UND MEDIDA | E34: COSTO UNITARIO | F34: TOTAL COSTO | G34: % PREC. DEFINIDO | H34: CODIGOS
A35: =+A17 -> 100 | B35: AZUCAR BLANCO INDUSTRIAL (BOLSAS:1500g) | C35: =+A35 -> 100 | D35: Gramos | E35: 0.05 | F35: =IFERROR(E35*C35,"") -> 5 | G35: =IFERROR(F35/$F$66,"") -> 0.0018133875 | H35: SE00016
A36: =+A18 -> 2 | B36: JUGO LIMON (KILO) | C36: =+A36 -> 2 | D36: Gramos | E36: 0.01 | F36: =IFERROR(E36*C36,"") -> 0.02 | G36: =IFERROR(F36/$F$66,"") -> 7.2535502e-06 | H36: SE00015
A37: =+A19 -> 0 | B37: =IFERROR(VLOOKUP(H37,[1]SEMIELABORADOS!$A$2:$M$6000,2,0),"") | C37: =+A37 -> 0 | D37: =IFERROR(VLOOKUP(H37,[1]SEMIELABORADOS!$A$2:$M$6000,6,0),"") | E37: =IFERROR(VLOOKUP(H37,[1]SEMIELABORADOS!$A$2:$M$65536,10,0),"") | F37: =IFERROR(E37*C37,"") | G37: =IFERROR(F37/$F$66,"")
A38: =+A20 -> 0 | B38: =IFERROR(VLOOKUP(H38,[1]SEMIELABORADOS!$A$2:$M$6000,2,0),"") | C38: =+A38 -> 0 | D38: =IFERROR(VLOOKUP(H38,[1]SEMIELABORADOS!$A$2:$M$6000,6,0),"") | E38: =IFERROR(VLOOKUP(H38,[1]SEMIELABORADOS!$A$2:$M$65536,10,0),"") | F38: =IFERROR(E38*C38,"") | G38: =IFERROR(F38/$F$66,"")
A39: =+A21 -> 0 | B39: =IFERROR(VLOOKUP(H39,[1]SEMIELABORADOS!$A$2:$M$6000,2,0),"") | C39: =+A39 -> 0 | D39: =IFERROR(VLOOKUP(H39,[1]SEMIELABORADOS!$A$2:$M$6000,6,0),"") | E39: =IFERROR(VLOOKUP(H39,[1]SEMIELABORADOS!$A$2:$M$65536,10,0),"") | F39: =IFERROR(E39*C39,"") | G39: =IFERROR(F39/$F$66,"")
A40: =+A22 -> 0 | B40: =IFERROR(VLOOKUP(H40,[1]SEMIELABORADOS!$A$2:$M$6000,2,0),"") | C40: =+A40 -> 0 | D40: =IFERROR(VLOOKUP(H40,[1]SEMIELABORADOS!$A$2:$M$6000,6,0),"") | E40: =IFERROR(VLOOKUP(H40,[1]SEMIELABORADOS!$A$2:$M$65536,10,0),"") | F40: =IFERROR(E40*C40,"") | G40: =IFERROR(F40/$F$66,"")
A41: =+A23 -> 0 | B41: =IFERROR(VLOOKUP(H41,[1]SEMIELABORADOS!$A$2:$M$6000,2,0),"") | C41: =+A41 -> 0 | D41: =IFERROR(VLOOKUP(H41,[1]SEMIELABORADOS!$A$2:$M$6000,6,0),"") | E41: =IFERROR(VLOOKUP(H41,[1]SEMIELABORADOS!$A$2:$M$65536,10,0),"") | F41: =IFERROR(E41*C41,"") | G41: =IFERROR(F41/$F$66,"")
A43: UNIDADES | B43: MODI | C43: UNIDADES | D43: UND MEDIDA | E43: COSTO UNITARIO | F43: TOTAL COSTO | G43: % PREC. DEFINIDO | H43: CODIGOS
A44: =+A35 -> 100 | B44: AZUCAR BLANCO INDUSTRIAL (BOLSAS:1500g) | C44: =+A44 -> 100 | D44: Gramos | E44: 0.01 | F44: =IFERROR(E44*C44,"") -> 1 | G44: =IFERROR(F44/$F$66,"") -> 0.00036267751 | H44: SE00016
A45: =+A36 -> 2 | B45: JUGO LIMON (KILO) | C45: =+A45 -> 2 | D45: Gramos | E45: 0.02 | F45: =IFERROR(E45*C45,"") -> 0.04 | G45: =IFERROR(F45/$F$66,"") -> 1.45071e-05 | H45: SE00015
...
