Workbook

Sheet COSTEO BATIDO
E1: Precio Local | F1: Costo MP | G1: Costo EM | H1: Costo MO
E2: =IFERROR(O55,"") -> 119061.09 | F2: =IFERROR(H46,"") -> 89196.957 | G2: =IFERROR(H47,"") -> 19.096393 | H2: =IFERROR(H49,"") -> 605
A4: BATIDO SUPER ESPONJA KALUA
A5: ESTRUCTURA DE COSTOS
F6: Fecha: | H6: =TODAY() -> 46058
A7: UNIDADES | B7: DESCRIPCION MAT.PRIMA | C7: UNIDADES | D7: UND MEDIDA | E7: COSTO UNITARIO | F7: TOTAL COSTO | G7: % PREC. DEFINIDO | H7: CODIGOS
A8: 15875 | B8: =IFERROR(VLOOKUP(H8,'[1]ARTICULOS MP PLANTA'!$A$2:$G$589,2,0),"") -> PREMEZCLA PASTEL SUPER ESPONJA | C8: =+A8 -> 15875 | D8: =IFERROR(VLOOKUP(H8,'[1]ARTICULOS MP PLANTA'!$A$2:$G$589,6,0),"") -> Gramo | E8: =IFERROR(VLOOKUP(H8,'[1]ARTICULOS MP PLANTA'!$A$2:$G$589,7,0),"") -> 1.8235 | F8: =IFERROR(C8*E8,"") -> 28948.062 | G8: =IFERROR(F8/$F$59,"") -> 0.31657989 | H8: 0510304
A9: 11112 | B9: =IFERROR(VLOOKUP(H9,'[1]ARTICULOS MP PLANTA'!$A$2:$G$589,2,0),"") -> HUEVO LIQUIDO REFRIG (UND:13.6 K) | C9: =+A9 -> 11112 | D9: =IFERROR(VLOOKUP(H9,'[1]ARTICULOS MP PLANTA'!$A$2:$G$589,6,0),"") -> Gramo | E9: =IFERROR(VLOOKUP(H9,'[1]ARTICULOS MP PLANTA'!$A$2:$G$589,7,0),"") -> 1.1627941 | F9: =IFERROR(C9*E9,"") -> 12920.968 | G9: =IFERROR(F9/$F$59,"") -> 0.14130544 | H9: 1210441
A10: 4762 | B10: AGUA | C10: =+A10 -> 4762 | D10: Mililitro | E10: 0.1 | F10: =IFERROR(C10*E10,"") -> 476.2 | G10: =IFERROR(F10/$F$59,"") -> 0.0052077869 | H10: 9999
B11: =IFERROR(VLOOKUP(H11,'[1]ARTICULOS MP PLANTA'!$A$2:$G$589,2,0),"") | C11: =+A11 -> 0 | D11: =IFERROR(VLOOKUP(H11,'[1]ARTICULOS MP PLANTA'!$A$2:$G$589,6,0),"") | E11: =IFERROR(VLOOKUP(H11,'[1]ARTICULOS MP PLANTA'!$A$2:$G$589,7,0),"") | F11: =IFERROR(C11*E11,"") | G11: =IFERROR(F11/$F$59,"")
B12: =IFERROR(VLOOKUP(H12,'[1]ARTICULOS MP PLANTA'!$A$2:$G$589,2,0),"") | C12: =+A12 -> 0 | D12: =IFERROR(VLOOKUP(H12,'[1]ARTICULOS MP PLANTA'!$A$2:$G$589,6,0),"") | E12: =IFERROR(VLOOKUP(H12,'[1]ARTICULOS MP PLANTA'!$A$2:$G$589,7,0),"") | F12: =IFERROR(C12*E12,"") | G12: =IFERROR(F12/$F$59,"")
B13: =IFERROR(VLOOKUP(H13,'[1]ARTICULOS MP PLANTA'!$A$2:$G$589,2,0),"") | C13: =+A13 -> 0 | D13: =IFERROR(VLOOKUP(H13,'[1]ARTICULOS MP PLANTA'!$A$2:$G$589,6,0),"") | E13: =IFERROR(VLOOKUP(H13,'[1]ARTICULOS MP PLANTA'!$A$2:$G$589,7,0),"") | F13: =IFERROR(C13*E13,"") | G13: =IFERROR(F13/$F$59,"")
B14: =IFERROR(VLOOKUP(H14,'[1]ARTICULOS MP PLANTA'!$A$2:$G$589,2,0),"") | C14: =+A14 -> 0 | D14: =IFERROR(VLOOKUP(H14,'[1]ARTICULOS MP PLANTA'!$A$2:$G$589,6,0),"") | E14: =IFERROR(VLOOKUP(H14,'[1]ARTICULOS MP PLANTA'!$A$2:$G$589,7,0),"") | F14: =IFERROR(C14*E14,"") | G14: =IFERROR(F14/$F$59,"")
B15: =IFERROR(VLOOKUP(H15,'[1]ARTICULOS MP PLANTA'!$A$2:$G$589,2,0),"")
A16: UNIDADES | B16: MATERIA PRIMA SEMIELABORADOS | C16: UNIDADES | D16: UND MEDIDA | E16: COSTO UNITARIO | F16: TOTAL COSTO | G16: % PREC. DEFINIDO | H16: CODIGOS
A17: 8252 | B17: PREMEZCLA SUPER ESPONJA KALUA | C17: =+A17 -> 8252 | D17: Gramo | E17: =+'[2]Costo '!$E$62 -> 5.6776208 | F17: =IFERROR(E17*C17,"") -> 46851.727 | G17: =IFERROR(F17/$F$59,"") -> 0.51237675
B18: =IFERROR(VLOOKUP($H18,[3]SEMIELABORADOS!$A$1:$J$999,2,0),"") | C18: =+A18 -> 0 | D18: =IFERROR(VLOOKUP($H18,[3]SEMIELABORADOS!$A$1:$J$999,4,0),"") | E18: =IFERROR(VLOOKUP($H18,[3]SEMIELABORADOS!$A$1:$J$999,6,0),"") | F18: =IFERROR(E18*C18,"") | G18: =IFERROR(F18/$F$59,"")
B19: =IFERROR(VLOOKUP($H19,[3]SEMIELABORADOS!$A$1:$J$999,2,0),"") | C19: =+A19 -> 0 | D19: =IFERROR(VLOOKUP($H19,[3]SEMIELABORADOS!$A$1:$J$999,4,0),"") | E19: =IFERROR(VLOOKUP($H19,[3]SEMIELABORADOS!$A$1:$J$999,6,0),"") | F19: =IFERROR(E19*C19,"") | G19: =IFERROR(F19/$F$59,"")
B20: =IFERROR(VLOOKUP($H20,[3]SEMIELABORADOS!$A$1:$J$999,2,0),"") | C20: =+A20 -> 0 | D20: =IFERROR(VLOOKUP($H20,[3]SEMIELABORADOS!$A$1:$J$999,4,0),"") | E20: =IFERROR(VLOOKUP($H20,[3]SEMIELABORADOS!$A$1:$J$999,6,0),"") | F20: =IFERROR(E20*C20,"") | G20: =IFERROR(F20/$F$59,"")
B21: =IFERROR(VLOOKUP($H21,[3]SEMIELABORADOS!$A$1:$J$999,2,0),"") | C21: =+A21 -> 0 | D21: =IFERROR(VLOOKUP($H21,[3]SEMIELABORADOS!$A$1:$J$999,4,0),"") | E21: =IFERROR(VLOOKUP($H21,[3]SEMIELABORADOS!$A$1:$J$999,6,0),"") | F21: =IFERROR(E21*C21,"") | G21: =IFERROR(F21/$F$59,"")
A23: UNIDADES | B23: EMPAQUE | C23: UNIDADES | D23: UND MEDIDA | E23: COSTO UNITARIO | F23: TOTAL COSTO | G23: % PREC. DEFINIDO | H23: CODIGOS
B24: =IFERROR(VLOOKUP(H24,'[1]EMPAQUE PLANTA'!$A$2:$H$176,2,0),"") | C24: =+A24 -> 0 | D24: =IFERROR(VLOOKUP(H24,'[1]EMPAQUE PLANTA'!$A$2:$H$176,7,0),"") | E24: =IFERROR(VLOOKUP(H24,'[1]EMPAQUE PLANTA'!$A$2:$H$176,8,0),"") | F24: =IFERROR(E24*C24,"") | G24: =IFERROR(F24/$F$59,"")
B25: =IFERROR(VLOOKUP(H25,'[1]EMPAQUE PLANTA'!$A$2:$H$176,2,0),"") | C25: =+A25 -> 0 | D25: =IFERROR(VLOOKUP(H25,'[1]EMPAQUE PLANTA'!$A$2:$H$176,7,0),"") | E25: =IFERROR(VLOOKUP($H25,'[3]EMP PLANTA'!$A$2:$F$500,6,0),"") | F25: =IFERROR(E25*C25,"") | G25: =IFERROR(F25/$F$59,"")
B26: =IFERROR(VLOOKUP(H26,'[1]EMPAQUE PLANTA'!$A$2:$H$176,2,0),"") | C26: =+A26 -> 0 | D26: =IFERROR(VLOOKUP(H26,'[1]EMPAQUE PLANTA'!$A$2:$H$176,7,0),"") | E26: =IFERROR(VLOOKUP($H26,'[3]EMP PLANTA'!$A$2:$F$500,6,0),"") | F26: =IFERROR(E26*C26,"") | G26: =IFERROR(F26/$F$59,"")
B27: =IFERROR(VLOOKUP(H27,'[1]EMPAQUE PLANTA'!$A$2:$H$176,2,0),"") | C27: =+A27 -> 0 | D27: =IFERROR(VLOOKUP(H27,'[1]EMPAQUE PLANTA'!$A$2:$H$176,7,0),"") | E27: =IFERROR(VLOOKUP($H27,'[3]EMP PLANTA'!$A$2:$F$500,6,0),"") | F27: =IFERROR(E27*C27,"") | G27: =IFERROR(F27/$F$59,"")
B28: =IFERROR(VLOOKUP(H28,'[1]EMPAQUE PLANTA'!$A$2:$H$176,2,0),"") | C28: =+A28 -> 0 | D28: =IFERROR(VLOOKUP(H28,'[1]EMPAQUE PLANTA'!$A$2:$H$176,7,0),"") | E28: =IFERROR(VLOOKUP($H28,'[3]EMP PLANTA'!$A$2:$F$500,6,0),"") | F28: =IFERROR(E28*C28,"") | G28: =IFERROR(F28/$F$59,"")
B29: =IFERROR(VLOOKUP(H29,'[1]EMPAQUE PLANTA'!$A$2:$H$176,2,0),"") | C29: =+A29 -> 0 | D29: =IFERROR(VLOOKUP(H29,'[1]EMPAQUE PLANTA'!$A$2:$H$176,7,0),"") | E29: =IFERROR(VLOOKUP($H29,'[3]EMP PLANTA'!$A$2:$F$500,6,0),"") | F29: =IFERROR(E29*C29,"") | G29: =IFERROR(F29/$F$59,"")
B30: =IFERROR(VLOOKUP(H30,'[1]EMPAQUE PLANTA'!$A$2:$H$176,2,0),"")
A31: UNIDADES | B31: EMPAQUE SEMIELABORADOS | C31: UNIDADES | D31: UND MEDIDA | E31: COSTO UNITARIO | F31: TOTAL COSTO | G31: % PREC. DEFINIDO | H31: CODIGOS
A32: =+A17 -> 8252 | B32: PREMEZCLA SUPER ESPONJA KALUA | C32: =+A32 -> 8252 | D32: N/A | E32: =+'[2]Costo '!$E$69 -> 0.0023141533 | F32: =IFERROR(E32*C32,"") -> 19.096393 | G32: =IFERROR(F32/$F$58,"") -> 0.043400894
A33: =+A18 -> 0 | C33: =+A33 -> 0 | D33: N/A | E33: =IFERROR(VLOOKUP($H33,[3]SEMIELABORADOS!$A$1:$J$999,8,0),"") | F33: =IFERROR(E33*C33,"") | G33: =IFERROR(F33/$F$58,"")
A34: =+A19 -> 0 | C34: =+A34 -> 0 | D34: N/A | E34: =IFERROR(VLOOKUP($H34,[3]SEMIELABORADOS!$A$1:$J$999,8,0),"") | F34: =IFERROR(E34*C34,"") | G34: =IFERROR(F34/$F$58,"")
A35: =+A20 -> 0 | C35: =+A35 -> 0 | D35: N/A | E35: =IFERROR(VLOOKUP($H35,[3]SEMIELABORADOS!$A$1:$J$999,8,0),"") | F35: =IFERROR(E35*C35,"") | G35: =IFERROR(F35/$F$58,"")
A36: =+A21 -> 0 | C36: =+A36 -> 0 | D36: N/A | E36: =IFERROR(VLOOKUP($H36,[3]SEMIELABORADOS!$A$1:$J$999,8,0),"") | F36: =IFERROR(E36*C36,"") | G36: =IFERROR(F36/$F$58,"")
A38: UNIDADES | B38: MODI | C38: UNIDADES | E38: COSTO UNITARIO | F38: TOTAL COSTO | G38: % PREC. DEFINIDO | H38: CODIGOS
A39: =+A17 -> 8252 | B39: PREMEZCLA SUPER ESPONJA KALUA | C39: =+A39 -> 8252 | D39: N/A | E39: =+'[2]Costo '!$E$67 -> 0.019995153 | F39: =IFERROR(C39*E39,"") -> 165 | G39: =IFERROR(F39/$F$59,"") -> 0.0018044621
A40: =+A18 -> 0 | C40: =+A40 -> 0 | D40: N/A | E40: =IFERROR(VLOOKUP($H40,[3]SEMIELABORADOS!$A$1:$J$999,10,0),"") | F40: =IFERROR(C40*E40,"") | G40: =IFERROR(F40/$F$59,"")
A41: =+A19 -> 0 | C41: =+A41 -> 0 | D41: N/A | E41: =IFERROR(VLOOKUP($H41,[3]SEMIELABORADOS!$A$1:$J$999,10,0),"") | F41: =IFERROR(C41*E41,"") | G41: =IFERROR(F41/$F$59,"")
A42: =+A20 -> 0 | C42: =+A42 -> 0 | D42: N/A | E42: =IFERROR(VLOOKUP($H42,[3]SEMIELABORADOS!$A$1:$J$999,10,0),"") | F42: =IFERROR(C42*E42,"") | G42: =IFERROR(F42/$F$59,"")
A43: =+A21 -> 0 | C43: =+A43 -> 0 | D43: N/A | E43: =IFERROR(VLOOKUP($H43,[3]SEMIELABORADOS!$A$1:$J$999,10,0),"") | F43: =IFERROR(C43*E43,"") | G43: =IFERROR(F43/$F$59,"")
...

Sheet Costo Rosquete
E1: Precio Local | F1: Costo MP | G1: Costo EM | H1: Costo MO
E2: =IFERROR(O55,"") -> 1211.1627 | F2: =IFERROR(H46,"") -> 879.31449 | G2: =IFERROR(H47,"") -> 4.62306 | H2: =IFERROR(H49,"") -> 30.013732
A5: ESTRUCTURA DE COSTOS
F6: Fecha: | H6: =TODAY() -> 46058
A7: UNIDADES | B7: DESCRIPCION MAT.PRIMA | C7: UNIDADES | D7: UND MEDIDA | E7: COSTO UNITARIO | F7: TOTAL COSTO | G7: % PREC. DEFINIDO | H7: CODIGOS
B8: =IFERROR(VLOOKUP($H8,'[3]MP PLANTA'!$A$2:$F$500,2,0),"") | C8: =+A8 -> 0 | D8: =IFERROR(VLOOKUP($H8,'[3]MP PLANTA'!$A$2:$F$500,5,0),"") | E8: =IFERROR(VLOOKUP($H8,'[3]MP PLANTA'!$A$2:$F$500,6,0),"") | F8: =IFERROR(C8*E8,"") | G8: =IFERROR(F8/$F$59,"")
B9: =IFERROR(VLOOKUP($H9,'[3]MP PLANTA'!$A$2:$F$500,2,0),"") | C9: =+A9 -> 0 | D9: =IFERROR(VLOOKUP($H9,'[3]MP PLANTA'!$A$2:$F$500,5,0),"") | E9: =IFERROR(VLOOKUP($H9,'[3]MP PLANTA'!$A$2:$F$500,6,0),"") | F9: =IFERROR(C9*E9,"") | G9: =IFERROR(F9/$F$59,"")
B10: =IFERROR(VLOOKUP($H10,'[3]MP PLANTA'!$A$2:$F$500,2,0),"") | C10: =+A10 -> 0 | D10: =IFERROR(VLOOKUP($H10,'[3]MP PLANTA'!$A$2:$F$500,5,0),"") | E10: =IFERROR(VLOOKUP($H10,'[3]MP PLANTA'!$A$2:$F$500,6,0),"") | F10: =IFERROR(C10*E10,"") | G10: =IFERROR(F10/$F$59,"")
B11: =IFERROR(VLOOKUP($H11,'[3]MP PLANTA'!$A$2:$F$500,2,0),"") | C11: =+A11 -> 0 | D11: =IFERROR(VLOOKUP($H11,'[3]MP PLANTA'!$A$2:$F$500,5,0),"") | E11: =IFERROR(VLOOKUP($H11,'[3]MP PLANTA'!$A$2:$F$500,6,0),"") | F11: =IFERROR(C11*E11,"") | G11: =IFERROR(F11/$F$59,"")
B12: =IFERROR(VLOOKUP($H12,'[3]MP PLANTA'!$A$2:$F$500,2,0),"") | C12: =+A12 -> 0 | D12: =IFERROR(VLOOKUP($H12,'[3]MP PLANTA'!$A$2:$F$500,5,0),"") | E12: =IFERROR(VLOOKUP($H12,'[3]MP PLANTA'!$A$2:$F$500,6,0),"") | F12: =IFERROR(C12*E12,"") | G12: =IFERROR(F12/$F$59,"")
B13: =IFERROR(VLOOKUP($H13,'[3]MP PLANTA'!$A$2:$F$500,2,0),"") | C13: =+A13 -> 0 | D13: =IFERROR(VLOOKUP($H13,'[3]MP PLANTA'!$A$2:$F$500,5,0),"") | E13: =IFERROR(VLOOKUP($H13,'[3]MP PLANTA'!$A$2:$F$500,6,0),"") | F13: =IFERROR(C13*E13,"") | G13: =IFERROR(F13/$F$59,"")
B14: =IFERROR(VLOOKUP($H14,'[3]MP PLANTA'!$A$2:$F$500,2,0),"") | C14: =+A14 -> 0 | D14: =IFERROR(VLOOKUP($H14,'[3]MP PLANTA'!$A$2:$F$500,5,0),"") | E14: =IFERROR(VLOOKUP($H14,'[3]MP PLANTA'!$A$2:$F$500,6,0),"") | F14: =IFERROR(C14*E14,"") | G14: =IFERROR(F14/$F$59,"")
A16: UNIDADES | B16: MATERIA PRIMA SEMIELABORADOS | C16: UNIDADES | D16: UND MEDIDA | E16: COSTO UNITARIO | F16: TOTAL COSTO | G16: % PREC. DEFINIDO | H16: CODIGOS
A17: 40000 | B17: BATIDO SUPER ESPONJA | C17: =+A17 -> 40000 | D17: Gramos | E17: =+'COSTEO BATIDO'!E62 -> 2.2299239 | F17: =IFERROR(E17*C17,"") -> 89196.957 | G17: =IFERROR(F17/$F$59,"") -> 0.93835277 | H17: NUEVO
A18: 1651 | B18: =IFERROR(VLOOKUP($H18,[3]SEMIELABORADOS!$A$1:$J$999,2,0),"") -> MEZCLA ENGRASE MOLDES (29800g) | C18: =+A18 -> 1651 | D18: =IFERROR(VLOOKUP($H18,[3]SEMIELABORADOS!$A$1:$J$999,4,0),"") -> GRAMO | E18: =IFERROR(VLOOKUP($H18,[3]SEMIELABORADOS!$A$1:$J$999,6,0),"") -> 0.83127517 | F18: =IFERROR(E18*C18,"") -> 1372.4353 | G18: =IFERROR(F18/$F$59,"") -> 0.014438031 | H18: 95720
B19: =IFERROR(VLOOKUP($H19,[3]SEMIELABORADOS!$A$1:$J$999,2,0),"") | C19: =+A19 -> 0 | D19: =IFERROR(VLOOKUP($H19,[3]SEMIELABORADOS!$A$1:$J$999,4,0),"") | E19: =IFERROR(VLOOKUP($H19,[3]SEMIELABORADOS!$A$1:$J$999,6,0),"") | F19: =IFERROR(E19*C19,"") | G19: =IFERROR(F19/$F$59,"")
B20: =IFERROR(VLOOKUP($H20,[3]SEMIELABORADOS!$A$1:$J$999,2,0),"") | C20: =+A20 -> 0 | D20: =IFERROR(VLOOKUP($H20,[3]SEMIELABORADOS!$A$1:$J$999,4,0),"") | E20: =IFERROR(VLOOKUP($H20,[3]SEMIELABORADOS!$A$1:$J$999,6,0),"") | F20: =IFERROR(E20*C20,"") | G20: =IFERROR(F20/$F$59,"")
B21: =IFERROR(VLOOKUP($H21,[3]SEMIELABORADOS!$A$1:$J$999,2,0),"") | C21: =+A21 -> 0 | D21: =IFERROR(VLOOKUP($H21,[3]SEMIELABORADOS!$A$1:$J$999,4,0),"") | E21: =IFERROR(VLOOKUP($H21,[3]SEMIELABORADOS!$A$1:$J$999,6,0),"") | F21: =IFERROR(E21*C21,"") | G21: =IFERROR(F21/$F$59,"")
A23: UNIDADES | B23: EMPAQUE | C23: UNIDADES | D23: UND MEDIDA | E23: COSTO UNITARIO | F23: TOTAL COSTO | G23: % PREC. DEFINIDO | H23: CODIGOS
A24: 9 | B24: =IFERROR(VLOOKUP($H24,'[3]EMP PLANTA'!$A$2:$F$500,2,0),"") -> BOLSA TRANSPARENTE 56X96X1.80 | C24: =+A24 -> 9 | D24: =IFERROR(VLOOKUP($H24,'[3]EMP PLANTA'!$A$2:$F$500,5,0),"") -> UND | E24: =IFERROR(VLOOKUP($H24,'[3]EMP PLANTA'!$A$2:$F$500,6,0),"") -> 50 | F24: =IFERROR(E24*C24,"") -> 450 | G24: =IFERROR(F24/$F$59,"") -> 0.0047340039 | H24: 1950928
A25: 9 | B25: =IFERROR(VLOOKUP($H25,'[3]EMP PLANTA'!$A$2:$F$500,2,0),"") -> ETIQ.BLANCA 1 1/4 * 3/4 | C25: =+A25 -> 9 | D25: =IFERROR(VLOOKUP($H25,'[3]EMP PLANTA'!$A$2:$F$500,5,0),"") -> UND | E25: =IFERROR(VLOOKUP($H25,'[3]EMP PLANTA'!$A$2:$F$500,6,0),"") -> 0.616 | F25: =IFERROR(E25*C25,"") -> 5.544 | G25: =IFERROR(F25/$F$59,"") -> 5.8322928e-05 | H25: 0702069
A26: 9 | B26: =IFERROR(VLOOKUP($H26,'[3]EMP PLANTA'!$A$2:$F$500,2,0),"") -> ETIQ.FECHA VENCIMIENTO VERDE | C26: =+A26 -> 9 | D26: =IFERROR(VLOOKUP($H26,'[3]EMP PLANTA'!$A$2:$F$500,5,0),"") -> UND | E26: =IFERROR(VLOOKUP($H26,'[3]EMP PLANTA'!$A$2:$F$500,6,0),"") -> 0.21185444 | F26: =IFERROR(E26*C26,"") -> 1.90669 | G26: =IFERROR(F26/$F$59,"") -> 2.0058395e-05 | H26: 0702012
B27: =IFERROR(VLOOKUP($H27,'[3]EMP PLANTA'!$A$2:$F$500,2,0),"") | C27: =+A27 -> 0 | D27: =IFERROR(VLOOKUP($H27,'[3]EMP PLANTA'!$A$2:$F$500,5,0),"") | E27: =IFERROR(VLOOKUP($H27,'[3]EMP PLANTA'!$A$2:$F$500,6,0),"") | F27: =IFERROR(E27*C27,"") | G27: =IFERROR(F27/$F$59,"")
B28: =IFERROR(VLOOKUP($H28,'[3]EMP PLANTA'!$A$2:$F$500,2,0),"") | C28: =+A28 -> 0 | D28: =IFERROR(VLOOKUP($H28,'[3]EMP PLANTA'!$A$2:$F$500,5,0),"") | E28: =IFERROR(VLOOKUP($H28,'[3]EMP PLANTA'!$A$2:$F$500,6,0),"") | F28: =IFERROR(E28*C28,"") | G28: =IFERROR(F28/$F$59,"")
B29: =IFERROR(VLOOKUP($H29,'[3]EMP PLANTA'!$A$2:$F$500,2,0),"") | C29: =+A29 -> 0 | D29: =IFERROR(VLOOKUP($H29,'[3]EMP PLANTA'!$A$2:$F$500,5,0),"") | E29: =IFERROR(VLOOKUP($H29,'[3]EMP PLANTA'!$A$2:$F$500,6,0),"") | F29: =IFERROR(E29*C29,"") | G29: =IFERROR(F29/$F$59,"")
A31: UNIDADES | B31: EMPAQUE SEMIELABORADOS | C31: UNIDADES | D31: UND MEDIDA | E31: COSTO UNITARIO | F31: TOTAL COSTO | G31: % PREC. DEFINIDO | H31: CODIGOS
A32: =+A17 -> 40000 | B32: BATIDO SUPER ESPONJA | C32: =+A32 -> 40000 | D32: N/A | E32: =+'[4]COSTEO ROSQUETE'!$E$32 -> 0 | F32: =IFERROR(E32*C32,"") -> 0 | G32: =IFERROR(F32/$F$58,"") -> 0 | H32: 95343
A33: =+A18 -> 1651 | B33: MEZCLA ENGRASE MOLDES (29800g) | C33: =+A33 -> 1651 | D33: N/A | E33: =IFERROR(VLOOKUP($H33,[3]SEMIELABORADOS!$A$1:$J$999,8,0),"") -> 0.011341301 | F33: =IFERROR(E33*C33,"") -> 18.724487 | G33: =IFERROR(F33/$F$58,"") -> 0.0085111306 | H33: 95720
A34: =+A19 -> 0 | C34: =+A34 -> 0 | D34: N/A | E34: =IFERROR(VLOOKUP($H34,[3]SEMIELABORADOS!$A$1:$J$999,8,0),"") | F34: =IFERROR(E34*C34,"") | G34: =IFERROR(F34/$F$58,"")
A35: =+A20 -> 0 | C35: =+A35 -> 0 | D35: N/A | E35: =IFERROR(VLOOKUP($H35,[3]SEMIELABORADOS!$A$1:$J$999,8,0),"") | F35: =IFERROR(E35*C35,"") | G35: =IFERROR(F35/$F$58,"")
A36: =+A21 -> 0 | C36: =+A36 -> 0 | D36: N/A | E36: =IFERROR(VLOOKUP($H36,[3]SEMIELABORADOS!$A$1:$J$999,8,0),"") | F36: =IFERROR(E36*C36,"") | G36: =IFERROR(F36/$F$58,"")
A38: UNIDADES | B38: MODI | C38: UNIDADES | E38: COSTO UNITARIO | F38: TOTAL COSTO | G38: % PREC. DEFINIDO | H38: CODIGOS
A39: =+A17 -> 40000 | B39: BATIDO SUPER ESPONJA | C39: =+A39 -> 40000 | D39: N/A | E39: =+'[4]COSTEO ROSQUETE'!$E$39 -> 0.02 | F39: =IFERROR(C39*E39,"") -> 800 | G39: =IFERROR(F39/$F$59,"") -> 0.008416007 | H39: 95343
A40: =+A18 -> 1651 | B40: MEZCLA ENGRASE MOLDES (29800g) | C40: =+A40 -> 1651 | D40: N/A | E40: =IFERROR(VLOOKUP($H40,[3]SEMIELABORADOS!$A$1:$J$999,10,0),"") -> 0.055369128 | F40: =IFERROR(C40*E40,"") -> 91.41443 | G40: =IFERROR(F40/$F$59,"") -> 0.00096168059 | H40: 95720
A41: =+A19 -> 0 | C41: =+A41 -> 0 | D41: N/A | E41: =IFERROR(VLOOKUP($H41,[3]SEMIELABORADOS!$A$1:$J$999,10,0),"") | F41: =IFERROR(C41*E41,"") | G41: =IFERROR(F41/$F$59,"")
A42: =+A20 -> 0 | C42: =+A42 -> 0 | D42: N/A | E42: =IFERROR(VLOOKUP($H42,[3]SEMIELABORADOS!$A$1:$J$999,10,0),"") | F42: =IFERROR(C42*E42,"") | G42: =IFERROR(F42/$F$59,"")
A43: =+A21 -> 0 | C43: =+A43 -> 0 | D43: N/A | E43: =IFERROR(VLOOKUP($H43,[3]SEMIELABORADOS!$A$1:$J$999,10,0),"") | F43: =IFERROR(C43*E43,"") | G43: =IFERROR(F43/$F$59,"")
A44: 1 | B44: MODI PREPARACION | C44: =+A44 -> 1 | D44: N/A | E44: =+F58 -> 2200 | F44: =IFERROR(C44*E44,"") -> 2200 | G44: =IFERROR(F44/$F$59,"") -> 0.023144019
B46: TOTAL MATERIA PRIMA | F46: =SUM(F8:F14,F17:F21) -> 90569.393 | G46: =+F46/$F$59 -> 0.9527908 | H46: =+F46/$D$53 -> 879.31449
B47: TOTAL EMPAQUE | F47: =SUM(F24:F29,F32:F36) -> 476.17518 | G47: =+F47/$F$59 -> 0.005009367 | H47: =+F47/$D$53 -> 4.62306 | K47: TOTAL MATERIA PRIMA + EMPAQUE | O47: =+F48 -> 91045.568
...

Sheet Hoja1
C1: SERVICIOS DE PASTELERIA S.A. | H1: CÓDIGO: | I1: ESP-RE-DES-037
C2: ESPECIFICACION DE RECETA | H2: REVISIÓN: | I2: 03
C3: SE00076 Crema Blanca Spoon con Café | H3: FECHA DE APROBACIÓN: | I3: 45613
C4: Elaborado | D4: Javier Tong, Chef
C5: Aprobado | D5: Esteban Cartin, Gte Manufactura
A6: AREA QUE PRODUCE: | D6: Decoración | G6: AREA QUE EMPACA: | I6: Decoracion
A7: # Código | B7: # Código Netsuite | C7: Descripción del ingrediente | D7: Marca | E7: Unidad Internacional | G7: Medida alternativa | I7: Costo - Referencia
E8: Cantidad | F8: Unidad medida | G8: Cantidad | H8: Unidad medida | I8: Colones
C9: Ensamble
A10: 95717 | B10: SE00010 | C10: CREMA CHANTILLY BLANCA SPOON-IND KILO | D10: FAS | E10: 16580 | F10: g
A11: 512316 | B11: MP10091 | C11: CAFÉ INSTANTANEO (PAQ: 500 G) | D11: NESCAFE | E11: 110 | F11: g
C15: Decoración
C19: Empaque
A20: 0702123 | B20: EM10011 | C20: ETIQUETA BLANCA 2 5/8X1 15/16 (UND) | D20: CEMUSA | E20: 1 | F20: ud
D25: Cantidad | E25: Unidad
A26: PESO TOTAL OBTENIDO | D26: 16580 | E26: g | F26: Tiempo de Horneo:
A27: TIEMPO TOTAL DE PREPARACION | D27: 3 | E27: Minutos | F27: Horno:
A28: CANTIDAD DE PORCIONES OBTENIDAS | D28: 1 | E28: Tanda | F28: Temperatura de Horneo:
A29: PESO DE CADA PORCIÓN | D29: 16580 | E29: g | F29: Otros
A30: MERMA | D30: =SUM(E10:E11)-D26 -> 110 | E30: g
A31: PROCEDIMIENTO DE PREPARACION DE LA RECETA
A32: 1, Mezclar en la top cream, la crema montada (18°temperatura maxima) con el café y dar 6 vueltas, dejando que quede homogeneo.
A33: 2.- Guardar, etiquetar y Mantener en refrigeración hasta su uso.
A35: CONTROL DE CAMBIOS
A36: 2, Actualización tiempo de preparación y procedimiento de la receta.
A37: 3, Se actualiza cantidad de instantaneo.

Sheet Costo ensamble
E1: Precio Local | F1: Costo MP | G1: Costo EM | H1: Costo MO
E2: =IFERROR(O63,"") -> 6392.0439 | F2: =IFERROR(H54,"") -> 3882.9116 | G2: =IFERROR(H55,"") -> 484.75641 | H2: =IFERROR(H57,"") -> 458.78398
A5: ESTRUCTURA DE COSTOS
F6: Fecha: | H6: =TODAY() -> 46058
A7: UNIDADES | B7: DESCRIPCION MAT.PRIMA | C7: UNIDADES | D7: UND MEDIDA | E7: COSTO UNITARIO | F7: TOTAL COSTO | G7: % PREC. DEFINIDO | H7: CODIGOS | M7: Se cam
A8: 425 | B8: =IFERROR(VLOOKUP(H8,'[1]ARTICULOS MP PLANTA'!$A$2:$G$589,2,0),"") -> MANJAR LECHE CONDENSADA (PAQ: 4.5 K) | C8: =+A8 -> 425 | D8: =IFERROR(VLOOKUP(H8,'[1]ARTICULOS MP PLANTA'!$A$2:$G$589,6,0),"") -> Gramo | E8: =IFERROR(VLOOKUP(H8,'[1]ARTICULOS MP PLANTA'!$A$2:$G$589,7,0),"") -> 2.5188889 | F8: =IFERROR(C8*E8,"") -> 1070.5278 | G8: =IFERROR(F8/$F$67,"") -> 0.22162639 | H8: 1112431
A9: 2 | B9: =IFERROR(VLOOKUP(H9,'[1]ARTICULOS MP PLANTA'!$A$2:$G$589,2,0),"") -> CHOCOLATE TRIAN OLEAJE GRD (CAJA:200 UN) | C9: =+A9 -> 2 | D9: =IFERROR(VLOOKUP(H9,'[1]ARTICULOS MP PLANTA'!$A$2:$G$589,6,0),"") -> und | E9: =IFERROR(VLOOKUP(H9,'[1]ARTICULOS MP PLANTA'!$A$2:$G$589,7,0),"") -> 115 | F9: =IFERROR(C9*E9,"") -> 230 | G9: =IFERROR(F9/$F$67,"") -> 0.047615831 | H9: 1210464 | M9: 83.07
B10: STICK DORADO (CAJA:100 UND) | C10: =+A10 -> 0 | D10: UND | E10: 58.38 | F10: =IFERROR(C10*E10,"") -> 0 | G10: =IFERROR(F10/$F$67,"") -> 0 | H10: 10700013
B11: =IFERROR(VLOOKUP($H11,'[3]MP PLANTA'!$A$2:$F$500,2,0),"") | C11: =+A11 -> 0 | D11: =IFERROR(VLOOKUP($H11,'[3]MP PLANTA'!$A$2:$F$500,5,0),"") | E11: =IFERROR(VLOOKUP($H11,'[3]MP PLANTA'!$A$2:$F$500,6,0),"") | F11: =IFERROR(C11*E11,"") | G11: =IFERROR(F11/$F$67,"")
B12: =IFERROR(VLOOKUP($H12,'[3]MP PLANTA'!$A$2:$F$500,2,0),"") | C12: =+A12 -> 0 | D12: =IFERROR(VLOOKUP($H12,'[3]MP PLANTA'!$A$2:$F$500,5,0),"") | E12: =IFERROR(VLOOKUP($H12,'[3]MP PLANTA'!$A$2:$F$500,6,0),"") | F12: =IFERROR(C12*E12,"") | G12: =IFERROR(F12/$F$67,"")
B13: =IFERROR(VLOOKUP($H13,'[3]MP PLANTA'!$A$2:$F$500,2,0),"") | C13: =+A13 -> 0 | D13: =IFERROR(VLOOKUP($H13,'[3]MP PLANTA'!$A$2:$F$500,5,0),"") | E13: =IFERROR(VLOOKUP($H13,'[3]MP PLANTA'!$A$2:$F$500,6,0),"") | F13: =IFERROR(C13*E13,"") | G13: =IFERROR(F13/$F$67,"")
M14: =+M9*3 -> 249.21
A15: UNIDADES | B15: MATERIA PRIMA SEMIELABORADOS | C15: UNIDADES | D15: UND MEDIDA | E15: COSTO UNITARIO | F15: TOTAL COSTO | G15: % PREC. DEFINIDO | H15: CODIGOS
A16: 1.5 | B16: ROSQUETE ESPONJA KALUA 380G | C16: =+A16 -> 1.5 | D16: UND | E16: =+'Costo Rosquete'!H46 -> 879.31449 | F16: =IFERROR(E16*C16,"") -> 1318.9717 | G16: =IFERROR(F16/$F$67,"") -> 0.27306059
A17: 180 | B17: =IFERROR(VLOOKUP($H17,[3]SEMIELABORADOS!$A$1:$J$999,2,0),"") -> ALMIBAR CON LICOR DE CAFE (3000g) | C17: =+A17 -> 180 | D17: =IFERROR(VLOOKUP($H17,[3]SEMIELABORADOS!$A$1:$J$999,4,0),"") -> GRAMO | E17: =IFERROR(VLOOKUP($H17,[3]SEMIELABORADOS!$A$1:$J$999,6,0),"") -> 3.1518526 | F17: =IFERROR(E17*C17,"") -> 567.33347 | G17: =IFERROR(F17/$F$67,"") -> 0.11745241 | H17: 96398
A18: 240 | B18: =IFERROR(VLOOKUP($H18,[3]SEMIELABORADOS!$A$1:$J$999,2,0),"") -> CREMA CHANTILLY CAFE (21 Kg) | C18: =+A18 -> 240 | D18: =IFERROR(VLOOKUP($H18,[3]SEMIELABORADOS!$A$1:$J$999,4,0),"") -> GRAMO | E18: =IFERROR(VLOOKUP($H18,[3]SEMIELABORADOS!$A$1:$J$999,6,0),"") -> 1.7820269 | F18: =IFERROR(E18*C18,"") -> 427.68644 | G18: =IFERROR(F18/$F$67,"") -> 0.088541937 | H18: 95719
A19: 80 | B19: GALLETA MARIA CON CHOCOLATE BLANCO | C19: =+A19 -> 80 | D19: GRAMO | E19: =+[5]Hoja1!$E$62 -> 2.6615006 | F19: =IFERROR(E19*C19,"") -> 212.92005 | G19: =IFERROR(F19/$F$67,"") -> 0.044079848 | H19: 96453
A20: 15 | B20: =IFERROR(VLOOKUP($H20,[3]SEMIELABORADOS!$A$1:$J$999,2,0),"") -> CREMA CHANTILLY BLANCA SPOON-IND (20800g) | C20: =+A20 -> 15 | D20: =IFERROR(VLOOKUP($H20,[3]SEMIELABORADOS!$A$1:$J$999,4,0),"") -> GRAMO | E20: =IFERROR(VLOOKUP($H20,[3]SEMIELABORADOS!$A$1:$J$999,6,0),"") -> 1.7037165 | F20: =IFERROR(E20*C20,"") -> 25.555747 | G20: =IFERROR(F20/$F$67,"") -> 0.0052906875 | H20: 95717
A21: 20 | B21: =IFERROR(VLOOKUP($H21,[3]SEMIELABORADOS!$A$1:$J$999,2,0),"") -> MEZCLA DULCE LECHE CON AGUA | C21: =+A21 -> 20 | D21: =IFERROR(VLOOKUP($H21,[3]SEMIELABORADOS!$A$1:$J$999,4,0),"") -> GRAMO | E21: =IFERROR(VLOOKUP($H21,[3]SEMIELABORADOS!$A$1:$J$999,6,0),"") -> 1.4958215 | F21: =IFERROR(E21*C21,"") -> 29.91643 | G21: =IFERROR(F21/$F$67,"") -> 0.0061934594 | H21: 910000005
B22: =IFERROR(VLOOKUP($H22,[3]SEMIELABORADOS!$A$1:$J$999,2,0),"") | C22: =+A22 -> 0 | D22: =IFERROR(VLOOKUP($H22,[3]SEMIELABORADOS!$A$1:$J$999,4,0),"") | E22: =IFERROR(VLOOKUP($H22,[3]SEMIELABORADOS!$A$1:$J$999,6,0),"") | F22: =IFERROR(E22*C22,"") | G22: =IFERROR(F22/$F$67,"")
B23: =IFERROR(VLOOKUP($H23,[3]SEMIELABORADOS!$A$1:$J$999,2,0),"") | C23: =+A23 -> 0 | D23: =IFERROR(VLOOKUP($H23,[3]SEMIELABORADOS!$A$1:$J$999,4,0),"") | E23: =IFERROR(VLOOKUP($H23,[3]SEMIELABORADOS!$A$1:$J$999,6,0),"") | F23: =IFERROR(E23*C23,"") | G23: =IFERROR(F23/$F$67,"")
A25: UNIDADES | B25: EMPAQUE | C25: UNIDADES | D25: UND MEDIDA | E25: COSTO UNITARIO | F25: TOTAL COSTO | G25: % PREC. DEFINIDO | H25: CODIGOS
A26: 1 | B26: =IFERROR(VLOOKUP(H26,'[1]EMPAQUE PLANTA'!$A$2:$H$176,2,0),"") -> ORLA CARTON 10" DORADA UND | C26: =+A26 -> 1 | D26: =IFERROR(VLOOKUP(H26,'[1]EMPAQUE PLANTA'!$A$2:$H$176,7,0),"") -> UND | E26: =IFERROR(VLOOKUP(H26,'[1]EMPAQUE PLANTA'!$A$2:$H$176,8,0),"") -> 111 | F26: =IFERROR(E26*C26,"") -> 111 | G26: =IFERROR(F26/$F$67,"") -> 0.022979814 | H26: 1950692
A27: 1 | B27: =IFERROR(VLOOKUP(H27,'[1]EMPAQUE PLANTA'!$A$2:$H$176,2,0),"") -> QUEQUERA 10" MEDIA (CAJA:66 UND) | C27: =+A27 -> 1 | D27: =IFERROR(VLOOKUP(H27,'[1]EMPAQUE PLANTA'!$A$2:$H$176,7,0),"") -> UND | E27: =IFERROR(VLOOKUP(H27,'[1]EMPAQUE PLANTA'!$A$2:$H$176,8,0),"") -> 313.41 | F27: =IFERROR(E27*C27,"") -> 313.41 | G27: =IFERROR(F27/$F$67,"") -> 0.064883816 | H27: 1942315
A28: 1 | B28: =IFERROR(VLOOKUP($H28,'[3]EMP PLANTA'!$A$2:$F$500,2,0),"") -> ETIQ.FECHA VENCIMIENTO VERDE | C28: =+A28 -> 1 | D28: =IFERROR(VLOOKUP($H28,'[3]EMP PLANTA'!$A$2:$F$500,5,0),"") -> UND | E28: =IFERROR(VLOOKUP($H28,'[3]EMP PLANTA'!$A$2:$F$500,6,0),"") -> 0.21185444 | F28: =IFERROR(E28*C28,"") -> 0.21185444 | G28: =IFERROR(F28/$F$67,"") -> 4.3859241e-05 | H28: 0702012
A29: 1 | B29: =IFERROR(VLOOKUP($H29,'[3]EMP PLANTA'!$A$2:$F$500,2,0),"") -> ETIQUETA IMP. SPOON GRANDE V-272 | C29: =+A29 -> 1 | D29: =IFERROR(VLOOKUP($H29,'[3]EMP PLANTA'!$A$2:$F$500,5,0),"") -> UND | E29: =IFERROR(VLOOKUP($H29,'[3]EMP PLANTA'!$A$2:$F$500,6,0),"") -> 49.742 | F29: =IFERROR(E29*C29,"") -> 49.742 | G29: =IFERROR(F29/$F$67,"") -> 0.010297855 | H29: 702175
A30: 1 | B30: =IFERROR(VLOOKUP($H30,'[3]EMP PLANTA'!$A$2:$F$500,2,0),"") -> ETIQ.BLANCA 1 1/4 * 3/4 | C30: =+A30 -> 1 | D30: =IFERROR(VLOOKUP($H30,'[3]EMP PLANTA'!$A$2:$F$500,5,0),"") -> UND | E30: =IFERROR(VLOOKUP($H30,'[3]EMP PLANTA'!$A$2:$F$500,6,0),"") -> 0.616 | F30: =IFERROR(E30*C30,"") -> 0.616 | G30: =IFERROR(F30/$F$67,"") -> 0.00012752762 | H30: 0702069
B31: =IFERROR(VLOOKUP($H31,'[3]EMP PLANTA'!$A$2:$F$500,2,0),"") | C31: =+A31 -> 0 | D31: =IFERROR(VLOOKUP($H31,'[3]EMP PLANTA'!$A$2:$F$500,5,0),"") | E31: =IFERROR(VLOOKUP($H31,'[3]EMP PLANTA'!$A$2:$F$500,6,0),"") | F31: =IFERROR(E31*C31,"") | G31: =IFERROR(F31/$F$67,"")
A33: UNIDADES | B33: EMPAQUE SEMIELABORADOS | C33: UNIDADES | D33: UND MEDIDA | E33: COSTO UNITARIO | F33: TOTAL COSTO | G33: % PREC. DEFINIDO | H33: CODIGOS
A34: =+A16 -> 1.5 | B34: ROSQUETE ESPONJA KALUA 380G | C34: =+A34 -> 1.5 | D34: N/A | E34: =+'Costo Rosquete'!H47 -> 4.62306 | F34: =IFERROR(E34*C34,"") -> 6.93459 | G34: =IFERROR(F34/$F$66,"") -> 0.018011922
A35: =+A17 -> 180 | B35: ALMIBAR CON LICOR DE CAFE (3000g) | C35: =+A35 -> 180 | D35: N/A | E35: =IFERROR(VLOOKUP($H35,[3]SEMIELABORADOS!$A$1:$J$999,8,0),"") -> 0.0065836962 | F35: =IFERROR(E35*C35,"") -> 1.1850653 | G35: =IFERROR(F35/$F$66,"") -> 0.0030780917 | H35: 96398
A36: =+A18 -> 240 | B36: CREMA CHANTILLY CAFE (21 Kg) | C36: =+A36 -> 240 | D36: N/A | E36: =IFERROR(VLOOKUP($H36,[3]SEMIELABORADOS!$A$1:$J$999,8,0),"") -> 0 | F36: =IFERROR(E36*C36,"") -> 0 | G36: =IFERROR(F36/$F$66,"") -> 0 | H36: 95719
A37: =+A19 -> 80 | B37: GALLETA MARIA CON CHOCOLATE BLANCO | C37: =+A37 -> 80 | D37: N/A | E37: =+[5]Hoja1!$E$69 -> 0 | F37: =IFERROR(E37*C37,"") -> 0 | G37: =IFERROR(F37/$F$66,"") -> 0 | H37: 96453
A38: =+A20 -> 15 | B38: CREMA CHANTILLY BLANCA SPOON-IND (20800g) | C38: =+A38 -> 15 | D38: N/A | E38: =IFERROR(VLOOKUP($H38,[3]SEMIELABORADOS!$A$1:$J$999,8,0),"") -> 5.7644231e-05 | F38: =IFERROR(E38*C38,"") -> 0.00086466346 | G38: =IFERROR(F38/$F$66,"") -> 2.2458791e-06 | H38: 95717
A39: =+A21 -> 20 | B39: MEZCLA DULCE LECHE CON AGUA | C39: =+A39 -> 20 | D39: N/A | E39: =IFERROR(VLOOKUP($H39,[3]SEMIELABORADOS!$A$1:$J$999,8,0),"") -> 0.082801667 | F39: =IFERROR(E39*C39,"") -> 1.6560333 | G39: =IFERROR(F39/$F$66,"") -> 0.0043013853 | H39: 910000005
A40: =+A22 -> 0 | C40: =+A40 -> 0 | D40: N/A | E40: =IFERROR(VLOOKUP($H40,[3]SEMIELABORADOS!$A$1:$J$999,8,0),"") | F40: =IFERROR(E40*C40,"") | G40: =IFERROR(F40/$F$66,"")
A41: =+A23 -> 0 | C41: =+A41 -> 0 | D41: N/A | E41: =IFERROR(VLOOKUP($H41,[3]SEMIELABORADOS!$A$1:$J$999,8,0),"") | F41: =IFERROR(E41*C41,"") | G41: =IFERROR(F41/$F$66,"")
A43: UNIDADES | B43: MODI | C43: UNIDADES | E43: COSTO UNITARIO | F43: TOTAL COSTO | G43: % PREC. DEFINIDO | H43: CODIGOS
A44: =+A16 -> 1.5 | B44: ROSQUETE ESPONJA KALUA 380G | C44: =+A44 -> 1.5 | D44: N/A | E44: =+'Costo Rosquete'!H49 -> 30.013732 | F44: =IFERROR(C44*E44,"") -> 45.020598 | G44: =IFERROR(F44/$F$67,"") -> 0.0093204052
A45: =+A17 -> 180 | B45: ALMIBAR CON LICOR DE CAFE (3000g) | C45: =+A45 -> 180 | D45: N/A | E45: =+'[6]COSTEO ALMIBAR'!$E$45 -> 0.035216187 | F45: =IFERROR(C45*E45,"") -> 6.3389137 | G45: =IFERROR(F45/$F$67,"") -> 0.0013123158 | H45: 96398
...

Sheet Precio Local
H1: TOTAL COSTO | I1: =+G51 -> 6551.845
B5: ESTRUCTURA DE COSTOS
B6: LOCALES
G7: Fecha: | I7: =TODAY() -> 46058
B8: UNIDADES | C8: DESCRIPCION SEMIELABORADOS PLANTA | D8: UNIDADES | E8: UND MEDIDA | F8: COSTO UNITARIO | G8: TOTAL COSTO | H8: % PREC. DEFINIDO | I8: CODIGOS
B9: 1 | C9: Torta Kalua | D9: =+B9 -> 1 | E9: UND | F9: =+'Costo ensamble'!O63 -> 6392.0439 | G9: =IFERROR(D9*F9,"") -> 6392.0439 | H9: =IFERROR(G9/$G$53,"") -> 0.51778461
C10: =IFERROR(VLOOKUP($I10,'[3]PROD PLANTA LOCALES'!$A$1:$I$494,2,0),"") | D10: =+B10 -> 0 | E10: =IFERROR(VLOOKUP($I10,'[3]PROD PLANTA LOCALES'!$A$1:$I$494,9,0),"") | F10: =IFERROR(VLOOKUP($I10,'[3]PROD PLANTA LOCALES'!$A$1:$I$494,8,0),"") | G10: =IFERROR(D10*F10,"") | H10: =IFERROR(G10/$G$53,"")
C11: =IFERROR(VLOOKUP($I11,'[3]PROD PLANTA LOCALES'!$A$1:$I$494,2,0),"") | D11: =+B11 -> 0 | E11: =IFERROR(VLOOKUP($I11,'[3]PROD PLANTA LOCALES'!$A$1:$I$494,9,0),"") | F11: =IFERROR(VLOOKUP($I11,'[3]PROD PLANTA LOCALES'!$A$1:$I$494,8,0),"") | G11: =IFERROR(D11*F11,"") | H11: =IFERROR(G11/$G$53,"")
C12: =IFERROR(VLOOKUP($I12,'[3]PROD PLANTA LOCALES'!$A$1:$I$494,2,0),"") | D12: =+B12 -> 0 | E12: =IFERROR(VLOOKUP($I12,'[3]PROD PLANTA LOCALES'!$A$1:$I$494,9,0),"") | F12: =IFERROR(VLOOKUP($I12,'[3]PROD PLANTA LOCALES'!$A$1:$I$494,8,0),"") | G12: =IFERROR(D12*F12,"") | H12: =IFERROR(G12/$G$53,"")
C13: =IFERROR(VLOOKUP($I13,'[3]PROD PLANTA LOCALES'!$A$1:$I$494,2,0),"") | D13: =+B13 -> 0 | E13: =IFERROR(VLOOKUP($I13,'[3]PROD PLANTA LOCALES'!$A$1:$I$494,9,0),"") | F13: =IFERROR(VLOOKUP($I13,'[3]PROD PLANTA LOCALES'!$A$1:$I$494,8,0),"") | G13: =IFERROR(D13*F13,"") | H13: =IFERROR(G13/$G$53,"")
C14: =IFERROR(VLOOKUP($I14,'[3]PROD PLANTA LOCALES'!$A$1:$I$494,2,0),"") | D14: =+B14 -> 0 | E14: =IFERROR(VLOOKUP($I14,'[3]PROD PLANTA LOCALES'!$A$1:$I$494,9,0),"") | F14: =IFERROR(VLOOKUP($I14,'[3]PROD PLANTA LOCALES'!$A$1:$I$494,8,0),"") | G14: =IFERROR(D14*F14,"") | H14: =IFERROR(G14/$G$53,"")
B16: UNIDADES | C16: DESCRIPCION MAT.PRIMA LOCAL | D16: UNIDADES | E16: UND MEDIDA | F16: COSTO UNITARIO | G16: TOTAL COSTO | H16: % PREC. DEFINIDO | I16: CODIGOS
C17: =IFERROR(VLOOKUP($I17,'[3]MP LOCALES'!$A$2:$F$503,2,0),"") | D17: =+B17 -> 0 | E17: =IFERROR(VLOOKUP($I17,'[3]MP LOCALES'!$A$2:$F$503,5,0),"") | F17: =IFERROR(VLOOKUP($I17,'[3]MP LOCALES'!$A$2:$F$503,6,0),"") | G17: =IFERROR(D17*F17,"") | H17: =IFERROR(G17/$G$53,"")
C18: =IFERROR(VLOOKUP($I18,'[3]MP LOCALES'!$A$2:$F$503,2,0),"") | D18: =+B18 -> 0 | E18: =IFERROR(VLOOKUP($I18,'[3]MP LOCALES'!$A$2:$F$503,5,0),"") | F18: =IFERROR(VLOOKUP($I18,'[3]MP LOCALES'!$A$2:$F$503,6,0),"") | G18: =IFERROR(D18*F18,"") | H18: =IFERROR(G18/$G$53,"")
C19: =IFERROR(VLOOKUP($I19,'[3]MP LOCALES'!$A$2:$F$503,2,0),"") | D19: =+B19 -> 0 | E19: =IFERROR(VLOOKUP($I19,'[3]MP LOCALES'!$A$2:$F$503,5,0),"") | F19: =IFERROR(VLOOKUP($I19,'[3]MP LOCALES'!$A$2:$F$503,6,0),"") | G19: =IFERROR(D19*F19,"") | H19: =IFERROR(G19/$G$53,"")
C20: =IFERROR(VLOOKUP($I20,'[3]MP LOCALES'!$A$2:$F$503,2,0),"") | D20: =+B20 -> 0 | E20: =IFERROR(VLOOKUP($I20,'[3]MP LOCALES'!$A$2:$F$503,5,0),"") | F20: =IFERROR(VLOOKUP($I20,'[3]MP LOCALES'!$A$2:$F$503,6,0),"") | G20: =IFERROR(D20*F20,"") | H20: =IFERROR(G20/$G$53,"")
B22: UNIDAD | C22: EMPAQUE | D22: UNIDAD | E22: UND MEDIDA | F22: COSTO UNITARIO | G22: TOTAL COSTO | H22: % PREC. DEFINIDO | I22: CÓDIGOS
C23: DOMICILIO Y LLEVAR
B24: 0.3 | C24: =IFERROR(VLOOKUP($I24,'[3]EMP LOCALES'!$A$2:$F$500,2,0),"") | D24: =+B24 -> 0.3 | E24: =IFERROR(VLOOKUP($I24,'[3]EMP LOCALES'!$A$2:$F$500,5,0),"") | F24: =IFERROR(VLOOKUP($I24,'[3]EMP LOCALES'!$A$2:$F$500,6,0),"") | G24: =IFERROR(F24*D24,"") | H24: =IFERROR(G24/$G$53,"")
B25: 0.3 | C25: =IFERROR(VLOOKUP($I25,'[3]EMP LOCALES'!$A$2:$F$500,2,0),"") | D25: =+B25 -> 0.3 | E25: =IFERROR(VLOOKUP($I25,'[3]EMP LOCALES'!$A$2:$F$500,5,0),"") | F25: =IFERROR(VLOOKUP($I25,'[3]EMP LOCALES'!$A$2:$F$500,6,0),"") | G25: =IFERROR(F25*D25,"") | H25: =IFERROR(G25/$G$53,"")
B26: 0.3 | C26: =IFERROR(VLOOKUP($I26,'[3]EMP LOCALES'!$A$2:$F$500,2,0),"") | D26: =+B26 -> 0.3 | E26: =IFERROR(VLOOKUP($I26,'[3]EMP LOCALES'!$A$2:$F$500,5,0),"") | F26: =IFERROR(VLOOKUP($I26,'[3]EMP LOCALES'!$A$2:$F$500,6,0),"") | G26: =IFERROR(F26*D26,"") | H26: =IFERROR(G26/$G$53,"")
B27: 0.3 | C27: =IFERROR(VLOOKUP($I27,'[3]EMP LOCALES'!$A$2:$F$500,2,0),"") | D27: =+B27 -> 0.3 | E27: =IFERROR(VLOOKUP($I27,'[3]EMP LOCALES'!$A$2:$F$500,5,0),"") | F27: =IFERROR(VLOOKUP($I27,'[3]EMP LOCALES'!$A$2:$F$500,6,0),"") | G27: =IFERROR(F27*D27,"") | H27: =IFERROR(G27/$G$53,"")
B28: 0.3 | C28: =IFERROR(VLOOKUP($I28,'[3]EMP LOCALES'!$A$2:$F$500,2,0),"") | D28: =+B28 -> 0.3 | E28: =IFERROR(VLOOKUP($I28,'[3]EMP LOCALES'!$A$2:$F$500,5,0),"") | F28: =IFERROR(VLOOKUP($I28,'[3]EMP LOCALES'!$A$2:$F$500,6,0),"") | G28: =IFERROR(F28*D28,"") | H28: =IFERROR(G28/$G$53,"")
B29: 0.3 | C29: =IFERROR(VLOOKUP($I29,'[3]EMP LOCALES'!$A$2:$F$500,2,0),"") | D29: =+B29 -> 0.3 | E29: =IFERROR(VLOOKUP($I29,'[3]EMP LOCALES'!$A$2:$F$500,5,0),"") | F29: =IFERROR(VLOOKUP($I29,'[3]EMP LOCALES'!$A$2:$F$500,6,0),"") | G29: =IFERROR(F29*D29,"") | H29: =IFERROR(G29/$G$53,"")
B30: 0.3 | C30: =IFERROR(VLOOKUP($I30,'[3]EMP LOCALES'!$A$2:$F$500,2,0),"") | D30: =+B30 -> 0.3 | E30: =IFERROR(VLOOKUP($I30,'[3]EMP LOCALES'!$A$2:$F$500,5,0),"") | F30: =IFERROR(VLOOKUP($I30,'[3]EMP LOCALES'!$A$2:$F$500,6,0),"") | G30: =IFERROR(F30*D30,"") | H30: =IFERROR(G30/$G$53,"")
B31: 0.3 | C31: =IFERROR(VLOOKUP($I31,'[3]EMP LOCALES'!$A$2:$F$500,2,0),"") | D31: =+B31 -> 0.3 | E31: =IFERROR(VLOOKUP($I31,'[3]EMP LOCALES'!$A$2:$F$500,5,0),"") | F31: =IFERROR(VLOOKUP($I31,'[3]EMP LOCALES'!$A$2:$F$500,6,0),"") | G31: =IFERROR(F31*D31,"") | H31: =IFERROR(G31/$G$53,"")
C32: FOOD COURT
B33: 0.05 | C33: =IFERROR(VLOOKUP($I33,'[3]EMP LOCALES'!$A$2:$F$500,2,0),"") | D33: =+B33 -> 0.05 | E33: =IFERROR(VLOOKUP($I33,'[3]EMP LOCALES'!$A$2:$F$500,5,0),"") | F33: =IFERROR(VLOOKUP($I33,'[3]EMP LOCALES'!$A$2:$F$500,6,0),"") | G33: =IFERROR(F33*D33,"") | H33: =IFERROR(G33/$G$53,"")
B34: 0.05 | C34: =IFERROR(VLOOKUP($I34,'[3]EMP LOCALES'!$A$2:$F$500,2,0),"") | D34: =+B34 -> 0.05 | E34: =IFERROR(VLOOKUP($I34,'[3]EMP LOCALES'!$A$2:$F$500,5,0),"") | F34: =IFERROR(VLOOKUP($I34,'[3]EMP LOCALES'!$A$2:$F$500,6,0),"") | G34: =IFERROR(F34*D34,"") | H34: =IFERROR(G34/$G$53,"")
B35: 0.05 | C35: =IFERROR(VLOOKUP($I35,'[3]EMP LOCALES'!$A$2:$F$500,2,0),"") | D35: =+B35 -> 0.05 | E35: =IFERROR(VLOOKUP($I35,'[3]EMP LOCALES'!$A$2:$F$500,5,0),"") | F35: =IFERROR(VLOOKUP($I35,'[3]EMP LOCALES'!$A$2:$F$500,6,0),"") | G35: =IFERROR(F35*D35,"") | H35: =IFERROR(G35/$G$53,"")
B36: 0.05 | C36: =IFERROR(VLOOKUP($I36,'[3]EMP LOCALES'!$A$2:$F$500,2,0),"") | D36: =+B36 -> 0.05 | E36: =IFERROR(VLOOKUP($I36,'[3]EMP LOCALES'!$A$2:$F$500,5,0),"") | F36: =IFERROR(VLOOKUP($I36,'[3]EMP LOCALES'!$A$2:$F$500,6,0),"") | G36: =IFERROR(F36*D36,"") | H36: =IFERROR(G36/$G$53,"")
B37: 0.05 | C37: =IFERROR(VLOOKUP($I37,'[3]EMP LOCALES'!$A$2:$F$500,2,0),"") | D37: =+B37 -> 0.05 | E37: =IFERROR(VLOOKUP($I37,'[3]EMP LOCALES'!$A$2:$F$500,5,0),"") | F37: =IFERROR(VLOOKUP($I37,'[3]EMP LOCALES'!$A$2:$F$500,6,0),"") | G37: =IFERROR(F37*D37,"") | H37: =IFERROR(G37/$G$53,"")
B38: 0.05 | C38: =IFERROR(VLOOKUP($I38,'[3]EMP LOCALES'!$A$2:$F$500,2,0),"") | D38: =+B38 -> 0.05 | E38: =IFERROR(VLOOKUP($I38,'[3]EMP LOCALES'!$A$2:$F$500,5,0),"") | F38: =IFERROR(VLOOKUP($I38,'[3]EMP LOCALES'!$A$2:$F$500,6,0),"") | G38: =IFERROR(F38*D38,"") | H38: =IFERROR(G38/$G$53,"")
B40: TOTAL MATERIA PRIMA PLANTA | G40: =SUM(G9:G14) -> 6392.0439 | H40: =+G40/$G$53 -> 0.51778461
B41: TOTAL MATERIA PRIMA LOCAL | F41: =SUM(F17:F20) -> 0 | G41: =SUM(G17:G20) -> 0 | H41: =+G41/$G$53 -> 0
B42: TOTAL MATERIA PRIMA | G42: =SUM(G40:G41) -> 6392.0439 | H42: =+G42/$G$53 -> 0.51778461
B43: TOTAL EMPAQUE | G43: =SUM(G24:G38) -> 0 | H43: =+G43/$G$53 -> 0
B44: TOTAL MATERIA PRIMA + EMPAQUE | G44: =SUM(G42:G43) -> 6392.0439 | H44: =+G44/$G$53 -> 0.51778461
B48: TOTAL MATERIA PRIMA | G48: =+G42 -> 6392.0439 | H48: =+G48/$G$53 -> 0.51778461
B49: EMPAQUE | F49: Local | G49: =+G43 -> 0 | H49: =+G49/$G$53 -> 0
...

Sheet Precio IND
B2: ESTRUCTURA DE COSTOS
B3: INDUSTRIA
F4: Fecha:
B5: UNIDAD | C5: DESCRIPCION MAT.PRIMA | D5: UNIDAD | E5: COSTO UNITARIO | F5: TOTAL COSTO | G5: % PREC. DEFINIDO | H5: CÓDIGOS
B6: 1 | C6: Torta Kalua Dia del padre | D6: =+B6 -> 1 | E6: =+'Costo ensamble'!H54 -> 3882.9116 | F6: =+D6*E6 -> 3882.9116 | G6: =+F6/$F$23 -> 0.62790745 | H6: SPOON
B8: UNIDAD | C8: EMPAQUE | D8: UNIDAD | E8: COSTO UNITARIO | F8: TOTAL COSTO | G8: % PREC. DEFINIDO | H8: CÓDIGOS
B9: 1 | C9: EMPAQUE PLANTA | D9: =+B9 -> 1 | E9: =+'Costo ensamble'!H55 -> 484.75641 | F9: =+D9*E9 -> 484.75641 | G9: =+F9/$F$23 -> 0.078390184 | H9: PLANTA
C11: TOTAL MATERIA PRIMA | F11: =SUM(F6) -> 3882.9116 | G11: =+F11/$F$23 -> 0.62790745
C12: TOTAL EMPAQUE | F12: =SUM(F9) -> 484.75641 | G12: =+F12/$F$23 -> 0.078390184
C13: TOTAL MATERIA PRIMA + EMPAQUE | F13: =SUM(F11:F12) -> 4367.6681 | G13: =+F13/$F$23 -> 0.70629763
B15: TOTAL MATERIA PRIMA + EMPAQUE | E15: Planta | F15: =+F13 -> 4367.6681 | G15: =+F15/$F$23 -> 0.70629763
C16: MODI PLANTA | F16: =+'Costo ensamble'!H57 -> 458.78398 | G16: =+F16/$F$23 -> 0.074190171
C17: DESECHO | E17: 0 | F17: =+(F15+F16)*E17 -> 0 | G17: =+F17/$F$23 -> 0
C18: GAF | E18: 0 | F18: =+F16*E18 -> 0 | G18: =+F18/$F$23 -> 0
F19: =SUM(F15:F18) -> 4826.452 | G19: =+F19/$F$21 -> 0.8
C20: % MK | E20: 0.25 | F20: =+F19*E20 -> 1206.613 | G20: =+F20/$F$23 -> 0.19512195
C21: COSTO PLANTA | F21: =SUM(F19:F20) -> 6033.065 | G21: =+F21/$F$23 -> 0.97560976
C22: TRANSFERENCIA | E22: 0.025 | F22: =+F21*E22 -> 150.82663 | G22: =+F22/$F$23 -> 0.024390244
C23: PRECIO DE VENTA PLANTA A LOCAL | F23: =SUM(F21:F22) -> 6183.8917 | G23: =+F23/$F$23 -> 1
C27: PRECIO DE VENTA PLANTA A LOCAL | F27: =+F23 -> 6183.8917
C28: CAMIONES | D28: LOGISTICA | E28: 0.1 | F28: =+F27*E28 -> 618.38917 | G28: Costo | H28: % Margen
C29: COSTO TOTAL | F29: =SUM(F27:F28) -> 6802.2808 | G29: =+F29/$F$31 -> 0.68965517 | H29: =1-(F29/F31) -> 0.31034483
C30: MARK UP LOCAL | E30: 0.45 | F30: =+F29*E30 -> 3061.0264
C31: PRECIO VENTA SIN IMP | F31: =SUM(F29:F30) -> 9863.3072
C32: PRECIO VENTA IVI | E32: 0.13 | F32: =+F31*(1+E32) -> 11145.537
C34: MARGEN SUPERMERCADO | E34: 0.65 | F34: =+F31/0.65 -> 15174.319
C35: PRECIO IVI | E35: 0.13 | F35: =+F34*1.13 -> 17146.98
A37: Esteban Ramírez S. / Costos
