Workbook

Sheet Costo Ensamble 
E1: Precio Local | F1: Costo MP | G1: Costo EM | H1: Costo MO
E2: =IFERROR(O71,"") -> 6363.5854 | F2: =IFERROR(H62,"") -> 4508.9879 | G2: =IFERROR(H63,"") -> 647.635 | H2: =IFERROR(H65,"") -> 580.85073
A5: ESTRUCTURA DE COSTOS
F6: Fecha: | H6: =TODAY() -> 46056
A7: UNIDADES | B7: DESCRIPCION MAT.PRIMA | C7: UNIDADES | D7: UND MEDIDA | E7: COSTO UNITARIO | F7: TOTAL COSTO | G7: % PREC. DEFINIDO | H7: CODIGOS
B8: =IFERROR(VLOOKUP(H8,'[1]Consolidado MP Planta'!$A$2:$M$823,3,0),"") | C8: =+A8 -> 0 | D8: =IFERROR(VLOOKUP(H8,'[1]Consolidado MP Planta'!$A$2:$M$823,13,0),"") | E8: =IFERROR(VLOOKUP(H8,'[1]Consolidado MP Planta'!$A$2:$M$823,12,0),"") | F8: =IFERROR(C8*E8,"") | G8: =IFERROR(F8/$F$75,"")
B9: =IFERROR(VLOOKUP(H9,'[1]Consolidado MP Planta'!$A$2:$M$823,3,0),"") | C9: =+A9 -> 0 | D9: =IFERROR(VLOOKUP(H9,'[1]Consolidado MP Planta'!$A$2:$M$823,13,0),"") | E9: =IFERROR(VLOOKUP(H9,'[1]Consolidado MP Planta'!$A$2:$M$823,12,0),"") | F9: =IFERROR(C9*E9,"") | G9: =IFERROR(F9/$F$75,"")
B10: =IFERROR(VLOOKUP(H10,'[1]Consolidado MP Planta'!$A$2:$M$823,3,0),"") | C10: =+A10 -> 0 | D10: =IFERROR(VLOOKUP(H10,'[1]Consolidado MP Planta'!$A$2:$M$823,13,0),"") | E10: =IFERROR(VLOOKUP(H10,'[1]Consolidado MP Planta'!$A$2:$M$823,12,0),"") | F10: =IFERROR(C10*E10,"") | G10: =IFERROR(F10/$F$75,"")
B11: =IFERROR(VLOOKUP(H11,'[1]Consolidado MP Planta'!$A$2:$M$823,3,0),"") | C11: =+A11 -> 0 | D11: =IFERROR(VLOOKUP(H11,'[1]Consolidado MP Planta'!$A$2:$M$823,13,0),"") | E11: =IFERROR(VLOOKUP(H11,'[1]Consolidado MP Planta'!$A$2:$M$823,12,0),"") | F11: =IFERROR(C11*E11,"") | G11: =IFERROR(F11/$F$75,"")
B12: =IFERROR(VLOOKUP(H12,'[1]Consolidado MP Planta'!$A$2:$M$823,3,0),"") | C12: =+A12 -> 0 | D12: =IFERROR(VLOOKUP(H12,'[1]Consolidado MP Planta'!$A$2:$M$823,13,0),"") | E12: =IFERROR(VLOOKUP(H12,'[1]Consolidado MP Planta'!$A$2:$M$823,12,0),"") | F12: =IFERROR(C12*E12,"") | G12: =IFERROR(F12/$F$75,"")
B13: =IFERROR(VLOOKUP(H13,'[1]Consolidado MP Planta'!$A$2:$M$823,3,0),"") | C13: =+A13 -> 0 | D13: =IFERROR(VLOOKUP(H13,'[1]Consolidado MP Planta'!$A$2:$M$823,13,0),"") | E13: =IFERROR(VLOOKUP(H13,'[1]Consolidado MP Planta'!$A$2:$M$823,12,0),"") | F13: =IFERROR(C13*E13,"") | G13: =IFERROR(F13/$F$75,"")
B14: =IFERROR(VLOOKUP(H14,'[1]Consolidado MP Planta'!$A$2:$M$823,3,0),"") | C14: =+A14 -> 0 | D14: =IFERROR(VLOOKUP(H14,'[1]Consolidado MP Planta'!$A$2:$M$823,13,0),"") | E14: =IFERROR(VLOOKUP(H14,'[1]Consolidado MP Planta'!$A$2:$M$823,12,0),"") | F14: =IFERROR(C14*E14,"") | G14: =IFERROR(F14/$F$75,"")
B15: =IFERROR(VLOOKUP(H15,[2]Hoja2!$A$2:$G$589,2,0),"")
A16: UNIDADES | B16: MATERIA PRIMA SEMIELABORADOS | C16: UNIDADES | D16: UND MEDIDA | E16: COSTO UNITARIO | F16: TOTAL COSTO | G16: % PREC. DEFINIDO | H16: CODIGOS
A17: 1 | B17: Rosquete vainilla Dawn 400g | C17: =+A17 -> 1 | D17: und | E17: =+'Costo Rosquete'!H53 -> 733.49573 | F17: =IFERROR(E17*C17,"") -> 733.49573 | G17: =IFERROR(F17/$F$75,"") -> 0.13024173 | H17: NUEVO
A18: 200 | B18: ALMIBAR FLOR DE CAÑA | C18: =+A18 -> 200 | D18: Gramos | E18: =+'Costo almibar flor de caña '!E69 -> 4.5328859 | F18: =IFERROR(E18*C18,"") -> 906.57718 | G18: =IFERROR(F18/$F$75,"") -> 0.1609746 | H18: NUEVO
A19: 1 | B19: FLAN SPOON 700G | C19: =+A19 -> 1 | D19: und | E19: =+'Costo Flan'!H53 -> 1172.864 | F19: =IFERROR(E19*C19,"") -> 1172.864 | G19: =IFERROR(F19/$F$75,"") -> 0.2082573 | H19: NUEVO
A20: 150 | B20: EMPAQUE RELLENO CARAMELO SPOON | C20: =+A20 -> 150 | D20: Gramos | E20: 2.23 | F20: =IFERROR(E20*C20,"") -> 334.5 | G20: =IFERROR(F20/$F$75,"") -> 0.059394837 | H20: SE00340
A21: 145 | B21: SEMILLAS BAÑADAS BELCOLADE | C21: =+A21 -> 145 | D21: Gramos | E21: =+'Costo semillas bañ belcolad'!E69 -> 4.1254089 | F21: =IFERROR(E21*C21,"") -> 598.18429 | G21: =IFERROR(F21/$F$75,"") -> 0.10621542 | H21: NUEVO
A22: 50 | B22: CREMA RON | C22: =+A22 -> 50 | D22: Gramos | E22: =+'Costo Crema Ron'!E69 -> 4.4663333 | F22: =IFERROR(E22*C22,"") -> 223.31667 | G22: =IFERROR(F22/$F$75,"") -> 0.039652786 | H22: NUEVO
A23: 220 | B23: CREMA BEIDGE (KILO) | C23: =+A23 -> 220 | D23: Gramos | E23: 2.3 | F23: =IFERROR(E23*C23,"") -> 506 | G23: =IFERROR(F23/$F$75,"") -> 0.089846899 | H23: SE00069
A24: 15 | B24: CREMA DULCE LECHE KILO | C24: =+A24 -> 15 | D24: Gramos | E24: 2.27 | F24: =IFERROR(E24*C24,"") -> 34.05 | G24: =IFERROR(F24/$F$75,"") -> 0.0060460215 | H24: SE00032
B25: =IFERROR(VLOOKUP(H25,[1]SEMIELABORADOS!$A$2:$M$6000,2,0),"") | C25: =+A25 -> 0 | D25: =IFERROR(VLOOKUP(H25,[1]SEMIELABORADOS!$A$2:$M$6000,6,0),"") | E25: =IFERROR(VLOOKUP(H25,[1]SEMIELABORADOS!$A$2:$H$65536,8,0),"") | F25: =IFERROR(E25*C25,"") | G25: =IFERROR(F25/$F$75,"")
B26: =IFERROR(VLOOKUP(H26,[1]SEMIELABORADOS!$A$2:$M$6000,2,0),"") | C26: =+A26 -> 0 | D26: =IFERROR(VLOOKUP(H26,[1]SEMIELABORADOS!$A$2:$M$6000,6,0),"") | E26: =IFERROR(VLOOKUP(H26,[1]SEMIELABORADOS!$A$2:$H$65536,8,0),"") | F26: =IFERROR(E26*C26,"") | G26: =IFERROR(F26/$F$75,"")
A28: UNIDADES | B28: EMPAQUE | C28: UNIDADES | D28: UND MEDIDA | E28: COSTO UNITARIO | F28: TOTAL COSTO | G28: % PREC. DEFINIDO | H28: CODIGOS
A29: 1 | B29: =IFERROR(VLOOKUP(H29,'[1]Consolidado MP Planta'!$A$2:$M$823,3,0),"") -> QUEQUERA RED BASE/DOMO 10 (CAJA:50) | C29: =+A29 -> 1 | D29: =IFERROR(VLOOKUP(H29,'[1]Consolidado MP Planta'!$A$2:$M$823,13,0),"") -> UND | E29: 415 | F29: =IFERROR(C29*E29,"") -> 415 | G29: =IFERROR(F29/$F$75,"") -> 0.073688662 | H29: 121603
A30: 1 | B30: =IFERROR(VLOOKUP(H30,'[1]Consolidado MP Planta'!$A$2:$M$823,3,0),"") -> ORLA CARTON 10" DORADA (UND) | C30: =+A30 -> 1 | D30: =IFERROR(VLOOKUP(H30,'[1]Consolidado MP Planta'!$A$2:$M$823,13,0),"") -> Und | E30: 137 | F30: =IFERROR(C30*E30,"") -> 137 | G30: =IFERROR(F30/$F$75,"") -> 0.024326137 | H30: 1950692
A31: 1 | B31: =IFERROR(VLOOKUP(H31,'[1]Consolidado MP Planta'!$A$2:$M$823,3,0),"") -> ETIQUETA BLANCA R-153 (UND) | C31: =+A31 -> 1 | D31: =IFERROR(VLOOKUP(H31,'[1]Consolidado MP Planta'!$A$2:$M$823,13,0),"") -> Und | E31: =IFERROR(VLOOKUP(H31,'[1]Consolidado MP Planta'!$A$2:$M$823,12,0),"") -> 0.39 | F31: =IFERROR(C31*E31,"") -> 0.39 | G31: =IFERROR(F31/$F$75,"") -> 6.9249586e-05 | H31: 701096
A32: 1 | B32: =IFERROR(VLOOKUP(H32,'[1]Consolidado MP Planta'!$A$2:$M$823,3,0),"") -> ETIQUETA BLANCA 2 5/8X1 15/16 (UND) | C32: =+A32 -> 1 | D32: =IFERROR(VLOOKUP(H32,'[1]Consolidado MP Planta'!$A$2:$M$823,13,0),"") -> Und | E32: =IFERROR(VLOOKUP(H32,'[1]Consolidado MP Planta'!$A$2:$M$823,12,0),"") -> 2.128 | F32: =IFERROR(C32*E32,"") -> 2.128 | G32: =IFERROR(F32/$F$75,"") -> 0.00037785415 | H32: 0702123
A33: 1 | B33: =IFERROR(VLOOKUP(H33,'[1]Consolidado MP Planta'!$A$2:$M$823,3,0),"") -> ETIQ.BLANCA 1 1/4 * 3/4 (UND) | C33: =+A33 -> 1 | D33: =IFERROR(VLOOKUP(H33,'[1]Consolidado MP Planta'!$A$2:$M$823,13,0),"") -> Und | E33: =IFERROR(VLOOKUP(H33,'[1]Consolidado MP Planta'!$A$2:$M$823,12,0),"") -> 0.58 | F33: =IFERROR(C33*E33,"") -> 0.58 | G33: =IFERROR(F33/$F$75,"") -> 0.00010298656 | H33: 0702069
A34: 1 | B34: ETIQUETA TORTA FLOR DE CAÑA | C34: =+A34 -> 1 | D34: UND | E34: 75 | F34: =IFERROR(C34*E34,"") -> 75 | G34: =IFERROR(F34/$F$75,"") -> 0.013317228 | H34: Nuevo
B35: =IFERROR(VLOOKUP(H35,'[1]Consolidado MP Planta'!$A$2:$M$823,3,0),"") | C35: =+A35 -> 0 | D35: =IFERROR(VLOOKUP(H35,'[1]Consolidado MP Planta'!$A$2:$M$823,13,0),"") | E35: =IFERROR(VLOOKUP(H35,'[1]Consolidado MP Planta'!$A$2:$M$823,12,0),"") | F35: =IFERROR(C35*E35,"") | G35: =IFERROR(F35/$F$75,"")
A37: UNIDADES | B37: EMPAQUE SEMIELABORADOS | C37: UNIDADES | D37: UND MEDIDA | E37: COSTO UNITARIO | F37: TOTAL COSTO | G37: % PREC. DEFINIDO | H37: CODIGOS
A38: =+A17 -> 1 | B38: Rosquete vainilla Dawn 400g | C38: =+A38 -> 1 | D38: und | E38: =+'Costo Rosquete'!H54 -> 9.4355556 | F38: =IFERROR(E38*C38,"") -> 9.4355556 | G38: =IFERROR(F38/$F$75,"") -> 0.0016754059 | H38: NUEVO
A39: =+A18 -> 200 | B39: ALMIBAR FLOR DE CAÑA | C39: =+A39 -> 200 | D39: Gramos | E39: =+'Costo almibar flor de caña '!E76 -> 0.0049838926 | F39: =IFERROR(E39*C39,"") -> 0.99677852 | G39: =IFERROR(F39/$F$75,"") -> 0.00017699103 | H39: NUEVO
A40: =+A19 -> 1 | B40: FLAN SPOON 700G | C40: =+A40 -> 1 | D40: und | E40: =+'Costo Flan'!H54 -> 1.568 | F40: =IFERROR(E40*C40,"") -> 1.568 | G40: =IFERROR(F40/$F$75,"") -> 0.00027841885 | H40: NUEVO
A41: =+A20 -> 150 | B41: EMPAQUE RELLENO CARAMELO SPOON | C41: =+A41 -> 150 | D41: Gramos | E41: 0.02 | F41: =IFERROR(E41*C41,"") -> 3 | G41: =IFERROR(F41/$F$75,"") -> 0.00053268912 | H41: SE00340
A42: =+A21 -> 145 | B42: SEMILLAS BAÑADAS BELCOLADE | C42: =+A42 -> 145 | D42: Gramos | E42: =+'Costo semillas bañ belcolad'!E76 -> 0 | F42: =IFERROR(E42*C42,"") -> 0 | G42: =IFERROR(F42/$F$75,"") -> 0 | H42: NUEVO
A43: =+A22 -> 50 | B43: CREMA RON | C43: =+A43 -> 50 | D43: Gramos | E43: =+'Costo Crema Ron'!E76 -> 0.0067333333 | F43: =IFERROR(E43*C43,"") -> 0.33666667 | G43: =IFERROR(F43/$F$75,"") -> 5.9779557e-05 | H43: NUEVO
A44: =+A23 -> 220 | B44: CREMA BEIDGE (KILO) | C44: =+A44 -> 220 | D44: Gramos | E44: 0.01 | F44: =IFERROR(E44*C44,"") -> 2.2 | G44: =IFERROR(F44/$F$75,"") -> 0.00039063869 | H44: SE00069
...

Sheet Crema Dulce Leche 
C1: SERVICIOS DE PASTELERIA S.A. | H1: CÓDIGO: | I1: ESP-RE-DES-020
C2: ESPECIFICACION DE RECETA | H2: REVISIÓN: | I2: 02
C3: Crema de Dulce de Leche(24500g) SE00032 | H3: FECHA DE APROBACIÓN: | I3: 45613
C4: Elaborado | D4: Javier Tong, Chef
C5: Aprobado | D5: Esteban Cartin, Gte Manufactura
A6: AREA QUE PRODUCE: | D6: Decoración | G6: AREA QUE EMPACA: | I6: Decoracion
A7: # Código | B7: # Código Netsuite | C7: Descripción del ingrediente | D7: Marca | E7: Unidad Internacional | G7: Medida alternativa | I7: Costo - Referencia
E8: Cantidad | F8: Unidad medida | G8: Cantidad | H8: Unidad medida | I8: Colones
C9: Ensamble
A10: 11400029 | B10: MP10165 | C10: CREMA BETTER DULCE LECHE RICH (UND:4 K) | D10: RICHS | E10: 16000 | F10: g | H10: 4 GALON
A11: 11400031 | B11: MP10048 | C11: CREMA PRESTIGE GRAND (UND:4 K) | D11: RICHS | E11: 8000 | F11: g | H11: 2 GALON
A12: 10415 | C12: AGUA POTABLE (PLANTA) | D12: FAS | E12: 1000 | F12: g
A13: 1212410 | B13: MP10008 | C13: PRESERVANTE 1047S (PAQ=5 KILO) | D13: ASEAL | E13: 22 | F13: g
C20: Decoración
C29: Empaque
A30: 702123 | B30: EM10011 | C30: ETIQUETA BLANCA 2 5/8X1 15/16 (UND) | E30: 1 | F30: ud
D40: Cantidad | E40: Unidad
A41: PESO TOTAL OBTENIDO | D41: 24500 | E41: g | F41: Tiempo de Horneo:
A42: TIEMPO TOTAL DE PREPARACION | D42: 21 | E42: min | F42: Horno:
A43: CANTIDAD DE PORCIONES OBTENIDAS | D43: 1 | E43: ud | F43: Temperatura de Horneo:
A44: PESO DE CADA PORCIÓN | D44: 24500 | E44: g | F44: Otros
A45: MERMA | D45: 500 | E45: g
A46: PROCEDIMIENTO DE PREPARACION DE LA RECETA
A47: 1.- Colocar en la top cream, la crema de dulce de leche y la prestige y el agua con el preservante. (Cumpliendo un temperatura de 5° liquida)
A48: 2.- Batir por 21 minutos.
A49: 3,- Una vez lista a una temperatura de 18° batida, retirar, etiquetar y guardar hasta que sean usadas.
A57: 2, Actualización tiempo de preparación y procedimiento

Sheet Mezcla Sirope Dulce leche 
C1: SERVICIOS DE PASTELERIA S.A. | H1: CÓDIGO: | I1: ESP-RE-POF-057
C2: ESPECIFICACION DE RECETA | H2: REVISIÓN: | I2: 04
C3: Mezcla Sirope de Dulce de Leche(5350g) 910000006(SE00034) | H3: FECHA DE APROBACIÓN: | I3: 45613
C4: Elaborado | D4: Mariela Barrantes Sánchez , Chef
C5: Aprobado | D5: Esteban Cartin, Gte Manufactura
A6: AREA QUE PRODUCE: | D6: Postres | G6: AREA QUE EMPACA: | I6: Postres
A7: # Código | B7: # Código Netsuite | C7: Descripción del ingrediente | D7: Marca | E7: Unidad Internacional | G7: Medida alternativa | I7: Costo - Referencia
E8: Cantidad | F8: Unidad medida | G8: Cantidad | H8: Unidad medida | I8: Colones
C9: Ensamble
A10: 11400066 | B10: MP10007 | C10: MANJAR DE LECHE CONDENSADA | D10: NESTLE | E10: 853 | F10: g
A11: 10415 | C11: AGUA POTABLE (PLANTA) | D11: FAS | E11: 158 | F11: g
C16: Decoración
C22: Empaque
A23: 1950765 | B23: EM10259 | C23: PLAST. AUTOAD 18 * 2000 | D23: MAYCA | E23: 20 | F23: cm
A24: 0702012 | B24: EM10005 | C24: ETIQ.FECHA VENCIMIENTO | D24: ETIPLAST | E24: 1 | F24: Unid | L24: =SUM(E10:E11) -> 1011
A25: 1950705 | B25: EM10037 | C25: BOLSA 8x12 TRANSP | D25: PLASTICOS P | E25: 1 | F25: Unid
D30: Cantidad | E30: Unidad
A31: PESO TOTAL OBTENIDO | D31: 1000 | E31: g | F31: Tiempo de Horneo:
A32: TIEMPO TOTAL DE PREPARACION | D32: 3 | E32: Min. | F32: Horno:
A33: CANTIDAD DE PORCIONES OBTENIDAS | D33: 1 | E33: Tanda | F33: Temperatura de Horneo:
A34: PESO DE CADA PORCIÓN | D34: 1000 | E34: g | F34: Otros
A35: MERMA | D35: =SUM(E10:E11)-D31 -> 11 | E35: g
A36: PROCEDIMIENTO DE PREPARACION DE LA RECETA
A37: 1, Mezclar con ayuda de una espatula de goma, el manjar con el agua.
A38: 2, Guardarlo en bolsa 8x12 y etiquetar.
A39: 3, Usar inmediatamente o si no, guardar en camara de refigeración.
A40: Cuenta con 7 dias de vida util despues de su elaboración, guardar los sobrantes en bolsasa plasticas en refigeración.
A43: CONTROL DE CAMBIOS
A44: 2, Actualización datos de receta, procedimiento y pesos finales.
A45: 3, Se actualizan datos de ingredientes
A46: 4, Se actualiza dato de vida util

Sheet Empaque Relleno de Caramelo 
C1: SERVICIOS DE PASTELERIA S.A. | H1: CÓDIGO: | I1: ESP-RE-EMPS-048
C2: ESPECIFICACION DE RECETA | H2: REVISIÓN: | I2: 01
C3: 20100162(SE00340) Empaque Relleno de caramelo Spoon | H3: FECHA DE APROBACIÓN: | I3: 45610
C4: Elaborado | D4: Javier Tong, Chef
C5: Aprobado | D5: Esteban Cartin, Gte Manufactura
A6: AREA QUE PRODUCE: | D6: Cocina | G6: AREA QUE EMPACA: | I6: Cocina
A7: # Código | B7: # Código Netsuite | C7: Descripción del ingrediente | D7: Marca | E7: Unidad Internacional | G7: Medida alternativa | I7: Costo - Referencia
E8: Cantidad | F8: Unidad medida | G8: Cantidad | H8: Unidad medida | I8: Colones
C9: Ensamble
A10: 90100353 | B10: SE00339 | C10: RELLENO DE CARAMELO SPOON | D10: FAS | E10: 4000 | F10: g
C18: Decoración
C24: Empaque
A25: 51600050 | B25: EM10307 | C25: BOLSA MARMITA 14 x 20 (KILO) | E25: 1 | F25: ud
A26: 702123 | B26: EM10011 | C26: ETIQUETA BLANCA 2 5/8X1 15/16 (UND) | D26: ETIPLAST | E26: 1 | F26: ud
D35: Cantidad | E35: Unidad
A36: PESO TOTAL OBTENIDO | D36: 4000 | E36: g | F36: Tiempo de Horneo:
A37: TIEMPO TOTAL DE PREPARACION | D37: 1.5 | E37: Minutos | F37: Horno:
A38: CANTIDAD DE PORCIONES OBTENIDAS | D38: 1 | E38: Bolsas | F38: Temperatura de Horneo:
A39: PESO DE CADA PORCIÓN | D39: 4000 | E39: g | F39: Otros
A40: MERMA | D40: 0 | E40: g
A41: PROCEDIMIENTO DE PREPARACION DE LA RECETA
A42: 1. Vaciar la marmita en bolsas de 4kg aprox.
A43: 2. Amarrar la bolsa y etiquetar
A51: CONTROL DE CAMBIOS

Sheet Relleno Caramelo Spoon
C1: SERVICIOS DE PASTELERIA S.A. | H1: CÓDIGO: | I1: ESP-RE-COCS-054
C2: ESPECIFICACION DE RECETA | H2: REVISIÓN: | I2: 01
C3: 90100353(SE00339) Caramelo Spoon | H3: FECHA DE APROBACIÓN: | I3: 45609
C4: Elaborado | D4: Javier Tong, Chef
C5: Aprobado | D5: Esteban Cartin, Gte Manufactura
A6: AREA QUE PRODUCE: | D6: Cocina | G6: AREA QUE EMPACA: | I6: Cocina
A7: # Código | B7: # Código Netsuite | C7: Descripción del ingrediente | D7: Marca | E7: Unidad Internacional | G7: Medida alternativa | I7: Costo - Referencia
E8: Cantidad | F8: Unidad medida | G8: Cantidad | H8: Unidad medida | I8: Colones
C9: Ensamble
A10: 90100132 | B10: SE00226 | C10: EMPAQUE AZUCAR REFINO | D10: VICTORIA | E10: 27000 | F10: g
A11: 0310107 | B11: MP10022 | C11: LACTOCREMA GRANEL | D11: DOS PINOS | E11: 4455 | F11: g
A12: 0310107 | B12: MP10022 | C12: LACTOCREMA GRANEL | D12: NESTLE | E12: 41000 | F12: g
C27: Decoración
C33: Empaque
D44: Cantidad | E44: Unidad
A45: PESO TOTAL OBTENIDO | D45: 44500 | E45: g | F45: Tiempo de Horneo:
A46: TIEMPO TOTAL DE PREPARACION | D46: 45 | E46: min | F46: Horno:
A47: CANTIDAD DE PORCIONES OBTENIDAS | D47: 1 | E47: tanda | F47: Temperatura de Horneo:
A48: PESO DE CADA PORCIÓN | D48: 44500 | E48: g | F48: Otros
A49: MERMA | D49: 27955 | E49: g
A50: PROCEDIMIENTO DE PREPARACION DE LA RECETA
A51: 1.Colcoar el azucar en la marmita, encender en programacion "caramelo"
A52: 2. Cuando la marmita lo indique, agregar la lactocrema en cubos.
A53: 3. Cuando la marmita lo indique agregar la leche.
A54: 4. Cocinar hasta que se termine el programa, cuidar que no se riegue.
A55: 5. Preparase para el proceso de empaque.
A62: CONTROL DE CAMBIOS

Sheet Batido Vainilla Dawn
C1: SERVICIOS DE PASTELERIA S.A. | H1: CÓDIGO: | I1: ESP-RE-BAS-027
C2: ESPECIFICACION DE RECETA | H2: REVISIÓN: | I2: 01
C3: SE00444 Batido Nucleo vainilla Dawn | H3: FECHA DE APROBACIÓN: | I3: 45619
C4: Elaborado | D4: Javier Tong, Chef
C5: Aprobado | D5: Esteban Cartin, Gte Manufactura
A6: AREA QUE PRODUCE: | D6: Batidos | G6: AREA QUE EMPACA: | I6: Batidos
A7: # Código | B7: # Código Netsuite | C7: Descripción del ingrediente | D7: Marca | E7: Unidad Internacional | G7: Medida alternativa | I7: Costo - Referencia
E8: Cantidad | F8: Unidad medida | G8: Cantidad | H8: Unidad medida | I8: Colones
C9: Ensamble
A10: 906000138 | B10: SE00443 | C10: PREMEZCLA BATIDO NUCLEO VAINILLA DAWN | D10: FAS | E10: 14195 | F10: g
A11: 1210482 | B11: MP10005 | C11: HUEVO ENTERO PASTERI INNOVO ( CAJA: 10 K) | D11: INNOVO | E11: 7700 | F11: g
A12: 10415 | C12: AGUA POTABLE (PLANTA) | D12: FAS | E12: 3090 | F12: g
A13: 1212437 | B13: MP10315 | C13: PRESERVANTE MIXTO (UND:17 K) | D13: PURATOS | E13: 390 | F13: g
C21: Decoración
C28: Empaque
D38: Cantidad | E38: Unidad
A39: PESO TOTAL OBTENIDO | D39: 24000 | E39: g | F39: Tiempo de Horneo:
A40: TIEMPO TOTAL DE PREPARACION | D40: 10 | E40: min | F40: Horno:
A41: CANTIDAD DE PORCIONES OBTENIDAS | D41: 1 | E41: Tanda | F41: Temperatura de Horneo:
A42: PESO DE CADA PORCIÓN | D42: 24000 | E42: g | F42: Otros
A43: MERMA | D43: 1375 | E43: g
A44: PROCEDIMIENTO DE PREPARACION DE LA RECETA
A46: 1, Colocar los liquidos en la batidora, posterior agregar los ingredientes secos
A47: 2, Batir por 1 min en velocidad 1. Con paleta
A48: 3, Batir 4 min en velocidad 3. con paleta
A55: CONTROL DE CAMBIOS

Sheet Premezcla Vainilla Dawn
C1: SERVICIOS DE PASTELERIA S.A. | H1: CÓDIGO: | I1: ESP-RE-PRES-025
C2: ESPECIFICACION DE RECETA | H2: REVISIÓN: | I2: 01
C3: SE00443 Premezcla Batido Nucleo Vainilla Dawn | H3: FECHA DE APROBACIÓN: | I3: 45617
C4: Elaborado | D4: Javier Tong, Chef
C5: Aprobado | D5: Esteban Cartin, Gte Manufactura
A6: AREA QUE PRODUCE: | D6: Premezclas | G6: AREA QUE EMPACA: | I6: Premezclas
A7: # Código | B7: # Código Netsuite | C7: Descripción del ingrediente | D7: Marca | E7: Unidad Internacional | G7: Medida alternativa | I7: Costo - Referencia
E8: Cantidad | F8: Unidad medida | G8: Cantidad | H8: Unidad medida | I8: Colones
C9: Ensamble
A10: 510301 | B10: MP10074 | C10: AZUCAR BLANCO INDUSTRIAL (SACO:50 K) | D10: LAICA | E10: 5820 | F10: g
A11: 1210445 | B11: MP10142 | C11: CLARA DE HUEVO DESHIDRATADA | E11: 350 | F11: g
A12: 11200072 | B12: MP10478 | C12: HARINA SILVER CAKE | D12: FAHACASA | E12: 3622 | F12: g
A13: 11200087 | B13: MP10493 | C13: COCENTRADO VAINILLA DAWN | D13: DAWN | E13: 3492 | F13: g
A14: 1160001 | B14: MP10481 | C14: GOMA XANTANA | D14: MABAKER & CHEF | E14: 60 | F14: g
A15: 1212410 | B15: MP10008 | C15: PRESERVANTE 1047S (PAQ=5 KILO) | D15: ASEAL | E15: 38 | F15: g
A16: 10100337 | B16: MP10494 | C16: CMC | D16: UNIVERSAL DE ALIMENTOS | E16: 30 | F16: g
A17: 310145 | B17: MP10234 | C17: LECHE POLVO INDUSTRIAL (SACO:25 KG) | D17: DOS PINOS | E17: 518 | F17: g
A18: 503000036 | B18: MP10085 | C18: BICARBONATO DE SODIO (PAQ:2.5 K) | E18: 65 | F18: g
A19: 11300012 | B19: MP10517 | C19: ACTI EGG | D19: PURATOS | E19: 200 | F19: g
C21: Decoración
C29: Empaque
A30: 1950708 | B30: EM10013 | C30: BOLSA 17x25 TRANSP KILO | E30: 2 | F30: ud
A31: 60100010 | B31: EM10133 | C31: ETIQUETA ROJA LETRA ALERJENO (UND) | E31: 2 | F31: ud
A32: 702123 | B32: EM10011 | C32: ETIQUETA BLANCA 2 5/8X1 15/16 (UND) | E32: 2 | F32: ud
A33: 1950705 | B33: EM10037 | C33: BOLSA 8x12 TRANSPARENTE KILO | E33: 1 | F33: ud
D42: Cantidad | E42: Unidad
A43: PESO TOTAL OBTENIDO | D43: 14195 | E43: g | F43: Tiempo de Horneo:
A44: TIEMPO TOTAL DE PREPARACION | D44: 3 | E44: min | F44: Horno:
A45: CANTIDAD DE PORCIONES OBTENIDAS | D45: 1 | E45: ud | F45: Temperatura de Horneo:
A46: PESO DE CADA PORCIÓN | D46: 14195 | E46: g | F46: Otros
A47: MERMA | D47: 0 | E47: g
A48: PROCEDIMIENTO DE PREPARACION DE LA RECETA
A49: 1, En una bolsa 17x25 empacar el azucar. Etiquetar
A50: 2, En una bolsa 17x25 empacar las harinas, concentrado,cmc, leche en polvo y la goma. Clara de huevo, acti egg. Etiquetar
A51: 3, En una bolsa 8*12 pesar el preservante y el bicarbonato (se debe pesar justo antes de su uso)
A52: 4, En una bolsa 8*12 pesar la clara
A57: CONTROL DE CAMBIOS

Sheet Costo Rosquete
E1: Precio Local | F1: Costo MP | G1: Costo EM | H1: Costo MO
E2: =IFERROR(O62,"") -> 744.02694 | F2: =IFERROR(H53,"") -> 733.49573 | G2: =IFERROR(H54,"") -> 9.4355556 | H2: =IFERROR(H56,"") -> 30.846154
A5: ESTRUCTURA DE COSTOS
F6: Fecha: | H6: =TODAY() -> 46056
A7: UNIDADES | B7: DESCRIPCION MAT.PRIMA | C7: UNIDADES | D7: UND MEDIDA | E7: COSTO UNITARIO | F7: TOTAL COSTO | G7: % PREC. DEFINIDO | H7: CODIGOS
B8: =IFERROR(VLOOKUP(H8,'[1]Consolidado MP Planta'!$A$2:$M$823,3,0),"") | C8: =+A8 -> 0 | D8: =IFERROR(VLOOKUP(H8,'[1]Consolidado MP Planta'!$A$2:$M$823,13,0),"") | E8: =IFERROR(VLOOKUP(H8,'[1]Consolidado MP Planta'!$A$2:$M$823,12,0),"") | F8: =IFERROR(C8*E8,"") | G8: =IFERROR(F8/$F$66,"")
B9: =IFERROR(VLOOKUP(H9,'[1]Consolidado MP Planta'!$A$2:$M$823,3,0),"") | C9: =+A9 -> 0 | D9: =IFERROR(VLOOKUP(H9,'[1]Consolidado MP Planta'!$A$2:$M$823,13,0),"") | E9: =IFERROR(VLOOKUP(H9,'[1]Consolidado MP Planta'!$A$2:$M$823,12,0),"") | F9: =IFERROR(C9*E9,"") | G9: =IFERROR(F9/$F$66,"")
B10: =IFERROR(VLOOKUP(H10,'[1]Consolidado MP Planta'!$A$2:$M$823,3,0),"") | C10: =+A10 -> 0 | D10: =IFERROR(VLOOKUP(H10,'[1]Consolidado MP Planta'!$A$2:$M$823,13,0),"") | E10: =IFERROR(VLOOKUP(H10,'[1]Consolidado MP Planta'!$A$2:$M$823,12,0),"") | F10: =IFERROR(C10*E10,"") | G10: =IFERROR(F10/$F$66,"")
B11: =IFERROR(VLOOKUP(H11,'[1]Consolidado MP Planta'!$A$2:$M$823,3,0),"") | C11: =+A11 -> 0 | D11: =IFERROR(VLOOKUP(H11,'[1]Consolidado MP Planta'!$A$2:$M$823,13,0),"") | E11: =IFERROR(VLOOKUP(H11,'[1]Consolidado MP Planta'!$A$2:$M$823,12,0),"") | F11: =IFERROR(C11*E11,"") | G11: =IFERROR(F11/$F$66,"")
B12: =IFERROR(VLOOKUP(H12,'[1]Consolidado MP Planta'!$A$2:$M$823,3,0),"") | C12: =+A12 -> 0 | D12: =IFERROR(VLOOKUP(H12,'[1]Consolidado MP Planta'!$A$2:$M$823,13,0),"") | E12: =IFERROR(VLOOKUP(H12,'[1]Consolidado MP Planta'!$A$2:$M$823,12,0),"") | F12: =IFERROR(C12*E12,"") | G12: =IFERROR(F12/$F$66,"")
B13: =IFERROR(VLOOKUP(H13,'[1]Consolidado MP Planta'!$A$2:$M$823,3,0),"") | C13: =+A13 -> 0 | D13: =IFERROR(VLOOKUP(H13,'[1]Consolidado MP Planta'!$A$2:$M$823,13,0),"") | E13: =IFERROR(VLOOKUP(H13,'[1]Consolidado MP Planta'!$A$2:$M$823,12,0),"") | F13: =IFERROR(C13*E13,"") | G13: =IFERROR(F13/$F$66,"")
B14: =IFERROR(VLOOKUP(H14,'[1]Consolidado MP Planta'!$A$2:$M$823,3,0),"") | C14: =+A14 -> 0 | D14: =IFERROR(VLOOKUP(H14,'[1]Consolidado MP Planta'!$A$2:$M$823,13,0),"") | E14: =IFERROR(VLOOKUP(H14,'[1]Consolidado MP Planta'!$A$2:$M$823,12,0),"") | F14: =IFERROR(C14*E14,"") | G14: =IFERROR(F14/$F$66,"")
B15: =IFERROR(VLOOKUP(H15,[2]Hoja2!$A$2:$G$589,2,0),"")
A16: UNIDADES | B16: MATERIA PRIMA SEMIELABORADOS | C16: UNIDADES | D16: UND MEDIDA | E16: COSTO UNITARIO | F16: TOTAL COSTO | G16: % PREC. DEFINIDO | H16: CODIGOS
A17: 24000 | B17: BATIDO NUCLEO VAINILLA DAWN | C17: =+A17 -> 24000 | D17: Gramos | E17: 1.76 | F17: =IFERROR(E17*C17,"") -> 42240 | G17: =IFERROR(F17/$F$66,"") -> 0.93044423 | H17: SE00444
A18: 650 | B18: MEZCLA P/ENGRASE MOLDES KILO | C18: =+A18 -> 650 | D18: Gramos | E18: 1.03 | F18: =IFERROR(E18*C18,"") -> 669.5 | G18: =IFERROR(F18/$F$66,"") -> 0.014747453 | H18: SE00701
B19: =IFERROR(VLOOKUP(H19,[1]SEMIELABORADOS!$A$2:$M$6000,2,0),"") | C19: =+A19 -> 0 | D19: =IFERROR(VLOOKUP(H19,[1]SEMIELABORADOS!$A$2:$M$6000,6,0),"") | E19: =IFERROR(VLOOKUP(H19,[1]SEMIELABORADOS!$A$2:$H$65536,8,0),"") | F19: =IFERROR(E19*C19,"") | G19: =IFERROR(F19/$F$66,"")
B20: =IFERROR(VLOOKUP(H20,[1]SEMIELABORADOS!$A$2:$M$6000,2,0),"") | C20: =+A20 -> 0 | D20: =IFERROR(VLOOKUP(H20,[1]SEMIELABORADOS!$A$2:$M$6000,6,0),"") | E20: =IFERROR(VLOOKUP(H20,[1]SEMIELABORADOS!$A$2:$H$65536,8,0),"") | F20: =IFERROR(E20*C20,"") | G20: =IFERROR(F20/$F$66,"")
B21: =IFERROR(VLOOKUP(H21,[1]SEMIELABORADOS!$A$2:$M$6000,2,0),"") | C21: =+A21 -> 0 | D21: =IFERROR(VLOOKUP(H21,[1]SEMIELABORADOS!$A$2:$M$6000,6,0),"") | E21: =IFERROR(VLOOKUP(H21,[1]SEMIELABORADOS!$A$2:$H$65536,8,0),"") | F21: =IFERROR(E21*C21,"") | G21: =IFERROR(F21/$F$66,"")
B22: =IFERROR(VLOOKUP(H22,[1]SEMIELABORADOS!$A$2:$M$6000,2,0),"") | C22: =+A22 -> 0 | D22: =IFERROR(VLOOKUP(H22,[1]SEMIELABORADOS!$A$2:$M$6000,6,0),"") | E22: =IFERROR(VLOOKUP(H22,[1]SEMIELABORADOS!$A$2:$H$65536,8,0),"") | F22: =IFERROR(E22*C22,"") | G22: =IFERROR(F22/$F$66,"")
B23: =IFERROR(VLOOKUP(H23,[1]SEMIELABORADOS!$A$2:$M$6000,2,0),"") | C23: =+A23 -> 0 | D23: =IFERROR(VLOOKUP(H23,[1]SEMIELABORADOS!$A$2:$M$6000,6,0),"") | E23: =IFERROR(VLOOKUP(H23,[1]SEMIELABORADOS!$A$2:$H$65536,8,0),"") | F23: =IFERROR(E23*C23,"") | G23: =IFERROR(F23/$F$66,"")
B24: =IFERROR(VLOOKUP(H24,[1]SEMIELABORADOS!$A$2:$M$6000,2,0),"") | C24: =+A24 -> 0 | D24: =IFERROR(VLOOKUP(H24,[1]SEMIELABORADOS!$A$2:$M$6000,6,0),"") | E24: =IFERROR(VLOOKUP(H24,[1]SEMIELABORADOS!$A$2:$H$65536,8,0),"") | F24: =IFERROR(E24*C24,"") | G24: =IFERROR(F24/$F$66,"")
A26: UNIDADES | B26: EMPAQUE | C26: UNIDADES | D26: UND MEDIDA | E26: COSTO UNITARIO | F26: TOTAL COSTO | G26: % PREC. DEFINIDO | H26: CODIGOS
A27: 6 | B27: =IFERROR(VLOOKUP(H27,'[1]Consolidado MP Planta'!$A$2:$M$823,3,0),"") -> BOLSA TRANSPARENTE 56X96X1.80 KILO | C27: =+A27 -> 6 | D27: =IFERROR(VLOOKUP(H27,'[1]Consolidado MP Planta'!$A$2:$M$823,13,0),"") -> Und | E27: =IFERROR(VLOOKUP(H27,'[1]Consolidado MP Planta'!$A$2:$M$823,12,0),"") -> 50 | F27: =IFERROR(C27*E27,"") -> 300 | G27: =IFERROR(F27/$F$66,"") -> 0.0066082687 | H27: 1950928
A28: 6 | B28: =IFERROR(VLOOKUP(H28,'[1]Consolidado MP Planta'!$A$2:$M$823,3,0),"") -> ETIQ.FECHA VENCIMIENTO BLANCO (ROLLO) | C28: =+A28 -> 6 | D28: =IFERROR(VLOOKUP(H28,'[1]Consolidado MP Planta'!$A$2:$M$823,13,0),"") -> Gramos | E28: =IFERROR(VLOOKUP(H28,'[1]Consolidado MP Planta'!$A$2:$M$823,12,0),"") -> 0.33333333 | F28: =IFERROR(C28*E28,"") -> 2 | G28: =IFERROR(F28/$F$66,"") -> 4.4055124e-05 | H28: 0702007
A29: 6 | B29: =IFERROR(VLOOKUP(H29,'[1]Consolidado MP Planta'!$A$2:$M$823,3,0),"") -> ETIQ.BLANCA 1 1/4 * 3/4 (UND) | C29: =+A29 -> 6 | D29: =IFERROR(VLOOKUP(H29,'[1]Consolidado MP Planta'!$A$2:$M$823,13,0),"") -> Und | E29: =IFERROR(VLOOKUP(H29,'[1]Consolidado MP Planta'!$A$2:$M$823,12,0),"") -> 0.58 | F29: =IFERROR(C29*E29,"") -> 3.48 | G29: =IFERROR(F29/$F$66,"") -> 7.6655916e-05 | H29: 0702069
B30: =IFERROR(VLOOKUP(H30,'[1]Consolidado MP Planta'!$A$2:$M$823,3,0),"") | C30: =+A30 -> 0 | D30: =IFERROR(VLOOKUP(H30,'[1]Consolidado MP Planta'!$A$2:$M$823,13,0),"") | E30: =IFERROR(VLOOKUP(H30,'[1]Consolidado MP Planta'!$A$2:$M$823,12,0),"") | F30: =IFERROR(C30*E30,"") | G30: =IFERROR(F30/$F$66,"")
B31: =IFERROR(VLOOKUP(H31,'[1]Consolidado MP Planta'!$A$2:$M$823,3,0),"") | C31: =+A31 -> 0 | D31: =IFERROR(VLOOKUP(H31,'[1]Consolidado MP Planta'!$A$2:$M$823,13,0),"") | E31: =IFERROR(VLOOKUP(H31,'[1]Consolidado MP Planta'!$A$2:$M$823,12,0),"") | F31: =IFERROR(C31*E31,"") | G31: =IFERROR(F31/$F$66,"")
B32: =IFERROR(VLOOKUP(H32,'[1]Consolidado MP Planta'!$A$2:$M$823,3,0),"") | C32: =+A32 -> 0 | D32: =IFERROR(VLOOKUP(H32,'[1]Consolidado MP Planta'!$A$2:$M$823,13,0),"") | E32: =IFERROR(VLOOKUP(H32,'[1]Consolidado MP Planta'!$A$2:$M$823,12,0),"") | F32: =IFERROR(C32*E32,"") | G32: =IFERROR(F32/$F$66,"")
A34: UNIDADES | B34: EMPAQUE SEMIELABORADOS | C34: UNIDADES | D34: UND MEDIDA | E34: COSTO UNITARIO | F34: TOTAL COSTO | G34: % PREC. DEFINIDO | H34: CODIGOS
A35: =+A17 -> 24000 | B35: BATIDO NUCLEO VAINILLA DAWN | C35: =+A35 -> 24000 | D35: Gramos | E35: 0.01 | F35: =IFERROR(E35*C35,"") -> 240 | G35: =IFERROR(F35/$F$66,"") -> 0.0052866149 | H35: SE00444
A36: =+A18 -> 650 | B36: MEZCLA P/ENGRASE MOLDES KILO | C36: =+A36 -> 650 | D36: Gramos | E36: 0.01 | F36: =IFERROR(E36*C36,"") -> 6.5 | G36: =IFERROR(F36/$F$66,"") -> 0.00014317915 | H36: SE00701
A37: =+A19 -> 0 | B37: =IFERROR(VLOOKUP(H37,[1]SEMIELABORADOS!$A$2:$M$6000,2,0),"") | C37: =+A37 -> 0 | D37: =IFERROR(VLOOKUP(H37,[1]SEMIELABORADOS!$A$2:$M$6000,6,0),"") | E37: =IFERROR(VLOOKUP(H37,[1]SEMIELABORADOS!$A$2:$M$65536,10,0),"") | F37: =IFERROR(E37*C37,"") | G37: =IFERROR(F37/$F$66,"")
A38: =+A20 -> 0 | B38: =IFERROR(VLOOKUP(H38,[1]SEMIELABORADOS!$A$2:$M$6000,2,0),"") | C38: =+A38 -> 0 | D38: =IFERROR(VLOOKUP(H38,[1]SEMIELABORADOS!$A$2:$M$6000,6,0),"") | E38: =IFERROR(VLOOKUP(H38,[1]SEMIELABORADOS!$A$2:$M$65536,10,0),"") | F38: =IFERROR(E38*C38,"") | G38: =IFERROR(F38/$F$66,"")
A39: =+A21 -> 0 | B39: =IFERROR(VLOOKUP(H39,[1]SEMIELABORADOS!$A$2:$M$6000,2,0),"") | C39: =+A39 -> 0 | D39: =IFERROR(VLOOKUP(H39,[1]SEMIELABORADOS!$A$2:$M$6000,6,0),"") | E39: =IFERROR(VLOOKUP(H39,[1]SEMIELABORADOS!$A$2:$M$65536,10,0),"") | F39: =IFERROR(E39*C39,"") | G39: =IFERROR(F39/$F$66,"")
A40: =+A22 -> 0 | B40: =IFERROR(VLOOKUP(H40,[1]SEMIELABORADOS!$A$2:$M$6000,2,0),"") | C40: =+A40 -> 0 | D40: =IFERROR(VLOOKUP(H40,[1]SEMIELABORADOS!$A$2:$M$6000,6,0),"") | E40: =IFERROR(VLOOKUP(H40,[1]SEMIELABORADOS!$A$2:$M$65536,10,0),"") | F40: =IFERROR(E40*C40,"") | G40: =IFERROR(F40/$F$66,"")
A41: =+A23 -> 0 | B41: =IFERROR(VLOOKUP(H41,[1]SEMIELABORADOS!$A$2:$M$6000,2,0),"") | C41: =+A41 -> 0 | D41: =IFERROR(VLOOKUP(H41,[1]SEMIELABORADOS!$A$2:$M$6000,6,0),"") | E41: =IFERROR(VLOOKUP(H41,[1]SEMIELABORADOS!$A$2:$M$65536,10,0),"") | F41: =IFERROR(E41*C41,"") | G41: =IFERROR(F41/$F$66,"")
A43: UNIDADES | B43: MODI | C43: UNIDADES | D43: UND MEDIDA | E43: COSTO UNITARIO | F43: TOTAL COSTO | G43: % PREC. DEFINIDO | H43: CODIGOS
A44: =+A35 -> 24000 | B44: BATIDO NUCLEO VAINILLA DAWN | C44: =+A44 -> 24000 | D44: Gramos | E44: 0.03 | F44: =IFERROR(E44*C44,"") -> 720 | G44: =IFERROR(F44/$F$66,"") -> 0.015859845 | H44: SE00444
A45: =+A36 -> 650 | B45: MEZCLA P/ENGRASE MOLDES KILO | C45: =+A45 -> 650 | D45: Gramos | E45: 0.01 | F45: =IFERROR(E45*C45,"") -> 6.5 | G45: =IFERROR(F45/$F$66,"") -> 0.00014317915 | H45: SE00701
...

Sheet Almibar 
C1: SERVICIOS DE PASTELERIA S.A. | H1: CÓDIGO: | I1: ESP-RE-COCS-017
C2: ESPECIFICACION DE RECETA | H2: REVISIÓN: | I2: 02
C3: SE00005 - ALMIBAR | H3: FECHA DE APROBACIÓN: | I3: 45608
C4: Elaborado | D4: Javier Tong, Chef
C5: Aprobado | D5: Esteban Cartin, Gte Manufactura
A6: AREA QUE PRODUCE: | D6: Cocina | G6: AREA QUE EMPACA: | I6: Cocina
A7: # Código | B7: # Código Netsuite | C7: Descripción del ingrediente | D7: Marca | E7: Unidad Internacional | G7: Medida alternativa | I7: Costo - Referencia
E8: Cantidad | F8: Unidad medida | G8: Cantidad | H8: Unidad medida | I8: Colones
C9: Ensamble
A10: 10415 | C10: AGUA POTABLE (PLANTA) | D10: FAS | E10: 21400 | F10: g
A11: 90100131 | B11: SE00016 | C11: AZUCAR BLANCO INDUSTRIAL KILO | D11: FAS | E11: 8000 | F11: g
A12: 10100311 | B12: MP10095 | C12: CANELA EN ASTILLA | D12: PRIMA | E12: 5 | F12: g
A13: 0810288 | B13: MP10598 | C13: JUGO DE NARANJA TB | D13: DOS PINOS | E13: 2000 | F13: g
A14: 1212410 | B14: MP10008 | C14: PRESERVANTE 1047S (PAQ=5 KILO) | D14: ASEAL | E14: 66 | F14: g
C16: Decoración
C18: Empaque
A19: 512000002 | B19: EM10259 | C19: PLAST. AUTOAD 18 * 2000 | D19: Mayca | E19: 90 | F19: Cm
A20: 0702123 | B20: EM10011 | C20: ETIQUETA BLANCA 2 5/8X1 15/16 (UND) | E20: 2 | F20: ud
D24: Cantidad | E24: Unidad
A25: PESO TOTAL OBTENIDO | D25: 28460 | E25: g | F25: Tiempo de Horneo:
A26: TIEMPO TOTAL DE PREPARACION | D26: 15 | E26: min | F26: Horno:
A27: CANTIDAD DE PORCIONES OBTENIDAS | D27: 1 | E27: Porciones | F27: Temperatura de Horneo:
A28: PESO DE CADA PORCIÓN | D28: 28460 | E28: g | F28: Otros
A29: MERMA | D29: =SUM(E10:E14)-D25 -> 3011 | E29: g
A30: PROCEDIMIENTO DE PREPARACION DE LA RECETA
A31: 1 Colocar en una olla el agua, jugo de naranja, azúcar y mezclar bien. Añadir luego el preservante y disolverlo por completo.
A32: 2 Llevar a fuego alto hasta obtener el herbor, dejar herbir unos 5 minutos.sacar la astilla de canela
A33: 3 Despues de la cocción, retirar del fuego y colocar en un bote cubrir con plastico adhesivo y dejar enfirar. Guardar en Camaras de Refrige.
A40: CONTROL DE CAMBIOS
A41: Revision #2: Actualizacion del rendimiento de la receta.

Sheet Costo almibar flor de caña 
E1: Precio Local | F1: Costo MP | G1: Costo EM | H1: Costo MO
E2: =IFERROR(O62,"") -> 34345.312 | F2: =IFERROR(H53,"") -> 33770 | G2: =IFERROR(H54,"") -> 37.13 | H2: =IFERROR(H56,"") -> 259
A5: ESTRUCTURA DE COSTOS
F6: Fecha: | H6: =TODAY() -> 46056
A7: UNIDADES | B7: DESCRIPCION MAT.PRIMA | C7: UNIDADES | D7: UND MEDIDA | E7: COSTO UNITARIO | F7: TOTAL COSTO | G7: % PREC. DEFINIDO | H7: CODIGOS
A8: 4000 | B8: FLOR DE CAÑA 4 AÑOS OSCURO | C8: =+A8 -> 4000 | D8: Mililitros | E8: 8.25 | F8: =IFERROR(C8*E8,"") -> 33000 | G8: =IFERROR(F8/$F$66,"") -> 0.95275133 | H8: MP10721
B9: =IFERROR(VLOOKUP(H9,'[1]Consolidado MP Planta'!$A$2:$M$823,3,0),"") | C9: =+A9 -> 0 | D9: =IFERROR(VLOOKUP(H9,'[1]Consolidado MP Planta'!$A$2:$M$823,13,0),"") | E9: =IFERROR(VLOOKUP(H9,'[1]Consolidado MP Planta'!$A$2:$M$823,12,0),"") | F9: =IFERROR(C9*E9,"") | G9: =IFERROR(F9/$F$66,"")
B10: =IFERROR(VLOOKUP(H10,'[1]Consolidado MP Planta'!$A$2:$M$823,3,0),"") | C10: =+A10 -> 0 | D10: =IFERROR(VLOOKUP(H10,'[1]Consolidado MP Planta'!$A$2:$M$823,13,0),"") | E10: =IFERROR(VLOOKUP(H10,'[1]Consolidado MP Planta'!$A$2:$M$823,12,0),"") | F10: =IFERROR(C10*E10,"") | G10: =IFERROR(F10/$F$66,"")
B11: =IFERROR(VLOOKUP(H11,'[1]Consolidado MP Planta'!$A$2:$M$823,3,0),"") | C11: =+A11 -> 0 | D11: =IFERROR(VLOOKUP(H11,'[1]Consolidado MP Planta'!$A$2:$M$823,13,0),"") | E11: =IFERROR(VLOOKUP(H11,'[1]Consolidado MP Planta'!$A$2:$M$823,12,0),"") | F11: =IFERROR(C11*E11,"") | G11: =IFERROR(F11/$F$66,"")
B12: =IFERROR(VLOOKUP(H12,'[1]Consolidado MP Planta'!$A$2:$M$823,3,0),"") | C12: =+A12 -> 0 | D12: =IFERROR(VLOOKUP(H12,'[1]Consolidado MP Planta'!$A$2:$M$823,13,0),"") | E12: =IFERROR(VLOOKUP(H12,'[1]Consolidado MP Planta'!$A$2:$M$823,12,0),"") | F12: =IFERROR(C12*E12,"") | G12: =IFERROR(F12/$F$66,"")
B13: =IFERROR(VLOOKUP(H13,'[1]Consolidado MP Planta'!$A$2:$M$823,3,0),"") | C13: =+A13 -> 0 | D13: =IFERROR(VLOOKUP(H13,'[1]Consolidado MP Planta'!$A$2:$M$823,13,0),"") | E13: =IFERROR(VLOOKUP(H13,'[1]Consolidado MP Planta'!$A$2:$M$823,12,0),"") | F13: =IFERROR(C13*E13,"") | G13: =IFERROR(F13/$F$66,"")
B14: =IFERROR(VLOOKUP(H14,'[1]Consolidado MP Planta'!$A$2:$M$823,3,0),"") | C14: =+A14 -> 0 | D14: =IFERROR(VLOOKUP(H14,'[1]Consolidado MP Planta'!$A$2:$M$823,13,0),"") | E14: =IFERROR(VLOOKUP(H14,'[1]Consolidado MP Planta'!$A$2:$M$823,12,0),"") | F14: =IFERROR(C14*E14,"") | G14: =IFERROR(F14/$F$66,"")
B15: =IFERROR(VLOOKUP(H15,[2]Hoja2!$A$2:$G$589,2,0),"")
A16: UNIDADES | B16: MATERIA PRIMA SEMIELABORADOS | C16: UNIDADES | D16: UND MEDIDA | E16: COSTO UNITARIO | F16: TOTAL COSTO | G16: % PREC. DEFINIDO | H16: CODIGOS
A17: 3500 | B17: Almibar | C17: =+A17 -> 3500 | D17: Gramos | E17: 0.22 | F17: =IFERROR(E17*C17,"") -> 770 | G17: =IFERROR(F17/$F$66,"") -> 0.022230864 | H17: SE00005
B18: =IFERROR(VLOOKUP(H18,[1]SEMIELABORADOS!$A$2:$M$6000,2,0),"") | C18: =+A18 -> 0 | D18: =IFERROR(VLOOKUP(H18,[1]SEMIELABORADOS!$A$2:$M$6000,6,0),"") | E18: =IFERROR(VLOOKUP(H18,[1]SEMIELABORADOS!$A$2:$H$65536,8,0),"") | F18: =IFERROR(E18*C18,"") | G18: =IFERROR(F18/$F$66,"")
B19: =IFERROR(VLOOKUP(H19,[1]SEMIELABORADOS!$A$2:$M$6000,2,0),"") | C19: =+A19 -> 0 | D19: =IFERROR(VLOOKUP(H19,[1]SEMIELABORADOS!$A$2:$M$6000,6,0),"") | E19: =IFERROR(VLOOKUP(H19,[1]SEMIELABORADOS!$A$2:$H$65536,8,0),"") | F19: =IFERROR(E19*C19,"") | G19: =IFERROR(F19/$F$66,"")
B20: =IFERROR(VLOOKUP(H20,[1]SEMIELABORADOS!$A$2:$M$6000,2,0),"") | C20: =+A20 -> 0 | D20: =IFERROR(VLOOKUP(H20,[1]SEMIELABORADOS!$A$2:$M$6000,6,0),"") | E20: =IFERROR(VLOOKUP(H20,[1]SEMIELABORADOS!$A$2:$H$65536,8,0),"") | F20: =IFERROR(E20*C20,"") | G20: =IFERROR(F20/$F$66,"")
B21: =IFERROR(VLOOKUP(H21,[1]SEMIELABORADOS!$A$2:$M$6000,2,0),"") | C21: =+A21 -> 0 | D21: =IFERROR(VLOOKUP(H21,[1]SEMIELABORADOS!$A$2:$M$6000,6,0),"") | E21: =IFERROR(VLOOKUP(H21,[1]SEMIELABORADOS!$A$2:$H$65536,8,0),"") | F21: =IFERROR(E21*C21,"") | G21: =IFERROR(F21/$F$66,"")
B22: =IFERROR(VLOOKUP(H22,[1]SEMIELABORADOS!$A$2:$M$6000,2,0),"") | C22: =+A22 -> 0 | D22: =IFERROR(VLOOKUP(H22,[1]SEMIELABORADOS!$A$2:$M$6000,6,0),"") | E22: =IFERROR(VLOOKUP(H22,[1]SEMIELABORADOS!$A$2:$H$65536,8,0),"") | F22: =IFERROR(E22*C22,"") | G22: =IFERROR(F22/$F$66,"")
B23: =IFERROR(VLOOKUP(H23,[1]SEMIELABORADOS!$A$2:$M$6000,2,0),"") | C23: =+A23 -> 0 | D23: =IFERROR(VLOOKUP(H23,[1]SEMIELABORADOS!$A$2:$M$6000,6,0),"") | E23: =IFERROR(VLOOKUP(H23,[1]SEMIELABORADOS!$A$2:$H$65536,8,0),"") | F23: =IFERROR(E23*C23,"") | G23: =IFERROR(F23/$F$66,"")
B24: =IFERROR(VLOOKUP(H24,[1]SEMIELABORADOS!$A$2:$M$6000,2,0),"") | C24: =+A24 -> 0 | D24: =IFERROR(VLOOKUP(H24,[1]SEMIELABORADOS!$A$2:$M$6000,6,0),"") | E24: =IFERROR(VLOOKUP(H24,[1]SEMIELABORADOS!$A$2:$H$65536,8,0),"") | F24: =IFERROR(E24*C24,"") | G24: =IFERROR(F24/$F$66,"")
A26: UNIDADES | B26: EMPAQUE | C26: UNIDADES | D26: UND MEDIDA | E26: COSTO UNITARIO | F26: TOTAL COSTO | G26: % PREC. DEFINIDO | H26: CODIGOS
A27: 1 | B27: Etiqueta Blanca 2 5/8X1 15/16 | C27: =+A27 -> 1 | D27: UND | E27: 2.13 | F27: =IFERROR(C27*E27,"") -> 2.13 | G27: =IFERROR(F27/$F$66,"") -> 6.1495768e-05 | H27: EM10011
B28: =IFERROR(VLOOKUP(H28,'[1]Consolidado MP Planta'!$A$2:$M$823,3,0),"") | C28: =+A28 -> 0 | D28: =IFERROR(VLOOKUP(H28,'[1]Consolidado MP Planta'!$A$2:$M$823,13,0),"") | E28: =IFERROR(VLOOKUP(H28,'[1]Consolidado MP Planta'!$A$2:$M$823,12,0),"") | F28: =IFERROR(C28*E28,"") | G28: =IFERROR(F28/$F$66,"")
B29: =IFERROR(VLOOKUP(H29,'[1]Consolidado MP Planta'!$A$2:$M$823,3,0),"") | C29: =+A29 -> 0 | D29: =IFERROR(VLOOKUP(H29,'[1]Consolidado MP Planta'!$A$2:$M$823,13,0),"") | E29: =IFERROR(VLOOKUP(H29,'[1]Consolidado MP Planta'!$A$2:$M$823,12,0),"") | F29: =IFERROR(C29*E29,"") | G29: =IFERROR(F29/$F$66,"")
B30: =IFERROR(VLOOKUP(H30,'[1]Consolidado MP Planta'!$A$2:$M$823,3,0),"") | C30: =+A30 -> 0 | D30: =IFERROR(VLOOKUP(H30,'[1]Consolidado MP Planta'!$A$2:$M$823,13,0),"") | E30: =IFERROR(VLOOKUP(H30,'[1]Consolidado MP Planta'!$A$2:$M$823,12,0),"") | F30: =IFERROR(C30*E30,"") | G30: =IFERROR(F30/$F$66,"")
B31: =IFERROR(VLOOKUP(H31,'[1]Consolidado MP Planta'!$A$2:$M$823,3,0),"") | C31: =+A31 -> 0 | D31: =IFERROR(VLOOKUP(H31,'[1]Consolidado MP Planta'!$A$2:$M$823,13,0),"") | E31: =IFERROR(VLOOKUP(H31,'[1]Consolidado MP Planta'!$A$2:$M$823,12,0),"") | F31: =IFERROR(C31*E31,"") | G31: =IFERROR(F31/$F$66,"")
B32: =IFERROR(VLOOKUP(H32,'[1]Consolidado MP Planta'!$A$2:$M$823,3,0),"") | C32: =+A32 -> 0 | D32: =IFERROR(VLOOKUP(H32,'[1]Consolidado MP Planta'!$A$2:$M$823,13,0),"") | E32: =IFERROR(VLOOKUP(H32,'[1]Consolidado MP Planta'!$A$2:$M$823,12,0),"") | F32: =IFERROR(C32*E32,"") | G32: =IFERROR(F32/$F$66,"")
A34: UNIDADES | B34: EMPAQUE SEMIELABORADOS | C34: UNIDADES | D34: UND MEDIDA | E34: COSTO UNITARIO | F34: TOTAL COSTO | G34: % PREC. DEFINIDO | H34: CODIGOS
A35: =+A17 -> 3500 | B35: Almibar | C35: =+A35 -> 3500 | D35: Gramos | E35: 0.01 | F35: =IFERROR(E35*C35,"") -> 35 | G35: =IFERROR(F35/$F$66,"") -> 0.0010104938 | H35: SE00005
A36: =+A18 -> 0 | B36: =IFERROR(VLOOKUP(H36,[1]SEMIELABORADOS!$A$2:$M$6000,2,0),"") | C36: =+A36 -> 0 | D36: =IFERROR(VLOOKUP(H36,[1]SEMIELABORADOS!$A$2:$M$6000,6,0),"") | E36: =IFERROR(VLOOKUP(H36,[1]SEMIELABORADOS!$A$2:$M$65536,10,0),"") | F36: =IFERROR(E36*C36,"") | G36: =IFERROR(F36/$F$66,"")
A37: =+A19 -> 0 | B37: =IFERROR(VLOOKUP(H37,[1]SEMIELABORADOS!$A$2:$M$6000,2,0),"") | C37: =+A37 -> 0 | D37: =IFERROR(VLOOKUP(H37,[1]SEMIELABORADOS!$A$2:$M$6000,6,0),"") | E37: =IFERROR(VLOOKUP(H37,[1]SEMIELABORADOS!$A$2:$M$65536,10,0),"") | F37: =IFERROR(E37*C37,"") | G37: =IFERROR(F37/$F$66,"")
A38: =+A20 -> 0 | B38: =IFERROR(VLOOKUP(H38,[1]SEMIELABORADOS!$A$2:$M$6000,2,0),"") | C38: =+A38 -> 0 | D38: =IFERROR(VLOOKUP(H38,[1]SEMIELABORADOS!$A$2:$M$6000,6,0),"") | E38: =IFERROR(VLOOKUP(H38,[1]SEMIELABORADOS!$A$2:$M$65536,10,0),"") | F38: =IFERROR(E38*C38,"") | G38: =IFERROR(F38/$F$66,"")
A39: =+A21 -> 0 | B39: =IFERROR(VLOOKUP(H39,[1]SEMIELABORADOS!$A$2:$M$6000,2,0),"") | C39: =+A39 -> 0 | D39: =IFERROR(VLOOKUP(H39,[1]SEMIELABORADOS!$A$2:$M$6000,6,0),"") | E39: =IFERROR(VLOOKUP(H39,[1]SEMIELABORADOS!$A$2:$M$65536,10,0),"") | F39: =IFERROR(E39*C39,"") | G39: =IFERROR(F39/$F$66,"")
A40: =+A22 -> 0 | B40: =IFERROR(VLOOKUP(H40,[1]SEMIELABORADOS!$A$2:$M$6000,2,0),"") | C40: =+A40 -> 0 | D40: =IFERROR(VLOOKUP(H40,[1]SEMIELABORADOS!$A$2:$M$6000,6,0),"") | E40: =IFERROR(VLOOKUP(H40,[1]SEMIELABORADOS!$A$2:$M$65536,10,0),"") | F40: =IFERROR(E40*C40,"") | G40: =IFERROR(F40/$F$66,"")
A41: =+A23 -> 0 | B41: =IFERROR(VLOOKUP(H41,[1]SEMIELABORADOS!$A$2:$M$6000,2,0),"") | C41: =+A41 -> 0 | D41: =IFERROR(VLOOKUP(H41,[1]SEMIELABORADOS!$A$2:$M$6000,6,0),"") | E41: =IFERROR(VLOOKUP(H41,[1]SEMIELABORADOS!$A$2:$M$65536,10,0),"") | F41: =IFERROR(E41*C41,"") | G41: =IFERROR(F41/$F$66,"")
A43: UNIDADES | B43: MODI | C43: UNIDADES | D43: UND MEDIDA | E43: COSTO UNITARIO | F43: TOTAL COSTO | G43: % PREC. DEFINIDO | H43: CODIGOS
A44: =+A35 -> 3500 | B44: Almibar | C44: =+A44 -> 3500 | D44: Gramos | E44: 0.03 | F44: =IFERROR(E44*C44,"") -> 105 | G44: =IFERROR(F44/$F$66,"") -> 0.0030314815 | H44: SE00005
A45: =+A36 -> 0 | B45: =IFERROR(VLOOKUP(H45,[1]SEMIELABORADOS!$A$2:$M$6000,2,0),"") | C45: =+A45 -> 0 | D45: =IFERROR(VLOOKUP(H45,[1]SEMIELABORADOS!$A$2:$M$6000,6,0),"") | E45: =IFERROR(VLOOKUP(H45,[1]SEMIELABORADOS!$A$2:$M$65536,12,0),"") | F45: =IFERROR(E45*C45,"") | G45: =IFERROR(F45/$F$66,"")
...

Sheet Mezcla Flan Caramelo
C1: SERVICIOS DE PASTELERIA S.A. | H1: CÓDIGO: | I1: ESP-RE-POS-017
C2: ESPECIFICACION DE RECETA | H2: REVISIÓN: | I2: 02
C3: Mezcla Flan de Caramelo SPOON (KILO) SE00619 | H3: FECHA DE APROBACIÓN: | I3: 45615
C4: Elaborado | D4: Javier Tong, Chef
C5: Aprobado | D5: Esteban Cartin, Gte Manufactura
A6: AREA QUE PRODUCE: | D6: Postres | G6: AREA QUE EMPACA: | I6: Postres
A7: # Código | B7: # Código Netsuite | C7: Descripción del ingrediente | D7: Marca | E7: Unidad Internacional | G7: Medida alternativa | I7: Costo - Referencia
E8: Cantidad | F8: Unidad medida | G8: Cantidad | H8: Unidad medida | I8: Colones
C9: Ensamble
A10: 11400046 | B10: MP10050 | C10: LECHE CONDENSADA (PAQ:11 K) | D10: NESTLE | E10: 26000 | F10: g
A11: 1110414 | B11: MP10024 | C11: LECHE EVAPORADA (UND: 1 L) | D11: NESTLE | E11: 14000 | F11: g
A12: 1210482 | B12: MP10005 | C12: HUEVO LIQUIDO REFRIGERADO | D12: INNOVO | E12: 4600 | F12: g
A13: 11300011 | B13: MP10037 | C13: YEMA DE HUEVO PASTEURIZADA | D13: INNOVO | E13: 4600 | F13: g
A14: 1212410 | B14: MP10008 | C14: PRESERVANTE 1047S | D14: ASEAL | E14: 50 | F14: g
C15: AGUA POTABLE (PLANTA) | D15: FAS | E15: 1000 | F15: g
B16: MP10043 | C16: GELATINA PURA (PAQ:1 K) | D16: MAYCA | E16: 190 | F16: g
C21: Decoración
C30: Empaque
D43: Cantidad | E43: Unidad
A44: PESO TOTAL OBTENIDO | D44: 50000 | E44: g | F44: Tiempo de Horneo:
A45: TIEMPO TOTAL DE PREPARACION | D45: 10 | E45: Minutos | F45: Horno:
A46: CANTIDAD DE PORCIONES OBTENIDAS | D46: 1 | E46: Tanda | F46: Temperatura de Horneo:
A47: PESO DE CADA PORCIÓN | D47: 50000 | E47: g | F47: Otros
A48: MERMA | D48: 440 | E48: g
A49: PROCEDIMIENTO DE PREPARACION DE LA RECETA
A50: 1,- Mezclar todos los ingredientes del flan en el vaso de la licuadora y licuar por 3 minutos en velocidad alta hasta que todo se mezcle bien
A51: 2,- Después de mezclar, dosifiquen en la olla.
A52: 3,- Usar de inmediato y pesar 500gr de mezcla por cada molde, mezclar con un batidor cada 5 minutos para evitar que la condensada se separe.
A58: CONTROL DE CAMBIOS
A59: 2, Se actualiaz procedimiento

Sheet Caramelo para flan
C1: SERVICIOS DE PASTELERIA S.A. | H1: CÓDIGO: | I1: ESP-RE-POS-025
C2: ESPECIFICACION DE RECETA | H2: REVISIÓN: | I2: 01
C3: Caramelo para Flan 900g Spoon 907000012(SE00048) | H3: FECHA DE APROBACIÓN: | I3: 45615
C4: Elaborado | D4: Javier Tong, Chef
C5: Aprobado | D5: Esteban Cartin, Gte Manufactura
A6: AREA QUE PRODUCE: | D6: Postres | G6: AREA QUE EMPACA: | I6: Postres
A7: # Código | B7: # Código Netsuite | C7: Descripción del ingrediente | D7: Marca | E7: Unidad Internacional | G7: Medida alternativa | I7: Costo - Referencia
E8: Cantidad | F8: Unidad medida | G8: Cantidad | H8: Unidad medida | I8: Colones
C9: Ensamble
A10: 90100131 | B10: SE00016 | C10: EMPAQUE AZUCAR INDUSTRIAL | D10: VICTORIA | E10: 1000 | F10: g
C21: Decoración
C30: Empaque
D43: Cantidad | E43: Unidad
A44: PESO TOTAL OBTENIDO | D44: 900 | E44: g | F44: Tiempo de Horneo:
A45: TIEMPO TOTAL DE PREPARACION | D45: 6 | E45: Min. | F45: Horno:
A46: CANTIDAD DE PORCIONES OBTENIDAS | D46: 1 | E46: Und. | F46: Temperatura de Horneo:
A47: PESO DE CADA PORCIÓN | D47: 900 | E47: g | F47: Otros
A48: MERMA | D48: 100 | E48: g
A49: PROCEDIMIENTO DE PREPARACION DE LA RECETA
A50: 1- colocar en la hornilla un sartén limpio, prender a llama media
A51: 2- colocar el kilo de azúcar refinada y mover de vez en cuando hasta obtener que el azúcar se derrita por completo
A52: 3- verter sobre los moldes a utilizar inmediatamente
A53: 4- producto que se debe de manejar con sumo cuidado, peligroso una quemadura, no se guarda se aplica de inmediato
A58: CONTROL DE CAMBIOS

Sheet Costo Flan
E1: Precio Local | F1: Costo MP | G1: Costo EM | H1: Costo MO
E2: =IFERROR(O62,"") -> 1187.1328 | F2: =IFERROR(H53,"") -> 1172.864 | G2: =IFERROR(H54,"") -> 1.568 | H2: =IFERROR(H56,"") -> 87.318
A5: ESTRUCTURA DE COSTOS
F6: Fecha: | H6: =TODAY() -> 46056
A7: UNIDADES | B7: DESCRIPCION MAT.PRIMA | C7: UNIDADES | D7: UND MEDIDA | E7: COSTO UNITARIO | F7: TOTAL COSTO | G7: % PREC. DEFINIDO | H7: CODIGOS
B8: =IFERROR(VLOOKUP(H8,'[1]Consolidado MP Planta'!$A$2:$M$823,3,0),"") | C8: =+A8 -> 0 | D8: =IFERROR(VLOOKUP(H8,'[1]Consolidado MP Planta'!$A$2:$M$823,13,0),"") | E8: =IFERROR(VLOOKUP(H8,'[1]Consolidado MP Planta'!$A$2:$M$823,12,0),"") | F8: =IFERROR(C8*E8,"") | G8: =IFERROR(F8/$F$66,"")
B9: =IFERROR(VLOOKUP(H9,'[1]Consolidado MP Planta'!$A$2:$M$823,3,0),"") | C9: =+A9 -> 0 | D9: =IFERROR(VLOOKUP(H9,'[1]Consolidado MP Planta'!$A$2:$M$823,13,0),"") | E9: =IFERROR(VLOOKUP(H9,'[1]Consolidado MP Planta'!$A$2:$M$823,12,0),"") | F9: =IFERROR(C9*E9,"") | G9: =IFERROR(F9/$F$66,"")
B10: =IFERROR(VLOOKUP(H10,'[1]Consolidado MP Planta'!$A$2:$M$823,3,0),"") | C10: =+A10 -> 0 | D10: =IFERROR(VLOOKUP(H10,'[1]Consolidado MP Planta'!$A$2:$M$823,13,0),"") | E10: =IFERROR(VLOOKUP(H10,'[1]Consolidado MP Planta'!$A$2:$M$823,12,0),"") | F10: =IFERROR(C10*E10,"") | G10: =IFERROR(F10/$F$66,"")
B11: =IFERROR(VLOOKUP(H11,'[1]Consolidado MP Planta'!$A$2:$M$823,3,0),"") | C11: =+A11 -> 0 | D11: =IFERROR(VLOOKUP(H11,'[1]Consolidado MP Planta'!$A$2:$M$823,13,0),"") | E11: =IFERROR(VLOOKUP(H11,'[1]Consolidado MP Planta'!$A$2:$M$823,12,0),"") | F11: =IFERROR(C11*E11,"") | G11: =IFERROR(F11/$F$66,"")
B12: =IFERROR(VLOOKUP(H12,'[1]Consolidado MP Planta'!$A$2:$M$823,3,0),"") | C12: =+A12 -> 0 | D12: =IFERROR(VLOOKUP(H12,'[1]Consolidado MP Planta'!$A$2:$M$823,13,0),"") | E12: =IFERROR(VLOOKUP(H12,'[1]Consolidado MP Planta'!$A$2:$M$823,12,0),"") | F12: =IFERROR(C12*E12,"") | G12: =IFERROR(F12/$F$66,"")
B13: =IFERROR(VLOOKUP(H13,'[1]Consolidado MP Planta'!$A$2:$M$823,3,0),"") | C13: =+A13 -> 0 | D13: =IFERROR(VLOOKUP(H13,'[1]Consolidado MP Planta'!$A$2:$M$823,13,0),"") | E13: =IFERROR(VLOOKUP(H13,'[1]Consolidado MP Planta'!$A$2:$M$823,12,0),"") | F13: =IFERROR(C13*E13,"") | G13: =IFERROR(F13/$F$66,"")
B14: =IFERROR(VLOOKUP(H14,'[1]Consolidado MP Planta'!$A$2:$M$823,3,0),"") | C14: =+A14 -> 0 | D14: =IFERROR(VLOOKUP(H14,'[1]Consolidado MP Planta'!$A$2:$M$823,13,0),"") | E14: =IFERROR(VLOOKUP(H14,'[1]Consolidado MP Planta'!$A$2:$M$823,12,0),"") | F14: =IFERROR(C14*E14,"") | G14: =IFERROR(F14/$F$66,"")
B15: =IFERROR(VLOOKUP(H15,[2]Hoja2!$A$2:$G$589,2,0),"")
A16: UNIDADES | B16: MATERIA PRIMA SEMIELABORADOS | C16: UNIDADES | D16: UND MEDIDA | E16: COSTO UNITARIO | F16: TOTAL COSTO | G16: % PREC. DEFINIDO | H16: CODIGOS
A17: 8400 | B17: Mezcla Flan Caramelo Spoon | C17: =+A17 -> 8400 | D17: Gramos | E17: 1.88 | F17: =IFERROR(E17*C17,"") -> 15792 | G17: =IFERROR(F17/$F$66,"") -> 0.90251841 | H17: SE00619
A18: 1120 | B18: Caramelo Para Flan 900 grs Spoon | C18: =+A18 -> 1120 | D18: Gramos | E18: 0.86 | F18: =IFERROR(E18*C18,"") -> 963.2 | G18: =IFERROR(F18/$F$66,"") -> 0.055047222 | H18: SE00048
B19: =IFERROR(VLOOKUP(H19,[1]SEMIELABORADOS!$A$2:$M$6000,2,0),"") | C19: =+A19 -> 0 | D19: =IFERROR(VLOOKUP(H19,[1]SEMIELABORADOS!$A$2:$M$6000,6,0),"") | E19: =IFERROR(VLOOKUP(H19,[1]SEMIELABORADOS!$A$2:$H$65536,8,0),"") | F19: =IFERROR(E19*C19,"") | G19: =IFERROR(F19/$F$66,"")
B20: =IFERROR(VLOOKUP(H20,[1]SEMIELABORADOS!$A$2:$M$6000,2,0),"") | C20: =+A20 -> 0 | D20: =IFERROR(VLOOKUP(H20,[1]SEMIELABORADOS!$A$2:$M$6000,6,0),"") | E20: =IFERROR(VLOOKUP(H20,[1]SEMIELABORADOS!$A$2:$H$65536,8,0),"") | F20: =IFERROR(E20*C20,"") | G20: =IFERROR(F20/$F$66,"")
B21: =IFERROR(VLOOKUP(H21,[1]SEMIELABORADOS!$A$2:$M$6000,2,0),"") | C21: =+A21 -> 0 | D21: =IFERROR(VLOOKUP(H21,[1]SEMIELABORADOS!$A$2:$M$6000,6,0),"") | E21: =IFERROR(VLOOKUP(H21,[1]SEMIELABORADOS!$A$2:$H$65536,8,0),"") | F21: =IFERROR(E21*C21,"") | G21: =IFERROR(F21/$F$66,"")
B22: =IFERROR(VLOOKUP(H22,[1]SEMIELABORADOS!$A$2:$M$6000,2,0),"") | C22: =+A22 -> 0 | D22: =IFERROR(VLOOKUP(H22,[1]SEMIELABORADOS!$A$2:$M$6000,6,0),"") | E22: =IFERROR(VLOOKUP(H22,[1]SEMIELABORADOS!$A$2:$H$65536,8,0),"") | F22: =IFERROR(E22*C22,"") | G22: =IFERROR(F22/$F$66,"")
B23: =IFERROR(VLOOKUP(H23,[1]SEMIELABORADOS!$A$2:$M$6000,2,0),"") | C23: =+A23 -> 0 | D23: =IFERROR(VLOOKUP(H23,[1]SEMIELABORADOS!$A$2:$M$6000,6,0),"") | E23: =IFERROR(VLOOKUP(H23,[1]SEMIELABORADOS!$A$2:$H$65536,8,0),"") | F23: =IFERROR(E23*C23,"") | G23: =IFERROR(F23/$F$66,"")
B24: =IFERROR(VLOOKUP(H24,[1]SEMIELABORADOS!$A$2:$M$6000,2,0),"") | C24: =+A24 -> 0 | D24: =IFERROR(VLOOKUP(H24,[1]SEMIELABORADOS!$A$2:$M$6000,6,0),"") | E24: =IFERROR(VLOOKUP(H24,[1]SEMIELABORADOS!$A$2:$H$65536,8,0),"") | F24: =IFERROR(E24*C24,"") | G24: =IFERROR(F24/$F$66,"")
A26: UNIDADES | B26: EMPAQUE | C26: UNIDADES | D26: UND MEDIDA | E26: COSTO UNITARIO | F26: TOTAL COSTO | G26: % PREC. DEFINIDO | H26: CODIGOS
A27: 0 | B27: =IFERROR(VLOOKUP(H27,'[1]Consolidado MP Planta'!$A$2:$M$823,3,0),"") | C27: =+A27 -> 0 | D27: =IFERROR(VLOOKUP(H27,'[1]Consolidado MP Planta'!$A$2:$M$823,13,0),"") | E27: =IFERROR(VLOOKUP(H27,'[1]Consolidado MP Planta'!$A$2:$M$823,12,0),"") | F27: =IFERROR(C27*E27,"") | G27: =IFERROR(F27/$F$66,"")
B28: =IFERROR(VLOOKUP(H28,'[1]Consolidado MP Planta'!$A$2:$M$823,3,0),"") | C28: =+A28 -> 0 | D28: =IFERROR(VLOOKUP(H28,'[1]Consolidado MP Planta'!$A$2:$M$823,13,0),"") | E28: =IFERROR(VLOOKUP(H28,'[1]Consolidado MP Planta'!$A$2:$M$823,12,0),"") | F28: =IFERROR(C28*E28,"") | G28: =IFERROR(F28/$F$66,"")
B29: =IFERROR(VLOOKUP(H29,'[1]Consolidado MP Planta'!$A$2:$M$823,3,0),"") | C29: =+A29 -> 0 | D29: =IFERROR(VLOOKUP(H29,'[1]Consolidado MP Planta'!$A$2:$M$823,13,0),"") | E29: =IFERROR(VLOOKUP(H29,'[1]Consolidado MP Planta'!$A$2:$M$823,12,0),"") | F29: =IFERROR(C29*E29,"") | G29: =IFERROR(F29/$F$66,"")
B30: =IFERROR(VLOOKUP(H30,'[1]Consolidado MP Planta'!$A$2:$M$823,3,0),"") | C30: =+A30 -> 0 | D30: =IFERROR(VLOOKUP(H30,'[1]Consolidado MP Planta'!$A$2:$M$823,13,0),"") | E30: =IFERROR(VLOOKUP(H30,'[1]Consolidado MP Planta'!$A$2:$M$823,12,0),"") | F30: =IFERROR(C30*E30,"") | G30: =IFERROR(F30/$F$66,"")
B31: =IFERROR(VLOOKUP(H31,'[1]Consolidado MP Planta'!$A$2:$M$823,3,0),"") | C31: =+A31 -> 0 | D31: =IFERROR(VLOOKUP(H31,'[1]Consolidado MP Planta'!$A$2:$M$823,13,0),"") | E31: =IFERROR(VLOOKUP(H31,'[1]Consolidado MP Planta'!$A$2:$M$823,12,0),"") | F31: =IFERROR(C31*E31,"") | G31: =IFERROR(F31/$F$66,"")
B32: =IFERROR(VLOOKUP(H32,'[1]Consolidado MP Planta'!$A$2:$M$823,3,0),"") | C32: =+A32 -> 0 | D32: =IFERROR(VLOOKUP(H32,'[1]Consolidado MP Planta'!$A$2:$M$823,13,0),"") | E32: =IFERROR(VLOOKUP(H32,'[1]Consolidado MP Planta'!$A$2:$M$823,12,0),"") | F32: =IFERROR(C32*E32,"") | G32: =IFERROR(F32/$F$66,"")
A34: UNIDADES | B34: EMPAQUE SEMIELABORADOS | C34: UNIDADES | D34: UND MEDIDA | E34: COSTO UNITARIO | F34: TOTAL COSTO | G34: % PREC. DEFINIDO | H34: CODIGOS
A35: =+A17 -> 8400 | B35: Mezcla Flan Caramelo Spoon | C35: =+A35 -> 8400 | D35: Gramos | E35: 0 | F35: =IFERROR(E35*C35,"") -> 0 | G35: =IFERROR(F35/$F$66,"") -> 0 | H35: SE00619
A36: =+A18 -> 1120 | B36: Caramelo Para Flan 900 grs Spoon | C36: =+A36 -> 1120 | D36: Gramos | E36: 0.02 | F36: =IFERROR(E36*C36,"") -> 22.4 | G36: =IFERROR(F36/$F$66,"") -> 0.001280168 | H36: SE00048
A37: =+A19 -> 0 | B37: =IFERROR(VLOOKUP(H37,[1]SEMIELABORADOS!$A$2:$M$6000,2,0),"") | C37: =+A37 -> 0 | D37: =IFERROR(VLOOKUP(H37,[1]SEMIELABORADOS!$A$2:$M$6000,6,0),"") | E37: =IFERROR(VLOOKUP(H37,[1]SEMIELABORADOS!$A$2:$M$65536,10,0),"") | F37: =IFERROR(E37*C37,"") | G37: =IFERROR(F37/$F$66,"")
A38: =+A20 -> 0 | B38: =IFERROR(VLOOKUP(H38,[1]SEMIELABORADOS!$A$2:$M$6000,2,0),"") | C38: =+A38 -> 0 | D38: =IFERROR(VLOOKUP(H38,[1]SEMIELABORADOS!$A$2:$M$6000,6,0),"") | E38: =IFERROR(VLOOKUP(H38,[1]SEMIELABORADOS!$A$2:$M$65536,10,0),"") | F38: =IFERROR(E38*C38,"") | G38: =IFERROR(F38/$F$66,"")
A39: =+A21 -> 0 | B39: =IFERROR(VLOOKUP(H39,[1]SEMIELABORADOS!$A$2:$M$6000,2,0),"") | C39: =+A39 -> 0 | D39: =IFERROR(VLOOKUP(H39,[1]SEMIELABORADOS!$A$2:$M$6000,6,0),"") | E39: =IFERROR(VLOOKUP(H39,[1]SEMIELABORADOS!$A$2:$M$65536,10,0),"") | F39: =IFERROR(E39*C39,"") | G39: =IFERROR(F39/$F$66,"")
A40: =+A22 -> 0 | B40: =IFERROR(VLOOKUP(H40,[1]SEMIELABORADOS!$A$2:$M$6000,2,0),"") | C40: =+A40 -> 0 | D40: =IFERROR(VLOOKUP(H40,[1]SEMIELABORADOS!$A$2:$M$6000,6,0),"") | E40: =IFERROR(VLOOKUP(H40,[1]SEMIELABORADOS!$A$2:$M$65536,10,0),"") | F40: =IFERROR(E40*C40,"") | G40: =IFERROR(F40/$F$66,"")
A41: =+A23 -> 0 | B41: =IFERROR(VLOOKUP(H41,[1]SEMIELABORADOS!$A$2:$M$6000,2,0),"") | C41: =+A41 -> 0 | D41: =IFERROR(VLOOKUP(H41,[1]SEMIELABORADOS!$A$2:$M$6000,6,0),"") | E41: =IFERROR(VLOOKUP(H41,[1]SEMIELABORADOS!$A$2:$M$65536,10,0),"") | F41: =IFERROR(E41*C41,"") | G41: =IFERROR(F41/$F$66,"")
A43: UNIDADES | B43: MODI | C43: UNIDADES | D43: UND MEDIDA | E43: COSTO UNITARIO | F43: TOTAL COSTO | G43: % PREC. DEFINIDO | H43: CODIGOS
A44: =+A35 -> 8400 | B44: Mezcla Flan Caramelo Spoon | C44: =+A44 -> 8400 | D44: Gramos | E44: 0.04 | F44: =IFERROR(E44*C44,"") -> 336 | G44: =IFERROR(F44/$F$66,"") -> 0.019202519 | H44: SE00619
A45: =+A36 -> 1120 | B45: Caramelo Para Flan 900 grs Spoon | C45: =+A45 -> 1120 | D45: Gramos | E45: 0.47 | F45: =IFERROR(E45*C45,"") -> 526.4 | G45: =IFERROR(F45/$F$66,"") -> 0.030083947 | H45: SE00048
...

Sheet Costo Marañon Caramelizado
E1: Precio Local | F1: Costo MP | G1: Costo EM | H1: Costo MO
E2: =IFERROR(O62,"") -> 21312 | F2: =IFERROR(H53,"") -> 18112 | G2: =IFERROR(H54,"") -> 0 | H2: =IFERROR(H56,"") -> 1540
A5: ESTRUCTURA DE COSTOS
F6: Fecha: | H6: =TODAY() -> 46056
A7: UNIDADES | B7: DESCRIPCION MAT.PRIMA | C7: UNIDADES | D7: UND MEDIDA | E7: COSTO UNITARIO | F7: TOTAL COSTO | G7: % PREC. DEFINIDO | H7: CODIGOS
A8: 6400 | B8: MARAÑON TOSTADO | C8: =+A8 -> 6400 | D8: Gramos | E8: 2.55 | F8: =IFERROR(C8*E8,"") -> 16320 | G8: =IFERROR(F8/$F$66,"") -> 0.81541942 | H8: NUEVO
A9: 0 | B9: Almendra Fileteada | C9: =+A9 -> 0 | D9: Gramos | E9: 7.55 | F9: =IFERROR(C9*E9,"") -> 0 | G9: =IFERROR(F9/$F$66,"") -> 0 | H9: MP10066
A10: 3200 | B10: Azucar Blanco Industrial | C10: =+A10 -> 3200 | D10: Gramos | E10: 0.56 | F10: =IFERROR(C10*E10,"") -> 1792 | G10: =IFERROR(F10/$F$66,"") -> 0.08953625 | H10: MP10074
B11: =IFERROR(VLOOKUP(H11,'[1]Consolidado MP Planta'!$A$2:$M$823,3,0),"") | C11: =+A11 -> 0 | E11: =IFERROR(VLOOKUP(H11,'[1]Consolidado MP Planta'!$A$2:$M$823,12,0),"") | F11: =IFERROR(C11*E11,"") | G11: =IFERROR(F11/$F$66,"")
B12: =IFERROR(VLOOKUP(H12,'[1]Consolidado MP Planta'!$A$2:$M$823,3,0),"") | C12: =+A12 -> 0 | D12: =IFERROR(VLOOKUP(H12,'[1]Consolidado MP Planta'!$A$2:$M$823,13,0),"") | E12: =IFERROR(VLOOKUP(H12,'[1]Consolidado MP Planta'!$A$2:$M$823,12,0),"") | F12: =IFERROR(C12*E12,"") | G12: =IFERROR(F12/$F$66,"")
B13: =IFERROR(VLOOKUP(H13,'[1]Consolidado MP Planta'!$A$2:$M$823,3,0),"") | C13: =+A13 -> 0 | D13: =IFERROR(VLOOKUP(H13,'[1]Consolidado MP Planta'!$A$2:$M$823,13,0),"") | E13: =IFERROR(VLOOKUP(H13,'[1]Consolidado MP Planta'!$A$2:$M$823,12,0),"") | F13: =IFERROR(C13*E13,"") | G13: =IFERROR(F13/$F$66,"")
B14: =IFERROR(VLOOKUP(H14,'[1]Consolidado MP Planta'!$A$2:$M$823,3,0),"") | C14: =+A14 -> 0 | D14: =IFERROR(VLOOKUP(H14,'[1]Consolidado MP Planta'!$A$2:$M$823,13,0),"") | E14: =IFERROR(VLOOKUP(H14,'[1]Consolidado MP Planta'!$A$2:$M$823,12,0),"") | F14: =IFERROR(C14*E14,"") | G14: =IFERROR(F14/$F$66,"")
B15: =IFERROR(VLOOKUP(H15,[2]Hoja2!$A$2:$G$589,2,0),"")
A16: UNIDADES | B16: MATERIA PRIMA SEMIELABORADOS | C16: UNIDADES | D16: UND MEDIDA | E16: COSTO UNITARIO | F16: TOTAL COSTO | G16: % PREC. DEFINIDO | H16: CODIGOS
B17: =IFERROR(VLOOKUP(H17,[1]SEMIELABORADOS!$A$2:$M$6000,2,0),"") | C17: =+A17 -> 0 | D17: =IFERROR(VLOOKUP(H17,[1]SEMIELABORADOS!$A$2:$M$6000,6,0),"") | E17: =IFERROR(VLOOKUP(H17,[1]SEMIELABORADOS!$A$2:$H$65536,8,0),"") | F17: =IFERROR(E17*C17,"") | G17: =IFERROR(F17/$F$66,"")
B18: =IFERROR(VLOOKUP(H18,[1]SEMIELABORADOS!$A$2:$M$6000,2,0),"") | C18: =+A18 -> 0 | D18: =IFERROR(VLOOKUP(H18,[1]SEMIELABORADOS!$A$2:$M$6000,6,0),"") | E18: =IFERROR(VLOOKUP(H18,[1]SEMIELABORADOS!$A$2:$H$65536,8,0),"") | F18: =IFERROR(E18*C18,"") | G18: =IFERROR(F18/$F$66,"")
B19: =IFERROR(VLOOKUP(H19,[1]SEMIELABORADOS!$A$2:$M$6000,2,0),"") | C19: =+A19 -> 0 | D19: =IFERROR(VLOOKUP(H19,[1]SEMIELABORADOS!$A$2:$M$6000,6,0),"") | E19: =IFERROR(VLOOKUP(H19,[1]SEMIELABORADOS!$A$2:$H$65536,8,0),"") | F19: =IFERROR(E19*C19,"") | G19: =IFERROR(F19/$F$66,"")
B20: =IFERROR(VLOOKUP(H20,[1]SEMIELABORADOS!$A$2:$M$6000,2,0),"") | C20: =+A20 -> 0 | D20: =IFERROR(VLOOKUP(H20,[1]SEMIELABORADOS!$A$2:$M$6000,6,0),"") | E20: =IFERROR(VLOOKUP(H20,[1]SEMIELABORADOS!$A$2:$H$65536,8,0),"") | F20: =IFERROR(E20*C20,"") | G20: =IFERROR(F20/$F$66,"")
B21: =IFERROR(VLOOKUP(H21,[1]SEMIELABORADOS!$A$2:$M$6000,2,0),"") | C21: =+A21 -> 0 | D21: =IFERROR(VLOOKUP(H21,[1]SEMIELABORADOS!$A$2:$M$6000,6,0),"") | E21: =IFERROR(VLOOKUP(H21,[1]SEMIELABORADOS!$A$2:$H$65536,8,0),"") | F21: =IFERROR(E21*C21,"") | G21: =IFERROR(F21/$F$66,"")
B22: =IFERROR(VLOOKUP(H22,[1]SEMIELABORADOS!$A$2:$M$6000,2,0),"") | C22: =+A22 -> 0 | D22: =IFERROR(VLOOKUP(H22,[1]SEMIELABORADOS!$A$2:$M$6000,6,0),"") | E22: =IFERROR(VLOOKUP(H22,[1]SEMIELABORADOS!$A$2:$H$65536,8,0),"") | F22: =IFERROR(E22*C22,"") | G22: =IFERROR(F22/$F$66,"")
B23: =IFERROR(VLOOKUP(H23,[1]SEMIELABORADOS!$A$2:$M$6000,2,0),"") | C23: =+A23 -> 0 | D23: =IFERROR(VLOOKUP(H23,[1]SEMIELABORADOS!$A$2:$M$6000,6,0),"") | E23: =IFERROR(VLOOKUP(H23,[1]SEMIELABORADOS!$A$2:$H$65536,8,0),"") | F23: =IFERROR(E23*C23,"") | G23: =IFERROR(F23/$F$66,"")
B24: =IFERROR(VLOOKUP(H24,[1]SEMIELABORADOS!$A$2:$M$6000,2,0),"") | C24: =+A24 -> 0 | D24: =IFERROR(VLOOKUP(H24,[1]SEMIELABORADOS!$A$2:$M$6000,6,0),"") | E24: =IFERROR(VLOOKUP(H24,[1]SEMIELABORADOS!$A$2:$H$65536,8,0),"") | F24: =IFERROR(E24*C24,"") | G24: =IFERROR(F24/$F$66,"")
A26: UNIDADES | B26: EMPAQUE | C26: UNIDADES | D26: UND MEDIDA | E26: COSTO UNITARIO | F26: TOTAL COSTO | G26: % PREC. DEFINIDO | H26: CODIGOS
A27: 0 | B27: =IFERROR(VLOOKUP(H27,'[1]Consolidado MP Planta'!$A$2:$M$823,3,0),"") | C27: =+A27 -> 0 | D27: =IFERROR(VLOOKUP(H27,'[1]Consolidado MP Planta'!$A$2:$M$823,13,0),"") | E27: =IFERROR(VLOOKUP(H27,'[1]Consolidado MP Planta'!$A$2:$M$823,12,0),"") | F27: =IFERROR(C27*E27,"") | G27: =IFERROR(F27/$F$66,"")
