Workbook

Sheet Premezcla
B1: SERVICIOS DE PASTELERIA S.A. | G1: CÓDIGO:
B2: ESPECIFICACION DE RECETA | G2: REVISIÓN:
B3: Premezcla mufin banano | G3: FECHA DE APROBACIÓN:
B4: Elaborado | C4: Juan Pablo Brenes,chef
B5: Aprobado | C5: Esteban Cartin, Gerente de Manufactura
A7: AREA QUE PRODUCE: | C7: Cocina | F7: AREA QUE EMPACA: | H7: Empaque
A8: # Código | B8: Descripción del ingrediente | C8: Marca | D8: Unidad Internacional | F8: Medida alternativa | H8: Costo - Referencia
D9: Cantidad | E9: Unidad medida | F9: Cantidad | G9: Unidad medida | H9: Colones
A10: 11200070 | B10: HARINA HARISOL HOJALDRE (SACO: 25 K) | C10: Fachasa | D10: 3000 | E10: g
A11: 10100046 | B11: POLVO HORNEAR FLEISHMAN (PAQ:2.5 K) | C11: Fleishman | D11: 150 | E11: g
A12: 503000036 | B12: BICARBONATO DE SODIO (PAQ:2.5 K) | C12: Mayca | D12: 100 | E12: g
A13: 0610256 | B13: NUEZ MOSCADA MOLIDA (PAQ:3 K) | C13: Mayca | D13: 10 | E13: g
A14: 1212410 | B14: PRESERVANTE 1047S (PAQ=5 KILO) | D14: 8 | E14: g
A16: 10100045 | B16: AZUCAR CARAMELO (PAQ:0.5 K) | C16: Layca | D16: 2000 | E16: g
D17: 1250
A18: 0310107 | B18: LACTOCREMA GRANEL (CAJA:25 KG) | C18: Dos pinos | D18: 125 | E18: g
A21: 1950702 | B21: BOLSA 12x18 TRANSP KILO | C21: Plasticos P | D21: 2 | E21: ud
A22: 1950708 | B22: BOLSA 17x25 TRANSP KILO | C22: Plasticos P | D22: 1 | E22: ud
A23: 702123 | B23: ETIQUETA BLANCA 2 5/8X1 15/16 (UND) | C23: Etiplast | D23: 1 | E23: ud
A24: 60100010 | B24: ETIQUETA ROJA LETRA ALERJENO (UND) | C24: Etiplast | D24: 1 | E24: ud
C26: Cantidad | D26: Unidad
A27: PESO TOTAL OBTENIDO | C27: 6500 | D27: g
A28: TIEMPO TOTAL DE PREPARACION | C28: 4 | D28: min
A29: CANTIDAD DE PORCIONES OBTENIDAS | C29: =C27/C30 -> 1 | D29: ud
A30: PESO DE CADA PORCIÓN | C30: 6500 | D30: g
A31: MERMA | C31: =SUM(D10:D23)-C27 -> 147 | D31: g
A32: PROCEDIMIENTO DE PREPARACION DE LA RECETA

Sheet Premezcla 2
B1: SERVICIOS DE PASTELERIA S.A. | G1: CÓDIGO:
B2: ESPECIFICACION DE RECETA | G2: REVISIÓN:
B3: Premezcla queque banano | G3: FECHA DE APROBACIÓN:
B4: Elaborado | C4: Juan Pablo Brenes,chef
B5: Aprobado | C5: Esteban Cartin, Gerente de Manufactura
A7: AREA QUE PRODUCE: | C7: Cocina | F7: AREA QUE EMPACA: | H7: Empaque
A8: # Código | B8: Descripción del ingrediente | C8: Marca | D8: Unidad Internacional | F8: Medida alternativa | H8: Costo - Referencia
D9: Cantidad | E9: Unidad medida | F9: Cantidad | G9: Unidad medida | H9: Colones
A10: 11200070 | B10: HARINA HARISOL HOJALDRE (SACO: 25 K) | C10: Fachasa | D10: 3180 | E10: g
A11: 10100046 | B11: POLVO HORNEAR FLEISHMAN (PAQ:2.5 K) | C11: Fleishman | D11: 150 | E11: g
A12: 503000036 | B12: BICARBONATO DE SODIO (PAQ:2.5 K) | C12: Mayca | D12: 100 | E12: g
A13: 0610256 | B13: NUEZ MOSCADA MOLIDA (PAQ:3 K) | C13: Mayca | D13: 10 | E13: g
A14: 1212410 | B14: PRESERVANTE 1047S (PAQ=5 KILO) | D14: 8 | E14: g
A16: 10100045 | B16: AZUCAR CARAMELO (PAQ:0.5 K) | C16: Layca | D16: 2000 | E16: g
D17: 1250
A18: 0310107 | B18: LACTOCREMA GRANEL (CAJA:25 KG) | C18: Dos pinos | D18: 125 | E18: g
A21: 1950702 | B21: BOLSA 12x18 TRANSP KILO | C21: Plasticos P | D21: 1 | E21: ud
A22: 1950708 | B22: BOLSA 17x25 TRANSP KILO | C22: Plasticos P | D22: 1 | E22: ud
A23: 702123 | B23: ETIQUETA BLANCA 2 5/8X1 15/16 (UND) | C23: Etiplast | D23: 1 | E23: ud
A24: 60100010 | B24: ETIQUETA ROJA LETRA ALERJENO (UND) | C24: Etiplast | D24: 1 | E24: ud
C26: Cantidad | D26: Unidad
A27: PESO TOTAL OBTENIDO | C27: 6680 | D27: g
A28: TIEMPO TOTAL DE PREPARACION | C28: 4 | D28: min
A29: CANTIDAD DE PORCIONES OBTENIDAS | C29: =C27/C30 -> 1 | D29: ud
A30: PESO DE CADA PORCIÓN | C30: 6680 | D30: g
A31: MERMA | C31: =SUM(D10:D23)-C27 -> 146 | D31: g
A32: PROCEDIMIENTO DE PREPARACION DE LA RECETA

Sheet Hoja1
C1: SERVICIOS DE PASTELERIA S.A. | H1: CÓDIGO: | I1: ESP-RE-PRES-030
C2: ESPECIFICACION DE RECETA | H2: REVISIÓN: | I2: 01
C3: SE00424 Premezcla queque banano spoon | H3: FECHA DE APROBACIÓN: | I3: 45617
C4: Elaborado | D4: Javier Tong, Chef
C5: Aprobado | D5: Esteban Cartin, Gte Manufactura
A6: AREA QUE PRODUCE: | D6: Premezclas | G6: AREA QUE EMPACA: | I6: Premezclas
A7: # Código | B7: # Código Netsuite | C7: Descripción del ingrediente | D7: Marca | E7: Unidad Internacional | G7: Medida alternativa | I7: Costo - Referencia
E8: Cantidad | F8: Unidad medida | G8: Cantidad | H8: Unidad medida | I8: Colones
C9: Ensamble
A10: 11200070 | B10: MP10206 | C10: HARINA HARISOL HOJALDRE | D10: FACHASA | E10: 3180 | F10: g
A11: 10100046 | B11: MP10304 | C11: POLVO HORNEAR | D11: FLEISHMAN | E11: 150 | F11: g
A12: 503000036 | B12: MP10085 | C12: BICARBONATO DE SODIO | D12: MAYCA | E12: 100 | F12: g
A13: 0610256 | B13: MP10013 | C13: NUEZ MOSCADA MOLIDA | D13: MAYCA | E13: 10 | F13: g
A14: 1212410 | B14: MP10008 | C14: PRESERVANTE 1047S | E14: 30 | F14: g
A16: 10100045 | B16: MP10075 | C16: AZUCAR CARAMELO | D16: LAYCA | E16: 2000 | F16: g
C21: Decoración
C29: Empaque
A30: 1950702 | B30: EM10016 | C30: BOLSA 12X18 TRANSPARENTE | D30: PLASTICOS P | E30: 1 | F30: ud
A31: 1950708 | B31: EM10013 | C31: BOLSA 17X25 TRANSPARENTE | D31: PLASTICOS P | E31: 2 | F31: ud
A32: 60100010 | B32: EM10133 | C32: ETIQUETA ROJA LETRA ALERJENO | D32: ETIPLAST | E32: 2 | F32: ud
A33: 0702123 | B33: EM10011 | C33: ETIQUETA BLANCA 2 5/8X1 15/16 | D33: ETIPLAST | E33: 2 | F33: ud
D42: Cantidad | E42: Unidad
A43: PESO TOTAL OBTENIDO | D43: 5430 | E43: g | F43: Tiempo de Horneo:
A44: TIEMPO TOTAL DE PREPARACION | D44: 4 | E44: min | F44: Horno:
A45: CANTIDAD DE PORCIONES OBTENIDAS | D45: 1 | E45: ud | F45: Temperatura de Horneo:
A46: PESO DE CADA PORCIÓN | D46: 5430 | E46: g | F46: Otros
A47: MERMA | D47: 143 | E47: g
A48: PROCEDIMIENTO DE PREPARACION DE LA RECETA
A49: 1.- Pesar en la bolsa 12x18 el harina, polvo de hornear, bicarbonato, nuez moscada y preservante.
A50: 2.- En una bolsa 17x25 pesar el azucar caramelo.
A51: 3.- Etiquetar.
A57: CONTROL DE CAMBIOS

Sheet Costo Premezcla 
E1: Precio Local | F1: Costo MP | G1: Costo EM | H1: Costo MO
E2: =IFERROR(O62,"") -> 8416.0095 | F2: =IFERROR(H53,"") -> 6157.91 | G2: =IFERROR(H54,"") -> 122.6941 | H2: =IFERROR(H56,"") -> 232
A5: ESTRUCTURA DE COSTOS
F6: Fecha: | H6: =TODAY() -> 45749
A7: UNIDADES | B7: DESCRIPCION MAT.PRIMA | C7: UNIDADES | D7: UND MEDIDA | E7: COSTO UNITARIO | F7: TOTAL COSTO | G7: % PREC. DEFINIDO | H7: CODIGOS
A8: 3180 | B8: HARINA HARISOL HOJALDRE (SACO: 25 K) | C8: =+A8 -> 3180 | D8: Gramos | E8: 0.68 | F8: =IFERROR(C8*E8,"") -> 2162.4 | G8: =IFERROR(F8/$F$66,"") -> 0.32587062 | H8: 11200070
A9: 150 | B9: =IFERROR(VLOOKUP(H9,'[1]Consolidado MP Planta'!$A$2:$M$823,3,0),"") -> POLVO HORNEAR FLEISHMAN (PAQ:2.5 K) | C9: =+A9 -> 150 | D9: =IFERROR(VLOOKUP(H9,'[1]Consolidado MP Planta'!$A$2:$M$823,13,0),"") -> Gramos | E9: 1.03 | F9: =IFERROR(C9*E9,"") -> 154.5 | G9: =IFERROR(F9/$F$66,"") -> 0.023282932 | H9: 10100046
A10: 100 | B10: =IFERROR(VLOOKUP(H10,'[1]Consolidado MP Planta'!$A$2:$M$823,3,0),"") -> BICARBONATO DE SODIO (PAQ:2.5 K) | C10: =+A10 -> 100 | D10: =IFERROR(VLOOKUP(H10,'[1]Consolidado MP Planta'!$A$2:$M$823,13,0),"") -> Gramos | E10: 1.35 | F10: =IFERROR(C10*E10,"") -> 135 | G10: =IFERROR(F10/$F$66,"") -> 0.020344309 | H10: 503000036
A11: 10 | B11: =IFERROR(VLOOKUP(H11,'[1]Consolidado MP Planta'!$A$2:$M$823,3,0),"") -> NUEZ MOSCADA MOLIDA (PAQ:3 K) | C11: =+A11 -> 10 | D11: =IFERROR(VLOOKUP(H11,'[1]Consolidado MP Planta'!$A$2:$M$823,13,0),"") -> Gramos | E11: 14.66 | F11: =IFERROR(C11*E11,"") -> 146.6 | G11: =IFERROR(F11/$F$66,"") -> 0.022092413 | H11: 0610256
A12: 8 | B12: =IFERROR(VLOOKUP(H12,'[1]Consolidado MP Planta'!$A$2:$M$823,3,0),"") -> PRESERVANTE 1047S (PAQ=5 KILO) | C12: =+A12 -> 8 | D12: =IFERROR(VLOOKUP(H12,'[1]Consolidado MP Planta'!$A$2:$M$823,13,0),"") -> Gramos | E12: 8.52 | F12: =IFERROR(C12*E12,"") -> 68.16 | G12: =IFERROR(F12/$F$66,"") -> 0.010271616 | H12: 1212410
A13: 2000 | B13: =IFERROR(VLOOKUP(H13,'[1]Consolidado MP Planta'!$A$2:$M$823,3,0),"") -> AZUCAR CARAMELO (PAQ:0.5 K) | C13: =+A13 -> 2000 | D13: =IFERROR(VLOOKUP(H13,'[1]Consolidado MP Planta'!$A$2:$M$823,13,0),"") -> Gramos | E13: 1.5 | F13: =IFERROR(C13*E13,"") -> 3000 | G13: =IFERROR(F13/$F$66,"") -> 0.45209576 | H13: 10100045
A14: 125 | B14: =IFERROR(VLOOKUP(H14,'[1]Consolidado MP Planta'!$A$2:$M$823,3,0),"") -> LACTOCREMA GRANEL (CAJA:25 KG) | C14: =+A14 -> 125 | D14: =IFERROR(VLOOKUP(H14,'[1]Consolidado MP Planta'!$A$2:$M$823,13,0),"") -> Gramos | E14: 3.93 | F14: =IFERROR(C14*E14,"") -> 491.25 | G14: =IFERROR(F14/$F$66,"") -> 0.074030681 | H14: 0310107
B15: =IFERROR(VLOOKUP(H15,'[2]ARTICULOS MP PLANTA'!$A$2:$G$589,2,0),"")
A16: UNIDADES | B16: MATERIA PRIMA SEMIELABORADOS | C16: UNIDADES | D16: UND MEDIDA | E16: COSTO UNITARIO | F16: TOTAL COSTO | G16: % PREC. DEFINIDO | H16: CODIGOS
B17: =IFERROR(VLOOKUP(H17,[1]SEMIELABORADOS!$A$2:$M$6000,2,0),"") | C17: =+A17 -> 0 | D17: =IFERROR(VLOOKUP(H17,[1]SEMIELABORADOS!$A$2:$M$6000,6,0),"") | E17: =IFERROR(VLOOKUP(H17,[1]SEMIELABORADOS!$A$2:$H$65536,8,0),"") | F17: =IFERROR(E17*C17,"") | G17: =IFERROR(F17/$F$66,"")
B18: =IFERROR(VLOOKUP(H18,[1]SEMIELABORADOS!$A$2:$M$6000,2,0),"") | C18: =+A18 -> 0 | D18: =IFERROR(VLOOKUP(H18,[1]SEMIELABORADOS!$A$2:$M$6000,6,0),"") | E18: =IFERROR(VLOOKUP(H18,[1]SEMIELABORADOS!$A$2:$H$65536,8,0),"") | F18: =IFERROR(E18*C18,"") | G18: =IFERROR(F18/$F$66,"")
B19: =IFERROR(VLOOKUP(H19,[1]SEMIELABORADOS!$A$2:$M$6000,2,0),"") | C19: =+A19 -> 0 | D19: =IFERROR(VLOOKUP(H19,[1]SEMIELABORADOS!$A$2:$M$6000,6,0),"") | E19: =IFERROR(VLOOKUP(H19,[1]SEMIELABORADOS!$A$2:$H$65536,8,0),"") | F19: =IFERROR(E19*C19,"") | G19: =IFERROR(F19/$F$66,"")
B20: =IFERROR(VLOOKUP(H20,[1]SEMIELABORADOS!$A$2:$M$6000,2,0),"") | C20: =+A20 -> 0 | D20: =IFERROR(VLOOKUP(H20,[1]SEMIELABORADOS!$A$2:$M$6000,6,0),"") | E20: =IFERROR(VLOOKUP(H20,[1]SEMIELABORADOS!$A$2:$H$65536,8,0),"") | F20: =IFERROR(E20*C20,"") | G20: =IFERROR(F20/$F$66,"")
B21: =IFERROR(VLOOKUP(H21,[1]SEMIELABORADOS!$A$2:$M$6000,2,0),"") | C21: =+A21 -> 0 | D21: =IFERROR(VLOOKUP(H21,[1]SEMIELABORADOS!$A$2:$M$6000,6,0),"") | E21: =IFERROR(VLOOKUP(H21,[1]SEMIELABORADOS!$A$2:$H$65536,8,0),"") | F21: =IFERROR(E21*C21,"") | G21: =IFERROR(F21/$F$66,"")
B22: =IFERROR(VLOOKUP(H22,[1]SEMIELABORADOS!$A$2:$M$6000,2,0),"") | C22: =+A22 -> 0 | D22: =IFERROR(VLOOKUP(H22,[1]SEMIELABORADOS!$A$2:$M$6000,6,0),"") | E22: =IFERROR(VLOOKUP(H22,[1]SEMIELABORADOS!$A$2:$H$65536,8,0),"") | F22: =IFERROR(E22*C22,"") | G22: =IFERROR(F22/$F$66,"")
B23: =IFERROR(VLOOKUP(H23,[1]SEMIELABORADOS!$A$2:$M$6000,2,0),"") | C23: =+A23 -> 0 | D23: =IFERROR(VLOOKUP(H23,[1]SEMIELABORADOS!$A$2:$M$6000,6,0),"") | E23: =IFERROR(VLOOKUP(H23,[1]SEMIELABORADOS!$A$2:$H$65536,8,0),"") | F23: =IFERROR(E23*C23,"") | G23: =IFERROR(F23/$F$66,"")
B24: =IFERROR(VLOOKUP(H24,[1]SEMIELABORADOS!$A$2:$M$6000,2,0),"") | C24: =+A24 -> 0 | D24: =IFERROR(VLOOKUP(H24,[1]SEMIELABORADOS!$A$2:$M$6000,6,0),"") | E24: =IFERROR(VLOOKUP(H24,[1]SEMIELABORADOS!$A$2:$H$65536,8,0),"") | F24: =IFERROR(E24*C24,"") | G24: =IFERROR(F24/$F$66,"")
A26: UNIDADES | B26: EMPAQUE | C26: UNIDADES | D26: UND MEDIDA | E26: COSTO UNITARIO | F26: TOTAL COSTO | G26: % PREC. DEFINIDO | H26: CODIGOS
A27: 1 | B27: =IFERROR(VLOOKUP(H27,'[1]Consolidado MP Planta'!$A$2:$M$823,3,0),"") -> BOLSA 12x18 TRANSP KILO | C27: =+A27 -> 1 | D27: =IFERROR(VLOOKUP(H27,'[1]Consolidado MP Planta'!$A$2:$M$823,13,0),"") -> Und | E27: =IFERROR(VLOOKUP(H27,'[1]Consolidado MP Planta'!$A$2:$M$823,12,0),"") -> 16 | F27: =IFERROR(C27*E27,"") -> 16 | G27: =IFERROR(F27/$F$66,"") -> 0.0024111774 | H27: 1950702
A28: 2 | B28: =IFERROR(VLOOKUP(H28,'[1]Consolidado MP Planta'!$A$2:$M$823,3,0),"") -> BOLSA 17x25 TRANSP KILO | C28: =+A28 -> 2 | D28: =IFERROR(VLOOKUP(H28,'[1]Consolidado MP Planta'!$A$2:$M$823,13,0),"") -> Und | E28: =IFERROR(VLOOKUP(H28,'[1]Consolidado MP Planta'!$A$2:$M$823,12,0),"") -> 47.619048 | F28: =IFERROR(C28*E28,"") -> 95.238095 | G28: =IFERROR(F28/$F$66,"") -> 0.014352246 | H28: 1950708
A29: 2 | B29: =IFERROR(VLOOKUP(H29,'[1]Consolidado MP Planta'!$A$2:$M$823,3,0),"") -> ETIQUETA BLANCA 2 5/8X1 15/16 (UND) | C29: =+A29 -> 2 | D29: =IFERROR(VLOOKUP(H29,'[1]Consolidado MP Planta'!$A$2:$M$823,13,0),"") -> Und | E29: =IFERROR(VLOOKUP(H29,'[1]Consolidado MP Planta'!$A$2:$M$823,12,0),"") -> 2.128 | F29: =IFERROR(C29*E29,"") -> 4.256 | G29: =IFERROR(F29/$F$66,"") -> 0.00064137319 | H29: 0702123
A30: 2 | B30: =IFERROR(VLOOKUP(H30,'[1]Consolidado MP Planta'!$A$2:$M$823,3,0),"") -> ETIQUETA ROJA LETRA ALERJENO (UND) | C30: =+A30 -> 2 | D30: =IFERROR(VLOOKUP(H30,'[1]Consolidado MP Planta'!$A$2:$M$823,13,0),"") -> Und | E30: =IFERROR(VLOOKUP(H30,'[1]Consolidado MP Planta'!$A$2:$M$823,12,0),"") -> 3.6 | F30: =IFERROR(C30*E30,"") -> 7.2 | G30: =IFERROR(F30/$F$66,"") -> 0.0010850298 | H30: 60100010
B31: =IFERROR(VLOOKUP(H31,'[1]Consolidado MP Planta'!$A$2:$M$823,3,0),"") | C31: =+A31 -> 0 | D31: =IFERROR(VLOOKUP(H31,'[1]Consolidado MP Planta'!$A$2:$M$823,13,0),"") | E31: =IFERROR(VLOOKUP(H31,'[1]Consolidado MP Planta'!$A$2:$M$823,12,0),"") | F31: =IFERROR(C31*E31,"") | G31: =IFERROR(F31/$F$66,"")
B32: =IFERROR(VLOOKUP(H32,'[1]Consolidado MP Planta'!$A$2:$M$823,3,0),"") | C32: =+A32 -> 0 | D32: =IFERROR(VLOOKUP(H32,'[1]Consolidado MP Planta'!$A$2:$M$823,13,0),"") | E32: =IFERROR(VLOOKUP(H32,'[1]Consolidado MP Planta'!$A$2:$M$823,12,0),"") | F32: =IFERROR(C32*E32,"") | G32: =IFERROR(F32/$F$66,"")
A34: UNIDADES | B34: EMPAQUE SEMIELABORADOS | C34: UNIDADES | D34: UND MEDIDA | E34: COSTO UNITARIO | F34: TOTAL COSTO | G34: % PREC. DEFINIDO | H34: CODIGOS
A35: =+A17 -> 0 | B35: =IFERROR(VLOOKUP(H35,[1]SEMIELABORADOS!$A$2:$M$6000,2,0),"") | C35: =+A35 -> 0 | D35: =IFERROR(VLOOKUP(H35,[1]SEMIELABORADOS!$A$2:$M$6000,6,0),"") | E35: =IFERROR(VLOOKUP(H35,[1]SEMIELABORADOS!$A$2:$M$65536,10,0),"") | F35: =IFERROR(E35*C35,"") | G35: =IFERROR(F35/$F$66,"")
A36: =+A18 -> 0 | B36: =IFERROR(VLOOKUP(H36,[1]SEMIELABORADOS!$A$2:$M$6000,2,0),"") | C36: =+A36 -> 0 | D36: =IFERROR(VLOOKUP(H36,[1]SEMIELABORADOS!$A$2:$M$6000,6,0),"") | E36: =IFERROR(VLOOKUP(H36,[1]SEMIELABORADOS!$A$2:$M$65536,10,0),"") | F36: =IFERROR(E36*C36,"") | G36: =IFERROR(F36/$F$66,"")
A37: =+A19 -> 0 | B37: =IFERROR(VLOOKUP(H37,[1]SEMIELABORADOS!$A$2:$M$6000,2,0),"") | C37: =+A37 -> 0 | D37: =IFERROR(VLOOKUP(H37,[1]SEMIELABORADOS!$A$2:$M$6000,6,0),"") | E37: =IFERROR(VLOOKUP(H37,[1]SEMIELABORADOS!$A$2:$M$65536,10,0),"") | F37: =IFERROR(E37*C37,"") | G37: =IFERROR(F37/$F$66,"")
A38: =+A20 -> 0 | B38: =IFERROR(VLOOKUP(H38,[1]SEMIELABORADOS!$A$2:$M$6000,2,0),"") | C38: =+A38 -> 0 | D38: =IFERROR(VLOOKUP(H38,[1]SEMIELABORADOS!$A$2:$M$6000,6,0),"") | E38: =IFERROR(VLOOKUP(H38,[1]SEMIELABORADOS!$A$2:$M$65536,10,0),"") | F38: =IFERROR(E38*C38,"") | G38: =IFERROR(F38/$F$66,"")
A39: =+A21 -> 0 | B39: =IFERROR(VLOOKUP(H39,[1]SEMIELABORADOS!$A$2:$M$6000,2,0),"") | C39: =+A39 -> 0 | D39: =IFERROR(VLOOKUP(H39,[1]SEMIELABORADOS!$A$2:$M$6000,6,0),"") | E39: =IFERROR(VLOOKUP(H39,[1]SEMIELABORADOS!$A$2:$M$65536,10,0),"") | F39: =IFERROR(E39*C39,"") | G39: =IFERROR(F39/$F$66,"")
A40: =+A22 -> 0 | B40: =IFERROR(VLOOKUP(H40,[1]SEMIELABORADOS!$A$2:$M$6000,2,0),"") | C40: =+A40 -> 0 | D40: =IFERROR(VLOOKUP(H40,[1]SEMIELABORADOS!$A$2:$M$6000,6,0),"") | E40: =IFERROR(VLOOKUP(H40,[1]SEMIELABORADOS!$A$2:$M$65536,10,0),"") | F40: =IFERROR(E40*C40,"") | G40: =IFERROR(F40/$F$66,"")
A41: =+A23 -> 0 | B41: =IFERROR(VLOOKUP(H41,[1]SEMIELABORADOS!$A$2:$M$6000,2,0),"") | C41: =+A41 -> 0 | D41: =IFERROR(VLOOKUP(H41,[1]SEMIELABORADOS!$A$2:$M$6000,6,0),"") | E41: =IFERROR(VLOOKUP(H41,[1]SEMIELABORADOS!$A$2:$M$65536,10,0),"") | F41: =IFERROR(E41*C41,"") | G41: =IFERROR(F41/$F$66,"")
A43: UNIDADES | B43: MODI | C43: UNIDADES | D43: UND MEDIDA | E43: COSTO UNITARIO | F43: TOTAL COSTO | G43: % PREC. DEFINIDO | H43: CODIGOS
A44: =+A35 -> 0 | B44: =IFERROR(VLOOKUP(H44,[1]SEMIELABORADOS!$A$2:$M$6000,2,0),"") | C44: =+A44 -> 0 | D44: =IFERROR(VLOOKUP(H44,[1]SEMIELABORADOS!$A$2:$M$6000,6,0),"") | E44: =IFERROR(VLOOKUP(H44,[1]SEMIELABORADOS!$A$2:$M$65536,12,0),"") | F44: =IFERROR(E44*C44,"") | G44: =IFERROR(F44/$F$66,"")
A45: =+A36 -> 0 | B45: =IFERROR(VLOOKUP(H45,[1]SEMIELABORADOS!$A$2:$M$6000,2,0),"") | C45: =+A45 -> 0 | D45: =IFERROR(VLOOKUP(H45,[1]SEMIELABORADOS!$A$2:$M$6000,6,0),"") | E45: =IFERROR(VLOOKUP(H45,[1]SEMIELABORADOS!$A$2:$M$65536,12,0),"") | F45: =IFERROR(E45*C45,"") | G45: =IFERROR(F45/$F$66,"")
...

Sheet Costo Banano batido
E1: Precio Local | F1: Costo MP | G1: Costo EM | H1: Costo MO
E2: =IFERROR(O62,"") -> 3350 | F2: =IFERROR(H53,"") -> 2500 | G2: =IFERROR(H54,"") -> 0 | H2: =IFERROR(H56,"") -> 232
A5: ESTRUCTURA DE COSTOS
F6: Fecha: | H6: =TODAY() -> 45749
A7: UNIDADES | B7: DESCRIPCION MAT.PRIMA | C7: UNIDADES | D7: UND MEDIDA | E7: COSTO UNITARIO | F7: TOTAL COSTO | G7: % PREC. DEFINIDO | H7: CODIGOS
A8: 50 | B8: BANANO ( UND) | C8: =+A8 -> 50 | D8: UND | E8: 50 | F8: =IFERROR(C8*E8,"") -> 2500 | G8: =IFERROR(F8/$F$66,"") -> 0.89863408 | H8: 101085
B9: =IFERROR(VLOOKUP(H9,'[1]Consolidado MP Planta'!$A$2:$M$823,3,0),"") | C9: =+A9 -> 0 | D9: =IFERROR(VLOOKUP(H9,'[1]Consolidado MP Planta'!$A$2:$M$823,13,0),"") | E9: =IFERROR(VLOOKUP(H9,'[1]Consolidado MP Planta'!$A$2:$M$823,12,0),"") | F9: =IFERROR(C9*E9,"") | G9: =IFERROR(F9/$F$66,"")
B10: =IFERROR(VLOOKUP(H10,'[1]Consolidado MP Planta'!$A$2:$M$823,3,0),"") | C10: =+A10 -> 0 | D10: =IFERROR(VLOOKUP(H10,'[1]Consolidado MP Planta'!$A$2:$M$823,13,0),"") | E10: =IFERROR(VLOOKUP(H10,'[1]Consolidado MP Planta'!$A$2:$M$823,12,0),"") | F10: =IFERROR(C10*E10,"") | G10: =IFERROR(F10/$F$66,"")
B11: =IFERROR(VLOOKUP(H11,'[1]Consolidado MP Planta'!$A$2:$M$823,3,0),"") | C11: =+A11 -> 0 | D11: =IFERROR(VLOOKUP(H11,'[1]Consolidado MP Planta'!$A$2:$M$823,13,0),"") | E11: =IFERROR(VLOOKUP(H11,'[1]Consolidado MP Planta'!$A$2:$M$823,12,0),"") | F11: =IFERROR(C11*E11,"") | G11: =IFERROR(F11/$F$66,"")
B12: =IFERROR(VLOOKUP(H12,'[1]Consolidado MP Planta'!$A$2:$M$823,3,0),"") | C12: =+A12 -> 0 | D12: =IFERROR(VLOOKUP(H12,'[1]Consolidado MP Planta'!$A$2:$M$823,13,0),"") | E12: =IFERROR(VLOOKUP(H12,'[1]Consolidado MP Planta'!$A$2:$M$823,12,0),"") | F12: =IFERROR(C12*E12,"") | G12: =IFERROR(F12/$F$66,"")
B13: =IFERROR(VLOOKUP(H13,'[1]Consolidado MP Planta'!$A$2:$M$823,3,0),"") | C13: =+A13 -> 0 | D13: =IFERROR(VLOOKUP(H13,'[1]Consolidado MP Planta'!$A$2:$M$823,13,0),"") | E13: =IFERROR(VLOOKUP(H13,'[1]Consolidado MP Planta'!$A$2:$M$823,12,0),"") | F13: =IFERROR(C13*E13,"") | G13: =IFERROR(F13/$F$66,"")
B14: =IFERROR(VLOOKUP(H14,'[1]Consolidado MP Planta'!$A$2:$M$823,3,0),"") | C14: =+A14 -> 0 | D14: =IFERROR(VLOOKUP(H14,'[1]Consolidado MP Planta'!$A$2:$M$823,13,0),"") | E14: =IFERROR(VLOOKUP(H14,'[1]Consolidado MP Planta'!$A$2:$M$823,12,0),"") | F14: =IFERROR(C14*E14,"") | G14: =IFERROR(F14/$F$66,"")
B15: =IFERROR(VLOOKUP(H15,'[2]ARTICULOS MP PLANTA'!$A$2:$G$589,2,0),"")
A16: UNIDADES | B16: MATERIA PRIMA SEMIELABORADOS | C16: UNIDADES | D16: UND MEDIDA | E16: COSTO UNITARIO | F16: TOTAL COSTO | G16: % PREC. DEFINIDO | H16: CODIGOS
B17: =IFERROR(VLOOKUP(H17,[1]SEMIELABORADOS!$A$2:$M$6000,2,0),"") | C17: =+A17 -> 0 | D17: =IFERROR(VLOOKUP(H17,[1]SEMIELABORADOS!$A$2:$M$6000,6,0),"") | E17: =IFERROR(VLOOKUP(H17,[1]SEMIELABORADOS!$A$2:$H$65536,8,0),"") | F17: =IFERROR(E17*C17,"") | G17: =IFERROR(F17/$F$66,"")
B18: =IFERROR(VLOOKUP(H18,[1]SEMIELABORADOS!$A$2:$M$6000,2,0),"") | C18: =+A18 -> 0 | D18: =IFERROR(VLOOKUP(H18,[1]SEMIELABORADOS!$A$2:$M$6000,6,0),"") | E18: =IFERROR(VLOOKUP(H18,[1]SEMIELABORADOS!$A$2:$H$65536,8,0),"") | F18: =IFERROR(E18*C18,"") | G18: =IFERROR(F18/$F$66,"")
B19: =IFERROR(VLOOKUP(H19,[1]SEMIELABORADOS!$A$2:$M$6000,2,0),"") | C19: =+A19 -> 0 | D19: =IFERROR(VLOOKUP(H19,[1]SEMIELABORADOS!$A$2:$M$6000,6,0),"") | E19: =IFERROR(VLOOKUP(H19,[1]SEMIELABORADOS!$A$2:$H$65536,8,0),"") | F19: =IFERROR(E19*C19,"") | G19: =IFERROR(F19/$F$66,"")
B20: =IFERROR(VLOOKUP(H20,[1]SEMIELABORADOS!$A$2:$M$6000,2,0),"") | C20: =+A20 -> 0 | D20: =IFERROR(VLOOKUP(H20,[1]SEMIELABORADOS!$A$2:$M$6000,6,0),"") | E20: =IFERROR(VLOOKUP(H20,[1]SEMIELABORADOS!$A$2:$H$65536,8,0),"") | F20: =IFERROR(E20*C20,"") | G20: =IFERROR(F20/$F$66,"")
B21: =IFERROR(VLOOKUP(H21,[1]SEMIELABORADOS!$A$2:$M$6000,2,0),"") | C21: =+A21 -> 0 | D21: =IFERROR(VLOOKUP(H21,[1]SEMIELABORADOS!$A$2:$M$6000,6,0),"") | E21: =IFERROR(VLOOKUP(H21,[1]SEMIELABORADOS!$A$2:$H$65536,8,0),"") | F21: =IFERROR(E21*C21,"") | G21: =IFERROR(F21/$F$66,"")
B22: =IFERROR(VLOOKUP(H22,[1]SEMIELABORADOS!$A$2:$M$6000,2,0),"") | C22: =+A22 -> 0 | D22: =IFERROR(VLOOKUP(H22,[1]SEMIELABORADOS!$A$2:$M$6000,6,0),"") | E22: =IFERROR(VLOOKUP(H22,[1]SEMIELABORADOS!$A$2:$H$65536,8,0),"") | F22: =IFERROR(E22*C22,"") | G22: =IFERROR(F22/$F$66,"")
B23: =IFERROR(VLOOKUP(H23,[1]SEMIELABORADOS!$A$2:$M$6000,2,0),"") | C23: =+A23 -> 0 | D23: =IFERROR(VLOOKUP(H23,[1]SEMIELABORADOS!$A$2:$M$6000,6,0),"") | E23: =IFERROR(VLOOKUP(H23,[1]SEMIELABORADOS!$A$2:$H$65536,8,0),"") | F23: =IFERROR(E23*C23,"") | G23: =IFERROR(F23/$F$66,"")
B24: =IFERROR(VLOOKUP(H24,[1]SEMIELABORADOS!$A$2:$M$6000,2,0),"") | C24: =+A24 -> 0 | D24: =IFERROR(VLOOKUP(H24,[1]SEMIELABORADOS!$A$2:$M$6000,6,0),"") | E24: =IFERROR(VLOOKUP(H24,[1]SEMIELABORADOS!$A$2:$H$65536,8,0),"") | F24: =IFERROR(E24*C24,"") | G24: =IFERROR(F24/$F$66,"")
A26: UNIDADES | B26: EMPAQUE | C26: UNIDADES | D26: UND MEDIDA | E26: COSTO UNITARIO | F26: TOTAL COSTO | G26: % PREC. DEFINIDO | H26: CODIGOS
A27: 0 | B27: =IFERROR(VLOOKUP(H27,'[1]Consolidado MP Planta'!$A$2:$M$823,3,0),"") | C27: =+A27 -> 0 | D27: =IFERROR(VLOOKUP(H27,'[1]Consolidado MP Planta'!$A$2:$M$823,13,0),"") | E27: =IFERROR(VLOOKUP(H27,'[1]Consolidado MP Planta'!$A$2:$M$823,12,0),"") | F27: =IFERROR(C27*E27,"") | G27: =IFERROR(F27/$F$66,"")
B28: =IFERROR(VLOOKUP(H28,'[1]Consolidado MP Planta'!$A$2:$M$823,3,0),"") | C28: =+A28 -> 0 | D28: =IFERROR(VLOOKUP(H28,'[1]Consolidado MP Planta'!$A$2:$M$823,13,0),"") | E28: =IFERROR(VLOOKUP(H28,'[1]Consolidado MP Planta'!$A$2:$M$823,12,0),"") | F28: =IFERROR(C28*E28,"") | G28: =IFERROR(F28/$F$66,"")
B29: =IFERROR(VLOOKUP(H29,'[1]Consolidado MP Planta'!$A$2:$M$823,3,0),"") | C29: =+A29 -> 0 | D29: =IFERROR(VLOOKUP(H29,'[1]Consolidado MP Planta'!$A$2:$M$823,13,0),"") | E29: =IFERROR(VLOOKUP(H29,'[1]Consolidado MP Planta'!$A$2:$M$823,12,0),"") | F29: =IFERROR(C29*E29,"") | G29: =IFERROR(F29/$F$66,"")
B30: =IFERROR(VLOOKUP(H30,'[1]Consolidado MP Planta'!$A$2:$M$823,3,0),"") | C30: =+A30 -> 0 | D30: =IFERROR(VLOOKUP(H30,'[1]Consolidado MP Planta'!$A$2:$M$823,13,0),"") | E30: =IFERROR(VLOOKUP(H30,'[1]Consolidado MP Planta'!$A$2:$M$823,12,0),"") | F30: =IFERROR(C30*E30,"") | G30: =IFERROR(F30/$F$66,"")
B31: =IFERROR(VLOOKUP(H31,'[1]Consolidado MP Planta'!$A$2:$M$823,3,0),"") | C31: =+A31 -> 0 | D31: =IFERROR(VLOOKUP(H31,'[1]Consolidado MP Planta'!$A$2:$M$823,13,0),"") | E31: =IFERROR(VLOOKUP(H31,'[1]Consolidado MP Planta'!$A$2:$M$823,12,0),"") | F31: =IFERROR(C31*E31,"") | G31: =IFERROR(F31/$F$66,"")
B32: =IFERROR(VLOOKUP(H32,'[1]Consolidado MP Planta'!$A$2:$M$823,3,0),"") | C32: =+A32 -> 0 | D32: =IFERROR(VLOOKUP(H32,'[1]Consolidado MP Planta'!$A$2:$M$823,13,0),"") | E32: =IFERROR(VLOOKUP(H32,'[1]Consolidado MP Planta'!$A$2:$M$823,12,0),"") | F32: =IFERROR(C32*E32,"") | G32: =IFERROR(F32/$F$66,"")
A34: UNIDADES | B34: EMPAQUE SEMIELABORADOS | C34: UNIDADES | D34: UND MEDIDA | E34: COSTO UNITARIO | F34: TOTAL COSTO | G34: % PREC. DEFINIDO | H34: CODIGOS
A35: =+A17 -> 0 | B35: =IFERROR(VLOOKUP(H35,[1]SEMIELABORADOS!$A$2:$M$6000,2,0),"") | C35: =+A35 -> 0 | D35: =IFERROR(VLOOKUP(H35,[1]SEMIELABORADOS!$A$2:$M$6000,6,0),"") | E35: =IFERROR(VLOOKUP(H35,[1]SEMIELABORADOS!$A$2:$M$65536,10,0),"") | F35: =IFERROR(E35*C35,"") | G35: =IFERROR(F35/$F$66,"")
A36: =+A18 -> 0 | B36: =IFERROR(VLOOKUP(H36,[1]SEMIELABORADOS!$A$2:$M$6000,2,0),"") | C36: =+A36 -> 0 | D36: =IFERROR(VLOOKUP(H36,[1]SEMIELABORADOS!$A$2:$M$6000,6,0),"") | E36: =IFERROR(VLOOKUP(H36,[1]SEMIELABORADOS!$A$2:$M$65536,10,0),"") | F36: =IFERROR(E36*C36,"") | G36: =IFERROR(F36/$F$66,"")
A37: =+A19 -> 0 | B37: =IFERROR(VLOOKUP(H37,[1]SEMIELABORADOS!$A$2:$M$6000,2,0),"") | C37: =+A37 -> 0 | D37: =IFERROR(VLOOKUP(H37,[1]SEMIELABORADOS!$A$2:$M$6000,6,0),"") | E37: =IFERROR(VLOOKUP(H37,[1]SEMIELABORADOS!$A$2:$M$65536,10,0),"") | F37: =IFERROR(E37*C37,"") | G37: =IFERROR(F37/$F$66,"")
A38: =+A20 -> 0 | B38: =IFERROR(VLOOKUP(H38,[1]SEMIELABORADOS!$A$2:$M$6000,2,0),"") | C38: =+A38 -> 0 | D38: =IFERROR(VLOOKUP(H38,[1]SEMIELABORADOS!$A$2:$M$6000,6,0),"") | E38: =IFERROR(VLOOKUP(H38,[1]SEMIELABORADOS!$A$2:$M$65536,10,0),"") | F38: =IFERROR(E38*C38,"") | G38: =IFERROR(F38/$F$66,"")
A39: =+A21 -> 0 | B39: =IFERROR(VLOOKUP(H39,[1]SEMIELABORADOS!$A$2:$M$6000,2,0),"") | C39: =+A39 -> 0 | D39: =IFERROR(VLOOKUP(H39,[1]SEMIELABORADOS!$A$2:$M$6000,6,0),"") | E39: =IFERROR(VLOOKUP(H39,[1]SEMIELABORADOS!$A$2:$M$65536,10,0),"") | F39: =IFERROR(E39*C39,"") | G39: =IFERROR(F39/$F$66,"")
A40: =+A22 -> 0 | B40: =IFERROR(VLOOKUP(H40,[1]SEMIELABORADOS!$A$2:$M$6000,2,0),"") | C40: =+A40 -> 0 | D40: =IFERROR(VLOOKUP(H40,[1]SEMIELABORADOS!$A$2:$M$6000,6,0),"") | E40: =IFERROR(VLOOKUP(H40,[1]SEMIELABORADOS!$A$2:$M$65536,10,0),"") | F40: =IFERROR(E40*C40,"") | G40: =IFERROR(F40/$F$66,"")
A41: =+A23 -> 0 | B41: =IFERROR(VLOOKUP(H41,[1]SEMIELABORADOS!$A$2:$M$6000,2,0),"") | C41: =+A41 -> 0 | D41: =IFERROR(VLOOKUP(H41,[1]SEMIELABORADOS!$A$2:$M$6000,6,0),"") | E41: =IFERROR(VLOOKUP(H41,[1]SEMIELABORADOS!$A$2:$M$65536,10,0),"") | F41: =IFERROR(E41*C41,"") | G41: =IFERROR(F41/$F$66,"")
A43: UNIDADES | B43: MODI | C43: UNIDADES | D43: UND MEDIDA | E43: COSTO UNITARIO | F43: TOTAL COSTO | G43: % PREC. DEFINIDO | H43: CODIGOS
A44: =+A35 -> 0 | B44: =IFERROR(VLOOKUP(H44,[1]SEMIELABORADOS!$A$2:$M$6000,2,0),"") | C44: =+A44 -> 0 | D44: =IFERROR(VLOOKUP(H44,[1]SEMIELABORADOS!$A$2:$M$6000,6,0),"") | E44: =IFERROR(VLOOKUP(H44,[1]SEMIELABORADOS!$A$2:$M$65536,12,0),"") | F44: =IFERROR(E44*C44,"") | G44: =IFERROR(F44/$F$66,"")
A45: =+A36 -> 0 | B45: =IFERROR(VLOOKUP(H45,[1]SEMIELABORADOS!$A$2:$M$6000,2,0),"") | C45: =+A45 -> 0 | D45: =IFERROR(VLOOKUP(H45,[1]SEMIELABORADOS!$A$2:$M$6000,6,0),"") | E45: =IFERROR(VLOOKUP(H45,[1]SEMIELABORADOS!$A$2:$M$65536,12,0),"") | F45: =IFERROR(E45*C45,"") | G45: =IFERROR(F45/$F$66,"")
...

Sheet Batido
B1: SERVICIOS DE PASTELERIA S.A. | G1: CÓDIGO:
B2: ESPECIFICACION DE RECETA | G2: REVISIÓN:
B3: Batido Mufin de banano Spoon | G3: FECHA DE APROBACIÓN:
B4: Elaborado | C4: Juan Pablo Brenes,chef
B5: Aprobado | C5: Esteban Cartin, Gerente de Manufactura
A7: AREA QUE PRODUCE: | C7: Batidos | F7: AREA QUE EMPACA: | H7: Batidos
A8: # Código | B8: Descripción del ingrediente | C8: Marca | D8: Unidad Internacional | F8: Medida alternativa | H8: Costo - Referencia
D9: Cantidad | E9: Unidad medida | F9: Cantidad | G9: Unidad medida | H9: Colones
A10: NUEVO | B10: PREMEZCLA MUFIN BANANO | C10: FAS | D10: 6500 | E10: g
A11: 11300009 | B11: CLARA DE HUEVO (CAJA:5 K) | C11: Innovo | D11: 1000 | E11: g
A12: 1210443 | B12: YEMA DE HUEVO PASTEURIZADA (CAJA:2 Kg) | C12: INNOVO | D12: 800 | E12: g
A13: NUEVO | B13: BANANO BATIDO | C13: FAS | D13: 6500 | E13: g
A14: 11900001 | B14: NUEZ PECANA QUEBRADURA (CAJA:10 Kg) | C14: NUECES INDUSTRIALES | D14: 2000 | E14: G
C18: Cantidad | D18: Unidad
A19: PESO TOTAL OBTENIDO | C19: 16000 | D19: g
A20: TIEMPO TOTAL DE PREPARACION | C20: 8 | D20: min
A21: CANTIDAD DE PORCIONES OBTENIDAS | C21: =C19/C22 -> 533.33333 | D21: ud | E21: 28g cocido
A22: PESO DE CADA PORCIÓN | C22: 30 | D22: g
A23: MERMA | C23: =SUM(D10:D14)-C19 -> 800 | D23: g
A24: PROCEDIMIENTO DE PREPARACION DE LA RECETA
A25: 1.- Llevar la clara de huevo a punto de nieve.
A26: 2.- En la batidora con paleta cremar la mantequilla con el azucar hasta deshacer el azucar.
A27: 3.- Luego agregar la yema por partes y e incorporar muy bien.
A28: 4.- Agregar el banano, le pecana y la premezcla, batir a velocidad 1 por 2 minutos hasta incorporar.
A29: 5.- Por ultimo agregar la clara en punto de nieve y batir en velocidad 1 por 1 minuto para incorporar.

Sheet Batido 2
B1: SERVICIOS DE PASTELERIA S.A. | G1: CÓDIGO:
B2: ESPECIFICACION DE RECETA | G2: REVISIÓN:
B3: Batido queque banano | G3: FECHA DE APROBACIÓN:
B4: Elaborado | C4: Juan Pablo Brenes,chef
B5: Aprobado | C5: Esteban Cartin, Gerente de Manufactura
A7: AREA QUE PRODUCE: | C7: Batidos | F7: AREA QUE EMPACA: | H7: Batidos
A8: # Código | B8: Descripción del ingrediente | C8: Marca | D8: Unidad Internacional | F8: Medida alternativa | H8: Costo - Referencia
D9: Cantidad | E9: Unidad medida | F9: Cantidad | G9: Unidad medida | H9: Colones
A10: NUEVO | B10: PREMEZCLA QUEQUE BANANO | C10: FAS | D10: 6680 | E10: g
A11: 11300009 | B11: CLARA DE HUEVO (CAJA:5 K) | C11: Innovo | D11: 1000 | E11: g
A12: 1210482 | B12: Huevo Liquido Refrigerado | C12: INNOVO | D12: 800 | E12: g
A13: NUEVO | B13: BANANO BATIDO | C13: FAS | D13: 6500 | E13: g
A14: 11900001 | B14: NUEZ PECANA QUEBRADURA (CAJA:10 Kg) | C14: NUECES INDUSTRIALES | D14: 2000 | E14: G
C18: Cantidad | D18: Unidad
A19: PESO TOTAL OBTENIDO | C19: 16000 | D19: g
A20: TIEMPO TOTAL DE PREPARACION | C20: 8 | D20: min
A21: CANTIDAD DE PORCIONES OBTENIDAS | C21: =C19/C22 -> 21.333333 | D21: ud
A22: PESO DE CADA PORCIÓN | C22: 750 | D22: g
A23: MERMA | C23: =SUM(D10:D14)-C19 -> 980 | D23: g
A24: PROCEDIMIENTO DE PREPARACION DE LA RECETA
A25: 1.- Llevar la clara de huevo a punto de nieve.
A26: 2.- En la batidora con paleta cremar la mantequilla con el azucar hasta deshacer el azucar.
A27: 3.- Luego agregar la yema por partes y e incorporar muy bien.
A28: 4.- Agregar el banano, le pecana y la premezcla, batir a velocidad 1 por 2 minutos hasta incorporar.
A29: 5.- Por ultimo agregar la clara en punto de nieve y batir en velocidad 1 por 1 minuto para incorporar.

Sheet Costo Batido
E1: Precio Local | F1: Costo MP | G1: Costo EM | H1: Costo MO
E2: =IFERROR(O62,"") -> 18471.369 | F2: =IFERROR(H53,"") -> 13661.91 | G2: =IFERROR(H54,"") -> 122.6941 | H2: =IFERROR(H56,"") -> 928
A5: ESTRUCTURA DE COSTOS
F6: Fecha: | H6: =TODAY() -> 45749
A7: UNIDADES | B7: DESCRIPCION MAT.PRIMA | C7: UNIDADES | D7: UND MEDIDA | E7: COSTO UNITARIO | F7: TOTAL COSTO | G7: % PREC. DEFINIDO | H7: CODIGOS
A8: 1000 | B8: =IFERROR(VLOOKUP(H8,'[1]Consolidado MP Planta'!$A$2:$M$823,3,0),"") -> CLARA DE HUEVO (CAJA:5 K) | C8: =+A8 -> 1000 | D8: =IFERROR(VLOOKUP(H8,'[1]Consolidado MP Planta'!$A$2:$M$823,13,0),"") -> Gramos | E8: 2.78 | F8: =IFERROR(C8*E8,"") -> 2780 | G8: =IFERROR(F8/$F$66,"") -> 0.19143577 | H8: 11300009
A9: 800 | B9: =IFERROR(VLOOKUP(H9,'[1]Consolidado MP Planta'!$A$2:$M$823,3,0),"") -> HUEVO ENTERO PASTERI INNOVO (CAJA:10 K) | C9: =+A9 -> 800 | D9: =IFERROR(VLOOKUP(H9,'[1]Consolidado MP Planta'!$A$2:$M$823,13,0),"") -> Gramos | E9: 2.78 | F9: =IFERROR(C9*E9,"") -> 2224 | G9: =IFERROR(F9/$F$66,"") -> 0.15314861 | H9: 1210482
A10: 0 | B10: =IFERROR(VLOOKUP(H10,'[1]Consolidado MP Planta'!$A$2:$M$823,3,0),"") -> NUEZ PECANA QUEBRADURA (CAJA:10 Kg) | C10: =+A10 -> 0 | D10: =IFERROR(VLOOKUP(H10,'[1]Consolidado MP Planta'!$A$2:$M$823,13,0),"") -> Gramos | E10: 10.09 | F10: =IFERROR(C10*E10,"") -> 0 | G10: =IFERROR(F10/$F$66,"") -> 0 | H10: 11900001
B11: =IFERROR(VLOOKUP(H11,'[1]Consolidado MP Planta'!$A$2:$M$823,3,0),"") | C11: =+A11 -> 0 | D11: =IFERROR(VLOOKUP(H11,'[1]Consolidado MP Planta'!$A$2:$M$823,13,0),"") | E11: =IFERROR(VLOOKUP(H11,'[1]Consolidado MP Planta'!$A$2:$M$823,12,0),"") | F11: =IFERROR(C11*E11,"") | G11: =IFERROR(F11/$F$66,"")
B12: =IFERROR(VLOOKUP(H12,'[1]Consolidado MP Planta'!$A$2:$M$823,3,0),"") | C12: =+A12 -> 0 | D12: =IFERROR(VLOOKUP(H12,'[1]Consolidado MP Planta'!$A$2:$M$823,13,0),"") | E12: =IFERROR(VLOOKUP(H12,'[1]Consolidado MP Planta'!$A$2:$M$823,12,0),"") | F12: =IFERROR(C12*E12,"") | G12: =IFERROR(F12/$F$66,"")
B13: =IFERROR(VLOOKUP(H13,'[1]Consolidado MP Planta'!$A$2:$M$823,3,0),"") | C13: =+A13 -> 0 | D13: =IFERROR(VLOOKUP(H13,'[1]Consolidado MP Planta'!$A$2:$M$823,13,0),"") | E13: =IFERROR(VLOOKUP(H13,'[1]Consolidado MP Planta'!$A$2:$M$823,12,0),"") | F13: =IFERROR(C13*E13,"") | G13: =IFERROR(F13/$F$66,"")
B14: =IFERROR(VLOOKUP(H14,'[1]Consolidado MP Planta'!$A$2:$M$823,3,0),"") | C14: =+A14 -> 0 | D14: =IFERROR(VLOOKUP(H14,'[1]Consolidado MP Planta'!$A$2:$M$823,13,0),"") | E14: =IFERROR(VLOOKUP(H14,'[1]Consolidado MP Planta'!$A$2:$M$823,12,0),"") | F14: =IFERROR(C14*E14,"") | G14: =IFERROR(F14/$F$66,"")
B15: =IFERROR(VLOOKUP(H15,'[2]ARTICULOS MP PLANTA'!$A$2:$G$589,2,0),"")
A16: UNIDADES | B16: MATERIA PRIMA SEMIELABORADOS | C16: UNIDADES | D16: UND MEDIDA | E16: COSTO UNITARIO | F16: TOTAL COSTO | G16: % PREC. DEFINIDO | H16: CODIGOS
A17: 6680 | B17: PREMEZCLA MUFIN BANANO | C17: =+A17 -> 6680 | D17: Gramos | E17: =+'Costo Premezcla '!E69 -> 0.92184281 | F17: =IFERROR(E17*C17,"") -> 6157.91 | G17: =IFERROR(F17/$F$66,"") -> 0.42404468 | H17: NUEVO
A18: 6500 | B18: BANANO BATIDO | C18: =+A18 -> 6500 | D18: Gramos | E18: =+'Costo Banano batido'!E69 -> 0.38461538 | F18: =IFERROR(E18*C18,"") -> 2500 | G18: =IFERROR(F18/$F$66,"") -> 0.17215447 | H18: NUEVO
B19: =IFERROR(VLOOKUP(H19,[1]SEMIELABORADOS!$A$2:$M$6000,2,0),"") | C19: =+A19 -> 0 | D19: =IFERROR(VLOOKUP(H19,[1]SEMIELABORADOS!$A$2:$M$6000,6,0),"") | E19: =IFERROR(VLOOKUP(H19,[1]SEMIELABORADOS!$A$2:$H$65536,8,0),"") | F19: =IFERROR(E19*C19,"") | G19: =IFERROR(F19/$F$66,"")
B20: =IFERROR(VLOOKUP(H20,[1]SEMIELABORADOS!$A$2:$M$6000,2,0),"") | C20: =+A20 -> 0 | D20: =IFERROR(VLOOKUP(H20,[1]SEMIELABORADOS!$A$2:$M$6000,6,0),"") | E20: =IFERROR(VLOOKUP(H20,[1]SEMIELABORADOS!$A$2:$H$65536,8,0),"") | F20: =IFERROR(E20*C20,"") | G20: =IFERROR(F20/$F$66,"")
B21: =IFERROR(VLOOKUP(H21,[1]SEMIELABORADOS!$A$2:$M$6000,2,0),"") | C21: =+A21 -> 0 | D21: =IFERROR(VLOOKUP(H21,[1]SEMIELABORADOS!$A$2:$M$6000,6,0),"") | E21: =IFERROR(VLOOKUP(H21,[1]SEMIELABORADOS!$A$2:$H$65536,8,0),"") | F21: =IFERROR(E21*C21,"") | G21: =IFERROR(F21/$F$66,"")
B22: =IFERROR(VLOOKUP(H22,[1]SEMIELABORADOS!$A$2:$M$6000,2,0),"") | C22: =+A22 -> 0 | D22: =IFERROR(VLOOKUP(H22,[1]SEMIELABORADOS!$A$2:$M$6000,6,0),"") | E22: =IFERROR(VLOOKUP(H22,[1]SEMIELABORADOS!$A$2:$H$65536,8,0),"") | F22: =IFERROR(E22*C22,"") | G22: =IFERROR(F22/$F$66,"")
B23: =IFERROR(VLOOKUP(H23,[1]SEMIELABORADOS!$A$2:$M$6000,2,0),"") | C23: =+A23 -> 0 | D23: =IFERROR(VLOOKUP(H23,[1]SEMIELABORADOS!$A$2:$M$6000,6,0),"") | E23: =IFERROR(VLOOKUP(H23,[1]SEMIELABORADOS!$A$2:$H$65536,8,0),"") | F23: =IFERROR(E23*C23,"") | G23: =IFERROR(F23/$F$66,"")
B24: =IFERROR(VLOOKUP(H24,[1]SEMIELABORADOS!$A$2:$M$6000,2,0),"") | C24: =+A24 -> 0 | D24: =IFERROR(VLOOKUP(H24,[1]SEMIELABORADOS!$A$2:$M$6000,6,0),"") | E24: =IFERROR(VLOOKUP(H24,[1]SEMIELABORADOS!$A$2:$H$65536,8,0),"") | F24: =IFERROR(E24*C24,"") | G24: =IFERROR(F24/$F$66,"")
A26: UNIDADES | B26: EMPAQUE | C26: UNIDADES | D26: UND MEDIDA | E26: COSTO UNITARIO | F26: TOTAL COSTO | G26: % PREC. DEFINIDO | H26: CODIGOS
A27: 0 | B27: =IFERROR(VLOOKUP(H27,'[1]Consolidado MP Planta'!$A$2:$M$823,3,0),"") | C27: =+A27 -> 0 | D27: =IFERROR(VLOOKUP(H27,'[1]Consolidado MP Planta'!$A$2:$M$823,13,0),"") | E27: =IFERROR(VLOOKUP(H27,'[1]Consolidado MP Planta'!$A$2:$M$823,12,0),"") | F27: =IFERROR(C27*E27,"") | G27: =IFERROR(F27/$F$66,"")
B28: =IFERROR(VLOOKUP(H28,'[1]Consolidado MP Planta'!$A$2:$M$823,3,0),"") | C28: =+A28 -> 0 | D28: =IFERROR(VLOOKUP(H28,'[1]Consolidado MP Planta'!$A$2:$M$823,13,0),"") | E28: =IFERROR(VLOOKUP(H28,'[1]Consolidado MP Planta'!$A$2:$M$823,12,0),"") | F28: =IFERROR(C28*E28,"") | G28: =IFERROR(F28/$F$66,"")
B29: =IFERROR(VLOOKUP(H29,'[1]Consolidado MP Planta'!$A$2:$M$823,3,0),"") | C29: =+A29 -> 0 | D29: =IFERROR(VLOOKUP(H29,'[1]Consolidado MP Planta'!$A$2:$M$823,13,0),"") | E29: =IFERROR(VLOOKUP(H29,'[1]Consolidado MP Planta'!$A$2:$M$823,12,0),"") | F29: =IFERROR(C29*E29,"") | G29: =IFERROR(F29/$F$66,"")
B30: =IFERROR(VLOOKUP(H30,'[1]Consolidado MP Planta'!$A$2:$M$823,3,0),"") | C30: =+A30 -> 0 | D30: =IFERROR(VLOOKUP(H30,'[1]Consolidado MP Planta'!$A$2:$M$823,13,0),"") | E30: =IFERROR(VLOOKUP(H30,'[1]Consolidado MP Planta'!$A$2:$M$823,12,0),"") | F30: =IFERROR(C30*E30,"") | G30: =IFERROR(F30/$F$66,"")
B31: =IFERROR(VLOOKUP(H31,'[1]Consolidado MP Planta'!$A$2:$M$823,3,0),"") | C31: =+A31 -> 0 | D31: =IFERROR(VLOOKUP(H31,'[1]Consolidado MP Planta'!$A$2:$M$823,13,0),"") | E31: =IFERROR(VLOOKUP(H31,'[1]Consolidado MP Planta'!$A$2:$M$823,12,0),"") | F31: =IFERROR(C31*E31,"") | G31: =IFERROR(F31/$F$66,"")
B32: =IFERROR(VLOOKUP(H32,'[1]Consolidado MP Planta'!$A$2:$M$823,3,0),"") | C32: =+A32 -> 0 | D32: =IFERROR(VLOOKUP(H32,'[1]Consolidado MP Planta'!$A$2:$M$823,13,0),"") | E32: =IFERROR(VLOOKUP(H32,'[1]Consolidado MP Planta'!$A$2:$M$823,12,0),"") | F32: =IFERROR(C32*E32,"") | G32: =IFERROR(F32/$F$66,"")
A34: UNIDADES | B34: EMPAQUE SEMIELABORADOS | C34: UNIDADES | D34: UND MEDIDA | E34: COSTO UNITARIO | F34: TOTAL COSTO | G34: % PREC. DEFINIDO | H34: CODIGOS
A35: =+A17 -> 6680 | B35: PREMEZCLA MUFIN BANANO | C35: =+A35 -> 6680 | D35: Gramos | E35: =+'Costo Premezcla '!E76 -> 0.01836738 | F35: =IFERROR(E35*C35,"") -> 122.6941 | G35: =IFERROR(F35/$F$66,"") -> 0.0084489346 | H35: NUEVO
A36: =+A18 -> 6500 | B36: BANANO BATIDO | C36: =+A36 -> 6500 | D36: Gramos | E36: =+'Costo Banano batido'!E76 -> 0 | F36: =IFERROR(E36*C36,"") -> 0 | G36: =IFERROR(F36/$F$66,"") -> 0 | H36: NUEVO
A37: =+A19 -> 0 | B37: =IFERROR(VLOOKUP(H37,[1]SEMIELABORADOS!$A$2:$M$6000,2,0),"") | C37: =+A37 -> 0 | D37: =IFERROR(VLOOKUP(H37,[1]SEMIELABORADOS!$A$2:$M$6000,6,0),"") | E37: =IFERROR(VLOOKUP(H37,[1]SEMIELABORADOS!$A$2:$M$65536,10,0),"") | F37: =IFERROR(E37*C37,"") | G37: =IFERROR(F37/$F$66,"")
A38: =+A20 -> 0 | B38: =IFERROR(VLOOKUP(H38,[1]SEMIELABORADOS!$A$2:$M$6000,2,0),"") | C38: =+A38 -> 0 | D38: =IFERROR(VLOOKUP(H38,[1]SEMIELABORADOS!$A$2:$M$6000,6,0),"") | E38: =IFERROR(VLOOKUP(H38,[1]SEMIELABORADOS!$A$2:$M$65536,10,0),"") | F38: =IFERROR(E38*C38,"") | G38: =IFERROR(F38/$F$66,"")
A39: =+A21 -> 0 | B39: =IFERROR(VLOOKUP(H39,[1]SEMIELABORADOS!$A$2:$M$6000,2,0),"") | C39: =+A39 -> 0 | D39: =IFERROR(VLOOKUP(H39,[1]SEMIELABORADOS!$A$2:$M$6000,6,0),"") | E39: =IFERROR(VLOOKUP(H39,[1]SEMIELABORADOS!$A$2:$M$65536,10,0),"") | F39: =IFERROR(E39*C39,"") | G39: =IFERROR(F39/$F$66,"")
A40: =+A22 -> 0 | B40: =IFERROR(VLOOKUP(H40,[1]SEMIELABORADOS!$A$2:$M$6000,2,0),"") | C40: =+A40 -> 0 | D40: =IFERROR(VLOOKUP(H40,[1]SEMIELABORADOS!$A$2:$M$6000,6,0),"") | E40: =IFERROR(VLOOKUP(H40,[1]SEMIELABORADOS!$A$2:$M$65536,10,0),"") | F40: =IFERROR(E40*C40,"") | G40: =IFERROR(F40/$F$66,"")
A41: =+A23 -> 0 | B41: =IFERROR(VLOOKUP(H41,[1]SEMIELABORADOS!$A$2:$M$6000,2,0),"") | C41: =+A41 -> 0 | D41: =IFERROR(VLOOKUP(H41,[1]SEMIELABORADOS!$A$2:$M$6000,6,0),"") | E41: =IFERROR(VLOOKUP(H41,[1]SEMIELABORADOS!$A$2:$M$65536,10,0),"") | F41: =IFERROR(E41*C41,"") | G41: =IFERROR(F41/$F$66,"")
A43: UNIDADES | B43: MODI | C43: UNIDADES | D43: UND MEDIDA | E43: COSTO UNITARIO | F43: TOTAL COSTO | G43: % PREC. DEFINIDO | H43: CODIGOS
A44: =+A35 -> 6680 | B44: PREMEZCLA MUFIN BANANO | C44: =+A44 -> 6680 | D44: Gramos | E44: =+'Costo Premezcla '!E74 -> 0.034730539 | F44: =IFERROR(E44*C44,"") -> 232 | G44: =IFERROR(F44/$F$66,"") -> 0.015975934 | H44: NUEVO
A45: =+A36 -> 6500 | B45: BANANO BATIDO | C45: =+A45 -> 6500 | D45: Gramos | E45: =+'Costo Banano batido'!E74 -> 0.035692308 | F45: =IFERROR(E45*C45,"") -> 232 | G45: =IFERROR(F45/$F$66,"") -> 0.015975934 | H45: NUEVO
...

Sheet Rosquete
B1: SERVICIOS DE PASTELERIA S.A. | G1: CÓDIGO:
B2: ESPECIFICACION DE RECETA | G2: REVISIÓN:
B3: Rosquete mufin de banano Spoon | G3: FECHA DE APROBACIÓN:
B4: Elaborado | C4: Juan Pablo Brenes,chef
B5: Aprobado | C5: Esteban Cartin, Gerente de Manufactura
A7: AREA QUE PRODUCE: | C7: Batidos | F7: AREA QUE EMPACA: | H7: Batidos
A8: # Código | B8: Descripción del ingrediente | C8: Marca | D8: Unidad Internacional | F8: Medida alternativa | H8: Costo - Referencia
D9: Cantidad | E9: Unidad medida | F9: Cantidad | G9: Unidad medida | H9: Colones
A10: NUEVO | B10: BATIDO MUFIN BANANO SPOON | C10: FAS | D10: 16000 | E10: g | F10: 533 | G10: ud
A11: 1950731 | B11: CAPSULA # 3 LOGO (PAQ:1000 UND) | C11: Rapibox | D11: 533 | E11: ud
C16: Cantidad | D16: Unidad
A17: PESO TOTAL OBTENIDO | C17: 16000 | D17: g
A18: TIEMPO TOTAL DE PREPARACION | C18: 20 | D18: min
A19: CANTIDAD DE PORCIONES OBTENIDAS | C19: =C17/C20 -> 533.33333 | D19: ud | E19: 28g cocido
A20: PESO DE CADA PORCIÓN | C20: 30 | D20: g
A21: MERMA | C21: =SUM(D10:D12)-C17 -> 533 | D21: g
A22: PROCEDIMIENTO DE PREPARACION DE LA RECETA
A23: 1.- Dosificar 30g en la capsula #3 y llevar al horno a 180ºC por 15 minutos.
A24: 2.- Dejar enfriar y desmoldar en bandejas metalicas.

Sheet Rosquete 2
B1: SERVICIOS DE PASTELERIA S.A. | G1: CÓDIGO:
B2: ESPECIFICACION DE RECETA | G2: REVISIÓN:
B3: Rosquete queque banano | G3: FECHA DE APROBACIÓN:
B4: Elaborado | C4: Juan Pablo Brenes,chef
B5: Aprobado | C5: Esteban Cartin, Gerente de Manufactura
A7: AREA QUE PRODUCE: | C7: Batidos | F7: AREA QUE EMPACA: | H7: Batidos
A8: # Código | B8: Descripción del ingrediente | C8: Marca | D8: Unidad Internacional | F8: Medida alternativa | H8: Costo - Referencia
D9: Cantidad | E9: Unidad medida | F9: Cantidad | G9: Unidad medida | H9: Colones
A10: NUEVO | B10: BATIDO QUEQUE BANANO | C10: FAS | D10: 16000 | E10: g | F10: 533 | G10: ud
A12: 902000019 | B12: MEZCLA P/ENGRASE MOLDES KILO | C12: Spoon | D12: 140 | E12: g
A13: 1950772 | B13: PAPEL ENCERADO 12 X 10 | C13: Mayca | D13: 7 | E13: ud
C16: Cantidad | D16: Unidad
A17: PESO TOTAL OBTENIDO | C17: 16000 | D17: g
A18: TIEMPO TOTAL DE PREPARACION | C18: 20 | D18: min
A19: CANTIDAD DE PORCIONES OBTENIDAS | C19: =C17/C20 -> 21.333333 | D19: ud | E19: 28g cocido
A20: PESO DE CADA PORCIÓN | C20: 750 | D20: g
A21: MERMA | C21: =SUM(D10:D12)-C17 -> 140 | D21: g
A22: PROCEDIMIENTO DE PREPARACION DE LA RECETA
A23: 1.- Dosificar 750g de batido en los moldes previamente engrasados y con papel, llevar al horno por 35 minutos a 180ºC.
A24: 2.- Dejar enfriar y desmoldar en bandejas metalicas.

Sheet Costo Rosquete 
E1: Precio Local | F1: Costo MP | G1: Costo EM | H1: Costo MO
E2: =IFERROR(O62,"") -> 159.32499 | F2: =IFERROR(H53,"") -> 117.10209 | G2: =IFERROR(H54,"") -> 1.7971637 | H2: =IFERROR(H56,"") -> 18.829286
A5: ESTRUCTURA DE COSTOS
F6: Fecha: | H6: =TODAY() -> 45749
A7: UNIDADES | B7: DESCRIPCION MAT.PRIMA | C7: UNIDADES | D7: UND MEDIDA | E7: COSTO UNITARIO | F7: TOTAL COSTO | G7: % PREC. DEFINIDO | H7: CODIGOS
B8: =IFERROR(VLOOKUP(H8,'[1]Consolidado MP Planta'!$A$2:$M$823,3,0),"") | C8: =+A8 -> 0 | D8: =IFERROR(VLOOKUP(H8,'[1]Consolidado MP Planta'!$A$2:$M$823,13,0),"") | E8: =IFERROR(VLOOKUP(H8,'[1]Consolidado MP Planta'!$A$2:$M$823,12,0),"") | F8: =IFERROR(C8*E8,"") | G8: =IFERROR(F8/$F$66,"")
B9: =IFERROR(VLOOKUP(H9,'[1]Consolidado MP Planta'!$A$2:$M$823,3,0),"") | C9: =+A9 -> 0 | D9: =IFERROR(VLOOKUP(H9,'[1]Consolidado MP Planta'!$A$2:$M$823,13,0),"") | E9: =IFERROR(VLOOKUP(H9,'[1]Consolidado MP Planta'!$A$2:$M$823,12,0),"") | F9: =IFERROR(C9*E9,"") | G9: =IFERROR(F9/$F$66,"")
B10: =IFERROR(VLOOKUP(H10,'[1]Consolidado MP Planta'!$A$2:$M$823,3,0),"") | C10: =+A10 -> 0 | D10: =IFERROR(VLOOKUP(H10,'[1]Consolidado MP Planta'!$A$2:$M$823,13,0),"") | E10: =IFERROR(VLOOKUP(H10,'[1]Consolidado MP Planta'!$A$2:$M$823,12,0),"") | F10: =IFERROR(C10*E10,"") | G10: =IFERROR(F10/$F$66,"")
B11: =IFERROR(VLOOKUP(H11,'[1]Consolidado MP Planta'!$A$2:$M$823,3,0),"") | C11: =+A11 -> 0 | D11: =IFERROR(VLOOKUP(H11,'[1]Consolidado MP Planta'!$A$2:$M$823,13,0),"") | E11: =IFERROR(VLOOKUP(H11,'[1]Consolidado MP Planta'!$A$2:$M$823,12,0),"") | F11: =IFERROR(C11*E11,"") | G11: =IFERROR(F11/$F$66,"")
B12: =IFERROR(VLOOKUP(H12,'[1]Consolidado MP Planta'!$A$2:$M$823,3,0),"") | C12: =+A12 -> 0 | D12: =IFERROR(VLOOKUP(H12,'[1]Consolidado MP Planta'!$A$2:$M$823,13,0),"") | E12: =IFERROR(VLOOKUP(H12,'[1]Consolidado MP Planta'!$A$2:$M$823,12,0),"") | F12: =IFERROR(C12*E12,"") | G12: =IFERROR(F12/$F$66,"")
B13: =IFERROR(VLOOKUP(H13,'[1]Consolidado MP Planta'!$A$2:$M$823,3,0),"") | C13: =+A13 -> 0 | D13: =IFERROR(VLOOKUP(H13,'[1]Consolidado MP Planta'!$A$2:$M$823,13,0),"") | E13: =IFERROR(VLOOKUP(H13,'[1]Consolidado MP Planta'!$A$2:$M$823,12,0),"") | F13: =IFERROR(C13*E13,"") | G13: =IFERROR(F13/$F$66,"")
B14: =IFERROR(VLOOKUP(H14,'[1]Consolidado MP Planta'!$A$2:$M$823,3,0),"") | C14: =+A14 -> 0 | D14: =IFERROR(VLOOKUP(H14,'[1]Consolidado MP Planta'!$A$2:$M$823,13,0),"") | E14: =IFERROR(VLOOKUP(H14,'[1]Consolidado MP Planta'!$A$2:$M$823,12,0),"") | F14: =IFERROR(C14*E14,"") | G14: =IFERROR(F14/$F$66,"")
B15: =IFERROR(VLOOKUP(H15,'[2]ARTICULOS MP PLANTA'!$A$2:$G$589,2,0),"")
A16: UNIDADES | B16: MATERIA PRIMA SEMIELABORADOS | C16: UNIDADES | D16: UND MEDIDA | E16: COSTO UNITARIO | F16: TOTAL COSTO | G16: % PREC. DEFINIDO | H16: CODIGOS
A17: 16000 | B17: BATIDO QUEQUE BANANO | C17: =+A17 -> 16000 | D17: Gramos | E17: =+'Costo Batido'!E69 -> 0.97585071 | F17: =IFERROR(E17*C17,"") -> 15613.611 | G17: =IFERROR(F17/$F$66,"") -> 0.88635614 | H17: Nuevo
A18: 0 | B18: =IFERROR(VLOOKUP(H18,[1]SEMIELABORADOS!$A$2:$M$6000,2,0),"") -> MEZCLA P/ENGRASE MOLDES KILO | C18: =+A18 -> 0 | D18: =IFERROR(VLOOKUP(H18,[1]SEMIELABORADOS!$A$2:$M$6000,6,0),"") -> Gramo | E18: 2.04 | F18: =IFERROR(E18*C18,"") -> 0 | G18: =IFERROR(F18/$F$66,"") -> 0 | H18: 902000019
B19: =IFERROR(VLOOKUP(H19,[1]SEMIELABORADOS!$A$2:$M$6000,2,0),"") | C19: =+A19 -> 0 | D19: =IFERROR(VLOOKUP(H19,[1]SEMIELABORADOS!$A$2:$M$6000,6,0),"") | E19: =IFERROR(VLOOKUP(H19,[1]SEMIELABORADOS!$A$2:$H$65536,8,0),"") | F19: =IFERROR(E19*C19,"") | G19: =IFERROR(F19/$F$66,"")
B20: =IFERROR(VLOOKUP(H20,[1]SEMIELABORADOS!$A$2:$M$6000,2,0),"") | C20: =+A20 -> 0 | D20: =IFERROR(VLOOKUP(H20,[1]SEMIELABORADOS!$A$2:$M$6000,6,0),"") | E20: =IFERROR(VLOOKUP(H20,[1]SEMIELABORADOS!$A$2:$H$65536,8,0),"") | F20: =IFERROR(E20*C20,"") | G20: =IFERROR(F20/$F$66,"")
B21: =IFERROR(VLOOKUP(H21,[1]SEMIELABORADOS!$A$2:$M$6000,2,0),"") | C21: =+A21 -> 0 | D21: =IFERROR(VLOOKUP(H21,[1]SEMIELABORADOS!$A$2:$M$6000,6,0),"") | E21: =IFERROR(VLOOKUP(H21,[1]SEMIELABORADOS!$A$2:$H$65536,8,0),"") | F21: =IFERROR(E21*C21,"") | G21: =IFERROR(F21/$F$66,"")
B22: =IFERROR(VLOOKUP(H22,[1]SEMIELABORADOS!$A$2:$M$6000,2,0),"") | C22: =+A22 -> 0 | D22: =IFERROR(VLOOKUP(H22,[1]SEMIELABORADOS!$A$2:$M$6000,6,0),"") | E22: =IFERROR(VLOOKUP(H22,[1]SEMIELABORADOS!$A$2:$H$65536,8,0),"") | F22: =IFERROR(E22*C22,"") | G22: =IFERROR(F22/$F$66,"")
B23: =IFERROR(VLOOKUP(H23,[1]SEMIELABORADOS!$A$2:$M$6000,2,0),"") | C23: =+A23 -> 0 | D23: =IFERROR(VLOOKUP(H23,[1]SEMIELABORADOS!$A$2:$M$6000,6,0),"") | E23: =IFERROR(VLOOKUP(H23,[1]SEMIELABORADOS!$A$2:$H$65536,8,0),"") | F23: =IFERROR(E23*C23,"") | G23: =IFERROR(F23/$F$66,"")
B24: =IFERROR(VLOOKUP(H24,[1]SEMIELABORADOS!$A$2:$M$6000,2,0),"") | C24: =+A24 -> 0 | D24: =IFERROR(VLOOKUP(H24,[1]SEMIELABORADOS!$A$2:$M$6000,6,0),"") | E24: =IFERROR(VLOOKUP(H24,[1]SEMIELABORADOS!$A$2:$H$65536,8,0),"") | F24: =IFERROR(E24*C24,"") | G24: =IFERROR(F24/$F$66,"")
A26: UNIDADES | B26: EMPAQUE | C26: UNIDADES | D26: UND MEDIDA | E26: COSTO UNITARIO | F26: TOTAL COSTO | G26: % PREC. DEFINIDO | H26: CODIGOS
A27: 7 | B27: =IFERROR(VLOOKUP(H27,'[1]Consolidado MP Planta'!$A$2:$M$823,3,0),"") -> PAPEL ENCERADO 10X10 (CAJA) | C27: =+A27 -> 7 | D27: =IFERROR(VLOOKUP(H27,'[1]Consolidado MP Planta'!$A$2:$M$823,13,0),"") -> Und | E27: 14.2 | F27: =IFERROR(C27*E27,"") -> 99.4 | G27: =IFERROR(F27/$F$66,"") -> 0.005642756 | H27: 1950772
B28: =IFERROR(VLOOKUP(H28,'[1]Consolidado MP Planta'!$A$2:$M$823,3,0),"") | C28: =+A28 -> 0 | D28: =IFERROR(VLOOKUP(H28,'[1]Consolidado MP Planta'!$A$2:$M$823,13,0),"") | E28: =IFERROR(VLOOKUP(H28,'[1]Consolidado MP Planta'!$A$2:$M$823,12,0),"") | F28: =IFERROR(C28*E28,"") | G28: =IFERROR(F28/$F$66,"")
B29: =IFERROR(VLOOKUP(H29,'[1]Consolidado MP Planta'!$A$2:$M$823,3,0),"") | C29: =+A29 -> 0 | D29: =IFERROR(VLOOKUP(H29,'[1]Consolidado MP Planta'!$A$2:$M$823,13,0),"") | E29: =IFERROR(VLOOKUP(H29,'[1]Consolidado MP Planta'!$A$2:$M$823,12,0),"") | F29: =IFERROR(C29*E29,"") | G29: =IFERROR(F29/$F$66,"")
B30: =IFERROR(VLOOKUP(H30,'[1]Consolidado MP Planta'!$A$2:$M$823,3,0),"") | C30: =+A30 -> 0 | D30: =IFERROR(VLOOKUP(H30,'[1]Consolidado MP Planta'!$A$2:$M$823,13,0),"") | E30: =IFERROR(VLOOKUP(H30,'[1]Consolidado MP Planta'!$A$2:$M$823,12,0),"") | F30: =IFERROR(C30*E30,"") | G30: =IFERROR(F30/$F$66,"")
B31: =IFERROR(VLOOKUP(H31,'[1]Consolidado MP Planta'!$A$2:$M$823,3,0),"") | C31: =+A31 -> 0 | D31: =IFERROR(VLOOKUP(H31,'[1]Consolidado MP Planta'!$A$2:$M$823,13,0),"") | E31: =IFERROR(VLOOKUP(H31,'[1]Consolidado MP Planta'!$A$2:$M$823,12,0),"") | F31: =IFERROR(C31*E31,"") | G31: =IFERROR(F31/$F$66,"")
B32: =IFERROR(VLOOKUP(H32,'[1]Consolidado MP Planta'!$A$2:$M$823,3,0),"") | C32: =+A32 -> 0 | D32: =IFERROR(VLOOKUP(H32,'[1]Consolidado MP Planta'!$A$2:$M$823,13,0),"") | E32: =IFERROR(VLOOKUP(H32,'[1]Consolidado MP Planta'!$A$2:$M$823,12,0),"") | F32: =IFERROR(C32*E32,"") | G32: =IFERROR(F32/$F$66,"")
A34: UNIDADES | B34: EMPAQUE SEMIELABORADOS | C34: UNIDADES | D34: UND MEDIDA | E34: COSTO UNITARIO | F34: TOTAL COSTO | G34: % PREC. DEFINIDO | H34: CODIGOS
A35: =+A17 -> 16000 | B35: BATIDO QUEQUE BANANO | C35: =+A35 -> 16000 | D35: Gramos | E35: =+'Costo Batido'!E76 -> 0.0087638639 | F35: =IFERROR(E35*C35,"") -> 140.22182 | G35: =IFERROR(F35/$F$66,"") -> 0.0079601362 | H35: Nuevo
A36: =+A18 -> 0 | B36: =IFERROR(VLOOKUP(H36,[1]SEMIELABORADOS!$A$2:$M$6000,2,0),"") -> MEZCLA P/ENGRASE MOLDES KILO | C36: =+A36 -> 0 | D36: =IFERROR(VLOOKUP(H36,[1]SEMIELABORADOS!$A$2:$M$6000,6,0),"") -> Gramo | E36: =IFERROR(VLOOKUP(H36,[1]SEMIELABORADOS!$A$2:$M$65536,10,0),"") -> 0.021536385 | F36: =IFERROR(E36*C36,"") -> 0 | G36: =IFERROR(F36/$F$66,"") -> 0 | H36: 902000019
A37: =+A19 -> 0 | B37: =IFERROR(VLOOKUP(H37,[1]SEMIELABORADOS!$A$2:$M$6000,2,0),"") | C37: =+A37 -> 0 | D37: =IFERROR(VLOOKUP(H37,[1]SEMIELABORADOS!$A$2:$M$6000,6,0),"") | E37: =IFERROR(VLOOKUP(H37,[1]SEMIELABORADOS!$A$2:$M$65536,10,0),"") | F37: =IFERROR(E37*C37,"") | G37: =IFERROR(F37/$F$66,"")
A38: =+A20 -> 0 | B38: =IFERROR(VLOOKUP(H38,[1]SEMIELABORADOS!$A$2:$M$6000,2,0),"") | C38: =+A38 -> 0 | D38: =IFERROR(VLOOKUP(H38,[1]SEMIELABORADOS!$A$2:$M$6000,6,0),"") | E38: =IFERROR(VLOOKUP(H38,[1]SEMIELABORADOS!$A$2:$M$65536,10,0),"") | F38: =IFERROR(E38*C38,"") | G38: =IFERROR(F38/$F$66,"")
A39: =+A21 -> 0 | B39: =IFERROR(VLOOKUP(H39,[1]SEMIELABORADOS!$A$2:$M$6000,2,0),"") | C39: =+A39 -> 0 | D39: =IFERROR(VLOOKUP(H39,[1]SEMIELABORADOS!$A$2:$M$6000,6,0),"") | E39: =IFERROR(VLOOKUP(H39,[1]SEMIELABORADOS!$A$2:$M$65536,10,0),"") | F39: =IFERROR(E39*C39,"") | G39: =IFERROR(F39/$F$66,"")
A40: =+A22 -> 0 | B40: =IFERROR(VLOOKUP(H40,[1]SEMIELABORADOS!$A$2:$M$6000,2,0),"") | C40: =+A40 -> 0 | D40: =IFERROR(VLOOKUP(H40,[1]SEMIELABORADOS!$A$2:$M$6000,6,0),"") | E40: =IFERROR(VLOOKUP(H40,[1]SEMIELABORADOS!$A$2:$M$65536,10,0),"") | F40: =IFERROR(E40*C40,"") | G40: =IFERROR(F40/$F$66,"")
A41: =+A23 -> 0 | B41: =IFERROR(VLOOKUP(H41,[1]SEMIELABORADOS!$A$2:$M$6000,2,0),"") | C41: =+A41 -> 0 | D41: =IFERROR(VLOOKUP(H41,[1]SEMIELABORADOS!$A$2:$M$6000,6,0),"") | E41: =IFERROR(VLOOKUP(H41,[1]SEMIELABORADOS!$A$2:$M$65536,10,0),"") | F41: =IFERROR(E41*C41,"") | G41: =IFERROR(F41/$F$66,"")
A43: UNIDADES | B43: MODI | C43: UNIDADES | D43: UND MEDIDA | E43: COSTO UNITARIO | F43: TOTAL COSTO | G43: % PREC. DEFINIDO | H43: CODIGOS
A44: =+A35 -> 16000 | B44: BATIDO QUEQUE BANANO | C44: =+A44 -> 16000 | D44: Gramos | E44: =+'Costo Batido'!E74 -> 0.066285714 | F44: =IFERROR(E44*C44,"") -> 1060.5714 | G44: =IFERROR(F44/$F$66,"") -> 0.060206699 | H44: Nuevo
A45: =+A36 -> 0 | B45: =IFERROR(VLOOKUP(H45,[1]SEMIELABORADOS!$A$2:$M$6000,2,0),"") -> MEZCLA P/ENGRASE MOLDES KILO | C45: =+A45 -> 0 | D45: =IFERROR(VLOOKUP(H45,[1]SEMIELABORADOS!$A$2:$M$6000,6,0),"") -> Gramo | E45: =IFERROR(VLOOKUP(H45,[1]SEMIELABORADOS!$A$2:$M$65536,12,0),"") -> 0.2512758 | F45: =IFERROR(E45*C45,"") -> 0 | G45: =IFERROR(F45/$F$66,"") -> 0 | H45: 902000019
...

Sheet Empaque
B1: SERVICIOS DE PASTELERIA S.A. | G1: CÓDIGO:
B2: ESPECIFICACION DE RECETA | G2: REVISIÓN:
B3: Empaque Mufin banano Spoon | G3: FECHA DE APROBACIÓN:
B4: Elaborado | C4: Juan Pablo Brenes, chef
B5: Aprobado | C5: Esteban Cartin, Gerente de Manufactura
A7: AREA QUE PRODUCE: | C7: Pastas | F7: AREA QUE EMPACA: | H7: Figuras
A8: # Código | B8: Descripción del ingrediente | C8: Marca | D8: Unidad Internacional | F8: Medida alternativa | H8: Costo - Referencia
D9: Cantidad | E9: Unidad medida | F9: Cantidad | G9: Unidad medida | H9: Colones
A10: NUEVO | B10: ROSQUETE MUFIN BANANO SPOON | C10: FAS | D10: 84 | E10: g | F10: 3 UNIDADES
B12: EMPAQUE
A13: 702077 | B13: ETIQ. GENERICA PEQUEÑA V-274 | C13: Litografia CR | D13: 1 | E13: ud
A14: 702012 | B14: ETIQ.FECHA VENCIMIENTO | C14: Etiplast | D14: 1 | E14: ud
A15: 702067 | B15: ETIQ.BLANCA 1 13/16 * 1 7/8 | D15: 1 | E15: ud
A16: 1950895 | B16: BOLSA CELOFAN 6 X 9 (KILO) | D16: 1 | E16: ud
C19: Cantidad | D19: Unidad
A20: PESO TOTAL OBTENIDO | C20: 84 | D20: g
A21: TIEMPO TOTAL DE PREPARACION | C21: 1 | D21: min
A22: CANTIDAD DE PORCIONES OBTENIDAS | C22: 1 | D22: ud
A23: PESO DE CADA PORCIÓN | C23: 84 | D23: g
A24: MERMA | C24: 0 | D24: g
A25: PROCEDIMIENTO DE PREPARACION DE LA RECETA
A26: 1, Empacar 3 unidades de mufin banano en una bolsa de celofan 6x9. Sellar.
A27: 2.- Etiquetar
A35: Control de cambios

Sheet Empaque 2
B1: SERVICIOS DE PASTELERIA S.A. | G1: CÓDIGO:
B2: ESPECIFICACION DE RECETA | G2: REVISIÓN:
B3: Empaque queque banano Spoon | G3: FECHA DE APROBACIÓN:
B4: Elaborado | C4: Juan Pablo Brenes, chef
B5: Aprobado | C5: Esteban Cartin, Gerente de Manufactura
A7: AREA QUE PRODUCE: | C7: Pastas | F7: AREA QUE EMPACA: | H7: Figuras
A8: # Código | B8: Descripción del ingrediente | C8: Marca | D8: Unidad Internacional | F8: Medida alternativa | H8: Costo - Referencia
D9: Cantidad | E9: Unidad medida | F9: Cantidad | G9: Unidad medida | H9: Colones
B10: ROSQUETE MUFIN BANANO SPOON | C10: Spoon | D10: 680 | E10: g | F10: 1 | G10: Unidad
B12: EMPAQUE
A13: 703201 | B13: CINTA ORG 5/8 PARA PORC QQ | C13: Litografia CR | D13: 140 | E13: cm
A14: 1950895 | B14: BOLSA DE CELOFAN 6*9 | C14: Alim Tec | D14: 21 | E14: g
A15: 702006 | B15: ETIQ.FECHA VENCIMIENTO | C15: Etiplast | D15: 7 | E15: Unids
A16: 60100027 | B16: LOGO OVALADO SPOON PEQ (ROLLO:1000 U) | C16: Litografia CR | D16: 7 | E16: Unids
A17: 1950752 | B17: CAJA BLANCA MINI | D17: 2 | E17: Unid
C19: Cantidad | D19: Unidad
A20: PESO TOTAL OBTENIDO | C20: 680 | D20: g
A21: TIEMPO TOTAL DE PREPARACION | C21: 3 | D21: min
A22: CANTIDAD DE PORCIONES OBTENIDAS | C22: 7 | D22: ud
A23: PESO DE CADA PORCIÓN | C23: 97 | D23: g
A24: MERMA | C24: 0 | D24: g
A25: PROCEDIMIENTO DE PREPARACION DE LA RECETA
A26: 1.- Una vez horneado el queque, dejar enfriar y cortar los extremos y porcionar luego en 8 partes iguales.
A27: 2.- Las 2 porciones de los extremos se colocan juntas en una misma bolsa convirtiendolas en una sola porcion ya que estas son mas pequeñas. Las 6 porciones restantes se colocan cada una en una bolsa por separado convirtiendose en 6 porciones.
A28: 3.- Sellar las bolsas y hacer un lazo con cintas de tela (30 cm) etiquetar con fecha de vencimiento y logo Spoon.
A29: 4.- Colocar las 7 porciones en una caja blanca MINI.
A35: Control de cambios

Sheet Empaque 3
B1: SERVICIOS DE PASTELERIA S.A. | G1: CÓDIGO:
B2: ESPECIFICACION DE RECETA | G2: REVISIÓN:
B3: Empaque queque banano Spoon | G3: FECHA DE APROBACIÓN:
B4: Elaborado | C4: Juan Pablo Brenes, chef
B5: Aprobado | C5: Esteban Cartin, Gerente de Manufactura
A7: AREA QUE PRODUCE: | C7: Pastas | F7: AREA QUE EMPACA: | H7: Figuras
A8: # Código | B8: Descripción del ingrediente | C8: Marca | D8: Unidad Internacional | F8: Medida alternativa | H8: Costo - Referencia
D9: Cantidad | E9: Unidad medida | F9: Cantidad | G9: Unidad medida | H9: Colones
A10: NUEVO | B10: ROSQUETE QUEQUE DE BANANO | C10: Spoon | D10: 680 | E10: g | F10: 1 | G10: Unidad
B12: EMPAQUE
A13: 1950895 | B13: BOLSA DE CELOFAN 6*9 | C13: Alim Tec | D13: 21 | E13: g
A14: 702006 | B14: ETIQ.FECHA VENCIMIENTO | C14: Etiplast | D14: 7 | E14: Unids
A15: 60100027 | B15: LOGO OVALADO SPOON PEQ (ROLLO:1000 U) | C15: Litografia CR | D15: 7 | E15: Unids
A16: 1959752 | B16: Caja Blanca Mini | D16: 2 | E16: Unid
C18: Cantidad | D18: Unidad
A19: PESO TOTAL OBTENIDO | C19: 680 | D19: g
A20: TIEMPO TOTAL DE PREPARACION | C20: 3 | D20: min
A21: CANTIDAD DE PORCIONES OBTENIDAS | C21: 7 | D21: ud
A22: PESO DE CADA PORCIÓN | C22: 97 | D22: g
A23: MERMA | C23: 0 | D23: g
A24: PROCEDIMIENTO DE PREPARACION DE LA RECETA
A25: 1.- Una vez horneado el queque, dejar enfriar y cortar los extremos y porcionar luego en 8 partes iguales.
A26: 2.- Las 2 porciones de los extremos se colocan juntas en una misma bolsa convirtiendolas en una sola porcion ya que estas son mas pequeñas. Las 6 porciones restantes se colocan cada una en una bolsa por separado convirtiendose en 6 porciones.
A27: 3.- Sellar las bolsas y hacer un lazo con cintas de tela (30 cm) etiquetar con fecha de vencimiento y logo Spoon.
A28: 4.- Colocar las 7 porciones en una caja blanca MINI.
A34: Control de cambios

Sheet Costo empaque 
E1: Precio Local | F1: Costo MP | G1: Costo EM | H1: Costo MO
E2: =IFERROR(O62,"") -> 1486.7409 | F2: =IFERROR(H53,"") -> 702.61251 | G2: =IFERROR(H54,"") -> 111.14298 | H2: =IFERROR(H56,"") -> 344.97571
A5: ESTRUCTURA DE COSTOS
F6: Fecha: | H6: =TODAY() -> 45749
A7: UNIDADES | B7: DESCRIPCION MAT.PRIMA | C7: UNIDADES | D7: UND MEDIDA | E7: COSTO UNITARIO | F7: TOTAL COSTO | G7: % PREC. DEFINIDO | H7: CODIGOS
B8: =IFERROR(VLOOKUP(H8,'[1]Consolidado MP Planta'!$A$2:$M$823,3,0),"") | C8: =+A8 -> 0 | D8: =IFERROR(VLOOKUP(H8,'[1]Consolidado MP Planta'!$A$2:$M$823,13,0),"") | E8: =IFERROR(VLOOKUP(H8,'[1]Consolidado MP Planta'!$A$2:$M$823,12,0),"") | F8: =IFERROR(C8*E8,"") | G8: =IFERROR(F8/$F$66,"")
B9: =IFERROR(VLOOKUP(H9,'[1]Consolidado MP Planta'!$A$2:$M$823,3,0),"") | C9: =+A9 -> 0 | D9: =IFERROR(VLOOKUP(H9,'[1]Consolidado MP Planta'!$A$2:$M$823,13,0),"") | E9: =IFERROR(VLOOKUP(H9,'[1]Consolidado MP Planta'!$A$2:$M$823,12,0),"") | F9: =IFERROR(C9*E9,"") | G9: =IFERROR(F9/$F$66,"")
B10: =IFERROR(VLOOKUP(H10,'[1]Consolidado MP Planta'!$A$2:$M$823,3,0),"") | C10: =+A10 -> 0 | D10: =IFERROR(VLOOKUP(H10,'[1]Consolidado MP Planta'!$A$2:$M$823,13,0),"") | E10: =IFERROR(VLOOKUP(H10,'[1]Consolidado MP Planta'!$A$2:$M$823,12,0),"") | F10: =IFERROR(C10*E10,"") | G10: =IFERROR(F10/$F$66,"")
B11: =IFERROR(VLOOKUP(H11,'[1]Consolidado MP Planta'!$A$2:$M$823,3,0),"") | C11: =+A11 -> 0 | D11: =IFERROR(VLOOKUP(H11,'[1]Consolidado MP Planta'!$A$2:$M$823,13,0),"") | E11: =IFERROR(VLOOKUP(H11,'[1]Consolidado MP Planta'!$A$2:$M$823,12,0),"") | F11: =IFERROR(C11*E11,"") | G11: =IFERROR(F11/$F$66,"")
B12: =IFERROR(VLOOKUP(H12,'[1]Consolidado MP Planta'!$A$2:$M$823,3,0),"") | C12: =+A12 -> 0 | D12: =IFERROR(VLOOKUP(H12,'[1]Consolidado MP Planta'!$A$2:$M$823,13,0),"") | E12: =IFERROR(VLOOKUP(H12,'[1]Consolidado MP Planta'!$A$2:$M$823,12,0),"") | F12: =IFERROR(C12*E12,"") | G12: =IFERROR(F12/$F$66,"")
B13: =IFERROR(VLOOKUP(H13,'[1]Consolidado MP Planta'!$A$2:$M$823,3,0),"") | C13: =+A13 -> 0 | D13: =IFERROR(VLOOKUP(H13,'[1]Consolidado MP Planta'!$A$2:$M$823,13,0),"") | E13: =IFERROR(VLOOKUP(H13,'[1]Consolidado MP Planta'!$A$2:$M$823,12,0),"") | F13: =IFERROR(C13*E13,"") | G13: =IFERROR(F13/$F$66,"")
B14: =IFERROR(VLOOKUP(H14,'[1]Consolidado MP Planta'!$A$2:$M$823,3,0),"") | C14: =+A14 -> 0 | D14: =IFERROR(VLOOKUP(H14,'[1]Consolidado MP Planta'!$A$2:$M$823,13,0),"") | E14: =IFERROR(VLOOKUP(H14,'[1]Consolidado MP Planta'!$A$2:$M$823,12,0),"") | F14: =IFERROR(C14*E14,"") | G14: =IFERROR(F14/$F$66,"")
B15: =IFERROR(VLOOKUP(H15,'[2]ARTICULOS MP PLANTA'!$A$2:$G$589,2,0),"")
A16: UNIDADES | B16: MATERIA PRIMA SEMIELABORADOS | C16: UNIDADES | D16: UND MEDIDA | E16: COSTO UNITARIO | F16: TOTAL COSTO | G16: % PREC. DEFINIDO | H16: CODIGOS
A17: 6 | B17: ROSQUETE MUFIN BANANO SPOON | C17: =+A17 -> 6 | D17: UND | E17: =+'Costo Rosquete '!H53 -> 117.10209 | F17: =IFERROR(E17*C17,"") -> 702.61251 | G17: =IFERROR(F17/$F$66,"") -> 0.66296224 | H17: NUEVO
