Workbook

Sheet Ensamble Industria
C1: SERVICIOS DE PASTELERIA S.A. | H1: CÓDIGO:
C2: ESPECIFICACION DE RECETA | H2: REVISIÓN:
C3: Cheesecake Pie de Pecanas | H3: FECHA DE APROBACIÓN:
C4: Elaborado | D4: Javier Tong, Chef
C5: Aprobado | D5: Esteban Cartin, Gte Manufactura
A7: AREA QUE PRODUCE: | D7: Postre | G7: AREA QUE EMPACA: | I7: Postre
A8: # Código | B8: # Codigo Netsuite | C8: Descripción del ingrediente | D8: Marca | E8: Unidad Internacional | G8: Medida alternativa | I8: Costo - Referencia
E9: Cantidad | F9: Unidad medida | G9: Cantidad | H9: Unidad medida | I9: Colones
A10: 907000002 | B10: SE00041 | C10: BASE GALLETA P/CHEESE CAKE (KILO) | D10: FAS | E10: 300 | F10: g | G10: Base y borde
C11: RELLENO PIE DE PECANAS | D11: FAS | E11: 300 | F11: g | K11: =SUM(E10:E17) -> 1555
A12: MP10562 | B12: 11900028 | C12: Pecana Entera | D12: Nueces Industriales | E12: 50 | F12: g
C13: RELLENO CHEESECAKE Y MANJAR | D13: FAS | E13: 650 | F13: g
C15: DECORACION
A16: MP10485 | B16: 0310099 | C16: Crema Dulce | D16: FAS | E16: 25 | F16: g | G16: Boquilla Wilton #61
C17: TOPPING CARAMELO Y PECANA | D17: FAS | E17: 230 | F17: g
C19: EMPAQUE
A20: 702175 | B20: EM10006 | C20: ETIQUETA IMPRES SPOON GRANDE V-272 (UND) | D20: ETIPLAST | E20: 1 | F20: ud
A21: 703020 | B21: EM10248 | C21: CINTA ADHESIVA TRANSPARENT 2*100 M (UND) | D21: ETIPLAST | E21: 60 | F21: cm
A22: 1950693 | B22: EM10020 | C22: ORLA CARTON 9" DORADA (UND ) | D22: RAPIBOX | E22: 1 | F22: ud
A23: 51400021 | B23: EM10021 | C23: QUEQUERA RED C/BASE ALTA 9" (CAJA:100 U) | D23: Exp PMT | E23: 1 | F23: ud
A24: 702123 | B24: EM10011 | C24: ETIQUETA BLANCA 2 5/8X1 15/16 (UND) | D24: Cemusa | E24: 1 | F24: ud
A25: 701096 | B25: EM10124 | C25: ETIQUETA BLANCA R-153 (UND) | D25: Cemusa | E25: 1 | F25: ud
A26: 702007 | B26: EM10004 | C26: ETIQ.FECHA VENCIMIENTO BLANCO (ROLLO) | D26: CEMUSA | E26: 1 | F26: ud
A27: 702069 | B27: EM10002 | C27: ETIQ.BLANCA 1 1/4 * 3/4 (UND) | D27: ETIPLAST | E27: 1 | F27: ud
D29: Cantidad | E29: Unidad
A30: PESO TOTAL OBTENIDO | D30: 1555 | E30: g
A31: TIEMPO TOTAL DE PREPARACION | D31: 5 | E31: min
A32: CANTIDAD DE PORCIONES OBTENIDAS | D32: 1 | E32: ud
A33: PESO DE CADA PORCIÓN | D33: =+D30 -> 1555 | E33: g
A34: MERMA | D34: =SUM(E10:E19)-D30 -> 0 | E34: g
A35: PROCEDIMIENTO DE PREPARACION DE LA RECETA
A36: 1.- Colocar dentro del molde desarmable redondo 21 cm ,previamente ensagrasado la base de galleta presionar y hornear a 175°C por 7 min en el Argental, a 175°C por 8 min en el Dicte 1 y Dicte 2, a 170°C en el Dicte 3 y a 175°C por 7 min en el Marshal
A37: 2.- Una vez fria la galleta, agregar el relleno de pecanas y las pecanas sobre el relleno de pecanas. Hornear por 30 min aprox. Enfriar
A38: 3.- Agregar la el relleno de cheesecake y manjar, emparejar con ayuda de una espatula. Enfriar por 6 horas como minimo.
A39: 4.- Desmoldar con ayuda de una espatula, Pegar a la orla con manjar, decorar con colocho de crema de manjar en el borde y topping de caramelo y pecanas en el centro.
A40: 5.- Tapar y etiquetar
A45: Control de cambios

Sheet Ensamble 2 Industria 
C1: SERVICIOS DE PASTELERIA S.A. | H1: CÓDIGO:
C2: ESPECIFICACION DE RECETA | H2: REVISIÓN:
C3: Cheesecake Pie de Pecanas | H3: FECHA DE APROBACIÓN:
C4: Elaborado | D4: Javier Tong, Chef
C5: Aprobado | D5: Esteban Cartin, Gte Manufactura
A7: AREA QUE PRODUCE: | D7: Postre | G7: AREA QUE EMPACA: | I7: Postre
A8: # Código | B8: # Codigo Netsuite | C8: Descripción del ingrediente | D8: Marca | E8: Unidad Internacional | G8: Medida alternativa | I8: Costo - Referencia
E9: Cantidad | F9: Unidad medida | G9: Cantidad | H9: Unidad medida | I9: Colones
A10: 907000002 | B10: SE00041 | C10: BASE GALLETA P/CHEESE CAKE (KILO) | D10: FAS | E10: 200 | F10: g | G10: Base y borde
C11: RELLENO PIE DE PECANAS | D11: FAS | E11: 280 | F11: g
B12: MP10562 | C12: Pecana Entera | D12: FAS | E12: 40 | F12: g
C13: RELLENO CHEESECAKE PREMIUM | D13: FAS | E13: 700 | F13: g
C15: DECORACION
B16: SE00032 | C16: Crema Dulce Leche | D16: FAS | E16: 25 | F16: g | G16: Boquilla Wilton #61
C17: TOPPING CARAMELO Y PECANA | D17: FAS | E17: 180 | F17: g
C19: EMPAQUE
A20: 702175 | B20: EM10006 | C20: ETIQUETA IMPRES SPOON GRANDE V-272 (UND) | D20: ETIPLAST | E20: 1 | F20: ud
A21: 703020 | B21: EM10248 | C21: CINTA ADHESIVA TRANSPARENT 2*100 M (UND) | D21: ETIPLAST | E21: 60 | F21: cm
A22: 1950693 | B22: EM10020 | C22: ORLA CARTON 9" DORADA (UND ) | D22: RAPIBOX | E22: 1 | F22: ud
A23: 51400021 | B23: EM10021 | C23: QUEQUERA RED C/BASE ALTA 9" (CAJA:100 U) | D23: Exp PMT | E23: 1 | F23: ud
A24: 702123 | B24: EM10011 | C24: ETIQUETA BLANCA 2 5/8X1 15/16 (UND) | D24: Cemusa | E24: 1 | F24: ud
A25: 701096 | B25: EM10124 | C25: ETIQUETA BLANCA R-153 (UND) | D25: Cemusa | E25: 1 | F25: ud
A26: 702007 | B26: EM10004 | C26: ETIQ.FECHA VENCIMIENTO BLANCO (ROLLO) | D26: CEMUSA | E26: 1 | F26: ud
A27: 702069 | B27: EM10002 | C27: ETIQ.BLANCA 1 1/4 * 3/4 (UND) | D27: ETIPLAST | E27: 1 | F27: ud
D29: Cantidad | E29: Unidad
A30: PESO TOTAL OBTENIDO | D30: 1420 | E30: g
A31: TIEMPO TOTAL DE PREPARACION | D31: 5 | E31: min
A32: CANTIDAD DE PORCIONES OBTENIDAS | D32: 1 | E32: ud
A33: PESO DE CADA PORCIÓN | D33: 1420 | E33: g
A34: MERMA | D34: 5 | E34: g
A35: PROCEDIMIENTO DE PREPARACION DE LA RECETA
A36: 1.- Colocar dentro del molde desarmable redondo 21 cm ,previamente ensagrasado la base de galleta presionar, despues colocar agregar el relleno de pecanas y hornear a 325°F por 25 minutos.
A37: 2.- Una vez fria la base, se agregar la el relleno de cheesecake premium, emparejar con ayuda de una espatula. Enfriar por 6 horas como minimo.
A38: 3.- Desmoldar con ayuda de una espatula, Pegar a la orla con manjar, decorar con colocho de crema de manjar en el borde y topping de caramelo y pecanas en el centro.
A39: 4.- Tapar y etiquetar
A44: Control de cambios

Sheet Ensamble Industria 3
C1: SERVICIOS DE PASTELERIA S.A. | H1: CÓDIGO:
C2: ESPECIFICACION DE RECETA | H2: REVISIÓN:
C3: Cheesecake Pie de Pecanas Industria | H3: FECHA DE APROBACIÓN:
C4: Elaborado | D4: Javier Tong, Chef
C5: Aprobado | D5: Esteban Cartin, Gte Manufactura
A7: AREA QUE PRODUCE: | D7: Postre | G7: AREA QUE EMPACA: | I7: Postre
A8: # Código | B8: # Codigo Netsuite | C8: Descripción del ingrediente | D8: Marca | E8: Unidad Internacional | G8: Medida alternativa | I8: Costo - Referencia
E9: Cantidad | F9: Unidad medida | G9: Cantidad | H9: Unidad medida | I9: Colones
A10: 907000002 | B10: SE00041 | C10: BASE GALLETA P/CHEESE CAKE (KILO) | D10: FAS | E10: 300 | F10: g | G10: Base y borde
C11: RELLENO PIE DE PECANAS | D11: FAS | E11: 280 | F11: g | K11: 1560
B12: MP10562 | C12: PECANA ENTERA | D12: FAS | E12: 40 | F12: g
C13: RELLENO CHEESECAKE PREMIUM | D13: FAS | E13: 700 | F13: g
C15: DECORACION
A16: MP10485 | B16: 0310099 | C16: CREMA DULCE | D16: FAS | E16: 60 | F16: g | G16: Boquilla Wilton #61
C17: TOPPING CARAMELO Y PECANA | D17: FAS | E17: 180 | F17: g
C19: EMPAQUE
B20: NUEVO | C20: ETIQUETA ESPECIAL DIA DE LA MADRE | E20: 1 | F20: ud
A21: 703020 | B21: EM10248 | C21: CINTA ADHESIVA TRANSPARENT 2*100 M (UND) | D21: ETIPLAST | E21: 60 | F21: cm
A22: 1950693 | B22: EM10020 | C22: ORLA CARTON 9" DORADA (UND ) | D22: RAPIBOX | E22: 1 | F22: ud
A23: 51400021 | B23: EM10021 | C23: QUEQUERA RED C/BASE ALTA 9" (CAJA:100 U) | D23: Exp PMT | E23: 1 | F23: ud
A24: 702123 | B24: EM10011 | C24: ETIQUETA BLANCA 2 5/8X1 15/16 (UND) | D24: Cemusa | E24: 1 | F24: ud
A25: 701096 | B25: EM10124 | C25: ETIQUETA BLANCA R-153 (UND) | D25: Cemusa | E25: 1 | F25: ud
A26: 702007 | B26: EM10004 | C26: ETIQ.FECHA VENCIMIENTO BLANCO (ROLLO) | D26: CEMUSA | E26: 1 | F26: ud
A27: 702069 | B27: EM10002 | C27: ETIQ.BLANCA 1 1/4 * 3/4 (UND) | D27: ETIPLAST | E27: 1 | F27: ud
B28: EM10018 | C28: Papel Mantequilla | E28: 0.25 | F28: ud | G28: 1/4 de papel
D30: Cantidad | E30: Unidad
A31: PESO TOTAL OBTENIDO | D31: 1533 | E31: g
A32: TIEMPO TOTAL DE PREPARACION | D32: 5 | E32: min
A33: CANTIDAD DE PORCIONES OBTENIDAS | D33: 1 | E33: ud
A34: PESO DE CADA PORCIÓN | D34: 1533 | E34: g
A35: MERMA | D35: 27 | E35: g
A36: PROCEDIMIENTO DE PREPARACION DE LA RECETA
A37: 1.- Colocar dentro del molde desarmable redondo 21 cm ,previamente ensagrasado, poner 1/4 de papel mantequilla en la base del molde (dejando el sobrante hacia abajo del molde) colocar la galleta y presionar hacia los bordes y en la base, hornear a 175°C por 7 min en el Argental, a 175°C por 8 min en el Dicte 1 y Dicte 2, a 170°C en el Dicte 3 y a 175°C por 7 min en el Marshal
A38: 2.- Una vez fria la galleta, agregar el relleno de pecanas. Hornear por 20 min aprox. Enfriar
A39: 3.- Agregar la el relleno de cheesecake premium, emparejar con ayuda de una espatula. Enfriar por 6 horas como minimo.
A40: 4.- Desmoldar con ayuda de una espatula, Pegar a la orla con manjar, decorar con colocho de crema de dulce en el borde y el topping de caramelo y pecanas en el centro.
A41: 5.- Tapar y etiquetar
A46: Control de cambios

Sheet ENSAMBLE INDUSTRIA 4
C1: SERVICIOS DE PASTELERIA S.A. | H1: CÓDIGO:
C2: ESPECIFICACION DE RECETA | H2: REVISIÓN:
C3: Cheesecake Pie de Pecanas Industria | H3: FECHA DE APROBACIÓN:
C4: Elaborado | D4: Javier Tong, Chef
C5: Aprobado | D5: Esteban Cartin, Gte Manufactura
A7: AREA QUE PRODUCE: | D7: Postre | G7: AREA QUE EMPACA: | I7: Postre
A8: # Código | B8: # Codigo Netsuite | C8: Descripción del ingrediente | D8: Marca | E8: Unidad Internacional | G8: Medida alternativa | I8: Costo - Referencia
E9: Cantidad | F9: Unidad medida | G9: Cantidad | H9: Unidad medida | I9: Colones
A10: 907000002 | B10: SE00041 | C10: BASE GALLETA P/CHEESE CAKE (KILO) | D10: FAS | E10: 280 | F10: g | G10: Base y borde
C11: RELLENO PIE DE PECANAS | D11: FAS | E11: 280 | F11: g | K11: 1525
B12: MP10562 | C12: PECANA ENTERA | D12: FAS | E12: 35 | F12: g
C13: RELLENO CHEESECAKE PREMIUM | D13: FAS | E13: 700 | F13: g
C15: DECORACION
B16: SE00032 | C16: CREMA DULCE DE LECHE | D16: FAS | E16: 50 | F16: g | G16: Boquilla Wilton #61
C17: TOPPING CARAMELO Y PECANA | D17: FAS | E17: 180 | F17: g
B18: MP10007 | C18: Manjar Leche Condensada | D18: NESTLE | E18: 10 | F18: g
C20: EMPAQUE
B21: NUEVO | C21: ETIQUETA ESPECIAL DIA DE LA MADRE | E21: 1 | F21: ud
A22: 703020 | B22: EM10248 | C22: CINTA ADHESIVA TRANSPARENT 2*100 M (UND) | D22: ETIPLAST | E22: 60 | F22: cm
A23: 1950693 | B23: EM10020 | C23: ORLA CARTON 9" DORADA (UND ) | D23: RAPIBOX | E23: 1 | F23: ud
A24: 51400021 | B24: EM10021 | C24: QUEQUERA RED C/BASE ALTA 9" (CAJA:100 U) | D24: Exp PMT | E24: 1 | F24: ud
A25: 702123 | B25: EM10011 | C25: ETIQUETA BLANCA 2 5/8X1 15/16 (UND) | D25: Cemusa | E25: 1 | F25: ud
A26: 701096 | B26: EM10124 | C26: ETIQUETA BLANCA R-153 (UND) | D26: Cemusa | E26: 1 | F26: ud
A27: 702007 | B27: EM10004 | C27: ETIQ.FECHA VENCIMIENTO BLANCO (ROLLO) | D27: CEMUSA | E27: 1 | F27: ud
A28: 702069 | B28: EM10002 | C28: ETIQ.BLANCA 1 1/4 * 3/4 (UND) | D28: ETIPLAST | E28: 1 | F28: ud
B29: EM10018 | C29: Papel Mantequilla | E29: 0.25 | F29: ud | G29: 1/4 de papel
D31: Cantidad | E31: Unidad
A32: PESO TOTAL OBTENIDO | D32: 1533 | E32: g
A33: TIEMPO TOTAL DE PREPARACION | D33: 5 | E33: min
A34: CANTIDAD DE PORCIONES OBTENIDAS | D34: 1 | E34: ud
A35: PESO DE CADA PORCIÓN | D35: 1533 | E35: g
A36: MERMA | D36: 2 | E36: g
A37: PROCEDIMIENTO DE PREPARACION DE LA RECETA
A38: 1.- Colocar dentro del molde desarmable redondo 21 cm ,previamente ensagrasado, poner 1/4 de papel mantequilla en la base del molde (dejando el sobrante hacia abajo del molde) colocar la galleta y presionar hacia los bordes y en la base, hornear a 175°C por 7 min en el Argental, a 175°C por 8 min en el Dicte 1 y Dicte 2, a 170°C en el Dicte 3 y a 175°C por 7 min en el Marshal
A39: 2.- Una vez fria la galleta, agregar el relleno de pecanas. Hornear por 20 min aprox. Enfriar
A40: 3.- Agregar la el relleno de cheesecake premium, emparejar con ayuda de una espatula. Enfriar por 6 horas como minimo.
A41: 4.- Desmoldar con ayuda de una espatula, Pegar a la orla con manjar, decorar con colocho de crema de dulce en el borde y el topping de caramelo y pecanas en el centro.
A42: 5.- Tapar y etiquetar
A47: Control de cambios

Sheet Costo Ensamble Industria
E1: Precio Local | F1: Costo MP | G1: Costo EM | H1: Costo MO
E2: =IFERROR(O63,"") -> 5901.5793 | F2: =IFERROR(H54,"") -> 4340.7685 | G2: =IFERROR(H55,"") -> 509.8502 | H2: =IFERROR(H57,"") -> 573.92889
A5: ESTRUCTURA DE COSTOS
F6: Fecha: | H6: =TODAY() -> 45831
A7: UNIDADES | B7: DESCRIPCION MAT.PRIMA | C7: UNIDADES | D7: UND MEDIDA | E7: COSTO UNITARIO | F7: TOTAL COSTO | G7: % PREC. DEFINIDO | H7: CODIGOS
A8: 50 | B8: Crema Dulce LECHE | C8: =+A8 -> 50 | D8: Gramo | E8: 2.27 | F8: =IFERROR(C8*E8,"") -> 113.5 | G8: =IFERROR(F8/$F$67,"") -> 0.02132483 | H8: 310099
A9: 35 | B9: Pecana Entera | C9: =+A9 -> 35 | D9: Gramo | E9: 8.47 | F9: =IFERROR(C9*E9,"") -> 296.45 | G9: =IFERROR(F9/$F$67,"") -> 0.055698201 | H9: 11900028
A10: 10 | B10: Manjar de leche condensada | C10: =+A10 -> 10 | D10: Gramo | E10: 2.56 | F10: =IFERROR(C10*E10,"") -> 25.6 | G10: =IFERROR(F10/$F$67,"") -> 0.0048098295
B11: =IFERROR(VLOOKUP(H11,'[1]Consolidado MP Planta'!$A$2:$M$823,3,0),"") | C11: =+A11 -> 0 | D11: =IFERROR(VLOOKUP(H11,'[1]Consolidado MP Planta'!$A$2:$M$823,13,0),"") | E11: =IFERROR(VLOOKUP(H11,'[1]Consolidado MP Planta'!$A$2:$M$823,12,0),"") | F11: =IFERROR(C11*E11,"") | G11: =IFERROR(F11/$F$67,"")
B12: =IFERROR(VLOOKUP(H12,'[1]Consolidado MP Planta'!$A$2:$M$823,3,0),"") | C12: =+A12 -> 0 | D12: =IFERROR(VLOOKUP(H12,'[1]Consolidado MP Planta'!$A$2:$M$823,13,0),"") | E12: =IFERROR(VLOOKUP(H12,'[1]Consolidado MP Planta'!$A$2:$M$823,12,0),"") | F12: =IFERROR(C12*E12,"") | G12: =IFERROR(F12/$F$67,"")
B13: =IFERROR(VLOOKUP(H13,'[1]Consolidado MP Planta'!$A$2:$M$823,3,0),"") | C13: =+A13 -> 0 | D13: =IFERROR(VLOOKUP(H13,'[1]Consolidado MP Planta'!$A$2:$M$823,13,0),"") | E13: =IFERROR(VLOOKUP(H13,'[1]Consolidado MP Planta'!$A$2:$M$823,12,0),"") | F13: =IFERROR(C13*E13,"") | G13: =IFERROR(F13/$F$67,"")
B14: =IFERROR(VLOOKUP(H14,'[1]Consolidado MP Planta'!$A$2:$M$823,3,0),"") | C14: =+A14 -> 0 | D14: =IFERROR(VLOOKUP(H14,'[1]Consolidado MP Planta'!$A$2:$M$823,13,0),"") | E14: =IFERROR(VLOOKUP(H14,'[1]Consolidado MP Planta'!$A$2:$M$823,12,0),"") | F14: =IFERROR(C14*E14,"") | G14: =IFERROR(F14/$F$67,"")
B15: =IFERROR(VLOOKUP(H15,'[2]ARTICULOS MP PLANTA'!$A$2:$G$589,2,0),"")
A16: UNIDADES | B16: MATERIA PRIMA SEMIELABORADOS | C16: UNIDADES | D16: UND MEDIDA | E16: COSTO UNITARIO | F16: TOTAL COSTO | G16: % PREC. DEFINIDO | H16: CODIGOS
A17: 200 | B17: =IFERROR(VLOOKUP(H17,[1]SEMIELABORADOS!$A$2:$M$6000,2,0),"") -> BASE GALLETA P/CHEESE CAKE (KILO) | C17: =+A17 -> 200 | D17: =IFERROR(VLOOKUP(H17,[1]SEMIELABORADOS!$A$2:$M$6000,6,0),"") -> Gramo | E17: 2.5 | F17: =IFERROR(E17*C17,"") -> 500 | G17: =IFERROR(F17/$F$67,"") -> 0.093941982 | H17: 907000002
A18: 280 | B18: RELLENO PIE DE PECANAS | C18: =+A18 -> 280 | D18: Gramo | E18: =+'Costo Relleno CK Premium'!E75 -> 2.638085 | F18: =IFERROR(E18*C18,"") -> 738.6638 | G18: =IFERROR(F18/$F$67,"") -> 0.13878308 | H18: NUEVO
A19: 700 | B19: RELLENO CHEESECAKE PREMIUM | C19: =+A19 -> 700 | D19: Gramo | E19: =+'Costo relleno CK y Manjar '!E75 -> 2.5338071 | F19: =IFERROR(E19*C19,"") -> 1773.665 | G19: =IFERROR(F19/$F$67,"") -> 0.3332432 | H19: NUEVO
A20: 180 | B20: TOPPING CARAMELO Y PECANA | C20: =+A20 -> 180 | D20: Gramo | E20: =+'Costo Topping caramelo pecana '!E69 -> 4.9604983 | F20: =IFERROR(E20*C20,"") -> 892.88969 | G20: =IFERROR(F20/$F$67,"") -> 0.16775965
B21: =IFERROR(VLOOKUP(H21,[1]SEMIELABORADOS!$A$2:$M$6000,2,0),"") | C21: =+A21 -> 0 | D21: =IFERROR(VLOOKUP(H21,[1]SEMIELABORADOS!$A$2:$M$6000,6,0),"") | E21: =IFERROR(VLOOKUP(H21,[1]SEMIELABORADOS!$A$2:$H$65536,8,0),"") | F21: =IFERROR(E21*C21,"") | G21: =IFERROR(F21/$F$67,"")
B22: =IFERROR(VLOOKUP(H22,[1]SEMIELABORADOS!$A$2:$M$6000,2,0),"") | C22: =+A22 -> 0 | D22: =IFERROR(VLOOKUP(H22,[1]SEMIELABORADOS!$A$2:$M$6000,6,0),"") | E22: =IFERROR(VLOOKUP(H22,[1]SEMIELABORADOS!$A$2:$H$65536,8,0),"") | F22: =IFERROR(E22*C22,"") | G22: =IFERROR(F22/$F$67,"")
B23: =IFERROR(VLOOKUP(H23,[1]SEMIELABORADOS!$A$2:$M$6000,2,0),"") | C23: =+A23 -> 0 | D23: =IFERROR(VLOOKUP(H23,[1]SEMIELABORADOS!$A$2:$M$6000,6,0),"") | E23: =IFERROR(VLOOKUP(H23,[1]SEMIELABORADOS!$A$2:$H$65536,8,0),"") | F23: =IFERROR(E23*C23,"") | G23: =IFERROR(F23/$F$67,"")
B24: =IFERROR(VLOOKUP(H24,[1]SEMIELABORADOS!$A$2:$M$6000,2,0),"") | C24: =+A24 -> 0 | D24: =IFERROR(VLOOKUP(H24,[1]SEMIELABORADOS!$A$2:$M$6000,6,0),"") | E24: =IFERROR(VLOOKUP(H24,[1]SEMIELABORADOS!$A$2:$H$65536,8,0),"") | F24: =IFERROR(E24*C24,"") | G24: =IFERROR(F24/$F$67,"")
A26: UNIDADES | B26: EMPAQUE | C26: UNIDADES | D26: UND MEDIDA | E26: COSTO UNITARIO | F26: TOTAL COSTO | G26: % PREC. DEFINIDO | H26: CODIGOS
A27: 1 | B27: =IFERROR(VLOOKUP(H27,'[1]Consolidado MP Planta'!$A$2:$M$823,3,0),"") -> ORLA #9 DORADA (UND) | C27: =+A27 -> 1 | D27: =IFERROR(VLOOKUP(H27,'[1]Consolidado MP Planta'!$A$2:$M$823,13,0),"") -> Und | E27: 111 | F27: =IFERROR(C27*E27,"") -> 111 | G27: =IFERROR(F27/$F$67,"") -> 0.02085512 | H27: 1950693
A28: 1 | B28: =IFERROR(VLOOKUP(H28,'[1]Consolidado MP Planta'!$A$2:$M$823,3,0),"") -> QUEQUERA RED C/BASE ALTA 9" (CAJA:100 U) | C28: =+A28 -> 1 | D28: =IFERROR(VLOOKUP(H28,'[1]Consolidado MP Planta'!$A$2:$M$823,13,0),"") -> Und | E28: 340.21 | F28: =IFERROR(C28*E28,"") -> 340.21 | G28: =IFERROR(F28/$F$67,"") -> 0.063920003 | H28: 51400021
A29: 1 | B29: =IFERROR(VLOOKUP(H29,'[1]Consolidado MP Planta'!$A$2:$M$823,3,0),"") -> ETIQUETA BLANCA 2 5/8X1 15/16 (UND) | C29: =+A29 -> 1 | D29: =IFERROR(VLOOKUP(H29,'[1]Consolidado MP Planta'!$A$2:$M$823,13,0),"") -> Und | E29: 2.13 | F29: =IFERROR(C29*E29,"") -> 2.13 | G29: =IFERROR(F29/$F$67,"") -> 0.00040019284 | H29: 0702123
A30: 1 | B30: =IFERROR(VLOOKUP(H30,'[1]Consolidado MP Planta'!$A$2:$M$823,3,0),"") -> ETIQUETA BLANCA R-153 (UND) | C30: =+A30 -> 1 | D30: =IFERROR(VLOOKUP(H30,'[1]Consolidado MP Planta'!$A$2:$M$823,13,0),"") -> Und | E30: 0.39 | F30: =IFERROR(C30*E30,"") -> 0.39 | G30: =IFERROR(F30/$F$67,"") -> 7.3274746e-05 | H30: 701096
A31: 1 | B31: =IFERROR(VLOOKUP(H31,'[1]Consolidado MP Planta'!$A$2:$M$823,3,0),"") -> ETIQ.FECHA VENCIMIENTO BLANCO (ROLLO) | C31: =+A31 -> 1 | D31: =IFERROR(VLOOKUP(H31,'[1]Consolidado MP Planta'!$A$2:$M$823,13,0),"") -> Gramos | E31: 0.33 | F31: =IFERROR(C31*E31,"") -> 0.33 | G31: =IFERROR(F31/$F$67,"") -> 6.2001708e-05 | H31: 0702007
A32: 1 | B32: =IFERROR(VLOOKUP(H32,'[1]Consolidado MP Planta'!$A$2:$M$823,3,0),"") -> ETIQUETA IMPRES SPOON GRANDE V-272 (UND) | C32: =+A32 -> 1 | D32: =IFERROR(VLOOKUP(H32,'[1]Consolidado MP Planta'!$A$2:$M$823,13,0),"") -> Und | E32: 52.31 | F32: =IFERROR(C32*E32,"") -> 52.31 | G32: =IFERROR(F32/$F$67,"") -> 0.0098282101 | H32: 702175
A33: 1 | B33: =IFERROR(VLOOKUP(H33,'[1]Consolidado MP Planta'!$A$2:$M$823,3,0),"") -> ETIQ.BLANCA 1 1/4 * 3/4 (UND) | C33: =+A33 -> 1 | D33: =IFERROR(VLOOKUP(H33,'[1]Consolidado MP Planta'!$A$2:$M$823,13,0),"") -> Und | E33: 0.58 | F33: =IFERROR(C33*E33,"") -> 0.58 | G33: =IFERROR(F33/$F$67,"") -> 0.0001089727 | H33: 0702069
A35: UNIDADES | B35: EMPAQUE SEMIELABORADOS | C35: UNIDADES | D35: UND MEDIDA | E35: COSTO UNITARIO | F35: TOTAL COSTO | G35: % PREC. DEFINIDO | H35: CODIGOS
A36: =+A17 -> 200 | B36: =IFERROR(VLOOKUP(H36,[1]SEMIELABORADOS!$A$2:$M$6000,2,0),"") -> BASE GALLETA P/CHEESE CAKE (KILO) | C36: =+A36 -> 200 | D36: =IFERROR(VLOOKUP(H36,[1]SEMIELABORADOS!$A$2:$M$6000,6,0),"") -> Gramo | E36: =IFERROR(VLOOKUP(H36,[1]SEMIELABORADOS!$A$2:$M$65536,10,0),"") -> 0.0016634562 | F36: =IFERROR(E36*C36,"") -> 0.33269124 | G36: =IFERROR(F36/$F$67,"") -> 6.2507349e-05 | H36: 907000002
A37: =+A18 -> 280 | B37: RELLENO PIE DE PECANAS | C37: =+A37 -> 280 | D37: Gramo | E37: =+'Costo relleno pie pecanas'!E82 -> 0.0053176 | F37: =IFERROR(E37*C37,"") -> 1.488928 | G37: =IFERROR(F37/$F$67,"") -> 0.00027974569 | H37: NUEVO
A38: =+A19 -> 700 | B38: RELLENO CHEESECAKE PREMIUM | C38: =+A38 -> 700 | D38: Gramo | E38: =+'Costo Relleno CK Premium'!E82 -> 5.8e-05 | F38: =IFERROR(E38*C38,"") -> 0.0406 | G38: =IFERROR(F38/$F$67,"") -> 7.6280889e-06 | H38: NUEVO
A39: =+A20 -> 180 | B39: TOPPING CARAMELO Y PECANA | C39: =+A39 -> 180 | D39: Gramo | E39: =+'Costo Topping caramelo pecana '!E76 -> 0.0057665794 | F39: =IFERROR(E39*C39,"") -> 1.0379843 | G39: =IFERROR(F39/$F$67,"") -> 0.0001950206
A40: =+A21 -> 0 | B40: =IFERROR(VLOOKUP(H40,[1]SEMIELABORADOS!$A$2:$M$6000,2,0),"") | C40: =+A40 -> 0 | D40: =IFERROR(VLOOKUP(H40,[1]SEMIELABORADOS!$A$2:$M$6000,6,0),"") | E40: =IFERROR(VLOOKUP(H40,[1]SEMIELABORADOS!$A$2:$M$65536,10,0),"") | F40: =IFERROR(E40*C40,"") | G40: =IFERROR(F40/$F$67,"")
A41: =+A22 -> 0 | B41: =IFERROR(VLOOKUP(H41,[1]SEMIELABORADOS!$A$2:$M$6000,2,0),"") | C41: =+A41 -> 0 | D41: =IFERROR(VLOOKUP(H41,[1]SEMIELABORADOS!$A$2:$M$6000,6,0),"") | E41: =IFERROR(VLOOKUP(H41,[1]SEMIELABORADOS!$A$2:$M$65536,10,0),"") | F41: =IFERROR(E41*C41,"") | G41: =IFERROR(F41/$F$67,"")
A42: =+A23 -> 0 | B42: =IFERROR(VLOOKUP(H42,[1]SEMIELABORADOS!$A$2:$M$6000,2,0),"") | C42: =+A42 -> 0 | D42: =IFERROR(VLOOKUP(H42,[1]SEMIELABORADOS!$A$2:$M$6000,6,0),"") | E42: =IFERROR(VLOOKUP(H42,[1]SEMIELABORADOS!$A$2:$M$65536,10,0),"") | F42: =IFERROR(E42*C42,"") | G42: =IFERROR(F42/$F$67,"")
A44: UNIDADES | B44: MODI | C44: UNIDADES | D44: UND MEDIDA | E44: COSTO UNITARIO | F44: TOTAL COSTO | G44: % PREC. DEFINIDO | H44: CODIGOS
A45: =+A36 -> 200 | B45: =IFERROR(VLOOKUP(H45,[1]SEMIELABORADOS!$A$2:$M$6000,2,0),"") -> BASE GALLETA P/CHEESE CAKE (KILO) | C45: =+A45 -> 200 | D45: =IFERROR(VLOOKUP(H45,[1]SEMIELABORADOS!$A$2:$M$6000,6,0),"") -> Gramo | E45: =IFERROR(VLOOKUP(H45,[1]SEMIELABORADOS!$A$2:$M$65536,12,0),"") -> 0.46147167 | F45: =IFERROR(E45*C45,"") -> 92.294334 | G45: =IFERROR(F45/$F$67,"") -> 0.017340625 | H45: 907000002
...

Sheet Ensamble Local
C1: SERVICIOS DE PASTELERIA S.A. | H1: CÓDIGO:
C2: ESPECIFICACION DE RECETA | H2: REVISIÓN:
C3: Cheesecake Pie de Pecanas | H3: FECHA DE APROBACIÓN:
C4: Elaborado | D4: Javier Tong, Chef
C5: Aprobado | D5: Esteban Cartin, Gte Manufactura
A7: AREA QUE PRODUCE: | D7: Postre | G7: AREA QUE EMPACA: | I7: Postre
A8: # Código | B8: # Codigo Netsuite | C8: Descripción del ingrediente | D8: Marca | E8: Unidad Internacional | G8: Medida alternativa | I8: Costo - Referencia
E9: Cantidad | F9: Unidad medida | G9: Cantidad | H9: Unidad medida | I9: Colones
A10: 907000002 | B10: SE00041 | C10: BASE GALLETA P/CHEESE CAKE (KILO) | D10: FAS | E10: 300 | F10: g | G10: Base y borde
C11: RELLENO PIE DE PECANAS | D11: FAS | E11: 300 | F11: g
A12: MP10562 | B12: 11900028 | C12: Pecana Entera | D12: Nueces Industriales | E12: 50 | F12: g
C13: RELLENO CHEESECAKE Y MANJAR | D13: FAS | E13: 650 | F13: g
C15: DECORACION
A16: MP10485 | B16: 0310099 | C16: Crema Dulce | D16: FAS | E16: 25 | F16: g | G16: Boquilla Wilton #61
C17: TOPPING CARAMELO Y PECANA | D17: FAS | E17: 230 | F17: g
C19: EMPAQUE
A21: 703020 | B21: EM10248 | C21: CINTA ADHESIVA TRANSPARENT 2*100 M (UND) | D21: ETIPLAST | E21: 60 | F21: cm
A22: 1950693 | B22: EM10020 | C22: ORLA CARTON 9" DORADA (UND ) | D22: RAPIBOX | E22: 1 | F22: ud
A23: 51400021 | B23: EM10021 | C23: QUEQUERA RED C/BASE ALTA 9" (CAJA:100 U) | D23: Exp PMT | E23: 1 | F23: ud
A24: 702123 | B24: EM10011 | C24: ETIQUETA BLANCA 2 5/8X1 15/16 (UND) | D24: Cemusa | E24: 1 | F24: ud
A25: 701096 | B25: EM10124 | C25: ETIQUETA BLANCA R-153 (UND) | D25: Cemusa | E25: 1 | F25: ud
A26: 702007 | B26: EM10004 | C26: ETIQ.FECHA VENCIMIENTO BLANCO (ROLLO) | D26: CEMUSA | E26: 1 | F26: ud
A27: 702069 | B27: EM10002 | C27: ETIQ.BLANCA 1 1/4 * 3/4 (UND) | D27: ETIPLAST | E27: 1 | F27: ud
D29: Cantidad | E29: Unidad
A30: PESO TOTAL OBTENIDO | D30: 1555 | E30: g
A31: TIEMPO TOTAL DE PREPARACION | D31: 5 | E31: min
A32: CANTIDAD DE PORCIONES OBTENIDAS | D32: 1 | E32: ud
A33: PESO DE CADA PORCIÓN | D33: =+D30 -> 1555 | E33: g
A34: MERMA | D34: =SUM(E10:E17)-D30 -> 0 | E34: g
A35: PROCEDIMIENTO DE PREPARACION DE LA RECETA
A36: 1.- Colocar dentro del molde desarmable redondo 21 cm ,previamente ensagrasado la base de galleta presionar y hornear a 175°C por 7 min en el Argental, a 175°C por 8 min en el Dicte 1 y Dicte 2, a 170°C en el Dicte 3 y a 175°C por 7 min en el Marshal
A37: 2.- Una vez fria la galleta, agregar el relleno de pecanas y las pecanas sobre el relleno de pecanas. Hornear por 30 min aprox. Enfriar
A38: 3.- Agregar la el relleno de cheesecake y manjar, emparejar con ayuda de una espatula. Enfriar por 6 horas como minimo.
A39: 4.- Desmoldar con ayuda de una espatula, Pegar a la orla con manjar, decorar con colocho de crema de manjar en el borde y topping de caramelo y pecanas en el centro.
A40: 5.- Tapar y etiquetar
A45: Control de cambios

Sheet Ensamble local 2
C1: SERVICIOS DE PASTELERIA S.A. | H1: CÓDIGO:
C2: ESPECIFICACION DE RECETA | H2: REVISIÓN:
C3: Cheesecake Pie de Pecanas | H3: FECHA DE APROBACIÓN:
C4: Elaborado | D4: Javier Tong, Chef
C5: Aprobado | D5: Esteban Cartin, Gte Manufactura
A7: AREA QUE PRODUCE: | D7: Postre | G7: AREA QUE EMPACA: | I7: Postre
A8: # Código | B8: # Codigo Netsuite | C8: Descripción del ingrediente | D8: Marca | E8: Unidad Internacional | G8: Medida alternativa | I8: Costo - Referencia
E9: Cantidad | F9: Unidad medida | G9: Cantidad | H9: Unidad medida | I9: Colones
A10: 907000002 | B10: SE00041 | C10: BASE GALLETA P/CHEESE CAKE (KILO) | D10: FAS | E10: 200 | F10: g | G10: Base y borde
C11: RELLENO PIE DE PECANAS | D11: FAS | E11: 280 | F11: g
B12: MP10562 | C12: Pecana Entera | D12: FAS | E12: 40 | F12: g
C13: RELLENO CHEESECAKE PREMIUM | D13: FAS | E13: 700 | F13: g
C15: DECORACION
B16: SE00032 | C16: Crema Dulce Leche | D16: FAS | E16: 25 | F16: g | G16: Boquilla Wilton #61
C17: TOPPING CARAMELO Y PECANA | D17: FAS | E17: 180 | F17: g
C19: EMPAQUE
A20: 702175 | B20: EM10006 | C20: ETIQUETA IMPRES SPOON GRANDE V-272 (UND) | D20: ETIPLAST | E20: 1 | F20: ud
A21: 703020 | B21: EM10248 | C21: CINTA ADHESIVA TRANSPARENT 2*100 M (UND) | D21: ETIPLAST | E21: 60 | F21: cm
A22: 1950693 | B22: EM10020 | C22: ORLA CARTON 9" DORADA (UND ) | D22: RAPIBOX | E22: 1 | F22: ud
A23: 51400021 | B23: EM10021 | C23: QUEQUERA RED C/BASE ALTA 9" (CAJA:100 U) | D23: Exp PMT | E23: 1 | F23: ud
A24: 702123 | B24: EM10011 | C24: ETIQUETA BLANCA 2 5/8X1 15/16 (UND) | D24: Cemusa | E24: 1 | F24: ud
A25: 701096 | B25: EM10124 | C25: ETIQUETA BLANCA R-153 (UND) | D25: Cemusa | E25: 1 | F25: ud
A26: 702007 | B26: EM10004 | C26: ETIQ.FECHA VENCIMIENTO BLANCO (ROLLO) | D26: CEMUSA | E26: 1 | F26: ud
A27: 702069 | B27: EM10002 | C27: ETIQ.BLANCA 1 1/4 * 3/4 (UND) | D27: ETIPLAST | E27: 1 | F27: ud
D29: Cantidad | E29: Unidad
A30: PESO TOTAL OBTENIDO | D30: 1420 | E30: g
A31: TIEMPO TOTAL DE PREPARACION | D31: 5 | E31: min
A32: CANTIDAD DE PORCIONES OBTENIDAS | D32: 1 | E32: ud
A33: PESO DE CADA PORCIÓN | D33: 1420 | E33: g
A34: MERMA | D34: 5 | E34: g
A35: PROCEDIMIENTO DE PREPARACION DE LA RECETA
A36: 1.- Colocar dentro del molde desarmable redondo 21 cm ,previamente ensagrasado la base de galleta presionar, despues colocar agregar el relleno de pecanas y hornear a 325°F por 25 minutos.
A37: 2.- Una vez fria la base, se agregar la el relleno de cheesecake premium, emparejar con ayuda de una espatula. Enfriar por 6 horas como minimo.
A38: 3.- Desmoldar con ayuda de una espatula, Pegar a la orla con manjar, decorar con colocho de crema de manjar en el borde y topping de caramelo y pecanas en el centro.
A39: 4.- Tapar y etiquetar
A44: Control de cambios

Sheet Ensamble Local 3
C1: SERVICIOS DE PASTELERIA S.A. | H1: CÓDIGO:
C2: ESPECIFICACION DE RECETA | H2: REVISIÓN:
C3: Cheesecake Pie de Pecanas Local | H3: FECHA DE APROBACIÓN:
C4: Elaborado | D4: Javier Tong, Chef
C5: Aprobado | D5: Esteban Cartin, Gte Manufactura
A7: AREA QUE PRODUCE: | D7: Postre | G7: AREA QUE EMPACA: | I7: Postre
A8: # Código | B8: # Codigo Netsuite | C8: Descripción del ingrediente | D8: Marca | E8: Unidad Internacional | G8: Medida alternativa | I8: Costo - Referencia
E9: Cantidad | F9: Unidad medida | G9: Cantidad | H9: Unidad medida | I9: Colones
A10: 907000002 | B10: SE00041 | C10: BASE GALLETA P/CHEESE CAKE (KILO) | D10: FAS | E10: 300 | F10: g | G10: Base y borde
C11: RELLENO PIE DE PECANAS | D11: FAS | E11: 280 | F11: g | K11: 1560
B12: MP10562 | C12: PECANA ENTERA | D12: FAS | E12: 40 | F12: g
C13: RELLENO CHEESECAKE PREMIUM | D13: FAS | E13: 700 | F13: g
C15: DECORACION
B16: SE00032 | C16: CREMA DULCE DE LECHE | D16: FAS | E16: 60 | F16: g | G16: Boquilla Wilton #61
C17: TOPPING CARAMELO Y PECANA | D17: FAS | E17: 180 | F17: g
C19: EMPAQUE
B20: NUEVO | C20: ETIQUETA ESPECIAL DIA DE LA MADRE | E20: 1 | F20: ud
A21: 703020 | B21: EM10248 | C21: CINTA ADHESIVA TRANSPARENT 2*100 M (UND) | D21: ETIPLAST | E21: 60 | F21: cm
A22: 1950693 | B22: EM10020 | C22: ORLA CARTON 9" DORADA (UND ) | D22: RAPIBOX | E22: 1 | F22: ud
A23: 51400021 | B23: EM10021 | C23: QUEQUERA RED C/BASE ALTA 9" (CAJA:100 U) | D23: Exp PMT | E23: 1 | F23: ud
A24: 702123 | B24: EM10011 | C24: ETIQUETA BLANCA 2 5/8X1 15/16 (UND) | D24: Cemusa | E24: 1 | F24: ud
A25: 701096 | B25: EM10124 | C25: ETIQUETA BLANCA R-153 (UND) | D25: Cemusa | E25: 1 | F25: ud
A26: 702007 | B26: EM10004 | C26: ETIQ.FECHA VENCIMIENTO BLANCO (ROLLO) | D26: CEMUSA | E26: 1 | F26: ud
A27: 702069 | B27: EM10002 | C27: ETIQ.BLANCA 1 1/4 * 3/4 (UND) | D27: ETIPLAST | E27: 1 | F27: ud
B28: EM10018 | C28: Papel Mantequilla | E28: 0.25 | F28: ud | G28: 1/4 de papel
D30: Cantidad | E30: Unidad
A31: PESO TOTAL OBTENIDO | D31: 1533 | E31: g
A32: TIEMPO TOTAL DE PREPARACION | D32: 5 | E32: min
A33: CANTIDAD DE PORCIONES OBTENIDAS | D33: 1 | E33: ud
A34: PESO DE CADA PORCIÓN | D34: 1533 | E34: g
A35: MERMA | D35: 27 | E35: g
A36: PROCEDIMIENTO DE PREPARACION DE LA RECETA
A37: 1.- Colocar dentro del molde desarmable redondo 21 cm ,previamente ensagrasado, poner 1/4 de papel mantequilla en la base del molde (dejando el sobrante hacia abajo del molde) colocar la galleta y presionar hacia los bordes y en la base, hornear a 175°C por 7 min en el Argental, a 175°C por 8 min en el Dicte 1 y Dicte 2, a 170°C en el Dicte 3 y a 175°C por 7 min en el Marshal
A38: 2.- Una vez fria la galleta, agregar el relleno de pecanas. Hornear por 20 min aprox. Enfriar
A39: 3.- Agregar la el relleno de cheesecake premium, emparejar con ayuda de una espatula. Enfriar por 6 horas como minimo.
A40: 4.- Desmoldar con ayuda de una espatula, Pegar a la orla con manjar, decorar con colocho de crema dulce en el borde y el topping de caramelo y pecanas en el centro.
A41: 5.- Tapar y etiquetar
A46: Control de cambios

Sheet Ensamble Local 4
C1: SERVICIOS DE PASTELERIA S.A. | H1: CÓDIGO:
C2: ESPECIFICACION DE RECETA | H2: REVISIÓN:
C3: Cheesecake Pie de Pecanas Industria | H3: FECHA DE APROBACIÓN:
C4: Elaborado | D4: Javier Tong, Chef
C5: Aprobado | D5: Esteban Cartin, Gte Manufactura
A7: AREA QUE PRODUCE: | D7: Postre | G7: AREA QUE EMPACA: | I7: Postre
A8: # Código | B8: # Codigo Netsuite | C8: Descripción del ingrediente | D8: Marca | E8: Unidad Internacional | G8: Medida alternativa | I8: Costo - Referencia
E9: Cantidad | F9: Unidad medida | G9: Cantidad | H9: Unidad medida | I9: Colones
A10: 907000002 | B10: SE00041 | C10: BASE GALLETA P/CHEESE CAKE (KILO) | D10: FAS | E10: 280 | F10: g | G10: Base y borde
C11: RELLENO PIE DE PECANAS | D11: FAS | E11: 280 | F11: g | K11: 1525
B12: MP10562 | C12: PECANA ENTERA | D12: FAS | E12: 35 | F12: g
C13: RELLENO CHEESECAKE PREMIUM | D13: FAS | E13: 700 | F13: g
C15: DECORACION
B16: SE00032 | C16: CREMA DULCE DE LECHE | D16: FAS | E16: 50 | F16: g | G16: Boquilla Wilton #61
C17: TOPPING CARAMELO Y PECANA | D17: FAS | E17: 180 | F17: g
B18: MP10007 | C18: Manjar Leche Condensada | D18: NESTLE | E18: 10 | F18: g
C20: EMPAQUE
B21: NUEVO | C21: ETIQUETA ESPECIAL DIA DE LA MADRE | E21: 1 | F21: ud
A22: 703020 | B22: EM10248 | C22: CINTA ADHESIVA TRANSPARENT 2*100 M (UND) | D22: ETIPLAST | E22: 60 | F22: cm
A23: 1950693 | B23: EM10020 | C23: ORLA CARTON 9" DORADA (UND ) | D23: RAPIBOX | E23: 1 | F23: ud
A24: 51400021 | B24: EM10021 | C24: QUEQUERA RED C/BASE ALTA 9" (CAJA:100 U) | D24: Exp PMT | E24: 1 | F24: ud
A25: 702123 | B25: EM10011 | C25: ETIQUETA BLANCA 2 5/8X1 15/16 (UND) | D25: Cemusa | E25: 1 | F25: ud
A26: 701096 | B26: EM10124 | C26: ETIQUETA BLANCA R-153 (UND) | D26: Cemusa | E26: 1 | F26: ud
A27: 702007 | B27: EM10004 | C27: ETIQ.FECHA VENCIMIENTO BLANCO (ROLLO) | D27: CEMUSA | E27: 1 | F27: ud
A28: 702069 | B28: EM10002 | C28: ETIQ.BLANCA 1 1/4 * 3/4 (UND) | D28: ETIPLAST | E28: 1 | F28: ud
B29: EM10018 | C29: Papel Mantequilla | E29: 0.25 | F29: ud | G29: 1/4 de papel
D31: Cantidad | E31: Unidad
A32: PESO TOTAL OBTENIDO | D32: 1533 | E32: g
A33: TIEMPO TOTAL DE PREPARACION | D33: 5 | E33: min
A34: CANTIDAD DE PORCIONES OBTENIDAS | D34: 1 | E34: ud
A35: PESO DE CADA PORCIÓN | D35: 1533 | E35: g
A36: MERMA | D36: 2 | E36: g
A37: PROCEDIMIENTO DE PREPARACION DE LA RECETA
A38: 1.- Colocar dentro del molde desarmable redondo 21 cm ,previamente ensagrasado, poner 1/4 de papel mantequilla en la base del molde (dejando el sobrante hacia abajo del molde) colocar la galleta y presionar hacia los bordes y en la base, hornear a 175°C por 7 min en el Argental, a 175°C por 8 min en el Dicte 1 y Dicte 2, a 170°C en el Dicte 3 y a 175°C por 7 min en el Marshal
A39: 2.- Una vez fria la galleta, agregar el relleno de pecanas. Hornear por 20 min aprox. Enfriar
A40: 3.- Agregar la el relleno de cheesecake premium, emparejar con ayuda de una espatula. Enfriar por 6 horas como minimo.
A41: 4.- Desmoldar con ayuda de una espatula, Pegar a la orla con manjar, decorar con colocho de crema de dulce en el borde y el topping de caramelo y pecanas en el centro.
A42: 5.- Tapar y etiquetar
A47: Control de cambios

Sheet Base de Galleta Cheese cake 
C1: SERVICIOS DE PASTELERIA S.A. | H1: CÓDIGO: | I1: ESP-RE-POS-031
C2: ESPECIFICACION DE RECETA | H2: REVISIÓN: | I2: 15
C3: Base Galleta Cheesecake SE00041 | H3: FECHA DE APROBACIÓN: | I3: 45546
C4: Elaborado | D4: Javier Tong, Chef
C5: Aprobado | D5: Esteban Cartin, Gte Manufactura
A6: AREA QUE PRODUCE: | D6: Postres | G6: AREA QUE EMPACA: | I6: Postres
A7: # Código | B7: # Codigo Netsuite | C7: Descripción del ingrediente | D7: Marca | E7: Unidad Internacional | G7: Medida Costos | I7: Costo - Referencia
E8: Cantidad | F8: Unidad medida | G8: Cantidad | H8: Unidad medida | I8: Colones
A9: 10100344 | B9: MP10523 | C9: GALLETA SODA MOLIDA (PAQ:1 KILO) | D9: POZUELO | E9: 2500 | F9: g
A10: 10100345 | B10: MP10555 | C10: GALLETA YEMITA (KILO) | D10: POZUELO | E10: 1500 | F10: g
A11: 906000002 | B11: SE00204 | C11: Corte Galleta Chilena Grande | D11: FAS | E11: 1000 | F11: g | G11: RECORTE DE CHILENA
A12: 0310107 | B12: MP10022 | C12: LACTOCREMA GRANEL (CAJA:25 KG) | D12: DOS PINOS | E12: 3000 | F12: g
A13: 101000073 | B13: MP10041 | C13: AZUCAR GLASS MOLIDA (PAQ: 4 K) | E13: 1400 | F13: g
A14: 1212410 | B14: MP10008 | C14: PRESERVANTE 1047S (PAQ=5 KILO) | E14: 10 | F14: g
D17: Cantidad | E17: Unidad
A18: PESO TOTAL OBTENIDO | D18: 9000 | E18: g | F18: TIEMPO DE HORNEO
A19: TIEMPO TOTAL DE PREPARACION | D19: 15 | E19: min | F19: HORNO
A20: CANTIDAD DE PORCIONES OBTENIDAS | D20: =D18/D21 -> 1 | E20: Tanda | F20: TEMPERATURA HORNEO | H20: =15/9 -> 1.6666667
A21: PESO DE CADA PORCIÓN | D21: 9000 | E21: g | F21: OTROS
A22: MERMA | D22: =SUM(E9:E15)-D18 -> 410 | E22: g
A23: PROCEDIMIENTO DE PREPARACION DE LA RECETA
A24: 1.- Derretir la lactocrema. No hervir.
A25: 2.- Mezclar todos los ingredientes en un bowl con el azucar en polvo.
A26: 2, Mezclar la galletas procesada con el azucar y la lactocrema, en batidora con paleta, hasta homogeneo.
A28: CONTROL DE CAMBIOS
A30: Revisión #9: Actualización de codigos
A31: Revisión #10: Actualizacion de peso final, y productos de reproceso.
A32: Revisión #11: Actualizacion completa por cambio de galletas y rendimiento.
A33: Revision #12: Actualizacion del peso de la lactocrema y el rendimiento.
A34: Revision #13: Se elimina galleta Maria y se agrega recorte de galleta chilena Spoon
A35: Revision #14: Se le bajo Lactocrema
A36: Revisión# 15:Se le aumenta la cantidad de lactocrema a la receta

Sheet Costo ensamble local
E1: Precio Local | F1: Costo MP | G1: Costo EM | H1: Costo MO
E2: =IFERROR(O63,"") -> 5901.5793 | F2: =IFERROR(H54,"") -> 4340.7685 | G2: =IFERROR(H55,"") -> 509.8502 | H2: =IFERROR(H57,"") -> 573.92889
A5: ESTRUCTURA DE COSTOS
F6: Fecha: | H6: =TODAY() -> 45831
A7: UNIDADES | B7: DESCRIPCION MAT.PRIMA | C7: UNIDADES | D7: UND MEDIDA | E7: COSTO UNITARIO | F7: TOTAL COSTO | G7: % PREC. DEFINIDO | H7: CODIGOS
A8: 50 | B8: Crema Dulce | C8: =+A8 -> 50 | D8: Gramo | E8: 2.27 | F8: =IFERROR(C8*E8,"") -> 113.5 | G8: =IFERROR(F8/$F$67,"") -> 0.02132483 | H8: 310099 | M8: 156 | N8: 60 | O8: =+M8-N8 -> 96
A9: 35 | B9: Pecana Entera | C9: =+A9 -> 35 | D9: Gramo | E9: 8.47 | F9: =IFERROR(C9*E9,"") -> 296.45 | G9: =IFERROR(F9/$F$67,"") -> 0.055698201 | H9: 11900028 | M9: 750 | N9: 500
A10: 10 | B10: Manjar de leche condensada | C10: =+A10 -> 10 | D10: Gramo | E10: 2.56 | F10: =IFERROR(C10*E10,"") -> 25.6 | G10: =IFERROR(F10/$F$67,"") -> 0.0048098295
B11: =IFERROR(VLOOKUP(H11,'[1]Consolidado MP Planta'!$A$2:$M$823,3,0),"") | C11: =+A11 -> 0 | D11: =IFERROR(VLOOKUP(H11,'[1]Consolidado MP Planta'!$A$2:$M$823,13,0),"") | E11: =IFERROR(VLOOKUP(H11,'[1]Consolidado MP Planta'!$A$2:$M$823,12,0),"") | F11: =IFERROR(C11*E11,"") | G11: =IFERROR(F11/$F$67,"")
B12: =IFERROR(VLOOKUP(H12,'[1]Consolidado MP Planta'!$A$2:$M$823,3,0),"") | C12: =+A12 -> 0 | D12: =IFERROR(VLOOKUP(H12,'[1]Consolidado MP Planta'!$A$2:$M$823,13,0),"") | E12: =IFERROR(VLOOKUP(H12,'[1]Consolidado MP Planta'!$A$2:$M$823,12,0),"") | F12: =IFERROR(C12*E12,"") | G12: =IFERROR(F12/$F$67,"")
B13: =IFERROR(VLOOKUP(H13,'[1]Consolidado MP Planta'!$A$2:$M$823,3,0),"") | C13: =+A13 -> 0 | D13: =IFERROR(VLOOKUP(H13,'[1]Consolidado MP Planta'!$A$2:$M$823,13,0),"") | E13: =IFERROR(VLOOKUP(H13,'[1]Consolidado MP Planta'!$A$2:$M$823,12,0),"") | F13: =IFERROR(C13*E13,"") | G13: =IFERROR(F13/$F$67,"")
B14: =IFERROR(VLOOKUP(H14,'[1]Consolidado MP Planta'!$A$2:$M$823,3,0),"") | C14: =+A14 -> 0 | D14: =IFERROR(VLOOKUP(H14,'[1]Consolidado MP Planta'!$A$2:$M$823,13,0),"") | E14: =IFERROR(VLOOKUP(H14,'[1]Consolidado MP Planta'!$A$2:$M$823,12,0),"") | F14: =IFERROR(C14*E14,"") | G14: =IFERROR(F14/$F$67,"")
B15: =IFERROR(VLOOKUP(H15,'[2]ARTICULOS MP PLANTA'!$A$2:$G$589,2,0),"")
A16: UNIDADES | B16: MATERIA PRIMA SEMIELABORADOS | C16: UNIDADES | D16: UND MEDIDA | E16: COSTO UNITARIO | F16: TOTAL COSTO | G16: % PREC. DEFINIDO | H16: CODIGOS | O16: =96+250 -> 346
A17: 200 | B17: =IFERROR(VLOOKUP(H17,[1]SEMIELABORADOS!$A$2:$M$6000,2,0),"") -> BASE GALLETA P/CHEESE CAKE (KILO) | C17: =+A17 -> 200 | D17: =IFERROR(VLOOKUP(H17,[1]SEMIELABORADOS!$A$2:$M$6000,6,0),"") -> Gramo | E17: 2.5 | F17: =IFERROR(E17*C17,"") -> 500 | G17: =IFERROR(F17/$F$67,"") -> 0.093941982 | H17: 907000002
A18: 280 | B18: RELLENO PIE DE PECANAS | C18: =+A18 -> 280 | D18: Gramo | E18: =+'Costo Relleno CK Premium'!E75 -> 2.638085 | F18: =IFERROR(E18*C18,"") -> 738.6638 | G18: =IFERROR(F18/$F$67,"") -> 0.13878308 | H18: NUEVO
A19: 700 | B19: RELLENO CHEESECAKE PREMIUM | C19: =+A19 -> 700 | D19: Gramo | E19: =+'Costo relleno CK y Manjar '!E75 -> 2.5338071 | F19: =IFERROR(E19*C19,"") -> 1773.665 | G19: =IFERROR(F19/$F$67,"") -> 0.3332432 | H19: NUEVO
A20: 180 | B20: TOPPING CARAMELO Y PECANA | C20: =+A20 -> 180 | D20: Gramo | E20: =+'Costo Topping caramelo pecana '!E69 -> 4.9604983 | F20: =IFERROR(E20*C20,"") -> 892.88969 | G20: =IFERROR(F20/$F$67,"") -> 0.16775965
B21: =IFERROR(VLOOKUP(H21,[1]SEMIELABORADOS!$A$2:$M$6000,2,0),"") | C21: =+A21 -> 0 | D21: =IFERROR(VLOOKUP(H21,[1]SEMIELABORADOS!$A$2:$M$6000,6,0),"") | E21: =IFERROR(VLOOKUP(H21,[1]SEMIELABORADOS!$A$2:$H$65536,8,0),"") | F21: =IFERROR(E21*C21,"") | G21: =IFERROR(F21/$F$67,"")
B22: =IFERROR(VLOOKUP(H22,[1]SEMIELABORADOS!$A$2:$M$6000,2,0),"") | C22: =+A22 -> 0 | D22: =IFERROR(VLOOKUP(H22,[1]SEMIELABORADOS!$A$2:$M$6000,6,0),"") | E22: =IFERROR(VLOOKUP(H22,[1]SEMIELABORADOS!$A$2:$H$65536,8,0),"") | F22: =IFERROR(E22*C22,"") | G22: =IFERROR(F22/$F$67,"")
B23: =IFERROR(VLOOKUP(H23,[1]SEMIELABORADOS!$A$2:$M$6000,2,0),"") | C23: =+A23 -> 0 | D23: =IFERROR(VLOOKUP(H23,[1]SEMIELABORADOS!$A$2:$M$6000,6,0),"") | E23: =IFERROR(VLOOKUP(H23,[1]SEMIELABORADOS!$A$2:$H$65536,8,0),"") | F23: =IFERROR(E23*C23,"") | G23: =IFERROR(F23/$F$67,"")
B24: =IFERROR(VLOOKUP(H24,[1]SEMIELABORADOS!$A$2:$M$6000,2,0),"") | C24: =+A24 -> 0 | D24: =IFERROR(VLOOKUP(H24,[1]SEMIELABORADOS!$A$2:$M$6000,6,0),"") | E24: =IFERROR(VLOOKUP(H24,[1]SEMIELABORADOS!$A$2:$H$65536,8,0),"") | F24: =IFERROR(E24*C24,"") | G24: =IFERROR(F24/$F$67,"")
A26: UNIDADES | B26: EMPAQUE | C26: UNIDADES | D26: UND MEDIDA | E26: COSTO UNITARIO | F26: TOTAL COSTO | G26: % PREC. DEFINIDO | H26: CODIGOS
A27: 1 | B27: =IFERROR(VLOOKUP(H27,'[1]Consolidado MP Planta'!$A$2:$M$823,3,0),"") -> ORLA #9 DORADA (UND) | C27: =+A27 -> 1 | D27: =IFERROR(VLOOKUP(H27,'[1]Consolidado MP Planta'!$A$2:$M$823,13,0),"") -> Und | E27: 111 | F27: =IFERROR(C27*E27,"") -> 111 | G27: =IFERROR(F27/$F$67,"") -> 0.02085512 | H27: 1950693
A28: 1 | B28: =IFERROR(VLOOKUP(H28,'[1]Consolidado MP Planta'!$A$2:$M$823,3,0),"") -> QUEQUERA RED C/BASE ALTA 9" (CAJA:100 U) | C28: =+A28 -> 1 | D28: =IFERROR(VLOOKUP(H28,'[1]Consolidado MP Planta'!$A$2:$M$823,13,0),"") -> Und | E28: 340.21 | F28: =IFERROR(C28*E28,"") -> 340.21 | G28: =IFERROR(F28/$F$67,"") -> 0.063920003 | H28: 51400021
A29: 1 | B29: =IFERROR(VLOOKUP(H29,'[1]Consolidado MP Planta'!$A$2:$M$823,3,0),"") -> ETIQUETA BLANCA 2 5/8X1 15/16 (UND) | C29: =+A29 -> 1 | D29: =IFERROR(VLOOKUP(H29,'[1]Consolidado MP Planta'!$A$2:$M$823,13,0),"") -> Und | E29: 2.13 | F29: =IFERROR(C29*E29,"") -> 2.13 | G29: =IFERROR(F29/$F$67,"") -> 0.00040019284 | H29: 0702123
A30: 1 | B30: =IFERROR(VLOOKUP(H30,'[1]Consolidado MP Planta'!$A$2:$M$823,3,0),"") -> ETIQUETA BLANCA R-153 (UND) | C30: =+A30 -> 1 | D30: =IFERROR(VLOOKUP(H30,'[1]Consolidado MP Planta'!$A$2:$M$823,13,0),"") -> Und | E30: 0.39 | F30: =IFERROR(C30*E30,"") -> 0.39 | G30: =IFERROR(F30/$F$67,"") -> 7.3274746e-05 | H30: 701096
A31: 1 | B31: =IFERROR(VLOOKUP(H31,'[1]Consolidado MP Planta'!$A$2:$M$823,3,0),"") -> ETIQ.FECHA VENCIMIENTO BLANCO (ROLLO) | C31: =+A31 -> 1 | D31: =IFERROR(VLOOKUP(H31,'[1]Consolidado MP Planta'!$A$2:$M$823,13,0),"") -> Gramos | E31: 0.33 | F31: =IFERROR(C31*E31,"") -> 0.33 | G31: =IFERROR(F31/$F$67,"") -> 6.2001708e-05 | H31: 0702007
A32: 1 | B32: =IFERROR(VLOOKUP(H32,'[1]Consolidado MP Planta'!$A$2:$M$823,3,0),"") -> ETIQUETA IMPRES SPOON GRANDE V-272 (UND) | C32: =+A32 -> 1 | D32: =IFERROR(VLOOKUP(H32,'[1]Consolidado MP Planta'!$A$2:$M$823,13,0),"") -> Und | E32: 52.31 | F32: =IFERROR(C32*E32,"") -> 52.31 | G32: =IFERROR(F32/$F$67,"") -> 0.0098282101 | H32: 702175
A33: 1 | B33: =IFERROR(VLOOKUP(H33,'[1]Consolidado MP Planta'!$A$2:$M$823,3,0),"") -> ETIQ.BLANCA 1 1/4 * 3/4 (UND) | C33: =+A33 -> 1 | D33: =IFERROR(VLOOKUP(H33,'[1]Consolidado MP Planta'!$A$2:$M$823,13,0),"") -> Und | E33: 0.58 | F33: =IFERROR(C33*E33,"") -> 0.58 | G33: =IFERROR(F33/$F$67,"") -> 0.0001089727 | H33: 0702069
A35: UNIDADES | B35: EMPAQUE SEMIELABORADOS | C35: UNIDADES | D35: UND MEDIDA | E35: COSTO UNITARIO | F35: TOTAL COSTO | G35: % PREC. DEFINIDO | H35: CODIGOS
A36: =+A17 -> 200 | B36: =IFERROR(VLOOKUP(H36,[1]SEMIELABORADOS!$A$2:$M$6000,2,0),"") -> BASE GALLETA P/CHEESE CAKE (KILO) | C36: =+A36 -> 200 | D36: =IFERROR(VLOOKUP(H36,[1]SEMIELABORADOS!$A$2:$M$6000,6,0),"") -> Gramo | E36: =IFERROR(VLOOKUP(H36,[1]SEMIELABORADOS!$A$2:$M$65536,10,0),"") -> 0.0016634562 | F36: =IFERROR(E36*C36,"") -> 0.33269124 | G36: =IFERROR(F36/$F$67,"") -> 6.2507349e-05 | H36: 907000002
A37: =+A18 -> 280 | B37: RELLENO PIE DE PECANAS | C37: =+A37 -> 280 | D37: Gramo | E37: =+'Costo relleno pie pecanas'!E82 -> 0.0053176 | F37: =IFERROR(E37*C37,"") -> 1.488928 | G37: =IFERROR(F37/$F$67,"") -> 0.00027974569 | H37: NUEVO
A38: =+A19 -> 700 | B38: RELLENO CHEESECAKE PREMIUM | C38: =+A38 -> 700 | D38: Gramo | E38: =+'Costo Relleno CK Premium'!E82 -> 5.8e-05 | F38: =IFERROR(E38*C38,"") -> 0.0406 | G38: =IFERROR(F38/$F$67,"") -> 7.6280889e-06 | H38: NUEVO
A39: =+A20 -> 180 | B39: TOPPING CARAMELO Y PECANA | C39: =+A39 -> 180 | D39: Gramo | E39: =+'Costo Topping caramelo pecana '!E76 -> 0.0057665794 | F39: =IFERROR(E39*C39,"") -> 1.0379843 | G39: =IFERROR(F39/$F$67,"") -> 0.0001950206
A40: =+A21 -> 0 | B40: =IFERROR(VLOOKUP(H40,[1]SEMIELABORADOS!$A$2:$M$6000,2,0),"") | C40: =+A40 -> 0 | D40: =IFERROR(VLOOKUP(H40,[1]SEMIELABORADOS!$A$2:$M$6000,6,0),"") | E40: =IFERROR(VLOOKUP(H40,[1]SEMIELABORADOS!$A$2:$M$65536,10,0),"") | F40: =IFERROR(E40*C40,"") | G40: =IFERROR(F40/$F$67,"")
A41: =+A22 -> 0 | B41: =IFERROR(VLOOKUP(H41,[1]SEMIELABORADOS!$A$2:$M$6000,2,0),"") | C41: =+A41 -> 0 | D41: =IFERROR(VLOOKUP(H41,[1]SEMIELABORADOS!$A$2:$M$6000,6,0),"") | E41: =IFERROR(VLOOKUP(H41,[1]SEMIELABORADOS!$A$2:$M$65536,10,0),"") | F41: =IFERROR(E41*C41,"") | G41: =IFERROR(F41/$F$67,"")
A42: =+A23 -> 0 | B42: =IFERROR(VLOOKUP(H42,[1]SEMIELABORADOS!$A$2:$M$6000,2,0),"") | C42: =+A42 -> 0 | D42: =IFERROR(VLOOKUP(H42,[1]SEMIELABORADOS!$A$2:$M$6000,6,0),"") | E42: =IFERROR(VLOOKUP(H42,[1]SEMIELABORADOS!$A$2:$M$65536,10,0),"") | F42: =IFERROR(E42*C42,"") | G42: =IFERROR(F42/$F$67,"")
A44: UNIDADES | B44: MODI | C44: UNIDADES | D44: UND MEDIDA | E44: COSTO UNITARIO | F44: TOTAL COSTO | G44: % PREC. DEFINIDO | H44: CODIGOS
A45: =+A36 -> 200 | B45: =IFERROR(VLOOKUP(H45,[1]SEMIELABORADOS!$A$2:$M$6000,2,0),"") -> BASE GALLETA P/CHEESE CAKE (KILO) | C45: =+A45 -> 200 | D45: =IFERROR(VLOOKUP(H45,[1]SEMIELABORADOS!$A$2:$M$6000,6,0),"") -> Gramo | E45: =IFERROR(VLOOKUP(H45,[1]SEMIELABORADOS!$A$2:$M$65536,12,0),"") -> 0.46147167 | F45: =IFERROR(E45*C45,"") -> 92.294334 | G45: =IFERROR(F45/$F$67,"") -> 0.017340625 | H45: 907000002
...

Sheet Corte Galleta Chilena 
C1: SERVICIOS DE PASTELERIA S.A. | H1: CÓDIGO: | I1: ESP-RE-PAPS-002
C2: ESPECIFICACION DE RECETA | H2: REVISIÓN: | I2: 01
C3: Corte Galleta Chilena Grande 143g 906000002(SE00204) | H3: FECHA DE APROBACIÓN: | I3: 45611
C4: Elaborado | D4: Javier Tong, Chef
C5: Aprobado | D5: Esteban Cartin, Gte Manufactura
A6: AREA QUE PRODUCE: | D6: Pastas | G6: AREA QUE EMPACA: | I6: Pastas
A7: # Código | B7: # Código Netsuite | C7: Descripción del ingrediente | D7: Marca | E7: Unidad Internacional | G7: Medida alternativa | I7: Costo - Referencia
E8: Cantidad | F8: Unidad medida | G8: Cantidad | H8: Unidad medida | I8: Colones
C9: Ensamble
A10: 906000035 | B10: SE00177 | C10: PASTA TORTA CHILENA SPOON KILO | D10: FAS | E10: 1001 | F10: g
A11: 90100137 | B11: SE00183 | C11: EMPAQUE HARINA ESTANDAR (KILO) | D11: FAS | E11: 20 | F11: g
C18: Decoración
C24: Empaque
D35: Cantidad | E35: Unidad
A36: PESO TOTAL OBTENIDO | D36: 1001 | E36: g | F36: Tiempo de Horneo:
A37: TIEMPO TOTAL DE PREPARACION | D37: 2 | E37: min | F37: Horno:
A38: CANTIDAD DE PORCIONES OBTENIDAS | D38: 7 | E38: Galletas | F38: Temperatura de Horneo:
A39: PESO DE CADA PORCIÓN | D39: 143 | E39: g | F39: Otros
A40: MERMA | D40: 0 | E40: g
A41: PROCEDIMIENTO DE PREPARACION DE LA RECETA
A42: 1-. Laminar la masa hasta 4 mm con ayuda e la maquina, hacer huecos con el zorro. En la laminadora Rondo a 2.8, en la laminadora Kemplex 3.
A43: 2-. Cortar con cortador redondo de 23 cm diametro y colocar los 7 circulos en la bandeja
A44: 3-. Llevar al horno en Dicte 1 por 23 min a 170°C o Dicte 2 por 22 a 24 min a 170°C.
A45: 4-. Enfriar.
A51: CONTROL DE CAMBIOS

Sheet Pasta Torta Chilena 
C1: SERVICIOS DE PASTELERIA S.A. | H1: CÓDIGO: | I1: ESP-RE-PAPS-011
C2: ESPECIFICACION DE RECETA | H2: REVISIÓN: | I2: 01
C3: PASTA TORTA CHILENA SPOON KILO SE00177 | H3: FECHA DE APROBACIÓN: | I3: 45611
C4: Elaborado | D4: Javier Tong, Chef
C5: Aprobado | D5: Esteban Cartin, Gte Manufactura
A6: AREA QUE PRODUCE: | D6: Pastas | G6: AREA QUE EMPACA: | I6: Pastas
A7: # Código | B7: # Código Netsuite | C7: Descripción del ingrediente | D7: Marca | E7: Unidad Internacional | G7: Medida alternativa | I7: Costo - Referencia
E8: Cantidad | F8: Unidad medida | G8: Cantidad | H8: Unidad medida | I8: Colones
C9: Ensamble
A10: 901000014 | B10: SE00178 | C10: PREMEZCLA P/PASTA CHILENA SPOON | D10: Spoon | E10: 23524 | F10: g
C16: Decoración
C22: Empaque
D33: Cantidad | E33: Unidad
A34: PESO TOTAL OBTENIDO | D34: 23300 | E34: g | F34: Tiempo de Horneo: | H34: 60 min
A35: TIEMPO TOTAL DE PREPARACION | D35: 8 | E35: min | F35: Horno: | H35: Dicte 1,2,3
A36: CANTIDAD DE PORCIONES OBTENIDAS | D36: 1 | E36: Tanda | F36: Temperatura de Horneo: | H36: 185 C
A37: PESO DE CADA PORCIÓN | D37: 23300 | E37: g | F37: Otros
A38: MERMA | D38: 224 | E38: g
A39: PROCEDIMIENTO DE PREPARACION DE LA RECETA
A40: 1.- Colocar la margarina, azucar y harina y preservante. Batir en velocidad 1 por 3 minutos, con ayuda de la paleta.
A41: 2.- Utilizar de inmediato.
A49: CONTROL DE CAMBIOS

Sheet Premezcla pasta Chilena 
C1: SERVICIOS DE PASTELERIA S.A. | H1: CÓDIGO: | I1: ESP-RE-PRES-008
C2: ESPECIFICACION DE RECETA | H2: REVISIÓN: | I2: 01
C3: PREMEZCLA P/PASTA CHILENA SPOON 901000014(SE00178) | H3: FECHA DE APROBACIÓN: | I3: 45616
C4: Elaborado | D4: Javier Tong, Chef
C5: Aprobado | D5: Esteban Cartin, Gte Manufactura
A6: AREA QUE PRODUCE: | D6: Premezclas | G6: AREA QUE EMPACA: | I6: Premezclas
A7: # Código | B7: # Código Netsuite | C7: Descripción del ingrediente | D7: Marca | E7: Unidad Internacional | G7: Medida alternativa | I7: Costo - Referencia
E8: Cantidad | F8: Unidad medida | G8: Cantidad | H8: Unidad medida | I8: Colones
C9: Ensamble
B10: MP10040 | C10: MARGARINA BAKER TABLETA (CAJA: 25 K) | D10: NUMAR | E10: 9000 | F10: g
B11: MP10049 | C11: AZUCAR POLVO P.REAL (PAQ:2.5 Kg) | D11: PASTELERO REAL | E11: 1 | F11: Bolsa
B12: MP10051 | C12: HARINA TRIGO NACARINA (SACO: 25 K) | D12: NACARINA | E12: 12000 | F12: g
B13: MP10008 | C13: PRESERVANTE 1047S (PAQ=5 KILO) | D13: ASEAL | E13: 24 | F13: g
C18: Decoración
C25: Empaque
B26: EM10011 | C26: ETIQUETA BLANCA 2 5/8X1 15/16 (UND) | D26: ETIPLAST | E26: 2 | F26: ud
B27: EM10013 | C27: BOLSA 17x25 TRANSP | D27: PLASTICOS P | E27: 2 | F27: ud
B28: EM10133 | C28: ETIQUETA ROJA LETRA ALERJENO (UND) | D28: ETIPLAST | E28: 1 | F28: ud
B29: AS00020 | C29: GUANTE LATEX CORRIENTE (CAJA:100 UND) | D29: MAYCA | E29: 2 | F29: ud
D38: Cantidad | E38: Unidad
A39: PESO TOTAL OBTENIDO | D39: 23524 | E39: g | F39: Tiempo de Horneo:
A40: TIEMPO TOTAL DE PREPARACION | D40: 0.14583333 | E40: Minutos | F40: Horno:
A41: CANTIDAD DE PORCIONES OBTENIDAS | D41: 1 | E41: Tanda | F41: Temperatura de Horneo:
A42: PESO DE CADA PORCIÓN | D42: 23524 | E42: g | F42: Otros
A43: MERMA | D43: 0 | E43: g
A44: PROCEDIMIENTO DE PREPARACION DE LA RECETA
A45: 1.- Colocar en 1 bolsa 17*25 la margarina. Etiquetar con nombre y alerjeno
A46: 2.- Colocar la harina, preservante en otra bolsa 17*25, enviar 1 bolsa de azucar en polvo entera.
A47: 3.- Etiquetar ambas bolsas con nombre y alerjeno.
A53: CONTROL DE CAMBIOS

Sheet Crema Dulce Leche
C1: SERVICIOS DE PASTELERIA S.A. | H1: CÓDIGO: | I1: ESP-RE-DES-020
C2: ESPECIFICACION DE RECETA | H2: REVISIÓN: | I2: 02
C3: Crema de Dulce de Leche(24500g) SE00032 | H3: FECHA DE APROBACIÓN: | I3: 45613
C4: Elaborado | D4: Javier Tong, Chef
C5: Aprobado | D5: Esteban Cartin, Gte Manufactura
A6: AREA QUE PRODUCE: | D6: Decoración | G6: AREA QUE EMPACA: | I6: Decoracion
A7: # Código | B7: # Código Netsuite | C7: Descripción del ingrediente | D7: Marca | E7: Unidad Internacional | G7: Medida alternativa | I7: Costo - Referencia
E8: Cantidad | F8: Unidad medida | G8: Cantidad | H8: Unidad medida | I8: Colones
C9: Ensamble
A10: 11400029 | B10: MP10165 | C10: CREMA BETTER DULCE LECHE RICH (UND:4 K) | D10: RICHS | E10: 16000 | F10: g | H10: 4 GALON
A11: 11400031 | B11: MP10048 | C11: CREMA PRESTIGE GRAND (UND:4 K) | D11: RICHS | E11: 8000 | F11: g | H11: 2 GALON
A12: 10415 | C12: AGUA POTABLE (PLANTA) | D12: FAS | E12: 1000 | F12: g
A13: 1212410 | B13: MP10008 | C13: PRESERVANTE 1047S (PAQ=5 KILO) | D13: ASEAL | E13: 22 | F13: g
C20: Decoración
C29: Empaque
A30: 702123 | B30: EM10011 | C30: ETIQUETA BLANCA 2 5/8X1 15/16 (UND) | E30: 1 | F30: ud
D40: Cantidad | E40: Unidad
A41: PESO TOTAL OBTENIDO | D41: 24500 | E41: g | F41: Tiempo de Horneo:
A42: TIEMPO TOTAL DE PREPARACION | D42: 21 | E42: min | F42: Horno:
A43: CANTIDAD DE PORCIONES OBTENIDAS | D43: 1 | E43: ud | F43: Temperatura de Horneo:
A44: PESO DE CADA PORCIÓN | D44: 24500 | E44: g | F44: Otros
A45: MERMA | D45: 500 | E45: g
A46: PROCEDIMIENTO DE PREPARACION DE LA RECETA
A47: 1.- Colocar en la top cream, la crema de dulce de leche y la prestige y el agua con el preservante. (Cumpliendo un temperatura de 5° liquida)
A48: 2.- Batir por 21 minutos.
A49: 3,- Una vez lista a una temperatura de 18° batida, retirar, etiquetar y guardar hasta que sean usadas.
A57: 2, Actualización tiempo de preparación y procedimiento

Sheet Topping caramelo pecana
C1: SERVICIOS DE PASTELERIA S.A. | H1: CÓDIGO:
C2: ESPECIFICACION DE RECETA | H2: REVISIÓN:
C3: Topping de caramelo y pecanas | H3: FECHA DE APROBACIÓN:
C4: Elaborado | D4: Javier Tong, Chef
C5: Aprobado | D5: Esteban Cartin, Gte Manufactura
A7: AREA QUE PRODUCE: | D7: Postre | G7: AREA QUE EMPACA: | I7: Postre
A8: # Código | B8: # Codigo Netsuite | C8: Descripción del ingrediente | D8: Marca | E8: Unidad Internacional | G8: Medida alternativa | I8: Costo - Referencia
E9: Cantidad | F9: Unidad medida | G9: Cantidad | H9: Unidad medida | I9: Colones
C10: SALSA DE CARAMELO PARA PECANAS | D10: FAS | E10: 4400 | F10: g
A11: MP10089 | B11: 410118 | C11: Brillo Glit | D11: GLIT | E11: 3000 | F11: g | K11: =SUM(E10:E12) -> 10400
C12: PECANA TOSTADA | D12: FAS | E12: 3000 | F12: g
D18: Cantidad | E18: Unidad
A19: PESO TOTAL OBTENIDO | D19: 10400 | E19: g
A20: TIEMPO TOTAL DE PREPARACION | D20: 5 | E20: min
A21: CANTIDAD DE PORCIONES OBTENIDAS | D21: 1 | E21: ud
A22: PESO DE CADA PORCIÓN | D22: =+D19 -> 10400 | E22: g
A23: MERMA | D23: =SUM(E10:E14)-D19 -> 0 | E23: g
A24: PROCEDIMIENTO DE PREPARACION DE LA RECETA
A25: 1.- Mezclar todos los ingredientes con ayuda de una paleta hasta homogenea en velocidad 1.
A34: Control de cambios

Sheet Costo Topping caramelo pecana 
E1: Precio Local | F1: Costo MP | G1: Costo EM | H1: Costo MO
E2: =IFERROR(O62,"") -> 51298.061 | F2: =IFERROR(H53,"") -> 49604.983 | G2: =IFERROR(H54,"") -> 57.665794 | H2: =IFERROR(H56,"") -> 893.09746
A5: ESTRUCTURA DE COSTOS
F6: Fecha: | H6: =TODAY() -> 45831
A7: UNIDADES | B7: DESCRIPCION MAT.PRIMA | C7: UNIDADES | D7: UND MEDIDA | E7: COSTO UNITARIO | F7: TOTAL COSTO | G7: % PREC. DEFINIDO | H7: CODIGOS
A8: 3200 | B8: =IFERROR(VLOOKUP(H8,'[1]Consolidado MP Planta'!$A$2:$M$823,3,0),"") -> BRILLO GLIT (UND:5 KILOS) | C8: =+A8 -> 3200 | D8: =IFERROR(VLOOKUP(H8,'[1]Consolidado MP Planta'!$A$2:$M$823,13,0),"") -> 0 | E8: 4.59 | F8: =IFERROR(C8*E8,"") -> 14688 | G8: =IFERROR(F8/$F$66,"") -> 0.28777571 | H8: 410118
B9: =IFERROR(VLOOKUP(H9,'[1]Consolidado MP Planta'!$A$2:$M$823,3,0),"") | C9: =+A9 -> 0 | D9: =IFERROR(VLOOKUP(H9,'[1]Consolidado MP Planta'!$A$2:$M$823,13,0),"") | E9: =IFERROR(VLOOKUP(H9,'[1]Consolidado MP Planta'!$A$2:$M$823,12,0),"") | F9: =IFERROR(C9*E9,"") | G9: =IFERROR(F9/$F$66,"")
B10: =IFERROR(VLOOKUP(H10,'[1]Consolidado MP Planta'!$A$2:$M$823,3,0),"") | C10: =+A10 -> 0 | D10: =IFERROR(VLOOKUP(H10,'[1]Consolidado MP Planta'!$A$2:$M$823,13,0),"") | E10: =IFERROR(VLOOKUP(H10,'[1]Consolidado MP Planta'!$A$2:$M$823,12,0),"") | F10: =IFERROR(C10*E10,"") | G10: =IFERROR(F10/$F$66,"")
B11: =IFERROR(VLOOKUP(H11,'[1]Consolidado MP Planta'!$A$2:$M$823,3,0),"") | C11: =+A11 -> 0 | D11: =IFERROR(VLOOKUP(H11,'[1]Consolidado MP Planta'!$A$2:$M$823,13,0),"") | E11: =IFERROR(VLOOKUP(H11,'[1]Consolidado MP Planta'!$A$2:$M$823,12,0),"") | F11: =IFERROR(C11*E11,"") | G11: =IFERROR(F11/$F$66,"")
B12: =IFERROR(VLOOKUP(H12,'[1]Consolidado MP Planta'!$A$2:$M$823,3,0),"") | C12: =+A12 -> 0 | D12: =IFERROR(VLOOKUP(H12,'[1]Consolidado MP Planta'!$A$2:$M$823,13,0),"") | E12: =IFERROR(VLOOKUP(H12,'[1]Consolidado MP Planta'!$A$2:$M$823,12,0),"") | F12: =IFERROR(C12*E12,"") | G12: =IFERROR(F12/$F$66,"")
B13: =IFERROR(VLOOKUP(H13,'[1]Consolidado MP Planta'!$A$2:$M$823,3,0),"") | C13: =+A13 -> 0 | D13: =IFERROR(VLOOKUP(H13,'[1]Consolidado MP Planta'!$A$2:$M$823,13,0),"") | E13: =IFERROR(VLOOKUP(H13,'[1]Consolidado MP Planta'!$A$2:$M$823,12,0),"") | F13: =IFERROR(C13*E13,"") | G13: =IFERROR(F13/$F$66,"")
B14: =IFERROR(VLOOKUP(H14,'[1]Consolidado MP Planta'!$A$2:$M$823,3,0),"") | C14: =+A14 -> 0 | D14: =IFERROR(VLOOKUP(H14,'[1]Consolidado MP Planta'!$A$2:$M$823,13,0),"") | E14: =IFERROR(VLOOKUP(H14,'[1]Consolidado MP Planta'!$A$2:$M$823,12,0),"") | F14: =IFERROR(C14*E14,"") | G14: =IFERROR(F14/$F$66,"")
B15: =IFERROR(VLOOKUP(H15,'[2]ARTICULOS MP PLANTA'!$A$2:$G$589,2,0),"")
A16: UNIDADES | B16: MATERIA PRIMA SEMIELABORADOS | C16: UNIDADES | D16: UND MEDIDA | E16: COSTO UNITARIO | F16: TOTAL COSTO | G16: % PREC. DEFINIDO | H16: CODIGOS
A17: 4000 | B17: SALSA DE CARAMELO PARA PECANAS | C17: =+A17 -> 4000 | D17: Gramos | E17: =+'Costo Salsa Caramelo'!E69 -> 2.2471028 | F17: =IFERROR(E17*C17,"") -> 8988.4112 | G17: =IFERROR(F17/$F$66,"") -> 0.1761061 | H17: NUEVO
A18: 3000 | B18: PECANA TOSTADA | C18: =+A18 -> 3000 | D18: Gramos | E18: =+'Costo Pecana Tostada'!E69 -> 8.6428571 | F18: =IFERROR(E18*C18,"") -> 25928.571 | G18: =IFERROR(F18/$F$66,"") -> 0.50800743 | H18: NUEVO
B19: =IFERROR(VLOOKUP(H19,[1]SEMIELABORADOS!$A$2:$M$6000,2,0),"") | C19: =+A19 -> 0 | D19: =IFERROR(VLOOKUP(H19,[1]SEMIELABORADOS!$A$2:$M$6000,6,0),"") | E19: =IFERROR(VLOOKUP(H19,[1]SEMIELABORADOS!$A$2:$H$65536,8,0),"") | F19: =IFERROR(E19*C19,"") | G19: =IFERROR(F19/$F$66,"")
B20: =IFERROR(VLOOKUP(H20,[1]SEMIELABORADOS!$A$2:$M$6000,2,0),"") | C20: =+A20 -> 0 | D20: =IFERROR(VLOOKUP(H20,[1]SEMIELABORADOS!$A$2:$M$6000,6,0),"") | E20: =IFERROR(VLOOKUP(H20,[1]SEMIELABORADOS!$A$2:$H$65536,8,0),"") | F20: =IFERROR(E20*C20,"") | G20: =IFERROR(F20/$F$66,"")
B21: =IFERROR(VLOOKUP(H21,[1]SEMIELABORADOS!$A$2:$M$6000,2,0),"") | C21: =+A21 -> 0 | D21: =IFERROR(VLOOKUP(H21,[1]SEMIELABORADOS!$A$2:$M$6000,6,0),"") | E21: =IFERROR(VLOOKUP(H21,[1]SEMIELABORADOS!$A$2:$H$65536,8,0),"") | F21: =IFERROR(E21*C21,"") | G21: =IFERROR(F21/$F$66,"")
B22: =IFERROR(VLOOKUP(H22,[1]SEMIELABORADOS!$A$2:$M$6000,2,0),"") | C22: =+A22 -> 0 | D22: =IFERROR(VLOOKUP(H22,[1]SEMIELABORADOS!$A$2:$M$6000,6,0),"") | E22: =IFERROR(VLOOKUP(H22,[1]SEMIELABORADOS!$A$2:$H$65536,8,0),"") | F22: =IFERROR(E22*C22,"") | G22: =IFERROR(F22/$F$66,"")
B23: =IFERROR(VLOOKUP(H23,[1]SEMIELABORADOS!$A$2:$M$6000,2,0),"") | C23: =+A23 -> 0 | D23: =IFERROR(VLOOKUP(H23,[1]SEMIELABORADOS!$A$2:$M$6000,6,0),"") | E23: =IFERROR(VLOOKUP(H23,[1]SEMIELABORADOS!$A$2:$H$65536,8,0),"") | F23: =IFERROR(E23*C23,"") | G23: =IFERROR(F23/$F$66,"")
B24: =IFERROR(VLOOKUP(H24,[1]SEMIELABORADOS!$A$2:$M$6000,2,0),"") | C24: =+A24 -> 0 | D24: =IFERROR(VLOOKUP(H24,[1]SEMIELABORADOS!$A$2:$M$6000,6,0),"") | E24: =IFERROR(VLOOKUP(H24,[1]SEMIELABORADOS!$A$2:$H$65536,8,0),"") | F24: =IFERROR(E24*C24,"") | G24: =IFERROR(F24/$F$66,"")
A26: UNIDADES | B26: EMPAQUE | C26: UNIDADES | D26: UND MEDIDA | E26: COSTO UNITARIO | F26: TOTAL COSTO | G26: % PREC. DEFINIDO | H26: CODIGOS
A27: 0 | B27: =IFERROR(VLOOKUP(H27,'[1]Consolidado MP Planta'!$A$2:$M$823,3,0),"") | C27: =+A27 -> 0 | D27: =IFERROR(VLOOKUP(H27,'[1]Consolidado MP Planta'!$A$2:$M$823,13,0),"") | E27: =IFERROR(VLOOKUP(H27,'[1]Consolidado MP Planta'!$A$2:$M$823,12,0),"") | F27: =IFERROR(C27*E27,"") | G27: =IFERROR(F27/$F$66,"")
B28: =IFERROR(VLOOKUP(H28,'[1]Consolidado MP Planta'!$A$2:$M$823,3,0),"") | C28: =+A28 -> 0 | D28: =IFERROR(VLOOKUP(H28,'[1]Consolidado MP Planta'!$A$2:$M$823,13,0),"") | E28: =IFERROR(VLOOKUP(H28,'[1]Consolidado MP Planta'!$A$2:$M$823,12,0),"") | F28: =IFERROR(C28*E28,"") | G28: =IFERROR(F28/$F$66,"")
