Workbook

Sheet Enmsable LOCALES
C1: SERVICIOS DE PASTELERIA S.A. | H1: CÓDIGO:
C2: ESPECIFICACION DE RECETA | H2: REVISIÓN:
C3: Postre de chocolate Cadbury LOCALES | H3: m
C4: Elaborado | D4: Jose Brizuela Lopez , chef
C5: Aprobado | D5: Esteban Cartin, Gte Manufactura
A7: AREA QUE PRODUCE: | D7: Postres | G7: AREA QUE EMPACA: | I7: Postres
A8: # Código | B8: # Codigo Netsuite | C8: Descripción del ingrediente | D8: Marca | G8: Medida alternativa | I8: Costo - Referencia
E9: Cantidad | F9: Unidad medida | G9: Cantidad | H9: Unidad medida | I9: Colones
C10: Emsamble
A11: 907000268 | B11: SE00345 | C11: Rosquete Chocolate 400 grs Spoon | D11: FAS | E11: 168 | F11: g
C12: DISCO MOUSSE CHOCOLATE | D12: FAS | E12: 440 | F12: g | G12: 1 | H12: UNIDAD
C13: Semillas de Cadbury | D13: FAS | E13: 80 | F13: g | H13: 1/4 Taza
C14: Mousse de pastelera | D14: FAS | E14: 400 | F14: g
C16: Decoracion
A17: 20100163 | B17: SE00337 | C17: Empaque Fudge De Chocolate | D17: FAS | E17: 50 | F17: g | G17: COLOCHO BOQUILLA 103
C18: Fudge Liquido | D18: FAS | E18: 70 | F18: g | J18: No hay receta
A19: 1210398 | B19: MP10384 | C19: Trozos Chocolate Oscuro | D19: FAS | E19: 35 | F19: g | G19: 6 ud
C20: Cuadros de Cadbury | D20: FAS | E20: 50 | F20: g | G20: 1/2 barra (6 pares)
C22: EMPAQUE
A23: 11400066 | B23: MP10007 | C23: Manjar Leche Condensada | E23: 10 | F23: g
A24: 51400021 | B24: EM10021 | C24: Quequera Red C/Base Alta 9" | D24: FAS | E24: 1 | F24: ud
A25: 1950693 | B25: EM10020 | C25: Orla #9 Dorada | D25: FAS | E25: 1 | F25: ud
A26: 0702069 | B26: EM10002 | C26: Etiq.Blanca 1 1/4 * 3/4 | E26: 1 | F26: ud
A27: 701096 | B27: EM10124 | C27: ETIQUETA BLANCA R-153 (UND) | D27: Cemusa | E27: 1 | F27: ud
A28: 702123 | B28: EM10011 | C28: ETIQUETA BLANCA 2 5/8X1 15/16 (UND) | D28: Etiplast | E28: 1 | F28: ud
D33: Cantidad | E33: Unidad
A34: PESO TOTAL OBTENIDO | D34: 1120 | E34: g | F34: Tiempo de Horneo:
A35: TIEMPO TOTAL DE PREPARACION | D35: 5 | E35: min | F35: Horno:
A36: CANTIDAD DE PORCIONES OBTENIDAS | D36: 1 | E36: ud | F36: Temperatura de Horneo:
A37: PESO DE CADA PORCIÓN | D37: =D34 -> 1120 | E37: g | F37: Otros
A38: MERMA | D38: =SUM(E11:E20)-D34 -> 173 | E38: g
A39: PROCEDIMIENTO DE PREPARACION DE LA RECETA
A40: 1, Agregar medio Rosquete de Chocolate Dawn de 400 g en un molde 22 cm Desmoldable.
A41: 2, Agregar las semillas toceadas, Agregar el disco de mousse de chocolate y colocarla en el Centro del Rosquete Grande
A42: 3, Agregar la mousse de crema pastelera dejar que corte al menos por 6 horas en refrigeraicon y dezmoldar y pegar con manjar a la orla.
A43: 4, Decorar con la Boquilla # 103 a los Borde con el Fudge Cholate Fas, Agregar el Fudge Liquido en el centro y Agregar los Trozos de Chocolate intercalando con los pares de chocolate cadbury
A44: 5, Tapar y etiquetar
A45: CONTROL DE CAMBIOS

Sheet Ensamble locales 2
C1: SERVICIOS DE PASTELERIA S.A. | H1: CÓDIGO:
C2: ESPECIFICACION DE RECETA | H2: REVISIÓN:
C3: Postre de chocolate Cadbury y arandanos rojos LOCALES | H3: m
C4: Elaborado | D4: Jose Brizuela Lopez , chef
C5: Aprobado | D5: Esteban Cartin, Gte Manufactura
A7: AREA QUE PRODUCE: | D7: Postres | G7: AREA QUE EMPACA: | I7: Postres
A8: # Código | B8: # Codigo Netsuite | C8: Descripción del ingrediente | D8: Marca | G8: Medida alternativa | I8: Costo - Referencia
E9: Cantidad | F9: Unidad medida | G9: Cantidad | H9: Unidad medida | I9: Colones
C10: Emsamble
A11: 907000268 | B11: SE00345 | C11: Rosquete Chocolate 400 grs Spoon | D11: FAS | E11: 168 | F11: g
C12: DISCO MOUSSE CHOCOLATE | D12: FAS | E12: 440 | F12: g | G12: 1 | H12: UNIDAD
C13: Semillas de Cadbury | D13: FAS | E13: 80 | F13: g | H13: 1/4 Taza
C14: Mousse de pastelera | D14: FAS | E14: 400 | F14: g
C16: Decoracion
A17: 20100163 | B17: SE00337 | C17: Empaque Fudge De Chocolate | D17: FAS | E17: 50 | F17: g | G17: COLOCHO BOQUILLA 103
C18: Fudge Liquido | D18: FAS | E18: 70 | F18: g
C19: Empaque Relleno Arandanos Rojos | D19: FAS | E19: 80 | F19: g | G19: Espejo en el centro
A20: 1210398 | B20: MP10384 | C20: Trozos Chocolate Oscuro | D20: FAS | E20: 35 | F20: g | G20: 6 ud
C21: Cuadros de Cadbury | D21: FAS | E21: 50 | F21: g | G21: 1/2 barra (6 pares)
C23: EMPAQUE
A24: 11400066 | B24: MP10007 | C24: Manjar Leche Condensada | E24: 10 | F24: g
A25: 51400021 | B25: EM10021 | C25: Quequera Red C/Base Alta 9" | D25: FAS | E25: 1 | F25: ud
A26: 1950693 | B26: EM10020 | C26: Orla #9 Dorada | D26: FAS | E26: 1 | F26: ud
A27: 0702069 | B27: EM10002 | C27: Etiq.Blanca 1 1/4 * 3/4 | E27: 1 | F27: ud
A28: 701096 | B28: EM10124 | C28: ETIQUETA BLANCA R-153 (UND) | D28: Cemusa | E28: 1 | F28: ud
A29: 702123 | B29: EM10011 | C29: ETIQUETA BLANCA 2 5/8X1 15/16 (UND) | D29: Etiplast | E29: 1 | F29: ud
D34: Cantidad | E34: Unidad
A35: PESO TOTAL OBTENIDO | D35: 1120 | E35: g | F35: Tiempo de Horneo:
A36: TIEMPO TOTAL DE PREPARACION | D36: 5 | E36: min | F36: Horno:
A37: CANTIDAD DE PORCIONES OBTENIDAS | D37: 1 | E37: ud | F37: Temperatura de Horneo:
A38: PESO DE CADA PORCIÓN | D38: 1120 | E38: g | F38: Otros
A39: MERMA | D39: 253 | E39: g
A40: PROCEDIMIENTO DE PREPARACION DE LA RECETA
A41: 1, Agregar medio Rosquete de Chocolate Dawn de 400 g en un molde 22 cm Desmoldable.
A42: 2, Agregar las semillas toceadas, Agregar el disco de mousse de chocolate y colocarla en el Centro del Rosquete Grande
A43: 3, Agregar la mousse de crema pastelera dejar que corte al menos por 6 horas en refrigeraicon y dezmoldar y pegar con manjar a la orla.
A44: 4, Decorar con la Boquilla # 103 a los Borde con el Fudge Cholate Fas, Agregar relleno de arandanos en el centro y hace run espejo, Agregar el Fudge Liquido en el borde y Agregar los Trozos de Chocolate intercalando con los pares de chocolate cadbury
A45: 5, Tapar y etiquetar
A46: CONTROL DE CAMBIOS

Sheet Ensamble 3
C1: SERVICIOS DE PASTELERIA S.A. | H1: CÓDIGO:
C2: ESPECIFICACION DE RECETA | H2: REVISIÓN:
C3: Postre de chocolate Cadbury y arandanos rojos LOCALES | H3: m
C4: Elaborado | D4: Jose Brizuela Lopez , chef
C5: Aprobado | D5: Esteban Cartin, Gte Manufactura
A7: AREA QUE PRODUCE: | D7: Postres | G7: AREA QUE EMPACA: | I7: Postres
A8: # Código | B8: # Codigo Netsuite | C8: Descripción del ingrediente | D8: Marca | G8: Medida alternativa | I8: Costo - Referencia
E9: Cantidad | F9: Unidad medida | G9: Cantidad | H9: Unidad medida | I9: Colones
C10: Emsamble
A11: 907000268 | B11: SE00345 | C11: Rosquete Chocolate 400 grs Spoon | D11: FAS | E11: 168 | F11: g
C12: DISCO MOUSSE CHOCOLATE | D12: FAS | E12: 340 | F12: g | G12: 1 | H12: UNIDAD
C13: Semillas de Cadbury | D13: FAS | E13: 50 | F13: g
C14: Mousse de pastelera | D14: FAS | E14: 350 | F14: g
C16: Decoracion
A17: 20100163 | B17: SE00337 | C17: Empaque Fudge De Chocolate | D17: FAS | E17: 50 | F17: g | G17: COLOCHO BOQUILLA 103
C18: Fudge Liquido | D18: FAS | E18: 50 | F18: g
C19: Empaque Relleno Arandanos Rojos | D19: FAS | E19: 60 | F19: g | G19: Espejo en el centro
C20: Cuadros de Cadbury | D20: FAS | E20: 25 | F20: g | G20: 1/4 barra (3 pares)
C22: EMPAQUE
A23: 11400066 | B23: MP10007 | C23: Manjar Leche Condensada | E23: 10 | F23: g
A24: 51400021 | B24: EM10021 | C24: Quequera Red C/Base Alta 9" | D24: FAS | E24: 1 | F24: ud
A25: 1950693 | B25: EM10020 | C25: Orla #9 Dorada | D25: FAS | E25: 1 | F25: ud
A26: 0702069 | B26: EM10002 | C26: Etiq.Blanca 1 1/4 * 3/4 | E26: 1 | F26: ud
A27: 701096 | B27: EM10124 | C27: ETIQUETA BLANCA R-153 (UND) | D27: Cemusa | E27: 1 | F27: ud
A28: 702123 | B28: EM10011 | C28: ETIQUETA BLANCA 2 5/8X1 15/16 (UND) | D28: Etiplast | E28: 1 | F28: ud
D33: Cantidad | E33: Unidad
A34: PESO TOTAL OBTENIDO | D34: 900 | E34: g | F34: Tiempo de Horneo:
A35: TIEMPO TOTAL DE PREPARACION | D35: 5 | E35: min | F35: Horno:
A36: CANTIDAD DE PORCIONES OBTENIDAS | D36: 1 | E36: ud | F36: Temperatura de Horneo:
A37: PESO DE CADA PORCIÓN | D37: 900 | E37: g | F37: Otros
A38: MERMA | D38: 253 | E38: g
A39: PROCEDIMIENTO DE PREPARACION DE LA RECETA
A40: 1, Agregar medio Rosquete de Chocolate Dawn de 400 g en un molde 22 cm Desmoldable.
A41: 2, Agregar las semillas toceadas, Agregar el disco de mousse de chocolate y colocarla en el Centro del Rosquete Grande
A42: 3, Agregar la mousse de crema pastelera dejar que corte al menos por 6 horas en refrigeraicon y dezmoldar y pegar con manjar a la orla.
A43: 4, Decorar con la Boquilla # 103 a los Borde con el Fudge Cholate Fas, Agregar relleno de arandanos en el centro y hace run espejo, Agregar el Fudge Liquido en el borde y Agregar los pares de chocolate cadbury
A44: 5, Tapar y etiquetar
A45: CONTROL DE CAMBIOS

Sheet Costo Ensamble locales
E1: Precio Local | F1: Costo MP | G1: Costo EM | H1: Costo MO
E2: =IFERROR(O68,"") -> 5773.4875 | F2: =IFERROR(H59,"") -> 4020.6054 | G2: =IFERROR(H60,"") -> 487.86875 | H2: =IFERROR(H62,"") -> 648.45223
A5: ESTRUCTURA DE COSTOS
F6: Fecha: | H6: =TODAY() -> 45776
A7: UNIDADES | B7: DESCRIPCION MAT.PRIMA | C7: UNIDADES | D7: UND MEDIDA | E7: COSTO UNITARIO | F7: TOTAL COSTO | G7: % PREC. DEFINIDO | H7: CODIGOS
A8: 0 | B8: Trozos Chocolate Oscuro | C8: =+A8 -> 0 | D8: =IFERROR(VLOOKUP(H8,'[1]Consolidado MP Planta'!$A$2:$M$823,13,0),"") | E8: 11.5 | F8: =IFERROR(C8*E8,"") -> 0 | G8: =IFERROR(F8/$F$72,"") -> 0 | H8: 1210398
A9: 25 | B9: Cuadros de Cadbury | C9: =+A9 -> 25 | D9: =IFERROR(VLOOKUP(H9,'[1]Consolidado MP Planta'!$A$2:$M$823,13,0),"") | E9: 10.48 | F9: =IFERROR(C9*E9,"") -> 262 | G9: =IFERROR(F9/$F$72,"") -> 0.053536185 | M9: Precio cadbury estimado mas x menos
A10: 10 | B10: Manjar Leche Condensada | C10: =+A10 -> 10 | D10: =IFERROR(VLOOKUP(H10,'[1]Consolidado MP Planta'!$A$2:$M$823,13,0),"") | E10: 2.56 | F10: =IFERROR(C10*E10,"") -> 25.6 | G10: =IFERROR(F10/$F$72,"") -> 0.0052310165 | H10: 11400066
B11: =IFERROR(VLOOKUP(H11,'[1]Consolidado MP Planta'!$A$2:$M$823,3,0),"") | C11: =+A11 -> 0 | D11: =IFERROR(VLOOKUP(H11,'[1]Consolidado MP Planta'!$A$2:$M$823,13,0),"") | E11: =IFERROR(VLOOKUP(H11,'[1]Consolidado MP Planta'!$A$2:$M$823,12,0),"") | F11: =IFERROR(C11*E11,"") | G11: =IFERROR(F11/$F$72,"")
B12: =IFERROR(VLOOKUP(H12,'[1]Consolidado MP Planta'!$A$2:$M$823,3,0),"") | C12: =+A12 -> 0 | D12: =IFERROR(VLOOKUP(H12,'[1]Consolidado MP Planta'!$A$2:$M$823,13,0),"") | E12: =IFERROR(VLOOKUP(H12,'[1]Consolidado MP Planta'!$A$2:$M$823,12,0),"") | F12: =IFERROR(C12*E12,"") | G12: =IFERROR(F12/$F$72,"")
B13: =IFERROR(VLOOKUP(H13,'[1]Consolidado MP Planta'!$A$2:$M$823,3,0),"") | C13: =+A13 -> 0 | D13: =IFERROR(VLOOKUP(H13,'[1]Consolidado MP Planta'!$A$2:$M$823,13,0),"") | E13: =IFERROR(VLOOKUP(H13,'[1]Consolidado MP Planta'!$A$2:$M$823,12,0),"") | F13: =IFERROR(C13*E13,"") | G13: =IFERROR(F13/$F$72,"")
B14: =IFERROR(VLOOKUP(H14,'[1]Consolidado MP Planta'!$A$2:$M$823,3,0),"") | C14: =+A14 -> 0 | D14: =IFERROR(VLOOKUP(H14,'[1]Consolidado MP Planta'!$A$2:$M$823,13,0),"") | E14: =IFERROR(VLOOKUP(H14,'[1]Consolidado MP Planta'!$A$2:$M$823,12,0),"") | F14: =IFERROR(C14*E14,"") | G14: =IFERROR(F14/$F$72,"")
B15: =IFERROR(VLOOKUP(H15,'[2]ARTICULOS MP PLANTA'!$A$2:$G$589,2,0),"")
A16: UNIDADES | B16: MATERIA PRIMA SEMIELABORADOS | C16: UNIDADES | D16: UND MEDIDA | E16: COSTO UNITARIO | F16: TOTAL COSTO | G16: % PREC. DEFINIDO | H16: CODIGOS
A17: 0.5 | B17: Rosquete Chocolate 400 grs Spoon | C17: =+A17 -> 0.5 | D17: und | E17: 517.65 | F17: =IFERROR(E17*C17,"") -> 258.825 | G17: =IFERROR(F17/$F$72,"") -> 0.052887416 | H17: 907000268
A18: 1 | B18: DISCO MOUSSE CHOCOLATE | C18: =+A18 -> 1 | D18: =IFERROR(VLOOKUP(H18,[1]SEMIELABORADOS!$A$2:$M$6000,6,0),"") | E18: =+'Costo disco'!H53 -> 1467.2327 | F18: =IFERROR(E18*C18,"") -> 1467.2327 | G18: =IFERROR(F18/$F$72,"") -> 0.29980931
A19: 50 | B19: Semillas de Cadbury | C19: =+A19 -> 50 | D19: =IFERROR(VLOOKUP(H19,[1]SEMIELABORADOS!$A$2:$M$6000,6,0),"") | E19: =+'costo semillas Cadbury'!E69 -> 3.9676 | F19: =IFERROR(E19*C19,"") -> 198.38 | G19: =IFERROR(F19/$F$72,"") -> 0.040536291
A20: 350 | B20: Mousse de pastelera | C20: =+A20 -> 350 | D20: =IFERROR(VLOOKUP(H20,[1]SEMIELABORADOS!$A$2:$M$6000,6,0),"") | E20: =+'Costo Mousse pastelera'!E69 -> 2.6250455 | F20: =IFERROR(E20*C20,"") -> 918.76593 | G20: =IFERROR(F20/$F$72,"") -> 0.18773749 | M20: =6*24 -> 144 | N20: =+M20*100 -> 14400 | O20: =12*24 -> 288 | P20: =+O20*42 -> 12096
A21: 50 | B21: Empaque Fudge De Chocolate | C21: =+A21 -> 50 | D21: =IFERROR(VLOOKUP(H21,[1]SEMIELABORADOS!$A$2:$M$6000,6,0),"") | E21: 2.34 | F21: =IFERROR(E21*C21,"") -> 117 | G21: =IFERROR(F21/$F$72,"") -> 0.02390738 | H21: 20100163 | N21: =150452/N20 -> 10.448056 | P21: =158763/P20 -> 13.125248
A22: 50 | B22: Fudge Liquido | C22: =+A22 -> 50 | D22: =IFERROR(VLOOKUP(H22,[1]SEMIELABORADOS!$A$2:$M$6000,6,0),"") | E22: 3.5 | F22: =IFERROR(E22*C22,"") -> 175 | G22: =IFERROR(F22/$F$72,"") -> 0.035758902
A23: 60 | B23: Empaque Relleno Arandanos Rojos | C23: =+A23 -> 60 | D23: =IFERROR(VLOOKUP(H23,[1]SEMIELABORADOS!$A$2:$M$6000,6,0),"") | E23: =+'Costo Empaque Relleno Arand'!E69 -> 6.6233641 | F23: =IFERROR(E23*C23,"") -> 397.40185 | G23: =IFERROR(F23/$F$72,"") -> 0.081203736
A24: 60 | B24: Galleta Oreo Bañada Chocolate Blanco | C24: =+A24 -> 60 | D24: =IFERROR(VLOOKUP(H24,[1]SEMIELABORADOS!$A$2:$M$6000,6,0),"") | E24: 3.34 | F24: =IFERROR(E24*C24,"") -> 200.4 | G24: =IFERROR(F24/$F$72,"") -> 0.040949051 | H24: 902000176
A26: UNIDADES | B26: EMPAQUE | C26: UNIDADES | D26: UND MEDIDA | E26: COSTO UNITARIO | F26: TOTAL COSTO | G26: % PREC. DEFINIDO | H26: CODIGOS
A27: 1 | B27: =IFERROR(VLOOKUP(H27,'[1]Consolidado MP Planta'!$A$2:$M$823,3,0),"") -> QUEQUERA RED C/BASE ALTA 9" (CAJA:100 U) | C27: =+A27 -> 1 | D27: =IFERROR(VLOOKUP(H27,'[1]Consolidado MP Planta'!$A$2:$M$823,13,0),"") -> Und | E27: 342.24 | F27: =IFERROR(C27*E27,"") -> 342.24 | G27: =IFERROR(F27/$F$72,"") -> 0.069932152 | H27: 51400021
A28: 1 | B28: =IFERROR(VLOOKUP(H28,'[1]Consolidado MP Planta'!$A$2:$M$823,3,0),"") -> ORLA #9 DORADA (UND) | C28: =+A28 -> 1 | D28: =IFERROR(VLOOKUP(H28,'[1]Consolidado MP Planta'!$A$2:$M$823,13,0),"") -> Und | E28: =IFERROR(VLOOKUP(H28,'[1]Consolidado MP Planta'!$A$2:$M$823,12,0),"") -> 135 | F28: =IFERROR(C28*E28,"") -> 135 | G28: =IFERROR(F28/$F$72,"") -> 0.027585439 | H28: 1950693
A29: 1 | B29: =IFERROR(VLOOKUP(H29,'[1]Consolidado MP Planta'!$A$2:$M$823,3,0),"") -> ETIQ.BLANCA 1 1/4 * 3/4 (UND) | C29: =+A29 -> 1 | D29: =IFERROR(VLOOKUP(H29,'[1]Consolidado MP Planta'!$A$2:$M$823,13,0),"") -> Und | E29: =IFERROR(VLOOKUP(H29,'[1]Consolidado MP Planta'!$A$2:$M$823,12,0),"") -> 0.58 | F29: =IFERROR(C29*E29,"") -> 0.58 | G29: =IFERROR(F29/$F$72,"") -> 0.00011851522 | H29: 0702069
A30: 1 | B30: =IFERROR(VLOOKUP(H30,'[1]Consolidado MP Planta'!$A$2:$M$823,3,0),"") -> ETIQUETA BLANCA R-153 (UND) | C30: =+A30 -> 1 | D30: =IFERROR(VLOOKUP(H30,'[1]Consolidado MP Planta'!$A$2:$M$823,13,0),"") -> Und | E30: =IFERROR(VLOOKUP(H30,'[1]Consolidado MP Planta'!$A$2:$M$823,12,0),"") -> 0.39 | F30: =IFERROR(C30*E30,"") -> 0.39 | G30: =IFERROR(F30/$F$72,"") -> 7.9691267e-05 | H30: 701096
A31: 1 | B31: =IFERROR(VLOOKUP(H31,'[1]Consolidado MP Planta'!$A$2:$M$823,3,0),"") -> ETIQUETA BLANCA 2 5/8X1 15/16 (UND) | C31: =+A31 -> 1 | D31: =IFERROR(VLOOKUP(H31,'[1]Consolidado MP Planta'!$A$2:$M$823,13,0),"") -> Und | E31: =IFERROR(VLOOKUP(H31,'[1]Consolidado MP Planta'!$A$2:$M$823,12,0),"") -> 2.128 | F31: =IFERROR(C31*E31,"") -> 2.128 | G31: =IFERROR(F31/$F$72,"") -> 0.00043482825 | H31: 0702123
B32: =IFERROR(VLOOKUP(H32,'[1]Consolidado MP Planta'!$A$2:$M$823,3,0),"") | C32: =+A32 -> 0 | D32: =IFERROR(VLOOKUP(H32,'[1]Consolidado MP Planta'!$A$2:$M$823,13,0),"") | E32: =IFERROR(VLOOKUP(H32,'[1]Consolidado MP Planta'!$A$2:$M$823,12,0),"") | F32: =IFERROR(C32*E32,"") | G32: =IFERROR(F32/$F$72,"")
B33: =IFERROR(VLOOKUP(H33,'[1]Consolidado MP Planta'!$A$2:$M$823,3,0),"") | C33: =+A33 -> 0 | D33: =IFERROR(VLOOKUP(H33,'[1]Consolidado MP Planta'!$A$2:$M$823,13,0),"") | E33: =IFERROR(VLOOKUP(H33,'[1]Consolidado MP Planta'!$A$2:$M$823,12,0),"") | F33: =IFERROR(C33*E33,"") | G33: =IFERROR(F33/$F$72,"")
B34: =IFERROR(VLOOKUP(H34,'[1]Consolidado MP Planta'!$A$2:$M$823,3,0),"") | C34: =+A34 -> 0 | D34: =IFERROR(VLOOKUP(H34,'[1]Consolidado MP Planta'!$A$2:$M$823,13,0),"") | E34: =IFERROR(VLOOKUP(H34,'[1]Consolidado MP Planta'!$A$2:$M$823,12,0),"") | F34: =IFERROR(C34*E34,"") | G34: =IFERROR(F34/$F$72,"")
B35: =IFERROR(VLOOKUP(H35,'[1]Consolidado MP Planta'!$A$2:$M$823,3,0),"") | C35: =+A35 -> 0 | D35: =IFERROR(VLOOKUP(H35,'[1]Consolidado MP Planta'!$A$2:$M$823,13,0),"") | E35: =IFERROR(VLOOKUP(H35,'[1]Consolidado MP Planta'!$A$2:$M$823,12,0),"") | F35: =IFERROR(C35*E35,"") | G35: =IFERROR(F35/$F$72,"")
B36: =IFERROR(VLOOKUP(H36,'[1]Consolidado MP Planta'!$A$2:$M$823,3,0),"") | C36: =+A36 -> 0 | D36: =IFERROR(VLOOKUP(H36,'[1]Consolidado MP Planta'!$A$2:$M$823,13,0),"") | E36: =IFERROR(VLOOKUP(H36,'[1]Consolidado MP Planta'!$A$2:$M$823,12,0),"") | F36: =IFERROR(C36*E36,"") | G36: =IFERROR(F36/$F$72,"")
A38: UNIDADES | B38: EMPAQUE SEMIELABORADOS | C38: UNIDADES | D38: UND MEDIDA | E38: COSTO UNITARIO | F38: TOTAL COSTO | G38: % PREC. DEFINIDO | H38: CODIGOS
A39: =+A17 -> 0.5 | B39: Rosquete Chocolate 400 grs Spoon | C39: =+A39 -> 0.5 | D39: =IFERROR(VLOOKUP(H39,[1]SEMIELABORADOS!$A$2:$M$6000,6,0),"") | E39: 5.29 | F39: =IFERROR(E39*C39,"") -> 2.645 | G39: =IFERROR(F39/$F$72,"") -> 0.00054047026 | H39: 907000268
A40: =+A18 -> 1 | B40: DISCO MOUSSE CHOCOLATE | C40: =+A40 -> 1 | D40: =IFERROR(VLOOKUP(H40,[1]SEMIELABORADOS!$A$2:$M$6000,6,0),"") | E40: =+'Costo disco'!H54 -> 2.4662564 | F40: =IFERROR(E40*C40,"") -> 2.4662564 | G40: =IFERROR(F40/$F$72,"") -> 0.00050394641
A41: =+A19 -> 50 | B41: Semillas de Cadbury | C41: =+A41 -> 50 | D41: =IFERROR(VLOOKUP(H41,[1]SEMIELABORADOS!$A$2:$M$6000,6,0),"") | E41: =+'costo semillas Cadbury'!E76 -> 0.0049747048 | F41: =IFERROR(E41*C41,"") -> 0.24873524 | G41: =IFERROR(F41/$F$72,"") -> 5.0825709e-05
A42: =+A20 -> 350 | B42: Mousse de pastelera | C42: =+A42 -> 350 | D42: =IFERROR(VLOOKUP(H42,[1]SEMIELABORADOS!$A$2:$M$6000,6,0),"") | E42: =+'Costo Mousse pastelera'!E76 -> 0 | F42: =IFERROR(E42*C42,"") -> 0 | G42: =IFERROR(F42/$F$72,"") -> 0
A43: =+A21 -> 50 | B43: Empaque Fudge De Chocolate | C43: =+A43 -> 50 | D43: =IFERROR(VLOOKUP(H43,[1]SEMIELABORADOS!$A$2:$M$6000,6,0),"") | E43: 0.01 | F43: =IFERROR(E43*C43,"") -> 0.5 | G43: =IFERROR(F43/$F$72,"") -> 0.00010216829
A44: =+A22 -> 50 | B44: Fudge Liquido | C44: =+A44 -> 50 | D44: =IFERROR(VLOOKUP(H44,[1]SEMIELABORADOS!$A$2:$M$6000,6,0),"") | E44: 0.01 | F44: =IFERROR(E44*C44,"") -> 0.5 | G44: =IFERROR(F44/$F$72,"") -> 0.00010216829
...

Sheet Emsamble IND
C1: SERVICIOS DE PASTELERIA S.A. | H1: CÓDIGO:
C2: ESPECIFICACION DE RECETA | H2: REVISIÓN:
C3: Postre de chocolate Cadbury INDUSTRIA | H3: m
C4: Elaborado | D4: Jose Brizuela Lopez , chef
C5: Aprobado | D5: Esteban Cartin, Gte Manufactura
A7: AREA QUE PRODUCE: | D7: Postres | G7: AREA QUE EMPACA: | I7: Postres
A8: # Código | B8: # Codigo Netsuite | C8: Descripción del ingrediente | D8: Marca | G8: Medida alternativa | I8: Costo - Referencia
E9: Cantidad | F9: Unidad medida | G9: Cantidad | H9: Unidad medida | I9: Colones
C10: Emsamble
A11: 907000268 | B11: SE00345 | C11: Rosquete Chocolate 400 grs Spoon | D11: FAS | E11: 168 | F11: g
C12: DISCO MOUSSE CHOCOLATE | D12: FAS | E12: 440 | F12: g | G12: 1 | H12: UNIDAD
C13: Semillas de Cadbury | D13: FAS | E13: 80 | F13: g | H13: 1/4 Taza
C14: Mousse de pastelera | D14: FAS | E14: 400 | F14: g
C16: Decoracion
A17: 20100163 | B17: SE00337 | C17: Empaque Fudge De Chocolate | D17: FAS | E17: 50 | F17: g | G17: COLOCHO BOQUILLA 103
C18: Fudge Liquido | D18: FAS | E18: 70 | F18: g
A19: 1210398 | B19: MP10384 | C19: Trozos Chocolate Oscuro | D19: FAS | E19: 35 | F19: g | G19: 6 ud
C20: Cuadros de Cadbury | D20: FAS | E20: 50 | F20: g | G20: 1/2 barra (6 pares)
C22: EMPAQUE
A23: 11400066 | B23: MP10007 | C23: Manjar Leche Condensada | E23: 10 | F23: g
A24: 51400021 | B24: EM10021 | C24: Quequera Red C/Base Alta 9" | D24: FAS | E24: 1 | F24: ud
A25: 1950693 | B25: EM10020 | C25: Orla #9 Dorada | D25: FAS | E25: 1 | F25: ud
A26: 0702069 | B26: EM10002 | C26: Etiq.Blanca 1 1/4 * 3/4 | E26: 1 | F26: ud
A27: 701096 | B27: EM10124 | C27: ETIQUETA BLANCA R-153 (UND) | D27: Cemusa | E27: 1 | F27: ud
A28: 702123 | B28: EM10011 | C28: ETIQUETA BLANCA 2 5/8X1 15/16 (UND) | D28: Etiplast | E28: 1 | F28: ud
A29: 60100120 | B29: EM10314 | C29: Etiqueta Edicion Especial | E29: 1 | F29: ud
D33: Cantidad | E33: Unidad
A34: PESO TOTAL OBTENIDO | D34: 1120 | E34: g | F34: Tiempo de Horneo:
A35: TIEMPO TOTAL DE PREPARACION | D35: 5 | E35: min | F35: Horno:
A36: CANTIDAD DE PORCIONES OBTENIDAS | D36: 1 | E36: ud | F36: Temperatura de Horneo:
A37: PESO DE CADA PORCIÓN | D37: =D34 -> 1120 | E37: g | F37: Otros
A38: MERMA | D38: =SUM(E11:E20)-D34 -> 173 | E38: g
A39: PROCEDIMIENTO DE PREPARACION DE LA RECETA
A40: 1, Agregar medio Rosquete de Chocolate Dawn de 400 g en un molde 22 cm Desmoldable.
A41: 2, Agregar las semillas toceadas, Agregar el disco de mousse de chocolate y colocarla en el Centro del Rosquete Grande
A42: 3, Agregar la mousse de crema pastelera dejar que corte al menos por 6 horas en refrigeraicon y dezmoldar y pegar con manjar a la orla.
A43: 4, Decorar con la Boquilla # 103 a los Borde con el Fudge Cholate Fas, Agregar el Fudge Liquido en el centro y Agregar los Trozos de Chocolate intercalando con los pares de chocolate cadbury
A44: 5, Tapar y etiquetar
A45: CONTROL DE CAMBIOS

Sheet Ensamble Industria 2
C1: SERVICIOS DE PASTELERIA S.A. | H1: CÓDIGO:
C2: ESPECIFICACION DE RECETA | H2: REVISIÓN:
C3: Postre de chocolate Cadbury y arandanos rojos INDUSTRIA | H3: m
C4: Elaborado | D4: Jose Brizuela Lopez , chef
C5: Aprobado | D5: Esteban Cartin, Gte Manufactura
A7: AREA QUE PRODUCE: | D7: Postres | G7: AREA QUE EMPACA: | I7: Postres
A8: # Código | B8: # Codigo Netsuite | C8: Descripción del ingrediente | D8: Marca | G8: Medida alternativa | I8: Costo - Referencia
E9: Cantidad | F9: Unidad medida | G9: Cantidad | H9: Unidad medida | I9: Colones
C10: Emsamble
A11: 907000268 | B11: SE00345 | C11: Rosquete Chocolate 400 grs Spoon | D11: FAS | E11: 168 | F11: g | G11: 0.5 | H11: Unidad
C12: DISCO MOUSSE CHOCOLATE | D12: FAS | E12: 340 | F12: g | G12: 1 | H12: UNIDAD
C13: Semillas de Cadbury | D13: FAS | E13: 50 | F13: g | H13: 1/4 Taza
C14: Mousse de pastelera | D14: FAS | E14: 350 | F14: g
C16: Decoracion
A17: 20100163 | B17: SE00337 | C17: Empaque Fudge De Chocolate | D17: FAS | E17: 50 | F17: g | G17: COLOCHO BOQUILLA 103
C18: Fudge Liquido | D18: FAS | E18: 50 | F18: g
C19: Empaque Relleno Arandanos Rojos | D19: FAS | E19: 60 | F19: g | G19: Espejo en el centro
C20: Cuadros de Cadbury | D20: FAS | E20: 25 | F20: g | G20: 1/2 barra (6 pares)
C22: EMPAQUE
A23: 11400066 | B23: MP10007 | C23: Manjar Leche Condensada | E23: 10 | F23: g
A24: 51400021 | B24: EM10021 | C24: Quequera Red C/Base Alta 9" | D24: FAS | E24: 1 | F24: ud
A25: 1950693 | B25: EM10020 | C25: Orla #9 Dorada | D25: FAS | E25: 1 | F25: ud
A26: 0702069 | B26: EM10002 | C26: Etiq.Blanca 1 1/4 * 3/4 | E26: 1 | F26: ud
A27: 701096 | B27: EM10124 | C27: ETIQUETA BLANCA R-153 (UND) | D27: Cemusa | E27: 1 | F27: ud
A28: 702123 | B28: EM10011 | C28: ETIQUETA BLANCA 2 5/8X1 15/16 (UND) | D28: Etiplast | E28: 1 | F28: ud
A29: 60100120 | B29: EM10314 | C29: Etiqueta Edicion Especial | E29: 1 | F29: ud
D33: Cantidad | E33: Unidad
A34: PESO TOTAL OBTENIDO | D34: 900 | E34: g | F34: Tiempo de Horneo:
A35: TIEMPO TOTAL DE PREPARACION | D35: 5 | E35: min | F35: Horno:
A36: CANTIDAD DE PORCIONES OBTENIDAS | D36: 1 | E36: ud | F36: Temperatura de Horneo:
A37: PESO DE CADA PORCIÓN | D37: 900 | E37: g | F37: Otros
A38: MERMA | D38: 253 | E38: g
A39: PROCEDIMIENTO DE PREPARACION DE LA RECETA
A40: 1, Agregar medio Rosquete de Chocolate Dawn de 400 g en un molde 22 cm Desmoldable.
A41: 2, Agregar las semillas toceadas, Agregar el disco de mousse de chocolate y colocarla en el Centro del Rosquete Grande
A42: 3, Agregar la mousse de crema pastelera dejar que corte al menos por 6 horas en refrigeraicon y dezmoldar y pegar con manjar a la orla.
A43: 4, Decorar con la Boquilla # 103 a los Borde con el Fudge Cholate Fas, Agregar relleno de arandanos en el centro y hace run espejo, Agregar el Fudge Liquido en el borde y Agregar los Trozos de Chocolate intercalando con los pares de chocolate cadbury
A44: 5, Tapar y etiquetar
A45: CONTROL DE CAMBIOS

Sheet Costo Ensamble Industria 
E1: Precio Local | F1: Costo MP | G1: Costo EM | H1: Costo MO
E2: =IFERROR(O68,"") -> 5883.4875 | F2: =IFERROR(H59,"") -> 4020.6054 | G2: =IFERROR(H60,"") -> 597.86875 | H2: =IFERROR(H62,"") -> 648.45223
A5: ESTRUCTURA DE COSTOS
F6: Fecha: | H6: =TODAY() -> 45776
A7: UNIDADES | B7: DESCRIPCION MAT.PRIMA | C7: UNIDADES | D7: UND MEDIDA | E7: COSTO UNITARIO | F7: TOTAL COSTO | G7: % PREC. DEFINIDO | H7: CODIGOS
A8: 0 | B8: Trozos Chocolate Oscuro | C8: =+A8 -> 0 | D8: =IFERROR(VLOOKUP(H8,'[1]Consolidado MP Planta'!$A$2:$M$823,13,0),"") | E8: 11.5 | F8: =IFERROR(C8*E8,"") -> 0 | G8: =IFERROR(F8/$F$72,"") -> 0 | H8: 1210398
A9: 25 | B9: Cuadros de Cadbury | C9: =+A9 -> 25 | D9: =IFERROR(VLOOKUP(H9,'[1]Consolidado MP Planta'!$A$2:$M$823,13,0),"") | E9: 10.48 | F9: =IFERROR(C9*E9,"") -> 262 | G9: =IFERROR(F9/$F$72,"") -> 0.052359303 | M9: Precio cadbury estimado mas x menos
A10: 10 | B10: Manjar Leche Condensada | C10: =+A10 -> 10 | D10: =IFERROR(VLOOKUP(H10,'[1]Consolidado MP Planta'!$A$2:$M$823,13,0),"") | E10: 2.56 | F10: =IFERROR(C10*E10,"") -> 25.6 | G10: =IFERROR(F10/$F$72,"") -> 0.0051160235 | H10: 11400066
B11: =IFERROR(VLOOKUP(H11,'[1]Consolidado MP Planta'!$A$2:$M$823,3,0),"") | C11: =+A11 -> 0 | D11: =IFERROR(VLOOKUP(H11,'[1]Consolidado MP Planta'!$A$2:$M$823,13,0),"") | E11: =IFERROR(VLOOKUP(H11,'[1]Consolidado MP Planta'!$A$2:$M$823,12,0),"") | F11: =IFERROR(C11*E11,"") | G11: =IFERROR(F11/$F$72,"")
B12: =IFERROR(VLOOKUP(H12,'[1]Consolidado MP Planta'!$A$2:$M$823,3,0),"") | C12: =+A12 -> 0 | D12: =IFERROR(VLOOKUP(H12,'[1]Consolidado MP Planta'!$A$2:$M$823,13,0),"") | E12: =IFERROR(VLOOKUP(H12,'[1]Consolidado MP Planta'!$A$2:$M$823,12,0),"") | F12: =IFERROR(C12*E12,"") | G12: =IFERROR(F12/$F$72,"")
B13: =IFERROR(VLOOKUP(H13,'[1]Consolidado MP Planta'!$A$2:$M$823,3,0),"") | C13: =+A13 -> 0 | D13: =IFERROR(VLOOKUP(H13,'[1]Consolidado MP Planta'!$A$2:$M$823,13,0),"") | E13: =IFERROR(VLOOKUP(H13,'[1]Consolidado MP Planta'!$A$2:$M$823,12,0),"") | F13: =IFERROR(C13*E13,"") | G13: =IFERROR(F13/$F$72,"")
B14: =IFERROR(VLOOKUP(H14,'[1]Consolidado MP Planta'!$A$2:$M$823,3,0),"") | C14: =+A14 -> 0 | D14: =IFERROR(VLOOKUP(H14,'[1]Consolidado MP Planta'!$A$2:$M$823,13,0),"") | E14: =IFERROR(VLOOKUP(H14,'[1]Consolidado MP Planta'!$A$2:$M$823,12,0),"") | F14: =IFERROR(C14*E14,"") | G14: =IFERROR(F14/$F$72,"")
B15: =IFERROR(VLOOKUP(H15,'[2]ARTICULOS MP PLANTA'!$A$2:$G$589,2,0),"")
A16: UNIDADES | B16: MATERIA PRIMA SEMIELABORADOS | C16: UNIDADES | D16: UND MEDIDA | E16: COSTO UNITARIO | F16: TOTAL COSTO | G16: % PREC. DEFINIDO | H16: CODIGOS
A17: 0.5 | B17: Rosquete Chocolate 400 grs Spoon | C17: =+A17 -> 0.5 | D17: und | E17: 517.65 | F17: =IFERROR(E17*C17,"") -> 258.825 | G17: =IFERROR(F17/$F$72,"") -> 0.051724796 | H17: 907000268
A18: 1 | B18: DISCO MOUSSE CHOCOLATE | C18: =+A18 -> 1 | D18: =IFERROR(VLOOKUP(H18,[1]SEMIELABORADOS!$A$2:$M$6000,6,0),"") | E18: =+'Costo disco'!H53 -> 1467.2327 | F18: =IFERROR(E18*C18,"") -> 1467.2327 | G18: =IFERROR(F18/$F$72,"") -> 0.29321863
A19: 50 | B19: Semillas de Cadbury | C19: =+A19 -> 50 | D19: =IFERROR(VLOOKUP(H19,[1]SEMIELABORADOS!$A$2:$M$6000,6,0),"") | E19: =+'costo semillas Cadbury'!E69 -> 3.9676 | F19: =IFERROR(E19*C19,"") -> 198.38 | G19: =IFERROR(F19/$F$72,"") -> 0.039645185
A20: 350 | B20: Mousse de pastelera | C20: =+A20 -> 350 | D20: =IFERROR(VLOOKUP(H20,[1]SEMIELABORADOS!$A$2:$M$6000,6,0),"") | E20: =+'Costo Mousse pastelera'!E69 -> 2.6250455 | F20: =IFERROR(E20*C20,"") -> 918.76593 | G20: =IFERROR(F20/$F$72,"") -> 0.18361047 | M20: =6*24 -> 144 | N20: =+M20*100 -> 14400 | O20: =12*24 -> 288 | P20: =+O20*42 -> 12096
A21: 50 | B21: Empaque Fudge De Chocolate | C21: =+A21 -> 50 | D21: =IFERROR(VLOOKUP(H21,[1]SEMIELABORADOS!$A$2:$M$6000,6,0),"") | E21: 2.34 | F21: =IFERROR(E21*C21,"") -> 117 | G21: =IFERROR(F21/$F$72,"") -> 0.023381826 | H21: 20100163 | N21: =150452/N20 -> 10.448056 | P21: =158763/P20 -> 13.125248
A22: 50 | B22: Fudge Liquido | C22: =+A22 -> 50 | D22: =IFERROR(VLOOKUP(H22,[1]SEMIELABORADOS!$A$2:$M$6000,6,0),"") | E22: 3.5 | F22: =IFERROR(E22*C22,"") -> 175 | G22: =IFERROR(F22/$F$72,"") -> 0.034972817
A23: 60 | B23: Empaque Relleno Arandanos Rojos | C23: =+A23 -> 60 | D23: =IFERROR(VLOOKUP(H23,[1]SEMIELABORADOS!$A$2:$M$6000,6,0),"") | E23: =+'Costo Empaque Relleno Arand'!E69 -> 6.6233641 | F23: =IFERROR(E23*C23,"") -> 397.40185 | G23: =IFERROR(F23/$F$72,"") -> 0.079418641
A24: 60 | B24: Galleta Oreo Bañada Chocolate Blanco | C24: =+A24 -> 60 | D24: =IFERROR(VLOOKUP(H24,[1]SEMIELABORADOS!$A$2:$M$6000,6,0),"") | E24: 3.34 | F24: =IFERROR(E24*C24,"") -> 200.4 | G24: =IFERROR(F24/$F$72,"") -> 0.040048872 | H24: 902000176
A26: UNIDADES | B26: EMPAQUE | C26: UNIDADES | D26: UND MEDIDA | E26: COSTO UNITARIO | F26: TOTAL COSTO | G26: % PREC. DEFINIDO | H26: CODIGOS
A27: 1 | B27: =IFERROR(VLOOKUP(H27,'[1]Consolidado MP Planta'!$A$2:$M$823,3,0),"") -> QUEQUERA RED C/BASE ALTA 9" (CAJA:100 U) | C27: =+A27 -> 1 | D27: =IFERROR(VLOOKUP(H27,'[1]Consolidado MP Planta'!$A$2:$M$823,13,0),"") -> Und | E27: 342.24 | F27: =IFERROR(C27*E27,"") -> 342.24 | G27: =IFERROR(F27/$F$72,"") -> 0.06839484 | H27: 51400021
A28: 1 | B28: =IFERROR(VLOOKUP(H28,'[1]Consolidado MP Planta'!$A$2:$M$823,3,0),"") -> ORLA #9 DORADA (UND) | C28: =+A28 -> 1 | D28: =IFERROR(VLOOKUP(H28,'[1]Consolidado MP Planta'!$A$2:$M$823,13,0),"") -> Und | E28: =IFERROR(VLOOKUP(H28,'[1]Consolidado MP Planta'!$A$2:$M$823,12,0),"") -> 135 | F28: =IFERROR(C28*E28,"") -> 135 | G28: =IFERROR(F28/$F$72,"") -> 0.02697903 | H28: 1950693
A29: 1 | B29: =IFERROR(VLOOKUP(H29,'[1]Consolidado MP Planta'!$A$2:$M$823,3,0),"") -> ETIQ.BLANCA 1 1/4 * 3/4 (UND) | C29: =+A29 -> 1 | D29: =IFERROR(VLOOKUP(H29,'[1]Consolidado MP Planta'!$A$2:$M$823,13,0),"") -> Und | E29: =IFERROR(VLOOKUP(H29,'[1]Consolidado MP Planta'!$A$2:$M$823,12,0),"") -> 0.58 | F29: =IFERROR(C29*E29,"") -> 0.58 | G29: =IFERROR(F29/$F$72,"") -> 0.00011590991 | H29: 0702069
A30: 1 | B30: =IFERROR(VLOOKUP(H30,'[1]Consolidado MP Planta'!$A$2:$M$823,3,0),"") -> ETIQUETA BLANCA R-153 (UND) | C30: =+A30 -> 1 | D30: =IFERROR(VLOOKUP(H30,'[1]Consolidado MP Planta'!$A$2:$M$823,13,0),"") -> Und | E30: =IFERROR(VLOOKUP(H30,'[1]Consolidado MP Planta'!$A$2:$M$823,12,0),"") -> 0.39 | F30: =IFERROR(C30*E30,"") -> 0.39 | G30: =IFERROR(F30/$F$72,"") -> 7.7939421e-05 | H30: 701096
A31: 1 | B31: =IFERROR(VLOOKUP(H31,'[1]Consolidado MP Planta'!$A$2:$M$823,3,0),"") -> ETIQUETA BLANCA 2 5/8X1 15/16 (UND) | C31: =+A31 -> 1 | D31: =IFERROR(VLOOKUP(H31,'[1]Consolidado MP Planta'!$A$2:$M$823,13,0),"") -> Und | E31: =IFERROR(VLOOKUP(H31,'[1]Consolidado MP Planta'!$A$2:$M$823,12,0),"") -> 2.128 | F31: =IFERROR(C31*E31,"") -> 2.128 | G31: =IFERROR(F31/$F$72,"") -> 0.00042526946 | H31: 0702123
A32: 1 | B32: Etiqueta Edicion Especial | C32: =+A32 -> 1 | D32: Und | E32: 110 | F32: =IFERROR(C32*E32,"") -> 110 | G32: =IFERROR(F32/$F$72,"") -> 0.021982914 | H32: 60100120
B33: =IFERROR(VLOOKUP(H33,'[1]Consolidado MP Planta'!$A$2:$M$823,3,0),"") | C33: =+A33 -> 0 | D33: =IFERROR(VLOOKUP(H33,'[1]Consolidado MP Planta'!$A$2:$M$823,13,0),"") | E33: =IFERROR(VLOOKUP(H33,'[1]Consolidado MP Planta'!$A$2:$M$823,12,0),"") | F33: =IFERROR(C33*E33,"") | G33: =IFERROR(F33/$F$72,"")
B34: =IFERROR(VLOOKUP(H34,'[1]Consolidado MP Planta'!$A$2:$M$823,3,0),"") | C34: =+A34 -> 0 | D34: =IFERROR(VLOOKUP(H34,'[1]Consolidado MP Planta'!$A$2:$M$823,13,0),"") | E34: =IFERROR(VLOOKUP(H34,'[1]Consolidado MP Planta'!$A$2:$M$823,12,0),"") | F34: =IFERROR(C34*E34,"") | G34: =IFERROR(F34/$F$72,"")
B35: =IFERROR(VLOOKUP(H35,'[1]Consolidado MP Planta'!$A$2:$M$823,3,0),"") | C35: =+A35 -> 0 | D35: =IFERROR(VLOOKUP(H35,'[1]Consolidado MP Planta'!$A$2:$M$823,13,0),"") | E35: =IFERROR(VLOOKUP(H35,'[1]Consolidado MP Planta'!$A$2:$M$823,12,0),"") | F35: =IFERROR(C35*E35,"") | G35: =IFERROR(F35/$F$72,"")
B36: =IFERROR(VLOOKUP(H36,'[1]Consolidado MP Planta'!$A$2:$M$823,3,0),"") | C36: =+A36 -> 0 | D36: =IFERROR(VLOOKUP(H36,'[1]Consolidado MP Planta'!$A$2:$M$823,13,0),"") | E36: =IFERROR(VLOOKUP(H36,'[1]Consolidado MP Planta'!$A$2:$M$823,12,0),"") | F36: =IFERROR(C36*E36,"") | G36: =IFERROR(F36/$F$72,"")
A38: UNIDADES | B38: EMPAQUE SEMIELABORADOS | C38: UNIDADES | D38: UND MEDIDA | E38: COSTO UNITARIO | F38: TOTAL COSTO | G38: % PREC. DEFINIDO | H38: CODIGOS
A39: =+A17 -> 0.5 | B39: Rosquete Chocolate 400 grs Spoon | C39: =+A39 -> 0.5 | D39: =IFERROR(VLOOKUP(H39,[1]SEMIELABORADOS!$A$2:$M$6000,6,0),"") | E39: 5.29 | F39: =IFERROR(E39*C39,"") -> 2.645 | G39: =IFERROR(F39/$F$72,"") -> 0.00052858915 | H39: 907000268
A40: =+A18 -> 1 | B40: DISCO MOUSSE CHOCOLATE | C40: =+A40 -> 1 | D40: =IFERROR(VLOOKUP(H40,[1]SEMIELABORADOS!$A$2:$M$6000,6,0),"") | E40: =+'Costo disco'!H54 -> 2.4662564 | F40: =IFERROR(E40*C40,"") -> 2.4662564 | G40: =IFERROR(F40/$F$72,"") -> 0.0004928682
A41: =+A19 -> 50 | B41: Semillas de Cadbury | C41: =+A41 -> 50 | D41: =IFERROR(VLOOKUP(H41,[1]SEMIELABORADOS!$A$2:$M$6000,6,0),"") | E41: =+'costo semillas Cadbury'!E76 -> 0.0049747048 | F41: =IFERROR(E41*C41,"") -> 0.24873524 | G41: =IFERROR(F41/$F$72,"") -> 4.9708411e-05
A42: =+A20 -> 350 | B42: Mousse de pastelera | C42: =+A42 -> 350 | D42: =IFERROR(VLOOKUP(H42,[1]SEMIELABORADOS!$A$2:$M$6000,6,0),"") | E42: =+'Costo Mousse pastelera'!E76 -> 0 | F42: =IFERROR(E42*C42,"") -> 0 | G42: =IFERROR(F42/$F$72,"") -> 0
A43: =+A21 -> 50 | B43: Empaque Fudge De Chocolate | C43: =+A43 -> 50 | D43: =IFERROR(VLOOKUP(H43,[1]SEMIELABORADOS!$A$2:$M$6000,6,0),"") | E43: 0.01 | F43: =IFERROR(E43*C43,"") -> 0.5 | G43: =IFERROR(F43/$F$72,"") -> 9.9922335e-05
A44: =+A22 -> 50 | B44: Fudge Liquido | C44: =+A44 -> 50 | D44: =IFERROR(VLOOKUP(H44,[1]SEMIELABORADOS!$A$2:$M$6000,6,0),"") | E44: 0.01 | F44: =IFERROR(E44*C44,"") -> 0.5 | G44: =IFERROR(F44/$F$72,"") -> 9.9922335e-05
...

Sheet costo semillas Cadbury
E1: Precio Local | F1: Costo MP | G1: Costo EM | H1: Costo MO
E2: =IFERROR(O62,"") -> 42105.747 | F2: =IFERROR(H53,"") -> 39676 | G2: =IFERROR(H54,"") -> 49.747048 | H2: =IFERROR(H56,"") -> 1220
A5: ESTRUCTURA DE COSTOS
F6: Fecha: | H6: =TODAY() -> 45776
A7: UNIDADES | B7: DESCRIPCION MAT.PRIMA | C7: UNIDADES | D7: UND MEDIDA | E7: COSTO UNITARIO | F7: TOTAL COSTO | G7: % PREC. DEFINIDO | H7: CODIGOS
A8: 2600 | B8: Cobertura Chocolate Leche | C8: =+A8 -> 2600 | D8: =IFERROR(VLOOKUP(H8,'[1]Consolidado MP Planta'!$A$2:$M$823,13,0),"") -> Gramos | E8: 4.4 | F8: =IFERROR(C8*E8,"") -> 11440 | G8: =IFERROR(F8/$F$66,"") -> 0.27408244 | H8: 1210386
A9: 2600 | B9: Chocolate Semi Amargo 54% | C9: =+A9 -> 2600 | D9: Gramos | E9: 4.4 | F9: =IFERROR(C9*E9,"") -> 11440 | G9: =IFERROR(F9/$F$66,"") -> 0.27408244 | H9: 10100331
A10: 2600 | B10: Pasas | C10: =+A10 -> 2600 | D10: Gramos | E10: 1.47 | F10: =IFERROR(C10*E10,"") -> 3822 | G10: =IFERROR(F10/$F$66,"") -> 0.09156845 | H10: 5105009
A11: 2600 | B11: Almendra Entera | C11: =+A11 -> 2600 | D11: Gramos | E11: 4.99 | F11: =IFERROR(C11*E11,"") -> 12974 | G11: =IFERROR(F11/$F$66,"") -> 0.3108344 | H11: 11900029
B12: =IFERROR(VLOOKUP(H12,'[1]Consolidado MP Planta'!$A$2:$M$823,3,0),"") | C12: =+A12 -> 0 | D12: =IFERROR(VLOOKUP(H12,'[1]Consolidado MP Planta'!$A$2:$M$823,13,0),"") | E12: =IFERROR(VLOOKUP(H12,'[1]Consolidado MP Planta'!$A$2:$M$823,12,0),"") | F12: =IFERROR(C12*E12,"") | G12: =IFERROR(F12/$F$66,"")
B13: =IFERROR(VLOOKUP(H13,'[1]Consolidado MP Planta'!$A$2:$M$823,3,0),"") | C13: =+A13 -> 0 | D13: =IFERROR(VLOOKUP(H13,'[1]Consolidado MP Planta'!$A$2:$M$823,13,0),"") | E13: =IFERROR(VLOOKUP(H13,'[1]Consolidado MP Planta'!$A$2:$M$823,12,0),"") | F13: =IFERROR(C13*E13,"") | G13: =IFERROR(F13/$F$66,"")
B14: =IFERROR(VLOOKUP(H14,'[1]Consolidado MP Planta'!$A$2:$M$823,3,0),"") | C14: =+A14 -> 0 | D14: =IFERROR(VLOOKUP(H14,'[1]Consolidado MP Planta'!$A$2:$M$823,13,0),"") | E14: =IFERROR(VLOOKUP(H14,'[1]Consolidado MP Planta'!$A$2:$M$823,12,0),"") | F14: =IFERROR(C14*E14,"") | G14: =IFERROR(F14/$F$66,"")
B15: =IFERROR(VLOOKUP(H15,'[2]ARTICULOS MP PLANTA'!$A$2:$G$589,2,0),"")
A16: UNIDADES | B16: MATERIA PRIMA SEMIELABORADOS | C16: UNIDADES | D16: UND MEDIDA | E16: COSTO UNITARIO | F16: TOTAL COSTO | G16: % PREC. DEFINIDO | H16: CODIGOS
B17: =IFERROR(VLOOKUP(H17,[1]SEMIELABORADOS!$A$2:$M$6000,2,0),"") | C17: =+A17 -> 0 | D17: =IFERROR(VLOOKUP(H17,[1]SEMIELABORADOS!$A$2:$M$6000,6,0),"") | E17: =IFERROR(VLOOKUP(H17,[1]SEMIELABORADOS!$A$2:$H$65536,8,0),"") | F17: =IFERROR(E17*C17,"") | G17: =IFERROR(F17/$F$66,"")
B18: =IFERROR(VLOOKUP(H18,[1]SEMIELABORADOS!$A$2:$M$6000,2,0),"") | C18: =+A18 -> 0 | D18: =IFERROR(VLOOKUP(H18,[1]SEMIELABORADOS!$A$2:$M$6000,6,0),"") | E18: =IFERROR(VLOOKUP(H18,[1]SEMIELABORADOS!$A$2:$H$65536,8,0),"") | F18: =IFERROR(E18*C18,"") | G18: =IFERROR(F18/$F$66,"")
B19: =IFERROR(VLOOKUP(H19,[1]SEMIELABORADOS!$A$2:$M$6000,2,0),"") | C19: =+A19 -> 0 | D19: =IFERROR(VLOOKUP(H19,[1]SEMIELABORADOS!$A$2:$M$6000,6,0),"") | E19: =IFERROR(VLOOKUP(H19,[1]SEMIELABORADOS!$A$2:$H$65536,8,0),"") | F19: =IFERROR(E19*C19,"") | G19: =IFERROR(F19/$F$66,"")
B20: =IFERROR(VLOOKUP(H20,[1]SEMIELABORADOS!$A$2:$M$6000,2,0),"") | C20: =+A20 -> 0 | D20: =IFERROR(VLOOKUP(H20,[1]SEMIELABORADOS!$A$2:$M$6000,6,0),"") | E20: =IFERROR(VLOOKUP(H20,[1]SEMIELABORADOS!$A$2:$H$65536,8,0),"") | F20: =IFERROR(E20*C20,"") | G20: =IFERROR(F20/$F$66,"")
B21: =IFERROR(VLOOKUP(H21,[1]SEMIELABORADOS!$A$2:$M$6000,2,0),"") | C21: =+A21 -> 0 | D21: =IFERROR(VLOOKUP(H21,[1]SEMIELABORADOS!$A$2:$M$6000,6,0),"") | E21: =IFERROR(VLOOKUP(H21,[1]SEMIELABORADOS!$A$2:$H$65536,8,0),"") | F21: =IFERROR(E21*C21,"") | G21: =IFERROR(F21/$F$66,"")
B22: =IFERROR(VLOOKUP(H22,[1]SEMIELABORADOS!$A$2:$M$6000,2,0),"") | C22: =+A22 -> 0 | D22: =IFERROR(VLOOKUP(H22,[1]SEMIELABORADOS!$A$2:$M$6000,6,0),"") | E22: =IFERROR(VLOOKUP(H22,[1]SEMIELABORADOS!$A$2:$H$65536,8,0),"") | F22: =IFERROR(E22*C22,"") | G22: =IFERROR(F22/$F$66,"")
B23: =IFERROR(VLOOKUP(H23,[1]SEMIELABORADOS!$A$2:$M$6000,2,0),"") | C23: =+A23 -> 0 | D23: =IFERROR(VLOOKUP(H23,[1]SEMIELABORADOS!$A$2:$M$6000,6,0),"") | E23: =IFERROR(VLOOKUP(H23,[1]SEMIELABORADOS!$A$2:$H$65536,8,0),"") | F23: =IFERROR(E23*C23,"") | G23: =IFERROR(F23/$F$66,"")
B24: =IFERROR(VLOOKUP(H24,[1]SEMIELABORADOS!$A$2:$M$6000,2,0),"") | C24: =+A24 -> 0 | D24: =IFERROR(VLOOKUP(H24,[1]SEMIELABORADOS!$A$2:$M$6000,6,0),"") | E24: =IFERROR(VLOOKUP(H24,[1]SEMIELABORADOS!$A$2:$H$65536,8,0),"") | F24: =IFERROR(E24*C24,"") | G24: =IFERROR(F24/$F$66,"")
A26: UNIDADES | B26: EMPAQUE | C26: UNIDADES | D26: UND MEDIDA | E26: COSTO UNITARIO | F26: TOTAL COSTO | G26: % PREC. DEFINIDO | H26: CODIGOS
A27: 1 | B27: =IFERROR(VLOOKUP(H27,'[1]Consolidado MP Planta'!$A$2:$M$823,3,0),"") -> BOLSA 17x25 TRANSP KILO | C27: =+A27 -> 1 | D27: =IFERROR(VLOOKUP(H27,'[1]Consolidado MP Planta'!$A$2:$M$823,13,0),"") -> Und | E27: =IFERROR(VLOOKUP(H27,'[1]Consolidado MP Planta'!$A$2:$M$823,12,0),"") -> 47.619048 | F27: =IFERROR(C27*E27,"") -> 47.619048 | G27: =IFERROR(F27/$F$66,"") -> 0.0011408693 | H27: 1950708
A28: 1 | B28: =IFERROR(VLOOKUP(H28,'[1]Consolidado MP Planta'!$A$2:$M$823,3,0),"") -> ETIQUETA BLANCA 2 5/8X1 15/16 (UND) | C28: =+A28 -> 1 | D28: =IFERROR(VLOOKUP(H28,'[1]Consolidado MP Planta'!$A$2:$M$823,13,0),"") -> Und | E28: =IFERROR(VLOOKUP(H28,'[1]Consolidado MP Planta'!$A$2:$M$823,12,0),"") -> 2.128 | F28: =IFERROR(C28*E28,"") -> 2.128 | G28: =IFERROR(F28/$F$66,"") -> 5.0983166e-05 | H28: 0702123
B29: =IFERROR(VLOOKUP(H29,'[1]Consolidado MP Planta'!$A$2:$M$823,3,0),"") | C29: =+A29 -> 0 | D29: =IFERROR(VLOOKUP(H29,'[1]Consolidado MP Planta'!$A$2:$M$823,13,0),"") | E29: =IFERROR(VLOOKUP(H29,'[1]Consolidado MP Planta'!$A$2:$M$823,12,0),"") | F29: =IFERROR(C29*E29,"") | G29: =IFERROR(F29/$F$66,"")
B30: =IFERROR(VLOOKUP(H30,'[1]Consolidado MP Planta'!$A$2:$M$823,3,0),"") | C30: =+A30 -> 0 | D30: =IFERROR(VLOOKUP(H30,'[1]Consolidado MP Planta'!$A$2:$M$823,13,0),"") | E30: =IFERROR(VLOOKUP(H30,'[1]Consolidado MP Planta'!$A$2:$M$823,12,0),"") | F30: =IFERROR(C30*E30,"") | G30: =IFERROR(F30/$F$66,"")
B31: =IFERROR(VLOOKUP(H31,'[1]Consolidado MP Planta'!$A$2:$M$823,3,0),"") | C31: =+A31 -> 0 | D31: =IFERROR(VLOOKUP(H31,'[1]Consolidado MP Planta'!$A$2:$M$823,13,0),"") | E31: =IFERROR(VLOOKUP(H31,'[1]Consolidado MP Planta'!$A$2:$M$823,12,0),"") | F31: =IFERROR(C31*E31,"") | G31: =IFERROR(F31/$F$66,"")
B32: =IFERROR(VLOOKUP(H32,'[1]Consolidado MP Planta'!$A$2:$M$823,3,0),"") | C32: =+A32 -> 0 | D32: =IFERROR(VLOOKUP(H32,'[1]Consolidado MP Planta'!$A$2:$M$823,13,0),"") | E32: =IFERROR(VLOOKUP(H32,'[1]Consolidado MP Planta'!$A$2:$M$823,12,0),"") | F32: =IFERROR(C32*E32,"") | G32: =IFERROR(F32/$F$66,"")
A34: UNIDADES | B34: EMPAQUE SEMIELABORADOS | C34: UNIDADES | D34: UND MEDIDA | E34: COSTO UNITARIO | F34: TOTAL COSTO | G34: % PREC. DEFINIDO | H34: CODIGOS
A35: =+A17 -> 0 | B35: =IFERROR(VLOOKUP(H35,[1]SEMIELABORADOS!$A$2:$M$6000,2,0),"") | C35: =+A35 -> 0 | D35: =IFERROR(VLOOKUP(H35,[1]SEMIELABORADOS!$A$2:$M$6000,6,0),"") | E35: =IFERROR(VLOOKUP(H35,[1]SEMIELABORADOS!$A$2:$M$65536,10,0),"") | F35: =IFERROR(E35*C35,"") | G35: =IFERROR(F35/$F$66,"")
A36: =+A18 -> 0 | B36: =IFERROR(VLOOKUP(H36,[1]SEMIELABORADOS!$A$2:$M$6000,2,0),"") | C36: =+A36 -> 0 | D36: =IFERROR(VLOOKUP(H36,[1]SEMIELABORADOS!$A$2:$M$6000,6,0),"") | E36: =IFERROR(VLOOKUP(H36,[1]SEMIELABORADOS!$A$2:$M$65536,10,0),"") | F36: =IFERROR(E36*C36,"") | G36: =IFERROR(F36/$F$66,"")
A37: =+A19 -> 0 | B37: =IFERROR(VLOOKUP(H37,[1]SEMIELABORADOS!$A$2:$M$6000,2,0),"") | C37: =+A37 -> 0 | D37: =IFERROR(VLOOKUP(H37,[1]SEMIELABORADOS!$A$2:$M$6000,6,0),"") | E37: =IFERROR(VLOOKUP(H37,[1]SEMIELABORADOS!$A$2:$M$65536,10,0),"") | F37: =IFERROR(E37*C37,"") | G37: =IFERROR(F37/$F$66,"")
A38: =+A20 -> 0 | B38: =IFERROR(VLOOKUP(H38,[1]SEMIELABORADOS!$A$2:$M$6000,2,0),"") | C38: =+A38 -> 0 | D38: =IFERROR(VLOOKUP(H38,[1]SEMIELABORADOS!$A$2:$M$6000,6,0),"") | E38: =IFERROR(VLOOKUP(H38,[1]SEMIELABORADOS!$A$2:$M$65536,10,0),"") | F38: =IFERROR(E38*C38,"") | G38: =IFERROR(F38/$F$66,"")
A39: =+A21 -> 0 | B39: =IFERROR(VLOOKUP(H39,[1]SEMIELABORADOS!$A$2:$M$6000,2,0),"") | C39: =+A39 -> 0 | D39: =IFERROR(VLOOKUP(H39,[1]SEMIELABORADOS!$A$2:$M$6000,6,0),"") | E39: =IFERROR(VLOOKUP(H39,[1]SEMIELABORADOS!$A$2:$M$65536,10,0),"") | F39: =IFERROR(E39*C39,"") | G39: =IFERROR(F39/$F$66,"")
A40: =+A22 -> 0 | B40: =IFERROR(VLOOKUP(H40,[1]SEMIELABORADOS!$A$2:$M$6000,2,0),"") | C40: =+A40 -> 0 | D40: =IFERROR(VLOOKUP(H40,[1]SEMIELABORADOS!$A$2:$M$6000,6,0),"") | E40: =IFERROR(VLOOKUP(H40,[1]SEMIELABORADOS!$A$2:$M$65536,10,0),"") | F40: =IFERROR(E40*C40,"") | G40: =IFERROR(F40/$F$66,"")
A41: =+A23 -> 0 | B41: =IFERROR(VLOOKUP(H41,[1]SEMIELABORADOS!$A$2:$M$6000,2,0),"") | C41: =+A41 -> 0 | D41: =IFERROR(VLOOKUP(H41,[1]SEMIELABORADOS!$A$2:$M$6000,6,0),"") | E41: =IFERROR(VLOOKUP(H41,[1]SEMIELABORADOS!$A$2:$M$65536,10,0),"") | F41: =IFERROR(E41*C41,"") | G41: =IFERROR(F41/$F$66,"")
A43: UNIDADES | B43: MODI | C43: UNIDADES | D43: UND MEDIDA | E43: COSTO UNITARIO | F43: TOTAL COSTO | G43: % PREC. DEFINIDO | H43: CODIGOS
A44: =+A35 -> 0 | B44: =IFERROR(VLOOKUP(H44,[1]SEMIELABORADOS!$A$2:$M$6000,2,0),"") | C44: =+A44 -> 0 | D44: =IFERROR(VLOOKUP(H44,[1]SEMIELABORADOS!$A$2:$M$6000,6,0),"") | E44: =IFERROR(VLOOKUP(H44,[1]SEMIELABORADOS!$A$2:$M$65536,12,0),"") | F44: =IFERROR(E44*C44,"") | G44: =IFERROR(F44/$F$66,"")
A45: =+A36 -> 0 | B45: =IFERROR(VLOOKUP(H45,[1]SEMIELABORADOS!$A$2:$M$6000,2,0),"") | C45: =+A45 -> 0 | D45: =IFERROR(VLOOKUP(H45,[1]SEMIELABORADOS!$A$2:$M$6000,6,0),"") | E45: =IFERROR(VLOOKUP(H45,[1]SEMIELABORADOS!$A$2:$M$65536,12,0),"") | F45: =IFERROR(E45*C45,"") | G45: =IFERROR(F45/$F$66,"")
...

Sheet Hoja1
C1: SERVICIOS DE PASTELERIA S.A. | H1: CÓDIGO: | I1: ESP-RE-COCS-082
C2: ESPECIFICACION DE RECETA | H2: REVISIÓN: | I2: 01
C3: SE00601 RELLENO ARANDANOS ROJOS | H3: FECHA DE APROBACIÓN: | I3: 45617
C4: Elaborado | D4: Javier Tong, Chef
C5: Aprobado | D5: Esteban Cartin, Gte Manufactura
A6: AREA QUE PRODUCE: | D6: Cocina | G6: AREA QUE EMPACA: | I6: Cocina
A7: # Código | B7: # Código Netsuite | C7: Descripción del ingrediente | D7: Marca | E7: Unidad Internacional | G7: Medida alternativa | I7: Costo - Referencia
E8: Cantidad | F8: Unidad medida | G8: Cantidad | H8: Unidad medida | I8: Colones
C9: Ensamble
B10: MP10688 | C10: ARANDANOS CONGELADOS ROJOS | D10: SYSCO | E10: 7142 | F10: g
B11: MP10689 | C11: ARANDANOS DESHIDRATADOS MFS | D11: MFS | E11: 2857 | F11: g
A12: 90100131 | B12: SE00016 | C12: EMPAQUE AZUCAR INDUSTRIAL | E12: 2857 | F12: g
A13: 1100022 | B13: MP10043 | C13: GELATINA PURA | E13: 30 | F13: g
A14: 90100129 | B14: SE00014 | C14: EMPAQUE ALMIDON MODIFICADO | E14: 200 | F14: g
A15: 1212410 | B15: MP10008 | C15: PRESERVANTE 1047S | E15: 10 | F15: g
A16: 10415 | C16: AGUA POTABLE (PLANTA) | D16: FAS | E16: 1000 | F16: g
A17: 10415 | C17: AGUA POTABLE (PLANTA) | D17: FAS | E17: 1600 | F17: g
C24: Decoración
C32: Empaque
A33: 512000003 | B33: EM10252 | C33: PLÁSTICO AUTOADERIBLE 1/ 12*2000 | E33: 1 | F33: ud
D45: Cantidad | E45: Unidad
A46: PESO TOTAL OBTENIDO | D46: 13000 | E46: g | F46: Tiempo de Horneo:
A47: TIEMPO TOTAL DE PREPARACION | D47: 10 | E47: min | F47: Horno:
A48: CANTIDAD DE PORCIONES OBTENIDAS | D48: 1 | E48: g | F48: Temperatura de Horneo:
A49: PESO DE CADA PORCIÓN | D49: 1 | E49: g | F49: Otros
A50: MERMA | D50: 2696 | E50: g
A51: PROCEDIMIENTO DE PREPARACION DE LA RECETA
A52: 1.- Colocar el Arandano deshidratado y Azucar y 1000 gramos de agua
A53: 2.-Cocinar a fuego medio y agregar 500 gramos de arandanos congelados, mover cada 5 minutos, para evitar que el relleno se pegue en el fondo de la olla.
A54: 3.- Una vez que el relleno este hirviendo agregar el restante de arandanos congelados, agregar el almidon disuelto en el agua
A55: 4.- Una Vez que el relleno hirvio agregar la gelatina Hidratada
A56: 5.-Hervir hasta que el relleno este bien espeso y con la textura deseada.
A57: 6.-Enfriar, cubir con plastico y rotular.
A58: 7-No mover mucho para que no se desbarate los arandanos
A60: CONTROL DE CAMBIOS

Sheet costo relleno arandanos
E1: Precio Local | F1: Costo MP | G1: Costo EM | H1: Costo MO
E2: =IFERROR(O62,"") -> 67985.659 | F2: =IFERROR(H53,"") -> 66233.641 | G2: =IFERROR(H54,"") -> 98.060883 | H2: =IFERROR(H56,"") -> 847.8268
A5: ESTRUCTURA DE COSTOS
F6: Fecha: | H6: =TODAY() -> 45776
A7: UNIDADES | B7: DESCRIPCION MAT.PRIMA | C7: UNIDADES | D7: UND MEDIDA | E7: COSTO UNITARIO | F7: TOTAL COSTO | G7: % PREC. DEFINIDO | H7: CODIGOS
A8: 7142 | B8: Arandanos Congelados Rojos | C8: =+A8 -> 7142 | D8: Gramos | E8: 7.03 | F8: =IFERROR(C8*E8,"") -> 50208.26 | G8: =IFERROR(F8/$F$66,"") -> 0.7354757
A9: 2857 | B9: Arandanos Deshidratados MFS | C9: =+A9 -> 2857 | D9: Gramos | E9: 4.74 | F9: =IFERROR(C9*E9,"") -> 13542.18 | G9: =IFERROR(F9/$F$66,"") -> 0.19837262
A10: 57 | B10: Gelatina Pura | C10: =+A10 -> 57 | D10: Gramos | E10: 13 | F10: =IFERROR(C10*E10,"") -> 741 | G10: =IFERROR(F10/$F$66,"") -> 0.010854539 | H10: 1100022
B11: =IFERROR(VLOOKUP(H11,'[1]Consolidado MP Planta'!$A$2:$M$823,3,0),"") | C11: =+A11 -> 0 | D11: =IFERROR(VLOOKUP(H11,'[1]Consolidado MP Planta'!$A$2:$M$823,13,0),"") | E11: =IFERROR(VLOOKUP(H11,'[1]Consolidado MP Planta'!$A$2:$M$823,12,0),"") | F11: =IFERROR(C11*E11,"") | G11: =IFERROR(F11/$F$66,"")
B12: =IFERROR(VLOOKUP(H12,'[1]Consolidado MP Planta'!$A$2:$M$823,3,0),"") | C12: =+A12 -> 0 | D12: =IFERROR(VLOOKUP(H12,'[1]Consolidado MP Planta'!$A$2:$M$823,13,0),"") | E12: =IFERROR(VLOOKUP(H12,'[1]Consolidado MP Planta'!$A$2:$M$823,12,0),"") | F12: =IFERROR(C12*E12,"") | G12: =IFERROR(F12/$F$66,"")
B13: =IFERROR(VLOOKUP(H13,'[1]Consolidado MP Planta'!$A$2:$M$823,3,0),"") | C13: =+A13 -> 0 | D13: =IFERROR(VLOOKUP(H13,'[1]Consolidado MP Planta'!$A$2:$M$823,13,0),"") | E13: =IFERROR(VLOOKUP(H13,'[1]Consolidado MP Planta'!$A$2:$M$823,12,0),"") | F13: =IFERROR(C13*E13,"") | G13: =IFERROR(F13/$F$66,"")
B14: =IFERROR(VLOOKUP(H14,'[1]Consolidado MP Planta'!$A$2:$M$823,3,0),"") | C14: =+A14 -> 0 | D14: =IFERROR(VLOOKUP(H14,'[1]Consolidado MP Planta'!$A$2:$M$823,13,0),"") | E14: =IFERROR(VLOOKUP(H14,'[1]Consolidado MP Planta'!$A$2:$M$823,12,0),"") | F14: =IFERROR(C14*E14,"") | G14: =IFERROR(F14/$F$66,"")
B15: =IFERROR(VLOOKUP(H15,'[2]ARTICULOS MP PLANTA'!$A$2:$G$589,2,0),"")
A16: UNIDADES | B16: MATERIA PRIMA SEMIELABORADOS | C16: UNIDADES | D16: UND MEDIDA | E16: COSTO UNITARIO | F16: TOTAL COSTO | G16: % PREC. DEFINIDO | H16: CODIGOS
A17: 2857 | B17: =IFERROR(VLOOKUP(H17,[1]SEMIELABORADOS!$A$2:$M$6000,2,0),"") -> AZUCAR BLANCO INDUSTRIAL KILO | C17: =+A17 -> 2857 | D17: =IFERROR(VLOOKUP(H17,[1]SEMIELABORADOS!$A$2:$M$6000,6,0),"") -> Gramo | E17: =IFERROR(VLOOKUP(H17,[1]SEMIELABORADOS!$A$2:$H$65536,8,0),"") -> 0.39034 | F17: =IFERROR(E17*C17,"") -> 1115.2014 | G17: =IFERROR(F17/$F$66,"") -> 0.016336027 | H17: 90100131
A18: 285 | B18: =IFERROR(VLOOKUP(H18,[1]SEMIELABORADOS!$A$2:$M$6000,2,0),"") -> EMPAQUE ALMIDON MODIFICADO KILO | C18: =+A18 -> 285 | D18: =IFERROR(VLOOKUP(H18,[1]SEMIELABORADOS!$A$2:$M$6000,6,0),"") -> Gramo | E18: 2.2 | F18: =IFERROR(E18*C18,"") -> 627 | G18: =IFERROR(F18/$F$66,"") -> 0.0091846095 | H18: 90100129
B19: =IFERROR(VLOOKUP(H19,[1]SEMIELABORADOS!$A$2:$M$6000,2,0),"") | C19: =+A19 -> 0 | D19: =IFERROR(VLOOKUP(H19,[1]SEMIELABORADOS!$A$2:$M$6000,6,0),"") | E19: =IFERROR(VLOOKUP(H19,[1]SEMIELABORADOS!$A$2:$H$65536,8,0),"") | F19: =IFERROR(E19*C19,"") | G19: =IFERROR(F19/$F$66,"")
B20: =IFERROR(VLOOKUP(H20,[1]SEMIELABORADOS!$A$2:$M$6000,2,0),"") | C20: =+A20 -> 0 | D20: =IFERROR(VLOOKUP(H20,[1]SEMIELABORADOS!$A$2:$M$6000,6,0),"") | E20: =IFERROR(VLOOKUP(H20,[1]SEMIELABORADOS!$A$2:$H$65536,8,0),"") | F20: =IFERROR(E20*C20,"") | G20: =IFERROR(F20/$F$66,"")
B21: =IFERROR(VLOOKUP(H21,[1]SEMIELABORADOS!$A$2:$M$6000,2,0),"") | C21: =+A21 -> 0 | D21: =IFERROR(VLOOKUP(H21,[1]SEMIELABORADOS!$A$2:$M$6000,6,0),"") | E21: =IFERROR(VLOOKUP(H21,[1]SEMIELABORADOS!$A$2:$H$65536,8,0),"") | F21: =IFERROR(E21*C21,"") | G21: =IFERROR(F21/$F$66,"")
B22: =IFERROR(VLOOKUP(H22,[1]SEMIELABORADOS!$A$2:$M$6000,2,0),"") | C22: =+A22 -> 0 | D22: =IFERROR(VLOOKUP(H22,[1]SEMIELABORADOS!$A$2:$M$6000,6,0),"") | E22: =IFERROR(VLOOKUP(H22,[1]SEMIELABORADOS!$A$2:$H$65536,8,0),"") | F22: =IFERROR(E22*C22,"") | G22: =IFERROR(F22/$F$66,"")
B23: =IFERROR(VLOOKUP(H23,[1]SEMIELABORADOS!$A$2:$M$6000,2,0),"") | C23: =+A23 -> 0 | D23: =IFERROR(VLOOKUP(H23,[1]SEMIELABORADOS!$A$2:$M$6000,6,0),"") | E23: =IFERROR(VLOOKUP(H23,[1]SEMIELABORADOS!$A$2:$H$65536,8,0),"") | F23: =IFERROR(E23*C23,"") | G23: =IFERROR(F23/$F$66,"")
B24: =IFERROR(VLOOKUP(H24,[1]SEMIELABORADOS!$A$2:$M$6000,2,0),"") | C24: =+A24 -> 0 | D24: =IFERROR(VLOOKUP(H24,[1]SEMIELABORADOS!$A$2:$M$6000,6,0),"") | E24: =IFERROR(VLOOKUP(H24,[1]SEMIELABORADOS!$A$2:$H$65536,8,0),"") | F24: =IFERROR(E24*C24,"") | G24: =IFERROR(F24/$F$66,"")
A26: UNIDADES | B26: EMPAQUE | C26: UNIDADES | D26: UND MEDIDA | E26: COSTO UNITARIO | F26: TOTAL COSTO | G26: % PREC. DEFINIDO | H26: CODIGOS
A27: 0 | B27: =IFERROR(VLOOKUP(H27,'[1]Consolidado MP Planta'!$A$2:$M$823,3,0),"") | C27: =+A27 -> 0 | D27: =IFERROR(VLOOKUP(H27,'[1]Consolidado MP Planta'!$A$2:$M$823,13,0),"") | E27: =IFERROR(VLOOKUP(H27,'[1]Consolidado MP Planta'!$A$2:$M$823,12,0),"") | F27: =IFERROR(C27*E27,"") | G27: =IFERROR(F27/$F$66,"")
B28: =IFERROR(VLOOKUP(H28,'[1]Consolidado MP Planta'!$A$2:$M$823,3,0),"") | C28: =+A28 -> 0 | D28: =IFERROR(VLOOKUP(H28,'[1]Consolidado MP Planta'!$A$2:$M$823,13,0),"") | E28: =IFERROR(VLOOKUP(H28,'[1]Consolidado MP Planta'!$A$2:$M$823,12,0),"") | F28: =IFERROR(C28*E28,"") | G28: =IFERROR(F28/$F$66,"")
B29: =IFERROR(VLOOKUP(H29,'[1]Consolidado MP Planta'!$A$2:$M$823,3,0),"") | C29: =+A29 -> 0 | D29: =IFERROR(VLOOKUP(H29,'[1]Consolidado MP Planta'!$A$2:$M$823,13,0),"") | E29: =IFERROR(VLOOKUP(H29,'[1]Consolidado MP Planta'!$A$2:$M$823,12,0),"") | F29: =IFERROR(C29*E29,"") | G29: =IFERROR(F29/$F$66,"")
B30: =IFERROR(VLOOKUP(H30,'[1]Consolidado MP Planta'!$A$2:$M$823,3,0),"") | C30: =+A30 -> 0 | D30: =IFERROR(VLOOKUP(H30,'[1]Consolidado MP Planta'!$A$2:$M$823,13,0),"") | E30: =IFERROR(VLOOKUP(H30,'[1]Consolidado MP Planta'!$A$2:$M$823,12,0),"") | F30: =IFERROR(C30*E30,"") | G30: =IFERROR(F30/$F$66,"")
B31: =IFERROR(VLOOKUP(H31,'[1]Consolidado MP Planta'!$A$2:$M$823,3,0),"") | C31: =+A31 -> 0 | D31: =IFERROR(VLOOKUP(H31,'[1]Consolidado MP Planta'!$A$2:$M$823,13,0),"") | E31: =IFERROR(VLOOKUP(H31,'[1]Consolidado MP Planta'!$A$2:$M$823,12,0),"") | F31: =IFERROR(C31*E31,"") | G31: =IFERROR(F31/$F$66,"")
B32: =IFERROR(VLOOKUP(H32,'[1]Consolidado MP Planta'!$A$2:$M$823,3,0),"") | C32: =+A32 -> 0 | D32: =IFERROR(VLOOKUP(H32,'[1]Consolidado MP Planta'!$A$2:$M$823,13,0),"") | E32: =IFERROR(VLOOKUP(H32,'[1]Consolidado MP Planta'!$A$2:$M$823,12,0),"") | F32: =IFERROR(C32*E32,"") | G32: =IFERROR(F32/$F$66,"")
A34: UNIDADES | B34: EMPAQUE SEMIELABORADOS | C34: UNIDADES | D34: UND MEDIDA | E34: COSTO UNITARIO | F34: TOTAL COSTO | G34: % PREC. DEFINIDO | H34: CODIGOS
A35: =+A17 -> 2857 | B35: =IFERROR(VLOOKUP(H35,[1]SEMIELABORADOS!$A$2:$M$6000,2,0),"") -> AZUCAR BLANCO INDUSTRIAL KILO | C35: =+A35 -> 2857 | D35: =IFERROR(VLOOKUP(H35,[1]SEMIELABORADOS!$A$2:$M$6000,6,0),"") -> Gramo | E35: =IFERROR(VLOOKUP(H35,[1]SEMIELABORADOS!$A$2:$M$65536,10,0),"") -> 0.033330522 | F35: =IFERROR(E35*C35,"") -> 95.225301 | G35: =IFERROR(F35/$F$66,"") -> 0.0013949078 | H35: 90100131
A36: =+A18 -> 285 | B36: =IFERROR(VLOOKUP(H36,[1]SEMIELABORADOS!$A$2:$M$6000,2,0),"") -> EMPAQUE ALMIDON MODIFICADO KILO | C36: =+A36 -> 285 | D36: =IFERROR(VLOOKUP(H36,[1]SEMIELABORADOS!$A$2:$M$6000,6,0),"") -> Gramo | E36: =IFERROR(VLOOKUP(H36,[1]SEMIELABORADOS!$A$2:$M$65536,10,0),"") -> 0.0099494095 | F36: =IFERROR(E36*C36,"") -> 2.8355817 | G36: =IFERROR(F36/$F$66,"") -> 4.1537019e-05 | H36: 90100129
A37: =+A19 -> 0 | B37: =IFERROR(VLOOKUP(H37,[1]SEMIELABORADOS!$A$2:$M$6000,2,0),"") | C37: =+A37 -> 0 | D37: =IFERROR(VLOOKUP(H37,[1]SEMIELABORADOS!$A$2:$M$6000,6,0),"") | E37: =IFERROR(VLOOKUP(H37,[1]SEMIELABORADOS!$A$2:$M$65536,10,0),"") | F37: =IFERROR(E37*C37,"") | G37: =IFERROR(F37/$F$66,"")
A38: =+A20 -> 0 | B38: =IFERROR(VLOOKUP(H38,[1]SEMIELABORADOS!$A$2:$M$6000,2,0),"") | C38: =+A38 -> 0 | D38: =IFERROR(VLOOKUP(H38,[1]SEMIELABORADOS!$A$2:$M$6000,6,0),"") | E38: =IFERROR(VLOOKUP(H38,[1]SEMIELABORADOS!$A$2:$M$65536,10,0),"") | F38: =IFERROR(E38*C38,"") | G38: =IFERROR(F38/$F$66,"")
A39: =+A21 -> 0 | B39: =IFERROR(VLOOKUP(H39,[1]SEMIELABORADOS!$A$2:$M$6000,2,0),"") | C39: =+A39 -> 0 | D39: =IFERROR(VLOOKUP(H39,[1]SEMIELABORADOS!$A$2:$M$6000,6,0),"") | E39: =IFERROR(VLOOKUP(H39,[1]SEMIELABORADOS!$A$2:$M$65536,10,0),"") | F39: =IFERROR(E39*C39,"") | G39: =IFERROR(F39/$F$66,"")
A40: =+A22 -> 0 | B40: =IFERROR(VLOOKUP(H40,[1]SEMIELABORADOS!$A$2:$M$6000,2,0),"") | C40: =+A40 -> 0 | D40: =IFERROR(VLOOKUP(H40,[1]SEMIELABORADOS!$A$2:$M$6000,6,0),"") | E40: =IFERROR(VLOOKUP(H40,[1]SEMIELABORADOS!$A$2:$M$65536,10,0),"") | F40: =IFERROR(E40*C40,"") | G40: =IFERROR(F40/$F$66,"")
A41: =+A23 -> 0 | B41: =IFERROR(VLOOKUP(H41,[1]SEMIELABORADOS!$A$2:$M$6000,2,0),"") | C41: =+A41 -> 0 | D41: =IFERROR(VLOOKUP(H41,[1]SEMIELABORADOS!$A$2:$M$6000,6,0),"") | E41: =IFERROR(VLOOKUP(H41,[1]SEMIELABORADOS!$A$2:$M$65536,10,0),"") | F41: =IFERROR(E41*C41,"") | G41: =IFERROR(F41/$F$66,"")
A43: UNIDADES | B43: MODI | C43: UNIDADES | D43: UND MEDIDA | E43: COSTO UNITARIO | F43: TOTAL COSTO | G43: % PREC. DEFINIDO | H43: CODIGOS
A44: =+A35 -> 2857 | B44: =IFERROR(VLOOKUP(H44,[1]SEMIELABORADOS!$A$2:$M$6000,2,0),"") -> AZUCAR BLANCO INDUSTRIAL KILO | C44: =+A44 -> 2857 | D44: =IFERROR(VLOOKUP(H44,[1]SEMIELABORADOS!$A$2:$M$6000,6,0),"") -> Gramo | E44: =IFERROR(VLOOKUP(H44,[1]SEMIELABORADOS!$A$2:$M$65536,12,0),"") -> 0.076260694 | F44: =IFERROR(E44*C44,"") -> 217.8768 | G44: =IFERROR(F44/$F$66,"") -> 0.0031915684 | H44: 90100131
A45: =+A36 -> 285 | B45: =IFERROR(VLOOKUP(H45,[1]SEMIELABORADOS!$A$2:$M$6000,2,0),"") -> EMPAQUE ALMIDON MODIFICADO KILO | C45: =+A45 -> 285 | D45: =IFERROR(VLOOKUP(H45,[1]SEMIELABORADOS!$A$2:$M$6000,6,0),"") -> Gramo | E45: 0.07 | F45: =IFERROR(E45*C45,"") -> 19.95 | G45: =IFERROR(F45/$F$66,"") -> 0.00029223758 | H45: 90100129
...

Sheet Costo Empaque Relleno Arand
E1: Precio Local | F1: Costo MP | G1: Costo EM | H1: Costo MO
E2: =IFERROR(O62,"") -> 34160.362 | F2: =IFERROR(H53,"") -> 33116.821 | G2: =IFERROR(H54,"") -> 97.562822 | H2: =IFERROR(H56,"") -> 484.9134
A5: ESTRUCTURA DE COSTOS
F6: Fecha: | H6: =TODAY() -> 45776
A7: UNIDADES | B7: DESCRIPCION MAT.PRIMA | C7: UNIDADES | D7: UND MEDIDA | E7: COSTO UNITARIO | F7: TOTAL COSTO | G7: % PREC. DEFINIDO | H7: CODIGOS
B8: =IFERROR(VLOOKUP(H8,'[1]Consolidado MP Planta'!$A$2:$M$823,3,0),"") | C8: =+A8 -> 0 | D8: =IFERROR(VLOOKUP(H8,'[1]Consolidado MP Planta'!$A$2:$M$823,13,0),"") | E8: =IFERROR(VLOOKUP(H8,'[1]Consolidado MP Planta'!$A$2:$M$823,12,0),"") | F8: =IFERROR(C8*E8,"") | G8: =IFERROR(F8/$F$66,"")
B9: =IFERROR(VLOOKUP(H9,'[1]Consolidado MP Planta'!$A$2:$M$823,3,0),"") | C9: =+A9 -> 0 | D9: =IFERROR(VLOOKUP(H9,'[1]Consolidado MP Planta'!$A$2:$M$823,13,0),"") | E9: =IFERROR(VLOOKUP(H9,'[1]Consolidado MP Planta'!$A$2:$M$823,12,0),"") | F9: =IFERROR(C9*E9,"") | G9: =IFERROR(F9/$F$66,"")
B10: =IFERROR(VLOOKUP(H10,'[1]Consolidado MP Planta'!$A$2:$M$823,3,0),"") | C10: =+A10 -> 0 | D10: =IFERROR(VLOOKUP(H10,'[1]Consolidado MP Planta'!$A$2:$M$823,13,0),"") | E10: =IFERROR(VLOOKUP(H10,'[1]Consolidado MP Planta'!$A$2:$M$823,12,0),"") | F10: =IFERROR(C10*E10,"") | G10: =IFERROR(F10/$F$66,"")
B11: =IFERROR(VLOOKUP(H11,'[1]Consolidado MP Planta'!$A$2:$M$823,3,0),"") | C11: =+A11 -> 0 | D11: =IFERROR(VLOOKUP(H11,'[1]Consolidado MP Planta'!$A$2:$M$823,13,0),"") | E11: =IFERROR(VLOOKUP(H11,'[1]Consolidado MP Planta'!$A$2:$M$823,12,0),"") | F11: =IFERROR(C11*E11,"") | G11: =IFERROR(F11/$F$66,"")
B12: =IFERROR(VLOOKUP(H12,'[1]Consolidado MP Planta'!$A$2:$M$823,3,0),"") | C12: =+A12 -> 0 | D12: =IFERROR(VLOOKUP(H12,'[1]Consolidado MP Planta'!$A$2:$M$823,13,0),"") | E12: =IFERROR(VLOOKUP(H12,'[1]Consolidado MP Planta'!$A$2:$M$823,12,0),"") | F12: =IFERROR(C12*E12,"") | G12: =IFERROR(F12/$F$66,"")
B13: =IFERROR(VLOOKUP(H13,'[1]Consolidado MP Planta'!$A$2:$M$823,3,0),"") | C13: =+A13 -> 0 | D13: =IFERROR(VLOOKUP(H13,'[1]Consolidado MP Planta'!$A$2:$M$823,13,0),"") | E13: =IFERROR(VLOOKUP(H13,'[1]Consolidado MP Planta'!$A$2:$M$823,12,0),"") | F13: =IFERROR(C13*E13,"") | G13: =IFERROR(F13/$F$66,"")
B14: =IFERROR(VLOOKUP(H14,'[1]Consolidado MP Planta'!$A$2:$M$823,3,0),"") | C14: =+A14 -> 0 | D14: =IFERROR(VLOOKUP(H14,'[1]Consolidado MP Planta'!$A$2:$M$823,13,0),"") | E14: =IFERROR(VLOOKUP(H14,'[1]Consolidado MP Planta'!$A$2:$M$823,12,0),"") | F14: =IFERROR(C14*E14,"") | G14: =IFERROR(F14/$F$66,"")
B15: =IFERROR(VLOOKUP(H15,'[2]ARTICULOS MP PLANTA'!$A$2:$G$589,2,0),"")
A16: UNIDADES | B16: MATERIA PRIMA SEMIELABORADOS | C16: UNIDADES | D16: UND MEDIDA | E16: COSTO UNITARIO | F16: TOTAL COSTO | G16: % PREC. DEFINIDO | H16: CODIGOS
A17: 5000 | B17: RELLENO ARANDANOS ROJOS | C17: =+A17 -> 5000 | D17: =IFERROR(VLOOKUP(H17,[1]SEMIELABORADOS!$A$2:$M$6000,6,0),"") | E17: =+'costo relleno arandanos'!E69 -> 6.6233641 | F17: =IFERROR(E17*C17,"") -> 33116.821 | G17: =IFERROR(F17/$F$66,"") -> 0.9758116
B18: =IFERROR(VLOOKUP(H18,[1]SEMIELABORADOS!$A$2:$M$6000,2,0),"") | C18: =+A18 -> 0 | D18: =IFERROR(VLOOKUP(H18,[1]SEMIELABORADOS!$A$2:$M$6000,6,0),"") | E18: =IFERROR(VLOOKUP(H18,[1]SEMIELABORADOS!$A$2:$H$65536,8,0),"") | F18: =IFERROR(E18*C18,"") | G18: =IFERROR(F18/$F$66,"")
B19: =IFERROR(VLOOKUP(H19,[1]SEMIELABORADOS!$A$2:$M$6000,2,0),"") | C19: =+A19 -> 0 | D19: =IFERROR(VLOOKUP(H19,[1]SEMIELABORADOS!$A$2:$M$6000,6,0),"") | E19: =IFERROR(VLOOKUP(H19,[1]SEMIELABORADOS!$A$2:$H$65536,8,0),"") | F19: =IFERROR(E19*C19,"") | G19: =IFERROR(F19/$F$66,"")
