Workbook

Sheet Premezcla
C1: SERVICIOS DE PASTELERIA S.A. | H1: CÓDIGO:
C2: ESPECIFICACION DE RECETA | H2: REVISIÓN:
C3: SE00428 Premezcla queque limon spoon | H3: FECHA DE APROBACIÓN:
C4: Elaborado | D4: Juan Pablo Brenes , chef
C5: Aprobado | D5: Esteban Cartin, Gte Manufactura
A6: AREA QUE PRODUCE: | D6: BATIDOS | G6: AREA QUE EMPACA: | I6: BATIDOS
A7: # Código | B7: # Codigo Netsuite | C7: Descripción del ingrediente | D7: Marca | E7: Unidad Internacional | G7: Medida alternativa | I7: Costo - Referencia
E8: Cantidad | F8: Unidad medida | G8: Cantidad | H8: Unidad medida | I8: Colones
A9: 11200070 | B9: MP10206 | C9: Harina Harisol Hojaldre | D9: Fachasa | E9: 2250 | F9: g
A10: 10100046 | B10: MP10304 | C10: Polvo Hornear | D10: Fleishman | E10: 50 | F10: g
A11: 5000001 | B11: MP10027 | C11: Sal Industrial | E11: 20 | F11: g
A12: 101132 | B12: MP10239 | C12: Limon En Polvo | E12: 30 | F12: g
A14: 0310107 | B14: MP10022 | C14: Lactocrema Granel | E14: 1500 | F14: g
A16: 510301 | B16: MP10074 | C16: Azucar Blanco Industrial | E16: 2300 | F16: g
C18: EMPAQUE
A19: 1950702 | B19: EM10016 | C19: Bolsa 12X18 Transparente | D19: Plasticos P | E19: 1 | F19: ud
A20: 1950708 | B20: EM10013 | C20: Bolsa 17X25 Transparente | D20: Plasticos P | E20: 2 | F20: ud
A21: 60100010 | B21: EM10133 | C21: Etiqueta Roja Letra Alerjeno | D21: Etiplast | E21: 2 | F21: ud
A22: 0702123 | B22: EM10011 | C22: Etiqueta Blanca 2 5/8X1 15/16 | D22: Etiplast | E22: 2 | F22: ud
D24: Cantidad | E24: Unidad
A25: PESO TOTAL OBTENIDO | D25: 6120 | E25: g | F25: Tiempo de Horneo:
A26: TIEMPO TOTAL DE PREPARACION | D26: 4 | E26: min | F26: Horno:
A27: CANTIDAD DE PORCIONES OBTENIDAS | D27: =D25/D28 -> 1 | E27: ud | F27: Temperatura de Horneo:
A28: PESO DE CADA PORCIÓN | D28: 6120 | E28: g | F28: Otros
A29: MERMA | D29: =SUM(E9:E17)-D25 -> 30 | E29: g
A30: PROCEDIMIENTO DE PREPARACION DE LA RECETA
A31: 1.- Pesar en la bolsa 12x18 el harina, polvo de hornear, sal y limon en polvo.
A32: 2.- En una bolsa 17x25 pesar la lactocrema y en la otra el azucar blanco.
A33: 3.- Etiquetar.
A37: CONTROL DE CAMBIOS

Sheet Costo Premezcla 
E1: Precio Local | F1: Costo MP | G1: Costo EM | H1: Costo MO
E2: =IFERROR(O62,"") -> 8215.1123 | F2: =IFERROR(H53,"") -> 7627.542 | G2: =IFERROR(H54,"") -> 111.57029 | H2: =IFERROR(H56,"") -> 244
A5: ESTRUCTURA DE COSTOS
F6: Fecha: | H6: =TODAY() -> 45679
A7: UNIDADES | B7: DESCRIPCION MAT.PRIMA | C7: UNIDADES | D7: UND MEDIDA | E7: COSTO UNITARIO | F7: TOTAL COSTO | G7: % PREC. DEFINIDO | H7: CODIGOS
A8: 2250 | B8: Harina Harisol Hojaldre | C8: =+A8 -> 2250 | D8: Gramos | E8: 0.56 | F8: =IFERROR(C8*E8,"") -> 1260 | G8: =IFERROR(F8/$F$66,"") -> 0.15487367 | H8: 11200070
A9: 50 | B9: =IFERROR(VLOOKUP(H9,'[1]Consolidado MP Planta'!$A$2:$M$823,3,0),"") -> POLVO HORNEAR FLEISHMAN (PAQ:2.5 K) | C9: =+A9 -> 50 | D9: =IFERROR(VLOOKUP(H9,'[1]Consolidado MP Planta'!$A$2:$M$823,13,0),"") -> Gramos | E9: 1.02 | F9: =IFERROR(C9*E9,"") -> 51 | G9: =IFERROR(F9/$F$66,"") -> 0.0062686961 | H9: 10100046
A10: 20 | B10: =IFERROR(VLOOKUP(H10,'[1]Consolidado MP Planta'!$A$2:$M$823,3,0),"") -> SAL INDUSTRIA (SACO:25 Kg) | C10: =+A10 -> 20 | D10: =IFERROR(VLOOKUP(H10,'[1]Consolidado MP Planta'!$A$2:$M$823,13,0),"") -> Gramos | E10: =IFERROR(VLOOKUP(H10,'[1]Consolidado MP Planta'!$A$2:$M$823,12,0),"") -> 0.188 | F10: =IFERROR(C10*E10,"") -> 3.76 | G10: =IFERROR(F10/$F$66,"") -> 0.0004621627 | H10: 5000001
A11: 30 | B11: Limon En Polvo | C11: =+A11 -> 30 | D11: Gramos | E11: 6 | F11: =IFERROR(C11*E11,"") -> 180 | G11: =IFERROR(F11/$F$66,"") -> 0.02212481 | H11: 101132
A12: 1500 | B12: =IFERROR(VLOOKUP(H12,'[1]Consolidado MP Planta'!$A$2:$M$823,3,0),"") -> LACTOCREMA GRANEL (CAJA:25 KG) | C12: =+A12 -> 1500 | D12: =IFERROR(VLOOKUP(H12,'[1]Consolidado MP Planta'!$A$2:$M$823,13,0),"") -> Gramos | E12: 3.49 | F12: =IFERROR(C12*E12,"") -> 5235 | G12: =IFERROR(F12/$F$66,"") -> 0.64346322 | H12: 0310107
A13: 2300 | B13: =IFERROR(VLOOKUP(H13,'[1]Consolidado MP Planta'!$A$2:$M$823,3,0),"") -> AZUCAR BLANCO INDUSTRIAL (SACO:50 K) | C13: =+A13 -> 2300 | D13: =IFERROR(VLOOKUP(H13,'[1]Consolidado MP Planta'!$A$2:$M$823,13,0),"") -> Gramos | E13: =IFERROR(VLOOKUP(H13,'[1]Consolidado MP Planta'!$A$2:$M$823,12,0),"") -> 0.39034 | F13: =IFERROR(C13*E13,"") -> 897.782 | G13: =IFERROR(F13/$F$66,"") -> 0.11035142 | H13: 510301
B14: =IFERROR(VLOOKUP(H14,'[1]Consolidado MP Planta'!$A$2:$M$823,3,0),"") | C14: =+A14 -> 0 | D14: =IFERROR(VLOOKUP(H14,'[1]Consolidado MP Planta'!$A$2:$M$823,13,0),"") | E14: =IFERROR(VLOOKUP(H14,'[1]Consolidado MP Planta'!$A$2:$M$823,12,0),"") | F14: =IFERROR(C14*E14,"") | G14: =IFERROR(F14/$F$66,"")
B15: =IFERROR(VLOOKUP(H15,'[2]ARTICULOS MP PLANTA'!$A$2:$G$589,2,0),"")
A16: UNIDADES | B16: MATERIA PRIMA SEMIELABORADOS | C16: UNIDADES | D16: UND MEDIDA | E16: COSTO UNITARIO | F16: TOTAL COSTO | G16: % PREC. DEFINIDO | H16: CODIGOS
B17: =IFERROR(VLOOKUP(H17,[1]SEMIELABORADOS!$A$2:$M$6000,2,0),"") | C17: =+A17 -> 0 | D17: =IFERROR(VLOOKUP(H17,[1]SEMIELABORADOS!$A$2:$M$6000,6,0),"") | E17: =IFERROR(VLOOKUP(H17,[1]SEMIELABORADOS!$A$2:$H$65536,8,0),"") | F17: =IFERROR(E17*C17,"") | G17: =IFERROR(F17/$F$66,"")
B18: =IFERROR(VLOOKUP(H18,[1]SEMIELABORADOS!$A$2:$M$6000,2,0),"") | C18: =+A18 -> 0 | D18: =IFERROR(VLOOKUP(H18,[1]SEMIELABORADOS!$A$2:$M$6000,6,0),"") | E18: =IFERROR(VLOOKUP(H18,[1]SEMIELABORADOS!$A$2:$H$65536,8,0),"") | F18: =IFERROR(E18*C18,"") | G18: =IFERROR(F18/$F$66,"")
B19: =IFERROR(VLOOKUP(H19,[1]SEMIELABORADOS!$A$2:$M$6000,2,0),"") | C19: =+A19 -> 0 | D19: =IFERROR(VLOOKUP(H19,[1]SEMIELABORADOS!$A$2:$M$6000,6,0),"") | E19: =IFERROR(VLOOKUP(H19,[1]SEMIELABORADOS!$A$2:$H$65536,8,0),"") | F19: =IFERROR(E19*C19,"") | G19: =IFERROR(F19/$F$66,"")
B20: =IFERROR(VLOOKUP(H20,[1]SEMIELABORADOS!$A$2:$M$6000,2,0),"") | C20: =+A20 -> 0 | D20: =IFERROR(VLOOKUP(H20,[1]SEMIELABORADOS!$A$2:$M$6000,6,0),"") | E20: =IFERROR(VLOOKUP(H20,[1]SEMIELABORADOS!$A$2:$H$65536,8,0),"") | F20: =IFERROR(E20*C20,"") | G20: =IFERROR(F20/$F$66,"")
B21: =IFERROR(VLOOKUP(H21,[1]SEMIELABORADOS!$A$2:$M$6000,2,0),"") | C21: =+A21 -> 0 | D21: =IFERROR(VLOOKUP(H21,[1]SEMIELABORADOS!$A$2:$M$6000,6,0),"") | E21: =IFERROR(VLOOKUP(H21,[1]SEMIELABORADOS!$A$2:$H$65536,8,0),"") | F21: =IFERROR(E21*C21,"") | G21: =IFERROR(F21/$F$66,"")
B22: =IFERROR(VLOOKUP(H22,[1]SEMIELABORADOS!$A$2:$M$6000,2,0),"") | C22: =+A22 -> 0 | D22: =IFERROR(VLOOKUP(H22,[1]SEMIELABORADOS!$A$2:$M$6000,6,0),"") | E22: =IFERROR(VLOOKUP(H22,[1]SEMIELABORADOS!$A$2:$H$65536,8,0),"") | F22: =IFERROR(E22*C22,"") | G22: =IFERROR(F22/$F$66,"")
B23: =IFERROR(VLOOKUP(H23,[1]SEMIELABORADOS!$A$2:$M$6000,2,0),"") | C23: =+A23 -> 0 | D23: =IFERROR(VLOOKUP(H23,[1]SEMIELABORADOS!$A$2:$M$6000,6,0),"") | E23: =IFERROR(VLOOKUP(H23,[1]SEMIELABORADOS!$A$2:$H$65536,8,0),"") | F23: =IFERROR(E23*C23,"") | G23: =IFERROR(F23/$F$66,"")
B24: =IFERROR(VLOOKUP(H24,[1]SEMIELABORADOS!$A$2:$M$6000,2,0),"") | C24: =+A24 -> 0 | D24: =IFERROR(VLOOKUP(H24,[1]SEMIELABORADOS!$A$2:$M$6000,6,0),"") | E24: =IFERROR(VLOOKUP(H24,[1]SEMIELABORADOS!$A$2:$H$65536,8,0),"") | F24: =IFERROR(E24*C24,"") | G24: =IFERROR(F24/$F$66,"")
A26: UNIDADES | B26: EMPAQUE | C26: UNIDADES | D26: UND MEDIDA | E26: COSTO UNITARIO | F26: TOTAL COSTO | G26: % PREC. DEFINIDO | H26: CODIGOS
A27: 1 | B27: =IFERROR(VLOOKUP(H27,'[1]Consolidado MP Planta'!$A$2:$M$823,3,0),"") -> BOLSA 12x18 TRANSP KILO | C27: =+A27 -> 1 | D27: =IFERROR(VLOOKUP(H27,'[1]Consolidado MP Planta'!$A$2:$M$823,13,0),"") -> Und | E27: =IFERROR(VLOOKUP(H27,'[1]Consolidado MP Planta'!$A$2:$M$823,12,0),"") -> 14.4 | F27: =IFERROR(C27*E27,"") -> 14.4 | G27: =IFERROR(F27/$F$66,"") -> 0.0017699848 | H27: 1950702
A28: 2 | B28: =IFERROR(VLOOKUP(H28,'[1]Consolidado MP Planta'!$A$2:$M$823,3,0),"") -> BOLSA 17x25 TRANSP KILO | C28: =+A28 -> 2 | D28: =IFERROR(VLOOKUP(H28,'[1]Consolidado MP Planta'!$A$2:$M$823,13,0),"") -> Und | E28: =IFERROR(VLOOKUP(H28,'[1]Consolidado MP Planta'!$A$2:$M$823,12,0),"") -> 42.857143 | F28: =IFERROR(C28*E28,"") -> 85.714286 | G28: =IFERROR(F28/$F$66,"") -> 0.010535624 | H28: 1950708
A29: 2 | B29: =IFERROR(VLOOKUP(H29,'[1]Consolidado MP Planta'!$A$2:$M$823,3,0),"") -> ETIQUETA ROJA LETRA ALERJENO (UND) | C29: =+A29 -> 2 | D29: =IFERROR(VLOOKUP(H29,'[1]Consolidado MP Planta'!$A$2:$M$823,13,0),"") -> Und | E29: =IFERROR(VLOOKUP(H29,'[1]Consolidado MP Planta'!$A$2:$M$823,12,0),"") -> 3.6 | F29: =IFERROR(C29*E29,"") -> 7.2 | G29: =IFERROR(F29/$F$66,"") -> 0.0008849924 | H29: 60100010
A30: 2 | B30: =IFERROR(VLOOKUP(H30,'[1]Consolidado MP Planta'!$A$2:$M$823,3,0),"") -> ETIQUETA BLANCA 2 5/8X1 15/16 (UND) | C30: =+A30 -> 2 | D30: =IFERROR(VLOOKUP(H30,'[1]Consolidado MP Planta'!$A$2:$M$823,13,0),"") -> Und | E30: =IFERROR(VLOOKUP(H30,'[1]Consolidado MP Planta'!$A$2:$M$823,12,0),"") -> 2.128 | F30: =IFERROR(C30*E30,"") -> 4.256 | G30: =IFERROR(F30/$F$66,"") -> 0.00052312884 | H30: 0702123
B31: =IFERROR(VLOOKUP(H31,'[1]Consolidado MP Planta'!$A$2:$M$823,3,0),"") | C31: =+A31 -> 0 | D31: =IFERROR(VLOOKUP(H31,'[1]Consolidado MP Planta'!$A$2:$M$823,13,0),"") | E31: =IFERROR(VLOOKUP(H31,'[1]Consolidado MP Planta'!$A$2:$M$823,12,0),"") | F31: =IFERROR(C31*E31,"") | G31: =IFERROR(F31/$F$66,"")
B32: =IFERROR(VLOOKUP(H32,'[1]Consolidado MP Planta'!$A$2:$M$823,3,0),"") | C32: =+A32 -> 0 | D32: =IFERROR(VLOOKUP(H32,'[1]Consolidado MP Planta'!$A$2:$M$823,13,0),"") | E32: =IFERROR(VLOOKUP(H32,'[1]Consolidado MP Planta'!$A$2:$M$823,12,0),"") | F32: =IFERROR(C32*E32,"") | G32: =IFERROR(F32/$F$66,"")
A34: UNIDADES | B34: EMPAQUE SEMIELABORADOS | C34: UNIDADES | D34: UND MEDIDA | E34: COSTO UNITARIO | F34: TOTAL COSTO | G34: % PREC. DEFINIDO | H34: CODIGOS
A35: =+A17 -> 0 | B35: =IFERROR(VLOOKUP(H35,[1]SEMIELABORADOS!$A$2:$M$6000,2,0),"") | C35: =+A35 -> 0 | D35: =IFERROR(VLOOKUP(H35,[1]SEMIELABORADOS!$A$2:$M$6000,6,0),"") | E35: =IFERROR(VLOOKUP(H35,[1]SEMIELABORADOS!$A$2:$M$65536,10,0),"") | F35: =IFERROR(E35*C35,"") | G35: =IFERROR(F35/$F$66,"")
A36: =+A18 -> 0 | B36: =IFERROR(VLOOKUP(H36,[1]SEMIELABORADOS!$A$2:$M$6000,2,0),"") | C36: =+A36 -> 0 | D36: =IFERROR(VLOOKUP(H36,[1]SEMIELABORADOS!$A$2:$M$6000,6,0),"") | E36: =IFERROR(VLOOKUP(H36,[1]SEMIELABORADOS!$A$2:$M$65536,10,0),"") | F36: =IFERROR(E36*C36,"") | G36: =IFERROR(F36/$F$66,"")
A37: =+A19 -> 0 | B37: =IFERROR(VLOOKUP(H37,[1]SEMIELABORADOS!$A$2:$M$6000,2,0),"") | C37: =+A37 -> 0 | D37: =IFERROR(VLOOKUP(H37,[1]SEMIELABORADOS!$A$2:$M$6000,6,0),"") | E37: =IFERROR(VLOOKUP(H37,[1]SEMIELABORADOS!$A$2:$M$65536,10,0),"") | F37: =IFERROR(E37*C37,"") | G37: =IFERROR(F37/$F$66,"")
A38: =+A20 -> 0 | B38: =IFERROR(VLOOKUP(H38,[1]SEMIELABORADOS!$A$2:$M$6000,2,0),"") | C38: =+A38 -> 0 | D38: =IFERROR(VLOOKUP(H38,[1]SEMIELABORADOS!$A$2:$M$6000,6,0),"") | E38: =IFERROR(VLOOKUP(H38,[1]SEMIELABORADOS!$A$2:$M$65536,10,0),"") | F38: =IFERROR(E38*C38,"") | G38: =IFERROR(F38/$F$66,"")
A39: =+A21 -> 0 | B39: =IFERROR(VLOOKUP(H39,[1]SEMIELABORADOS!$A$2:$M$6000,2,0),"") | C39: =+A39 -> 0 | D39: =IFERROR(VLOOKUP(H39,[1]SEMIELABORADOS!$A$2:$M$6000,6,0),"") | E39: =IFERROR(VLOOKUP(H39,[1]SEMIELABORADOS!$A$2:$M$65536,10,0),"") | F39: =IFERROR(E39*C39,"") | G39: =IFERROR(F39/$F$66,"")
A40: =+A22 -> 0 | B40: =IFERROR(VLOOKUP(H40,[1]SEMIELABORADOS!$A$2:$M$6000,2,0),"") | C40: =+A40 -> 0 | D40: =IFERROR(VLOOKUP(H40,[1]SEMIELABORADOS!$A$2:$M$6000,6,0),"") | E40: =IFERROR(VLOOKUP(H40,[1]SEMIELABORADOS!$A$2:$M$65536,10,0),"") | F40: =IFERROR(E40*C40,"") | G40: =IFERROR(F40/$F$66,"")
A41: =+A23 -> 0 | B41: =IFERROR(VLOOKUP(H41,[1]SEMIELABORADOS!$A$2:$M$6000,2,0),"") | C41: =+A41 -> 0 | D41: =IFERROR(VLOOKUP(H41,[1]SEMIELABORADOS!$A$2:$M$6000,6,0),"") | E41: =IFERROR(VLOOKUP(H41,[1]SEMIELABORADOS!$A$2:$M$65536,10,0),"") | F41: =IFERROR(E41*C41,"") | G41: =IFERROR(F41/$F$66,"")
A43: UNIDADES | B43: MODI | C43: UNIDADES | D43: UND MEDIDA | E43: COSTO UNITARIO | F43: TOTAL COSTO | G43: % PREC. DEFINIDO | H43: CODIGOS
A44: =+A35 -> 0 | B44: =IFERROR(VLOOKUP(H44,[1]SEMIELABORADOS!$A$2:$M$6000,2,0),"") | C44: =+A44 -> 0 | D44: =IFERROR(VLOOKUP(H44,[1]SEMIELABORADOS!$A$2:$M$6000,6,0),"") | E44: =IFERROR(VLOOKUP(H44,[1]SEMIELABORADOS!$A$2:$M$65536,12,0),"") | F44: =IFERROR(E44*C44,"") | G44: =IFERROR(F44/$F$66,"")
A45: =+A36 -> 0 | B45: =IFERROR(VLOOKUP(H45,[1]SEMIELABORADOS!$A$2:$M$6000,2,0),"") | C45: =+A45 -> 0 | D45: =IFERROR(VLOOKUP(H45,[1]SEMIELABORADOS!$A$2:$M$6000,6,0),"") | E45: =IFERROR(VLOOKUP(H45,[1]SEMIELABORADOS!$A$2:$M$65536,12,0),"") | F45: =IFERROR(E45*C45,"") | G45: =IFERROR(F45/$F$66,"")
...

Sheet Batido
C1: SERVICIOS DE PASTELERIA S.A. | H1: CÓDIGO:
C2: ESPECIFICACION DE RECETA | H2: REVISIÓN:
C3: SE00429 Batido queque limon spoon | H3: FECHA DE APROBACIÓN:
C4: Elaborado | D4: Juan Pablo Brenes , chef
C5: Aprobado | D5: Esteban Cartin, Gte Manufactura
A6: AREA QUE PRODUCE: | D6: BATIDOS | G6: AREA QUE EMPACA: | I6: BATIDOS
A7: # Código | B7: # Codigo Netsuite | C7: Descripción del ingrediente | D7: Marca | E7: Unidad Internacional | G7: Medida alternativa | I7: Costo - Referencia
E8: Cantidad | F8: Unidad medida | G8: Cantidad | H8: Unidad medida | I8: Colones
A9: NUEVO | B9: SE00428 | C9: PREMEZCLA QUEQUE LIMON | D9: FAS | E9: 6120 | F9: g
A10: 1210482 | B10: MP10005 | C10: Huevo Liquido Refrigerado | D10: INNOVO | E10: 1800 | F10: g
A11: NUEVO | B11: NUEVO | C11: GALON JUGO LIMON NATURAL | E11: 1500 | F11: g
A12: 11400047 | B12: MP10030 | C12: LECHE 2% PASTEURIZADA (UND) | D12: DOS PINOS | E12: 800 | F12: g
A13: 119000026 | B13: MP10357 | C13: Semilla Amapola | E13: 50 | F13: g
D16: Cantidad | E16: Unidad
A17: PESO TOTAL OBTENIDO | D17: 10000 | E17: g | F17: Tiempo de Horneo:
A18: TIEMPO TOTAL DE PREPARACION | D18: 8 | E18: min | F18: Horno:
A19: CANTIDAD DE PORCIONES OBTENIDAS | D19: =D17/D20 -> 66.666667 | E19: ud | F19: Temperatura de Horneo:
A20: PESO DE CADA PORCIÓN | D20: 150 | E20: g | F20: Otros
A21: MERMA | D21: =SUM(E9:E12)-D17 -> 220 | E21: g
A22: PROCEDIMIENTO DE PREPARACION DE LA RECETA
A23: 1.- Cremar el azucar con la mantequilla, cuando este bien cremado agregar el huevo y mezclar.
A24: 2.- Despues incorporar en velocidad 1 el jugo de limon.
A25: 3.- Alternar entre la leche y todos los secos hasta incorporar.
A26: 4.- Dosificar
A29: CONTROL DE CAMBIOS

Sheet Costo Batido 
E1: Precio Local | F1: Costo MP | G1: Costo EM | H1: Costo MO
E2: =IFERROR(O62,"") -> 18825.612 | F2: =IFERROR(H53,"") -> 17286.042 | G2: =IFERROR(H54,"") -> 111.57029 | H2: =IFERROR(H56,"") -> 732
A5: ESTRUCTURA DE COSTOS
F6: Fecha: | H6: =TODAY() -> 45679
A7: UNIDADES | B7: DESCRIPCION MAT.PRIMA | C7: UNIDADES | D7: UND MEDIDA | E7: COSTO UNITARIO | F7: TOTAL COSTO | G7: % PREC. DEFINIDO | H7: CODIGOS
A8: 1800 | B8: =IFERROR(VLOOKUP(H8,'[1]Consolidado MP Planta'!$A$2:$M$823,3,0),"") -> HUEVO ENTERO PASTERI INNOVO (CAJA:10 K) | C8: =+A8 -> 1800 | D8: =IFERROR(VLOOKUP(H8,'[1]Consolidado MP Planta'!$A$2:$M$823,13,0),"") -> Gramos | E8: 2.36 | F8: =IFERROR(C8*E8,"") -> 4248 | G8: =IFERROR(F8/$F$66,"") -> 0.23300545 | H8: 1210482
A9: 1500 | B9: GALON JUGO LIMON NATURAL | C9: =+A9 -> 1500 | D9: Gramos | E9: 3 | F9: =IFERROR(C9*E9,"") -> 4500 | G9: =IFERROR(F9/$F$66,"") -> 0.24682781 | M9: Precio Jugo Limon aprox
A10: 800 | B10: =IFERROR(VLOOKUP(H10,'[1]Consolidado MP Planta'!$A$2:$M$823,3,0),"") -> LECHE 2% PASTEURIZADA (UND) | C10: =+A10 -> 800 | D10: =IFERROR(VLOOKUP(H10,'[1]Consolidado MP Planta'!$A$2:$M$823,13,0),"") -> Mililitros | E10: 0.55 | F10: =IFERROR(C10*E10,"") -> 440 | G10: =IFERROR(F10/$F$66,"") -> 0.024134275 | H10: 11400047
A11: 50 | B11: =IFERROR(VLOOKUP(H11,'[1]Consolidado MP Planta'!$A$2:$M$823,3,0),"") -> SEMILLA DE AMAPOLA (UND: 566 G) | C11: =+A11 -> 50 | D11: =IFERROR(VLOOKUP(H11,'[1]Consolidado MP Planta'!$A$2:$M$823,13,0),"") -> Gramos | E11: 9.41 | F11: =IFERROR(C11*E11,"") -> 470.5 | G11: =IFERROR(F11/$F$66,"") -> 0.025807219 | H11: 119000026
B12: =IFERROR(VLOOKUP(H12,'[1]Consolidado MP Planta'!$A$2:$M$823,3,0),"") | C12: =+A12 -> 0 | D12: =IFERROR(VLOOKUP(H12,'[1]Consolidado MP Planta'!$A$2:$M$823,13,0),"") | E12: =IFERROR(VLOOKUP(H12,'[1]Consolidado MP Planta'!$A$2:$M$823,12,0),"") | F12: =IFERROR(C12*E12,"") | G12: =IFERROR(F12/$F$66,"")
B13: =IFERROR(VLOOKUP(H13,'[1]Consolidado MP Planta'!$A$2:$M$823,3,0),"") | C13: =+A13 -> 0 | D13: =IFERROR(VLOOKUP(H13,'[1]Consolidado MP Planta'!$A$2:$M$823,13,0),"") | E13: =IFERROR(VLOOKUP(H13,'[1]Consolidado MP Planta'!$A$2:$M$823,12,0),"") | F13: =IFERROR(C13*E13,"") | G13: =IFERROR(F13/$F$66,"")
B14: =IFERROR(VLOOKUP(H14,'[1]Consolidado MP Planta'!$A$2:$M$823,3,0),"") | C14: =+A14 -> 0 | D14: =IFERROR(VLOOKUP(H14,'[1]Consolidado MP Planta'!$A$2:$M$823,13,0),"") | E14: =IFERROR(VLOOKUP(H14,'[1]Consolidado MP Planta'!$A$2:$M$823,12,0),"") | F14: =IFERROR(C14*E14,"") | G14: =IFERROR(F14/$F$66,"")
B15: =IFERROR(VLOOKUP(H15,'[2]ARTICULOS MP PLANTA'!$A$2:$G$589,2,0),"")
A16: UNIDADES | B16: MATERIA PRIMA SEMIELABORADOS | C16: UNIDADES | D16: UND MEDIDA | E16: COSTO UNITARIO | F16: TOTAL COSTO | G16: % PREC. DEFINIDO | H16: CODIGOS
A17: 6120 | B17: PREMEZCLA QUEQUE LIMON | C17: =+A17 -> 6120 | D17: Gramos | E17: =+'Costo Premezcla '!E69 -> 1.2463304 | F17: =IFERROR(E17*C17,"") -> 7627.542 | G17: =IFERROR(F17/$F$66,"") -> 0.41837544
B18: =IFERROR(VLOOKUP(H18,[1]SEMIELABORADOS!$A$2:$M$6000,2,0),"") | C18: =+A18 -> 0 | D18: =IFERROR(VLOOKUP(H18,[1]SEMIELABORADOS!$A$2:$M$6000,6,0),"") | E18: =IFERROR(VLOOKUP(H18,[1]SEMIELABORADOS!$A$2:$H$65536,8,0),"") | F18: =IFERROR(E18*C18,"") | G18: =IFERROR(F18/$F$66,"")
B19: =IFERROR(VLOOKUP(H19,[1]SEMIELABORADOS!$A$2:$M$6000,2,0),"") | C19: =+A19 -> 0 | D19: =IFERROR(VLOOKUP(H19,[1]SEMIELABORADOS!$A$2:$M$6000,6,0),"") | E19: =IFERROR(VLOOKUP(H19,[1]SEMIELABORADOS!$A$2:$H$65536,8,0),"") | F19: =IFERROR(E19*C19,"") | G19: =IFERROR(F19/$F$66,"")
B20: =IFERROR(VLOOKUP(H20,[1]SEMIELABORADOS!$A$2:$M$6000,2,0),"") | C20: =+A20 -> 0 | D20: =IFERROR(VLOOKUP(H20,[1]SEMIELABORADOS!$A$2:$M$6000,6,0),"") | E20: =IFERROR(VLOOKUP(H20,[1]SEMIELABORADOS!$A$2:$H$65536,8,0),"") | F20: =IFERROR(E20*C20,"") | G20: =IFERROR(F20/$F$66,"")
B21: =IFERROR(VLOOKUP(H21,[1]SEMIELABORADOS!$A$2:$M$6000,2,0),"") | C21: =+A21 -> 0 | D21: =IFERROR(VLOOKUP(H21,[1]SEMIELABORADOS!$A$2:$M$6000,6,0),"") | E21: =IFERROR(VLOOKUP(H21,[1]SEMIELABORADOS!$A$2:$H$65536,8,0),"") | F21: =IFERROR(E21*C21,"") | G21: =IFERROR(F21/$F$66,"")
B22: =IFERROR(VLOOKUP(H22,[1]SEMIELABORADOS!$A$2:$M$6000,2,0),"") | C22: =+A22 -> 0 | D22: =IFERROR(VLOOKUP(H22,[1]SEMIELABORADOS!$A$2:$M$6000,6,0),"") | E22: =IFERROR(VLOOKUP(H22,[1]SEMIELABORADOS!$A$2:$H$65536,8,0),"") | F22: =IFERROR(E22*C22,"") | G22: =IFERROR(F22/$F$66,"")
B23: =IFERROR(VLOOKUP(H23,[1]SEMIELABORADOS!$A$2:$M$6000,2,0),"") | C23: =+A23 -> 0 | D23: =IFERROR(VLOOKUP(H23,[1]SEMIELABORADOS!$A$2:$M$6000,6,0),"") | E23: =IFERROR(VLOOKUP(H23,[1]SEMIELABORADOS!$A$2:$H$65536,8,0),"") | F23: =IFERROR(E23*C23,"") | G23: =IFERROR(F23/$F$66,"")
B24: =IFERROR(VLOOKUP(H24,[1]SEMIELABORADOS!$A$2:$M$6000,2,0),"") | C24: =+A24 -> 0 | D24: =IFERROR(VLOOKUP(H24,[1]SEMIELABORADOS!$A$2:$M$6000,6,0),"") | E24: =IFERROR(VLOOKUP(H24,[1]SEMIELABORADOS!$A$2:$H$65536,8,0),"") | F24: =IFERROR(E24*C24,"") | G24: =IFERROR(F24/$F$66,"")
A26: UNIDADES | B26: EMPAQUE | C26: UNIDADES | D26: UND MEDIDA | E26: COSTO UNITARIO | F26: TOTAL COSTO | G26: % PREC. DEFINIDO | H26: CODIGOS
A27: 0 | B27: =IFERROR(VLOOKUP(H27,'[1]Consolidado MP Planta'!$A$2:$M$823,3,0),"") | C27: =+A27 -> 0 | D27: =IFERROR(VLOOKUP(H27,'[1]Consolidado MP Planta'!$A$2:$M$823,13,0),"") | E27: =IFERROR(VLOOKUP(H27,'[1]Consolidado MP Planta'!$A$2:$M$823,12,0),"") | F27: =IFERROR(C27*E27,"") | G27: =IFERROR(F27/$F$66,"")
B28: =IFERROR(VLOOKUP(H28,'[1]Consolidado MP Planta'!$A$2:$M$823,3,0),"") | C28: =+A28 -> 0 | D28: =IFERROR(VLOOKUP(H28,'[1]Consolidado MP Planta'!$A$2:$M$823,13,0),"") | E28: =IFERROR(VLOOKUP(H28,'[1]Consolidado MP Planta'!$A$2:$M$823,12,0),"") | F28: =IFERROR(C28*E28,"") | G28: =IFERROR(F28/$F$66,"")
B29: =IFERROR(VLOOKUP(H29,'[1]Consolidado MP Planta'!$A$2:$M$823,3,0),"") | C29: =+A29 -> 0 | D29: =IFERROR(VLOOKUP(H29,'[1]Consolidado MP Planta'!$A$2:$M$823,13,0),"") | E29: =IFERROR(VLOOKUP(H29,'[1]Consolidado MP Planta'!$A$2:$M$823,12,0),"") | F29: =IFERROR(C29*E29,"") | G29: =IFERROR(F29/$F$66,"")
B30: =IFERROR(VLOOKUP(H30,'[1]Consolidado MP Planta'!$A$2:$M$823,3,0),"") | C30: =+A30 -> 0 | D30: =IFERROR(VLOOKUP(H30,'[1]Consolidado MP Planta'!$A$2:$M$823,13,0),"") | E30: =IFERROR(VLOOKUP(H30,'[1]Consolidado MP Planta'!$A$2:$M$823,12,0),"") | F30: =IFERROR(C30*E30,"") | G30: =IFERROR(F30/$F$66,"")
B31: =IFERROR(VLOOKUP(H31,'[1]Consolidado MP Planta'!$A$2:$M$823,3,0),"") | C31: =+A31 -> 0 | D31: =IFERROR(VLOOKUP(H31,'[1]Consolidado MP Planta'!$A$2:$M$823,13,0),"") | E31: =IFERROR(VLOOKUP(H31,'[1]Consolidado MP Planta'!$A$2:$M$823,12,0),"") | F31: =IFERROR(C31*E31,"") | G31: =IFERROR(F31/$F$66,"")
B32: =IFERROR(VLOOKUP(H32,'[1]Consolidado MP Planta'!$A$2:$M$823,3,0),"") | C32: =+A32 -> 0 | D32: =IFERROR(VLOOKUP(H32,'[1]Consolidado MP Planta'!$A$2:$M$823,13,0),"") | E32: =IFERROR(VLOOKUP(H32,'[1]Consolidado MP Planta'!$A$2:$M$823,12,0),"") | F32: =IFERROR(C32*E32,"") | G32: =IFERROR(F32/$F$66,"")
A34: UNIDADES | B34: EMPAQUE SEMIELABORADOS | C34: UNIDADES | D34: UND MEDIDA | E34: COSTO UNITARIO | F34: TOTAL COSTO | G34: % PREC. DEFINIDO | H34: CODIGOS
A35: =+A17 -> 6120 | B35: PREMEZCLA QUEQUE LIMON | C35: =+A35 -> 6120 | D35: Gramos | E35: =+'Costo Premezcla '!E76 -> 0.018230439 | F35: =IFERROR(E35*C35,"") -> 111.57029 | G35: =IFERROR(F35/$F$66,"") -> 0.0061196998
A36: =+A18 -> 0 | B36: =IFERROR(VLOOKUP(H36,[1]SEMIELABORADOS!$A$2:$M$6000,2,0),"") | C36: =+A36 -> 0 | D36: =IFERROR(VLOOKUP(H36,[1]SEMIELABORADOS!$A$2:$M$6000,6,0),"") | E36: =IFERROR(VLOOKUP(H36,[1]SEMIELABORADOS!$A$2:$M$65536,10,0),"") | F36: =IFERROR(E36*C36,"") | G36: =IFERROR(F36/$F$66,"")
A37: =+A19 -> 0 | B37: =IFERROR(VLOOKUP(H37,[1]SEMIELABORADOS!$A$2:$M$6000,2,0),"") | C37: =+A37 -> 0 | D37: =IFERROR(VLOOKUP(H37,[1]SEMIELABORADOS!$A$2:$M$6000,6,0),"") | E37: =IFERROR(VLOOKUP(H37,[1]SEMIELABORADOS!$A$2:$M$65536,10,0),"") | F37: =IFERROR(E37*C37,"") | G37: =IFERROR(F37/$F$66,"")
A38: =+A20 -> 0 | B38: =IFERROR(VLOOKUP(H38,[1]SEMIELABORADOS!$A$2:$M$6000,2,0),"") | C38: =+A38 -> 0 | D38: =IFERROR(VLOOKUP(H38,[1]SEMIELABORADOS!$A$2:$M$6000,6,0),"") | E38: =IFERROR(VLOOKUP(H38,[1]SEMIELABORADOS!$A$2:$M$65536,10,0),"") | F38: =IFERROR(E38*C38,"") | G38: =IFERROR(F38/$F$66,"")
A39: =+A21 -> 0 | B39: =IFERROR(VLOOKUP(H39,[1]SEMIELABORADOS!$A$2:$M$6000,2,0),"") | C39: =+A39 -> 0 | D39: =IFERROR(VLOOKUP(H39,[1]SEMIELABORADOS!$A$2:$M$6000,6,0),"") | E39: =IFERROR(VLOOKUP(H39,[1]SEMIELABORADOS!$A$2:$M$65536,10,0),"") | F39: =IFERROR(E39*C39,"") | G39: =IFERROR(F39/$F$66,"")
A40: =+A22 -> 0 | B40: =IFERROR(VLOOKUP(H40,[1]SEMIELABORADOS!$A$2:$M$6000,2,0),"") | C40: =+A40 -> 0 | D40: =IFERROR(VLOOKUP(H40,[1]SEMIELABORADOS!$A$2:$M$6000,6,0),"") | E40: =IFERROR(VLOOKUP(H40,[1]SEMIELABORADOS!$A$2:$M$65536,10,0),"") | F40: =IFERROR(E40*C40,"") | G40: =IFERROR(F40/$F$66,"")
A41: =+A23 -> 0 | B41: =IFERROR(VLOOKUP(H41,[1]SEMIELABORADOS!$A$2:$M$6000,2,0),"") | C41: =+A41 -> 0 | D41: =IFERROR(VLOOKUP(H41,[1]SEMIELABORADOS!$A$2:$M$6000,6,0),"") | E41: =IFERROR(VLOOKUP(H41,[1]SEMIELABORADOS!$A$2:$M$65536,10,0),"") | F41: =IFERROR(E41*C41,"") | G41: =IFERROR(F41/$F$66,"")
A43: UNIDADES | B43: MODI | C43: UNIDADES | D43: UND MEDIDA | E43: COSTO UNITARIO | F43: TOTAL COSTO | G43: % PREC. DEFINIDO | H43: CODIGOS
A44: =+A35 -> 6120 | B44: PREMEZCLA QUEQUE LIMON | C44: =+A44 -> 6120 | D44: Gramos | E44: =+'Costo Premezcla '!E74 -> 0.039869281 | F44: =IFERROR(E44*C44,"") -> 244 | G44: =IFERROR(F44/$F$66,"") -> 0.013383552
A45: =+A36 -> 0 | B45: =IFERROR(VLOOKUP(H45,[1]SEMIELABORADOS!$A$2:$M$6000,2,0),"") | C45: =+A45 -> 0 | D45: =IFERROR(VLOOKUP(H45,[1]SEMIELABORADOS!$A$2:$M$6000,6,0),"") | E45: =IFERROR(VLOOKUP(H45,[1]SEMIELABORADOS!$A$2:$M$65536,12,0),"") | F45: =IFERROR(E45*C45,"") | G45: =IFERROR(F45/$F$66,"")
...

Sheet Hoja1
C1: SERVICIOS DE PASTELERIA S.A. | H1: CÓDIGO: | I1: ESP-RE-BAS-061
C2: ESPECIFICACION DE RECETA | H2: REVISIÓN: | I2: 01
C3: SE00626 Rosquete limon 900g | H3: FECHA DE APROBACIÓN: | I3: 45619
C4: Elaborado | D4: Javier Tong, Chef
C5: Aprobado | D5: Esteban Cartin, Gte Manufactura
A6: AREA QUE PRODUCE: | D6: Batidos | G6: AREA QUE EMPACA: | I6: Batidos
A7: # Código | B7: # Código Netsuite | C7: Descripción del ingrediente | D7: Marca | E7: Unidad Internacional | G7: Medida alternativa | I7: Costo - Referencia
E8: Cantidad | F8: Unidad medida | G8: Cantidad | H8: Unidad medida | I8: Colones
C9: Ensamble
B10: SE00429 | C10: BATIDO QUEQUE LIMON | D10: FAS | E10: 10000 | F10: g
A12: 95720 | C12: MEZCLA ENGRASE MOLDES (29800g) | D12: FAS | E12: 520 | F12: g
C21: Decoración
C28: Empaque
D38: Cantidad | E38: Unidad
A39: PESO TOTAL OBTENIDO | D39: 10000 | E39: g | F39: Tiempo de Horneo:
A40: TIEMPO TOTAL DE PREPARACION | D40: 25 | E40: min | F40: Horno:
A41: CANTIDAD DE PORCIONES OBTENIDAS | D41: 11.111111 | E41: ud | F41: Temperatura de Horneo:
A42: PESO DE CADA PORCIÓN | D42: 900 | E42: g | F42: Otros
A43: MERMA | D43: 0 | E43: g
A44: PROCEDIMIENTO DE PREPARACION DE LA RECETA
A45: 1.- Pesar 900g de batido en los moldes previamente engrasados.
A46: 2.- Llevar al horno a 180ºC 35 minutos.
A55: CONTROL DE CAMBIOS

Sheet Costo Rosquete 
E1: Precio Local | F1: Costo MP | G1: Costo EM | H1: Costo MO
E2: =IFERROR(O62,"") -> 1697.0857 | F2: =IFERROR(H53,"") -> 1651.2158 | G2: =IFERROR(H54,"") -> 10.041326 | H2: =IFERROR(H56,"") -> 204.066
A5: ESTRUCTURA DE COSTOS
F6: Fecha: | H6: =TODAY() -> 45679
A7: UNIDADES | B7: DESCRIPCION MAT.PRIMA | C7: UNIDADES | D7: UND MEDIDA | E7: COSTO UNITARIO | F7: TOTAL COSTO | G7: % PREC. DEFINIDO | H7: CODIGOS
B8: =IFERROR(VLOOKUP(H8,'[1]Consolidado MP Planta'!$A$2:$M$823,3,0),"") | C8: =+A8 -> 0 | D8: =IFERROR(VLOOKUP(H8,'[1]Consolidado MP Planta'!$A$2:$M$823,13,0),"") | E8: =IFERROR(VLOOKUP(H8,'[1]Consolidado MP Planta'!$A$2:$M$823,12,0),"") | F8: =IFERROR(C8*E8,"") | G8: =IFERROR(F8/$F$66,"")
B9: =IFERROR(VLOOKUP(H9,'[1]Consolidado MP Planta'!$A$2:$M$823,3,0),"") | C9: =+A9 -> 0 | D9: =IFERROR(VLOOKUP(H9,'[1]Consolidado MP Planta'!$A$2:$M$823,13,0),"") | E9: =IFERROR(VLOOKUP(H9,'[1]Consolidado MP Planta'!$A$2:$M$823,12,0),"") | F9: =IFERROR(C9*E9,"") | G9: =IFERROR(F9/$F$66,"")
B10: =IFERROR(VLOOKUP(H10,'[1]Consolidado MP Planta'!$A$2:$M$823,3,0),"") | C10: =+A10 -> 0 | D10: =IFERROR(VLOOKUP(H10,'[1]Consolidado MP Planta'!$A$2:$M$823,13,0),"") | E10: =IFERROR(VLOOKUP(H10,'[1]Consolidado MP Planta'!$A$2:$M$823,12,0),"") | F10: =IFERROR(C10*E10,"") | G10: =IFERROR(F10/$F$66,"")
B11: =IFERROR(VLOOKUP(H11,'[1]Consolidado MP Planta'!$A$2:$M$823,3,0),"") | C11: =+A11 -> 0 | D11: =IFERROR(VLOOKUP(H11,'[1]Consolidado MP Planta'!$A$2:$M$823,13,0),"") | E11: =IFERROR(VLOOKUP(H11,'[1]Consolidado MP Planta'!$A$2:$M$823,12,0),"") | F11: =IFERROR(C11*E11,"") | G11: =IFERROR(F11/$F$66,"")
B12: =IFERROR(VLOOKUP(H12,'[1]Consolidado MP Planta'!$A$2:$M$823,3,0),"") | C12: =+A12 -> 0 | D12: =IFERROR(VLOOKUP(H12,'[1]Consolidado MP Planta'!$A$2:$M$823,13,0),"") | E12: =IFERROR(VLOOKUP(H12,'[1]Consolidado MP Planta'!$A$2:$M$823,12,0),"") | F12: =IFERROR(C12*E12,"") | G12: =IFERROR(F12/$F$66,"")
B13: =IFERROR(VLOOKUP(H13,'[1]Consolidado MP Planta'!$A$2:$M$823,3,0),"") | C13: =+A13 -> 0 | D13: =IFERROR(VLOOKUP(H13,'[1]Consolidado MP Planta'!$A$2:$M$823,13,0),"") | E13: =IFERROR(VLOOKUP(H13,'[1]Consolidado MP Planta'!$A$2:$M$823,12,0),"") | F13: =IFERROR(C13*E13,"") | G13: =IFERROR(F13/$F$66,"")
B14: =IFERROR(VLOOKUP(H14,'[1]Consolidado MP Planta'!$A$2:$M$823,3,0),"") | C14: =+A14 -> 0 | D14: =IFERROR(VLOOKUP(H14,'[1]Consolidado MP Planta'!$A$2:$M$823,13,0),"") | E14: =IFERROR(VLOOKUP(H14,'[1]Consolidado MP Planta'!$A$2:$M$823,12,0),"") | F14: =IFERROR(C14*E14,"") | G14: =IFERROR(F14/$F$66,"")
B15: =IFERROR(VLOOKUP(H15,'[2]ARTICULOS MP PLANTA'!$A$2:$G$589,2,0),"")
A16: UNIDADES | B16: MATERIA PRIMA SEMIELABORADOS | C16: UNIDADES | D16: UND MEDIDA | E16: COSTO UNITARIO | F16: TOTAL COSTO | G16: % PREC. DEFINIDO | H16: CODIGOS
A17: 10000 | B17: BATIDO QUEQUE LIMON | C17: =+A17 -> 10000 | D17: Gramos | E17: =+'Costo Batido '!E69 -> 1.7286042 | F17: =IFERROR(E17*C17,"") -> 17286.042 | G17: =IFERROR(F17/$F$66,"") -> 0.84942238
A18: 520 | B18: MEZCLA ENGRASE MOLDES (29800g) | C18: =+A18 -> 520 | D18: Gramos | E18: 2.04 | F18: =IFERROR(E18*C18,"") -> 1060.8 | G18: =IFERROR(F18/$F$66,"") -> 0.05212687 | H18: 95720
B19: =IFERROR(VLOOKUP(H19,[1]SEMIELABORADOS!$A$2:$M$6000,2,0),"") | C19: =+A19 -> 0 | D19: =IFERROR(VLOOKUP(H19,[1]SEMIELABORADOS!$A$2:$M$6000,6,0),"") | E19: =IFERROR(VLOOKUP(H19,[1]SEMIELABORADOS!$A$2:$H$65536,8,0),"") | F19: =IFERROR(E19*C19,"") | G19: =IFERROR(F19/$F$66,"")
B20: =IFERROR(VLOOKUP(H20,[1]SEMIELABORADOS!$A$2:$M$6000,2,0),"") | C20: =+A20 -> 0 | D20: =IFERROR(VLOOKUP(H20,[1]SEMIELABORADOS!$A$2:$M$6000,6,0),"") | E20: =IFERROR(VLOOKUP(H20,[1]SEMIELABORADOS!$A$2:$H$65536,8,0),"") | F20: =IFERROR(E20*C20,"") | G20: =IFERROR(F20/$F$66,"")
B21: =IFERROR(VLOOKUP(H21,[1]SEMIELABORADOS!$A$2:$M$6000,2,0),"") | C21: =+A21 -> 0 | D21: =IFERROR(VLOOKUP(H21,[1]SEMIELABORADOS!$A$2:$M$6000,6,0),"") | E21: =IFERROR(VLOOKUP(H21,[1]SEMIELABORADOS!$A$2:$H$65536,8,0),"") | F21: =IFERROR(E21*C21,"") | G21: =IFERROR(F21/$F$66,"")
B22: =IFERROR(VLOOKUP(H22,[1]SEMIELABORADOS!$A$2:$M$6000,2,0),"") | C22: =+A22 -> 0 | D22: =IFERROR(VLOOKUP(H22,[1]SEMIELABORADOS!$A$2:$M$6000,6,0),"") | E22: =IFERROR(VLOOKUP(H22,[1]SEMIELABORADOS!$A$2:$H$65536,8,0),"") | F22: =IFERROR(E22*C22,"") | G22: =IFERROR(F22/$F$66,"")
B23: =IFERROR(VLOOKUP(H23,[1]SEMIELABORADOS!$A$2:$M$6000,2,0),"") | C23: =+A23 -> 0 | D23: =IFERROR(VLOOKUP(H23,[1]SEMIELABORADOS!$A$2:$M$6000,6,0),"") | E23: =IFERROR(VLOOKUP(H23,[1]SEMIELABORADOS!$A$2:$H$65536,8,0),"") | F23: =IFERROR(E23*C23,"") | G23: =IFERROR(F23/$F$66,"")
B24: =IFERROR(VLOOKUP(H24,[1]SEMIELABORADOS!$A$2:$M$6000,2,0),"") | C24: =+A24 -> 0 | D24: =IFERROR(VLOOKUP(H24,[1]SEMIELABORADOS!$A$2:$M$6000,6,0),"") | E24: =IFERROR(VLOOKUP(H24,[1]SEMIELABORADOS!$A$2:$H$65536,8,0),"") | F24: =IFERROR(E24*C24,"") | G24: =IFERROR(F24/$F$66,"")
A26: UNIDADES | B26: EMPAQUE | C26: UNIDADES | D26: UND MEDIDA | E26: COSTO UNITARIO | F26: TOTAL COSTO | G26: % PREC. DEFINIDO | H26: CODIGOS
A27: 0 | B27: =IFERROR(VLOOKUP(H27,'[1]Consolidado MP Planta'!$A$2:$M$823,3,0),"") | C27: =+A27 -> 0 | D27: =IFERROR(VLOOKUP(H27,'[1]Consolidado MP Planta'!$A$2:$M$823,13,0),"") | E27: =IFERROR(VLOOKUP(H27,'[1]Consolidado MP Planta'!$A$2:$M$823,12,0),"") | F27: =IFERROR(C27*E27,"") | G27: =IFERROR(F27/$F$66,"")
B28: =IFERROR(VLOOKUP(H28,'[1]Consolidado MP Planta'!$A$2:$M$823,3,0),"") | C28: =+A28 -> 0 | D28: =IFERROR(VLOOKUP(H28,'[1]Consolidado MP Planta'!$A$2:$M$823,13,0),"") | E28: =IFERROR(VLOOKUP(H28,'[1]Consolidado MP Planta'!$A$2:$M$823,12,0),"") | F28: =IFERROR(C28*E28,"") | G28: =IFERROR(F28/$F$66,"")
B29: =IFERROR(VLOOKUP(H29,'[1]Consolidado MP Planta'!$A$2:$M$823,3,0),"") | C29: =+A29 -> 0 | D29: =IFERROR(VLOOKUP(H29,'[1]Consolidado MP Planta'!$A$2:$M$823,13,0),"") | E29: =IFERROR(VLOOKUP(H29,'[1]Consolidado MP Planta'!$A$2:$M$823,12,0),"") | F29: =IFERROR(C29*E29,"") | G29: =IFERROR(F29/$F$66,"")
B30: =IFERROR(VLOOKUP(H30,'[1]Consolidado MP Planta'!$A$2:$M$823,3,0),"") | C30: =+A30 -> 0 | D30: =IFERROR(VLOOKUP(H30,'[1]Consolidado MP Planta'!$A$2:$M$823,13,0),"") | E30: =IFERROR(VLOOKUP(H30,'[1]Consolidado MP Planta'!$A$2:$M$823,12,0),"") | F30: =IFERROR(C30*E30,"") | G30: =IFERROR(F30/$F$66,"")
B31: =IFERROR(VLOOKUP(H31,'[1]Consolidado MP Planta'!$A$2:$M$823,3,0),"") | C31: =+A31 -> 0 | D31: =IFERROR(VLOOKUP(H31,'[1]Consolidado MP Planta'!$A$2:$M$823,13,0),"") | E31: =IFERROR(VLOOKUP(H31,'[1]Consolidado MP Planta'!$A$2:$M$823,12,0),"") | F31: =IFERROR(C31*E31,"") | G31: =IFERROR(F31/$F$66,"")
B32: =IFERROR(VLOOKUP(H32,'[1]Consolidado MP Planta'!$A$2:$M$823,3,0),"") | C32: =+A32 -> 0 | D32: =IFERROR(VLOOKUP(H32,'[1]Consolidado MP Planta'!$A$2:$M$823,13,0),"") | E32: =IFERROR(VLOOKUP(H32,'[1]Consolidado MP Planta'!$A$2:$M$823,12,0),"") | F32: =IFERROR(C32*E32,"") | G32: =IFERROR(F32/$F$66,"")
A34: UNIDADES | B34: EMPAQUE SEMIELABORADOS | C34: UNIDADES | D34: UND MEDIDA | E34: COSTO UNITARIO | F34: TOTAL COSTO | G34: % PREC. DEFINIDO | H34: CODIGOS
A35: =+A17 -> 10000 | B35: BATIDO QUEQUE LIMON | C35: =+A35 -> 10000 | D35: Gramos | E35: =+'Costo Batido '!E76 -> 0.011157029 | F35: =IFERROR(E35*C35,"") -> 111.57029 | G35: =IFERROR(F35/$F$66,"") -> 0.0054824753
A36: =+A18 -> 520 | B36: MEZCLA ENGRASE MOLDES (29800g) | C36: =+A36 -> 520 | D36: Gramos | E36: 0 | F36: =IFERROR(E36*C36,"") -> 0 | G36: =IFERROR(F36/$F$66,"") -> 0
A37: =+A19 -> 0 | B37: =IFERROR(VLOOKUP(H37,[1]SEMIELABORADOS!$A$2:$M$6000,2,0),"") | C37: =+A37 -> 0 | D37: =IFERROR(VLOOKUP(H37,[1]SEMIELABORADOS!$A$2:$M$6000,6,0),"") | E37: =IFERROR(VLOOKUP(H37,[1]SEMIELABORADOS!$A$2:$M$65536,10,0),"") | F37: =IFERROR(E37*C37,"") | G37: =IFERROR(F37/$F$66,"")
A38: =+A20 -> 0 | B38: =IFERROR(VLOOKUP(H38,[1]SEMIELABORADOS!$A$2:$M$6000,2,0),"") | C38: =+A38 -> 0 | D38: =IFERROR(VLOOKUP(H38,[1]SEMIELABORADOS!$A$2:$M$6000,6,0),"") | E38: =IFERROR(VLOOKUP(H38,[1]SEMIELABORADOS!$A$2:$M$65536,10,0),"") | F38: =IFERROR(E38*C38,"") | G38: =IFERROR(F38/$F$66,"")
A39: =+A21 -> 0 | B39: =IFERROR(VLOOKUP(H39,[1]SEMIELABORADOS!$A$2:$M$6000,2,0),"") | C39: =+A39 -> 0 | D39: =IFERROR(VLOOKUP(H39,[1]SEMIELABORADOS!$A$2:$M$6000,6,0),"") | E39: =IFERROR(VLOOKUP(H39,[1]SEMIELABORADOS!$A$2:$M$65536,10,0),"") | F39: =IFERROR(E39*C39,"") | G39: =IFERROR(F39/$F$66,"")
A40: =+A22 -> 0 | B40: =IFERROR(VLOOKUP(H40,[1]SEMIELABORADOS!$A$2:$M$6000,2,0),"") | C40: =+A40 -> 0 | D40: =IFERROR(VLOOKUP(H40,[1]SEMIELABORADOS!$A$2:$M$6000,6,0),"") | E40: =IFERROR(VLOOKUP(H40,[1]SEMIELABORADOS!$A$2:$M$65536,10,0),"") | F40: =IFERROR(E40*C40,"") | G40: =IFERROR(F40/$F$66,"")
A41: =+A23 -> 0 | B41: =IFERROR(VLOOKUP(H41,[1]SEMIELABORADOS!$A$2:$M$6000,2,0),"") | C41: =+A41 -> 0 | D41: =IFERROR(VLOOKUP(H41,[1]SEMIELABORADOS!$A$2:$M$6000,6,0),"") | E41: =IFERROR(VLOOKUP(H41,[1]SEMIELABORADOS!$A$2:$M$65536,10,0),"") | F41: =IFERROR(E41*C41,"") | G41: =IFERROR(F41/$F$66,"")
A43: UNIDADES | B43: MODI | C43: UNIDADES | D43: UND MEDIDA | E43: COSTO UNITARIO | F43: TOTAL COSTO | G43: % PREC. DEFINIDO | H43: CODIGOS
A44: =+A35 -> 10000 | B44: BATIDO QUEQUE LIMON | C44: =+A44 -> 10000 | D44: Gramos | E44: =+'Costo Batido '!E74 -> 0.0732 | F44: =IFERROR(E44*C44,"") -> 732 | G44: =IFERROR(F44/$F$66,"") -> 0.035969899
A45: =+A36 -> 520 | B45: MEZCLA ENGRASE MOLDES (29800g) | C45: =+A45 -> 520 | D45: Gramos | E45: 0.02 | F45: =IFERROR(E45*C45,"") -> 10.4 | G45: =IFERROR(F45/$F$66,"") -> 0.00051104774
...

Sheet Costo Empaque 
E1: Precio Local | F1: Costo MP | G1: Costo EM | H1: Costo MO
E2: =IFERROR(O62,"") -> 2570.2455 | F2: =IFERROR(H53,"") -> 1651.2158 | G2: =IFERROR(H54,"") -> 376.68041 | H2: =IFERROR(H56,"") -> 278.011
A5: ESTRUCTURA DE COSTOS
F6: Fecha: | H6: =TODAY() -> 45679
A7: UNIDADES | B7: DESCRIPCION MAT.PRIMA | C7: UNIDADES | D7: UND MEDIDA | E7: COSTO UNITARIO | F7: TOTAL COSTO | G7: % PREC. DEFINIDO | H7: CODIGOS
B8: =IFERROR(VLOOKUP(H8,'[1]Consolidado MP Planta'!$A$2:$M$823,3,0),"") | C8: =+A8 -> 0 | D8: =IFERROR(VLOOKUP(H8,'[1]Consolidado MP Planta'!$A$2:$M$823,13,0),"") | E8: =IFERROR(VLOOKUP(H8,'[1]Consolidado MP Planta'!$A$2:$M$823,12,0),"") | F8: =IFERROR(C8*E8,"") | G8: =IFERROR(F8/$F$66,"")
B9: =IFERROR(VLOOKUP(H9,'[1]Consolidado MP Planta'!$A$2:$M$823,3,0),"") | C9: =+A9 -> 0 | D9: =IFERROR(VLOOKUP(H9,'[1]Consolidado MP Planta'!$A$2:$M$823,13,0),"") | E9: =IFERROR(VLOOKUP(H9,'[1]Consolidado MP Planta'!$A$2:$M$823,12,0),"") | F9: =IFERROR(C9*E9,"") | G9: =IFERROR(F9/$F$66,"")
B10: =IFERROR(VLOOKUP(H10,'[1]Consolidado MP Planta'!$A$2:$M$823,3,0),"") | C10: =+A10 -> 0 | D10: =IFERROR(VLOOKUP(H10,'[1]Consolidado MP Planta'!$A$2:$M$823,13,0),"") | E10: =IFERROR(VLOOKUP(H10,'[1]Consolidado MP Planta'!$A$2:$M$823,12,0),"") | F10: =IFERROR(C10*E10,"") | G10: =IFERROR(F10/$F$66,"")
B11: =IFERROR(VLOOKUP(H11,'[1]Consolidado MP Planta'!$A$2:$M$823,3,0),"") | C11: =+A11 -> 0 | D11: =IFERROR(VLOOKUP(H11,'[1]Consolidado MP Planta'!$A$2:$M$823,13,0),"") | E11: =IFERROR(VLOOKUP(H11,'[1]Consolidado MP Planta'!$A$2:$M$823,12,0),"") | F11: =IFERROR(C11*E11,"") | G11: =IFERROR(F11/$F$66,"")
B12: =IFERROR(VLOOKUP(H12,'[1]Consolidado MP Planta'!$A$2:$M$823,3,0),"") | C12: =+A12 -> 0 | D12: =IFERROR(VLOOKUP(H12,'[1]Consolidado MP Planta'!$A$2:$M$823,13,0),"") | E12: =IFERROR(VLOOKUP(H12,'[1]Consolidado MP Planta'!$A$2:$M$823,12,0),"") | F12: =IFERROR(C12*E12,"") | G12: =IFERROR(F12/$F$66,"")
B13: =IFERROR(VLOOKUP(H13,'[1]Consolidado MP Planta'!$A$2:$M$823,3,0),"") | C13: =+A13 -> 0 | D13: =IFERROR(VLOOKUP(H13,'[1]Consolidado MP Planta'!$A$2:$M$823,13,0),"") | E13: =IFERROR(VLOOKUP(H13,'[1]Consolidado MP Planta'!$A$2:$M$823,12,0),"") | F13: =IFERROR(C13*E13,"") | G13: =IFERROR(F13/$F$66,"")
B14: =IFERROR(VLOOKUP(H14,'[1]Consolidado MP Planta'!$A$2:$M$823,3,0),"") | C14: =+A14 -> 0 | D14: =IFERROR(VLOOKUP(H14,'[1]Consolidado MP Planta'!$A$2:$M$823,13,0),"") | E14: =IFERROR(VLOOKUP(H14,'[1]Consolidado MP Planta'!$A$2:$M$823,12,0),"") | F14: =IFERROR(C14*E14,"") | G14: =IFERROR(F14/$F$66,"")
B15: =IFERROR(VLOOKUP(H15,'[2]ARTICULOS MP PLANTA'!$A$2:$G$589,2,0),"")
A16: UNIDADES | B16: MATERIA PRIMA SEMIELABORADOS | C16: UNIDADES | D16: UND MEDIDA | E16: COSTO UNITARIO | F16: TOTAL COSTO | G16: % PREC. DEFINIDO | H16: CODIGOS
A17: 1 | B17: ROSQUETE LIMON 150G | C17: =+A17 -> 1 | D17: UND | E17: =+'Costo Rosquete '!H53 -> 1651.2158 | F17: =IFERROR(E17*C17,"") -> 1651.2158 | G17: =IFERROR(F17/$F$66,"") -> 0.7163873
B18: =IFERROR(VLOOKUP(H18,[1]SEMIELABORADOS!$A$2:$M$6000,2,0),"") | C18: =+A18 -> 0 | D18: =IFERROR(VLOOKUP(H18,[1]SEMIELABORADOS!$A$2:$M$6000,6,0),"") | E18: =IFERROR(VLOOKUP(H18,[1]SEMIELABORADOS!$A$2:$H$65536,8,0),"") | F18: =IFERROR(E18*C18,"") | G18: =IFERROR(F18/$F$66,"")
B19: =IFERROR(VLOOKUP(H19,[1]SEMIELABORADOS!$A$2:$M$6000,2,0),"") | C19: =+A19 -> 0 | D19: =IFERROR(VLOOKUP(H19,[1]SEMIELABORADOS!$A$2:$M$6000,6,0),"") | E19: =IFERROR(VLOOKUP(H19,[1]SEMIELABORADOS!$A$2:$H$65536,8,0),"") | F19: =IFERROR(E19*C19,"") | G19: =IFERROR(F19/$F$66,"")
B20: =IFERROR(VLOOKUP(H20,[1]SEMIELABORADOS!$A$2:$M$6000,2,0),"") | C20: =+A20 -> 0 | D20: =IFERROR(VLOOKUP(H20,[1]SEMIELABORADOS!$A$2:$M$6000,6,0),"") | E20: =IFERROR(VLOOKUP(H20,[1]SEMIELABORADOS!$A$2:$H$65536,8,0),"") | F20: =IFERROR(E20*C20,"") | G20: =IFERROR(F20/$F$66,"")
B21: =IFERROR(VLOOKUP(H21,[1]SEMIELABORADOS!$A$2:$M$6000,2,0),"") | C21: =+A21 -> 0 | D21: =IFERROR(VLOOKUP(H21,[1]SEMIELABORADOS!$A$2:$M$6000,6,0),"") | E21: =IFERROR(VLOOKUP(H21,[1]SEMIELABORADOS!$A$2:$H$65536,8,0),"") | F21: =IFERROR(E21*C21,"") | G21: =IFERROR(F21/$F$66,"")
B22: =IFERROR(VLOOKUP(H22,[1]SEMIELABORADOS!$A$2:$M$6000,2,0),"") | C22: =+A22 -> 0 | D22: =IFERROR(VLOOKUP(H22,[1]SEMIELABORADOS!$A$2:$M$6000,6,0),"") | E22: =IFERROR(VLOOKUP(H22,[1]SEMIELABORADOS!$A$2:$H$65536,8,0),"") | F22: =IFERROR(E22*C22,"") | G22: =IFERROR(F22/$F$66,"")
B23: =IFERROR(VLOOKUP(H23,[1]SEMIELABORADOS!$A$2:$M$6000,2,0),"") | C23: =+A23 -> 0 | D23: =IFERROR(VLOOKUP(H23,[1]SEMIELABORADOS!$A$2:$M$6000,6,0),"") | E23: =IFERROR(VLOOKUP(H23,[1]SEMIELABORADOS!$A$2:$H$65536,8,0),"") | F23: =IFERROR(E23*C23,"") | G23: =IFERROR(F23/$F$66,"")
B24: =IFERROR(VLOOKUP(H24,[1]SEMIELABORADOS!$A$2:$M$6000,2,0),"") | C24: =+A24 -> 0 | D24: =IFERROR(VLOOKUP(H24,[1]SEMIELABORADOS!$A$2:$M$6000,6,0),"") | E24: =IFERROR(VLOOKUP(H24,[1]SEMIELABORADOS!$A$2:$H$65536,8,0),"") | F24: =IFERROR(E24*C24,"") | G24: =IFERROR(F24/$F$66,"")
A26: UNIDADES | B26: EMPAQUE | C26: UNIDADES | D26: UND MEDIDA | E26: COSTO UNITARIO | F26: TOTAL COSTO | G26: % PREC. DEFINIDO | H26: CODIGOS
A27: 6 | B27: =IFERROR(VLOOKUP(H27,'[1]Consolidado MP Planta'!$A$2:$M$823,3,0),"") -> BOLSA CELOFAN 6 X 9 (KILO) | C27: =+A27 -> 6 | D27: =IFERROR(VLOOKUP(H27,'[1]Consolidado MP Planta'!$A$2:$M$823,13,0),"") -> Unidades | E27: 14.89 | F27: =IFERROR(C27*E27,"") -> 89.34 | G27: =IFERROR(F27/$F$66,"") -> 0.038760556 | H27: 1950895
A28: 6 | B28: =IFERROR(VLOOKUP(H28,'[1]Consolidado MP Planta'!$A$2:$M$823,3,0),"") -> ETIQUETA BLANCA R-153 (UND) | C28: =+A28 -> 6 | D28: =IFERROR(VLOOKUP(H28,'[1]Consolidado MP Planta'!$A$2:$M$823,13,0),"") -> Und | E28: 39 | F28: =IFERROR(C28*E28,"") -> 234 | G28: =IFERROR(F28/$F$66,"") -> 0.10152194 | H28: 701096
A29: 2 | B29: =IFERROR(VLOOKUP(H29,'[1]Consolidado MP Planta'!$A$2:$M$823,3,0),"") -> CAJA BLANCA MINI (PAQ:100 UND) | C29: =+A29 -> 2 | D29: =IFERROR(VLOOKUP(H29,'[1]Consolidado MP Planta'!$A$2:$M$823,13,0),"") -> Und | E29: 25.75 | F29: =IFERROR(C29*E29,"") -> 51.5 | G29: =IFERROR(F29/$F$66,"") -> 0.022343504 | H29: 1959752
B30: =IFERROR(VLOOKUP(H30,'[1]Consolidado MP Planta'!$A$2:$M$823,3,0),"") | C30: =+A30 -> 0 | D30: =IFERROR(VLOOKUP(H30,'[1]Consolidado MP Planta'!$A$2:$M$823,13,0),"") | E30: =IFERROR(VLOOKUP(H30,'[1]Consolidado MP Planta'!$A$2:$M$823,12,0),"") | F30: =IFERROR(C30*E30,"") | G30: =IFERROR(F30/$F$66,"")
B31: =IFERROR(VLOOKUP(H31,'[1]Consolidado MP Planta'!$A$2:$M$823,3,0),"") | C31: =+A31 -> 0 | D31: =IFERROR(VLOOKUP(H31,'[1]Consolidado MP Planta'!$A$2:$M$823,13,0),"") | E31: =IFERROR(VLOOKUP(H31,'[1]Consolidado MP Planta'!$A$2:$M$823,12,0),"") | F31: =IFERROR(C31*E31,"") | G31: =IFERROR(F31/$F$66,"")
B32: =IFERROR(VLOOKUP(H32,'[1]Consolidado MP Planta'!$A$2:$M$823,3,0),"") | C32: =+A32 -> 0 | D32: =IFERROR(VLOOKUP(H32,'[1]Consolidado MP Planta'!$A$2:$M$823,13,0),"") | E32: =IFERROR(VLOOKUP(H32,'[1]Consolidado MP Planta'!$A$2:$M$823,12,0),"") | F32: =IFERROR(C32*E32,"") | G32: =IFERROR(F32/$F$66,"")
A34: UNIDADES | B34: EMPAQUE SEMIELABORADOS | C34: UNIDADES | D34: UND MEDIDA | E34: COSTO UNITARIO | F34: TOTAL COSTO | G34: % PREC. DEFINIDO | H34: CODIGOS
A35: =+A17 -> 1 | B35: ROSQUETE LIMON 150G | C35: =+A35 -> 1 | D35: und | E35: =+'[3]Costo Rosquete'!H54 -> 1.8404114 | F35: =IFERROR(E35*C35,"") -> 1.8404114 | G35: =IFERROR(F35/$F$66,"") -> 0.00079847067
A36: =+A18 -> 0 | B36: =IFERROR(VLOOKUP(H36,[1]SEMIELABORADOS!$A$2:$M$6000,2,0),"") | C36: =+A36 -> 0 | D36: =IFERROR(VLOOKUP(H36,[1]SEMIELABORADOS!$A$2:$M$6000,6,0),"") | E36: =IFERROR(VLOOKUP(H36,[1]SEMIELABORADOS!$A$2:$M$65536,10,0),"") | F36: =IFERROR(E36*C36,"") | G36: =IFERROR(F36/$F$66,"")
A37: =+A19 -> 0 | B37: =IFERROR(VLOOKUP(H37,[1]SEMIELABORADOS!$A$2:$M$6000,2,0),"") | C37: =+A37 -> 0 | D37: =IFERROR(VLOOKUP(H37,[1]SEMIELABORADOS!$A$2:$M$6000,6,0),"") | E37: =IFERROR(VLOOKUP(H37,[1]SEMIELABORADOS!$A$2:$M$65536,10,0),"") | F37: =IFERROR(E37*C37,"") | G37: =IFERROR(F37/$F$66,"")
A38: =+A20 -> 0 | B38: =IFERROR(VLOOKUP(H38,[1]SEMIELABORADOS!$A$2:$M$6000,2,0),"") | C38: =+A38 -> 0 | D38: =IFERROR(VLOOKUP(H38,[1]SEMIELABORADOS!$A$2:$M$6000,6,0),"") | E38: =IFERROR(VLOOKUP(H38,[1]SEMIELABORADOS!$A$2:$M$65536,10,0),"") | F38: =IFERROR(E38*C38,"") | G38: =IFERROR(F38/$F$66,"")
A39: =+A21 -> 0 | B39: =IFERROR(VLOOKUP(H39,[1]SEMIELABORADOS!$A$2:$M$6000,2,0),"") | C39: =+A39 -> 0 | D39: =IFERROR(VLOOKUP(H39,[1]SEMIELABORADOS!$A$2:$M$6000,6,0),"") | E39: =IFERROR(VLOOKUP(H39,[1]SEMIELABORADOS!$A$2:$M$65536,10,0),"") | F39: =IFERROR(E39*C39,"") | G39: =IFERROR(F39/$F$66,"")
A40: =+A22 -> 0 | B40: =IFERROR(VLOOKUP(H40,[1]SEMIELABORADOS!$A$2:$M$6000,2,0),"") | C40: =+A40 -> 0 | D40: =IFERROR(VLOOKUP(H40,[1]SEMIELABORADOS!$A$2:$M$6000,6,0),"") | E40: =IFERROR(VLOOKUP(H40,[1]SEMIELABORADOS!$A$2:$M$65536,10,0),"") | F40: =IFERROR(E40*C40,"") | G40: =IFERROR(F40/$F$66,"")
A41: =+A23 -> 0 | B41: =IFERROR(VLOOKUP(H41,[1]SEMIELABORADOS!$A$2:$M$6000,2,0),"") | C41: =+A41 -> 0 | D41: =IFERROR(VLOOKUP(H41,[1]SEMIELABORADOS!$A$2:$M$6000,6,0),"") | E41: =IFERROR(VLOOKUP(H41,[1]SEMIELABORADOS!$A$2:$M$65536,10,0),"") | F41: =IFERROR(E41*C41,"") | G41: =IFERROR(F41/$F$66,"")
A43: UNIDADES | B43: MODI | C43: UNIDADES | D43: UND MEDIDA | E43: COSTO UNITARIO | F43: TOTAL COSTO | G43: % PREC. DEFINIDO | H43: CODIGOS
A44: =+A35 -> 1 | B44: ROSQUETE LIMON 150G | C44: =+A44 -> 1 | D44: und | E44: =+'[3]Costo Rosquete'!H56 -> 34.011 | F44: =IFERROR(E44*C44,"") -> 34.011 | G44: =IFERROR(F44/$F$66,"") -> 0.014755823
A45: =+A36 -> 0 | B45: =IFERROR(VLOOKUP(H45,[1]SEMIELABORADOS!$A$2:$M$6000,2,0),"") | C45: =+A45 -> 0 | D45: =IFERROR(VLOOKUP(H45,[1]SEMIELABORADOS!$A$2:$M$6000,6,0),"") | E45: =IFERROR(VLOOKUP(H45,[1]SEMIELABORADOS!$A$2:$M$65536,12,0),"") | F45: =IFERROR(E45*C45,"") | G45: =IFERROR(F45/$F$66,"")
...
