Workbook

Sheet Hoja1
C1: SERVICIOS DE PASTELERIA S.A. | H1: CÓDIGO: | I1: ESP-RE-PRES-034
C2: ESPECIFICACION DE RECETA | H2: REVISIÓN: | I2: 01
C3: SE00403 Premezcla Queque seco chocolate Spoon | H3: FECHA DE APROBACIÓN: | I3: 45617
C4: Elaborado | D4: Javier Tong, Chef
C5: Aprobado | D5: Esteban Cartin, Gte Manufactura
A6: AREA QUE PRODUCE: | D6: Premezclas | G6: AREA QUE EMPACA: | I6: Premezclas
A7: # Código | B7: # Código Netsuite | C7: Descripción del ingrediente | D7: Marca | E7: Unidad Internacional | G7: Medida alternativa | I7: Costo - Referencia
E8: Cantidad | F8: Unidad medida | G8: Cantidad | H8: Unidad medida | I8: Colones
C9: Ensamble
A10: 11200072 | B10: MP10478 | C10: HARINA SILVER CAKE | D10: FACHASSA | E10: 2170 | F10: g
A11: 90100131 | B11: SE00016 | C11: EMPAQUE AZUCAR INDUSTRIAL | D11: FAS | E11: 4500 | F11: g
A12: 11200073 | B12: MP10482 | C12: COCENTRADO DAWN CHOCOLATE | D12: DAWN | E12: 3330 | F12: g
C24: Decoración
C32: Empaque
A33: 1950708 | B33: EM10013 | C33: BOLSA 17x25 TRANSP KILO | E33: 1 | F33: ud
A34: 60100010 | B34: EM10133 | C34: ETIQUETA ROJA LETRA ALERJENO (UND) | E34: 1 | F34: ud
A35: 702123 | B35: EM10011 | C35: ETIQUETA BLANCA 2 5/8X1 15/16 (UND) | E35: 1 | F35: ud
D45: Cantidad | E45: Unidad
A46: PESO TOTAL OBTENIDO | D46: 10000 | E46: g | F46: Tiempo de Horneo:
A47: TIEMPO TOTAL DE PREPARACION | D47: 3 | E47: min | F47: Horno:
A48: CANTIDAD DE PORCIONES OBTENIDAS | D48: 1 | E48: ud | F48: Temperatura de Horneo:
A49: PESO DE CADA PORCIÓN | D49: 10000 | E49: g | F49: Otros
A50: MERMA | D50: 0 | E50: g
A51: PROCEDIMIENTO DE PREPARACION DE LA RECETA
A52: 1.- Pesar todos los ingredientes en la bolsa y etiquetar.
A60: CONTROL DE CAMBIOS

Sheet Costo Premezcla 
E1: Precio Local | F1: Costo MP | G1: Costo EM | H1: Costo MO
E2: =IFERROR(O62,"") -> 12955.916 | F2: =IFERROR(H53,"") -> 11651.1 | G2: =IFERROR(H54,"") -> 278.34705 | H2: =IFERROR(H56,"") -> 526.17312
A5: ESTRUCTURA DE COSTOS
F6: Fecha: | H6: =TODAY() -> 45749
A7: UNIDADES | B7: DESCRIPCION MAT.PRIMA | C7: UNIDADES | D7: UND MEDIDA | E7: COSTO UNITARIO | F7: TOTAL COSTO | G7: % PREC. DEFINIDO | H7: CODIGOS
A8: 2170 | B8: Harina Silver Cake | C8: =+A8 -> 2170 | D8: Gramos | E8: 0.63 | F8: =IFERROR(C8*E8,"") -> 1367.1 | G8: =IFERROR(F8/$F$66,"") -> 0.11073698 | H8: 11200072
A9: 3300 | B9: Concentrado Dawn Chocolate | C9: =+A9 -> 3300 | D9: Gramos | E9: 2.53 | F9: =IFERROR(C9*E9,"") -> 8349 | G9: =IFERROR(F9/$F$66,"") -> 0.6762805 | H9: 11200073
B10: =IFERROR(VLOOKUP(H10,'[1]Consolidado MP Planta'!$A$2:$M$823,3,0),"") | C10: =+A10 -> 0 | D10: =IFERROR(VLOOKUP(H10,'[1]Consolidado MP Planta'!$A$2:$M$823,13,0),"") | E10: =IFERROR(VLOOKUP(H10,'[1]Consolidado MP Planta'!$A$2:$M$823,12,0),"") | F10: =IFERROR(C10*E10,"") | G10: =IFERROR(F10/$F$66,"")
B11: =IFERROR(VLOOKUP(H11,'[1]Consolidado MP Planta'!$A$2:$M$823,3,0),"") | C11: =+A11 -> 0 | D11: =IFERROR(VLOOKUP(H11,'[1]Consolidado MP Planta'!$A$2:$M$823,13,0),"") | E11: =IFERROR(VLOOKUP(H11,'[1]Consolidado MP Planta'!$A$2:$M$823,12,0),"") | F11: =IFERROR(C11*E11,"") | G11: =IFERROR(F11/$F$66,"")
B12: =IFERROR(VLOOKUP(H12,'[1]Consolidado MP Planta'!$A$2:$M$823,3,0),"") | C12: =+A12 -> 0 | D12: =IFERROR(VLOOKUP(H12,'[1]Consolidado MP Planta'!$A$2:$M$823,13,0),"") | E12: =IFERROR(VLOOKUP(H12,'[1]Consolidado MP Planta'!$A$2:$M$823,12,0),"") | F12: =IFERROR(C12*E12,"") | G12: =IFERROR(F12/$F$66,"")
B13: =IFERROR(VLOOKUP(H13,'[1]Consolidado MP Planta'!$A$2:$M$823,3,0),"") | C13: =+A13 -> 0 | D13: =IFERROR(VLOOKUP(H13,'[1]Consolidado MP Planta'!$A$2:$M$823,13,0),"") | E13: =IFERROR(VLOOKUP(H13,'[1]Consolidado MP Planta'!$A$2:$M$823,12,0),"") | F13: =IFERROR(C13*E13,"") | G13: =IFERROR(F13/$F$66,"")
B14: =IFERROR(VLOOKUP(H14,'[1]Consolidado MP Planta'!$A$2:$M$823,3,0),"") | C14: =+A14 -> 0 | D14: =IFERROR(VLOOKUP(H14,'[1]Consolidado MP Planta'!$A$2:$M$823,13,0),"") | E14: =IFERROR(VLOOKUP(H14,'[1]Consolidado MP Planta'!$A$2:$M$823,12,0),"") | F14: =IFERROR(C14*E14,"") | G14: =IFERROR(F14/$F$66,"")
B15: =IFERROR(VLOOKUP(H15,'[2]ARTICULOS MP PLANTA'!$A$2:$G$589,2,0),"")
A16: UNIDADES | B16: MATERIA PRIMA SEMIELABORADOS | C16: UNIDADES | D16: UND MEDIDA | E16: COSTO UNITARIO | F16: TOTAL COSTO | G16: % PREC. DEFINIDO | H16: CODIGOS
A17: 4500 | B17: =IFERROR(VLOOKUP(H17,[1]SEMIELABORADOS!$A$2:$M$6000,2,0),"") -> AZUCAR BLANCO INDUSTRIAL KILO | C17: =+A17 -> 4500 | D17: =IFERROR(VLOOKUP(H17,[1]SEMIELABORADOS!$A$2:$M$6000,6,0),"") -> Gramo | E17: 0.43 | F17: =IFERROR(E17*C17,"") -> 1935 | G17: =IFERROR(F17/$F$66,"") -> 0.15673767 | H17: 90100131
B18: =IFERROR(VLOOKUP(H18,[1]SEMIELABORADOS!$A$2:$M$6000,2,0),"") | C18: =+A18 -> 0 | D18: =IFERROR(VLOOKUP(H18,[1]SEMIELABORADOS!$A$2:$M$6000,6,0),"") | F18: =IFERROR(E18*C18,"") -> 0 | G18: =IFERROR(F18/$F$66,"") -> 0
B19: =IFERROR(VLOOKUP(H19,[1]SEMIELABORADOS!$A$2:$M$6000,2,0),"") | C19: =+A19 -> 0 | D19: =IFERROR(VLOOKUP(H19,[1]SEMIELABORADOS!$A$2:$M$6000,6,0),"") | E19: =IFERROR(VLOOKUP(H19,[1]SEMIELABORADOS!$A$2:$H$65536,8,0),"") | F19: =IFERROR(E19*C19,"") | G19: =IFERROR(F19/$F$66,"")
B20: =IFERROR(VLOOKUP(H20,[1]SEMIELABORADOS!$A$2:$M$6000,2,0),"") | C20: =+A20 -> 0 | D20: =IFERROR(VLOOKUP(H20,[1]SEMIELABORADOS!$A$2:$M$6000,6,0),"") | E20: =IFERROR(VLOOKUP(H20,[1]SEMIELABORADOS!$A$2:$H$65536,8,0),"") | F20: =IFERROR(E20*C20,"") | G20: =IFERROR(F20/$F$66,"")
B21: =IFERROR(VLOOKUP(H21,[1]SEMIELABORADOS!$A$2:$M$6000,2,0),"") | C21: =+A21 -> 0 | D21: =IFERROR(VLOOKUP(H21,[1]SEMIELABORADOS!$A$2:$M$6000,6,0),"") | E21: =IFERROR(VLOOKUP(H21,[1]SEMIELABORADOS!$A$2:$H$65536,8,0),"") | F21: =IFERROR(E21*C21,"") | G21: =IFERROR(F21/$F$66,"")
B22: =IFERROR(VLOOKUP(H22,[1]SEMIELABORADOS!$A$2:$M$6000,2,0),"") | C22: =+A22 -> 0 | D22: =IFERROR(VLOOKUP(H22,[1]SEMIELABORADOS!$A$2:$M$6000,6,0),"") | E22: =IFERROR(VLOOKUP(H22,[1]SEMIELABORADOS!$A$2:$H$65536,8,0),"") | F22: =IFERROR(E22*C22,"") | G22: =IFERROR(F22/$F$66,"")
B23: =IFERROR(VLOOKUP(H23,[1]SEMIELABORADOS!$A$2:$M$6000,2,0),"") | C23: =+A23 -> 0 | D23: =IFERROR(VLOOKUP(H23,[1]SEMIELABORADOS!$A$2:$M$6000,6,0),"") | E23: =IFERROR(VLOOKUP(H23,[1]SEMIELABORADOS!$A$2:$H$65536,8,0),"") | F23: =IFERROR(E23*C23,"") | G23: =IFERROR(F23/$F$66,"")
B24: =IFERROR(VLOOKUP(H24,[1]SEMIELABORADOS!$A$2:$M$6000,2,0),"") | C24: =+A24 -> 0 | D24: =IFERROR(VLOOKUP(H24,[1]SEMIELABORADOS!$A$2:$M$6000,6,0),"") | E24: =IFERROR(VLOOKUP(H24,[1]SEMIELABORADOS!$A$2:$H$65536,8,0),"") | F24: =IFERROR(E24*C24,"") | G24: =IFERROR(F24/$F$66,"")
A26: UNIDADES | B26: EMPAQUE | C26: UNIDADES | D26: UND MEDIDA | E26: COSTO UNITARIO | F26: TOTAL COSTO | G26: % PREC. DEFINIDO | H26: CODIGOS
A27: 1 | B27: =IFERROR(VLOOKUP(H27,'[1]Consolidado MP Planta'!$A$2:$M$823,3,0),"") -> BOLSA 17x25 TRANSP KILO | C27: =+A27 -> 1 | D27: =IFERROR(VLOOKUP(H27,'[1]Consolidado MP Planta'!$A$2:$M$823,13,0),"") -> Und | E27: =IFERROR(VLOOKUP(H27,'[1]Consolidado MP Planta'!$A$2:$M$823,12,0),"") -> 47.619048 | F27: =IFERROR(C27*E27,"") -> 47.619048 | G27: =IFERROR(F27/$F$66,"") -> 0.0038572085 | H27: 1950708
A28: 1 | B28: =IFERROR(VLOOKUP(H28,'[1]Consolidado MP Planta'!$A$2:$M$823,3,0),"") -> ETIQUETA ROJA LETRA ALERJENO (UND) | C28: =+A28 -> 1 | D28: =IFERROR(VLOOKUP(H28,'[1]Consolidado MP Planta'!$A$2:$M$823,13,0),"") -> Und | E28: =IFERROR(VLOOKUP(H28,'[1]Consolidado MP Planta'!$A$2:$M$823,12,0),"") -> 3.6 | F28: =IFERROR(C28*E28,"") -> 3.6 | G28: =IFERROR(F28/$F$66,"") -> 0.00029160496 | H28: 60100010
A29: 1 | B29: =IFERROR(VLOOKUP(H29,'[1]Consolidado MP Planta'!$A$2:$M$823,3,0),"") -> ETIQUETA BLANCA 2 5/8X1 15/16 (UND) | C29: =+A29 -> 1 | D29: =IFERROR(VLOOKUP(H29,'[1]Consolidado MP Planta'!$A$2:$M$823,13,0),"") -> Und | E29: =IFERROR(VLOOKUP(H29,'[1]Consolidado MP Planta'!$A$2:$M$823,12,0),"") -> 2.128 | F29: =IFERROR(C29*E29,"") -> 2.128 | G29: =IFERROR(F29/$F$66,"") -> 0.00017237093 | H29: 0702123
B30: =IFERROR(VLOOKUP(H30,'[1]Consolidado MP Planta'!$A$2:$M$823,3,0),"") | C30: =+A30 -> 0 | D30: =IFERROR(VLOOKUP(H30,'[1]Consolidado MP Planta'!$A$2:$M$823,13,0),"") | E30: =IFERROR(VLOOKUP(H30,'[1]Consolidado MP Planta'!$A$2:$M$823,12,0),"") | F30: =IFERROR(C30*E30,"") | G30: =IFERROR(F30/$F$66,"")
B31: =IFERROR(VLOOKUP(H31,'[1]Consolidado MP Planta'!$A$2:$M$823,3,0),"") | C31: =+A31 -> 0 | D31: =IFERROR(VLOOKUP(H31,'[1]Consolidado MP Planta'!$A$2:$M$823,13,0),"") | E31: =IFERROR(VLOOKUP(H31,'[1]Consolidado MP Planta'!$A$2:$M$823,12,0),"") | F31: =IFERROR(C31*E31,"") | G31: =IFERROR(F31/$F$66,"")
B32: =IFERROR(VLOOKUP(H32,'[1]Consolidado MP Planta'!$A$2:$M$823,3,0),"") | C32: =+A32 -> 0 | D32: =IFERROR(VLOOKUP(H32,'[1]Consolidado MP Planta'!$A$2:$M$823,13,0),"") | E32: =IFERROR(VLOOKUP(H32,'[1]Consolidado MP Planta'!$A$2:$M$823,12,0),"") | F32: =IFERROR(C32*E32,"") | G32: =IFERROR(F32/$F$66,"")
A34: UNIDADES | B34: EMPAQUE SEMIELABORADOS | C34: UNIDADES | D34: UND MEDIDA | E34: COSTO UNITARIO | F34: TOTAL COSTO | G34: % PREC. DEFINIDO | H34: CODIGOS
A35: =+A17 -> 4500 | B35: =IFERROR(VLOOKUP(H35,[1]SEMIELABORADOS!$A$2:$M$6000,2,0),"") -> AZUCAR BLANCO INDUSTRIAL KILO | C35: =+A35 -> 4500 | D35: =IFERROR(VLOOKUP(H35,[1]SEMIELABORADOS!$A$2:$M$6000,6,0),"") -> Gramo | E35: 0.05 | F35: =IFERROR(E35*C35,"") -> 225 | G35: =IFERROR(F35/$F$66,"") -> 0.01822531 | H35: 90100131
A36: =+A18 -> 0 | B36: =IFERROR(VLOOKUP(H36,[1]SEMIELABORADOS!$A$2:$M$6000,2,0),"") | C36: =+A36 -> 0 | D36: =IFERROR(VLOOKUP(H36,[1]SEMIELABORADOS!$A$2:$M$6000,6,0),"") | E36: =IFERROR(VLOOKUP(H36,[1]SEMIELABORADOS!$A$2:$M$65536,10,0),"") | F36: =IFERROR(E36*C36,"") | G36: =IFERROR(F36/$F$66,"")
A37: =+A19 -> 0 | B37: =IFERROR(VLOOKUP(H37,[1]SEMIELABORADOS!$A$2:$M$6000,2,0),"") | C37: =+A37 -> 0 | D37: =IFERROR(VLOOKUP(H37,[1]SEMIELABORADOS!$A$2:$M$6000,6,0),"") | E37: =IFERROR(VLOOKUP(H37,[1]SEMIELABORADOS!$A$2:$M$65536,10,0),"") | F37: =IFERROR(E37*C37,"") | G37: =IFERROR(F37/$F$66,"")
A38: =+A20 -> 0 | B38: =IFERROR(VLOOKUP(H38,[1]SEMIELABORADOS!$A$2:$M$6000,2,0),"") | C38: =+A38 -> 0 | D38: =IFERROR(VLOOKUP(H38,[1]SEMIELABORADOS!$A$2:$M$6000,6,0),"") | E38: =IFERROR(VLOOKUP(H38,[1]SEMIELABORADOS!$A$2:$M$65536,10,0),"") | F38: =IFERROR(E38*C38,"") | G38: =IFERROR(F38/$F$66,"")
A39: =+A21 -> 0 | B39: =IFERROR(VLOOKUP(H39,[1]SEMIELABORADOS!$A$2:$M$6000,2,0),"") | C39: =+A39 -> 0 | D39: =IFERROR(VLOOKUP(H39,[1]SEMIELABORADOS!$A$2:$M$6000,6,0),"") | E39: =IFERROR(VLOOKUP(H39,[1]SEMIELABORADOS!$A$2:$M$65536,10,0),"") | F39: =IFERROR(E39*C39,"") | G39: =IFERROR(F39/$F$66,"")
A40: =+A22 -> 0 | B40: =IFERROR(VLOOKUP(H40,[1]SEMIELABORADOS!$A$2:$M$6000,2,0),"") | C40: =+A40 -> 0 | D40: =IFERROR(VLOOKUP(H40,[1]SEMIELABORADOS!$A$2:$M$6000,6,0),"") | E40: =IFERROR(VLOOKUP(H40,[1]SEMIELABORADOS!$A$2:$M$65536,10,0),"") | F40: =IFERROR(E40*C40,"") | G40: =IFERROR(F40/$F$66,"")
A41: =+A23 -> 0 | B41: =IFERROR(VLOOKUP(H41,[1]SEMIELABORADOS!$A$2:$M$6000,2,0),"") | C41: =+A41 -> 0 | D41: =IFERROR(VLOOKUP(H41,[1]SEMIELABORADOS!$A$2:$M$6000,6,0),"") | E41: =IFERROR(VLOOKUP(H41,[1]SEMIELABORADOS!$A$2:$M$65536,10,0),"") | F41: =IFERROR(E41*C41,"") | G41: =IFERROR(F41/$F$66,"")
A43: UNIDADES | B43: MODI | C43: UNIDADES | D43: UND MEDIDA | E43: COSTO UNITARIO | F43: TOTAL COSTO | G43: % PREC. DEFINIDO | H43: CODIGOS
A44: =+A35 -> 4500 | B44: =IFERROR(VLOOKUP(H44,[1]SEMIELABORADOS!$A$2:$M$6000,2,0),"") -> AZUCAR BLANCO INDUSTRIAL KILO | C44: =+A44 -> 4500 | D44: =IFERROR(VLOOKUP(H44,[1]SEMIELABORADOS!$A$2:$M$6000,6,0),"") -> Gramo | E44: =IFERROR(VLOOKUP(H44,[1]SEMIELABORADOS!$A$2:$M$65536,12,0),"") -> 0.076260694 | F44: =IFERROR(E44*C44,"") -> 343.17312 | G44: =IFERROR(F44/$F$66,"") -> 0.027797496 | H44: 90100131
A45: =+A36 -> 0 | B45: =IFERROR(VLOOKUP(H45,[1]SEMIELABORADOS!$A$2:$M$6000,2,0),"") | C45: =+A45 -> 0 | D45: =IFERROR(VLOOKUP(H45,[1]SEMIELABORADOS!$A$2:$M$6000,6,0),"") | E45: =IFERROR(VLOOKUP(H45,[1]SEMIELABORADOS!$A$2:$M$65536,12,0),"") | F45: =IFERROR(E45*C45,"") | G45: =IFERROR(F45/$F$66,"")
...

Sheet Costo batido
E1: Precio Local | F1: Costo MP | G1: Costo EM | H1: Costo MO
E2: =IFERROR(O62,"") -> 29471.916 | F2: =IFERROR(H53,"") -> 27810.1 | G2: =IFERROR(H54,"") -> 278.34705 | H2: =IFERROR(H56,"") -> 709.17312
A5: ESTRUCTURA DE COSTOS
F6: Fecha: | H6: =TODAY() -> 45749
A7: UNIDADES | B7: DESCRIPCION MAT.PRIMA | C7: UNIDADES | D7: UND MEDIDA | E7: COSTO UNITARIO | F7: TOTAL COSTO | G7: % PREC. DEFINIDO | H7: CODIGOS
A8: 3500 | B8: =IFERROR(VLOOKUP(H8,'[1]Consolidado MP Planta'!$A$2:$M$823,3,0),"") -> HUEVO ENTERO PASTERI INNOVO (CAJA:10 K) | C8: =+A8 -> 3500 | D8: =IFERROR(VLOOKUP(H8,'[1]Consolidado MP Planta'!$A$2:$M$823,13,0),"") -> Gramos | E8: 2.78 | F8: =IFERROR(C8*E8,"") -> 9730 | G8: =IFERROR(F8/$F$66,"") -> 0.33752319 | H8: 1210482
A9: 3000 | B9: =IFERROR(VLOOKUP(H9,'[1]Consolidado MP Planta'!$A$2:$M$823,3,0),"") -> ACEITE CAPULLO RBD (UND:17 L) | C9: =+A9 -> 3000 | D9: =IFERROR(VLOOKUP(H9,'[1]Consolidado MP Planta'!$A$2:$M$823,13,0),"") -> Mililitros | E9: 1.58 | F9: =IFERROR(C9*E9,"") -> 4740 | G9: =IFERROR(F9/$F$66,"") -> 0.16442548 | H9: 10100050
A10: 2250 | B10: =IFERROR(VLOOKUP(H10,'[1]Consolidado MP Planta'!$A$2:$M$823,3,0),"") -> AGUA PLANTA | C10: =+A10 -> 2250 | D10: =IFERROR(VLOOKUP(H10,'[1]Consolidado MP Planta'!$A$2:$M$823,13,0),"") -> Mililitros | E10: 0.1 | F10: =IFERROR(C10*E10,"") -> 225 | G10: =IFERROR(F10/$F$66,"") -> 0.0078050069 | H10: 10415
A11: 600 | B11: Mani Picado | C11: =+A11 -> 600 | D11: Gramos | E11: 2.44 | F11: =IFERROR(C11*E11,"") -> 1464 | G11: =IFERROR(F11/$F$66,"") -> 0.050784578 | H11: 11900030
B12: =IFERROR(VLOOKUP(H12,'[1]Consolidado MP Planta'!$A$2:$M$823,3,0),"") | C12: =+A12 -> 0 | D12: =IFERROR(VLOOKUP(H12,'[1]Consolidado MP Planta'!$A$2:$M$823,13,0),"") | E12: =IFERROR(VLOOKUP(H12,'[1]Consolidado MP Planta'!$A$2:$M$823,12,0),"") | F12: =IFERROR(C12*E12,"") | G12: =IFERROR(F12/$F$66,"")
B13: =IFERROR(VLOOKUP(H13,'[1]Consolidado MP Planta'!$A$2:$M$823,3,0),"") | C13: =+A13 -> 0 | D13: =IFERROR(VLOOKUP(H13,'[1]Consolidado MP Planta'!$A$2:$M$823,13,0),"") | E13: =IFERROR(VLOOKUP(H13,'[1]Consolidado MP Planta'!$A$2:$M$823,12,0),"") | F13: =IFERROR(C13*E13,"") | G13: =IFERROR(F13/$F$66,"")
B14: =IFERROR(VLOOKUP(H14,'[1]Consolidado MP Planta'!$A$2:$M$823,3,0),"") | C14: =+A14 -> 0 | D14: =IFERROR(VLOOKUP(H14,'[1]Consolidado MP Planta'!$A$2:$M$823,13,0),"") | E14: =IFERROR(VLOOKUP(H14,'[1]Consolidado MP Planta'!$A$2:$M$823,12,0),"") | F14: =IFERROR(C14*E14,"") | G14: =IFERROR(F14/$F$66,"")
B15: =IFERROR(VLOOKUP(H15,'[2]ARTICULOS MP PLANTA'!$A$2:$G$589,2,0),"")
A16: UNIDADES | B16: MATERIA PRIMA SEMIELABORADOS | C16: UNIDADES | D16: UND MEDIDA | E16: COSTO UNITARIO | F16: TOTAL COSTO | G16: % PREC. DEFINIDO | H16: CODIGOS
A17: 10000 | B17: Premezcla chocolate marmoleado Spoon | C17: =+A17 -> 10000 | D17: Gramos | E17: =+'Costo Premezcla '!E69 -> 1.16511 | F17: =IFERROR(E17*C17,"") -> 11651.1 | G17: =IFERROR(F17/$F$66,"") -> 0.40416407 | H17: NUEVO
B18: =IFERROR(VLOOKUP(H18,[1]SEMIELABORADOS!$A$2:$M$6000,2,0),"") | C18: =+A18 -> 0 | D18: =IFERROR(VLOOKUP(H18,[1]SEMIELABORADOS!$A$2:$M$6000,6,0),"") | E18: =IFERROR(VLOOKUP(H18,[1]SEMIELABORADOS!$A$2:$H$65536,8,0),"") | F18: =IFERROR(E18*C18,"") | G18: =IFERROR(F18/$F$66,"")
B19: =IFERROR(VLOOKUP(H19,[1]SEMIELABORADOS!$A$2:$M$6000,2,0),"") | C19: =+A19 -> 0 | D19: =IFERROR(VLOOKUP(H19,[1]SEMIELABORADOS!$A$2:$M$6000,6,0),"") | E19: =IFERROR(VLOOKUP(H19,[1]SEMIELABORADOS!$A$2:$H$65536,8,0),"") | F19: =IFERROR(E19*C19,"") | G19: =IFERROR(F19/$F$66,"")
B20: =IFERROR(VLOOKUP(H20,[1]SEMIELABORADOS!$A$2:$M$6000,2,0),"") | C20: =+A20 -> 0 | D20: =IFERROR(VLOOKUP(H20,[1]SEMIELABORADOS!$A$2:$M$6000,6,0),"") | E20: =IFERROR(VLOOKUP(H20,[1]SEMIELABORADOS!$A$2:$H$65536,8,0),"") | F20: =IFERROR(E20*C20,"") | G20: =IFERROR(F20/$F$66,"")
B21: =IFERROR(VLOOKUP(H21,[1]SEMIELABORADOS!$A$2:$M$6000,2,0),"") | C21: =+A21 -> 0 | D21: =IFERROR(VLOOKUP(H21,[1]SEMIELABORADOS!$A$2:$M$6000,6,0),"") | E21: =IFERROR(VLOOKUP(H21,[1]SEMIELABORADOS!$A$2:$H$65536,8,0),"") | F21: =IFERROR(E21*C21,"") | G21: =IFERROR(F21/$F$66,"")
B22: =IFERROR(VLOOKUP(H22,[1]SEMIELABORADOS!$A$2:$M$6000,2,0),"") | C22: =+A22 -> 0 | D22: =IFERROR(VLOOKUP(H22,[1]SEMIELABORADOS!$A$2:$M$6000,6,0),"") | E22: =IFERROR(VLOOKUP(H22,[1]SEMIELABORADOS!$A$2:$H$65536,8,0),"") | F22: =IFERROR(E22*C22,"") | G22: =IFERROR(F22/$F$66,"")
B23: =IFERROR(VLOOKUP(H23,[1]SEMIELABORADOS!$A$2:$M$6000,2,0),"") | C23: =+A23 -> 0 | D23: =IFERROR(VLOOKUP(H23,[1]SEMIELABORADOS!$A$2:$M$6000,6,0),"") | E23: =IFERROR(VLOOKUP(H23,[1]SEMIELABORADOS!$A$2:$H$65536,8,0),"") | F23: =IFERROR(E23*C23,"") | G23: =IFERROR(F23/$F$66,"")
B24: =IFERROR(VLOOKUP(H24,[1]SEMIELABORADOS!$A$2:$M$6000,2,0),"") | C24: =+A24 -> 0 | D24: =IFERROR(VLOOKUP(H24,[1]SEMIELABORADOS!$A$2:$M$6000,6,0),"") | E24: =IFERROR(VLOOKUP(H24,[1]SEMIELABORADOS!$A$2:$H$65536,8,0),"") | F24: =IFERROR(E24*C24,"") | G24: =IFERROR(F24/$F$66,"")
A26: UNIDADES | B26: EMPAQUE | C26: UNIDADES | D26: UND MEDIDA | E26: COSTO UNITARIO | F26: TOTAL COSTO | G26: % PREC. DEFINIDO | H26: CODIGOS
A27: 0 | B27: =IFERROR(VLOOKUP(H27,'[1]Consolidado MP Planta'!$A$2:$M$823,3,0),"") | C27: =+A27 -> 0 | D27: =IFERROR(VLOOKUP(H27,'[1]Consolidado MP Planta'!$A$2:$M$823,13,0),"") | E27: =IFERROR(VLOOKUP(H27,'[1]Consolidado MP Planta'!$A$2:$M$823,12,0),"") | F27: =IFERROR(C27*E27,"") | G27: =IFERROR(F27/$F$66,"")
B28: =IFERROR(VLOOKUP(H28,'[1]Consolidado MP Planta'!$A$2:$M$823,3,0),"") | C28: =+A28 -> 0 | D28: =IFERROR(VLOOKUP(H28,'[1]Consolidado MP Planta'!$A$2:$M$823,13,0),"") | E28: =IFERROR(VLOOKUP(H28,'[1]Consolidado MP Planta'!$A$2:$M$823,12,0),"") | F28: =IFERROR(C28*E28,"") | G28: =IFERROR(F28/$F$66,"")
B29: =IFERROR(VLOOKUP(H29,'[1]Consolidado MP Planta'!$A$2:$M$823,3,0),"") | C29: =+A29 -> 0 | D29: =IFERROR(VLOOKUP(H29,'[1]Consolidado MP Planta'!$A$2:$M$823,13,0),"") | E29: =IFERROR(VLOOKUP(H29,'[1]Consolidado MP Planta'!$A$2:$M$823,12,0),"") | F29: =IFERROR(C29*E29,"") | G29: =IFERROR(F29/$F$66,"")
B30: =IFERROR(VLOOKUP(H30,'[1]Consolidado MP Planta'!$A$2:$M$823,3,0),"") | C30: =+A30 -> 0 | D30: =IFERROR(VLOOKUP(H30,'[1]Consolidado MP Planta'!$A$2:$M$823,13,0),"") | E30: =IFERROR(VLOOKUP(H30,'[1]Consolidado MP Planta'!$A$2:$M$823,12,0),"") | F30: =IFERROR(C30*E30,"") | G30: =IFERROR(F30/$F$66,"")
B31: =IFERROR(VLOOKUP(H31,'[1]Consolidado MP Planta'!$A$2:$M$823,3,0),"") | C31: =+A31 -> 0 | D31: =IFERROR(VLOOKUP(H31,'[1]Consolidado MP Planta'!$A$2:$M$823,13,0),"") | E31: =IFERROR(VLOOKUP(H31,'[1]Consolidado MP Planta'!$A$2:$M$823,12,0),"") | F31: =IFERROR(C31*E31,"") | G31: =IFERROR(F31/$F$66,"")
B32: =IFERROR(VLOOKUP(H32,'[1]Consolidado MP Planta'!$A$2:$M$823,3,0),"") | C32: =+A32 -> 0 | D32: =IFERROR(VLOOKUP(H32,'[1]Consolidado MP Planta'!$A$2:$M$823,13,0),"") | E32: =IFERROR(VLOOKUP(H32,'[1]Consolidado MP Planta'!$A$2:$M$823,12,0),"") | F32: =IFERROR(C32*E32,"") | G32: =IFERROR(F32/$F$66,"")
A34: UNIDADES | B34: EMPAQUE SEMIELABORADOS | C34: UNIDADES | D34: UND MEDIDA | E34: COSTO UNITARIO | F34: TOTAL COSTO | G34: % PREC. DEFINIDO | H34: CODIGOS
A35: =+A17 -> 10000 | B35: Premezcla chocolate marmoleado Spoon | C35: =+A35 -> 10000 | D35: Gramos | E35: =+'Costo Premezcla '!E76 -> 0.027834705 | F35: =IFERROR(E35*C35,"") -> 278.34705 | G35: =IFERROR(F35/$F$66,"") -> 0.0096555584
A36: =+A18 -> 0 | B36: =IFERROR(VLOOKUP(H36,[1]SEMIELABORADOS!$A$2:$M$6000,2,0),"") | C36: =+A36 -> 0 | D36: =IFERROR(VLOOKUP(H36,[1]SEMIELABORADOS!$A$2:$M$6000,6,0),"") | E36: =IFERROR(VLOOKUP(H36,[1]SEMIELABORADOS!$A$2:$M$65536,10,0),"") | F36: =IFERROR(E36*C36,"") | G36: =IFERROR(F36/$F$66,"")
A37: =+A19 -> 0 | B37: =IFERROR(VLOOKUP(H37,[1]SEMIELABORADOS!$A$2:$M$6000,2,0),"") | C37: =+A37 -> 0 | D37: =IFERROR(VLOOKUP(H37,[1]SEMIELABORADOS!$A$2:$M$6000,6,0),"") | E37: =IFERROR(VLOOKUP(H37,[1]SEMIELABORADOS!$A$2:$M$65536,10,0),"") | F37: =IFERROR(E37*C37,"") | G37: =IFERROR(F37/$F$66,"")
A38: =+A20 -> 0 | B38: =IFERROR(VLOOKUP(H38,[1]SEMIELABORADOS!$A$2:$M$6000,2,0),"") | C38: =+A38 -> 0 | D38: =IFERROR(VLOOKUP(H38,[1]SEMIELABORADOS!$A$2:$M$6000,6,0),"") | E38: =IFERROR(VLOOKUP(H38,[1]SEMIELABORADOS!$A$2:$M$65536,10,0),"") | F38: =IFERROR(E38*C38,"") | G38: =IFERROR(F38/$F$66,"")
A39: =+A21 -> 0 | B39: =IFERROR(VLOOKUP(H39,[1]SEMIELABORADOS!$A$2:$M$6000,2,0),"") | C39: =+A39 -> 0 | D39: =IFERROR(VLOOKUP(H39,[1]SEMIELABORADOS!$A$2:$M$6000,6,0),"") | E39: =IFERROR(VLOOKUP(H39,[1]SEMIELABORADOS!$A$2:$M$65536,10,0),"") | F39: =IFERROR(E39*C39,"") | G39: =IFERROR(F39/$F$66,"")
A40: =+A22 -> 0 | B40: =IFERROR(VLOOKUP(H40,[1]SEMIELABORADOS!$A$2:$M$6000,2,0),"") | C40: =+A40 -> 0 | D40: =IFERROR(VLOOKUP(H40,[1]SEMIELABORADOS!$A$2:$M$6000,6,0),"") | E40: =IFERROR(VLOOKUP(H40,[1]SEMIELABORADOS!$A$2:$M$65536,10,0),"") | F40: =IFERROR(E40*C40,"") | G40: =IFERROR(F40/$F$66,"")
A41: =+A23 -> 0 | B41: =IFERROR(VLOOKUP(H41,[1]SEMIELABORADOS!$A$2:$M$6000,2,0),"") | C41: =+A41 -> 0 | D41: =IFERROR(VLOOKUP(H41,[1]SEMIELABORADOS!$A$2:$M$6000,6,0),"") | E41: =IFERROR(VLOOKUP(H41,[1]SEMIELABORADOS!$A$2:$M$65536,10,0),"") | F41: =IFERROR(E41*C41,"") | G41: =IFERROR(F41/$F$66,"")
A43: UNIDADES | B43: MODI | C43: UNIDADES | D43: UND MEDIDA | E43: COSTO UNITARIO | F43: TOTAL COSTO | G43: % PREC. DEFINIDO | H43: CODIGOS
A44: =+A35 -> 10000 | B44: Premezcla chocolate marmoleado Spoon | C44: =+A44 -> 10000 | D44: Gramos | E44: =+'Costo Premezcla '!E74 -> 0.052617312 | F44: =IFERROR(E44*C44,"") -> 526.17312 | G44: =IFERROR(F44/$F$66,"") -> 0.018252377
A45: =+A36 -> 0 | B45: =IFERROR(VLOOKUP(H45,[1]SEMIELABORADOS!$A$2:$M$6000,2,0),"") | C45: =+A45 -> 0 | D45: =IFERROR(VLOOKUP(H45,[1]SEMIELABORADOS!$A$2:$M$6000,6,0),"") | E45: =IFERROR(VLOOKUP(H45,[1]SEMIELABORADOS!$A$2:$M$65536,12,0),"") | F45: =IFERROR(E45*C45,"") | G45: =IFERROR(F45/$F$66,"")
...

Sheet Costo Rosquete 
E1: Precio Local | F1: Costo MP | G1: Costo EM | H1: Costo MO
E2: =IFERROR(O61,"") -> 1228.1559 | F2: =IFERROR(H52,"") -> 1214.9707 | G2: =IFERROR(H53,"") -> 9.8533658 | H2: =IFERROR(H55,"") -> 54.218254
M4: =34/3500 -> 0.0097142857
A5: ESTRUCTURA DE COSTOS | M5: =+M4*535 -> 5.1971429
F6: Fecha: | H6: =TODAY() -> 45749
A7: UNIDADES | B7: DESCRIPCION MAT.PRIMA | C7: UNIDADES | D7: UND MEDIDA | E7: COSTO UNITARIO | F7: TOTAL COSTO | G7: % PREC. DEFINIDO | H7: CODIGOS
A8: 1120 | B8: PRESERVANTE NATALUX | C8: =+A8 -> 1120 | D8: Gramos | E8: 5.19 | F8: =IFERROR(C8*E8,"") -> 5812.8 | G8: =IFERROR(F8/$F$65,"") -> 0.14436461 | H8: NUEVO | M8: TP 535
A9: 690 | B9: Mani Picado | H9: 11900030
A10: 690 | B10: Mani Picado | C10: =+A10 -> 690 | D10: Gramos | E10: =+'Costo batido'!E11 -> 2.44 | F10: =IFERROR(C10*E10,"") -> 1683.6 | G10: =IFERROR(F10/$F$65,"") -> 0.041813285 | H10: 11900030
B11: =IFERROR(VLOOKUP(H11,'[1]Consolidado MP Planta'!$A$2:$M$823,3,0),"") | C11: =+A11 -> 0 | D11: =IFERROR(VLOOKUP(H11,'[1]Consolidado MP Planta'!$A$2:$M$823,13,0),"") | E11: =IFERROR(VLOOKUP(H11,'[1]Consolidado MP Planta'!$A$2:$M$823,12,0),"") | F11: =IFERROR(C11*E11,"") | G11: =IFERROR(F11/$F$65,"")
B12: =IFERROR(VLOOKUP(H12,'[1]Consolidado MP Planta'!$A$2:$M$823,3,0),"") | C12: =+A12 -> 0 | D12: =IFERROR(VLOOKUP(H12,'[1]Consolidado MP Planta'!$A$2:$M$823,13,0),"") | E12: =IFERROR(VLOOKUP(H12,'[1]Consolidado MP Planta'!$A$2:$M$823,12,0),"") | F12: =IFERROR(C12*E12,"") | G12: =IFERROR(F12/$F$65,"")
B13: =IFERROR(VLOOKUP(H13,'[1]Consolidado MP Planta'!$A$2:$M$823,3,0),"") | C13: =+A13 -> 0 | D13: =IFERROR(VLOOKUP(H13,'[1]Consolidado MP Planta'!$A$2:$M$823,13,0),"") | E13: =IFERROR(VLOOKUP(H13,'[1]Consolidado MP Planta'!$A$2:$M$823,12,0),"") | F13: =IFERROR(C13*E13,"") | G13: =IFERROR(F13/$F$65,"")
B14: =IFERROR(VLOOKUP(H14,'[2]ARTICULOS MP PLANTA'!$A$2:$G$589,2,0),"")
A15: UNIDADES | B15: MATERIA PRIMA SEMIELABORADOS | C15: UNIDADES | D15: UND MEDIDA | E15: COSTO UNITARIO | F15: TOTAL COSTO | G15: % PREC. DEFINIDO | H15: CODIGOS
A16: 19350 | B16: Batido queque chocolate con mani Spoon | C16: =+A16 -> 19350 | D16: Gramos | E16: =+'Costo batido'!E69 -> 1.4372145 | F16: =IFERROR(E16*C16,"") -> 27810.1 | G16: =IFERROR(F16/$F$65,"") -> 0.69068165 | H16: NUEVO
A17: 1600 | B17: =IFERROR(VLOOKUP(H17,[1]SEMIELABORADOS!$A$2:$M$6000,2,0),"") -> MEZCLA P/ENGRASE MOLDES KILO | C17: =+A17 -> 1600 | D17: =IFERROR(VLOOKUP(H17,[1]SEMIELABORADOS!$A$2:$M$6000,6,0),"") -> Gramo | E17: 2.04 | F17: =IFERROR(E17*C17,"") -> 3264 | G17: =IFERROR(F17/$F$65,"") -> 0.081063531 | H17: 902000019
A18: 0 | C18: =+A18 -> 0 | D18: Gramos | E18: 0 | F18: =IFERROR(E18*C18,"") -> 0 | G18: =IFERROR(F18/$F$65,"") -> 0
B19: =IFERROR(VLOOKUP(H19,[1]SEMIELABORADOS!$A$2:$M$6000,2,0),"") | C19: =+A19 -> 0 | D19: =IFERROR(VLOOKUP(H19,[1]SEMIELABORADOS!$A$2:$M$6000,6,0),"") | E19: =IFERROR(VLOOKUP(H19,[1]SEMIELABORADOS!$A$2:$H$65536,8,0),"") | F19: =IFERROR(E19*C19,"") | G19: =IFERROR(F19/$F$65,"")
B20: =IFERROR(VLOOKUP(H20,[1]SEMIELABORADOS!$A$2:$M$6000,2,0),"") | C20: =+A20 -> 0 | D20: =IFERROR(VLOOKUP(H20,[1]SEMIELABORADOS!$A$2:$M$6000,6,0),"") | E20: =IFERROR(VLOOKUP(H20,[1]SEMIELABORADOS!$A$2:$H$65536,8,0),"") | F20: =IFERROR(E20*C20,"") | G20: =IFERROR(F20/$F$65,"")
B21: =IFERROR(VLOOKUP(H21,[1]SEMIELABORADOS!$A$2:$M$6000,2,0),"") | C21: =+A21 -> 0 | D21: =IFERROR(VLOOKUP(H21,[1]SEMIELABORADOS!$A$2:$M$6000,6,0),"") | E21: =IFERROR(VLOOKUP(H21,[1]SEMIELABORADOS!$A$2:$H$65536,8,0),"") | F21: =IFERROR(E21*C21,"") | G21: =IFERROR(F21/$F$65,"")
B22: =IFERROR(VLOOKUP(H22,[1]SEMIELABORADOS!$A$2:$M$6000,2,0),"") | C22: =+A22 -> 0 | D22: =IFERROR(VLOOKUP(H22,[1]SEMIELABORADOS!$A$2:$M$6000,6,0),"") | E22: =IFERROR(VLOOKUP(H22,[1]SEMIELABORADOS!$A$2:$H$65536,8,0),"") | F22: =IFERROR(E22*C22,"") | G22: =IFERROR(F22/$F$65,"")
B23: =IFERROR(VLOOKUP(H23,[1]SEMIELABORADOS!$A$2:$M$6000,2,0),"") | C23: =+A23 -> 0 | D23: =IFERROR(VLOOKUP(H23,[1]SEMIELABORADOS!$A$2:$M$6000,6,0),"") | E23: =IFERROR(VLOOKUP(H23,[1]SEMIELABORADOS!$A$2:$H$65536,8,0),"") | F23: =IFERROR(E23*C23,"") | G23: =IFERROR(F23/$F$65,"")
A25: UNIDADES | B25: EMPAQUE | C25: UNIDADES | D25: UND MEDIDA | E25: COSTO UNITARIO | F25: TOTAL COSTO | G25: % PREC. DEFINIDO | H25: CODIGOS
A26: 0 | B26: =IFERROR(VLOOKUP(H26,'[1]Consolidado MP Planta'!$A$2:$M$823,3,0),"") | C26: =+A26 -> 0 | D26: =IFERROR(VLOOKUP(H26,'[1]Consolidado MP Planta'!$A$2:$M$823,13,0),"") | E26: =IFERROR(VLOOKUP(H26,'[1]Consolidado MP Planta'!$A$2:$M$823,12,0),"") | F26: =IFERROR(C26*E26,"") | G26: =IFERROR(F26/$F$65,"")
B27: =IFERROR(VLOOKUP(H27,'[1]Consolidado MP Planta'!$A$2:$M$823,3,0),"") | C27: =+A27 -> 0 | D27: =IFERROR(VLOOKUP(H27,'[1]Consolidado MP Planta'!$A$2:$M$823,13,0),"") | E27: =IFERROR(VLOOKUP(H27,'[1]Consolidado MP Planta'!$A$2:$M$823,12,0),"") | F27: =IFERROR(C27*E27,"") | G27: =IFERROR(F27/$F$65,"")
B28: =IFERROR(VLOOKUP(H28,'[1]Consolidado MP Planta'!$A$2:$M$823,3,0),"") | C28: =+A28 -> 0 | D28: =IFERROR(VLOOKUP(H28,'[1]Consolidado MP Planta'!$A$2:$M$823,13,0),"") | E28: =IFERROR(VLOOKUP(H28,'[1]Consolidado MP Planta'!$A$2:$M$823,12,0),"") | F28: =IFERROR(C28*E28,"") | G28: =IFERROR(F28/$F$65,"")
B29: =IFERROR(VLOOKUP(H29,'[1]Consolidado MP Planta'!$A$2:$M$823,3,0),"") | C29: =+A29 -> 0 | D29: =IFERROR(VLOOKUP(H29,'[1]Consolidado MP Planta'!$A$2:$M$823,13,0),"") | E29: =IFERROR(VLOOKUP(H29,'[1]Consolidado MP Planta'!$A$2:$M$823,12,0),"") | F29: =IFERROR(C29*E29,"") | G29: =IFERROR(F29/$F$65,"")
B30: =IFERROR(VLOOKUP(H30,'[1]Consolidado MP Planta'!$A$2:$M$823,3,0),"") | C30: =+A30 -> 0 | D30: =IFERROR(VLOOKUP(H30,'[1]Consolidado MP Planta'!$A$2:$M$823,13,0),"") | E30: =IFERROR(VLOOKUP(H30,'[1]Consolidado MP Planta'!$A$2:$M$823,12,0),"") | F30: =IFERROR(C30*E30,"") | G30: =IFERROR(F30/$F$65,"")
B31: =IFERROR(VLOOKUP(H31,'[1]Consolidado MP Planta'!$A$2:$M$823,3,0),"") | C31: =+A31 -> 0 | D31: =IFERROR(VLOOKUP(H31,'[1]Consolidado MP Planta'!$A$2:$M$823,13,0),"") | E31: =IFERROR(VLOOKUP(H31,'[1]Consolidado MP Planta'!$A$2:$M$823,12,0),"") | F31: =IFERROR(C31*E31,"") | G31: =IFERROR(F31/$F$65,"")
A33: UNIDADES | B33: EMPAQUE SEMIELABORADOS | C33: UNIDADES | D33: UND MEDIDA | E33: COSTO UNITARIO | F33: TOTAL COSTO | G33: % PREC. DEFINIDO | H33: CODIGOS
A34: =+A16 -> 19350 | B34: Batido queque chocolate con mani Spoon | C34: =+A34 -> 19350 | D34: Gramos | E34: =+'Costo batido'!E76 -> 0.01438486 | F34: =IFERROR(E34*C34,"") -> 278.34705 | G34: =IFERROR(F34/$F$65,"") -> 0.0069129273 | H34: NUEVO
A35: =+A17 -> 1600 | B35: =IFERROR(VLOOKUP(H35,[1]SEMIELABORADOS!$A$2:$M$6000,2,0),"") -> MEZCLA P/ENGRASE MOLDES KILO | C35: =+A35 -> 1600 | D35: =IFERROR(VLOOKUP(H35,[1]SEMIELABORADOS!$A$2:$M$6000,6,0),"") -> Gramo | E35: =IFERROR(VLOOKUP(H35,[1]SEMIELABORADOS!$A$2:$M$65536,10,0),"") -> 0.021536385 | F35: =IFERROR(E35*C35,"") -> 34.458216 | G35: =IFERROR(F35/$F$65,"") -> 0.00085579187 | H35: 902000019
A36: =+A18 -> 0 | C36: =+A36 -> 0 | D36: Gramos | F36: =IFERROR(E36*C36,"") -> 0 | G36: =IFERROR(F36/$F$65,"") -> 0
A37: =+A19 -> 0 | B37: =IFERROR(VLOOKUP(H37,[1]SEMIELABORADOS!$A$2:$M$6000,2,0),"") | C37: =+A37 -> 0 | D37: =IFERROR(VLOOKUP(H37,[1]SEMIELABORADOS!$A$2:$M$6000,6,0),"") | E37: =IFERROR(VLOOKUP(H37,[1]SEMIELABORADOS!$A$2:$M$65536,10,0),"") | F37: =IFERROR(E37*C37,"") | G37: =IFERROR(F37/$F$65,"")
A38: =+A20 -> 0 | B38: =IFERROR(VLOOKUP(H38,[1]SEMIELABORADOS!$A$2:$M$6000,2,0),"") | C38: =+A38 -> 0 | D38: =IFERROR(VLOOKUP(H38,[1]SEMIELABORADOS!$A$2:$M$6000,6,0),"") | E38: =IFERROR(VLOOKUP(H38,[1]SEMIELABORADOS!$A$2:$M$65536,10,0),"") | F38: =IFERROR(E38*C38,"") | G38: =IFERROR(F38/$F$65,"")
A39: =+A21 -> 0 | B39: =IFERROR(VLOOKUP(H39,[1]SEMIELABORADOS!$A$2:$M$6000,2,0),"") | C39: =+A39 -> 0 | D39: =IFERROR(VLOOKUP(H39,[1]SEMIELABORADOS!$A$2:$M$6000,6,0),"") | E39: =IFERROR(VLOOKUP(H39,[1]SEMIELABORADOS!$A$2:$M$65536,10,0),"") | F39: =IFERROR(E39*C39,"") | G39: =IFERROR(F39/$F$65,"")
A40: =+A22 -> 0 | B40: =IFERROR(VLOOKUP(H40,[1]SEMIELABORADOS!$A$2:$M$6000,2,0),"") | C40: =+A40 -> 0 | D40: =IFERROR(VLOOKUP(H40,[1]SEMIELABORADOS!$A$2:$M$6000,6,0),"") | E40: =IFERROR(VLOOKUP(H40,[1]SEMIELABORADOS!$A$2:$M$65536,10,0),"") | F40: =IFERROR(E40*C40,"") | G40: =IFERROR(F40/$F$65,"")
A42: UNIDADES | B42: MODI | C42: UNIDADES | D42: UND MEDIDA | E42: COSTO UNITARIO | F42: TOTAL COSTO | G42: % PREC. DEFINIDO | H42: CODIGOS
A43: =+A34 -> 19350 | B43: Batido queque chocolate con mani Spoon | C43: =+A43 -> 19350 | D43: Gramos | E43: =+'Costo batido'!E74 -> 0.036649774 | F43: =IFERROR(E43*C43,"") -> 709.17312 | G43: =IFERROR(F43/$F$65,"") -> 0.017612769 | H43: NUEVO
A44: =+A35 -> 1600 | B44: =IFERROR(VLOOKUP(H44,[1]SEMIELABORADOS!$A$2:$M$6000,2,0),"") -> MEZCLA P/ENGRASE MOLDES KILO | C44: =+A44 -> 1600 | D44: =IFERROR(VLOOKUP(H44,[1]SEMIELABORADOS!$A$2:$M$6000,6,0),"") -> Gramo | E44: =IFERROR(VLOOKUP(H44,[1]SEMIELABORADOS!$A$2:$M$65536,12,0),"") -> 0.2512758 | F44: =IFERROR(E44*C44,"") -> 402.04128 | G44: =IFERROR(F44/$F$65,"") -> 0.0099849527 | H44: 902000019
...

Sheet Costo Empaque 
E1: Precio Local | F1: Costo MP | G1: Costo EM | H1: Costo MO
E2: =IFERROR(O61,"") -> 1792.7072 | F2: =IFERROR(H52,"") -> 1214.9707 | G2: =IFERROR(H53,"") -> 352.96637 | H2: =IFERROR(H55,"") -> 115.21825
A5: ESTRUCTURA DE COSTOS
F6: Fecha: | H6: =TODAY() -> 45749
A7: UNIDADES | B7: DESCRIPCION MAT.PRIMA | C7: UNIDADES | D7: UND MEDIDA | E7: COSTO UNITARIO | F7: TOTAL COSTO | G7: % PREC. DEFINIDO | H7: CODIGOS
B8: =IFERROR(VLOOKUP(H8,'[1]Consolidado MP Planta'!$A$2:$M$823,3,0),"") | C8: =+A8 -> 0 | D8: =IFERROR(VLOOKUP(H8,'[1]Consolidado MP Planta'!$A$2:$M$823,13,0),"") | E8: =IFERROR(VLOOKUP(H8,'[1]Consolidado MP Planta'!$A$2:$M$823,12,0),"") | F8: =IFERROR(C8*E8,"") | G8: =IFERROR(F8/$F$65,"")
B9: =IFERROR(VLOOKUP(H9,'[1]Consolidado MP Planta'!$A$2:$M$823,3,0),"") | C9: =+A9 -> 0 | D9: =IFERROR(VLOOKUP(H9,'[1]Consolidado MP Planta'!$A$2:$M$823,13,0),"") | E9: =IFERROR(VLOOKUP(H9,'[1]Consolidado MP Planta'!$A$2:$M$823,12,0),"") | F9: =IFERROR(C9*E9,"") | G9: =IFERROR(F9/$F$65,"")
B10: =IFERROR(VLOOKUP(H10,'[1]Consolidado MP Planta'!$A$2:$M$823,3,0),"") | C10: =+A10 -> 0 | D10: =IFERROR(VLOOKUP(H10,'[1]Consolidado MP Planta'!$A$2:$M$823,13,0),"") | E10: =IFERROR(VLOOKUP(H10,'[1]Consolidado MP Planta'!$A$2:$M$823,12,0),"") | F10: =IFERROR(C10*E10,"") | G10: =IFERROR(F10/$F$65,"")
B11: =IFERROR(VLOOKUP(H11,'[1]Consolidado MP Planta'!$A$2:$M$823,3,0),"") | C11: =+A11 -> 0 | D11: =IFERROR(VLOOKUP(H11,'[1]Consolidado MP Planta'!$A$2:$M$823,13,0),"") | E11: =IFERROR(VLOOKUP(H11,'[1]Consolidado MP Planta'!$A$2:$M$823,12,0),"") | F11: =IFERROR(C11*E11,"") | G11: =IFERROR(F11/$F$65,"")
B12: =IFERROR(VLOOKUP(H12,'[1]Consolidado MP Planta'!$A$2:$M$823,3,0),"") | C12: =+A12 -> 0 | D12: =IFERROR(VLOOKUP(H12,'[1]Consolidado MP Planta'!$A$2:$M$823,13,0),"") | E12: =IFERROR(VLOOKUP(H12,'[1]Consolidado MP Planta'!$A$2:$M$823,12,0),"") | F12: =IFERROR(C12*E12,"") | G12: =IFERROR(F12/$F$65,"")
B13: =IFERROR(VLOOKUP(H13,'[1]Consolidado MP Planta'!$A$2:$M$823,3,0),"") | C13: =+A13 -> 0 | D13: =IFERROR(VLOOKUP(H13,'[1]Consolidado MP Planta'!$A$2:$M$823,13,0),"") | E13: =IFERROR(VLOOKUP(H13,'[1]Consolidado MP Planta'!$A$2:$M$823,12,0),"") | F13: =IFERROR(C13*E13,"") | G13: =IFERROR(F13/$F$65,"")
B14: =IFERROR(VLOOKUP(H14,'[1]Consolidado MP Planta'!$A$2:$M$823,3,0),"") | C14: =+A14 -> 0 | D14: =IFERROR(VLOOKUP(H14,'[1]Consolidado MP Planta'!$A$2:$M$823,13,0),"") | E14: =IFERROR(VLOOKUP(H14,'[1]Consolidado MP Planta'!$A$2:$M$823,12,0),"") | F14: =IFERROR(C14*E14,"") | G14: =IFERROR(F14/$F$65,"")
B15: =IFERROR(VLOOKUP(H15,'[2]ARTICULOS MP PLANTA'!$A$2:$G$589,2,0),"")
A16: UNIDADES | B16: MATERIA PRIMA SEMIELABORADOS | C16: UNIDADES | D16: UND MEDIDA | E16: COSTO UNITARIO | F16: TOTAL COSTO | G16: % PREC. DEFINIDO | H16: CODIGOS
A17: 1 | B17: Rosquete chocolate con mani Spoon | C17: =+A17 -> 1 | D17: UND | E17: =+'Costo Rosquete '!H52 -> 1214.9707 | F17: =IFERROR(E17*C17,"") -> 1214.9707 | G17: =IFERROR(F17/$F$65,"") -> 0.73490437 | H17: NUEVO
B18: =IFERROR(VLOOKUP(H18,[1]SEMIELABORADOS!$A$2:$M$6000,2,0),"") | C18: =+A18 -> 0 | D18: =IFERROR(VLOOKUP(H18,[1]SEMIELABORADOS!$A$2:$M$6000,6,0),"") | E18: =IFERROR(VLOOKUP(H18,[1]SEMIELABORADOS!$A$2:$H$65536,8,0),"") | F18: =IFERROR(E18*C18,"") | G18: =IFERROR(F18/$F$65,"")
B19: =IFERROR(VLOOKUP(H19,[1]SEMIELABORADOS!$A$2:$M$6000,2,0),"") | C19: =+A19 -> 0 | D19: =IFERROR(VLOOKUP(H19,[1]SEMIELABORADOS!$A$2:$M$6000,6,0),"") | E19: =IFERROR(VLOOKUP(H19,[1]SEMIELABORADOS!$A$2:$H$65536,8,0),"") | F19: =IFERROR(E19*C19,"") | G19: =IFERROR(F19/$F$65,"")
B20: =IFERROR(VLOOKUP(H20,[1]SEMIELABORADOS!$A$2:$M$6000,2,0),"") | C20: =+A20 -> 0 | D20: =IFERROR(VLOOKUP(H20,[1]SEMIELABORADOS!$A$2:$M$6000,6,0),"") | E20: =IFERROR(VLOOKUP(H20,[1]SEMIELABORADOS!$A$2:$H$65536,8,0),"") | F20: =IFERROR(E20*C20,"") | G20: =IFERROR(F20/$F$65,"")
B21: =IFERROR(VLOOKUP(H21,[1]SEMIELABORADOS!$A$2:$M$6000,2,0),"") | C21: =+A21 -> 0 | D21: =IFERROR(VLOOKUP(H21,[1]SEMIELABORADOS!$A$2:$M$6000,6,0),"") | E21: =IFERROR(VLOOKUP(H21,[1]SEMIELABORADOS!$A$2:$H$65536,8,0),"") | F21: =IFERROR(E21*C21,"") | G21: =IFERROR(F21/$F$65,"")
B22: =IFERROR(VLOOKUP(H22,[1]SEMIELABORADOS!$A$2:$M$6000,2,0),"") | C22: =+A22 -> 0 | D22: =IFERROR(VLOOKUP(H22,[1]SEMIELABORADOS!$A$2:$M$6000,6,0),"") | E22: =IFERROR(VLOOKUP(H22,[1]SEMIELABORADOS!$A$2:$H$65536,8,0),"") | F22: =IFERROR(E22*C22,"") | G22: =IFERROR(F22/$F$65,"")
B23: =IFERROR(VLOOKUP(H23,[1]SEMIELABORADOS!$A$2:$M$6000,2,0),"") | C23: =+A23 -> 0 | D23: =IFERROR(VLOOKUP(H23,[1]SEMIELABORADOS!$A$2:$M$6000,6,0),"") | E23: =IFERROR(VLOOKUP(H23,[1]SEMIELABORADOS!$A$2:$H$65536,8,0),"") | F23: =IFERROR(E23*C23,"") | G23: =IFERROR(F23/$F$65,"")
B24: =IFERROR(VLOOKUP(H24,[1]SEMIELABORADOS!$A$2:$M$6000,2,0),"") | C24: =+A24 -> 0 | D24: =IFERROR(VLOOKUP(H24,[1]SEMIELABORADOS!$A$2:$M$6000,6,0),"") | E24: =IFERROR(VLOOKUP(H24,[1]SEMIELABORADOS!$A$2:$H$65536,8,0),"") | F24: =IFERROR(E24*C24,"") | G24: =IFERROR(F24/$F$65,"")
A26: UNIDADES | B26: EMPAQUE | C26: UNIDADES | D26: UND MEDIDA | E26: COSTO UNITARIO | F26: TOTAL COSTO | G26: % PREC. DEFINIDO | H26: CODIGOS
A27: 1 | B27: Quequera Red C/Base Alta 9" | C27: =+A27 -> 1 | D27: Und | E27: 340 | F27: =IFERROR(C27*E27,"") -> 340 | G27: =IFERROR(F27/$F$65,"") -> 0.2056572 | H27: 51400021
A28: 1 | B28: =IFERROR(VLOOKUP(H28,'[1]Consolidado MP Planta'!$A$2:$M$823,3,0),"") -> ETIQUETA BLANCA 2 5/8X1 15/16 (UND) | C28: =+A28 -> 1 | D28: =IFERROR(VLOOKUP(H28,'[1]Consolidado MP Planta'!$A$2:$M$823,13,0),"") -> Und | E28: =IFERROR(VLOOKUP(H28,'[1]Consolidado MP Planta'!$A$2:$M$823,12,0),"") -> 2.128 | F28: =IFERROR(C28*E28,"") -> 2.128 | G28: =IFERROR(F28/$F$65,"") -> 0.0012871721 | H28: 0702123
A29: 1 | B29: =IFERROR(VLOOKUP(H29,'[1]Consolidado MP Planta'!$A$2:$M$823,3,0),"") -> ETIQUETA BLANCA R-153 (UND) | C29: =+A29 -> 1 | D29: =IFERROR(VLOOKUP(H29,'[1]Consolidado MP Planta'!$A$2:$M$823,13,0),"") -> Und | E29: =IFERROR(VLOOKUP(H29,'[1]Consolidado MP Planta'!$A$2:$M$823,12,0),"") -> 0.39 | F29: =IFERROR(C29*E29,"") -> 0.39 | G29: =IFERROR(F29/$F$65,"") -> 0.00023590091 | H29: 701096
A30: 1 | B30: =IFERROR(VLOOKUP(H30,'[1]Consolidado MP Planta'!$A$2:$M$823,3,0),"") -> ETIQUETA BLANCA VENCE (ROLLO:1000 UND) | C30: =+A30 -> 1 | D30: Und | E30: =IFERROR(VLOOKUP(H30,'[1]Consolidado MP Planta'!$A$2:$M$823,12,0),"") -> 0.595 | F30: =IFERROR(C30*E30,"") -> 0.595 | G30: =IFERROR(F30/$F$65,"") -> 0.0003599001 | H30: 0702155
B31: =IFERROR(VLOOKUP(H31,'[1]Consolidado MP Planta'!$A$2:$M$823,3,0),"") | C31: =+A31 -> 0 | D31: =IFERROR(VLOOKUP(H31,'[1]Consolidado MP Planta'!$A$2:$M$823,13,0),"") | E31: =IFERROR(VLOOKUP(H31,'[1]Consolidado MP Planta'!$A$2:$M$823,12,0),"") | F31: =IFERROR(C31*E31,"") | G31: =IFERROR(F31/$F$65,"")
A33: UNIDADES | B33: EMPAQUE SEMIELABORADOS | C33: UNIDADES | D33: UND MEDIDA | E33: COSTO UNITARIO | F33: TOTAL COSTO | G33: % PREC. DEFINIDO | H33: CODIGOS
A34: =+A17 -> 1 | B34: ROSQUETE MARMOLEADO SPOON | C34: =+A34 -> 1 | D34: UND | E34: =+'Costo Rosquete '!H53 -> 9.8533658 | F34: =IFERROR(E34*C34,"") -> 9.8533658 | G34: =IFERROR(F34/$F$65,"") -> 0.005960046 | H34: NUEVO
A35: =+A18 -> 0 | B35: =IFERROR(VLOOKUP(H35,[1]SEMIELABORADOS!$A$2:$M$6000,2,0),"") | C35: =+A35 -> 0 | D35: =IFERROR(VLOOKUP(H35,[1]SEMIELABORADOS!$A$2:$M$6000,6,0),"") | E35: =IFERROR(VLOOKUP(H35,[1]SEMIELABORADOS!$A$2:$M$65536,10,0),"") | F35: =IFERROR(E35*C35,"") | G35: =IFERROR(F35/$F$65,"")
A36: =+A19 -> 0 | B36: =IFERROR(VLOOKUP(H36,[1]SEMIELABORADOS!$A$2:$M$6000,2,0),"") | C36: =+A36 -> 0 | D36: =IFERROR(VLOOKUP(H36,[1]SEMIELABORADOS!$A$2:$M$6000,6,0),"") | E36: =IFERROR(VLOOKUP(H36,[1]SEMIELABORADOS!$A$2:$M$65536,10,0),"") | F36: =IFERROR(E36*C36,"") | G36: =IFERROR(F36/$F$65,"")
A37: =+A20 -> 0 | B37: =IFERROR(VLOOKUP(H37,[1]SEMIELABORADOS!$A$2:$M$6000,2,0),"") | C37: =+A37 -> 0 | D37: =IFERROR(VLOOKUP(H37,[1]SEMIELABORADOS!$A$2:$M$6000,6,0),"") | E37: =IFERROR(VLOOKUP(H37,[1]SEMIELABORADOS!$A$2:$M$65536,10,0),"") | F37: =IFERROR(E37*C37,"") | G37: =IFERROR(F37/$F$65,"")
A38: =+A21 -> 0 | B38: =IFERROR(VLOOKUP(H38,[1]SEMIELABORADOS!$A$2:$M$6000,2,0),"") | C38: =+A38 -> 0 | D38: =IFERROR(VLOOKUP(H38,[1]SEMIELABORADOS!$A$2:$M$6000,6,0),"") | E38: =IFERROR(VLOOKUP(H38,[1]SEMIELABORADOS!$A$2:$M$65536,10,0),"") | F38: =IFERROR(E38*C38,"") | G38: =IFERROR(F38/$F$65,"")
A39: =+A22 -> 0 | B39: =IFERROR(VLOOKUP(H39,[1]SEMIELABORADOS!$A$2:$M$6000,2,0),"") | C39: =+A39 -> 0 | D39: =IFERROR(VLOOKUP(H39,[1]SEMIELABORADOS!$A$2:$M$6000,6,0),"") | E39: =IFERROR(VLOOKUP(H39,[1]SEMIELABORADOS!$A$2:$M$65536,10,0),"") | F39: =IFERROR(E39*C39,"") | G39: =IFERROR(F39/$F$65,"")
A40: =+A23 -> 0 | B40: =IFERROR(VLOOKUP(H40,[1]SEMIELABORADOS!$A$2:$M$6000,2,0),"") | C40: =+A40 -> 0 | D40: =IFERROR(VLOOKUP(H40,[1]SEMIELABORADOS!$A$2:$M$6000,6,0),"") | E40: =IFERROR(VLOOKUP(H40,[1]SEMIELABORADOS!$A$2:$M$65536,10,0),"") | F40: =IFERROR(E40*C40,"") | G40: =IFERROR(F40/$F$65,"")
A42: UNIDADES | B42: MODI | C42: UNIDADES | D42: UND MEDIDA | E42: COSTO UNITARIO | F42: TOTAL COSTO | G42: % PREC. DEFINIDO | H42: CODIGOS
A43: =+A34 -> 1 | B43: ROSQUETE MARMOLEADO SPOON | C43: =+A43 -> 1 | D43: UND | E43: =+'Costo Rosquete '!H55 -> 54.218254 | F43: =IFERROR(E43*C43,"") -> 54.218254 | G43: =IFERROR(F43/$F$65,"") -> 0.032795219 | H43: NUEVO
A44: =+A35 -> 0 | B44: =IFERROR(VLOOKUP(H44,[1]SEMIELABORADOS!$A$2:$M$6000,2,0),"") | C44: =+A44 -> 0 | D44: =IFERROR(VLOOKUP(H44,[1]SEMIELABORADOS!$A$2:$M$6000,6,0),"") | E44: =IFERROR(VLOOKUP(H44,[1]SEMIELABORADOS!$A$2:$M$65536,12,0),"") | F44: =IFERROR(E44*C44,"") | G44: =IFERROR(F44/$F$65,"")
A45: =+A36 -> 0 | B45: =IFERROR(VLOOKUP(H45,[1]SEMIELABORADOS!$A$2:$M$6000,2,0),"") | C45: =+A45 -> 0 | D45: =IFERROR(VLOOKUP(H45,[1]SEMIELABORADOS!$A$2:$M$6000,6,0),"") | E45: =IFERROR(VLOOKUP(H45,[1]SEMIELABORADOS!$A$2:$M$65536,12,0),"") | F45: =IFERROR(E45*C45,"") | G45: =IFERROR(F45/$F$65,"")
...
