Workbook

Sheet Hoja1
C1: SERVICIOS DE PASTELERIA S.A. | H1: CÓDIGO: | I1: ESP-RE-POS-039
C2: ESPECIFICACION DE RECETA | H2: REVISIÓN: | I2: 02
C3: 902000116(SE00299) Brittle de almendras | H3: FECHA DE APROBACIÓN: | I3: 45615
C4: Elaborado | D4: Javier Tong, Chef
C5: Aprobado | D5: Esteban Cartin, Gte Manufactura
A6: AREA QUE PRODUCE: | D6: Postres | G6: AREA QUE EMPACA: | I6: Postres
A7: # Código | B7: # Código Netsuite | C7: Descripción del ingrediente | D7: Marca | E7: Unidad Internacional | G7: Medida alternativa | I7: Costo - Referencia
E8: Cantidad | F8: Unidad medida | G8: Cantidad | H8: Unidad medida | I8: Colones
C9: Ensamble
A10: 90100131 | B10: SE00016 | C10: AZUCAR BLANCO INDUSTRIAL KILO | D10: FAS | E10: 1080 | F10: g
A11: 10100048 | B11: MP10573 | C11: SIROPE KARO DARK | D11: KARO | E11: 450 | F11: g
A12: 0310107 | B12: MP10022 | C12: LACTOCREMA GRANEL | D12: DOS PINOS | E12: 145 | F12: g
A13: 503000036 | B13: MP10085 | C13: BICARBONATO DE SODIO | D13: MAYCA | E13: 7 | F13: g
A14: 90100142 | B14: SE00104 | C14: EMPAQUE SAL KILO | D14: FAS | E14: 3 | F14: g
A15: 11900029 | B15: MP10591 | C15: ALMENDRA ENTERA | D15: NUECES INDUSTRIALES | E15: 630 | F15: g
C16: Agua | D16: FAS | E16: 180 | F16: g
C21: Decoración
C30: Empaque
A31: 512000002 | B31: EM10259 | C31: PLÁSTICO AUTOADERIBLE 1/ 18*2000 | E31: 1 | F31: metro
A32: 702067 | B32: EM10120 | C32: ETIQ.BLANCA 1 13/16 * 1 7/8 | D32: ETIPLAST | E32: 1 | F32: ud
D43: Cantidad | E43: Unidad
A44: PESO TOTAL OBTENIDO | D44: 2000 | E44: g | F44: Tiempo de Horneo:
A45: TIEMPO TOTAL DE PREPARACION | D45: 20 | E45: min | F45: Horno:
A46: CANTIDAD DE PORCIONES OBTENIDAS | D46: 1 | E46: tanda | F46: Temperatura de Horneo:
A47: PESO DE CADA PORCIÓN | D47: 2000 | E47: g | F47: Otros
A48: MERMA | D48: =SUM(E10:E16)-D44 -> 495
A49: PROCEDIMIENTO DE PREPARACION DE LA RECETA
A50: 1, Colocar el azucar junto con el agua, sirope en una olla y cocinar hasta tomar punto caramelo.
A51: 3, Agregar lactocrema, bicarbonato y sal y mezclar bien. Si le falta color seguir dandole punto.
A52: 3, Colocar sobre bandejas con lamina de silicon las almendras bien esparcidas, Agregar el caramelo anterior cubriendolas muy bien.
A53: 4, Dejar que enfrie a temp ambiente.
A54: 5, Pasar po la maquina para quebrar.
A55: 6,Etiquetar y emplasticar
A58: CONTROL DE CAMBIOS
A59: 2, Actualización ingredientes, se agrega agua a la receta y actualización merma

Sheet costeo brittle
E1: Precio Local | F1: Costo MP | G1: Costo EM | H1: Costo MO
E2: =IFERROR(O62,"") -> 8928.7531 | F2: =IFERROR(H53,"") -> 5531.4857 | G2: =IFERROR(H54,"") -> 75.675814 | H2: =IFERROR(H56,"") -> 1139.6264
A5: ESTRUCTURA DE COSTOS
F6: Fecha: | H6: =TODAY() -> 45754
A7: UNIDADES | B7: DESCRIPCION MAT.PRIMA | C7: UNIDADES | D7: UND MEDIDA | E7: COSTO UNITARIO | F7: TOTAL COSTO | G7: % PREC. DEFINIDO | H7: CODIGOS
A8: 180 | B8: =IFERROR(VLOOKUP(H8,'[1]Consolidado MP Planta'!$A$2:$M$823,3,0),"") -> AGUA PLANTA | C8: =+A8 -> 180 | D8: =IFERROR(VLOOKUP(H8,'[1]Consolidado MP Planta'!$A$2:$M$823,13,0),"") -> Mililitros | E8: =IFERROR(VLOOKUP(H8,'[1]Consolidado MP Planta'!$A$2:$M$823,12,0),"") -> 0.1 | F8: =IFERROR(C8*E8,"") -> 18 | G8: =IFERROR(F8/$F$66,"") -> 0.0026401512 | H8: 10415
A9: 450 | B9: =IFERROR(VLOOKUP(H9,'[1]Consolidado MP Planta'!$A$2:$M$823,3,0),"") -> SIROPE KARO DARK (UND: 3.78 K) | C9: =+A9 -> 450 | D9: =IFERROR(VLOOKUP(H9,'[1]Consolidado MP Planta'!$A$2:$M$823,13,0),"") -> Mililitros | E9: =IFERROR(VLOOKUP(H9,'[1]Consolidado MP Planta'!$A$2:$M$823,12,0),"") -> 2.5428571 | F9: =IFERROR(C9*E9,"") -> 1144.2857 | G9: =IFERROR(F9/$F$66,"") -> 0.16783819 | H9: 10100048
A10: 145 | B10: =IFERROR(VLOOKUP(H10,'[1]Consolidado MP Planta'!$A$2:$M$823,3,0),"") -> LACTOCREMA GRANEL (CAJA:25 KG) | C10: =+A10 -> 145 | D10: =IFERROR(VLOOKUP(H10,'[1]Consolidado MP Planta'!$A$2:$M$823,13,0),"") -> Gramos | E10: =IFERROR(VLOOKUP(H10,'[1]Consolidado MP Planta'!$A$2:$M$823,12,0),"") -> 3.055 | F10: =IFERROR(C10*E10,"") -> 442.975 | G10: =IFERROR(F10/$F$66,"") -> 0.064973389 | H10: 0310107
A11: 7 | B11: =IFERROR(VLOOKUP(H11,'[1]Consolidado MP Planta'!$A$2:$M$823,3,0),"") -> BICARBONATO DE SODIO (PAQ:2.5 K) | C11: =+A11 -> 7 | D11: =IFERROR(VLOOKUP(H11,'[1]Consolidado MP Planta'!$A$2:$M$823,13,0),"") -> Gramos | E11: =IFERROR(VLOOKUP(H11,'[1]Consolidado MP Planta'!$A$2:$M$823,12,0),"") -> 0.70658 | F11: =IFERROR(C11*E11,"") -> 4.94606 | G11: =IFERROR(F11/$F$66,"") -> 0.00072546369 | H11: 503000036
A12: 630 | B12: =IFERROR(VLOOKUP(H12,'[1]Consolidado MP Planta'!$A$2:$M$823,3,0),"") -> ALMENDRA ENTERA (CAJA:12 KG) | C12: =+A12 -> 630 | D12: =IFERROR(VLOOKUP(H12,'[1]Consolidado MP Planta'!$A$2:$M$823,13,0),"") -> Gramos | E12: =IFERROR(VLOOKUP(H12,'[1]Consolidado MP Planta'!$A$2:$M$823,12,0),"") -> 5.5533075 | F12: =IFERROR(C12*E12,"") -> 3498.5837 | G12: =IFERROR(F12/$F$66,"") -> 0.51315501 | H12: 510149
B13: =IFERROR(VLOOKUP(H13,'[1]Consolidado MP Planta'!$A$2:$M$823,3,0),"") | C13: =+A13 -> 0 | D13: =IFERROR(VLOOKUP(H13,'[1]Consolidado MP Planta'!$A$2:$M$823,13,0),"") | E13: =IFERROR(VLOOKUP(H13,'[1]Consolidado MP Planta'!$A$2:$M$823,12,0),"") | F13: =IFERROR(C13*E13,"") | G13: =IFERROR(F13/$F$66,"")
B14: =IFERROR(VLOOKUP(H14,'[1]Consolidado MP Planta'!$A$2:$M$823,3,0),"") | C14: =+A14 -> 0 | D14: =IFERROR(VLOOKUP(H14,'[1]Consolidado MP Planta'!$A$2:$M$823,13,0),"") | E14: =IFERROR(VLOOKUP(H14,'[1]Consolidado MP Planta'!$A$2:$M$823,12,0),"") | F14: =IFERROR(C14*E14,"") | G14: =IFERROR(F14/$F$66,"")
B15: =IFERROR(VLOOKUP(H15,'[2]ARTICULOS MP PLANTA'!$A$2:$G$589,2,0),"")
A16: UNIDADES | B16: MATERIA PRIMA SEMIELABORADOS | C16: UNIDADES | D16: UND MEDIDA | E16: COSTO UNITARIO | F16: TOTAL COSTO | G16: % PREC. DEFINIDO | H16: CODIGOS
A17: 1080 | B17: =IFERROR(VLOOKUP(H17,[1]SEMIELABORADOS!$A$2:$M$6000,2,0),"") -> AZUCAR BLANCO INDUSTRIAL KILO | C17: =+A17 -> 1080 | D17: =IFERROR(VLOOKUP(H17,[1]SEMIELABORADOS!$A$2:$M$6000,6,0),"") -> Gramo | E17: =IFERROR(VLOOKUP(H17,[1]SEMIELABORADOS!$A$2:$H$65536,8,0),"") -> 0.39034 | F17: =IFERROR(E17*C17,"") -> 421.5672 | G17: =IFERROR(F17/$F$66,"") -> 0.061833398 | H17: 90100131
A18: 3 | B18: =IFERROR(VLOOKUP(H18,[1]SEMIELABORADOS!$A$2:$M$6000,2,0),"") -> EMPAQUE SAL KILO | C18: =+A18 -> 3 | D18: =IFERROR(VLOOKUP(H18,[1]SEMIELABORADOS!$A$2:$M$6000,6,0),"") -> Gramo | E18: =IFERROR(VLOOKUP(H18,[1]SEMIELABORADOS!$A$2:$H$65536,8,0),"") -> 0.376 | F18: =IFERROR(E18*C18,"") -> 1.128 | G18: =IFERROR(F18/$F$66,"") -> 0.00016544948 | H18: 90100142
B19: =IFERROR(VLOOKUP(H19,[1]SEMIELABORADOS!$A$2:$M$6000,2,0),"") | C19: =+A19 -> 0 | D19: =IFERROR(VLOOKUP(H19,[1]SEMIELABORADOS!$A$2:$M$6000,6,0),"") | E19: =IFERROR(VLOOKUP(H19,[1]SEMIELABORADOS!$A$2:$H$65536,8,0),"") | F19: =IFERROR(E19*C19,"") | G19: =IFERROR(F19/$F$66,"")
B20: =IFERROR(VLOOKUP(H20,[1]SEMIELABORADOS!$A$2:$M$6000,2,0),"") | C20: =+A20 -> 0 | D20: =IFERROR(VLOOKUP(H20,[1]SEMIELABORADOS!$A$2:$M$6000,6,0),"") | E20: =IFERROR(VLOOKUP(H20,[1]SEMIELABORADOS!$A$2:$H$65536,8,0),"") | F20: =IFERROR(E20*C20,"") | G20: =IFERROR(F20/$F$66,"")
B21: =IFERROR(VLOOKUP(H21,[1]SEMIELABORADOS!$A$2:$M$6000,2,0),"") | C21: =+A21 -> 0 | D21: =IFERROR(VLOOKUP(H21,[1]SEMIELABORADOS!$A$2:$M$6000,6,0),"") | E21: =IFERROR(VLOOKUP(H21,[1]SEMIELABORADOS!$A$2:$H$65536,8,0),"") | F21: =IFERROR(E21*C21,"") | G21: =IFERROR(F21/$F$66,"")
B22: =IFERROR(VLOOKUP(H22,[1]SEMIELABORADOS!$A$2:$M$6000,2,0),"") | C22: =+A22 -> 0 | D22: =IFERROR(VLOOKUP(H22,[1]SEMIELABORADOS!$A$2:$M$6000,6,0),"") | E22: =IFERROR(VLOOKUP(H22,[1]SEMIELABORADOS!$A$2:$H$65536,8,0),"") | F22: =IFERROR(E22*C22,"") | G22: =IFERROR(F22/$F$66,"")
B23: =IFERROR(VLOOKUP(H23,[1]SEMIELABORADOS!$A$2:$M$6000,2,0),"") | C23: =+A23 -> 0 | D23: =IFERROR(VLOOKUP(H23,[1]SEMIELABORADOS!$A$2:$M$6000,6,0),"") | E23: =IFERROR(VLOOKUP(H23,[1]SEMIELABORADOS!$A$2:$H$65536,8,0),"") | F23: =IFERROR(E23*C23,"") | G23: =IFERROR(F23/$F$66,"")
B24: =IFERROR(VLOOKUP(H24,[1]SEMIELABORADOS!$A$2:$M$6000,2,0),"") | C24: =+A24 -> 0 | D24: =IFERROR(VLOOKUP(H24,[1]SEMIELABORADOS!$A$2:$M$6000,6,0),"") | E24: =IFERROR(VLOOKUP(H24,[1]SEMIELABORADOS!$A$2:$H$65536,8,0),"") | F24: =IFERROR(E24*C24,"") | G24: =IFERROR(F24/$F$66,"")
A26: UNIDADES | B26: EMPAQUE | C26: UNIDADES | D26: UND MEDIDA | E26: COSTO UNITARIO | F26: TOTAL COSTO | G26: % PREC. DEFINIDO | H26: CODIGOS
A27: 1 | B27: =IFERROR(VLOOKUP(H27,'[1]Consolidado MP Planta'!$A$2:$M$823,3,0),"") -> BOLSA TRANSPARENTE 56X96X1.80 KILO | C27: =+A27 -> 1 | D27: =IFERROR(VLOOKUP(H27,'[1]Consolidado MP Planta'!$A$2:$M$823,13,0),"") -> Und | E27: =IFERROR(VLOOKUP(H27,'[1]Consolidado MP Planta'!$A$2:$M$823,12,0),"") -> 50 | F27: =IFERROR(C27*E27,"") -> 50 | G27: =IFERROR(F27/$F$66,"") -> 0.0073337535 | H27: 1950928
B28: =IFERROR(VLOOKUP(H28,'[1]Consolidado MP Planta'!$A$2:$M$823,3,0),"") | C28: =+A28 -> 0 | D28: =IFERROR(VLOOKUP(H28,'[1]Consolidado MP Planta'!$A$2:$M$823,13,0),"") | E28: =IFERROR(VLOOKUP(H28,'[1]Consolidado MP Planta'!$A$2:$M$823,12,0),"") | F28: =IFERROR(C28*E28,"") | G28: =IFERROR(F28/$F$66,"")
B29: =IFERROR(VLOOKUP(H29,'[1]Consolidado MP Planta'!$A$2:$M$823,3,0),"") | C29: =+A29 -> 0 | D29: =IFERROR(VLOOKUP(H29,'[1]Consolidado MP Planta'!$A$2:$M$823,13,0),"") | E29: =IFERROR(VLOOKUP(H29,'[1]Consolidado MP Planta'!$A$2:$M$823,12,0),"") | F29: =IFERROR(C29*E29,"") | G29: =IFERROR(F29/$F$66,"")
B30: =IFERROR(VLOOKUP(H30,'[1]Consolidado MP Planta'!$A$2:$M$823,3,0),"") | C30: =+A30 -> 0 | D30: =IFERROR(VLOOKUP(H30,'[1]Consolidado MP Planta'!$A$2:$M$823,13,0),"") | E30: =IFERROR(VLOOKUP(H30,'[1]Consolidado MP Planta'!$A$2:$M$823,12,0),"") | F30: =IFERROR(C30*E30,"") | G30: =IFERROR(F30/$F$66,"")
B31: =IFERROR(VLOOKUP(H31,'[1]Consolidado MP Planta'!$A$2:$M$823,3,0),"") | C31: =+A31 -> 0 | D31: =IFERROR(VLOOKUP(H31,'[1]Consolidado MP Planta'!$A$2:$M$823,13,0),"") | E31: =IFERROR(VLOOKUP(H31,'[1]Consolidado MP Planta'!$A$2:$M$823,12,0),"") | F31: =IFERROR(C31*E31,"") | G31: =IFERROR(F31/$F$66,"")
B32: =IFERROR(VLOOKUP(H32,'[1]Consolidado MP Planta'!$A$2:$M$823,3,0),"") | C32: =+A32 -> 0 | D32: =IFERROR(VLOOKUP(H32,'[1]Consolidado MP Planta'!$A$2:$M$823,13,0),"") | E32: =IFERROR(VLOOKUP(H32,'[1]Consolidado MP Planta'!$A$2:$M$823,12,0),"") | F32: =IFERROR(C32*E32,"") | G32: =IFERROR(F32/$F$66,"")
A34: UNIDADES | B34: EMPAQUE SEMIELABORADOS | C34: UNIDADES | D34: UND MEDIDA | E34: COSTO UNITARIO | F34: TOTAL COSTO | G34: % PREC. DEFINIDO | H34: CODIGOS
A35: =+A17 -> 1080 | B35: =IFERROR(VLOOKUP(H35,[1]SEMIELABORADOS!$A$2:$M$6000,2,0),"") -> AZUCAR BLANCO INDUSTRIAL KILO | C35: =+A35 -> 1080 | D35: =IFERROR(VLOOKUP(H35,[1]SEMIELABORADOS!$A$2:$M$6000,6,0),"") -> Gramo | E35: =IFERROR(VLOOKUP(H35,[1]SEMIELABORADOS!$A$2:$M$65536,10,0),"") -> 0.023759093 | F35: =IFERROR(E35*C35,"") -> 25.659821 | G35: =IFERROR(F35/$F$66,"") -> 0.003763656 | H35: 90100131
A36: =+A18 -> 3 | B36: =IFERROR(VLOOKUP(H36,[1]SEMIELABORADOS!$A$2:$M$6000,2,0),"") -> EMPAQUE SAL KILO | C36: =+A36 -> 3 | D36: =IFERROR(VLOOKUP(H36,[1]SEMIELABORADOS!$A$2:$M$6000,6,0),"") -> Gramo | E36: =IFERROR(VLOOKUP(H36,[1]SEMIELABORADOS!$A$2:$M$65536,10,0),"") -> 0.0053312 | F36: =IFERROR(E36*C36,"") -> 0.0159936 | G36: =IFERROR(F36/$F$66,"") -> 2.3458624e-06 | H36: 90100142
A37: =+A19 -> 0 | B37: =IFERROR(VLOOKUP(H37,[1]SEMIELABORADOS!$A$2:$M$6000,2,0),"") | C37: =+A37 -> 0 | D37: =IFERROR(VLOOKUP(H37,[1]SEMIELABORADOS!$A$2:$M$6000,6,0),"") | E37: =IFERROR(VLOOKUP(H37,[1]SEMIELABORADOS!$A$2:$M$65536,10,0),"") | F37: =IFERROR(E37*C37,"") | G37: =IFERROR(F37/$F$66,"")
A38: =+A20 -> 0 | B38: =IFERROR(VLOOKUP(H38,[1]SEMIELABORADOS!$A$2:$M$6000,2,0),"") | C38: =+A38 -> 0 | D38: =IFERROR(VLOOKUP(H38,[1]SEMIELABORADOS!$A$2:$M$6000,6,0),"") | E38: =IFERROR(VLOOKUP(H38,[1]SEMIELABORADOS!$A$2:$M$65536,10,0),"") | F38: =IFERROR(E38*C38,"") | G38: =IFERROR(F38/$F$66,"")
A39: =+A21 -> 0 | B39: =IFERROR(VLOOKUP(H39,[1]SEMIELABORADOS!$A$2:$M$6000,2,0),"") | C39: =+A39 -> 0 | D39: =IFERROR(VLOOKUP(H39,[1]SEMIELABORADOS!$A$2:$M$6000,6,0),"") | E39: =IFERROR(VLOOKUP(H39,[1]SEMIELABORADOS!$A$2:$M$65536,10,0),"") | F39: =IFERROR(E39*C39,"") | G39: =IFERROR(F39/$F$66,"")
A40: =+A22 -> 0 | B40: =IFERROR(VLOOKUP(H40,[1]SEMIELABORADOS!$A$2:$M$6000,2,0),"") | C40: =+A40 -> 0 | D40: =IFERROR(VLOOKUP(H40,[1]SEMIELABORADOS!$A$2:$M$6000,6,0),"") | E40: =IFERROR(VLOOKUP(H40,[1]SEMIELABORADOS!$A$2:$M$65536,10,0),"") | F40: =IFERROR(E40*C40,"") | G40: =IFERROR(F40/$F$66,"")
A41: =+A23 -> 0 | B41: =IFERROR(VLOOKUP(H41,[1]SEMIELABORADOS!$A$2:$M$6000,2,0),"") | C41: =+A41 -> 0 | D41: =IFERROR(VLOOKUP(H41,[1]SEMIELABORADOS!$A$2:$M$6000,6,0),"") | E41: =IFERROR(VLOOKUP(H41,[1]SEMIELABORADOS!$A$2:$M$65536,10,0),"") | F41: =IFERROR(E41*C41,"") | G41: =IFERROR(F41/$F$66,"")
A43: UNIDADES | B43: MODI | C43: UNIDADES | D43: UND MEDIDA | E43: COSTO UNITARIO | F43: TOTAL COSTO | G43: % PREC. DEFINIDO | H43: CODIGOS
A44: =+A35 -> 1080 | B44: =IFERROR(VLOOKUP(H44,[1]SEMIELABORADOS!$A$2:$M$6000,2,0),"") -> AZUCAR BLANCO INDUSTRIAL KILO | C44: =+A44 -> 1080 | D44: =IFERROR(VLOOKUP(H44,[1]SEMIELABORADOS!$A$2:$M$6000,6,0),"") -> Gramo | E44: =IFERROR(VLOOKUP(H44,[1]SEMIELABORADOS!$A$2:$M$65536,12,0),"") -> 0.03663 | F44: =IFERROR(E44*C44,"") -> 39.5604 | G44: =IFERROR(F44/$F$66,"") -> 0.0058025244 | H44: 90100131
A45: =+A36 -> 3 | B45: =IFERROR(VLOOKUP(H45,[1]SEMIELABORADOS!$A$2:$M$6000,2,0),"") -> EMPAQUE SAL KILO | C45: =+A45 -> 3 | D45: =IFERROR(VLOOKUP(H45,[1]SEMIELABORADOS!$A$2:$M$6000,6,0),"") -> Gramo | E45: =IFERROR(VLOOKUP(H45,[1]SEMIELABORADOS!$A$2:$M$65536,12,0),"") -> 0.022 | F45: =IFERROR(E45*C45,"") -> 0.066 | G45: =IFERROR(F45/$F$66,"") -> 9.6805546e-06 | H45: 90100142
...

Sheet EMPAQUE BRITTLE
B1: SERVICIOS DE PASTELERIA S.A. | G1: CÓDIGO:
B2: ESPECIFICACION DE RECETA | G2: REVISIÓN:
B3: Empaque Brittle almendras 160g | G3: FECHA DE APROBACIÓN:
B4: Elaborado | C4: Javier Tong, Chef
B5: Aprobado | C5: Esteban Cartin, Gte Manufactura
A7: AREA QUE PRODUCE: | C7: Postre | F7: AREA QUE EMPACA: | H7: Postre
A8: # Código | B8: Descripción del ingrediente | C8: Marca | D8: Unidad Internacional | F8: Medida alternativa | H8: Costo - Referencia
D9: Cantidad | E9: Unidad medida | F9: Cantidad | G9: Unidad medida | H9: Colones
A10: 902000116 | B10: BRITTLE DE ALMENDRAS | C10: FAS | D10: 160 | E10: g
A13: 1950705 | B13: BOLSA 8x12 TRANSPARENTE KILO | C13: CEMUSA | D13: 1 | E13: ud
A14: 702069 | B14: ETIQ.BLANCA 1 1/4 * 3/4 (UND) | C14: CEMUSA | D14: 1 | E14: ud
A15: 701096 | B15: ETIQUETA BLANCA R-153 (UND) | C15: Cemusa | D15: 1 | E15: ud
A16: 702007 | B16: ETIQ.FECHA VENCIMIENTO BLANCO (ROLLO) | C16: CEMUSA | D16: 1 | E16: ud
C18: Cantidad | D18: Unidad
A19: PESO TOTAL OBTENIDO | C19: 160 | D19: g
A20: TIEMPO TOTAL DE PREPARACION | C20: 30 | D20: SEG
A21: CANTIDAD DE PORCIONES OBTENIDAS | C21: 1 | D21: ud
A22: PESO DE CADA PORCIÓN | C22: 160 | D22: g
A23: MERMA | C23: 0 | D23: g
A24: PROCEDIMIENTO DE PREPARACION DE LA RECETA
A25: 1, Empacar 160g de Brittle en una bolsa 8*12, hacer nudo
A26: 2, Etiquetar

Sheet COSTO EMPAQUE BRITTLE
E1: Precio Local | F1: Costo MP | G1: Costo EM | H1: Costo MO
E2: =IFERROR(O62,"") -> 691.90292 | F2: =IFERROR(H53,"") -> 442.51886 | G2: =IFERROR(H54,"") -> 14.204065 | H2: =IFERROR(H56,"") -> 118.67011
A5: ESTRUCTURA DE COSTOS
F6: Fecha: | H6: =TODAY() -> 45754
A7: UNIDADES | B7: DESCRIPCION MAT.PRIMA | C7: UNIDADES | D7: UND MEDIDA | E7: COSTO UNITARIO | F7: TOTAL COSTO | G7: % PREC. DEFINIDO | H7: CODIGOS
B8: =IFERROR(VLOOKUP(H8,'[1]Consolidado MP Planta'!$A$2:$M$823,3,0),"") | C8: =+A8 -> 0 | D8: =IFERROR(VLOOKUP(H8,'[1]Consolidado MP Planta'!$A$2:$M$823,13,0),"") | E8: =IFERROR(VLOOKUP(H8,'[1]Consolidado MP Planta'!$A$2:$M$823,12,0),"") | F8: =IFERROR(C8*E8,"") | G8: =IFERROR(F8/$F$66,"")
B9: =IFERROR(VLOOKUP(H9,'[1]Consolidado MP Planta'!$A$2:$M$823,3,0),"") | C9: =+A9 -> 0 | D9: =IFERROR(VLOOKUP(H9,'[1]Consolidado MP Planta'!$A$2:$M$823,13,0),"") | E9: =IFERROR(VLOOKUP(H9,'[1]Consolidado MP Planta'!$A$2:$M$823,12,0),"") | F9: =IFERROR(C9*E9,"") | G9: =IFERROR(F9/$F$66,"")
B10: =IFERROR(VLOOKUP(H10,'[1]Consolidado MP Planta'!$A$2:$M$823,3,0),"") | C10: =+A10 -> 0 | D10: =IFERROR(VLOOKUP(H10,'[1]Consolidado MP Planta'!$A$2:$M$823,13,0),"") | E10: =IFERROR(VLOOKUP(H10,'[1]Consolidado MP Planta'!$A$2:$M$823,12,0),"") | F10: =IFERROR(C10*E10,"") | G10: =IFERROR(F10/$F$66,"")
B11: =IFERROR(VLOOKUP(H11,'[1]Consolidado MP Planta'!$A$2:$M$823,3,0),"") | C11: =+A11 -> 0 | D11: =IFERROR(VLOOKUP(H11,'[1]Consolidado MP Planta'!$A$2:$M$823,13,0),"") | E11: =IFERROR(VLOOKUP(H11,'[1]Consolidado MP Planta'!$A$2:$M$823,12,0),"") | F11: =IFERROR(C11*E11,"") | G11: =IFERROR(F11/$F$66,"")
B12: =IFERROR(VLOOKUP(H12,'[1]Consolidado MP Planta'!$A$2:$M$823,3,0),"") | C12: =+A12 -> 0 | D12: =IFERROR(VLOOKUP(H12,'[1]Consolidado MP Planta'!$A$2:$M$823,13,0),"") | E12: =IFERROR(VLOOKUP(H12,'[1]Consolidado MP Planta'!$A$2:$M$823,12,0),"") | F12: =IFERROR(C12*E12,"") | G12: =IFERROR(F12/$F$66,"")
B13: =IFERROR(VLOOKUP(H13,'[1]Consolidado MP Planta'!$A$2:$M$823,3,0),"") | C13: =+A13 -> 0 | D13: =IFERROR(VLOOKUP(H13,'[1]Consolidado MP Planta'!$A$2:$M$823,13,0),"") | E13: =IFERROR(VLOOKUP(H13,'[1]Consolidado MP Planta'!$A$2:$M$823,12,0),"") | F13: =IFERROR(C13*E13,"") | G13: =IFERROR(F13/$F$66,"")
B14: =IFERROR(VLOOKUP(H14,'[1]Consolidado MP Planta'!$A$2:$M$823,3,0),"") | C14: =+A14 -> 0 | D14: =IFERROR(VLOOKUP(H14,'[1]Consolidado MP Planta'!$A$2:$M$823,13,0),"") | E14: =IFERROR(VLOOKUP(H14,'[1]Consolidado MP Planta'!$A$2:$M$823,12,0),"") | F14: =IFERROR(C14*E14,"") | G14: =IFERROR(F14/$F$66,"")
B15: =IFERROR(VLOOKUP(H15,'[2]ARTICULOS MP PLANTA'!$A$2:$G$589,2,0),"")
A16: UNIDADES | B16: MATERIA PRIMA SEMIELABORADOS | C16: UNIDADES | D16: UND MEDIDA | E16: COSTO UNITARIO | F16: TOTAL COSTO | G16: % PREC. DEFINIDO | H16: CODIGOS
A17: 160 | B17: BRITTLE DE ALMENDRAS | C17: =+A17 -> 160 | D17: Gramos | E17: =+'costeo brittle'!E69 -> 2.7657428 | F17: =IFERROR(E17*C17,"") -> 442.51886 | G17: =IFERROR(F17/$F$66,"") -> 0.89747074
B18: =IFERROR(VLOOKUP(H18,[1]SEMIELABORADOS!$A$2:$M$6000,2,0),"") | C18: =+A18 -> 0 | D18: =IFERROR(VLOOKUP(H18,[1]SEMIELABORADOS!$A$2:$M$6000,6,0),"") | E18: =IFERROR(VLOOKUP(H18,[1]SEMIELABORADOS!$A$2:$H$65536,8,0),"") | F18: =IFERROR(E18*C18,"") | G18: =IFERROR(F18/$F$66,"")
B19: =IFERROR(VLOOKUP(H19,[1]SEMIELABORADOS!$A$2:$M$6000,2,0),"") | C19: =+A19 -> 0 | D19: =IFERROR(VLOOKUP(H19,[1]SEMIELABORADOS!$A$2:$M$6000,6,0),"") | E19: =IFERROR(VLOOKUP(H19,[1]SEMIELABORADOS!$A$2:$H$65536,8,0),"") | F19: =IFERROR(E19*C19,"") | G19: =IFERROR(F19/$F$66,"")
B20: =IFERROR(VLOOKUP(H20,[1]SEMIELABORADOS!$A$2:$M$6000,2,0),"") | C20: =+A20 -> 0 | D20: =IFERROR(VLOOKUP(H20,[1]SEMIELABORADOS!$A$2:$M$6000,6,0),"") | E20: =IFERROR(VLOOKUP(H20,[1]SEMIELABORADOS!$A$2:$H$65536,8,0),"") | F20: =IFERROR(E20*C20,"") | G20: =IFERROR(F20/$F$66,"")
B21: =IFERROR(VLOOKUP(H21,[1]SEMIELABORADOS!$A$2:$M$6000,2,0),"") | C21: =+A21 -> 0 | D21: =IFERROR(VLOOKUP(H21,[1]SEMIELABORADOS!$A$2:$M$6000,6,0),"") | E21: =IFERROR(VLOOKUP(H21,[1]SEMIELABORADOS!$A$2:$H$65536,8,0),"") | F21: =IFERROR(E21*C21,"") | G21: =IFERROR(F21/$F$66,"")
B22: =IFERROR(VLOOKUP(H22,[1]SEMIELABORADOS!$A$2:$M$6000,2,0),"") | C22: =+A22 -> 0 | D22: =IFERROR(VLOOKUP(H22,[1]SEMIELABORADOS!$A$2:$M$6000,6,0),"") | E22: =IFERROR(VLOOKUP(H22,[1]SEMIELABORADOS!$A$2:$H$65536,8,0),"") | F22: =IFERROR(E22*C22,"") | G22: =IFERROR(F22/$F$66,"")
B23: =IFERROR(VLOOKUP(H23,[1]SEMIELABORADOS!$A$2:$M$6000,2,0),"") | C23: =+A23 -> 0 | D23: =IFERROR(VLOOKUP(H23,[1]SEMIELABORADOS!$A$2:$M$6000,6,0),"") | E23: =IFERROR(VLOOKUP(H23,[1]SEMIELABORADOS!$A$2:$H$65536,8,0),"") | F23: =IFERROR(E23*C23,"") | G23: =IFERROR(F23/$F$66,"")
B24: =IFERROR(VLOOKUP(H24,[1]SEMIELABORADOS!$A$2:$M$6000,2,0),"") | C24: =+A24 -> 0 | D24: =IFERROR(VLOOKUP(H24,[1]SEMIELABORADOS!$A$2:$M$6000,6,0),"") | E24: =IFERROR(VLOOKUP(H24,[1]SEMIELABORADOS!$A$2:$H$65536,8,0),"") | F24: =IFERROR(E24*C24,"") | G24: =IFERROR(F24/$F$66,"")
A26: UNIDADES | B26: EMPAQUE | C26: UNIDADES | D26: UND MEDIDA | E26: COSTO UNITARIO | F26: TOTAL COSTO | G26: % PREC. DEFINIDO | H26: CODIGOS
A27: 1 | B27: =IFERROR(VLOOKUP(H27,'[1]Consolidado MP Planta'!$A$2:$M$823,3,0),"") -> BOLSA 8x12 TRANSPARENTE KILO | C27: =+A27 -> 1 | D27: =IFERROR(VLOOKUP(H27,'[1]Consolidado MP Planta'!$A$2:$M$823,13,0),"") -> Und | E27: =IFERROR(VLOOKUP(H27,'[1]Consolidado MP Planta'!$A$2:$M$823,12,0),"") -> 7 | F27: =IFERROR(C27*E27,"") -> 7 | G27: =IFERROR(F27/$F$66,"") -> 0.014196672 | H27: 1950705
A28: 1 | B28: =IFERROR(VLOOKUP(H28,'[1]Consolidado MP Planta'!$A$2:$M$823,3,0),"") -> ETIQ.BLANCA 1 1/4 * 3/4 (UND) | C28: =+A28 -> 1 | D28: =IFERROR(VLOOKUP(H28,'[1]Consolidado MP Planta'!$A$2:$M$823,13,0),"") -> Und | E28: =IFERROR(VLOOKUP(H28,'[1]Consolidado MP Planta'!$A$2:$M$823,12,0),"") -> 0.58 | F28: =IFERROR(C28*E28,"") -> 0.58 | G28: =IFERROR(F28/$F$66,"") -> 0.0011762957 | H28: 0702069
A29: 1 | B29: =IFERROR(VLOOKUP(H29,'[1]Consolidado MP Planta'!$A$2:$M$823,3,0),"") -> ETIQUETA BLANCA R-153 (UND) | C29: =+A29 -> 1 | D29: =IFERROR(VLOOKUP(H29,'[1]Consolidado MP Planta'!$A$2:$M$823,13,0),"") -> Und | E29: =IFERROR(VLOOKUP(H29,'[1]Consolidado MP Planta'!$A$2:$M$823,12,0),"") -> 0.39 | F29: =IFERROR(C29*E29,"") -> 0.39 | G29: =IFERROR(F29/$F$66,"") -> 0.00079095745 | H29: 701096
A30: 1 | B30: ETIQ.FECHA VENCIMIENTO BLANCO (ROLLO) | C30: =+A30 -> 1 | D30: Und | E30: 0.18 | F30: =IFERROR(C30*E30,"") -> 0.18 | G30: =IFERROR(F30/$F$66,"") -> 0.00036505729 | H30: 702007
B31: =IFERROR(VLOOKUP(H31,'[1]Consolidado MP Planta'!$A$2:$M$823,3,0),"") | C31: =+A31 -> 0 | D31: =IFERROR(VLOOKUP(H31,'[1]Consolidado MP Planta'!$A$2:$M$823,13,0),"") | E31: =IFERROR(VLOOKUP(H31,'[1]Consolidado MP Planta'!$A$2:$M$823,12,0),"") | F31: =IFERROR(C31*E31,"") | G31: =IFERROR(F31/$F$66,"")
B32: =IFERROR(VLOOKUP(H32,'[1]Consolidado MP Planta'!$A$2:$M$823,3,0),"") | C32: =+A32 -> 0 | D32: =IFERROR(VLOOKUP(H32,'[1]Consolidado MP Planta'!$A$2:$M$823,13,0),"") | E32: =IFERROR(VLOOKUP(H32,'[1]Consolidado MP Planta'!$A$2:$M$823,12,0),"") | F32: =IFERROR(C32*E32,"") | G32: =IFERROR(F32/$F$66,"")
A34: UNIDADES | B34: EMPAQUE SEMIELABORADOS | C34: UNIDADES | D34: UND MEDIDA | E34: COSTO UNITARIO | F34: TOTAL COSTO | G34: % PREC. DEFINIDO | H34: CODIGOS
A35: =+A17 -> 160 | B35: BRITTLE DE ALMENDRAS | C35: =+A35 -> 160 | D35: Gramos | E35: =+'costeo brittle'!E76 -> 0.037837907 | F35: =IFERROR(E35*C35,"") -> 6.0540652 | G35: =IFERROR(F35/$F$66,"") -> 0.012278226
A36: =+A18 -> 0 | B36: =IFERROR(VLOOKUP(H36,[1]SEMIELABORADOS!$A$2:$M$6000,2,0),"") | C36: =+A36 -> 0 | D36: =IFERROR(VLOOKUP(H36,[1]SEMIELABORADOS!$A$2:$M$6000,6,0),"") | E36: =IFERROR(VLOOKUP(H36,[1]SEMIELABORADOS!$A$2:$M$65536,10,0),"") | F36: =IFERROR(E36*C36,"") | G36: =IFERROR(F36/$F$66,"")
A37: =+A19 -> 0 | B37: =IFERROR(VLOOKUP(H37,[1]SEMIELABORADOS!$A$2:$M$6000,2,0),"") | C37: =+A37 -> 0 | D37: =IFERROR(VLOOKUP(H37,[1]SEMIELABORADOS!$A$2:$M$6000,6,0),"") | E37: =IFERROR(VLOOKUP(H37,[1]SEMIELABORADOS!$A$2:$M$65536,10,0),"") | F37: =IFERROR(E37*C37,"") | G37: =IFERROR(F37/$F$66,"")
A38: =+A20 -> 0 | B38: =IFERROR(VLOOKUP(H38,[1]SEMIELABORADOS!$A$2:$M$6000,2,0),"") | C38: =+A38 -> 0 | D38: =IFERROR(VLOOKUP(H38,[1]SEMIELABORADOS!$A$2:$M$6000,6,0),"") | E38: =IFERROR(VLOOKUP(H38,[1]SEMIELABORADOS!$A$2:$M$65536,10,0),"") | F38: =IFERROR(E38*C38,"") | G38: =IFERROR(F38/$F$66,"")
A39: =+A21 -> 0 | B39: =IFERROR(VLOOKUP(H39,[1]SEMIELABORADOS!$A$2:$M$6000,2,0),"") | C39: =+A39 -> 0 | D39: =IFERROR(VLOOKUP(H39,[1]SEMIELABORADOS!$A$2:$M$6000,6,0),"") | E39: =IFERROR(VLOOKUP(H39,[1]SEMIELABORADOS!$A$2:$M$65536,10,0),"") | F39: =IFERROR(E39*C39,"") | G39: =IFERROR(F39/$F$66,"")
A40: =+A22 -> 0 | B40: =IFERROR(VLOOKUP(H40,[1]SEMIELABORADOS!$A$2:$M$6000,2,0),"") | C40: =+A40 -> 0 | D40: =IFERROR(VLOOKUP(H40,[1]SEMIELABORADOS!$A$2:$M$6000,6,0),"") | E40: =IFERROR(VLOOKUP(H40,[1]SEMIELABORADOS!$A$2:$M$65536,10,0),"") | F40: =IFERROR(E40*C40,"") | G40: =IFERROR(F40/$F$66,"")
A41: =+A23 -> 0 | B41: =IFERROR(VLOOKUP(H41,[1]SEMIELABORADOS!$A$2:$M$6000,2,0),"") | C41: =+A41 -> 0 | D41: =IFERROR(VLOOKUP(H41,[1]SEMIELABORADOS!$A$2:$M$6000,6,0),"") | E41: =IFERROR(VLOOKUP(H41,[1]SEMIELABORADOS!$A$2:$M$65536,10,0),"") | F41: =IFERROR(E41*C41,"") | G41: =IFERROR(F41/$F$66,"")
A43: UNIDADES | B43: MODI | C43: UNIDADES | D43: UND MEDIDA | E43: COSTO UNITARIO | F43: TOTAL COSTO | G43: % PREC. DEFINIDO | H43: CODIGOS
A44: =+A35 -> 160 | B44: BRITTLE DE ALMENDRAS | C44: =+A44 -> 160 | D44: Gramos | E44: =+'costeo brittle'!E74 -> 0.5698132 | F44: =IFERROR(E44*C44,"") -> 91.170112 | G44: =IFERROR(F44/$F$66,"") -> 0.18490174
A45: =+A36 -> 0 | B45: =IFERROR(VLOOKUP(H45,[1]SEMIELABORADOS!$A$2:$M$6000,2,0),"") | C45: =+A45 -> 0 | D45: =IFERROR(VLOOKUP(H45,[1]SEMIELABORADOS!$A$2:$M$6000,6,0),"") | E45: =IFERROR(VLOOKUP(H45,[1]SEMIELABORADOS!$A$2:$M$65536,12,0),"") | F45: =IFERROR(E45*C45,"") | G45: =IFERROR(F45/$F$66,"")
...

Sheet ENSAMBLE 2
B1: SERVICIOS DE PASTELERIA S.A. | G1: CÓDIGO:
B2: ESPECIFICACION DE RECETA | G2: REVISIÓN:
B3: Postre caramelo y almendras (dia de la madre 2021) | G3: FECHA DE APROBACIÓN:
B4: Elaborado | C4: Javier Tong, Chef
B5: Aprobado | C5: Esteban Cartin, Gte Manufactura
A7: AREA QUE PRODUCE: | C7: Postre | F7: AREA QUE EMPACA: | H7: Postre
A8: # Código | B8: Descripción del ingrediente | C8: Marca | D8: Unidad Internacional | F8: Medida alternativa | H8: Costo - Referencia
D9: Cantidad | E9: Unidad medida | F9: Cantidad | G9: Unidad medida | H9: Colones
A10: 907000002 | B10: BASE GALLETA P/CHEESE CAKE (KILO) | C10: FAS | D10: 200 | E10: g
A11: 90200029 | B11: RELLENO CHEESECAKE KILO | C11: FAS | D11: 300 | E11: g
A12: 410154 | B12: RELLENO CARAMELO (KILO) | C12: CONEXU | D12: 120 | E12: g
A13: 90200029 | B13: RELLENO CHEESECAKE KILO | C13: FAS | D13: 300 | E13: g
B14: DECORACION
A15: 901000111 | B15: GANACHE DE DULCE LECHE (4800g) | C15: FAS | D15: 90 | E15: g | F15: Espejo
E16: g | F16: 3/4 tz
B17: CHOCOLATE CORAZON DORADO | C17: Karol | D17: 1 | E17: ud
A18: 1112431 | B18: MANJAR LECHE CONDENSADA (PAQ: 4.5 K) | C18: NESTLE | D18: 20 | E18: g | F18: Para pegar
B19: EMPAQUE
A20: 702182 | B20: ETIQUETA IMP. SPOON MEDIANA V-273 (UND) | C20: ETIPLAST | D20: 1 | E20: ud
A21: 703020 | B21: CINTA ADHESIVA TRANSPARENT 2*100 M (UND) | C21: ETIPLAST | D21: 60 | E21: cm
A22: 1950693 | B22: ORLA CARTON 9" DORADA (UND ) | C22: RAPIBOX | D22: 1 | E22: ud
A23: 51400021 | B23: QUEQUERA RED C/BASE ALTA 9" (CAJA:100 U) | C23: Exp PMT | D23: 1 | E23: ud
A24: 702123 | B24: ETIQUETA BLANCA 2 5/8X1 15/16 (UND) | C24: Cemusa | D24: 1 | E24: ud
A25: 701096 | B25: ETIQUETA BLANCA R-153 (UND) | C25: Cemusa | D25: 1 | E25: ud
A26: 702007 | B26: ETIQ.FECHA VENCIMIENTO BLANCO (ROLLO) | C26: CEMUSA | D26: 1 | E26: ud
C28: Cantidad | D28: Unidad
A29: PESO TOTAL OBTENIDO | C29: 950 | D29: g
A30: TIEMPO TOTAL DE PREPARACION | C30: 5 | D30: min
A31: CANTIDAD DE PORCIONES OBTENIDAS | C31: 1 | D31: ud
A32: PESO DE CADA PORCIÓN | C32: 950 | D32: g
A33: MERMA | C33: 191 | D33: g
A34: PROCEDIMIENTO DE PREPARACION DE LA RECETA
A35: 1.- Colocar dentro del molde desarmable redondo 21 cm ,previamente ensagrasado la base de galleta presionar y hornear a 175°C por 7 min en el Argental, a 175°C por 8 min en el Dicte 1 y Dicte 2, a 170°C en el Dicte 3 y a 175°C por 7 min en el Marshal
A36: 2.- Una vez fria la galleta, dosificar en el molde 275g de mezcla de cheesecake, 120g de caramelo y 275g de mezcla de cheesecake. Dejar enfriar al menos 6 horas en Refrigeracion
A37: 3.- Desmoldar con ayuda de una espatula.
A38: 4.- Pegar a la orla con manjar, decorar con ganache en el hacinedo espejo y dejar chorrear. sobre este ganache colocar el brittle de almednras.
A39: 5.- Decorar con un corazon de chocolate, tapar y etiquetar

Sheet Hoja5

Sheet COSTEO ENSAMBLE
E1: Precio Local | F1: Costo MP | G1: Costo EM | H1: Costo MO
E2: =IFERROR(O67,"") -> 3912.1697 | F2: =IFERROR(H58,"") -> 2227.3038 | G2: =IFERROR(H59,"") -> 393.7941 | H2: =IFERROR(H61,"") -> 386.06712
A5: ESTRUCTURA DE COSTOS
F6: Fecha: | H6: =TODAY() -> 45754
A7: UNIDADES | B7: DESCRIPCION MAT.PRIMA | C7: UNIDADES | D7: UND MEDIDA | E7: COSTO UNITARIO | F7: TOTAL COSTO | G7: % PREC. DEFINIDO | H7: CODIGOS
A8: 120 | B8: =IFERROR(VLOOKUP(H8,'[1]Consolidado MP Planta'!$A$2:$M$823,3,0),"") -> RELLENO CARAMELO KILO | C8: =+A8 -> 120 | D8: =IFERROR(VLOOKUP(H8,'[1]Consolidado MP Planta'!$A$2:$M$823,13,0),"") -> Gramos | E8: =IFERROR(VLOOKUP(H8,'[1]Consolidado MP Planta'!$A$2:$M$823,12,0),"") -> 3.335 | F8: =IFERROR(C8*E8,"") -> 400.2 | G8: =IFERROR(F8/$F$71,"") -> 0.13609264 | H8: 0410154
B9: =IFERROR(VLOOKUP(H9,'[1]Consolidado MP Planta'!$A$2:$M$823,3,0),"") -> CHOCOLATE CORAZON ROJO PASION (CAJA:200) | C9: =+A9 -> 0 | D9: =IFERROR(VLOOKUP(H9,'[1]Consolidado MP Planta'!$A$2:$M$823,13,0),"") -> Und | E9: =IFERROR(VLOOKUP(H9,'[1]Consolidado MP Planta'!$A$2:$M$823,12,0),"") -> 38.25 | F9: =IFERROR(C9*E9,"") -> 0 | G9: =IFERROR(F9/$F$71,"") -> 0 | H9: 10700029
A10: 20 | B10: =IFERROR(VLOOKUP(H10,'[1]Consolidado MP Planta'!$A$2:$M$823,3,0),"") -> MANJAR LECHE CONDENSADA (PAQ: 4.5 K) | C10: =+A10 -> 20 | D10: =IFERROR(VLOOKUP(H10,'[1]Consolidado MP Planta'!$A$2:$M$823,13,0),"") -> Gramos | E10: =IFERROR(VLOOKUP(H10,'[1]Consolidado MP Planta'!$A$2:$M$823,12,0),"") -> 2.142 | F10: =IFERROR(C10*E10,"") -> 42.84 | G10: =IFERROR(F10/$F$71,"") -> 0.014568237 | H10: 1112431
B11: =IFERROR(VLOOKUP(H11,'[1]Consolidado MP Planta'!$A$2:$M$823,3,0),"") | C11: =+A11 -> 0 | D11: =IFERROR(VLOOKUP(H11,'[1]Consolidado MP Planta'!$A$2:$M$823,13,0),"") | E11: =IFERROR(VLOOKUP(H11,'[1]Consolidado MP Planta'!$A$2:$M$823,12,0),"") | F11: =IFERROR(C11*E11,"") | G11: =IFERROR(F11/$F$71,"")
B12: =IFERROR(VLOOKUP(H12,'[1]Consolidado MP Planta'!$A$2:$M$823,3,0),"") | C12: =+A12 -> 0 | D12: =IFERROR(VLOOKUP(H12,'[1]Consolidado MP Planta'!$A$2:$M$823,13,0),"") | E12: =IFERROR(VLOOKUP(H12,'[1]Consolidado MP Planta'!$A$2:$M$823,12,0),"") | F12: =IFERROR(C12*E12,"") | G12: =IFERROR(F12/$F$71,"")
B13: =IFERROR(VLOOKUP(H13,'[1]Consolidado MP Planta'!$A$2:$M$823,3,0),"") | C13: =+A13 -> 0 | D13: =IFERROR(VLOOKUP(H13,'[1]Consolidado MP Planta'!$A$2:$M$823,13,0),"") | E13: =IFERROR(VLOOKUP(H13,'[1]Consolidado MP Planta'!$A$2:$M$823,12,0),"") | F13: =IFERROR(C13*E13,"") | G13: =IFERROR(F13/$F$71,"")
B14: =IFERROR(VLOOKUP(H14,'[1]Consolidado MP Planta'!$A$2:$M$823,3,0),"") | C14: =+A14 -> 0 | D14: =IFERROR(VLOOKUP(H14,'[1]Consolidado MP Planta'!$A$2:$M$823,13,0),"") | E14: =IFERROR(VLOOKUP(H14,'[1]Consolidado MP Planta'!$A$2:$M$823,12,0),"") | F14: =IFERROR(C14*E14,"") | G14: =IFERROR(F14/$F$71,"")
B15: =IFERROR(VLOOKUP(H15,'[2]ARTICULOS MP PLANTA'!$A$2:$G$589,2,0),"")
A16: UNIDADES | B16: MATERIA PRIMA SEMIELABORADOS | C16: UNIDADES | D16: UND MEDIDA | E16: COSTO UNITARIO | F16: TOTAL COSTO | G16: % PREC. DEFINIDO | H16: CODIGOS
A17: 200 | B17: =IFERROR(VLOOKUP(H17,[1]SEMIELABORADOS!$A$2:$M$6000,2,0),"") -> BASE GALLETA P/CHEESE CAKE (KILO) | C17: =+A17 -> 200 | D17: =IFERROR(VLOOKUP(H17,[1]SEMIELABORADOS!$A$2:$M$6000,6,0),"") -> Gramo | E17: =IFERROR(VLOOKUP(H17,[1]SEMIELABORADOS!$A$2:$H$65536,8,0),"") -> 2.0071033 | F17: =IFERROR(E17*C17,"") -> 401.42065 | G17: =IFERROR(F17/$F$71,"") -> 0.13650773 | H17: 907000002
A18: 600 | B18: =IFERROR(VLOOKUP(H18,[1]SEMIELABORADOS!$A$2:$M$6000,2,0),"") -> RELLENO CHEESECAKE KILO | C18: =+A18 -> 600 | D18: =IFERROR(VLOOKUP(H18,[1]SEMIELABORADOS!$A$2:$M$6000,6,0),"") -> Gramo | E18: =IFERROR(VLOOKUP(H18,[1]SEMIELABORADOS!$A$2:$H$65536,8,0),"") -> 1.8699122 | F18: =IFERROR(E18*C18,"") -> 1121.9473 | G18: =IFERROR(F18/$F$71,"") -> 0.38153117 | H18: 90200029
A19: 90 | B19: GANACHE DE DULCE LECHE (4800g) | C19: =+A19 -> 90 | D19: Gramo | E19: =+'[3]COSTEO GANACHE'!$E$69 -> 2.8988426 | F19: =IFERROR(E19*C19,"") -> 260.89583 | G19: =IFERROR(F19/$F$71,"") -> 0.088720645 | H19: 901000111
A20: 0 | B20: =IFERROR(VLOOKUP(H20,[1]SEMIELABORADOS!$A$2:$M$6000,2,0),"") -> CREMA DULCE LECHE KILO | C20: =+A20 -> 0 | D20: =IFERROR(VLOOKUP(H20,[1]SEMIELABORADOS!$A$2:$M$6000,6,0),"") -> Gramo | E20: =IFERROR(VLOOKUP(H20,[1]SEMIELABORADOS!$A$2:$H$65536,8,0),"") -> 1.9863913 | F20: =IFERROR(E20*C20,"") -> 0 | G20: =IFERROR(F20/$F$71,"") -> 0 | H20: 96344
B22: =IFERROR(VLOOKUP(H22,[1]SEMIELABORADOS!$A$2:$M$6000,2,0),"") | C22: =+A22 -> 0 | D22: =IFERROR(VLOOKUP(H22,[1]SEMIELABORADOS!$A$2:$M$6000,6,0),"") | E22: =IFERROR(VLOOKUP(H22,[1]SEMIELABORADOS!$A$2:$H$65536,8,0),"") | F22: =IFERROR(E22*C22,"") | G22: =IFERROR(F22/$F$71,"")
B23: =IFERROR(VLOOKUP(H23,[1]SEMIELABORADOS!$A$2:$M$6000,2,0),"") | C23: =+A23 -> 0 | D23: =IFERROR(VLOOKUP(H23,[1]SEMIELABORADOS!$A$2:$M$6000,6,0),"") | E23: =IFERROR(VLOOKUP(H23,[1]SEMIELABORADOS!$A$2:$H$65536,8,0),"") | F23: =IFERROR(E23*C23,"") | G23: =IFERROR(F23/$F$71,"")
B24: =IFERROR(VLOOKUP(H24,[1]SEMIELABORADOS!$A$2:$M$6000,2,0),"") | C24: =+A24 -> 0 | D24: =IFERROR(VLOOKUP(H24,[1]SEMIELABORADOS!$A$2:$M$6000,6,0),"") | E24: =IFERROR(VLOOKUP(H24,[1]SEMIELABORADOS!$A$2:$H$65536,8,0),"") | F24: =IFERROR(E24*C24,"") | G24: =IFERROR(F24/$F$71,"")
A26: UNIDADES | B26: EMPAQUE | C26: UNIDADES | D26: UND MEDIDA | E26: COSTO UNITARIO | F26: TOTAL COSTO | G26: % PREC. DEFINIDO | H26: CODIGOS
A27: 1 | B27: =IFERROR(VLOOKUP(H27,'[1]Consolidado MP Planta'!$A$2:$M$823,3,0),"") -> ETIQUETA IMP. SPOON MEDIANA V-273 (UND) | C27: =+A27 -> 1 | D27: =IFERROR(VLOOKUP(H27,'[1]Consolidado MP Planta'!$A$2:$M$823,13,0),"") -> Und | E27: =IFERROR(VLOOKUP(H27,'[1]Consolidado MP Planta'!$A$2:$M$823,12,0),"") -> 32.49 | F27: =IFERROR(C27*E27,"") -> 32.49 | G27: =IFERROR(F27/$F$71,"") -> 0.0110486 | H27: 702182
A28: 60 | B28: =IFERROR(VLOOKUP(H28,'[1]Consolidado MP Planta'!$A$2:$M$823,3,0),"") -> CINTA ADHESIVA TRANSPARENT 2*100 M (UND) | C28: =+A28 -> 60 | D28: =IFERROR(VLOOKUP(H28,'[1]Consolidado MP Planta'!$A$2:$M$823,13,0),"") -> Cm | E28: =IFERROR(VLOOKUP(H28,'[1]Consolidado MP Planta'!$A$2:$M$823,12,0),"") -> 0.145 | F28: =IFERROR(C28*E28,"") -> 8.7 | G28: =IFERROR(F28/$F$71,"") -> 0.0029585356 | H28: 703020
A29: 1 | B29: =IFERROR(VLOOKUP(H29,'[1]Consolidado MP Planta'!$A$2:$M$823,3,0),"") -> ORLA #9 DORADA (UND) | C29: =+A29 -> 1 | D29: =IFERROR(VLOOKUP(H29,'[1]Consolidado MP Planta'!$A$2:$M$823,13,0),"") -> Und | E29: =IFERROR(VLOOKUP(H29,'[1]Consolidado MP Planta'!$A$2:$M$823,12,0),"") -> 105 | F29: =IFERROR(C29*E29,"") -> 105 | G29: =IFERROR(F29/$F$71,"") -> 0.035706464 | H29: 1950693
A30: 1 | B30: =IFERROR(VLOOKUP(H30,'[1]Consolidado MP Planta'!$A$2:$M$823,3,0),"") -> QUEQUERA RED C/BASE ALTA 9" (CAJA:100 U) | C30: =+A30 -> 1 | D30: =IFERROR(VLOOKUP(H30,'[1]Consolidado MP Planta'!$A$2:$M$823,13,0),"") -> Und | E30: =IFERROR(VLOOKUP(H30,'[1]Consolidado MP Planta'!$A$2:$M$823,12,0),"") -> 244.36 | F30: =IFERROR(C30*E30,"") -> 244.36 | G30: =IFERROR(F30/$F$71,"") -> 0.083097444 | H30: 51400021
A31: 1 | B31: =IFERROR(VLOOKUP(H31,'[1]Consolidado MP Planta'!$A$2:$M$823,3,0),"") -> ETIQUETA BLANCA 2 5/8X1 15/16 (UND) | C31: =+A31 -> 1 | D31: =IFERROR(VLOOKUP(H31,'[1]Consolidado MP Planta'!$A$2:$M$823,13,0),"") -> Und | E31: =IFERROR(VLOOKUP(H31,'[1]Consolidado MP Planta'!$A$2:$M$823,12,0),"") -> 2.128 | F31: =IFERROR(C31*E31,"") -> 2.128 | G31: =IFERROR(F31/$F$71,"") -> 0.00072365101 | H31: 0702123
A32: 1 | B32: =IFERROR(VLOOKUP(H32,'[1]Consolidado MP Planta'!$A$2:$M$823,3,0),"") -> ETIQUETA BLANCA R-153 (UND) | C32: =+A32 -> 1 | D32: =IFERROR(VLOOKUP(H32,'[1]Consolidado MP Planta'!$A$2:$M$823,13,0),"") -> Und | E32: =IFERROR(VLOOKUP(H32,'[1]Consolidado MP Planta'!$A$2:$M$823,12,0),"") -> 0.39 | F32: =IFERROR(C32*E32,"") -> 0.39 | G32: =IFERROR(F32/$F$71,"") -> 0.00013262401 | H32: 701096
A33: 1 | B33: =IFERROR(VLOOKUP(H33,'[1]Consolidado MP Planta'!$A$2:$M$823,3,0),"") -> ETIQ.FECHA VENCIMIENTO AMARILLO (ROLLO) | C33: =+A33 -> 1 | D33: =IFERROR(VLOOKUP(H33,'[1]Consolidado MP Planta'!$A$2:$M$823,13,0),"") -> Und | E33: =IFERROR(VLOOKUP(H33,'[1]Consolidado MP Planta'!$A$2:$M$823,12,0),"") -> 0.2 | F33: =IFERROR(C33*E33,"") -> 0.2 | G33: =IFERROR(F33/$F$71,"") -> 6.8012313e-05 | H33: 0702006
B34: =IFERROR(VLOOKUP(H34,'[1]Consolidado MP Planta'!$A$2:$M$823,3,0),"") | C34: =+A34 -> 0 | D34: =IFERROR(VLOOKUP(H34,'[1]Consolidado MP Planta'!$A$2:$M$823,13,0),"") | E34: =IFERROR(VLOOKUP(H34,'[1]Consolidado MP Planta'!$A$2:$M$823,12,0),"") | F34: =IFERROR(C34*E34,"") | G34: =IFERROR(F34/$F$71,"")
B35: =IFERROR(VLOOKUP(H35,'[1]Consolidado MP Planta'!$A$2:$M$823,3,0),"") | C35: =+A35 -> 0 | D35: =IFERROR(VLOOKUP(H35,'[1]Consolidado MP Planta'!$A$2:$M$823,13,0),"") | E35: =IFERROR(VLOOKUP(H35,'[1]Consolidado MP Planta'!$A$2:$M$823,12,0),"") | F35: =IFERROR(C35*E35,"") | G35: =IFERROR(F35/$F$71,"")
B36: =IFERROR(VLOOKUP(H36,'[1]Consolidado MP Planta'!$A$2:$M$823,3,0),"") | C36: =+A36 -> 0 | D36: =IFERROR(VLOOKUP(H36,'[1]Consolidado MP Planta'!$A$2:$M$823,13,0),"") | E36: =IFERROR(VLOOKUP(H36,'[1]Consolidado MP Planta'!$A$2:$M$823,12,0),"") | F36: =IFERROR(C36*E36,"") | G36: =IFERROR(F36/$F$71,"")
B37: =IFERROR(VLOOKUP(H37,'[1]Consolidado MP Planta'!$A$2:$M$823,3,0),"") | C37: =+A37 -> 0 | D37: =IFERROR(VLOOKUP(H37,'[1]Consolidado MP Planta'!$A$2:$M$823,13,0),"") | E37: =IFERROR(VLOOKUP(H37,'[1]Consolidado MP Planta'!$A$2:$M$823,12,0),"") | F37: =IFERROR(C37*E37,"") | G37: =IFERROR(F37/$F$71,"")
A39: UNIDADES | B39: EMPAQUE SEMIELABORADOS | C39: UNIDADES | D39: UND MEDIDA | E39: COSTO UNITARIO | F39: TOTAL COSTO | G39: % PREC. DEFINIDO | H39: CODIGOS
A40: =+A17 -> 200 | B40: =IFERROR(VLOOKUP(H40,[1]SEMIELABORADOS!$A$2:$M$6000,2,0),"") -> BASE GALLETA P/CHEESE CAKE (KILO) | C40: =+A40 -> 200 | D40: =IFERROR(VLOOKUP(H40,[1]SEMIELABORADOS!$A$2:$M$6000,6,0),"") -> Gramo | E40: =IFERROR(VLOOKUP(H40,[1]SEMIELABORADOS!$A$2:$M$65536,10,0),"") -> 0.0011524699 | F40: =IFERROR(E40*C40,"") -> 0.23049398 | G40: =IFERROR(F40/$F$71,"") -> 7.8382144e-05 | H40: 907000002
A41: =+A18 -> 600 | B41: =IFERROR(VLOOKUP(H41,[1]SEMIELABORADOS!$A$2:$M$6000,2,0),"") -> RELLENO CHEESECAKE KILO | C41: =+A41 -> 600 | D41: =IFERROR(VLOOKUP(H41,[1]SEMIELABORADOS!$A$2:$M$6000,6,0),"") -> Gramo | E41: =IFERROR(VLOOKUP(H41,[1]SEMIELABORADOS!$A$2:$M$65536,10,0),"") -> 7.4358974e-06 | F41: =IFERROR(E41*C41,"") -> 0.0044615385 | G41: =IFERROR(F41/$F$71,"") -> 1.5171977e-06 | H41: 90200029
A42: =+A19 -> 90 | B42: GANACHE DE DULCE LECHE (4800g) | C42: =+A42 -> 90 | D42: Gramo | E42: =+'[3]COSTEO GANACHE'!$E$76 -> 0.0032348958 | F42: =IFERROR(E42*C42,"") -> 0.29114063 | G42: =IFERROR(F42/$F$71,"") -> 9.9005736e-05 | H42: 901000111
A43: =+A20 -> 0 | B43: =IFERROR(VLOOKUP(H43,[1]SEMIELABORADOS!$A$2:$M$6000,2,0),"") -> CREMA DULCE LECHE KILO | C43: =+A43 -> 0 | D43: =IFERROR(VLOOKUP(H43,[1]SEMIELABORADOS!$A$2:$M$6000,6,0),"") -> Gramo | E43: =IFERROR(VLOOKUP(H43,[1]SEMIELABORADOS!$A$2:$M$65536,10,0),"") -> 8.512e-05 | F43: =IFERROR(E43*C43,"") -> 0 | G43: =IFERROR(F43/$F$71,"") -> 0 | H43: 96344
A44: =+A21 -> 0 | B44: BRITTLE DE ALMENDRAS | C44: =+A44 -> 0 | D44: Gramo | E44: =+'costeo brittle'!E76 -> 0.037837907 | F44: =IFERROR(E44*C44,"") -> 0 | G44: =IFERROR(F44/$F$71,"") -> 0
A45: =+A22 -> 0 | B45: =IFERROR(VLOOKUP(H45,[1]SEMIELABORADOS!$A$2:$M$6000,2,0),"") | C45: =+A45 -> 0 | D45: =IFERROR(VLOOKUP(H45,[1]SEMIELABORADOS!$A$2:$M$6000,6,0),"") | E45: =IFERROR(VLOOKUP(H45,[1]SEMIELABORADOS!$A$2:$M$65536,10,0),"") | F45: =IFERROR(E45*C45,"") | G45: =IFERROR(F45/$F$71,"")
...

Sheet INS
B1: SERVICIOS DE PASTELERIA S.A. | G1: CÓDIGO
B2: INSTRUCTIVO | G2: REVISION
B3: Postre Cumbrel almendra | G3: FECHA APROBACION
B4: ELABORADO: | D4: Enmanuel Madrigal, Chef | F4: APROBADO: | G4: Yenny Castro Q, Calidad
A6: # Código | B6: Descrip. - Componentes | C6: ALÉRGENOS | D6: Cantidades | E6: Vida Útil | F6: Tipo Almacenamiento | G6: Tiempo Calentamiento
B7: Postre caramelo y almendras locales | D7: 1 ud | E7: Ver empaque | F7: Refrigeracion | G7: N.A.
B8: Empaque caramelo almendras 160g | D8: 1 bolsa -160g | E8: Ver empaque | F8: Refrigeracion | G8: N.A.
A13: 702182 | B13: ETIQUETA IMP. SPOON MEDIANA V-273 (UND) | D13: 1 | E13: ud | F13: N/A | G13: N/A
A16: 1. DIAGRAMA Y/O FOTOGRAFIA DE PRODUCTO
A18: PRESENTACIÓN SALON | E18: LLEVAR / DOMICILIO
A29: 2. DESCRIPCIÓN DE ACTIVIDADES
A30: 1, Colocar sobre el postre 1 bolsa del caramelo almendras, esparciendo sobre toda la superficie.
A31: 2, Se porciona en 6 porc.
A34: 3. ESPECIFICACIONES DEL PLATO
A35: Postre frio de queso relleno con caramelo, con caramelo crujiente de almendras

Sheet PRECIO 2
H1: TOTAL COSTO | I1: =+G51 -> 4719.1745
B5: ESTRUCTURA DE COSTOS
B6: LOCALES
G7: Fecha: | I7: =TODAY() -> 45754
B8: UNIDADES | C8: DESCRIPCION SEMIELABORADOS PLANTA | D8: UNIDADES | E8: UND MEDIDA | F8: COSTO UNITARIO | G8: TOTAL COSTO | H8: % PREC. DEFINIDO | I8: CODIGOS
B9: 1 | C9: POSTRE CARAMELO Y ALMENDRAS | D9: =+B9 -> 1 | E9: UND | F9: =+'COSTEO ENSAMBLE'!O67 -> 3912.1697 | G9: =IFERROR(D9*F9,"") -> 3912.1697 | H9: =IFERROR(G9/$G$53,"") -> 0.34137478
B10: 1 | C10: Bolsa Brittle 160 g | D10: =+B10 -> 1 | E10: UND | F10: =+'COSTO EMPAQUE BRITTLE'!O62 -> 691.90292 | G10: =IFERROR(D10*F10,"") -> 691.90292 | H10: =IFERROR(G10/$G$53,"") -> 0.060375245
C11: =VLOOKUP(I11,'[1]COMPRAS LOCALES'!$A$2:$F$380,2,0) -> #N/A | D11: =+B11 -> 0 | E11: =VLOOKUP(I11,'[1]COMPRAS LOCALES'!$A$2:$F$380,5,0) -> #N/A | F11: =VLOOKUP(I11,'[1]COMPRAS LOCALES'!$A$2:$F$380,6,0) -> #N/A | G11: =IFERROR(D11*F11,"") | H11: =IFERROR(G11/$G$53,"")
C12: =VLOOKUP(I12,'[1]COMPRAS LOCALES'!$A$2:$F$380,2,0) -> #N/A | D12: =+B12 -> 0 | E12: =VLOOKUP(I12,'[1]COMPRAS LOCALES'!$A$2:$F$380,5,0) -> #N/A | F12: =VLOOKUP(I12,'[1]COMPRAS LOCALES'!$A$2:$F$380,6,0) -> #N/A | G12: =IFERROR(D12*F12,"") | H12: =IFERROR(G12/$G$53,"")
C13: =VLOOKUP(I13,'[1]COMPRAS LOCALES'!$A$2:$F$380,2,0) -> #N/A | D13: =+B13 -> 0 | E13: =VLOOKUP(I13,'[1]COMPRAS LOCALES'!$A$2:$F$380,5,0) -> #N/A | F13: =VLOOKUP(I13,'[1]COMPRAS LOCALES'!$A$2:$F$380,6,0) -> #N/A | G13: =IFERROR(D13*F13,"") | H13: =IFERROR(G13/$G$53,"")
C14: =VLOOKUP(I14,'[1]COMPRAS LOCALES'!$A$2:$F$380,2,0) -> #N/A | D14: =+B14 -> 0 | E14: =VLOOKUP(I14,'[1]COMPRAS LOCALES'!$A$2:$F$380,5,0) -> #N/A | F14: =VLOOKUP(I14,'[1]COMPRAS LOCALES'!$A$2:$F$380,6,0) -> #N/A | G14: =IFERROR(D14*F14,"") | H14: =IFERROR(G14/$G$53,"")
B16: UNIDADES | C16: DESCRIPCION MAT.PRIMA LOCAL | D16: UNIDADES | E16: UND MEDIDA | F16: COSTO UNITARIO | G16: TOTAL COSTO | H16: % PREC. DEFINIDO | I16: CODIGOS
C17: =VLOOKUP(I17,'[1]COMPRAS LOCALES'!$A$2:$F$380,2,0) -> #N/A | D17: =+B17 -> 0 | E17: =VLOOKUP(I17,'[1]COMPRAS LOCALES'!$A$2:$F$380,5,0) -> #N/A | F17: =VLOOKUP(I17,'[1]COMPRAS LOCALES'!$A$2:$F$380,6,0) -> #N/A | G17: =IFERROR(D17*F17,"") | H17: =IFERROR(G17/$G$53,"")
C18: =VLOOKUP(I18,'[1]COMPRAS LOCALES'!$A$2:$F$380,2,0) -> #N/A | D18: =+B18 -> 0 | E18: =VLOOKUP(I18,'[1]COMPRAS LOCALES'!$A$2:$F$380,5,0) -> #N/A | F18: =VLOOKUP(I18,'[1]COMPRAS LOCALES'!$A$2:$F$380,6,0) -> #N/A | G18: =IFERROR(D18*F18,"") | H18: =IFERROR(G18/$G$53,"")
C19: =VLOOKUP(I19,'[1]COMPRAS LOCALES'!$A$2:$F$380,2,0) -> #N/A | D19: =+B19 -> 0 | E19: =VLOOKUP(I19,'[1]COMPRAS LOCALES'!$A$2:$F$380,5,0) -> #N/A | F19: =VLOOKUP(I19,'[1]COMPRAS LOCALES'!$A$2:$F$380,6,0) -> #N/A | G19: =IFERROR(D19*F19,"") | H19: =IFERROR(G19/$G$53,"")
C20: =VLOOKUP(I20,'[1]COMPRAS LOCALES'!$A$2:$F$380,2,0) -> #N/A | D20: =+B20 -> 0 | E20: =VLOOKUP(I20,'[1]COMPRAS LOCALES'!$A$2:$F$380,5,0) -> #N/A | F20: =VLOOKUP(I20,'[1]COMPRAS LOCALES'!$A$2:$F$380,6,0) -> #N/A | G20: =IFERROR(D20*F20,"") | H20: =IFERROR(G20/$G$53,"")
B22: UNIDAD | C22: EMPAQUE | D22: UNIDAD | E22: UND MEDIDA | F22: COSTO UNITARIO | G22: TOTAL COSTO | H22: % PREC. DEFINIDO | I22: CÓDIGOS
C23: DOMICILIO Y LLEVAR
B24: 0.55 | C24: =VLOOKUP(I24,'[4]COMPRAS LOCALES'!$A$1:$F$380,2,0) -> #N/A | D24: =+B24 -> 0.55 | E24: =VLOOKUP(I24,'[1]COMPRAS LOCALES'!$A$2:$F$380,5,0) -> #N/A | F24: =VLOOKUP(I24,'[1]COMPRAS LOCALES'!$A$2:$F$380,6,0) -> #N/A | G24: =IFERROR(F24*D24,"") | H24: =IFERROR(G24/$G$53,"")
B25: 0.55 | C25: =VLOOKUP(I25,'[4]COMPRAS LOCALES'!$A$1:$F$380,2,0) -> #N/A | D25: =+B25 -> 0.55 | E25: =VLOOKUP(I25,'[1]COMPRAS LOCALES'!$A$2:$F$380,5,0) -> #N/A | F25: =VLOOKUP(I25,'[1]COMPRAS LOCALES'!$A$2:$F$380,6,0) -> #N/A | G25: =IFERROR(F25*D25,"") | H25: =IFERROR(G25/$G$53,"")
B26: 0.55 | C26: =VLOOKUP(I26,'[4]COMPRAS LOCALES'!$A$1:$F$380,2,0) -> #N/A | D26: =+B26 -> 0.55 | E26: =VLOOKUP(I26,'[1]COMPRAS LOCALES'!$A$2:$F$380,5,0) -> #N/A | F26: =VLOOKUP(I26,'[1]COMPRAS LOCALES'!$A$2:$F$380,6,0) -> #N/A | G26: =IFERROR(F26*D26,"") | H26: =IFERROR(G26/$G$53,"")
B27: 0.55 | C27: =VLOOKUP(I27,'[4]COMPRAS LOCALES'!$A$1:$F$380,2,0) -> #N/A | D27: =+B27 -> 0.55 | E27: =VLOOKUP(I27,'[1]COMPRAS LOCALES'!$A$2:$F$380,5,0) -> #N/A | F27: =VLOOKUP(I27,'[1]COMPRAS LOCALES'!$A$2:$F$380,6,0) -> #N/A | G27: =IFERROR(F27*D27,"") | H27: =IFERROR(G27/$G$53,"")
B28: 0.55 | C28: =VLOOKUP(I28,'[4]COMPRAS LOCALES'!$A$1:$F$380,2,0) -> #N/A | D28: =+B28 -> 0.55 | E28: =VLOOKUP(I28,'[1]COMPRAS LOCALES'!$A$2:$F$380,5,0) -> #N/A | F28: =VLOOKUP(I28,'[1]COMPRAS LOCALES'!$A$2:$F$380,6,0) -> #N/A | G28: =IFERROR(F28*D28,"") | H28: =IFERROR(G28/$G$53,"")
B29: 0.55 | C29: =VLOOKUP(I29,'[4]COMPRAS LOCALES'!$A$1:$F$380,2,0) -> #N/A | D29: =+B29 -> 0.55 | E29: =VLOOKUP(I29,'[1]COMPRAS LOCALES'!$A$2:$F$380,5,0) -> #N/A | F29: =VLOOKUP(I29,'[1]COMPRAS LOCALES'!$A$2:$F$380,6,0) -> #N/A | G29: =IFERROR(F29*D29,"") | H29: =IFERROR(G29/$G$53,"")
B30: 0.55 | C30: =VLOOKUP(I30,'[4]COMPRAS LOCALES'!$A$1:$F$380,2,0) -> #N/A | D30: =+B30 -> 0.55 | E30: =VLOOKUP(I30,'[1]COMPRAS LOCALES'!$A$2:$F$380,5,0) -> #N/A | F30: =VLOOKUP(I30,'[1]COMPRAS LOCALES'!$A$2:$F$380,6,0) -> #N/A | G30: =IFERROR(F30*D30,"") | H30: =IFERROR(G30/$G$53,"")
B31: 0.55 | C31: =VLOOKUP(I31,'[4]COMPRAS LOCALES'!$A$1:$F$380,2,0) -> #N/A | D31: =+B31 -> 0.55 | E31: =VLOOKUP(I31,'[1]COMPRAS LOCALES'!$A$2:$F$380,5,0) -> #N/A | F31: =VLOOKUP(I31,'[1]COMPRAS LOCALES'!$A$2:$F$380,6,0) -> #N/A | G31: =IFERROR(F31*D31,"") | H31: =IFERROR(G31/$G$53,"")
C32: FOOD COURT
B33: 0.05 | C33: =IFERROR(VLOOKUP(I33,'[2]EMP LOCALES'!$A$2:$G$119,2,0),"") | D33: =+B33 -> 0.05 | E33: =IFERROR(VLOOKUP(I33,'[2]EMP LOCALES'!$A$2:$G$119,6,0),"") | F33: =IFERROR(VLOOKUP(I33,'[2]EMP LOCALES'!$A$2:$G$119,7,0),"") | G33: =IFERROR(F33*D33,"") | H33: =IFERROR(G33/$G$53,"")
B34: 0.05 | C34: =IFERROR(VLOOKUP(I34,'[2]EMP LOCALES'!$A$2:$G$119,2,0),"") | D34: =+B34 -> 0.05 | E34: =IFERROR(VLOOKUP(I34,'[2]EMP LOCALES'!$A$2:$G$119,6,0),"") | F34: =IFERROR(VLOOKUP(I34,'[2]EMP LOCALES'!$A$2:$G$119,7,0),"") | G34: =IFERROR(F34*D34,"") | H34: =IFERROR(G34/$G$53,"")
B35: 0.05 | C35: =IFERROR(VLOOKUP(I35,'[2]EMP LOCALES'!$A$2:$G$119,2,0),"") | D35: =+B35 -> 0.05 | E35: =IFERROR(VLOOKUP(I35,'[2]EMP LOCALES'!$A$2:$G$119,6,0),"") | F35: =IFERROR(VLOOKUP(I35,'[2]EMP LOCALES'!$A$2:$G$119,7,0),"") | G35: =IFERROR(F35*D35,"") | H35: =IFERROR(G35/$G$53,"")
B36: 0.05 | C36: =IFERROR(VLOOKUP(I36,'[2]EMP LOCALES'!$A$2:$G$119,2,0),"") | D36: =+B36 -> 0.05 | E36: =IFERROR(VLOOKUP(I36,'[2]EMP LOCALES'!$A$2:$G$119,6,0),"") | F36: =IFERROR(VLOOKUP(I36,'[2]EMP LOCALES'!$A$2:$G$119,7,0),"") | G36: =IFERROR(F36*D36,"") | H36: =IFERROR(G36/$G$53,"")
B37: 0.05 | C37: =IFERROR(VLOOKUP(I37,'[2]EMP LOCALES'!$A$2:$G$119,2,0),"") | D37: =+B37 -> 0.05 | E37: =IFERROR(VLOOKUP(I37,'[2]EMP LOCALES'!$A$2:$G$119,6,0),"") | F37: =IFERROR(VLOOKUP(I37,'[2]EMP LOCALES'!$A$2:$G$119,7,0),"") | G37: =IFERROR(F37*D37,"") | H37: =IFERROR(G37/$G$53,"")
B38: 0.05 | C38: =IFERROR(VLOOKUP(I38,'[2]EMP LOCALES'!$A$2:$G$119,2,0),"") | D38: =+B38 -> 0.05 | E38: =IFERROR(VLOOKUP(I38,'[2]EMP LOCALES'!$A$2:$G$119,6,0),"") | F38: =IFERROR(VLOOKUP(I38,'[2]EMP LOCALES'!$A$2:$G$119,7,0),"") | G38: =IFERROR(F38*D38,"") | H38: =IFERROR(G38/$G$53,"")
B40: TOTAL MATERIA PRIMA PLANTA | G40: =SUM(G9:G14) -> 4604.0726 | H40: =+G40/$G$53 -> 0.40175002
B41: TOTAL MATERIA PRIMA LOCAL | F41: =SUM(F17:F20) -> #N/A | G41: =SUM(G17:G20) -> 0 | H41: =+G41/$G$53 -> 0
B42: TOTAL MATERIA PRIMA | G42: =SUM(G40:G41) -> 4604.0726 | H42: =+G42/$G$53 -> 0.40175002
B43: TOTAL EMPAQUE | G43: =SUM(G24:G38) -> 0 | H43: =+G43/$G$53 -> 0
B44: TOTAL MATERIA PRIMA + EMPAQUE | G44: =SUM(G42:G43) -> 4604.0726 | H44: =+G44/$G$53 -> 0.40175002
B48: TOTAL MATERIA PRIMA | G48: =+G42 -> 4604.0726 | H48: =+G48/$G$53 -> 0.40175002
B49: EMPAQUE | F49: Local | G49: =+G43 -> 0 | H49: =+G49/$G$53 -> 0
...

Sheet ENSAMBLE INDUSTRIA 
B1: SERVICIOS DE PASTELERIA S.A. | G1: CÓDIGO:
B2: ESPECIFICACION DE RECETA | G2: REVISIÓN:
B3: 30800096 Postre caramelo y almendras (dia de la madre 2021) INDUSTRIA | G3: FECHA DE APROBACIÓN:
B4: Elaborado | C4: Javier Tong, Chef
B5: Aprobado | C5: Esteban Cartin, Gte Manufactura
A7: AREA QUE PRODUCE: | C7: Postre | F7: AREA QUE EMPACA: | H7: Postre
A8: # Código | B8: Descripción del ingrediente | C8: Marca | D8: Unidad Internacional | F8: Medida alternativa | H8: Costo - Referencia
D9: Cantidad | E9: Unidad medida | F9: Cantidad | G9: Unidad medida | H9: Colones
A10: 907000002 | B10: BASE GALLETA P/CHEESE CAKE (KILO) | C10: FAS | D10: 200 | E10: g
A11: 90200029 | B11: RELLENO CHEESECAKE KILO | C11: FAS | D11: 300 | E11: g
A12: 410154 | B12: RELLENO CARAMELO (KILO) | C12: CONEXU | D12: 120 | E12: g
A13: 90200029 | B13: RELLENO CHEESECAKE KILO | C13: FAS | D13: 300 | E13: g
B14: DECORACION
A15: 901000111 | B15: GANACHE DE DULCE LECHE (4800g) | C15: FAS | D15: 90 | E15: g | F15: Espejo
A16: 902000116 | B16: BRITTLE DE ALMENDRAS | C16: FAS | D16: 160 | E16: g | F16: 3/4 tz
A17: 1112431 | B17: MANJAR LECHE CONDENSADA (PAQ: 4.5 K) | C17: NESTLE | D17: 20 | E17: g | F17: Para pegar
B18: EMPAQUE
A19: 702182 | B19: ETIQUETA IMP. SPOON MEDIANA V-273 (UND) | C19: ETIPLAST | D19: 1 | E19: ud
A20: 703020 | B20: CINTA ADHESIVA TRANSPARENT 2*100 M (UND) | C20: ETIPLAST | D20: 60 | E20: cm
A21: 1950693 | B21: ORLA CARTON 9" DORADA (UND ) | C21: RAPIBOX | D21: 1 | E21: ud
A22: 51400021 | B22: QUEQUERA RED C/BASE ALTA 9" (CAJA:100 U) | C22: Exp PMT | D22: 1 | E22: ud
A23: 702123 | B23: ETIQUETA BLANCA 2 5/8X1 15/16 (UND) | C23: Cemusa | D23: 1 | E23: ud
A24: 701096 | B24: ETIQUETA BLANCA R-153 (UND) | C24: Cemusa | D24: 1 | E24: ud
A25: 702007 | B25: ETIQ.FECHA VENCIMIENTO BLANCO (ROLLO) | C25: CEMUSA | D25: 1 | E25: ud
C27: Cantidad | D27: Unidad
A28: PESO TOTAL OBTENIDO | C28: 1000 | D28: g
A29: TIEMPO TOTAL DE PREPARACION | C29: 5 | D29: min
A30: CANTIDAD DE PORCIONES OBTENIDAS | C30: 1 | D30: ud
A31: PESO DE CADA PORCIÓN | C31: =+C28 -> 1000 | D31: g
A32: MERMA | C32: =SUM(D10:D18)-C28 -> 190 | D32: g
A33: PROCEDIMIENTO DE PREPARACION DE LA RECETA
A34: 1.- Colocar dentro del molde desarmable redondo 21 cm ,previamente ensagrasado la base de galleta presionar y hornear a 175°C por 7 min en el Argental, a 175°C por 8 min en el Dicte 1 y Dicte 2, a 170°C en el Dicte 3 y a 175°C por 7 min en el Marshal
A35: 2.- Una vez fria la galleta, dosificar en el molde 275g de mezcla de cheesecake, 120g de caramelo y 275g de mezcla de cheesecake. Dejar enfriar al menos 6 horas en Refrigeracion
A36: 3.- Desmoldar con ayuda de una espatula.
A37: 4.- Pegar a la orla con manjar, decorar con ganache en el hacinedo espejo y dejar chorrear. sobre este ganache colocar el brittle de almednras.
A38: 5.- Decorar con un corazon de chocolate, tapar y etiquetar

Sheet COSTO ENSAM IND
E1: Precio Local | F1: Costo MP | G1: Costo EM | H1: Costo MO
E2: =IFERROR(O67,"") -> 4405.5999 | F2: =IFERROR(H58,"") -> 2669.8227 | G2: =IFERROR(H59,"") -> 399.84816 | H2: =IFERROR(H61,"") -> 477.23723
A5: ESTRUCTURA DE COSTOS
F6: Fecha: | H6: =TODAY() -> 45754
A7: UNIDADES | B7: DESCRIPCION MAT.PRIMA | C7: UNIDADES | D7: UND MEDIDA | E7: COSTO UNITARIO | F7: TOTAL COSTO | G7: % PREC. DEFINIDO | H7: CODIGOS
A8: 120 | B8: =IFERROR(VLOOKUP(H8,'[1]Consolidado MP Planta'!$A$2:$M$823,3,0),"") -> RELLENO CARAMELO KILO | C8: =+A8 -> 120 | D8: =IFERROR(VLOOKUP(H8,'[1]Consolidado MP Planta'!$A$2:$M$823,13,0),"") -> Gramos | E8: =IFERROR(VLOOKUP(H8,'[1]Consolidado MP Planta'!$A$2:$M$823,12,0),"") -> 3.335 | F8: =IFERROR(C8*E8,"") -> 400.2 | G8: =IFERROR(F8/$F$71,"") -> 0.11777283 | H8: 0410154
B9: =IFERROR(VLOOKUP(H9,'[1]Consolidado MP Planta'!$A$2:$M$823,3,0),"") -> CHOCOLATE CORAZON ROJO PASION (CAJA:200) | C9: =+A9 -> 0 | D9: =IFERROR(VLOOKUP(H9,'[1]Consolidado MP Planta'!$A$2:$M$823,13,0),"") -> Und | E9: =IFERROR(VLOOKUP(H9,'[1]Consolidado MP Planta'!$A$2:$M$823,12,0),"") -> 38.25 | F9: =IFERROR(C9*E9,"") -> 0 | G9: =IFERROR(F9/$F$71,"") -> 0 | H9: 10700029
A10: 20 | B10: =IFERROR(VLOOKUP(H10,'[1]Consolidado MP Planta'!$A$2:$M$823,3,0),"") -> MANJAR LECHE CONDENSADA (PAQ: 4.5 K) | C10: =+A10 -> 20 | D10: =IFERROR(VLOOKUP(H10,'[1]Consolidado MP Planta'!$A$2:$M$823,13,0),"") -> Gramos | E10: =IFERROR(VLOOKUP(H10,'[1]Consolidado MP Planta'!$A$2:$M$823,12,0),"") -> 2.142 | F10: =IFERROR(C10*E10,"") -> 42.84 | G10: =IFERROR(F10/$F$71,"") -> 0.012607166 | H10: 1112431
B11: =IFERROR(VLOOKUP(H11,'[1]Consolidado MP Planta'!$A$2:$M$823,3,0),"") | C11: =+A11 -> 0 | D11: =IFERROR(VLOOKUP(H11,'[1]Consolidado MP Planta'!$A$2:$M$823,13,0),"") | E11: =IFERROR(VLOOKUP(H11,'[1]Consolidado MP Planta'!$A$2:$M$823,12,0),"") | F11: =IFERROR(C11*E11,"") | G11: =IFERROR(F11/$F$71,"")
B12: =IFERROR(VLOOKUP(H12,'[1]Consolidado MP Planta'!$A$2:$M$823,3,0),"") | C12: =+A12 -> 0 | D12: =IFERROR(VLOOKUP(H12,'[1]Consolidado MP Planta'!$A$2:$M$823,13,0),"") | E12: =IFERROR(VLOOKUP(H12,'[1]Consolidado MP Planta'!$A$2:$M$823,12,0),"") | F12: =IFERROR(C12*E12,"") | G12: =IFERROR(F12/$F$71,"")
B13: =IFERROR(VLOOKUP(H13,'[1]Consolidado MP Planta'!$A$2:$M$823,3,0),"") | C13: =+A13 -> 0 | D13: =IFERROR(VLOOKUP(H13,'[1]Consolidado MP Planta'!$A$2:$M$823,13,0),"") | E13: =IFERROR(VLOOKUP(H13,'[1]Consolidado MP Planta'!$A$2:$M$823,12,0),"") | F13: =IFERROR(C13*E13,"") | G13: =IFERROR(F13/$F$71,"")
B14: =IFERROR(VLOOKUP(H14,'[1]Consolidado MP Planta'!$A$2:$M$823,3,0),"") | C14: =+A14 -> 0 | D14: =IFERROR(VLOOKUP(H14,'[1]Consolidado MP Planta'!$A$2:$M$823,13,0),"") | E14: =IFERROR(VLOOKUP(H14,'[1]Consolidado MP Planta'!$A$2:$M$823,12,0),"") | F14: =IFERROR(C14*E14,"") | G14: =IFERROR(F14/$F$71,"")
B15: =IFERROR(VLOOKUP(H15,'[2]ARTICULOS MP PLANTA'!$A$2:$G$589,2,0),"")
A16: UNIDADES | B16: MATERIA PRIMA SEMIELABORADOS | C16: UNIDADES | D16: UND MEDIDA | E16: COSTO UNITARIO | F16: TOTAL COSTO | G16: % PREC. DEFINIDO | H16: CODIGOS
A17: 200 | B17: =IFERROR(VLOOKUP(H17,[1]SEMIELABORADOS!$A$2:$M$6000,2,0),"") -> BASE GALLETA P/CHEESE CAKE (KILO) | C17: =+A17 -> 200 | D17: =IFERROR(VLOOKUP(H17,[1]SEMIELABORADOS!$A$2:$M$6000,6,0),"") -> Gramo | E17: =IFERROR(VLOOKUP(H17,[1]SEMIELABORADOS!$A$2:$H$65536,8,0),"") -> 2.0071033 | F17: =IFERROR(E17*C17,"") -> 401.42065 | G17: =IFERROR(F17/$F$71,"") -> 0.11813205 | H17: 907000002
A18: 600 | B18: =IFERROR(VLOOKUP(H18,[1]SEMIELABORADOS!$A$2:$M$6000,2,0),"") -> RELLENO CHEESECAKE KILO | C18: =+A18 -> 600 | D18: =IFERROR(VLOOKUP(H18,[1]SEMIELABORADOS!$A$2:$M$6000,6,0),"") -> Gramo | E18: =IFERROR(VLOOKUP(H18,[1]SEMIELABORADOS!$A$2:$H$65536,8,0),"") -> 1.8699122 | F18: =IFERROR(E18*C18,"") -> 1121.9473 | G18: =IFERROR(F18/$F$71,"") -> 0.3301722 | H18: 90200029
A19: 90 | B19: GANACHE DE DULCE LECHE (4800g) | C19: =+A19 -> 90 | D19: Gramo | E19: =+'[3]COSTEO GANACHE'!$E$69 -> 2.8988426 | F19: =IFERROR(E19*C19,"") -> 260.89583 | G19: =IFERROR(F19/$F$71,"") -> 0.076777712 | H19: 901000111
A20: 0 | B20: =IFERROR(VLOOKUP(H20,[1]SEMIELABORADOS!$A$2:$M$6000,2,0),"") -> COCCION PICADILLO PLATANO CON CHORIZO KILO | C20: =+A20 -> 0 | D20: Gramo | E20: =+'[3]COSTEO GANACHE'!$E$69 -> 2.8988426 | F20: =IFERROR(E20*C20,"") -> 0 | G20: =IFERROR(F20/$F$71,"") -> 0 | H20: 901000112
A21: 160 | B21: BRITTLE DE ALMENDRAS | C21: =+A21 -> 160 | D21: Gramo | E21: =+'costeo brittle'!E69 -> 2.7657428 | F21: =IFERROR(E21*C21,"") -> 442.51886 | G21: =IFERROR(F21/$F$71,"") -> 0.13022663
B22: =IFERROR(VLOOKUP(H22,[1]SEMIELABORADOS!$A$2:$M$6000,2,0),"") | C22: =+A22 -> 0 | D22: =IFERROR(VLOOKUP(H22,[1]SEMIELABORADOS!$A$2:$M$6000,6,0),"") | E22: =IFERROR(VLOOKUP(H22,[1]SEMIELABORADOS!$A$2:$H$65536,8,0),"") | F22: =IFERROR(E22*C22,"") | G22: =IFERROR(F22/$F$71,"")
B23: =IFERROR(VLOOKUP(H23,[1]SEMIELABORADOS!$A$2:$M$6000,2,0),"") | C23: =+A23 -> 0 | D23: =IFERROR(VLOOKUP(H23,[1]SEMIELABORADOS!$A$2:$M$6000,6,0),"") | E23: =IFERROR(VLOOKUP(H23,[1]SEMIELABORADOS!$A$2:$H$65536,8,0),"") | F23: =IFERROR(E23*C23,"") | G23: =IFERROR(F23/$F$71,"")
B24: =IFERROR(VLOOKUP(H24,[1]SEMIELABORADOS!$A$2:$M$6000,2,0),"") | C24: =+A24 -> 0 | D24: =IFERROR(VLOOKUP(H24,[1]SEMIELABORADOS!$A$2:$M$6000,6,0),"") | E24: =IFERROR(VLOOKUP(H24,[1]SEMIELABORADOS!$A$2:$H$65536,8,0),"") | F24: =IFERROR(E24*C24,"") | G24: =IFERROR(F24/$F$71,"")
A26: UNIDADES | B26: EMPAQUE | C26: UNIDADES | D26: UND MEDIDA | E26: COSTO UNITARIO | F26: TOTAL COSTO | G26: % PREC. DEFINIDO | H26: CODIGOS
A27: 1 | B27: =IFERROR(VLOOKUP(H27,'[1]Consolidado MP Planta'!$A$2:$M$823,3,0),"") -> ETIQUETA IMP. SPOON MEDIANA V-273 (UND) | C27: =+A27 -> 1 | D27: =IFERROR(VLOOKUP(H27,'[1]Consolidado MP Planta'!$A$2:$M$823,13,0),"") -> Und | E27: =IFERROR(VLOOKUP(H27,'[1]Consolidado MP Planta'!$A$2:$M$823,12,0),"") -> 32.49 | F27: =IFERROR(C27*E27,"") -> 32.49 | G27: =IFERROR(F27/$F$71,"") -> 0.0095613174 | H27: 702182
A28: 60 | B28: =IFERROR(VLOOKUP(H28,'[1]Consolidado MP Planta'!$A$2:$M$823,3,0),"") -> CINTA ADHESIVA TRANSPARENT 2*100 M (UND) | C28: =+A28 -> 60 | D28: =IFERROR(VLOOKUP(H28,'[1]Consolidado MP Planta'!$A$2:$M$823,13,0),"") -> Cm | E28: =IFERROR(VLOOKUP(H28,'[1]Consolidado MP Planta'!$A$2:$M$823,12,0),"") -> 0.145 | F28: =IFERROR(C28*E28,"") -> 8.7 | G28: =IFERROR(F28/$F$71,"") -> 0.0025602789 | H28: 703020
A29: 1 | B29: =IFERROR(VLOOKUP(H29,'[1]Consolidado MP Planta'!$A$2:$M$823,3,0),"") -> ORLA #9 DORADA (UND) | C29: =+A29 -> 1 | D29: =IFERROR(VLOOKUP(H29,'[1]Consolidado MP Planta'!$A$2:$M$823,13,0),"") -> Und | E29: =IFERROR(VLOOKUP(H29,'[1]Consolidado MP Planta'!$A$2:$M$823,12,0),"") -> 105 | F29: =IFERROR(C29*E29,"") -> 105 | G29: =IFERROR(F29/$F$71,"") -> 0.030899918 | H29: 1950693
A30: 1 | B30: =IFERROR(VLOOKUP(H30,'[1]Consolidado MP Planta'!$A$2:$M$823,3,0),"") -> QUEQUERA RED C/BASE ALTA 9" (CAJA:100 U) | C30: =+A30 -> 1 | D30: =IFERROR(VLOOKUP(H30,'[1]Consolidado MP Planta'!$A$2:$M$823,13,0),"") -> Und | E30: =IFERROR(VLOOKUP(H30,'[1]Consolidado MP Planta'!$A$2:$M$823,12,0),"") -> 244.36 | F30: =IFERROR(C30*E30,"") -> 244.36 | G30: =IFERROR(F30/$F$71,"") -> 0.071911466 | H30: 51400021
A31: 1 | B31: =IFERROR(VLOOKUP(H31,'[1]Consolidado MP Planta'!$A$2:$M$823,3,0),"") -> ETIQUETA BLANCA 2 5/8X1 15/16 (UND) | C31: =+A31 -> 1 | D31: =IFERROR(VLOOKUP(H31,'[1]Consolidado MP Planta'!$A$2:$M$823,13,0),"") -> Und | E31: =IFERROR(VLOOKUP(H31,'[1]Consolidado MP Planta'!$A$2:$M$823,12,0),"") -> 2.128 | F31: =IFERROR(C31*E31,"") -> 2.128 | G31: =IFERROR(F31/$F$71,"") -> 0.00062623833 | H31: 0702123
A32: 1 | B32: =IFERROR(VLOOKUP(H32,'[1]Consolidado MP Planta'!$A$2:$M$823,3,0),"") -> ETIQUETA BLANCA R-153 (UND) | C32: =+A32 -> 1 | D32: =IFERROR(VLOOKUP(H32,'[1]Consolidado MP Planta'!$A$2:$M$823,13,0),"") -> Und | E32: =IFERROR(VLOOKUP(H32,'[1]Consolidado MP Planta'!$A$2:$M$823,12,0),"") -> 0.39 | F32: =IFERROR(C32*E32,"") -> 0.39 | G32: =IFERROR(F32/$F$71,"") -> 0.00011477112 | H32: 701096
A33: 1 | B33: =IFERROR(VLOOKUP(H33,'[1]Consolidado MP Planta'!$A$2:$M$823,3,0),"") -> ETIQ.FECHA VENCIMIENTO AMARILLO (ROLLO) | C33: =+A33 -> 1 | D33: =IFERROR(VLOOKUP(H33,'[1]Consolidado MP Planta'!$A$2:$M$823,13,0),"") -> Und | E33: =IFERROR(VLOOKUP(H33,'[1]Consolidado MP Planta'!$A$2:$M$823,12,0),"") -> 0.2 | F33: =IFERROR(C33*E33,"") -> 0.2 | G33: =IFERROR(F33/$F$71,"") -> 5.8856986e-05 | H33: 0702006
B34: =IFERROR(VLOOKUP(H34,'[1]Consolidado MP Planta'!$A$2:$M$823,3,0),"") | C34: =+A34 -> 0 | D34: =IFERROR(VLOOKUP(H34,'[1]Consolidado MP Planta'!$A$2:$M$823,13,0),"") | E34: =IFERROR(VLOOKUP(H34,'[1]Consolidado MP Planta'!$A$2:$M$823,12,0),"") | F34: =IFERROR(C34*E34,"") | G34: =IFERROR(F34/$F$71,"")
B35: =IFERROR(VLOOKUP(H35,'[1]Consolidado MP Planta'!$A$2:$M$823,3,0),"") | C35: =+A35 -> 0 | D35: =IFERROR(VLOOKUP(H35,'[1]Consolidado MP Planta'!$A$2:$M$823,13,0),"") | E35: =IFERROR(VLOOKUP(H35,'[1]Consolidado MP Planta'!$A$2:$M$823,12,0),"") | F35: =IFERROR(C35*E35,"") | G35: =IFERROR(F35/$F$71,"")
