Workbook

Sheet Costo Premezcla 
E1: Precio Local | F1: Costo MP | G1: Costo EM | H1: Costo MO
E2: =IFERROR(O61,"") -> 7174.0412 | F2: =IFERROR(H52,"") -> 5799.3063 | G2: =IFERROR(H53,"") -> 153.728 | H2: =IFERROR(H55,"") -> 268.52139
A5: ESTRUCTURA DE COSTOS
F6: Fecha: | H6: =TODAY() -> 45663
A7: UNIDADES | B7: DESCRIPCION MAT.PRIMA | C7: UNIDADES | D7: UND MEDIDA | E7: COSTO UNITARIO | F7: TOTAL COSTO | G7: % PREC. DEFINIDO | H7: CODIGOS
A8: 884 | B8: HARINA FHACASA VERDE (SACO: 25 K) | C8: =+A8 -> 884 | D8: Gramos | E8: 0.61 | F8: =IFERROR(C8*E8,"") -> 539.24 | G8: =IFERROR(F8/$F$65,"") -> 0.087184837 | H8: 11200071
A9: 56 | B9: =IFERROR(VLOOKUP(H9,'[1]Consolidado MP Planta'!$A$2:$M$823,3,0),"") -> COCOA DUTCH PROCESS (SACO:25 KG) | C9: =+A9 -> 56 | D9: =IFERROR(VLOOKUP(H9,'[1]Consolidado MP Planta'!$A$2:$M$823,13,0),"") -> Gramos | E9: 3.15 | F9: =IFERROR(C9*E9,"") -> 176.4 | G9: =IFERROR(F9/$F$65,"") -> 0.02852052 | H9: 0512255
A10: 10 | B10: =IFERROR(VLOOKUP(H10,'[1]Consolidado MP Planta'!$A$2:$M$823,3,0),"") -> POLVO HORNEAR FLEISHMAN (PAQ:2.5 K) | C10: =+A10 -> 10 | D10: =IFERROR(VLOOKUP(H10,'[1]Consolidado MP Planta'!$A$2:$M$823,13,0),"") -> Gramos | E10: 1.03 | F10: =IFERROR(C10*E10,"") -> 10.3 | G10: =IFERROR(F10/$F$65,"") -> 0.0016653138 | H10: 10100046
A11: 10 | B11: =IFERROR(VLOOKUP(H11,'[1]Consolidado MP Planta'!$A$2:$M$823,3,0),"") -> PRESERVANTE 1017S (PAQ=5 KILO) | C11: =+A11 -> 10 | D11: =IFERROR(VLOOKUP(H11,'[1]Consolidado MP Planta'!$A$2:$M$823,13,0),"") -> Gramos | E11: =IFERROR(VLOOKUP(H11,'[1]Consolidado MP Planta'!$A$2:$M$823,12,0),"") -> 11.66863 | F11: =IFERROR(C11*E11,"") -> 116.6863 | G11: =IFERROR(F11/$F$65,"") -> 0.018865952 | H11: 1212412
A12: 450 | B12: =IFERROR(VLOOKUP(H12,'[1]Consolidado MP Planta'!$A$2:$M$823,3,0),"") -> PECANA ENTERA (CAJA:13.6 K) | C12: =+A12 -> 450 | D12: =IFERROR(VLOOKUP(H12,'[1]Consolidado MP Planta'!$A$2:$M$823,13,0),"") -> Gramos | E12: 9.28 | F12: =IFERROR(C12*E12,"") -> 4176 | G12: =IFERROR(F12/$F$65,"") -> 0.67517966 | H12: 0510262
B13: =IFERROR(VLOOKUP(H13,'[1]Consolidado MP Planta'!$A$2:$M$823,3,0),"") | C13: =+A13 -> 0 | D13: =IFERROR(VLOOKUP(H13,'[1]Consolidado MP Planta'!$A$2:$M$823,13,0),"") | E13: =IFERROR(VLOOKUP(H13,'[1]Consolidado MP Planta'!$A$2:$M$823,12,0),"") | F13: =IFERROR(C13*E13,"") | G13: =IFERROR(F13/$F$65,"")
B14: =IFERROR(VLOOKUP(H14,'[2]ARTICULOS MP PLANTA'!$A$2:$G$589,2,0),"")
A15: UNIDADES | B15: MATERIA PRIMA SEMIELABORADOS | C15: UNIDADES | D15: UND MEDIDA | E15: COSTO UNITARIO | F15: TOTAL COSTO | G15: % PREC. DEFINIDO | H15: CODIGOS
A16: 2000 | B16: =IFERROR(VLOOKUP(H16,[1]SEMIELABORADOS!$A$2:$M$6000,2,0),"") -> AZUCAR BLANCO INDUSTRIAL KILO | C16: =+A16 -> 2000 | D16: =IFERROR(VLOOKUP(H16,[1]SEMIELABORADOS!$A$2:$M$6000,6,0),"") -> Gramo | E16: =IFERROR(VLOOKUP(H16,[1]SEMIELABORADOS!$A$2:$H$65536,8,0),"") -> 0.39034 | F16: =IFERROR(E16*C16,"") -> 780.68 | G16: =IFERROR(F16/$F$65,"") -> 0.12622109 | H16: 90100131
B17: =IFERROR(VLOOKUP(H17,[1]SEMIELABORADOS!$A$2:$M$6000,2,0),"") | C17: =+A17 -> 0 | D17: =IFERROR(VLOOKUP(H17,[1]SEMIELABORADOS!$A$2:$M$6000,6,0),"") | E17: =IFERROR(VLOOKUP(H17,[1]SEMIELABORADOS!$A$2:$H$65536,8,0),"") | F17: =IFERROR(E17*C17,"") | G17: =IFERROR(F17/$F$65,"")
B18: =IFERROR(VLOOKUP(H18,[1]SEMIELABORADOS!$A$2:$M$6000,2,0),"") | C18: =+A18 -> 0 | D18: =IFERROR(VLOOKUP(H18,[1]SEMIELABORADOS!$A$2:$M$6000,6,0),"") | E18: =IFERROR(VLOOKUP(H18,[1]SEMIELABORADOS!$A$2:$H$65536,8,0),"") | F18: =IFERROR(E18*C18,"") | G18: =IFERROR(F18/$F$65,"")
B19: =IFERROR(VLOOKUP(H19,[1]SEMIELABORADOS!$A$2:$M$6000,2,0),"") | C19: =+A19 -> 0 | D19: =IFERROR(VLOOKUP(H19,[1]SEMIELABORADOS!$A$2:$M$6000,6,0),"") | E19: =IFERROR(VLOOKUP(H19,[1]SEMIELABORADOS!$A$2:$H$65536,8,0),"") | F19: =IFERROR(E19*C19,"") | G19: =IFERROR(F19/$F$65,"")
B20: =IFERROR(VLOOKUP(H20,[1]SEMIELABORADOS!$A$2:$M$6000,2,0),"") | C20: =+A20 -> 0 | D20: =IFERROR(VLOOKUP(H20,[1]SEMIELABORADOS!$A$2:$M$6000,6,0),"") | E20: =IFERROR(VLOOKUP(H20,[1]SEMIELABORADOS!$A$2:$H$65536,8,0),"") | F20: =IFERROR(E20*C20,"") | G20: =IFERROR(F20/$F$65,"")
B21: =IFERROR(VLOOKUP(H21,[1]SEMIELABORADOS!$A$2:$M$6000,2,0),"") | C21: =+A21 -> 0 | D21: =IFERROR(VLOOKUP(H21,[1]SEMIELABORADOS!$A$2:$M$6000,6,0),"") | E21: =IFERROR(VLOOKUP(H21,[1]SEMIELABORADOS!$A$2:$H$65536,8,0),"") | F21: =IFERROR(E21*C21,"") | G21: =IFERROR(F21/$F$65,"")
B22: =IFERROR(VLOOKUP(H22,[1]SEMIELABORADOS!$A$2:$M$6000,2,0),"") | C22: =+A22 -> 0 | D22: =IFERROR(VLOOKUP(H22,[1]SEMIELABORADOS!$A$2:$M$6000,6,0),"") | E22: =IFERROR(VLOOKUP(H22,[1]SEMIELABORADOS!$A$2:$H$65536,8,0),"") | F22: =IFERROR(E22*C22,"") | G22: =IFERROR(F22/$F$65,"")
B23: =IFERROR(VLOOKUP(H23,[1]SEMIELABORADOS!$A$2:$M$6000,2,0),"") | C23: =+A23 -> 0 | D23: =IFERROR(VLOOKUP(H23,[1]SEMIELABORADOS!$A$2:$M$6000,6,0),"") | E23: =IFERROR(VLOOKUP(H23,[1]SEMIELABORADOS!$A$2:$H$65536,8,0),"") | F23: =IFERROR(E23*C23,"") | G23: =IFERROR(F23/$F$65,"")
A25: UNIDADES | B25: EMPAQUE | C25: UNIDADES | D25: UND MEDIDA | E25: COSTO UNITARIO | F25: TOTAL COSTO | G25: % PREC. DEFINIDO | H25: CODIGOS
A26: 3 | B26: =IFERROR(VLOOKUP(H26,'[1]Consolidado MP Planta'!$A$2:$M$823,3,0),"") -> BOLSA 12x18 TRANSP KILO | C26: =+A26 -> 3 | D26: =IFERROR(VLOOKUP(H26,'[1]Consolidado MP Planta'!$A$2:$M$823,13,0),"") -> Und | E26: =IFERROR(VLOOKUP(H26,'[1]Consolidado MP Planta'!$A$2:$M$823,12,0),"") -> 16 | F26: =IFERROR(C26*E26,"") -> 48 | G26: =IFERROR(F26/$F$65,"") -> 0.0077606858 | H26: 1950702
A27: 1 | B27: =IFERROR(VLOOKUP(H27,'[1]Consolidado MP Planta'!$A$2:$M$823,3,0),"") -> ETIQUETA BLANCA 2 5/8X1 15/16 (UND) | C27: =+A27 -> 1 | D27: =IFERROR(VLOOKUP(H27,'[1]Consolidado MP Planta'!$A$2:$M$823,13,0),"") -> Und | E27: =IFERROR(VLOOKUP(H27,'[1]Consolidado MP Planta'!$A$2:$M$823,12,0),"") -> 2.128 | F27: =IFERROR(C27*E27,"") -> 2.128 | G27: =IFERROR(F27/$F$65,"") -> 0.00034405707 | H27: 0702123
A28: 1 | B28: =IFERROR(VLOOKUP(H28,'[1]Consolidado MP Planta'!$A$2:$M$823,3,0),"") -> ETIQUETA ROJA LETRA ALERJENO (UND) | C28: =+A28 -> 1 | D28: =IFERROR(VLOOKUP(H28,'[1]Consolidado MP Planta'!$A$2:$M$823,13,0),"") -> Und | E28: =IFERROR(VLOOKUP(H28,'[1]Consolidado MP Planta'!$A$2:$M$823,12,0),"") -> 3.6 | F28: =IFERROR(C28*E28,"") -> 3.6 | G28: =IFERROR(F28/$F$65,"") -> 0.00058205143 | H28: 60100010
B29: =IFERROR(VLOOKUP(H29,'[1]Consolidado MP Planta'!$A$2:$M$823,3,0),"") | C29: =+A29 -> 0 | D29: =IFERROR(VLOOKUP(H29,'[1]Consolidado MP Planta'!$A$2:$M$823,13,0),"") | E29: =IFERROR(VLOOKUP(H29,'[1]Consolidado MP Planta'!$A$2:$M$823,12,0),"") | F29: =IFERROR(C29*E29,"") | G29: =IFERROR(F29/$F$65,"")
B30: =IFERROR(VLOOKUP(H30,'[1]Consolidado MP Planta'!$A$2:$M$823,3,0),"") | C30: =+A30 -> 0 | D30: =IFERROR(VLOOKUP(H30,'[1]Consolidado MP Planta'!$A$2:$M$823,13,0),"") | E30: =IFERROR(VLOOKUP(H30,'[1]Consolidado MP Planta'!$A$2:$M$823,12,0),"") | F30: =IFERROR(C30*E30,"") | G30: =IFERROR(F30/$F$65,"")
B31: =IFERROR(VLOOKUP(H31,'[1]Consolidado MP Planta'!$A$2:$M$823,3,0),"") | C31: =+A31 -> 0 | D31: =IFERROR(VLOOKUP(H31,'[1]Consolidado MP Planta'!$A$2:$M$823,13,0),"") | E31: =IFERROR(VLOOKUP(H31,'[1]Consolidado MP Planta'!$A$2:$M$823,12,0),"") | F31: =IFERROR(C31*E31,"") | G31: =IFERROR(F31/$F$65,"")
A33: UNIDADES | B33: EMPAQUE SEMIELABORADOS | C33: UNIDADES | D33: UND MEDIDA | E33: COSTO UNITARIO | F33: TOTAL COSTO | G33: % PREC. DEFINIDO | H33: CODIGOS
A34: =+A16 -> 2000 | B34: =IFERROR(VLOOKUP(H34,[1]SEMIELABORADOS!$A$2:$M$6000,2,0),"") -> AZUCAR BLANCO INDUSTRIAL KILO | C34: =+A34 -> 2000 | D34: =IFERROR(VLOOKUP(H34,[1]SEMIELABORADOS!$A$2:$M$6000,6,0),"") -> Gramo | E34: 0.05 | F34: =IFERROR(E34*C34,"") -> 100 | G34: =IFERROR(F34/$F$65,"") -> 0.016168095 | H34: 90100131
A35: =+A17 -> 0 | B35: =IFERROR(VLOOKUP(H35,[1]SEMIELABORADOS!$A$2:$M$6000,2,0),"") | C35: =+A35 -> 0 | D35: =IFERROR(VLOOKUP(H35,[1]SEMIELABORADOS!$A$2:$M$6000,6,0),"") | E35: =IFERROR(VLOOKUP(H35,[1]SEMIELABORADOS!$A$2:$M$65536,10,0),"") | F35: =IFERROR(E35*C35,"") | G35: =IFERROR(F35/$F$65,"")
A36: =+A18 -> 0 | B36: =IFERROR(VLOOKUP(H36,[1]SEMIELABORADOS!$A$2:$M$6000,2,0),"") | C36: =+A36 -> 0 | D36: =IFERROR(VLOOKUP(H36,[1]SEMIELABORADOS!$A$2:$M$6000,6,0),"") | E36: =IFERROR(VLOOKUP(H36,[1]SEMIELABORADOS!$A$2:$M$65536,10,0),"") | F36: =IFERROR(E36*C36,"") | G36: =IFERROR(F36/$F$65,"")
A37: =+A19 -> 0 | B37: =IFERROR(VLOOKUP(H37,[1]SEMIELABORADOS!$A$2:$M$6000,2,0),"") | C37: =+A37 -> 0 | D37: =IFERROR(VLOOKUP(H37,[1]SEMIELABORADOS!$A$2:$M$6000,6,0),"") | E37: =IFERROR(VLOOKUP(H37,[1]SEMIELABORADOS!$A$2:$M$65536,10,0),"") | F37: =IFERROR(E37*C37,"") | G37: =IFERROR(F37/$F$65,"")
A38: =+A20 -> 0 | B38: =IFERROR(VLOOKUP(H38,[1]SEMIELABORADOS!$A$2:$M$6000,2,0),"") | C38: =+A38 -> 0 | D38: =IFERROR(VLOOKUP(H38,[1]SEMIELABORADOS!$A$2:$M$6000,6,0),"") | E38: =IFERROR(VLOOKUP(H38,[1]SEMIELABORADOS!$A$2:$M$65536,10,0),"") | F38: =IFERROR(E38*C38,"") | G38: =IFERROR(F38/$F$65,"")
A39: =+A21 -> 0 | B39: =IFERROR(VLOOKUP(H39,[1]SEMIELABORADOS!$A$2:$M$6000,2,0),"") | C39: =+A39 -> 0 | D39: =IFERROR(VLOOKUP(H39,[1]SEMIELABORADOS!$A$2:$M$6000,6,0),"") | E39: =IFERROR(VLOOKUP(H39,[1]SEMIELABORADOS!$A$2:$M$65536,10,0),"") | F39: =IFERROR(E39*C39,"") | G39: =IFERROR(F39/$F$65,"")
A40: =+A22 -> 0 | B40: =IFERROR(VLOOKUP(H40,[1]SEMIELABORADOS!$A$2:$M$6000,2,0),"") | C40: =+A40 -> 0 | D40: =IFERROR(VLOOKUP(H40,[1]SEMIELABORADOS!$A$2:$M$6000,6,0),"") | E40: =IFERROR(VLOOKUP(H40,[1]SEMIELABORADOS!$A$2:$M$65536,10,0),"") | F40: =IFERROR(E40*C40,"") | G40: =IFERROR(F40/$F$65,"")
A42: UNIDADES | B42: MODI | C42: UNIDADES | D42: UND MEDIDA | E42: COSTO UNITARIO | F42: TOTAL COSTO | G42: % PREC. DEFINIDO | H42: CODIGOS
A43: =+A34 -> 2000 | B43: =IFERROR(VLOOKUP(H43,[1]SEMIELABORADOS!$A$2:$M$6000,2,0),"") -> AZUCAR BLANCO INDUSTRIAL KILO | C43: =+A43 -> 2000 | D43: =IFERROR(VLOOKUP(H43,[1]SEMIELABORADOS!$A$2:$M$6000,6,0),"") -> Gramo | E43: =IFERROR(VLOOKUP(H43,[1]SEMIELABORADOS!$A$2:$M$65536,12,0),"") -> 0.076260694 | F43: =IFERROR(E43*C43,"") -> 152.52139 | G43: =IFERROR(F43/$F$65,"") -> 0.024659803 | H43: 90100131
A44: =+A35 -> 0 | B44: =IFERROR(VLOOKUP(H44,[1]SEMIELABORADOS!$A$2:$M$6000,2,0),"") | C44: =+A44 -> 0 | D44: =IFERROR(VLOOKUP(H44,[1]SEMIELABORADOS!$A$2:$M$6000,6,0),"") | E44: =IFERROR(VLOOKUP(H44,[1]SEMIELABORADOS!$A$2:$M$65536,12,0),"") | F44: =IFERROR(E44*C44,"") | G44: =IFERROR(F44/$F$65,"")
A45: =+A36 -> 0 | B45: =IFERROR(VLOOKUP(H45,[1]SEMIELABORADOS!$A$2:$M$6000,2,0),"") | C45: =+A45 -> 0 | D45: =IFERROR(VLOOKUP(H45,[1]SEMIELABORADOS!$A$2:$M$6000,6,0),"") | E45: =IFERROR(VLOOKUP(H45,[1]SEMIELABORADOS!$A$2:$M$65536,12,0),"") | F45: =IFERROR(E45*C45,"") | G45: =IFERROR(F45/$F$65,"")
...

Sheet Hoja1
C1: SERVICIOS DE PASTELERIA S.A. | H1: CÓDIGO: | I1: ESP-RE-PRES-027
C2: ESPECIFICACION DE RECETA | H2: REVISIÓN: | I2: 01
C3: 906000145 (SE00471) Premezcla para Turron de chocolate y pecanas | H3: FECHA DE APROBACIÓN: | I3: 45617
C4: Elaborado | D4: Javier Tong, Chef
C5: Aprobado | D5: Esteban Cartin, Gte Manufactura
A6: AREA QUE PRODUCE: | D6: Premezclas | G6: AREA QUE EMPACA: | I6: Premezclas
A7: # Código | B7: # Código Netsuite | C7: Descripción del ingrediente | D7: Marca | E7: Unidad Internacional | G7: Medida alternativa | I7: Costo - Referencia
E8: Cantidad | F8: Unidad medida | G8: Cantidad | H8: Unidad medida | I8: Colones
C9: Ensamble
A10: 90100131 | B10: SE00016 | C10: AZUCAR BLANCO INDUSTRIAL KILO | D10: FAS | E10: 2000 | F10: g
A11: 11200071 | B11: MP10479 | C11: HARINA FHACASA VERDE (SACO: 25 K) | D11: FHACASA | E11: 884 | F11: g
A12: 512255 | B12: MP10146 | C12: COCOA DUTCH PROCESS (SACO: 25 KG) | D12: CR COCOA | E12: 56 | F12: g
A13: 10100046 | B13: MP10304 | C13: POLVO HORNEAR FLEISHMAN (PAQ:2.5 K) | D13: FLEISHMAN | E13: 10 | F13: g
A14: 1212412 | B14: MP10025 | C14: PRESERVANTE 1017S (PAQ=5 KILO) | D14: MAYCA | E14: 10 | F14: g
A15: 11900028 | B15: MP10562 | C15: PECANA ENTERA (CAJA:13.6 K) | D15: NUECES INDUSTRIALES | E15: 450 | F15: g
C21: Decoración
C29: Empaque
A30: 1950702 | B30: EM10016 | C30: BOLSA 12x18 TRANSP KILO | D30: ETIPLAST | E30: 3 | F30: ud
A31: 0702123 | B31: EM10011 | C31: ETIQUETA BLANCA 2 5/8X1 15/16 (UND) | D31: ETIPLAST | E31: 1 | F31: ud
A32: 60100010 | B32: EM10133 | C32: ETIQUETA ROJA LETRA ALERJENO (UND) | D32: ETIPLAST | E32: 1 | F32: ud
D42: Cantidad | E42: Unidad
A43: PESO TOTAL OBTENIDO | D43: 3410 | E43: g | F43: Tiempo de Horneo:
A44: TIEMPO TOTAL DE PREPARACION | D44: 2 | E44: min | F44: Horno:
A45: CANTIDAD DE PORCIONES OBTENIDAS | D45: 1 | E45: ud | F45: Temperatura de Horneo:
A46: PESO DE CADA PORCIÓN | D46: 3410 | E46: g | F46: Otros
A47: MERMA | D47: 0 | E47: g
A48: PROCEDIMIENTO DE PREPARACION DE LA RECETA
A49: 1.- Empacar en una bolsa 12x18 el azucar.
A50: 2.- En la otra bolsa colocar la harina, cocoa, preservante y el polvo de hornear, colocar esta bolsa dentro del azucar.
A51: 3.- Pesar en una bolsa 12x18 las pecanas.
A52: 4.- Etiquetar con nombre y alerjeno
A57: CONTROL DE CAMBIOS

Sheet Costo Batido
E1: Precio Local | F1: Costo MP | G1: Costo EM | H1: Costo MO
E2: =IFERROR(O62,"") -> 759.06385 | F2: =IFERROR(H53,"") -> 643.59442 | G2: =IFERROR(H54,"") -> 8.5153992 | H2: =IFERROR(H56,"") -> 47.09633
A5: ESTRUCTURA DE COSTOS
F6: Fecha: | H6: =TODAY() -> 45663
A7: UNIDADES | B7: DESCRIPCION MAT.PRIMA | C7: UNIDADES | D7: UND MEDIDA | E7: COSTO UNITARIO | F7: TOTAL COSTO | G7: % PREC. DEFINIDO | H7: CODIGOS
A8: 600 | B8: =IFERROR(VLOOKUP(H8,'[1]Consolidado MP Planta'!$A$2:$M$823,3,0),"") -> LACTOCREMA GRANEL (CAJA:25 KG) | C8: =+A8 -> 600 | D8: =IFERROR(VLOOKUP(H8,'[1]Consolidado MP Planta'!$A$2:$M$823,13,0),"") -> Gramos | E8: 3.93 | F8: =IFERROR(C8*E8,"") -> 2358 | G8: =IFERROR(F8/$F$66,"") -> 0.18789338 | H8: 0310107
A9: 780 | B9: =IFERROR(VLOOKUP(H9,'[1]Consolidado MP Planta'!$A$2:$M$823,3,0),"") -> CLARA DE HUEVO (CAJA:5 K) | C9: =+A9 -> 780 | D9: =IFERROR(VLOOKUP(H9,'[1]Consolidado MP Planta'!$A$2:$M$823,13,0),"") -> Gramos | E9: 2.78 | F9: =IFERROR(C9*E9,"") -> 2168.4 | G9: =IFERROR(F9/$F$66,"") -> 0.17278541 | H9: 11300009
A10: 440 | B10: =IFERROR(VLOOKUP(H10,'[1]Consolidado MP Planta'!$A$2:$M$823,3,0),"") -> YEMA DE HUEVO (UND: 8.34 K) | C10: =+A10 -> 440 | D10: =IFERROR(VLOOKUP(H10,'[1]Consolidado MP Planta'!$A$2:$M$823,13,0),"") -> 0 | E10: 2.9 | F10: =IFERROR(C10*E10,"") -> 1276 | G10: =IFERROR(F10/$F$66,"") -> 0.10167597 | H10: 11300011
B11: =IFERROR(VLOOKUP(H11,'[1]Consolidado MP Planta'!$A$2:$M$823,3,0),"") | C11: =+A11 -> 0 | D11: =IFERROR(VLOOKUP(H11,'[1]Consolidado MP Planta'!$A$2:$M$823,13,0),"") | E11: =IFERROR(VLOOKUP(H11,'[1]Consolidado MP Planta'!$A$2:$M$823,12,0),"") | F11: =IFERROR(C11*E11,"") | G11: =IFERROR(F11/$F$66,"")
B12: =IFERROR(VLOOKUP(H12,'[1]Consolidado MP Planta'!$A$2:$M$823,3,0),"") | C12: =+A12 -> 0 | D12: =IFERROR(VLOOKUP(H12,'[1]Consolidado MP Planta'!$A$2:$M$823,13,0),"") | E12: =IFERROR(VLOOKUP(H12,'[1]Consolidado MP Planta'!$A$2:$M$823,12,0),"") | F12: =IFERROR(C12*E12,"") | G12: =IFERROR(F12/$F$66,"")
B13: =IFERROR(VLOOKUP(H13,'[1]Consolidado MP Planta'!$A$2:$M$823,3,0),"") | C13: =+A13 -> 0 | D13: =IFERROR(VLOOKUP(H13,'[1]Consolidado MP Planta'!$A$2:$M$823,13,0),"") | E13: =IFERROR(VLOOKUP(H13,'[1]Consolidado MP Planta'!$A$2:$M$823,12,0),"") | F13: =IFERROR(C13*E13,"") | G13: =IFERROR(F13/$F$66,"")
B14: =IFERROR(VLOOKUP(H14,'[1]Consolidado MP Planta'!$A$2:$M$823,3,0),"") | C14: =+A14 -> 0 | D14: =IFERROR(VLOOKUP(H14,'[1]Consolidado MP Planta'!$A$2:$M$823,13,0),"") | E14: =IFERROR(VLOOKUP(H14,'[1]Consolidado MP Planta'!$A$2:$M$823,12,0),"") | F14: =IFERROR(C14*E14,"") | G14: =IFERROR(F14/$F$66,"")
B15: =IFERROR(VLOOKUP(H15,'[2]ARTICULOS MP PLANTA'!$A$2:$G$589,2,0),"")
A16: UNIDADES | B16: MATERIA PRIMA SEMIELABORADOS | C16: UNIDADES | D16: UND MEDIDA | E16: COSTO UNITARIO | F16: TOTAL COSTO | G16: % PREC. DEFINIDO | H16: CODIGOS
A17: 3400 | B17: PREMEZCLA PARA TURRON DE CHOCOLATE Y PECANAS | C17: =+A17 -> 3400 | D17: Gramos | E17: =+'Costo Premezcla '!E68 -> 1.7006763 | F17: =IFERROR(E17*C17,"") -> 5782.2995 | G17: =IFERROR(F17/$F$66,"") -> 0.46075309 | H17: NUEVO
B18: =IFERROR(VLOOKUP(H18,[1]SEMIELABORADOS!$A$2:$M$6000,2,0),"") | C18: =+A18 -> 0 | D18: =IFERROR(VLOOKUP(H18,[1]SEMIELABORADOS!$A$2:$M$6000,6,0),"") | E18: =IFERROR(VLOOKUP(H18,[1]SEMIELABORADOS!$A$2:$H$65536,8,0),"") | F18: =IFERROR(E18*C18,"") | G18: =IFERROR(F18/$F$66,"")
B19: =IFERROR(VLOOKUP(H19,[1]SEMIELABORADOS!$A$2:$M$6000,2,0),"") | C19: =+A19 -> 0 | D19: =IFERROR(VLOOKUP(H19,[1]SEMIELABORADOS!$A$2:$M$6000,6,0),"") | E19: =IFERROR(VLOOKUP(H19,[1]SEMIELABORADOS!$A$2:$H$65536,8,0),"") | F19: =IFERROR(E19*C19,"") | G19: =IFERROR(F19/$F$66,"")
B20: =IFERROR(VLOOKUP(H20,[1]SEMIELABORADOS!$A$2:$M$6000,2,0),"") | C20: =+A20 -> 0 | D20: =IFERROR(VLOOKUP(H20,[1]SEMIELABORADOS!$A$2:$M$6000,6,0),"") | E20: =IFERROR(VLOOKUP(H20,[1]SEMIELABORADOS!$A$2:$H$65536,8,0),"") | F20: =IFERROR(E20*C20,"") | G20: =IFERROR(F20/$F$66,"")
B21: =IFERROR(VLOOKUP(H21,[1]SEMIELABORADOS!$A$2:$M$6000,2,0),"") | C21: =+A21 -> 0 | D21: =IFERROR(VLOOKUP(H21,[1]SEMIELABORADOS!$A$2:$M$6000,6,0),"") | E21: =IFERROR(VLOOKUP(H21,[1]SEMIELABORADOS!$A$2:$H$65536,8,0),"") | F21: =IFERROR(E21*C21,"") | G21: =IFERROR(F21/$F$66,"")
B22: =IFERROR(VLOOKUP(H22,[1]SEMIELABORADOS!$A$2:$M$6000,2,0),"") | C22: =+A22 -> 0 | D22: =IFERROR(VLOOKUP(H22,[1]SEMIELABORADOS!$A$2:$M$6000,6,0),"") | E22: =IFERROR(VLOOKUP(H22,[1]SEMIELABORADOS!$A$2:$H$65536,8,0),"") | F22: =IFERROR(E22*C22,"") | G22: =IFERROR(F22/$F$66,"")
B23: =IFERROR(VLOOKUP(H23,[1]SEMIELABORADOS!$A$2:$M$6000,2,0),"") | C23: =+A23 -> 0 | D23: =IFERROR(VLOOKUP(H23,[1]SEMIELABORADOS!$A$2:$M$6000,6,0),"") | E23: =IFERROR(VLOOKUP(H23,[1]SEMIELABORADOS!$A$2:$H$65536,8,0),"") | F23: =IFERROR(E23*C23,"") | G23: =IFERROR(F23/$F$66,"")
B24: =IFERROR(VLOOKUP(H24,[1]SEMIELABORADOS!$A$2:$M$6000,2,0),"") | C24: =+A24 -> 0 | D24: =IFERROR(VLOOKUP(H24,[1]SEMIELABORADOS!$A$2:$M$6000,6,0),"") | E24: =IFERROR(VLOOKUP(H24,[1]SEMIELABORADOS!$A$2:$H$65536,8,0),"") | F24: =IFERROR(E24*C24,"") | G24: =IFERROR(F24/$F$66,"")
A26: UNIDADES | B26: EMPAQUE | C26: UNIDADES | D26: UND MEDIDA | E26: COSTO UNITARIO | F26: TOTAL COSTO | G26: % PREC. DEFINIDO | H26: CODIGOS
A27: 0 | B27: =IFERROR(VLOOKUP(H27,'[1]Consolidado MP Planta'!$A$2:$M$823,3,0),"") | C27: =+A27 -> 0 | D27: =IFERROR(VLOOKUP(H27,'[1]Consolidado MP Planta'!$A$2:$M$823,13,0),"") | E27: =IFERROR(VLOOKUP(H27,'[1]Consolidado MP Planta'!$A$2:$M$823,12,0),"") | F27: =IFERROR(C27*E27,"") | G27: =IFERROR(F27/$F$66,"")
B28: =IFERROR(VLOOKUP(H28,'[1]Consolidado MP Planta'!$A$2:$M$823,3,0),"") | C28: =+A28 -> 0 | D28: =IFERROR(VLOOKUP(H28,'[1]Consolidado MP Planta'!$A$2:$M$823,13,0),"") | E28: =IFERROR(VLOOKUP(H28,'[1]Consolidado MP Planta'!$A$2:$M$823,12,0),"") | F28: =IFERROR(C28*E28,"") | G28: =IFERROR(F28/$F$66,"")
B29: =IFERROR(VLOOKUP(H29,'[1]Consolidado MP Planta'!$A$2:$M$823,3,0),"") | C29: =+A29 -> 0 | D29: =IFERROR(VLOOKUP(H29,'[1]Consolidado MP Planta'!$A$2:$M$823,13,0),"") | E29: =IFERROR(VLOOKUP(H29,'[1]Consolidado MP Planta'!$A$2:$M$823,12,0),"") | F29: =IFERROR(C29*E29,"") | G29: =IFERROR(F29/$F$66,"")
B30: =IFERROR(VLOOKUP(H30,'[1]Consolidado MP Planta'!$A$2:$M$823,3,0),"") | C30: =+A30 -> 0 | D30: =IFERROR(VLOOKUP(H30,'[1]Consolidado MP Planta'!$A$2:$M$823,13,0),"") | E30: =IFERROR(VLOOKUP(H30,'[1]Consolidado MP Planta'!$A$2:$M$823,12,0),"") | F30: =IFERROR(C30*E30,"") | G30: =IFERROR(F30/$F$66,"")
B31: =IFERROR(VLOOKUP(H31,'[1]Consolidado MP Planta'!$A$2:$M$823,3,0),"") | C31: =+A31 -> 0 | D31: =IFERROR(VLOOKUP(H31,'[1]Consolidado MP Planta'!$A$2:$M$823,13,0),"") | E31: =IFERROR(VLOOKUP(H31,'[1]Consolidado MP Planta'!$A$2:$M$823,12,0),"") | F31: =IFERROR(C31*E31,"") | G31: =IFERROR(F31/$F$66,"")
B32: =IFERROR(VLOOKUP(H32,'[1]Consolidado MP Planta'!$A$2:$M$823,3,0),"") | C32: =+A32 -> 0 | D32: =IFERROR(VLOOKUP(H32,'[1]Consolidado MP Planta'!$A$2:$M$823,13,0),"") | E32: =IFERROR(VLOOKUP(H32,'[1]Consolidado MP Planta'!$A$2:$M$823,12,0),"") | F32: =IFERROR(C32*E32,"") | G32: =IFERROR(F32/$F$66,"")
A34: UNIDADES | B34: EMPAQUE SEMIELABORADOS | C34: UNIDADES | D34: UND MEDIDA | E34: COSTO UNITARIO | F34: TOTAL COSTO | G34: % PREC. DEFINIDO | H34: CODIGOS
A35: =+A17 -> 3400 | B35: PREMEZCLA PARA TURRON DE CHOCOLATE Y PECANAS | C35: =+A35 -> 3400 | D35: Gramos | E35: =+'Costo Premezcla '!E75 -> 0.045081525 | F35: =IFERROR(E35*C35,"") -> 153.27718 | G35: =IFERROR(F35/$F$66,"") -> 0.012213642 | H35: NUEVO
A36: =+A18 -> 0 | B36: =IFERROR(VLOOKUP(H36,[1]SEMIELABORADOS!$A$2:$M$6000,2,0),"") | C36: =+A36 -> 0 | D36: =IFERROR(VLOOKUP(H36,[1]SEMIELABORADOS!$A$2:$M$6000,6,0),"") | E36: =IFERROR(VLOOKUP(H36,[1]SEMIELABORADOS!$A$2:$M$65536,10,0),"") | F36: =IFERROR(E36*C36,"") | G36: =IFERROR(F36/$F$66,"")
A37: =+A19 -> 0 | B37: =IFERROR(VLOOKUP(H37,[1]SEMIELABORADOS!$A$2:$M$6000,2,0),"") | C37: =+A37 -> 0 | D37: =IFERROR(VLOOKUP(H37,[1]SEMIELABORADOS!$A$2:$M$6000,6,0),"") | E37: =IFERROR(VLOOKUP(H37,[1]SEMIELABORADOS!$A$2:$M$65536,10,0),"") | F37: =IFERROR(E37*C37,"") | G37: =IFERROR(F37/$F$66,"")
A38: =+A20 -> 0 | B38: =IFERROR(VLOOKUP(H38,[1]SEMIELABORADOS!$A$2:$M$6000,2,0),"") | C38: =+A38 -> 0 | D38: =IFERROR(VLOOKUP(H38,[1]SEMIELABORADOS!$A$2:$M$6000,6,0),"") | E38: =IFERROR(VLOOKUP(H38,[1]SEMIELABORADOS!$A$2:$M$65536,10,0),"") | F38: =IFERROR(E38*C38,"") | G38: =IFERROR(F38/$F$66,"")
A39: =+A21 -> 0 | B39: =IFERROR(VLOOKUP(H39,[1]SEMIELABORADOS!$A$2:$M$6000,2,0),"") | C39: =+A39 -> 0 | D39: =IFERROR(VLOOKUP(H39,[1]SEMIELABORADOS!$A$2:$M$6000,6,0),"") | E39: =IFERROR(VLOOKUP(H39,[1]SEMIELABORADOS!$A$2:$M$65536,10,0),"") | F39: =IFERROR(E39*C39,"") | G39: =IFERROR(F39/$F$66,"")
A40: =+A22 -> 0 | B40: =IFERROR(VLOOKUP(H40,[1]SEMIELABORADOS!$A$2:$M$6000,2,0),"") | C40: =+A40 -> 0 | D40: =IFERROR(VLOOKUP(H40,[1]SEMIELABORADOS!$A$2:$M$6000,6,0),"") | E40: =IFERROR(VLOOKUP(H40,[1]SEMIELABORADOS!$A$2:$M$65536,10,0),"") | F40: =IFERROR(E40*C40,"") | G40: =IFERROR(F40/$F$66,"")
A41: =+A23 -> 0 | B41: =IFERROR(VLOOKUP(H41,[1]SEMIELABORADOS!$A$2:$M$6000,2,0),"") | C41: =+A41 -> 0 | D41: =IFERROR(VLOOKUP(H41,[1]SEMIELABORADOS!$A$2:$M$6000,6,0),"") | E41: =IFERROR(VLOOKUP(H41,[1]SEMIELABORADOS!$A$2:$M$65536,10,0),"") | F41: =IFERROR(E41*C41,"") | G41: =IFERROR(F41/$F$66,"")
A43: UNIDADES | B43: MODI | C43: UNIDADES | D43: UND MEDIDA | E43: COSTO UNITARIO | F43: TOTAL COSTO | G43: % PREC. DEFINIDO | H43: CODIGOS
A44: =+A35 -> 3400 | B44: PREMEZCLA PARA TURRON DE CHOCOLATE Y PECANAS | C44: =+A44 -> 3400 | D44: Gramos | E44: =+'Costo Premezcla '!E73 -> 0.078745275 | F44: =IFERROR(E44*C44,"") -> 267.73394 | G44: =IFERROR(F44/$F$66,"") -> 0.021333941 | H44: NUEVO
A45: =+A36 -> 0 | B45: =IFERROR(VLOOKUP(H45,[1]SEMIELABORADOS!$A$2:$M$6000,2,0),"") | C45: =+A45 -> 0 | D45: =IFERROR(VLOOKUP(H45,[1]SEMIELABORADOS!$A$2:$M$6000,6,0),"") | E45: =IFERROR(VLOOKUP(H45,[1]SEMIELABORADOS!$A$2:$M$65536,12,0),"") | F45: =IFERROR(E45*C45,"") | G45: =IFERROR(F45/$F$66,"")
...

Sheet Mezcla engrase moldes
B1: SERVICIOS DE PASTELERIA S.A. | G1: CÓDIGO: | H1: ESP-RE-BAS-006
B2: ESPECIFICACION DE RECETA | G2: REVISIÓN: | H2: 06
B3: Mezcla para engrase moldes 29800g 902000019 | G3: FECHA DE APROBACIÓN: | H3: 44202
B4: Elaborado | C4: Javier Tong, Chef
B5: Aprobado | C5: Jeffry Rodriguez. Gte de Manufactura
A6: # Código | B6: Descripción del ingrediente | C6: Marca | D6: Unidad Internacional | F6: Medida Costeo | H6: Costo - Referencia
D7: Cantidad | E7: Unidad medida | F7: Cantidad | G7: Unidad medida | H7: Colones
A9: 1210401 | B9: MANTECA MAX PAN (CAJA:25 k) | C9: Max Pan | D9: 25000 | E9: g | F9: 1 | G9: Caja
A10: 0510188 | B10: HARINA ESTANDAR (SACO: 25 KG ) | C10: Harisol | D10: 5000 | E10: g | F10: =+D10/25000 -> 0.2 | G10: Saco
A12: 512000002 | B12: PLASTICO AUTOAD (UND: 18 * 2000 M) | C12: Mayca | D12: 800 | E12: cm | F12: =+D12/20000 -> 0.04 | G12: Und
C15: Cantidad | D15: Unidad
A16: PESO TOTAL OBTENIDO | C16: 29800 | D16: g | E16: Tiempo de Horneo:
A17: TIEMPO TOTAL DE PREPARACION | C17: 30 | D17: min | E17: Horno:
A18: CANTIDAD DE PORCIONES OBTENIDAS | C18: 1 | D18: Tanda | E18: Temperatura de Horneo:
A19: PESO DE CADA PORCIÓN | C19: =C16 -> 29800 | D19: g | E19: Otros
A20: MERMA | C20: =SUM(D9:D10)-C16 -> 200 | D20: g
A21: PROCEDIMIENTO DE PREPARACION DE LA RECETA
A22: 1,- Colocar la manteca en la batidora y batir por 3 minutos hasta que se suavise.
A23: 2,- Agregar el harina y batir 40 minutos mas hasta homogenizar en velocidad 1.
A24: 3,- Colocar la mezcla en botes de plastico.Cubrir con papel autoadhesivo.
A27: Control de cambios
A28: 5, Actualizacion de codigos
A29: Revisión #6: Actualización de procedimiento.

Sheet Costo Rosquete 
E1: Precio Local | F1: Costo MP | G1: Costo EM | H1: Costo MO
E2: =IFERROR(O62,"") -> 796.21069 | F2: =IFERROR(H53,"") -> 659.91442 | G2: =IFERROR(H54,"") -> 22.88769 | H2: =IFERROR(H56,"") -> 74.884314
A5: ESTRUCTURA DE COSTOS
F6: Fecha: | H6: =TODAY() -> 45663
A7: UNIDADES | B7: DESCRIPCION MAT.PRIMA | C7: UNIDADES | D7: UND MEDIDA | E7: COSTO UNITARIO | F7: TOTAL COSTO | G7: % PREC. DEFINIDO | H7: CODIGOS
B8: =IFERROR(VLOOKUP(H8,'[1]Consolidado MP Planta'!$A$2:$M$823,3,0),"") | C8: =+A8 -> 0 | D8: =IFERROR(VLOOKUP(H8,'[1]Consolidado MP Planta'!$A$2:$M$823,13,0),"") | E8: =IFERROR(VLOOKUP(H8,'[1]Consolidado MP Planta'!$A$2:$M$823,12,0),"") | F8: =IFERROR(C8*E8,"") | G8: =IFERROR(F8/$F$66,"")
B9: =IFERROR(VLOOKUP(H9,'[1]Consolidado MP Planta'!$A$2:$M$823,3,0),"") | C9: =+A9 -> 0 | D9: =IFERROR(VLOOKUP(H9,'[1]Consolidado MP Planta'!$A$2:$M$823,13,0),"") | E9: =IFERROR(VLOOKUP(H9,'[1]Consolidado MP Planta'!$A$2:$M$823,12,0),"") | F9: =IFERROR(C9*E9,"") | G9: =IFERROR(F9/$F$66,"")
B10: =IFERROR(VLOOKUP(H10,'[1]Consolidado MP Planta'!$A$2:$M$823,3,0),"") | C10: =+A10 -> 0 | D10: =IFERROR(VLOOKUP(H10,'[1]Consolidado MP Planta'!$A$2:$M$823,13,0),"") | E10: =IFERROR(VLOOKUP(H10,'[1]Consolidado MP Planta'!$A$2:$M$823,12,0),"") | F10: =IFERROR(C10*E10,"") | G10: =IFERROR(F10/$F$66,"")
B11: =IFERROR(VLOOKUP(H11,'[1]Consolidado MP Planta'!$A$2:$M$823,3,0),"") | C11: =+A11 -> 0 | D11: =IFERROR(VLOOKUP(H11,'[1]Consolidado MP Planta'!$A$2:$M$823,13,0),"") | E11: =IFERROR(VLOOKUP(H11,'[1]Consolidado MP Planta'!$A$2:$M$823,12,0),"") | F11: =IFERROR(C11*E11,"") | G11: =IFERROR(F11/$F$66,"")
B12: =IFERROR(VLOOKUP(H12,'[1]Consolidado MP Planta'!$A$2:$M$823,3,0),"") | C12: =+A12 -> 0 | D12: =IFERROR(VLOOKUP(H12,'[1]Consolidado MP Planta'!$A$2:$M$823,13,0),"") | E12: =IFERROR(VLOOKUP(H12,'[1]Consolidado MP Planta'!$A$2:$M$823,12,0),"") | F12: =IFERROR(C12*E12,"") | G12: =IFERROR(F12/$F$66,"")
B13: =IFERROR(VLOOKUP(H13,'[1]Consolidado MP Planta'!$A$2:$M$823,3,0),"") | C13: =+A13 -> 0 | D13: =IFERROR(VLOOKUP(H13,'[1]Consolidado MP Planta'!$A$2:$M$823,13,0),"") | E13: =IFERROR(VLOOKUP(H13,'[1]Consolidado MP Planta'!$A$2:$M$823,12,0),"") | F13: =IFERROR(C13*E13,"") | G13: =IFERROR(F13/$F$66,"")
B14: =IFERROR(VLOOKUP(H14,'[1]Consolidado MP Planta'!$A$2:$M$823,3,0),"") | C14: =+A14 -> 0 | D14: =IFERROR(VLOOKUP(H14,'[1]Consolidado MP Planta'!$A$2:$M$823,13,0),"") | E14: =IFERROR(VLOOKUP(H14,'[1]Consolidado MP Planta'!$A$2:$M$823,12,0),"") | F14: =IFERROR(C14*E14,"") | G14: =IFERROR(F14/$F$66,"")
B15: =IFERROR(VLOOKUP(H15,'[2]ARTICULOS MP PLANTA'!$A$2:$G$589,2,0),"")
A16: UNIDADES | B16: MATERIA PRIMA SEMIELABORADOS | C16: UNIDADES | D16: UND MEDIDA | E16: COSTO UNITARIO | F16: TOTAL COSTO | G16: % PREC. DEFINIDO | H16: CODIGOS
A17: 5040 | B17: BATIDO TURRON DE CHOCOLATE Y PECANAS | C17: =+A17 -> 5040 | D17: Gramos | E17: =+'Costo Batido'!E69 -> 2.2985515 | F17: =IFERROR(E17*C17,"") -> 11584.7 | G17: =IFERROR(F17/$F$66,"") -> 0.89167897 | H17: NUEVO
A18: 144 | B18: =IFERROR(VLOOKUP(H18,[1]SEMIELABORADOS!$A$2:$M$6000,2,0),"") -> MEZCLA P/ENGRASE MOLDES KILO | C18: =+A18 -> 144 | D18: =IFERROR(VLOOKUP(H18,[1]SEMIELABORADOS!$A$2:$M$6000,6,0),"") -> Gramo | E18: 2.04 | F18: =IFERROR(E18*C18,"") -> 293.76 | G18: =IFERROR(F18/$F$66,"") -> 0.022610825 | H18: 902000019
B19: =IFERROR(VLOOKUP(H19,[1]SEMIELABORADOS!$A$2:$M$6000,2,0),"") | C19: =+A19 -> 0 | D19: =IFERROR(VLOOKUP(H19,[1]SEMIELABORADOS!$A$2:$M$6000,6,0),"") | E19: =IFERROR(VLOOKUP(H19,[1]SEMIELABORADOS!$A$2:$H$65536,8,0),"") | F19: =IFERROR(E19*C19,"") | G19: =IFERROR(F19/$F$66,"")
B20: =IFERROR(VLOOKUP(H20,[1]SEMIELABORADOS!$A$2:$M$6000,2,0),"") | C20: =+A20 -> 0 | D20: =IFERROR(VLOOKUP(H20,[1]SEMIELABORADOS!$A$2:$M$6000,6,0),"") | E20: =IFERROR(VLOOKUP(H20,[1]SEMIELABORADOS!$A$2:$H$65536,8,0),"") | F20: =IFERROR(E20*C20,"") | G20: =IFERROR(F20/$F$66,"")
B21: =IFERROR(VLOOKUP(H21,[1]SEMIELABORADOS!$A$2:$M$6000,2,0),"") | C21: =+A21 -> 0 | D21: =IFERROR(VLOOKUP(H21,[1]SEMIELABORADOS!$A$2:$M$6000,6,0),"") | E21: =IFERROR(VLOOKUP(H21,[1]SEMIELABORADOS!$A$2:$H$65536,8,0),"") | F21: =IFERROR(E21*C21,"") | G21: =IFERROR(F21/$F$66,"")
B22: =IFERROR(VLOOKUP(H22,[1]SEMIELABORADOS!$A$2:$M$6000,2,0),"") | C22: =+A22 -> 0 | D22: =IFERROR(VLOOKUP(H22,[1]SEMIELABORADOS!$A$2:$M$6000,6,0),"") | E22: =IFERROR(VLOOKUP(H22,[1]SEMIELABORADOS!$A$2:$H$65536,8,0),"") | F22: =IFERROR(E22*C22,"") | G22: =IFERROR(F22/$F$66,"")
B23: =IFERROR(VLOOKUP(H23,[1]SEMIELABORADOS!$A$2:$M$6000,2,0),"") | C23: =+A23 -> 0 | D23: =IFERROR(VLOOKUP(H23,[1]SEMIELABORADOS!$A$2:$M$6000,6,0),"") | E23: =IFERROR(VLOOKUP(H23,[1]SEMIELABORADOS!$A$2:$H$65536,8,0),"") | F23: =IFERROR(E23*C23,"") | G23: =IFERROR(F23/$F$66,"")
B24: =IFERROR(VLOOKUP(H24,[1]SEMIELABORADOS!$A$2:$M$6000,2,0),"") | C24: =+A24 -> 0 | D24: =IFERROR(VLOOKUP(H24,[1]SEMIELABORADOS!$A$2:$M$6000,6,0),"") | E24: =IFERROR(VLOOKUP(H24,[1]SEMIELABORADOS!$A$2:$H$65536,8,0),"") | F24: =IFERROR(E24*C24,"") | G24: =IFERROR(F24/$F$66,"")
A26: UNIDADES | B26: EMPAQUE | C26: UNIDADES | D26: UND MEDIDA | E26: COSTO UNITARIO | F26: TOTAL COSTO | G26: % PREC. DEFINIDO | H26: CODIGOS
A27: 18 | B27: =IFERROR(VLOOKUP(H27,'[1]Consolidado MP Planta'!$A$2:$M$823,3,0),"") -> PAPEL ENCERADO 10X10 (CAJA) | C27: =+A27 -> 18 | D27: =IFERROR(VLOOKUP(H27,'[1]Consolidado MP Planta'!$A$2:$M$823,13,0),"") -> Und | E27: 14.2 | F27: =IFERROR(C27*E27,"") -> 255.6 | G27: =IFERROR(F27/$F$66,"") -> 0.019673634 | H27: 1950772
B28: =IFERROR(VLOOKUP(H28,'[1]Consolidado MP Planta'!$A$2:$M$823,3,0),"") | C28: =+A28 -> 0 | D28: =IFERROR(VLOOKUP(H28,'[1]Consolidado MP Planta'!$A$2:$M$823,13,0),"") | E28: =IFERROR(VLOOKUP(H28,'[1]Consolidado MP Planta'!$A$2:$M$823,12,0),"") | F28: =IFERROR(C28*E28,"") | G28: =IFERROR(F28/$F$66,"")
B29: =IFERROR(VLOOKUP(H29,'[1]Consolidado MP Planta'!$A$2:$M$823,3,0),"") | C29: =+A29 -> 0 | D29: =IFERROR(VLOOKUP(H29,'[1]Consolidado MP Planta'!$A$2:$M$823,13,0),"") | E29: =IFERROR(VLOOKUP(H29,'[1]Consolidado MP Planta'!$A$2:$M$823,12,0),"") | F29: =IFERROR(C29*E29,"") | G29: =IFERROR(F29/$F$66,"")
B30: =IFERROR(VLOOKUP(H30,'[1]Consolidado MP Planta'!$A$2:$M$823,3,0),"") | C30: =+A30 -> 0 | D30: =IFERROR(VLOOKUP(H30,'[1]Consolidado MP Planta'!$A$2:$M$823,13,0),"") | E30: =IFERROR(VLOOKUP(H30,'[1]Consolidado MP Planta'!$A$2:$M$823,12,0),"") | F30: =IFERROR(C30*E30,"") | G30: =IFERROR(F30/$F$66,"")
B31: =IFERROR(VLOOKUP(H31,'[1]Consolidado MP Planta'!$A$2:$M$823,3,0),"") | C31: =+A31 -> 0 | D31: =IFERROR(VLOOKUP(H31,'[1]Consolidado MP Planta'!$A$2:$M$823,13,0),"") | E31: =IFERROR(VLOOKUP(H31,'[1]Consolidado MP Planta'!$A$2:$M$823,12,0),"") | F31: =IFERROR(C31*E31,"") | G31: =IFERROR(F31/$F$66,"")
B32: =IFERROR(VLOOKUP(H32,'[1]Consolidado MP Planta'!$A$2:$M$823,3,0),"") | C32: =+A32 -> 0 | D32: =IFERROR(VLOOKUP(H32,'[1]Consolidado MP Planta'!$A$2:$M$823,13,0),"") | E32: =IFERROR(VLOOKUP(H32,'[1]Consolidado MP Planta'!$A$2:$M$823,12,0),"") | F32: =IFERROR(C32*E32,"") | G32: =IFERROR(F32/$F$66,"")
A34: UNIDADES | B34: EMPAQUE SEMIELABORADOS | C34: UNIDADES | D34: UND MEDIDA | E34: COSTO UNITARIO | F34: TOTAL COSTO | G34: % PREC. DEFINIDO | H34: CODIGOS
A35: =+A17 -> 5040 | B35: BATIDO TURRON DE CHOCOLATE Y PECANAS | C35: =+A35 -> 5040 | D35: Gramos | E35: =+'Costo Batido'!E76 -> 0.03041214 | F35: =IFERROR(E35*C35,"") -> 153.27718 | G35: =IFERROR(F35/$F$66,"") -> 0.011797806 | H35: NUEVO
A36: =+A18 -> 144 | B36: =IFERROR(VLOOKUP(H36,[1]SEMIELABORADOS!$A$2:$M$6000,2,0),"") -> MEZCLA P/ENGRASE MOLDES KILO | C36: =+A36 -> 144 | D36: =IFERROR(VLOOKUP(H36,[1]SEMIELABORADOS!$A$2:$M$6000,6,0),"") -> Gramo | E36: =IFERROR(VLOOKUP(H36,[1]SEMIELABORADOS!$A$2:$M$65536,10,0),"") -> 0.021536385 | F36: =IFERROR(E36*C36,"") -> 3.1012394 | G36: =IFERROR(F36/$F$66,"") -> 0.00023870364 | H36: 902000019
A37: =+A19 -> 0 | B37: =IFERROR(VLOOKUP(H37,[1]SEMIELABORADOS!$A$2:$M$6000,2,0),"") | C37: =+A37 -> 0 | D37: =IFERROR(VLOOKUP(H37,[1]SEMIELABORADOS!$A$2:$M$6000,6,0),"") | E37: =IFERROR(VLOOKUP(H37,[1]SEMIELABORADOS!$A$2:$M$65536,10,0),"") | F37: =IFERROR(E37*C37,"") | G37: =IFERROR(F37/$F$66,"")
A38: =+A20 -> 0 | B38: =IFERROR(VLOOKUP(H38,[1]SEMIELABORADOS!$A$2:$M$6000,2,0),"") | C38: =+A38 -> 0 | D38: =IFERROR(VLOOKUP(H38,[1]SEMIELABORADOS!$A$2:$M$6000,6,0),"") | E38: =IFERROR(VLOOKUP(H38,[1]SEMIELABORADOS!$A$2:$M$65536,10,0),"") | F38: =IFERROR(E38*C38,"") | G38: =IFERROR(F38/$F$66,"")
A39: =+A21 -> 0 | B39: =IFERROR(VLOOKUP(H39,[1]SEMIELABORADOS!$A$2:$M$6000,2,0),"") | C39: =+A39 -> 0 | D39: =IFERROR(VLOOKUP(H39,[1]SEMIELABORADOS!$A$2:$M$6000,6,0),"") | E39: =IFERROR(VLOOKUP(H39,[1]SEMIELABORADOS!$A$2:$M$65536,10,0),"") | F39: =IFERROR(E39*C39,"") | G39: =IFERROR(F39/$F$66,"")
A40: =+A22 -> 0 | B40: =IFERROR(VLOOKUP(H40,[1]SEMIELABORADOS!$A$2:$M$6000,2,0),"") | C40: =+A40 -> 0 | D40: =IFERROR(VLOOKUP(H40,[1]SEMIELABORADOS!$A$2:$M$6000,6,0),"") | E40: =IFERROR(VLOOKUP(H40,[1]SEMIELABORADOS!$A$2:$M$65536,10,0),"") | F40: =IFERROR(E40*C40,"") | G40: =IFERROR(F40/$F$66,"")
A41: =+A23 -> 0 | B41: =IFERROR(VLOOKUP(H41,[1]SEMIELABORADOS!$A$2:$M$6000,2,0),"") | C41: =+A41 -> 0 | D41: =IFERROR(VLOOKUP(H41,[1]SEMIELABORADOS!$A$2:$M$6000,6,0),"") | E41: =IFERROR(VLOOKUP(H41,[1]SEMIELABORADOS!$A$2:$M$65536,10,0),"") | F41: =IFERROR(E41*C41,"") | G41: =IFERROR(F41/$F$66,"")
A43: UNIDADES | B43: MODI | C43: UNIDADES | D43: UND MEDIDA | E43: COSTO UNITARIO | F43: TOTAL COSTO | G43: % PREC. DEFINIDO | H43: CODIGOS
A44: =+A35 -> 5040 | B44: BATIDO TURRON DE CHOCOLATE Y PECANAS | C44: =+A44 -> 5040 | D44: Gramos | E44: =+'Costo Batido'!E74 -> 0.16820118 | F44: =IFERROR(E44*C44,"") -> 847.73394 | G44: =IFERROR(F44/$F$66,"") -> 0.065250421 | H44: NUEVO
A45: =+A36 -> 144 | B45: =IFERROR(VLOOKUP(H45,[1]SEMIELABORADOS!$A$2:$M$6000,2,0),"") -> MEZCLA P/ENGRASE MOLDES KILO | C45: =+A45 -> 144 | D45: =IFERROR(VLOOKUP(H45,[1]SEMIELABORADOS!$A$2:$M$6000,6,0),"") -> Gramo | E45: =IFERROR(VLOOKUP(H45,[1]SEMIELABORADOS!$A$2:$M$65536,12,0),"") -> 0.2512758 | F45: =IFERROR(E45*C45,"") -> 36.183715 | G45: =IFERROR(F45/$F$66,"") -> 0.0027850751 | H45: 902000019
...

Sheet Costo Chesse Cake Dulce Leche 
E1: Precio Local | F1: Costo MP | G1: Costo EM | H1: Costo MO
E2: =IFERROR(O68,"") -> 1434.0459 | F2: =IFERROR(H59,"") -> 1233.7689 | G2: =IFERROR(H60,"") -> 0.0030982906 | H2: =IFERROR(H62,"") -> 51.666667
A5: ESTRUCTURA DE COSTOS
F6: Fecha: | H6: =TODAY() -> 45663
A7: UNIDADES | B7: DESCRIPCION MAT.PRIMA | C7: UNIDADES | D7: UND MEDIDA | E7: COSTO UNITARIO | F7: TOTAL COSTO | G7: % PREC. DEFINIDO | H7: CODIGOS
A8: 1960 | B8: =IFERROR(VLOOKUP(H8,'[1]Consolidado MP Planta'!$A$2:$M$823,3,0),"") -> QUESO CREMA PANADERO (CAJA: 5 K) | C8: =+A8 -> 1960 | D8: =IFERROR(VLOOKUP(H8,'[1]Consolidado MP Planta'!$A$2:$M$823,13,0),"") -> Gramos | E8: 3.08 | F8: =IFERROR(C8*E8,"") -> 6036.8 | G8: =IFERROR(F8/$F$72,"") -> 0.25664427 | H8: 1730660
A9: 1560 | B9: =IFERROR(VLOOKUP(H9,'[1]Consolidado MP Planta'!$A$2:$M$823,3,0),"") -> LECHE CONDENSADA (PAQ:11 K) | C9: =+A9 -> 1560 | D9: =IFERROR(VLOOKUP(H9,'[1]Consolidado MP Planta'!$A$2:$M$823,13,0),"") -> Gramos | E9: 2.16 | F9: =IFERROR(C9*E9,"") -> 3369.6 | G9: =IFERROR(F9/$F$72,"") -> 0.1432528 | H9: 11400046
A10: 820 | B10: =IFERROR(VLOOKUP(H10,'[1]Consolidado MP Planta'!$A$2:$M$823,3,0),"") -> LECHE HOMOGENIZ TB 3.5% (CAJA:12 UND) | C10: =+A10 -> 820 | D10: =IFERROR(VLOOKUP(H10,'[1]Consolidado MP Planta'!$A$2:$M$823,13,0),"") -> Mililitros | E10: 0.76 | F10: =IFERROR(C10*E10,"") -> 623.2 | G10: =IFERROR(F10/$F$72,"") -> 0.026494287 | H10: 114000002
A11: 295 | B11: =IFERROR(VLOOKUP(H11,'[1]Consolidado MP Planta'!$A$2:$M$823,3,0),"") -> AZUCAR GLASS MOLIDA (PAQ: 4 K) | C11: =+A11 -> 295 | D11: =IFERROR(VLOOKUP(H11,'[1]Consolidado MP Planta'!$A$2:$M$823,13,0),"") -> Gramos | E11: 1.72 | F11: =IFERROR(C11*E11,"") -> 507.4 | G11: =IFERROR(F11/$F$72,"") -> 0.021571247 | H11: 101000073
A12: 100 | B12: =IFERROR(VLOOKUP(H12,'[1]Consolidado MP Planta'!$A$2:$M$823,3,0),"") -> GELATINA PURA (PAQ:1 k) | C12: =+A12 -> 100 | D12: =IFERROR(VLOOKUP(H12,'[1]Consolidado MP Planta'!$A$2:$M$823,13,0),"") -> Gramos | E12: 12.86 | F12: =IFERROR(C12*E12,"") -> 1286 | G12: =IFERROR(F12/$F$72,"") -> 0.0546721 | H12: 0510186
A13: 600 | B13: =IFERROR(VLOOKUP(H13,'[1]Consolidado MP Planta'!$A$2:$M$823,3,0),"") -> AGUA PLANTA | C13: =+A13 -> 600 | D13: =IFERROR(VLOOKUP(H13,'[1]Consolidado MP Planta'!$A$2:$M$823,13,0),"") -> Mililitros | E13: =IFERROR(VLOOKUP(H13,'[1]Consolidado MP Planta'!$A$2:$M$823,12,0),"") -> 0.1 | F13: =IFERROR(C13*E13,"") -> 60 | G13: =IFERROR(F13/$F$72,"") -> 0.0025507978 | H13: 10415
A14: 100 | B14: =IFERROR(VLOOKUP(H14,'[1]Consolidado MP Planta'!$A$2:$M$823,3,0),"") -> TRIPLE SEC | C14: =+A14 -> 100 | D14: =IFERROR(VLOOKUP(H14,'[1]Consolidado MP Planta'!$A$2:$M$823,13,0),"") -> Mililitros | E14: 7.47 | F14: =IFERROR(C14*E14,"") -> 747 | G14: =IFERROR(F14/$F$72,"") -> 0.031757433 | H14: 1010339
A15: 18 | B15: =IFERROR(VLOOKUP(H15,'[1]Consolidado MP Planta'!$A$2:$M$823,3,0),"") -> PRESERVANTE 1047S (PAQ=5 KILO) | C15: =+A15 -> 18 | D15: =IFERROR(VLOOKUP(H15,'[1]Consolidado MP Planta'!$A$2:$M$823,13,0),"") -> Gramos | E15: 7.88 | F15: =IFERROR(C15*E15,"") -> 141.84 | G15: =IFERROR(F15/$F$72,"") -> 0.006030086 | H15: 1212410
A16: 1850 | B16: MANJAR LECHE CONDENSADA (PAQ: 6 K) | C16: =+A16 -> 1850 | D16: Gramos | E16: 2.56 | F16: =IFERROR(C16*E16,"") -> 4736 | G16: =IFERROR(F16/$F$72,"") -> 0.20134297 | H16: 11400066
B17: =IFERROR(VLOOKUP(H17,'[1]Consolidado MP Planta'!$A$2:$M$823,3,0),"") | C17: =+A17 -> 0 | D17: =IFERROR(VLOOKUP(H17,'[1]Consolidado MP Planta'!$A$2:$M$823,13,0),"") | E17: =IFERROR(VLOOKUP(H17,'[1]Consolidado MP Planta'!$A$2:$M$823,12,0),"") | F17: =IFERROR(C17*E17,"") | G17: =IFERROR(F17/$F$72,"")
B18: =IFERROR(VLOOKUP(H18,'[1]Consolidado MP Planta'!$A$2:$M$823,3,0),"") | C18: =+A18 -> 0 | D18: =IFERROR(VLOOKUP(H18,'[1]Consolidado MP Planta'!$A$2:$M$823,13,0),"") | E18: =IFERROR(VLOOKUP(H18,'[1]Consolidado MP Planta'!$A$2:$M$823,12,0),"") | F18: =IFERROR(C18*E18,"") | G18: =IFERROR(F18/$F$72,"")
B19: =IFERROR(VLOOKUP(H19,'[1]Consolidado MP Planta'!$A$2:$M$823,3,0),"") | C19: =+A19 -> 0 | D19: =IFERROR(VLOOKUP(H19,'[1]Consolidado MP Planta'!$A$2:$M$823,13,0),"") | E19: =IFERROR(VLOOKUP(H19,'[1]Consolidado MP Planta'!$A$2:$M$823,12,0),"") | F19: =IFERROR(C19*E19,"") | G19: =IFERROR(F19/$F$72,"")
B20: =IFERROR(VLOOKUP(H20,'[1]Consolidado MP Planta'!$A$2:$M$823,3,0),"") | C20: =+A20 -> 0 | D20: =IFERROR(VLOOKUP(H20,'[1]Consolidado MP Planta'!$A$2:$M$823,13,0),"") | E20: =IFERROR(VLOOKUP(H20,'[1]Consolidado MP Planta'!$A$2:$M$823,12,0),"") | F20: =IFERROR(C20*E20,"") | G20: =IFERROR(F20/$F$72,"")
B21: =IFERROR(VLOOKUP(H21,'[2]ARTICULOS MP PLANTA'!$A$2:$G$589,2,0),"")
A22: UNIDADES | B22: MATERIA PRIMA SEMIELABORADOS | C22: UNIDADES | D22: UND MEDIDA | E22: COSTO UNITARIO | F22: TOTAL COSTO | G22: % PREC. DEFINIDO | H22: CODIGOS
A23: 2000 | B23: =IFERROR(VLOOKUP(H23,[1]SEMIELABORADOS!$A$2:$M$6000,2,0),"") -> CREMA CHANTILLY BLANCA SPOON-IND KILO | C23: =+A23 -> 2000 | D23: =IFERROR(VLOOKUP(H23,[1]SEMIELABORADOS!$A$2:$M$6000,6,0),"") -> Gramo | E23: 2.35 | F23: =IFERROR(E23*C23,"") -> 4700 | G23: =IFERROR(F23/$F$72,"") -> 0.19981249 | H23: 95717
B24: =IFERROR(VLOOKUP(H24,[1]SEMIELABORADOS!$A$2:$M$6000,2,0),"") | C24: =+A24 -> 0 | D24: =IFERROR(VLOOKUP(H24,[1]SEMIELABORADOS!$A$2:$M$6000,6,0),"") | E24: =IFERROR(VLOOKUP(H24,[1]SEMIELABORADOS!$A$2:$H$65536,8,0),"") | F24: =IFERROR(E24*C24,"") | G24: =IFERROR(F24/$F$72,"")
B25: =IFERROR(VLOOKUP(H25,[1]SEMIELABORADOS!$A$2:$M$6000,2,0),"") | C25: =+A25 -> 0 | D25: =IFERROR(VLOOKUP(H25,[1]SEMIELABORADOS!$A$2:$M$6000,6,0),"") | E25: =IFERROR(VLOOKUP(H25,[1]SEMIELABORADOS!$A$2:$H$65536,8,0),"") | F25: =IFERROR(E25*C25,"") | G25: =IFERROR(F25/$F$72,"")
B26: =IFERROR(VLOOKUP(H26,[1]SEMIELABORADOS!$A$2:$M$6000,2,0),"") | C26: =+A26 -> 0 | D26: =IFERROR(VLOOKUP(H26,[1]SEMIELABORADOS!$A$2:$M$6000,6,0),"") | E26: =IFERROR(VLOOKUP(H26,[1]SEMIELABORADOS!$A$2:$H$65536,8,0),"") | F26: =IFERROR(E26*C26,"") | G26: =IFERROR(F26/$F$72,"")
B27: =IFERROR(VLOOKUP(H27,[1]SEMIELABORADOS!$A$2:$M$6000,2,0),"") | C27: =+A27 -> 0 | D27: =IFERROR(VLOOKUP(H27,[1]SEMIELABORADOS!$A$2:$M$6000,6,0),"") | E27: =IFERROR(VLOOKUP(H27,[1]SEMIELABORADOS!$A$2:$H$65536,8,0),"") | F27: =IFERROR(E27*C27,"") | G27: =IFERROR(F27/$F$72,"")
B28: =IFERROR(VLOOKUP(H28,[1]SEMIELABORADOS!$A$2:$M$6000,2,0),"") | C28: =+A28 -> 0 | D28: =IFERROR(VLOOKUP(H28,[1]SEMIELABORADOS!$A$2:$M$6000,6,0),"") | E28: =IFERROR(VLOOKUP(H28,[1]SEMIELABORADOS!$A$2:$H$65536,8,0),"") | F28: =IFERROR(E28*C28,"") | G28: =IFERROR(F28/$F$72,"")
B29: =IFERROR(VLOOKUP(H29,[1]SEMIELABORADOS!$A$2:$M$6000,2,0),"") | C29: =+A29 -> 0 | D29: =IFERROR(VLOOKUP(H29,[1]SEMIELABORADOS!$A$2:$M$6000,6,0),"") | E29: =IFERROR(VLOOKUP(H29,[1]SEMIELABORADOS!$A$2:$H$65536,8,0),"") | F29: =IFERROR(E29*C29,"") | G29: =IFERROR(F29/$F$72,"")
B30: =IFERROR(VLOOKUP(H30,[1]SEMIELABORADOS!$A$2:$M$6000,2,0),"") | C30: =+A30 -> 0 | D30: =IFERROR(VLOOKUP(H30,[1]SEMIELABORADOS!$A$2:$M$6000,6,0),"") | E30: =IFERROR(VLOOKUP(H30,[1]SEMIELABORADOS!$A$2:$H$65536,8,0),"") | F30: =IFERROR(E30*C30,"") | G30: =IFERROR(F30/$F$72,"")
A32: UNIDADES | B32: EMPAQUE | C32: UNIDADES | D32: UND MEDIDA | E32: COSTO UNITARIO | F32: TOTAL COSTO | G32: % PREC. DEFINIDO | H32: CODIGOS
A33: 0 | B33: =IFERROR(VLOOKUP(H33,'[1]Consolidado MP Planta'!$A$2:$M$823,3,0),"") | C33: =+A33 -> 0 | D33: =IFERROR(VLOOKUP(H33,'[1]Consolidado MP Planta'!$A$2:$M$823,13,0),"") | E33: =IFERROR(VLOOKUP(H33,'[1]Consolidado MP Planta'!$A$2:$M$823,12,0),"") | F33: =IFERROR(C33*E33,"") | G33: =IFERROR(F33/$F$72,"")
B34: =IFERROR(VLOOKUP(H34,'[1]Consolidado MP Planta'!$A$2:$M$823,3,0),"") | C34: =+A34 -> 0 | D34: =IFERROR(VLOOKUP(H34,'[1]Consolidado MP Planta'!$A$2:$M$823,13,0),"") | E34: =IFERROR(VLOOKUP(H34,'[1]Consolidado MP Planta'!$A$2:$M$823,12,0),"") | F34: =IFERROR(C34*E34,"") | G34: =IFERROR(F34/$F$72,"")
B35: =IFERROR(VLOOKUP(H35,'[1]Consolidado MP Planta'!$A$2:$M$823,3,0),"") | C35: =+A35 -> 0 | D35: =IFERROR(VLOOKUP(H35,'[1]Consolidado MP Planta'!$A$2:$M$823,13,0),"") | E35: =IFERROR(VLOOKUP(H35,'[1]Consolidado MP Planta'!$A$2:$M$823,12,0),"") | F35: =IFERROR(C35*E35,"") | G35: =IFERROR(F35/$F$72,"")
B36: =IFERROR(VLOOKUP(H36,'[1]Consolidado MP Planta'!$A$2:$M$823,3,0),"") | C36: =+A36 -> 0 | D36: =IFERROR(VLOOKUP(H36,'[1]Consolidado MP Planta'!$A$2:$M$823,13,0),"") | E36: =IFERROR(VLOOKUP(H36,'[1]Consolidado MP Planta'!$A$2:$M$823,12,0),"") | F36: =IFERROR(C36*E36,"") | G36: =IFERROR(F36/$F$72,"")
B37: =IFERROR(VLOOKUP(H37,'[1]Consolidado MP Planta'!$A$2:$M$823,3,0),"") | C37: =+A37 -> 0 | D37: =IFERROR(VLOOKUP(H37,'[1]Consolidado MP Planta'!$A$2:$M$823,13,0),"") | E37: =IFERROR(VLOOKUP(H37,'[1]Consolidado MP Planta'!$A$2:$M$823,12,0),"") | F37: =IFERROR(C37*E37,"") | G37: =IFERROR(F37/$F$72,"")
B38: =IFERROR(VLOOKUP(H38,'[1]Consolidado MP Planta'!$A$2:$M$823,3,0),"") | C38: =+A38 -> 0 | D38: =IFERROR(VLOOKUP(H38,'[1]Consolidado MP Planta'!$A$2:$M$823,13,0),"") | E38: =IFERROR(VLOOKUP(H38,'[1]Consolidado MP Planta'!$A$2:$M$823,12,0),"") | F38: =IFERROR(C38*E38,"") | G38: =IFERROR(F38/$F$72,"")
A40: UNIDADES | B40: EMPAQUE SEMIELABORADOS | C40: UNIDADES | D40: UND MEDIDA | E40: COSTO UNITARIO | F40: TOTAL COSTO | G40: % PREC. DEFINIDO | H40: CODIGOS
A41: =+A23 -> 2000 | B41: =IFERROR(VLOOKUP(H41,[1]SEMIELABORADOS!$A$2:$M$6000,2,0),"") -> CREMA CHANTILLY BLANCA SPOON-IND KILO | C41: =+A41 -> 2000 | D41: =IFERROR(VLOOKUP(H41,[1]SEMIELABORADOS!$A$2:$M$6000,6,0),"") -> Gramo | E41: =IFERROR(VLOOKUP(H41,[1]SEMIELABORADOS!$A$2:$M$65536,10,0),"") -> 2.7884615e-05 | F41: =IFERROR(E41*C41,"") -> 0.055769231 | G41: =IFERROR(F41/$F$72,"") -> 2.3709339e-06 | H41: 95717
A42: =+A24 -> 0 | B42: =IFERROR(VLOOKUP(H42,[1]SEMIELABORADOS!$A$2:$M$6000,2,0),"") | C42: =+A42 -> 0 | D42: =IFERROR(VLOOKUP(H42,[1]SEMIELABORADOS!$A$2:$M$6000,6,0),"") | E42: =IFERROR(VLOOKUP(H42,[1]SEMIELABORADOS!$A$2:$M$65536,10,0),"") | F42: =IFERROR(E42*C42,"") | G42: =IFERROR(F42/$F$72,"")
A43: =+A25 -> 0 | B43: =IFERROR(VLOOKUP(H43,[1]SEMIELABORADOS!$A$2:$M$6000,2,0),"") | C43: =+A43 -> 0 | D43: =IFERROR(VLOOKUP(H43,[1]SEMIELABORADOS!$A$2:$M$6000,6,0),"") | E43: =IFERROR(VLOOKUP(H43,[1]SEMIELABORADOS!$A$2:$M$65536,10,0),"") | F43: =IFERROR(E43*C43,"") | G43: =IFERROR(F43/$F$72,"")
A44: =+A26 -> 0 | B44: =IFERROR(VLOOKUP(H44,[1]SEMIELABORADOS!$A$2:$M$6000,2,0),"") | C44: =+A44 -> 0 | D44: =IFERROR(VLOOKUP(H44,[1]SEMIELABORADOS!$A$2:$M$6000,6,0),"") | E44: =IFERROR(VLOOKUP(H44,[1]SEMIELABORADOS!$A$2:$M$65536,10,0),"") | F44: =IFERROR(E44*C44,"") | G44: =IFERROR(F44/$F$72,"")
...

Sheet Relleno Suspiro Limeño
B1: SERVICIOS DE PASTELERIA S.A. | G1: CÓDIGO:
B2: ESPECIFICACION DE RECETA | G2: REVISIÓN:
B3: 902000170 Relleno Suspiro Limeño | G3: FECHA DE APROBACIÓN:
B4: Elaborado | C4: Maria Jose Rodriguez, Chef
B5: Aprobado | C5: Esteban Cartin, Gerente de Manufactura
A6: # Código | B6: Descripción del ingrediente | C6: Marca | D6: Unidad Internacional | F6: Unidad
D7: Cantidad | E7: Unidad medida | F7: Cantidad
A8: 1110414 | B8: LECHE EVAPORADA (UND: 1 L) | C8: Nestle | D8: 400 | E8: g
A9: 11400046 | B9: LECHE CONDENSADA (PAQ:11 K) | C9: Nestle | D9: 400 | E9: g
A10: 1210443 | B10: YEMA DE HUEVO PASTEURIZADA (CAJA:2 Kg) | C10: Innovo | D10: 80 | E10: g
A11: 0510143 | B11: GLUCOSA | C11: Nuevo | D11: 10 | E11: g
A12: 510215 | B12: ALMIDON MODIFICADO (SACO:25 K) | C12: Nuevo | D12: 10 | E12: g
A13: 1212412 | B13: PRESERVANTE 1017S (PAQ=5 KILO) | C13: Mayca | D13: =0.8*2 -> 1.6 | E13: g
A14: 10415 | B14: AGUA POTABLE | C14: FAS | D14: 30 | E14: g
C17: Cantidad | D17: Unidad
A18: PESO TOTAL OBTENIDO | C18: 800 | D18: g | E18: Tiempo de Horneo
A19: TIEMPO TOTAL DE PREPARACION | C19: 15 | D19: Min. | E19: Horno: | I19: =+C19/C18 -> 0.01875 | J19: =+I19*1000 -> 18.75
A20: CANTIDAD DE PORCIONES OBTENIDAS | C20: 1 | D20: Und. | E20: Temperatura de Horneo
A21: PESO DE CADA PORCIÓN | C21: =C18 -> 800 | D21: g | E21: Otros:
A22: MERMA | C22: 130 | D22: g
A23: PROCEDIMIENTO DE PREPARACION DE LA RECETA
A24: 1.- Colocar en una olla la leche condensada y la evaporada y cocinar moviendo constantemete por 10 minutos.
A25: 2,- Una vez pasados los 10 minutos, agregar el almidon disuelto en el agua junto con el preservante, mezclar constantemente.
A26: 3,- Apagar el fuego y agregar las yemas temperadas y la glucosa, mezclar y retirar del fuego.
A29: CONTROL DE CAMBIOS

Sheet Costo Crema Vino tinto
E1: Precio Local | F1: Costo MP | G1: Costo EM | H1: Costo MO
E2: =IFERROR(O62,"") -> 74808.006 | F2: =IFERROR(H53,"") -> 63989.08 | G2: =IFERROR(H54,"") -> 0.58 | H2: =IFERROR(H56,"") -> 580
A5: ESTRUCTURA DE COSTOS
F6: Fecha: | H6: =TODAY() -> 45663
A7: UNIDADES | B7: DESCRIPCION MAT.PRIMA | C7: UNIDADES | D7: UND MEDIDA | E7: COSTO UNITARIO | F7: TOTAL COSTO | G7: % PREC. DEFINIDO | H7: CODIGOS
A8: 16000 | B8: CREMA AMBIENTE | C8: =+A8 -> 16000 | D8: Gramos | E8: 3.61 | F8: =IFERROR(C8*E8,"") -> 57760 | G8: =IFERROR(F8/$F$66,"") -> 0.87715246 | H8: Nuevo
A9: 2100 | B9: VINO TINTO TORO | C9: =+A9 -> 2100 | D9: Mililitros | E9: 2.8 | F9: =IFERROR(C9*E9,"") -> 5880 | G9: =IFERROR(F9/$F$66,"") -> 0.089294607 | H9: 102000063
A10: 36 | B10: =IFERROR(VLOOKUP(H10,'[1]Consolidado MP Planta'!$A$2:$M$823,3,0),"") -> PRESERVANTE 1017S (PAQ=5 KILO) | C10: =+A10 -> 36 | D10: =IFERROR(VLOOKUP(H10,'[1]Consolidado MP Planta'!$A$2:$M$823,13,0),"") -> Gramos | E10: 9.28 | F10: =IFERROR(C10*E10,"") -> 334.08 | G10: =IFERROR(F10/$F$66,"") -> 0.0050733915 | H10: 1212412
A11: 150 | B11: =IFERROR(VLOOKUP(H11,'[1]Consolidado MP Planta'!$A$2:$M$823,3,0),"") -> AGUA PLANTA | C11: =+A11 -> 150 | D11: =IFERROR(VLOOKUP(H11,'[1]Consolidado MP Planta'!$A$2:$M$823,13,0),"") -> Mililitros | E11: =IFERROR(VLOOKUP(H11,'[1]Consolidado MP Planta'!$A$2:$M$823,12,0),"") -> 0.1 | F11: =IFERROR(C11*E11,"") -> 15 | G11: =IFERROR(F11/$F$66,"") -> 0.00022779236 | H11: 10415
B12: =IFERROR(VLOOKUP(H12,'[1]Consolidado MP Planta'!$A$2:$M$823,3,0),"") | C12: =+A12 -> 0 | D12: =IFERROR(VLOOKUP(H12,'[1]Consolidado MP Planta'!$A$2:$M$823,13,0),"") | E12: =IFERROR(VLOOKUP(H12,'[1]Consolidado MP Planta'!$A$2:$M$823,12,0),"") | F12: =IFERROR(C12*E12,"") | G12: =IFERROR(F12/$F$66,"")
B13: =IFERROR(VLOOKUP(H13,'[1]Consolidado MP Planta'!$A$2:$M$823,3,0),"") | C13: =+A13 -> 0 | D13: =IFERROR(VLOOKUP(H13,'[1]Consolidado MP Planta'!$A$2:$M$823,13,0),"") | E13: =IFERROR(VLOOKUP(H13,'[1]Consolidado MP Planta'!$A$2:$M$823,12,0),"") | F13: =IFERROR(C13*E13,"") | G13: =IFERROR(F13/$F$66,"")
B14: =IFERROR(VLOOKUP(H14,'[1]Consolidado MP Planta'!$A$2:$M$823,3,0),"") | C14: =+A14 -> 0 | D14: =IFERROR(VLOOKUP(H14,'[1]Consolidado MP Planta'!$A$2:$M$823,13,0),"") | E14: =IFERROR(VLOOKUP(H14,'[1]Consolidado MP Planta'!$A$2:$M$823,12,0),"") | F14: =IFERROR(C14*E14,"") | G14: =IFERROR(F14/$F$66,"")
B15: =IFERROR(VLOOKUP(H15,'[2]ARTICULOS MP PLANTA'!$A$2:$G$589,2,0),"")
A16: UNIDADES | B16: MATERIA PRIMA SEMIELABORADOS | C16: UNIDADES | D16: UND MEDIDA | E16: COSTO UNITARIO | F16: TOTAL COSTO | G16: % PREC. DEFINIDO | H16: CODIGOS
B17: =IFERROR(VLOOKUP(H17,[1]SEMIELABORADOS!$A$2:$M$6000,2,0),"") | C17: =+A17 -> 0 | D17: =IFERROR(VLOOKUP(H17,[1]SEMIELABORADOS!$A$2:$M$6000,6,0),"") | E17: =IFERROR(VLOOKUP(H17,[1]SEMIELABORADOS!$A$2:$H$65536,8,0),"") | F17: =IFERROR(E17*C17,"") | G17: =IFERROR(F17/$F$66,"")
B18: =IFERROR(VLOOKUP(H18,[1]SEMIELABORADOS!$A$2:$M$6000,2,0),"") | C18: =+A18 -> 0 | D18: =IFERROR(VLOOKUP(H18,[1]SEMIELABORADOS!$A$2:$M$6000,6,0),"") | E18: =IFERROR(VLOOKUP(H18,[1]SEMIELABORADOS!$A$2:$H$65536,8,0),"") | F18: =IFERROR(E18*C18,"") | G18: =IFERROR(F18/$F$66,"")
B19: =IFERROR(VLOOKUP(H19,[1]SEMIELABORADOS!$A$2:$M$6000,2,0),"") | C19: =+A19 -> 0 | D19: =IFERROR(VLOOKUP(H19,[1]SEMIELABORADOS!$A$2:$M$6000,6,0),"") | E19: =IFERROR(VLOOKUP(H19,[1]SEMIELABORADOS!$A$2:$H$65536,8,0),"") | F19: =IFERROR(E19*C19,"") | G19: =IFERROR(F19/$F$66,"")
B20: =IFERROR(VLOOKUP(H20,[1]SEMIELABORADOS!$A$2:$M$6000,2,0),"") | C20: =+A20 -> 0 | D20: =IFERROR(VLOOKUP(H20,[1]SEMIELABORADOS!$A$2:$M$6000,6,0),"") | E20: =IFERROR(VLOOKUP(H20,[1]SEMIELABORADOS!$A$2:$H$65536,8,0),"") | F20: =IFERROR(E20*C20,"") | G20: =IFERROR(F20/$F$66,"")
B21: =IFERROR(VLOOKUP(H21,[1]SEMIELABORADOS!$A$2:$M$6000,2,0),"") | C21: =+A21 -> 0 | D21: =IFERROR(VLOOKUP(H21,[1]SEMIELABORADOS!$A$2:$M$6000,6,0),"") | E21: =IFERROR(VLOOKUP(H21,[1]SEMIELABORADOS!$A$2:$H$65536,8,0),"") | F21: =IFERROR(E21*C21,"") | G21: =IFERROR(F21/$F$66,"")
B22: =IFERROR(VLOOKUP(H22,[1]SEMIELABORADOS!$A$2:$M$6000,2,0),"") | C22: =+A22 -> 0 | D22: =IFERROR(VLOOKUP(H22,[1]SEMIELABORADOS!$A$2:$M$6000,6,0),"") | E22: =IFERROR(VLOOKUP(H22,[1]SEMIELABORADOS!$A$2:$H$65536,8,0),"") | F22: =IFERROR(E22*C22,"") | G22: =IFERROR(F22/$F$66,"")
B23: =IFERROR(VLOOKUP(H23,[1]SEMIELABORADOS!$A$2:$M$6000,2,0),"") | C23: =+A23 -> 0 | D23: =IFERROR(VLOOKUP(H23,[1]SEMIELABORADOS!$A$2:$M$6000,6,0),"") | E23: =IFERROR(VLOOKUP(H23,[1]SEMIELABORADOS!$A$2:$H$65536,8,0),"") | F23: =IFERROR(E23*C23,"") | G23: =IFERROR(F23/$F$66,"")
B24: =IFERROR(VLOOKUP(H24,[1]SEMIELABORADOS!$A$2:$M$6000,2,0),"") | C24: =+A24 -> 0 | D24: =IFERROR(VLOOKUP(H24,[1]SEMIELABORADOS!$A$2:$M$6000,6,0),"") | E24: =IFERROR(VLOOKUP(H24,[1]SEMIELABORADOS!$A$2:$H$65536,8,0),"") | F24: =IFERROR(E24*C24,"") | G24: =IFERROR(F24/$F$66,"")
A26: UNIDADES | B26: EMPAQUE | C26: UNIDADES | D26: UND MEDIDA | E26: COSTO UNITARIO | F26: TOTAL COSTO | G26: % PREC. DEFINIDO | H26: CODIGOS
A27: 1 | B27: =IFERROR(VLOOKUP(H27,'[1]Consolidado MP Planta'!$A$2:$M$823,3,0),"") -> ETIQ.BLANCA 1 1/4 * 3/4 (UND) | C27: =+A27 -> 1 | D27: =IFERROR(VLOOKUP(H27,'[1]Consolidado MP Planta'!$A$2:$M$823,13,0),"") -> Und | E27: =IFERROR(VLOOKUP(H27,'[1]Consolidado MP Planta'!$A$2:$M$823,12,0),"") -> 0.58 | F27: =IFERROR(C27*E27,"") -> 0.58 | G27: =IFERROR(F27/$F$66,"") -> 8.8079714e-06 | H27: 0702069
B28: =IFERROR(VLOOKUP(H28,'[1]Consolidado MP Planta'!$A$2:$M$823,3,0),"") | C28: =+A28 -> 0 | D28: =IFERROR(VLOOKUP(H28,'[1]Consolidado MP Planta'!$A$2:$M$823,13,0),"") | E28: =IFERROR(VLOOKUP(H28,'[1]Consolidado MP Planta'!$A$2:$M$823,12,0),"") | F28: =IFERROR(C28*E28,"") | G28: =IFERROR(F28/$F$66,"")
B29: =IFERROR(VLOOKUP(H29,'[1]Consolidado MP Planta'!$A$2:$M$823,3,0),"") | C29: =+A29 -> 0 | D29: =IFERROR(VLOOKUP(H29,'[1]Consolidado MP Planta'!$A$2:$M$823,13,0),"") | E29: =IFERROR(VLOOKUP(H29,'[1]Consolidado MP Planta'!$A$2:$M$823,12,0),"") | F29: =IFERROR(C29*E29,"") | G29: =IFERROR(F29/$F$66,"")
B30: =IFERROR(VLOOKUP(H30,'[1]Consolidado MP Planta'!$A$2:$M$823,3,0),"") | C30: =+A30 -> 0 | D30: =IFERROR(VLOOKUP(H30,'[1]Consolidado MP Planta'!$A$2:$M$823,13,0),"") | E30: =IFERROR(VLOOKUP(H30,'[1]Consolidado MP Planta'!$A$2:$M$823,12,0),"") | F30: =IFERROR(C30*E30,"") | G30: =IFERROR(F30/$F$66,"")
B31: =IFERROR(VLOOKUP(H31,'[1]Consolidado MP Planta'!$A$2:$M$823,3,0),"") | C31: =+A31 -> 0 | D31: =IFERROR(VLOOKUP(H31,'[1]Consolidado MP Planta'!$A$2:$M$823,13,0),"") | E31: =IFERROR(VLOOKUP(H31,'[1]Consolidado MP Planta'!$A$2:$M$823,12,0),"") | F31: =IFERROR(C31*E31,"") | G31: =IFERROR(F31/$F$66,"")
B32: =IFERROR(VLOOKUP(H32,'[1]Consolidado MP Planta'!$A$2:$M$823,3,0),"") | C32: =+A32 -> 0 | D32: =IFERROR(VLOOKUP(H32,'[1]Consolidado MP Planta'!$A$2:$M$823,13,0),"") | E32: =IFERROR(VLOOKUP(H32,'[1]Consolidado MP Planta'!$A$2:$M$823,12,0),"") | F32: =IFERROR(C32*E32,"") | G32: =IFERROR(F32/$F$66,"")
A34: UNIDADES | B34: EMPAQUE SEMIELABORADOS | C34: UNIDADES | D34: UND MEDIDA | E34: COSTO UNITARIO | F34: TOTAL COSTO | G34: % PREC. DEFINIDO | H34: CODIGOS
A35: =+A17 -> 0 | B35: =IFERROR(VLOOKUP(H35,[1]SEMIELABORADOS!$A$2:$M$6000,2,0),"") | C35: =+A35 -> 0 | D35: =IFERROR(VLOOKUP(H35,[1]SEMIELABORADOS!$A$2:$M$6000,6,0),"") | E35: =IFERROR(VLOOKUP(H35,[1]SEMIELABORADOS!$A$2:$M$65536,10,0),"") | F35: =IFERROR(E35*C35,"") | G35: =IFERROR(F35/$F$66,"")
A36: =+A18 -> 0 | B36: =IFERROR(VLOOKUP(H36,[1]SEMIELABORADOS!$A$2:$M$6000,2,0),"") | C36: =+A36 -> 0 | D36: =IFERROR(VLOOKUP(H36,[1]SEMIELABORADOS!$A$2:$M$6000,6,0),"") | E36: =IFERROR(VLOOKUP(H36,[1]SEMIELABORADOS!$A$2:$M$65536,10,0),"") | F36: =IFERROR(E36*C36,"") | G36: =IFERROR(F36/$F$66,"")
A37: =+A19 -> 0 | B37: =IFERROR(VLOOKUP(H37,[1]SEMIELABORADOS!$A$2:$M$6000,2,0),"") | C37: =+A37 -> 0 | D37: =IFERROR(VLOOKUP(H37,[1]SEMIELABORADOS!$A$2:$M$6000,6,0),"") | E37: =IFERROR(VLOOKUP(H37,[1]SEMIELABORADOS!$A$2:$M$65536,10,0),"") | F37: =IFERROR(E37*C37,"") | G37: =IFERROR(F37/$F$66,"")
A38: =+A20 -> 0 | B38: =IFERROR(VLOOKUP(H38,[1]SEMIELABORADOS!$A$2:$M$6000,2,0),"") | C38: =+A38 -> 0 | D38: =IFERROR(VLOOKUP(H38,[1]SEMIELABORADOS!$A$2:$M$6000,6,0),"") | E38: =IFERROR(VLOOKUP(H38,[1]SEMIELABORADOS!$A$2:$M$65536,10,0),"") | F38: =IFERROR(E38*C38,"") | G38: =IFERROR(F38/$F$66,"")
A39: =+A21 -> 0 | B39: =IFERROR(VLOOKUP(H39,[1]SEMIELABORADOS!$A$2:$M$6000,2,0),"") | C39: =+A39 -> 0 | D39: =IFERROR(VLOOKUP(H39,[1]SEMIELABORADOS!$A$2:$M$6000,6,0),"") | E39: =IFERROR(VLOOKUP(H39,[1]SEMIELABORADOS!$A$2:$M$65536,10,0),"") | F39: =IFERROR(E39*C39,"") | G39: =IFERROR(F39/$F$66,"")
A40: =+A22 -> 0 | B40: =IFERROR(VLOOKUP(H40,[1]SEMIELABORADOS!$A$2:$M$6000,2,0),"") | C40: =+A40 -> 0 | D40: =IFERROR(VLOOKUP(H40,[1]SEMIELABORADOS!$A$2:$M$6000,6,0),"") | E40: =IFERROR(VLOOKUP(H40,[1]SEMIELABORADOS!$A$2:$M$65536,10,0),"") | F40: =IFERROR(E40*C40,"") | G40: =IFERROR(F40/$F$66,"")
A41: =+A23 -> 0 | B41: =IFERROR(VLOOKUP(H41,[1]SEMIELABORADOS!$A$2:$M$6000,2,0),"") | C41: =+A41 -> 0 | D41: =IFERROR(VLOOKUP(H41,[1]SEMIELABORADOS!$A$2:$M$6000,6,0),"") | E41: =IFERROR(VLOOKUP(H41,[1]SEMIELABORADOS!$A$2:$M$65536,10,0),"") | F41: =IFERROR(E41*C41,"") | G41: =IFERROR(F41/$F$66,"")
A43: UNIDADES | B43: MODI | C43: UNIDADES | D43: UND MEDIDA | E43: COSTO UNITARIO | F43: TOTAL COSTO | G43: % PREC. DEFINIDO | H43: CODIGOS
A44: =+A35 -> 0 | B44: =IFERROR(VLOOKUP(H44,[1]SEMIELABORADOS!$A$2:$M$6000,2,0),"") | C44: =+A44 -> 0 | D44: =IFERROR(VLOOKUP(H44,[1]SEMIELABORADOS!$A$2:$M$6000,6,0),"") | E44: =IFERROR(VLOOKUP(H44,[1]SEMIELABORADOS!$A$2:$M$65536,12,0),"") | F44: =IFERROR(E44*C44,"") | G44: =IFERROR(F44/$F$66,"")
A45: =+A36 -> 0 | B45: =IFERROR(VLOOKUP(H45,[1]SEMIELABORADOS!$A$2:$M$6000,2,0),"") | C45: =+A45 -> 0 | D45: =IFERROR(VLOOKUP(H45,[1]SEMIELABORADOS!$A$2:$M$6000,6,0),"") | E45: =IFERROR(VLOOKUP(H45,[1]SEMIELABORADOS!$A$2:$M$65536,12,0),"") | F45: =IFERROR(E45*C45,"") | G45: =IFERROR(F45/$F$66,"")
...

Sheet Costo Ensamble locales 
E1: Precio Local | F1: Costo MP | G1: Costo EM | H1: Costo MO
E2: =IFERROR(O62,"") -> 4432.7569 | F2: =IFERROR(H53,"") -> 2725.2158 | G2: =IFERROR(H54,"") -> 635.0644 | H2: =IFERROR(H56,"") -> 534.83188
A5: ESTRUCTURA DE COSTOS
F6: Fecha: | H6: =TODAY() -> 45663
A7: UNIDADES | B7: DESCRIPCION MAT.PRIMA | C7: UNIDADES | D7: UND MEDIDA | E7: COSTO UNITARIO | F7: TOTAL COSTO | G7: % PREC. DEFINIDO | H7: CODIGOS
A8: 10 | B8: =IFERROR(VLOOKUP(H8,'[1]Consolidado MP Planta'!$A$2:$M$823,3,0),"") -> ACEITE CAPULLO RBD (UND:17 L) | C8: =+A8 -> 10 | D8: =IFERROR(VLOOKUP(H8,'[1]Consolidado MP Planta'!$A$2:$M$823,13,0),"") -> Mililitros | E8: 1.37 | F8: =IFERROR(C8*E8,"") -> 13.7 | G8: =IFERROR(F8/$F$66,"") -> 0.0035856511 | H8: 10100050
A9: 60 | B9: =IFERROR(VLOOKUP(H9,'[1]Consolidado MP Planta'!$A$2:$M$823,3,0),"") -> PECANA ENTERA (CAJA:13.6 K) | C9: =+A9 -> 60 | D9: =IFERROR(VLOOKUP(H9,'[1]Consolidado MP Planta'!$A$2:$M$823,13,0),"") -> Gramos | E9: 9.28 | F9: =IFERROR(C9*E9,"") -> 556.8 | G9: =IFERROR(F9/$F$66,"") -> 0.14572924 | H9: 0510262
A10: 1 | B10: =IFERROR(VLOOKUP(H10,'[1]Consolidado MP Planta'!$A$2:$M$823,3,0),"") -> CANELA EN POLVO BADIA (UND: 1.82 K) | C10: =+A10 -> 1 | D10: =IFERROR(VLOOKUP(H10,'[1]Consolidado MP Planta'!$A$2:$M$823,13,0),"") -> Gramos | E10: 9.39 | F10: =IFERROR(C10*E10,"") -> 9.39 | G10: =IFERROR(F10/$F$66,"") -> 0.0024576105 | H10: 10100122
B11: =IFERROR(VLOOKUP(H11,'[1]Consolidado MP Planta'!$A$2:$M$823,3,0),"") | C11: =+A11 -> 0 | D11: =IFERROR(VLOOKUP(H11,'[1]Consolidado MP Planta'!$A$2:$M$823,13,0),"") | E11: =IFERROR(VLOOKUP(H11,'[1]Consolidado MP Planta'!$A$2:$M$823,12,0),"") | F11: =IFERROR(C11*E11,"") | G11: =IFERROR(F11/$F$66,"")
B12: =IFERROR(VLOOKUP(H12,'[1]Consolidado MP Planta'!$A$2:$M$823,3,0),"") | C12: =+A12 -> 0 | D12: =IFERROR(VLOOKUP(H12,'[1]Consolidado MP Planta'!$A$2:$M$823,13,0),"") | E12: =IFERROR(VLOOKUP(H12,'[1]Consolidado MP Planta'!$A$2:$M$823,12,0),"") | F12: =IFERROR(C12*E12,"") | G12: =IFERROR(F12/$F$66,"")
B13: =IFERROR(VLOOKUP(H13,'[1]Consolidado MP Planta'!$A$2:$M$823,3,0),"") | C13: =+A13 -> 0 | D13: =IFERROR(VLOOKUP(H13,'[1]Consolidado MP Planta'!$A$2:$M$823,13,0),"") | E13: =IFERROR(VLOOKUP(H13,'[1]Consolidado MP Planta'!$A$2:$M$823,12,0),"") | F13: =IFERROR(C13*E13,"") | G13: =IFERROR(F13/$F$66,"")
B14: =IFERROR(VLOOKUP(H14,'[1]Consolidado MP Planta'!$A$2:$M$823,3,0),"") | C14: =+A14 -> 0 | D14: =IFERROR(VLOOKUP(H14,'[1]Consolidado MP Planta'!$A$2:$M$823,13,0),"") | E14: =IFERROR(VLOOKUP(H14,'[1]Consolidado MP Planta'!$A$2:$M$823,12,0),"") | F14: =IFERROR(C14*E14,"") | G14: =IFERROR(F14/$F$66,"")
B15: =IFERROR(VLOOKUP(H15,'[2]ARTICULOS MP PLANTA'!$A$2:$G$589,2,0),"")
A16: UNIDADES | B16: MATERIA PRIMA SEMIELABORADOS | C16: UNIDADES | D16: UND MEDIDA | E16: COSTO UNITARIO | F16: TOTAL COSTO | G16: % PREC. DEFINIDO | H16: CODIGOS
A17: 1 | B17: TURRON DE CHOCOLATE Y PECANAS | C17: =+A17 -> 1 | D17: UND | E17: =+'Costo Rosquete '!H53 -> 659.91442 | F17: =IFERROR(E17*C17,"") -> 659.91442 | G17: =IFERROR(F17/$F$66,"") -> 0.172717 | H17: NUEVO
