Workbook

Sheet Costo Salsa Maracuya
E1: Precio Local | F1: Costo MP | G1: Costo EM | H1: Costo MO
E2: =IFERROR(O62,"") -> 1964.4909 | F2: =IFERROR(H53,"") -> 1387.8 | G2: =IFERROR(H54,"") -> 5 | H2: =IFERROR(H56,"") -> 312.2
A5: ESTRUCTURA DE COSTOS
F6: Fecha: | H6: =TODAY() -> 46034
A7: UNIDADES | B7: DESCRIPCION MAT.PRIMA | C7: UNIDADES | D7: UND MEDIDA | E7: COSTO UNITARIO | F7: TOTAL COSTO | G7: % PREC. DEFINIDO | H7: CODIGOS
A8: 360 | B8: Maracuya Congelada | C8: =+A8 -> 360 | D8: Gramos | E8: 3.61 | F8: =IFERROR(C8*E8,"") -> 1299.6 | G8: =IFERROR(F8/$F$66,"") -> 0.75184142 | H8: MP10423
B9: =IFERROR(VLOOKUP(H9,'[1]Consolidado MP Planta'!$A$2:$M$823,3,0),"") | C9: =+A9 -> 0 | D9: =IFERROR(VLOOKUP(H9,'[1]Consolidado MP Planta'!$A$2:$M$823,13,0),"") | E9: =IFERROR(VLOOKUP(H9,'[1]Consolidado MP Planta'!$A$2:$M$823,12,0),"") | F9: =IFERROR(C9*E9,"") | G9: =IFERROR(F9/$F$66,"")
B10: =IFERROR(VLOOKUP(H10,'[1]Consolidado MP Planta'!$A$2:$M$823,3,0),"") | C10: =+A10 -> 0 | D10: =IFERROR(VLOOKUP(H10,'[1]Consolidado MP Planta'!$A$2:$M$823,13,0),"") | E10: =IFERROR(VLOOKUP(H10,'[1]Consolidado MP Planta'!$A$2:$M$823,12,0),"") | F10: =IFERROR(C10*E10,"") | G10: =IFERROR(F10/$F$66,"")
B11: =IFERROR(VLOOKUP(H11,'[1]Consolidado MP Planta'!$A$2:$M$823,3,0),"") | C11: =+A11 -> 0 | D11: =IFERROR(VLOOKUP(H11,'[1]Consolidado MP Planta'!$A$2:$M$823,13,0),"") | E11: =IFERROR(VLOOKUP(H11,'[1]Consolidado MP Planta'!$A$2:$M$823,12,0),"") | F11: =IFERROR(C11*E11,"") | G11: =IFERROR(F11/$F$66,"")
B12: =IFERROR(VLOOKUP(H12,'[1]Consolidado MP Planta'!$A$2:$M$823,3,0),"") | C12: =+A12 -> 0 | D12: =IFERROR(VLOOKUP(H12,'[1]Consolidado MP Planta'!$A$2:$M$823,13,0),"") | E12: =IFERROR(VLOOKUP(H12,'[1]Consolidado MP Planta'!$A$2:$M$823,12,0),"") | F12: =IFERROR(C12*E12,"") | G12: =IFERROR(F12/$F$66,"")
B13: =IFERROR(VLOOKUP(H13,'[1]Consolidado MP Planta'!$A$2:$M$823,3,0),"") | C13: =+A13 -> 0 | D13: =IFERROR(VLOOKUP(H13,'[1]Consolidado MP Planta'!$A$2:$M$823,13,0),"") | E13: =IFERROR(VLOOKUP(H13,'[1]Consolidado MP Planta'!$A$2:$M$823,12,0),"") | F13: =IFERROR(C13*E13,"") | G13: =IFERROR(F13/$F$66,"")
B14: =IFERROR(VLOOKUP(H14,'[1]Consolidado MP Planta'!$A$2:$M$823,3,0),"") | C14: =+A14 -> 0 | D14: =IFERROR(VLOOKUP(H14,'[1]Consolidado MP Planta'!$A$2:$M$823,13,0),"") | E14: =IFERROR(VLOOKUP(H14,'[1]Consolidado MP Planta'!$A$2:$M$823,12,0),"") | F14: =IFERROR(C14*E14,"") | G14: =IFERROR(F14/$F$66,"")
B15: =IFERROR(VLOOKUP(H15,'[2]ARTICULOS MP PLANTA'!$A$2:$G$589,2,0),"")
A16: UNIDADES | B16: MATERIA PRIMA SEMIELABORADOS | C16: UNIDADES | D16: UND MEDIDA | E16: COSTO UNITARIO | F16: TOTAL COSTO | G16: % PREC. DEFINIDO | H16: CODIGOS
A17: 100 | B17: Empaque Azucar Industrial | C17: =+A17 -> 100 | D17: Gramos | E17: 0.47 | F17: =IFERROR(E17*C17,"") -> 47 | G17: =IFERROR(F17/$F$66,"") -> 0.027190325 | H17: SE00016
A18: 20 | B18: Empaque Almidon Modificado | C18: =+A18 -> 20 | D18: Gramos | E18: 2.06 | F18: =IFERROR(E18*C18,"") -> 41.2 | G18: =IFERROR(F18/$F$66,"") -> 0.023834923 | H18: SE00014
B19: =IFERROR(VLOOKUP(H19,[1]SEMIELABORADOS!$A$2:$M$6000,2,0),"") | C19: =+A19 -> 0 | D19: =IFERROR(VLOOKUP(H19,[1]SEMIELABORADOS!$A$2:$M$6000,6,0),"") | E19: =IFERROR(VLOOKUP(H19,[1]SEMIELABORADOS!$A$2:$H$65536,8,0),"") | F19: =IFERROR(E19*C19,"") | G19: =IFERROR(F19/$F$66,"")
B20: =IFERROR(VLOOKUP(H20,[1]SEMIELABORADOS!$A$2:$M$6000,2,0),"") | C20: =+A20 -> 0 | D20: =IFERROR(VLOOKUP(H20,[1]SEMIELABORADOS!$A$2:$M$6000,6,0),"") | E20: =IFERROR(VLOOKUP(H20,[1]SEMIELABORADOS!$A$2:$H$65536,8,0),"") | F20: =IFERROR(E20*C20,"") | G20: =IFERROR(F20/$F$66,"")
B21: =IFERROR(VLOOKUP(H21,[1]SEMIELABORADOS!$A$2:$M$6000,2,0),"") | C21: =+A21 -> 0 | D21: =IFERROR(VLOOKUP(H21,[1]SEMIELABORADOS!$A$2:$M$6000,6,0),"") | E21: =IFERROR(VLOOKUP(H21,[1]SEMIELABORADOS!$A$2:$H$65536,8,0),"") | F21: =IFERROR(E21*C21,"") | G21: =IFERROR(F21/$F$66,"")
B22: =IFERROR(VLOOKUP(H22,[1]SEMIELABORADOS!$A$2:$M$6000,2,0),"") | C22: =+A22 -> 0 | D22: =IFERROR(VLOOKUP(H22,[1]SEMIELABORADOS!$A$2:$M$6000,6,0),"") | E22: =IFERROR(VLOOKUP(H22,[1]SEMIELABORADOS!$A$2:$H$65536,8,0),"") | F22: =IFERROR(E22*C22,"") | G22: =IFERROR(F22/$F$66,"")
B23: =IFERROR(VLOOKUP(H23,[1]SEMIELABORADOS!$A$2:$M$6000,2,0),"") | C23: =+A23 -> 0 | D23: =IFERROR(VLOOKUP(H23,[1]SEMIELABORADOS!$A$2:$M$6000,6,0),"") | E23: =IFERROR(VLOOKUP(H23,[1]SEMIELABORADOS!$A$2:$H$65536,8,0),"") | F23: =IFERROR(E23*C23,"") | G23: =IFERROR(F23/$F$66,"")
B24: =IFERROR(VLOOKUP(H24,[1]SEMIELABORADOS!$A$2:$M$6000,2,0),"") | C24: =+A24 -> 0 | D24: =IFERROR(VLOOKUP(H24,[1]SEMIELABORADOS!$A$2:$M$6000,6,0),"") | E24: =IFERROR(VLOOKUP(H24,[1]SEMIELABORADOS!$A$2:$H$65536,8,0),"") | F24: =IFERROR(E24*C24,"") | G24: =IFERROR(F24/$F$66,"")
A26: UNIDADES | B26: EMPAQUE | C26: UNIDADES | D26: UND MEDIDA | E26: COSTO UNITARIO | F26: TOTAL COSTO | G26: % PREC. DEFINIDO | H26: CODIGOS
A27: 0 | B27: =IFERROR(VLOOKUP(H27,'[1]Consolidado MP Planta'!$A$2:$M$823,3,0),"") | C27: =+A27 -> 0 | D27: =IFERROR(VLOOKUP(H27,'[1]Consolidado MP Planta'!$A$2:$M$823,13,0),"") | E27: =IFERROR(VLOOKUP(H27,'[1]Consolidado MP Planta'!$A$2:$M$823,12,0),"") | F27: =IFERROR(C27*E27,"") | G27: =IFERROR(F27/$F$66,"")
B28: =IFERROR(VLOOKUP(H28,'[1]Consolidado MP Planta'!$A$2:$M$823,3,0),"") | C28: =+A28 -> 0 | D28: =IFERROR(VLOOKUP(H28,'[1]Consolidado MP Planta'!$A$2:$M$823,13,0),"") | E28: =IFERROR(VLOOKUP(H28,'[1]Consolidado MP Planta'!$A$2:$M$823,12,0),"") | F28: =IFERROR(C28*E28,"") | G28: =IFERROR(F28/$F$66,"")
B29: =IFERROR(VLOOKUP(H29,'[1]Consolidado MP Planta'!$A$2:$M$823,3,0),"") | C29: =+A29 -> 0 | D29: =IFERROR(VLOOKUP(H29,'[1]Consolidado MP Planta'!$A$2:$M$823,13,0),"") | E29: =IFERROR(VLOOKUP(H29,'[1]Consolidado MP Planta'!$A$2:$M$823,12,0),"") | F29: =IFERROR(C29*E29,"") | G29: =IFERROR(F29/$F$66,"")
B30: =IFERROR(VLOOKUP(H30,'[1]Consolidado MP Planta'!$A$2:$M$823,3,0),"") | C30: =+A30 -> 0 | D30: =IFERROR(VLOOKUP(H30,'[1]Consolidado MP Planta'!$A$2:$M$823,13,0),"") | E30: =IFERROR(VLOOKUP(H30,'[1]Consolidado MP Planta'!$A$2:$M$823,12,0),"") | F30: =IFERROR(C30*E30,"") | G30: =IFERROR(F30/$F$66,"")
B31: =IFERROR(VLOOKUP(H31,'[1]Consolidado MP Planta'!$A$2:$M$823,3,0),"") | C31: =+A31 -> 0 | D31: =IFERROR(VLOOKUP(H31,'[1]Consolidado MP Planta'!$A$2:$M$823,13,0),"") | E31: =IFERROR(VLOOKUP(H31,'[1]Consolidado MP Planta'!$A$2:$M$823,12,0),"") | F31: =IFERROR(C31*E31,"") | G31: =IFERROR(F31/$F$66,"")
B32: =IFERROR(VLOOKUP(H32,'[1]Consolidado MP Planta'!$A$2:$M$823,3,0),"") | C32: =+A32 -> 0 | D32: =IFERROR(VLOOKUP(H32,'[1]Consolidado MP Planta'!$A$2:$M$823,13,0),"") | E32: =IFERROR(VLOOKUP(H32,'[1]Consolidado MP Planta'!$A$2:$M$823,12,0),"") | F32: =IFERROR(C32*E32,"") | G32: =IFERROR(F32/$F$66,"")
A34: UNIDADES | B34: EMPAQUE SEMIELABORADOS | C34: UNIDADES | D34: UND MEDIDA | E34: COSTO UNITARIO | F34: TOTAL COSTO | G34: % PREC. DEFINIDO | H34: CODIGOS
A35: =+A17 -> 100 | B35: Empaque Azucar Industrial | C35: =+A35 -> 100 | D35: Gramo | E35: 0.05 | F35: =IFERROR(E35*C35,"") -> 5 | G35: =IFERROR(F35/$F$66,"") -> 0.0028925878
A36: =+A18 -> 20 | B36: Empaque Almidon Modificado | C36: =+A36 -> 20 | D36: Gramo | E36: 0 | F36: =IFERROR(E36*C36,"") -> 0 | G36: =IFERROR(F36/$F$66,"") -> 0
A37: =+A19 -> 0 | B37: =IFERROR(VLOOKUP(H37,[1]SEMIELABORADOS!$A$2:$M$6000,2,0),"") | C37: =+A37 -> 0 | D37: =IFERROR(VLOOKUP(H37,[1]SEMIELABORADOS!$A$2:$M$6000,6,0),"") | E37: =IFERROR(VLOOKUP(H37,[1]SEMIELABORADOS!$A$2:$M$65536,10,0),"") | F37: =IFERROR(E37*C37,"") | G37: =IFERROR(F37/$F$66,"")
A38: =+A20 -> 0 | B38: =IFERROR(VLOOKUP(H38,[1]SEMIELABORADOS!$A$2:$M$6000,2,0),"") | C38: =+A38 -> 0 | D38: =IFERROR(VLOOKUP(H38,[1]SEMIELABORADOS!$A$2:$M$6000,6,0),"") | E38: =IFERROR(VLOOKUP(H38,[1]SEMIELABORADOS!$A$2:$M$65536,10,0),"") | F38: =IFERROR(E38*C38,"") | G38: =IFERROR(F38/$F$66,"")
A39: =+A21 -> 0 | B39: =IFERROR(VLOOKUP(H39,[1]SEMIELABORADOS!$A$2:$M$6000,2,0),"") | C39: =+A39 -> 0 | D39: =IFERROR(VLOOKUP(H39,[1]SEMIELABORADOS!$A$2:$M$6000,6,0),"") | E39: =IFERROR(VLOOKUP(H39,[1]SEMIELABORADOS!$A$2:$M$65536,10,0),"") | F39: =IFERROR(E39*C39,"") | G39: =IFERROR(F39/$F$66,"")
A40: =+A22 -> 0 | B40: =IFERROR(VLOOKUP(H40,[1]SEMIELABORADOS!$A$2:$M$6000,2,0),"") | C40: =+A40 -> 0 | D40: =IFERROR(VLOOKUP(H40,[1]SEMIELABORADOS!$A$2:$M$6000,6,0),"") | E40: =IFERROR(VLOOKUP(H40,[1]SEMIELABORADOS!$A$2:$M$65536,10,0),"") | F40: =IFERROR(E40*C40,"") | G40: =IFERROR(F40/$F$66,"")
A41: =+A23 -> 0 | B41: =IFERROR(VLOOKUP(H41,[1]SEMIELABORADOS!$A$2:$M$6000,2,0),"") | C41: =+A41 -> 0 | D41: =IFERROR(VLOOKUP(H41,[1]SEMIELABORADOS!$A$2:$M$6000,6,0),"") | E41: =IFERROR(VLOOKUP(H41,[1]SEMIELABORADOS!$A$2:$M$65536,10,0),"") | F41: =IFERROR(E41*C41,"") | G41: =IFERROR(F41/$F$66,"")
A43: UNIDADES | B43: MODI | C43: UNIDADES | D43: UND MEDIDA | E43: COSTO UNITARIO | F43: TOTAL COSTO | G43: % PREC. DEFINIDO | H43: CODIGOS
A44: =+A35 -> 100 | B44: Empaque Azucar Industrial | C44: =+A44 -> 100 | D44: Gramo | E44: 0.04 | F44: =IFERROR(E44*C44,"") -> 4 | G44: =IFERROR(F44/$F$66,"") -> 0.0023140702
A45: =+A36 -> 20 | B45: Empaque Almidon Modificado | C45: =+A45 -> 20 | D45: Gramo | E45: 0.01 | F45: =IFERROR(E45*C45,"") -> 0.2 | G45: =IFERROR(F45/$F$66,"") -> 0.00011570351
...

Sheet Crema chantilly Blanca 
C1: SERVICIOS DE PASTELERIA S.A. | H1: CÓDIGO: | I1: ESP-RE-DES-018
C2: ESPECIFICACION DE RECETA | H2: REVISIÓN: | I2: 02
C3: Crema Blanca Spoon (20800g) SE00010 | H3: FECHA DE APROBACIÓN: | I3: 45613
C4: Elaborado | D4: Javier Tong, Chef
C5: Aprobado | D5: Esteban Cartin, Gte Manufactura
A6: AREA QUE PRODUCE: | D6: Decoración | G6: AREA QUE EMPACA: | I6: Decoracion
A7: # Código | B7: # Código Netsuite | C7: Descripción del ingrediente | D7: Marca | E7: Unidad Internacional | G7: Medida alternativa | I7: Costo - Referencia
E8: Cantidad | F8: Unidad medida | G8: Cantidad | H8: Unidad medida | I8: Colones
C9: Ensamble
A10: 310148 | B10: MP10047 | C10: BETTERCREME SUPREMO (UND:4 K) | D10: RICHS | E10: 12800 | F10: g
A11: 11400031 | B11: MP10048 | C11: CREMA PRESTIGE GRAND (UND:4 K) | D11: RICHS | E11: 3200 | F11: g
A12: 10415 | C12: AGUA POTABLE (PLANTA) | D12: AYA | E12: 800 | F12: g
A13: 1212410 | B13: MP10008 | C13: PRESERVANTE 1047S (PAQ=5 KILO) | D13: ASEAL | E13: 12 | F13: g
C20: Decoración
C29: Empaque
A30: 702123 | B30: EM10011 | C30: ETIQUETA BLANCA 2 5/8X1 15/16 (UND) | D30: Etiplas | E30: 1 | F30: ud
D40: Cantidad | E40: Unidad
A41: PESO TOTAL OBTENIDO | D41: 16597 | E41: g | F41: Tiempo de Horneo:
A42: TIEMPO TOTAL DE PREPARACION | D42: 17 | E42: min | F42: Horno:
A43: CANTIDAD DE PORCIONES OBTENIDAS | D43: 1 | E43: Tanda | F43: Temperatura de Horneo:
A44: PESO DE CADA PORCIÓN | D44: 16597 | E44: g | F44: Otros
A45: MERMA | D45: 215 | E45: g
A46: PROCEDIMIENTO DE PREPARACION DE LA RECETA
A47: 1.- Abrir los galones de crema y verter dentro de la top cream. (Temperatura 5° liquida )
A48: 2.- Disolver el preservante en el agua. Agregar a la top cream.
A49: 3.- Batir por 17 minutos. Una ves lista (Temperatura 18° batida) Colocar en una tina plastica, tapar.
A50: 4.- Etiquetar con nombre y fecha de vencimiento.
A51: 5.- Mantener en refrigeración hasta su uso.
A56: CONTROL DE CAMBIOS
A57: 2, Actualización tiempo de preparación y procedimiento

Sheet Fudge de chocolate 
C1: SERVICIOS DE PASTELERIA S.A. | H1: CÓDIGO: | I1: ESP-RE-COCS-053
C2: ESPECIFICACION DE RECETA | H2: REVISIÓN: | I2: 01
C3: SE00338 Fudge de chocolate Spoon | H3: FECHA DE APROBACIÓN: | I3: 45609
C4: Elaborado | D4: Javier Tong, Chef
C5: Aprobado | D5: Esteban Cartin, Gte Manufactura
A6: AREA QUE PRODUCE: | D6: Cocina | G6: AREA QUE EMPACA: | I6: Cocina
A7: # Código | B7: # Código Netsuite | C7: Descripción del ingrediente | D7: Marca | E7: Unidad Internacional | G7: Medida alternativa | I7: Costo - Referencia
E8: Cantidad | F8: Unidad medida | G8: Cantidad | H8: Unidad medida | I8: Colones
C9: Ensamble
A10: 11400066 | B10: MP10007 | C10: MANJAR LECHE CONDENSADA | D10: NESTLE | E10: 72000 | F10: g
A11: 1110414 | B11: MP10024 | C11: LECHE EVAPORADA (LITRO) | D11: NESTLE | E11: 13000 | F11: g
A12: 0512255 | B12: MP10146 | C12: COCOA DUTCH PROCESS | D12: CIA NACIONAL | E12: 1700 | F12: g
A13: 10200035 | B13: MP10476 | C13: CHOCOLATE JOHNNYS MARMITA (CAJA: 12K) | D13: JOHNNYS | E13: 1000 | F13: g
A14: 0310107 | B14: MP10022 | C14: LACTOCREMA GRANEL | D14: DOS PINOS | E14: 1320 | F14: g
A15: 1212410 | B15: MP10008 | C15: PRESERVANTE 1047 (PAQ=5 KILOS) | D15: ASEAL | E15: 270 | F15: g
C27: Decoración
C33: Empaque
D44: Cantidad | E44: Unidad
A45: PESO TOTAL OBTENIDO | D45: 80361 | E45: g | F45: Tiempo de Horneo:
A46: TIEMPO TOTAL DE PREPARACION | D46: 58 | E46: MIN | F46: Horno:
A47: CANTIDAD DE PORCIONES OBTENIDAS | D47: 1 | E47: TANDA | F47: Temperatura de Horneo:
A48: PESO DE CADA PORCIÓN | D48: 5000 | E48: GRAMOS | F48: Otros
A49: MERMA | D49: 8929 | E49: GRAMOS
A50: PROCEDIMIENTO DE PREPARACION DE LA RECETA
A51: 1. Licuar la cocoa, el preservante y el Johnnys con la leche. Colocar el licuado en olla y agregar el resto de ingredientes.
A52: 2. Encender la marmita en progrmacion Fudge.
A53: 3. Apagar y empezar el proceso de empaque
A62: CONTROL DE CAMBIOS

Sheet Empaque Fudge Chocolate
C1: SERVICIOS DE PASTELERIA S.A. | H1: CÓDIGO: | I1: ESP-RE-EMPS-047
C2: ESPECIFICACION DE RECETA | H2: REVISIÓN: | I2: 01
C3: SE00337 Empaque Fudge de chocolate Spoon | H3: FECHA DE APROBACIÓN: | I3: 45610
C4: Elaborado | D4: Javier Tong, Chef
C5: Aprobado | D5: Esteban Cartin, Gte Manufactura
A6: AREA QUE PRODUCE: | D6: Cocina | G6: AREA QUE EMPACA: | I6: Cocina
A7: # Código | B7: # Código Netsuite | C7: Descripción del ingrediente | D7: Marca | E7: Unidad Internacional | G7: Medida alternativa | I7: Costo - Referencia
E8: Cantidad | F8: Unidad medida | G8: Cantidad | H8: Unidad medida | I8: Colones
C9: Ensamble
A10: 90100354 | B10: SE00338 | C10: FUDGE DE CHOCOLATE SPOON | D10: FAS | E10: 5000 | F10: g
C18: Decoración
C24: Empaque
A25: 51600050 | B25: EM10307 | C25: BOLSA MARMITA 14 x 20 (KILO) | E25: 1 | F25: ud
A26: 702123 | B26: EM10011 | C26: ETIQUETA BLANCA 2 5/8X1 15/16 (UND) | D26: ETIPLAST | E26: 1 | F26: ud
D35: Cantidad | E35: Unidad
A36: PESO TOTAL OBTENIDO | D36: 5000 | E36: g | F36: Tiempo de Horneo:
A37: TIEMPO TOTAL DE PREPARACION | D37: 3 | E37: Minutos | F37: Horno:
A38: CANTIDAD DE PORCIONES OBTENIDAS | D38: 1 | E38: Bolsas | F38: Temperatura de Horneo:
A39: PESO DE CADA PORCIÓN | D39: 5000 | E39: g | F39: Otros
A40: MERMA | D40: 0 | E40: g
A41: PROCEDIMIENTO DE PREPARACION DE LA RECETA
A42: 1. Vaciar la marmita en bolsas de 5kg aprox.
A43: 2. Amarrar la bolsa y etiquetar
A51: CONTROL DE CAMBIOS

Sheet Costo Mousse Maracuya
E1: Precio Local | F1: Costo MP | G1: Costo EM | H1: Costo MO
E2: =IFERROR(O62,"") -> 3689.947 | F2: =IFERROR(H53,"") -> 3253.96 | G2: =IFERROR(H54,"") -> 2 | H2: =IFERROR(H56,"") -> 237
A5: ESTRUCTURA DE COSTOS
F6: Fecha: | H6: =TODAY() -> 46034
A7: UNIDADES | B7: DESCRIPCION MAT.PRIMA | C7: UNIDADES | D7: UND MEDIDA | E7: COSTO UNITARIO | F7: TOTAL COSTO | G7: % PREC. DEFINIDO | H7: CODIGOS
A8: 330 | B8: Queso Crema Panadero | C8: =+A8 -> 330 | D8: Gramos | E8: 3.071 | F8: =IFERROR(C8*E8,"") -> 1013.43 | G8: =IFERROR(F8/$F$66,"") -> 0.28530935 | H8: MP10046
A9: 370 | B9: Maracuya Congelada | C9: =+A9 -> 370 | D9: Gramos | E9: 3.61 | F9: =IFERROR(C9*E9,"") -> 1335.7 | G9: =IFERROR(F9/$F$66,"") -> 0.37603752 | H9: MP10423
A10: 150 | B10: Leche Condensada | C10: =+A10 -> 150 | D10: Gramos | E10: 2.21 | F10: =IFERROR(C10*E10,"") -> 331.5 | G10: =IFERROR(F10/$F$66,"") -> 0.093326673 | H10: MP10050
A11: 0.5 | B11: Colorante Gel Egg Yellow | C11: =+A11 -> 0.5 | D11: Gramos | E11: 18.46 | F11: =IFERROR(C11*E11,"") -> 9.23 | G11: =IFERROR(F11/$F$66,"") -> 0.0025985074 | H11: MP10150
A12: 10 | B12: Gelatina Pura | C12: =+A12 -> 10 | D12: Gramos | E12: 13.01 | F12: =IFERROR(C12*E12,"") -> 130.1 | G12: =IFERROR(F12/$F$66,"") -> 0.036626848 | H12: MP10043
B13: =IFERROR(VLOOKUP(H13,'[1]Consolidado MP Planta'!$A$2:$M$823,3,0),"") | C13: =+A13 -> 0 | D13: =IFERROR(VLOOKUP(H13,'[1]Consolidado MP Planta'!$A$2:$M$823,13,0),"") | E13: =IFERROR(VLOOKUP(H13,'[1]Consolidado MP Planta'!$A$2:$M$823,12,0),"") | F13: =IFERROR(C13*E13,"") | G13: =IFERROR(F13/$F$66,"")
B14: =IFERROR(VLOOKUP(H14,'[1]Consolidado MP Planta'!$A$2:$M$823,3,0),"") | C14: =+A14 -> 0 | D14: =IFERROR(VLOOKUP(H14,'[1]Consolidado MP Planta'!$A$2:$M$823,13,0),"") | E14: =IFERROR(VLOOKUP(H14,'[1]Consolidado MP Planta'!$A$2:$M$823,12,0),"") | F14: =IFERROR(C14*E14,"") | G14: =IFERROR(F14/$F$66,"")
B15: =IFERROR(VLOOKUP(H15,'[2]ARTICULOS MP PLANTA'!$A$2:$G$589,2,0),"")
A16: UNIDADES | B16: MATERIA PRIMA SEMIELABORADOS | C16: UNIDADES | D16: UND MEDIDA | E16: COSTO UNITARIO | F16: TOTAL COSTO | G16: % PREC. DEFINIDO | H16: CODIGOS
A17: 200 | B17: Crema Chantilly Blanca (Spoon-Ind) | C17: =+A17 -> 200 | D17: Gramos | E17: 2.17 | F17: =IFERROR(E17*C17,"") -> 434 | G17: =IFERROR(F17/$F$66,"") -> 0.12218334 | H17: SE00010
B18: =IFERROR(VLOOKUP(H18,[1]SEMIELABORADOS!$A$2:$M$6000,2,0),"") | C18: =+A18 -> 0 | D18: =IFERROR(VLOOKUP(H18,[1]SEMIELABORADOS!$A$2:$M$6000,6,0),"") | E18: =IFERROR(VLOOKUP(H18,[1]SEMIELABORADOS!$A$2:$H$65536,8,0),"") | F18: =IFERROR(E18*C18,"") | G18: =IFERROR(F18/$F$66,"")
B19: =IFERROR(VLOOKUP(H19,[1]SEMIELABORADOS!$A$2:$M$6000,2,0),"") | C19: =+A19 -> 0 | D19: =IFERROR(VLOOKUP(H19,[1]SEMIELABORADOS!$A$2:$M$6000,6,0),"") | E19: =IFERROR(VLOOKUP(H19,[1]SEMIELABORADOS!$A$2:$H$65536,8,0),"") | F19: =IFERROR(E19*C19,"") | G19: =IFERROR(F19/$F$66,"")
B20: =IFERROR(VLOOKUP(H20,[1]SEMIELABORADOS!$A$2:$M$6000,2,0),"") | C20: =+A20 -> 0 | D20: =IFERROR(VLOOKUP(H20,[1]SEMIELABORADOS!$A$2:$M$6000,6,0),"") | E20: =IFERROR(VLOOKUP(H20,[1]SEMIELABORADOS!$A$2:$H$65536,8,0),"") | F20: =IFERROR(E20*C20,"") | G20: =IFERROR(F20/$F$66,"")
B21: =IFERROR(VLOOKUP(H21,[1]SEMIELABORADOS!$A$2:$M$6000,2,0),"") | C21: =+A21 -> 0 | D21: =IFERROR(VLOOKUP(H21,[1]SEMIELABORADOS!$A$2:$M$6000,6,0),"") | E21: =IFERROR(VLOOKUP(H21,[1]SEMIELABORADOS!$A$2:$H$65536,8,0),"") | F21: =IFERROR(E21*C21,"") | G21: =IFERROR(F21/$F$66,"")
B22: =IFERROR(VLOOKUP(H22,[1]SEMIELABORADOS!$A$2:$M$6000,2,0),"") | C22: =+A22 -> 0 | D22: =IFERROR(VLOOKUP(H22,[1]SEMIELABORADOS!$A$2:$M$6000,6,0),"") | E22: =IFERROR(VLOOKUP(H22,[1]SEMIELABORADOS!$A$2:$H$65536,8,0),"") | F22: =IFERROR(E22*C22,"") | G22: =IFERROR(F22/$F$66,"")
B23: =IFERROR(VLOOKUP(H23,[1]SEMIELABORADOS!$A$2:$M$6000,2,0),"") | C23: =+A23 -> 0 | D23: =IFERROR(VLOOKUP(H23,[1]SEMIELABORADOS!$A$2:$M$6000,6,0),"") | E23: =IFERROR(VLOOKUP(H23,[1]SEMIELABORADOS!$A$2:$H$65536,8,0),"") | F23: =IFERROR(E23*C23,"") | G23: =IFERROR(F23/$F$66,"")
B24: =IFERROR(VLOOKUP(H24,[1]SEMIELABORADOS!$A$2:$M$6000,2,0),"") | C24: =+A24 -> 0 | D24: =IFERROR(VLOOKUP(H24,[1]SEMIELABORADOS!$A$2:$M$6000,6,0),"") | E24: =IFERROR(VLOOKUP(H24,[1]SEMIELABORADOS!$A$2:$H$65536,8,0),"") | F24: =IFERROR(E24*C24,"") | G24: =IFERROR(F24/$F$66,"")
A26: UNIDADES | B26: EMPAQUE | C26: UNIDADES | D26: UND MEDIDA | E26: COSTO UNITARIO | F26: TOTAL COSTO | G26: % PREC. DEFINIDO | H26: CODIGOS
A27: 0 | B27: =IFERROR(VLOOKUP(H27,'[1]Consolidado MP Planta'!$A$2:$M$823,3,0),"") | C27: =+A27 -> 0 | D27: =IFERROR(VLOOKUP(H27,'[1]Consolidado MP Planta'!$A$2:$M$823,13,0),"") | E27: =IFERROR(VLOOKUP(H27,'[1]Consolidado MP Planta'!$A$2:$M$823,12,0),"") | F27: =IFERROR(C27*E27,"") | G27: =IFERROR(F27/$F$66,"")
B28: =IFERROR(VLOOKUP(H28,'[1]Consolidado MP Planta'!$A$2:$M$823,3,0),"") | C28: =+A28 -> 0 | D28: =IFERROR(VLOOKUP(H28,'[1]Consolidado MP Planta'!$A$2:$M$823,13,0),"") | E28: =IFERROR(VLOOKUP(H28,'[1]Consolidado MP Planta'!$A$2:$M$823,12,0),"") | F28: =IFERROR(C28*E28,"") | G28: =IFERROR(F28/$F$66,"")
B29: =IFERROR(VLOOKUP(H29,'[1]Consolidado MP Planta'!$A$2:$M$823,3,0),"") | C29: =+A29 -> 0 | D29: =IFERROR(VLOOKUP(H29,'[1]Consolidado MP Planta'!$A$2:$M$823,13,0),"") | E29: =IFERROR(VLOOKUP(H29,'[1]Consolidado MP Planta'!$A$2:$M$823,12,0),"") | F29: =IFERROR(C29*E29,"") | G29: =IFERROR(F29/$F$66,"")
B30: =IFERROR(VLOOKUP(H30,'[1]Consolidado MP Planta'!$A$2:$M$823,3,0),"") | C30: =+A30 -> 0 | D30: =IFERROR(VLOOKUP(H30,'[1]Consolidado MP Planta'!$A$2:$M$823,13,0),"") | E30: =IFERROR(VLOOKUP(H30,'[1]Consolidado MP Planta'!$A$2:$M$823,12,0),"") | F30: =IFERROR(C30*E30,"") | G30: =IFERROR(F30/$F$66,"")
B31: =IFERROR(VLOOKUP(H31,'[1]Consolidado MP Planta'!$A$2:$M$823,3,0),"") | C31: =+A31 -> 0 | D31: =IFERROR(VLOOKUP(H31,'[1]Consolidado MP Planta'!$A$2:$M$823,13,0),"") | E31: =IFERROR(VLOOKUP(H31,'[1]Consolidado MP Planta'!$A$2:$M$823,12,0),"") | F31: =IFERROR(C31*E31,"") | G31: =IFERROR(F31/$F$66,"")
B32: =IFERROR(VLOOKUP(H32,'[1]Consolidado MP Planta'!$A$2:$M$823,3,0),"") | C32: =+A32 -> 0 | D32: =IFERROR(VLOOKUP(H32,'[1]Consolidado MP Planta'!$A$2:$M$823,13,0),"") | E32: =IFERROR(VLOOKUP(H32,'[1]Consolidado MP Planta'!$A$2:$M$823,12,0),"") | F32: =IFERROR(C32*E32,"") | G32: =IFERROR(F32/$F$66,"")
A34: UNIDADES | B34: EMPAQUE SEMIELABORADOS | C34: UNIDADES | D34: UND MEDIDA | E34: COSTO UNITARIO | F34: TOTAL COSTO | G34: % PREC. DEFINIDO | H34: CODIGOS
A35: =+A17 -> 200 | B35: Crema Chantilly Blanca (Spoon-Ind) | C35: =+A35 -> 200 | D35: Gramos | E35: 0.01 | F35: =IFERROR(E35*C35,"") -> 2 | G35: =IFERROR(F35/$F$66,"") -> 0.00056305685 | H35: SE00010
A36: =+A18 -> 0 | B36: =IFERROR(VLOOKUP(H36,[1]SEMIELABORADOS!$A$2:$M$6000,2,0),"") | C36: =+A36 -> 0 | D36: =IFERROR(VLOOKUP(H36,[1]SEMIELABORADOS!$A$2:$M$6000,6,0),"") | E36: =IFERROR(VLOOKUP(H36,[1]SEMIELABORADOS!$A$2:$M$65536,10,0),"") | F36: =IFERROR(E36*C36,"") | G36: =IFERROR(F36/$F$66,"")
A37: =+A19 -> 0 | B37: =IFERROR(VLOOKUP(H37,[1]SEMIELABORADOS!$A$2:$M$6000,2,0),"") | C37: =+A37 -> 0 | D37: =IFERROR(VLOOKUP(H37,[1]SEMIELABORADOS!$A$2:$M$6000,6,0),"") | E37: =IFERROR(VLOOKUP(H37,[1]SEMIELABORADOS!$A$2:$M$65536,10,0),"") | F37: =IFERROR(E37*C37,"") | G37: =IFERROR(F37/$F$66,"")
A38: =+A20 -> 0 | B38: =IFERROR(VLOOKUP(H38,[1]SEMIELABORADOS!$A$2:$M$6000,2,0),"") | C38: =+A38 -> 0 | D38: =IFERROR(VLOOKUP(H38,[1]SEMIELABORADOS!$A$2:$M$6000,6,0),"") | E38: =IFERROR(VLOOKUP(H38,[1]SEMIELABORADOS!$A$2:$M$65536,10,0),"") | F38: =IFERROR(E38*C38,"") | G38: =IFERROR(F38/$F$66,"")
A39: =+A21 -> 0 | B39: =IFERROR(VLOOKUP(H39,[1]SEMIELABORADOS!$A$2:$M$6000,2,0),"") | C39: =+A39 -> 0 | D39: =IFERROR(VLOOKUP(H39,[1]SEMIELABORADOS!$A$2:$M$6000,6,0),"") | E39: =IFERROR(VLOOKUP(H39,[1]SEMIELABORADOS!$A$2:$M$65536,10,0),"") | F39: =IFERROR(E39*C39,"") | G39: =IFERROR(F39/$F$66,"")
A40: =+A22 -> 0 | B40: =IFERROR(VLOOKUP(H40,[1]SEMIELABORADOS!$A$2:$M$6000,2,0),"") | C40: =+A40 -> 0 | D40: =IFERROR(VLOOKUP(H40,[1]SEMIELABORADOS!$A$2:$M$6000,6,0),"") | E40: =IFERROR(VLOOKUP(H40,[1]SEMIELABORADOS!$A$2:$M$65536,10,0),"") | F40: =IFERROR(E40*C40,"") | G40: =IFERROR(F40/$F$66,"")
A41: =+A23 -> 0 | B41: =IFERROR(VLOOKUP(H41,[1]SEMIELABORADOS!$A$2:$M$6000,2,0),"") | C41: =+A41 -> 0 | D41: =IFERROR(VLOOKUP(H41,[1]SEMIELABORADOS!$A$2:$M$6000,6,0),"") | E41: =IFERROR(VLOOKUP(H41,[1]SEMIELABORADOS!$A$2:$M$65536,10,0),"") | F41: =IFERROR(E41*C41,"") | G41: =IFERROR(F41/$F$66,"")
A43: UNIDADES | B43: MODI | C43: UNIDADES | D43: UND MEDIDA | E43: COSTO UNITARIO | F43: TOTAL COSTO | G43: % PREC. DEFINIDO | H43: CODIGOS
A44: =+A35 -> 200 | B44: Crema Chantilly Blanca (Spoon-Ind) | C44: =+A44 -> 200 | D44: Gramos | E44: 0.03 | F44: =IFERROR(E44*C44,"") -> 6 | G44: =IFERROR(F44/$F$66,"") -> 0.0016891705 | H44: SE00010
A45: =+A36 -> 0 | B45: =IFERROR(VLOOKUP(H45,[1]SEMIELABORADOS!$A$2:$M$6000,2,0),"") | C45: =+A45 -> 0 | D45: =IFERROR(VLOOKUP(H45,[1]SEMIELABORADOS!$A$2:$M$6000,6,0),"") | E45: =IFERROR(VLOOKUP(H45,[1]SEMIELABORADOS!$A$2:$M$65536,12,0),"") | F45: =IFERROR(E45*C45,"") | G45: =IFERROR(F45/$F$66,"")
...

Sheet Premezcla Brownie
C1: SERVICIOS DE PASTELERIA S.A. | H1: CÓDIGO:
C2: ESPECIFICACION DE RECETA | H2: REVISIÓN:
C3: Premezcla Para Brownie Casero 95361 SE00170 | H3: FECHA DE APROBACIÓN:
C4: Elaborado | D4: Javier Tong, Chef
C5: Aprobado | D5: Esteban Cartin, Gte Manufactura
A6: AREA QUE PRODUCE: | D6: Premezcla | G6: AREA QUE EMPACA: | I6: Premezcla
A7: # Código | B7: # Código Netsuite | C7: Descripción del ingrediente | D7: Marca | E7: Unidad Internacional | G7: Medida alternativa | I7: Costo - Referencia
E8: Cantidad | F8: Unidad medida | G8: Cantidad | H8: Unidad medida | I8: Colones
C9: Ensamble
A10: 11200070 | B10: MP10206 | C10: Harina Harisol Hojaldre | D10: HARISOL | E10: 2850 | F10: g | J10: =+E10/$D$43 -> 0.17592593 | K10: =+J10*1000 -> 175.92593
A11: 512316 | B11: MP10091 | C11: Café Instantaneo | D11: NESCAFE | E11: 200 | F11: g | J11: =+E11/$D$43 -> 0.012345679 | K11: =+J11*1000 -> 12.345679
A12: 5000001 | B12: MP10027 | C12: Sal Industrial | D12: ATLANTIDA | E12: 50 | F12: g | J12: =+E12/$D$43 -> 0.0030864198 | K12: =+J12*1000 -> 3.0864198
A13: 1212410 | B13: MP10008 | C13: Preservante 1047S | D13: ASEAL | E13: 20 | F13: g | J13: =+E13/$D$43 -> 0.0012345679 | K13: =+J13*1000 -> 1.2345679
A14: 512255 | B14: MP10146 | C14: Cocoa Dutch Process | D14: COSTA RICA CACAO | E14: 600 | F14: g | J14: =+E14/$D$43 -> 0.037037037 | K14: =+J14*1000 -> 37.037037
A15: 10100331 | B15: MP10492 | C15: Chocolate Semi Amargo 54% | D15: CORDILLERA | E15: 1000 | F15: g | J15: =+E15/$D$43 -> 0.061728395 | K15: =+J15*1000 -> 61.728395
A16: 1210386 | B16: MP10001 | C16: Cobertura Chocolate Leche | D16: CORDILLERA | E16: 2000 | F16: g | J16: =+E16/$D$43 -> 0.12345679 | K16: =+J16*1000 -> 123.45679
A17: 510301 | B17: MP10074 | C17: Azucar Blanco Industrial | D17: LAYCA | E17: 7500 | F17: g | J17: =+E17/$D$43 -> 0.46296296 | K17: =+J17*1000 -> 462.96296
A18: 11900028 | B18: MP10562 | C18: Pecana Entera | D18: NUECES INDUSTRIALES | E18: 2000 | F18: G | J18: =+E18/$D$43 -> 0.12345679 | K18: =+J18*1000 -> 123.45679
C26: Decoración
C33: Empaque
B34: 1950708 | C34: BOLSA 17x25 TRANSP KILO | D34: Plasticos P | E34: 3 | F34: ud
B35: 702123 | C35: ETIQUETA BLANCA 2 5/8X1 15/16 (UND) | D35: Etiplast | E35: 1 | F35: ud
B36: 60100010 | C36: ETIQUETA ROJA LETRA ALERJENO (UND) | D36: Etiplast | E36: 1 | F36: ud
D42: Cantidad | E42: Unidad
A43: PESO TOTAL OBTENIDO | D43: 16200 | E43: g | F43: Tiempo de Horneo:
A44: TIEMPO TOTAL DE PREPARACION | D44: 4 | E44: min | F44: Horno:
A45: CANTIDAD DE PORCIONES OBTENIDAS | D45: 1 | E45: Tanda | F45: Temperatura de Horneo:
A46: PESO DE CADA PORCIÓN | D46: 16200 | E46: g | F46: Otros
A47: MERMA | D47: =SUM(E9:E22)-D43 -> 20 | E47: g
A48: PROCEDIMIENTO DE PREPARACION DE LA RECETA
A49: 1.- Pesar en la bolsa 17x25 la harina, café instantaneo, sal, preservante y cocoa.
A50: 2.- Pesar en la bolsa 17x25 el chocolate rallado oscuro y la cobertura de chocolate leche.
A51: 3.- En la bolsa 17x25 pesar el azucar.
A52: 4.- Etiquetar con nombre y alerjeno.
A63: CONTROL DE CAMBIOS
C68: Eliminar bolsa 8x12 No se utiliza, agregar 3 bolsas de 17x25 una para el chocolate, otra para el azucar y una para los polvos. Verificar las marcas de las materias primas . Harina marca harisol. Sal de 25 kg y marca atlantida. Marca del preservante. chocolaterallano no: (Chocolate Semi Amargo 54%). Pecana entera (no quebradura).

Sheet Batido Brownie Casero
C1: SERVICIOS DE PASTELERIA S.A. | H1: CÓDIGO: | I1: ESP-RE-BAS-010
C2: ESPECIFICACION DE RECETA | H2: REVISIÓN: | I2: 01
C3: Batido De Brownie Casero 902000014(SE00169) | H3: FECHA DE APROBACIÓN: | I3: 45619
C4: Elaborado | D4: Javier Tong, Chef
C5: Aprobado | D5: Esteban Cartin, Gte Manufactura
A6: AREA QUE PRODUCE: | D6: Batidos | G6: AREA QUE EMPACA: | I6: Batidos
A7: # Código | B7: # Código Netsuite | C7: Descripción del ingrediente | D7: Marca | E7: Unidad Internacional | G7: Medida alternativa | I7: Costo - Referencia
E8: Cantidad | F8: Unidad medida | G8: Cantidad | H8: Unidad medida | I8: Colones
C9: Ensamble
A10: 95361 | B10: SE00170 | C10: Premezcla Para Brownie Casero | D10: FAS | E10: 16200 | F10: g
C11: AGUA POTABLE (PLANTA) | D11: FAS | E11: 1600 | F11: g
A12: 10100050 | B12: MP10002 | C12: Aceite Capullo Rbd | D12: CAPULLO | E12: 1400 | F12: g
A13: 10100289 | B13: MP10040 | C13: Margarina Baker Tableta | D13: BAKER | E13: 600 | F13: g
A14: 118000004 | B14: MP10385 | C14: Vainilla Oscura | D14: VAINOL | E14: 300 | F14: g
A15: 1210482 | B15: MP10005 | C15: Huevo Liquido Refrigerado | D15: INNOVO | E15: 1200 | F15: g
A16: 11300011 | B16: MP10037 | C16: Yema De Huevo Pasteurizada | D16: INNOVO | E16: 400 | F16: g
C18: Decoración
C26: Empaque
D36: Cantidad | E36: Unidad
A37: PESO TOTAL OBTENIDO | D37: 20600 | E37: g | F37: Tiempo de Horneo:
A38: TIEMPO TOTAL DE PREPARACION | D38: 10 | E38: min | F38: Horno:
A39: CANTIDAD DE PORCIONES OBTENIDAS | D39: 10 | E39: Moldes | F39: Temperatura de Horneo:
A40: PESO DE CADA PORCIÓN | D40: 2000 | E40: g | F40: Otros
A41: MERMA | D41: =SUM(E10:E17)-D37 -> 1100 | E41: g
A42: PROCEDIMIENTO DE PREPARACION DE LA RECETA
A43: 1.- En el agua hirviendo derretir los chocolates, vainilla, agregar el aceite y la margarina y colocar en la batidora
A44: 2.- Agregar el huevo y la yema y mezclar a velocidad 1 por 1 minuto.
A45: 3.- Luego agregar los ingredientes secos e incorporar a velocidad 2 por 1 minuto.
A46: 4.- Agregar el azucar y la pecana y mezclar a velocidad 1 por 1 minuto.
A57: CONTROL DE CAMBIOS
A58: 2, Correccion d batido a nueva receta, con pecanas y chocolates.

Sheet Rosquete Brownie Casero
B1: SERVICIOS DE PASTELERIA S.A. | G1: CÓDIGO: | H1: ESP-RE-BAS-138
B2: ESPECIFICACION DE RECETA | G2: REVISIÓN: | H2: 01
B3: SE00200 907000241 Rosquete Brownie Casero redondo 250g | G3: FECHA DE APROBACIÓN: | H3: 44096
B4: Elaborado | C4: Javier Tong, Chef
B5: Aprobado | C5: Jeffry Rodriguez. Gte de Manufactura
A7: # Código | B7: Descripción del ingrediente | C7: Marca | D7: Unidad Internacional | F7: Medida alternativa | H7: Costo - Referencia
D8: Cantidad | E8: Unidad medida | F8: Cantidad | G8: Unidad medida | H8: Colones
A9: 902000014 | B9: BATIDO BROWNIE CASERO (KILO) | C9: FAS | D9: 8000 | E9: g
B10: MEZCLA ENGRASE MOLDES (29800g) | D10: 300
A11: 1950928 | B11: BOLSA TRANSPARENTE 56X96X1.80 ** | D11: 2 | E11: ud
A12: 702007 | B12: ETIQ.FECHA VENCIMIENTO BLANCO (ROLLO) | D12: 2 | E12: ud
A13: 906036 | B13: PAPEL MANTEQUILLA (CAJA= 1000 UND) | C13: TIPS | D13: 4 | E13: ud
A14: 702123 | B14: ETIQUETA BLANCA 2 5/8X1 15/16 (UND) | C14: CEMUSA | D14: 2 | E14: ud
C16: Cantidad | D16: Unidad
A17: PESO TOTAL OBTENIDO | C17: 8000 | D17: g | E17: Tiempo de Horneo
A18: TIEMPO TOTAL DE PREPARACION | C18: 10 | D18: min | E18: Horno:
A19: CANTIDAD DE PORCIONES OBTENIDAS | C19: =+C17/C20 -> 32 | D19: ud | E19: Temperatura de Horneo
A20: PESO DE CADA PORCIÓN | C20: 250 | D20: g | E20: Otros
A21: MERMA | C21: 80 | D21: g
A22: PROCEDIMIENTO DE PREPARACION DE LA RECETA
A23: 1- Colocar la mezcla molde con el papel mantequilla, MOLDE ENGRASADO CON MARGARINA y luego Aceite.
A24: 2- Dosificar 250 g en cada molde redondo
A25: 3- COLOCAR EN EL HORNO INMEDIATAMENTE Y HORNEAR POR 30 MINUTOS.
A26: 4-Empacar 24 por lata y etiquetar.

Sheet Ensamble
C1: SERVICIOS DE PASTELERIA S.A. | H1: CÓDIGO: | I1: ESP-RE-POS-120
C2: ESPECIFICACION DE RECETA | H2: REVISIÓN: | I2: 01
C3: PTI00267 Postre brownie maracuya spoon | H3: FECHA DE APROBACIÓN: | I3: 45988
C4: Elaborado | D4: Javier Tong, Chef
C5: Aprobado | D5: Esteban Cartin, Gte Manufactura
A6: AREA QUE PRODUCE: | D6: Postres | G6: AREA QUE EMPACA: | I6: Postres | K6: 7151-7671
A7: # Código | B7: # Código Netsuite | C7: Descripción del ingrediente | D7: Marca | E7: Unidad Internacional | G7: Medida alternativa | I7: Costo - Referencia
E8: Cantidad | F8: Unidad medida | G8: Cantidad | H8: Unidad medida | I8: Colones
A9: 907000241 | B9: SE00200 | C9: ROSQUETE REDONDO BROWNIE CASERO 250G | D9: FAS | E9: 225 | F9: g | H9: molde pequeño
B10: SE00337 | C10: Empaque Fudge De Chocolate | D10: FAS | E10: 100 | F10: g | H10: 1/3 TAZA
B11: SE00765 | C11: MOUSSE MARACUYA | D11: FAS | E11: 350 | F11: g
A12: 907000241 | B12: SE00200 | C12: ROSQUETE REDONDO BROWNIE CASERO 250G | D12: FAS | E12: 80 | F12: g | H12: 1/4 UNIDAD | K12: =1/4 -> 0.25
C14: DECORACION
B15: SE00010 | C15: Crema Chantilly Blanca (Spoon-Ind) | D15: FAS | E15: 20 | F15: g | H15: Boquilla 805
B16: SE00764 | C16: SALSA DE MARACUYA | D16: FAS | E16: 140 | F16: g | H16: 1/2 taza
C18: EMPAQUE
B19: EM10455 | C19: QUEQUERA REDONDA CON BASE 7 ALTA | D19: FAS | E19: 1 | F19: ud
B20: MP10007 | C20: Manjar Leche Condensada | D20: Nestle | E20: 10 | F20: g
A21: 702069 | B21: EM10002 | C21: ETIQ.BLANCA 1 1/4 * 3/4 | D21: CEMUSA | E21: 1 | F21: ud
A22: 701096 | B22: EM10124 | C22: ETIQUETA BLANCA R-153 | D22: CEMUSA | E22: 1 | F22: ud
B23: EM10011 | C23: Etiqueta Blanca 2 5/8X1 15/16 | D23: CEMUSA | E23: 1 | F23: ud
D27: Cantidad | E27: Unidad
A28: PESO TOTAL OBTENIDO | D28: 900 | E28: g | F28: Tiempo de Horneo:
A29: TIEMPO TOTAL DE PREPARACION | D29: 7 | E29: min | F29: Horno:
A30: CANTIDAD DE PORCIONES OBTENIDAS | D30: 1 | E30: uds | F30: Temperatura de Horneo:
A31: PESO DE CADA PORCIÓN | D31: 900 | E31: g | F31: Otros
A32: MERMA | D32: =SUM(E9:E16)-D28 -> 15 | E32: g
A33: PROCEDIMIENTO DE PREPARACION DE LA RECETA
A34: 1.- Colocar en el molde engrasado el brownie.
A35: 2.- Luego agregar el fudge en un circulo en el centro y dosificar encima el mousse de maracuya.
A36: 3.- Sobre el mousse agregar el brownie en trozos y mezclar un poco. Llevar a enfriamiento por minimo 4 horas
A37: 4.- Desmoldar y colocar en la orla con manjar, con la boquilla redonda hacer colochos al borde y en el centro la salsa de maracuya.
A38: 5.- Tapar y etiquetar
A43: CONTROL DE CAMBIOS

Sheet Costo Ensamble 
E1: Precio Local | F1: Costo MP | G1: Costo EM | H1: Costo MO
E2: =IFERROR(O62,"") -> 4074.2362 | F2: =IFERROR(H53,"") -> 2303.7033 | G2: =IFERROR(H54,"") -> 353.36083 | H2: =IFERROR(H56,"") -> 773.91667
A5: ESTRUCTURA DE COSTOS
F6: Fecha: | H6: =TODAY() -> 46034
A7: UNIDADES | B7: DESCRIPCION MAT.PRIMA | C7: UNIDADES | D7: UND MEDIDA | E7: COSTO UNITARIO | F7: TOTAL COSTO | G7: % PREC. DEFINIDO | H7: CODIGOS
B8: =IFERROR(VLOOKUP(H8,'[1]Consolidado MP Planta'!$A$2:$M$823,3,0),"") | C8: =+A8 -> 0 | D8: =IFERROR(VLOOKUP(H8,'[1]Consolidado MP Planta'!$A$2:$M$823,13,0),"") | E8: =IFERROR(VLOOKUP(H8,'[1]Consolidado MP Planta'!$A$2:$M$823,12,0),"") | F8: =IFERROR(C8*E8,"") | G8: =IFERROR(F8/$F$66,"")
B9: =IFERROR(VLOOKUP(H9,'[1]Consolidado MP Planta'!$A$2:$M$823,3,0),"") | C9: =+A9 -> 0 | D9: =IFERROR(VLOOKUP(H9,'[1]Consolidado MP Planta'!$A$2:$M$823,13,0),"") | E9: =IFERROR(VLOOKUP(H9,'[1]Consolidado MP Planta'!$A$2:$M$823,12,0),"") | F9: =IFERROR(C9*E9,"") | G9: =IFERROR(F9/$F$66,"")
B10: =IFERROR(VLOOKUP(H10,'[1]Consolidado MP Planta'!$A$2:$M$823,3,0),"") | C10: =+A10 -> 0 | D10: =IFERROR(VLOOKUP(H10,'[1]Consolidado MP Planta'!$A$2:$M$823,13,0),"") | E10: =IFERROR(VLOOKUP(H10,'[1]Consolidado MP Planta'!$A$2:$M$823,12,0),"") | F10: =IFERROR(C10*E10,"") | G10: =IFERROR(F10/$F$66,"")
B11: =IFERROR(VLOOKUP(H11,'[1]Consolidado MP Planta'!$A$2:$M$823,3,0),"") | C11: =+A11 -> 0 | D11: =IFERROR(VLOOKUP(H11,'[1]Consolidado MP Planta'!$A$2:$M$823,13,0),"") | E11: =IFERROR(VLOOKUP(H11,'[1]Consolidado MP Planta'!$A$2:$M$823,12,0),"") | F11: =IFERROR(C11*E11,"") | G11: =IFERROR(F11/$F$66,"")
B12: =IFERROR(VLOOKUP(H12,'[1]Consolidado MP Planta'!$A$2:$M$823,3,0),"") | C12: =+A12 -> 0 | D12: =IFERROR(VLOOKUP(H12,'[1]Consolidado MP Planta'!$A$2:$M$823,13,0),"") | E12: =IFERROR(VLOOKUP(H12,'[1]Consolidado MP Planta'!$A$2:$M$823,12,0),"") | F12: =IFERROR(C12*E12,"") | G12: =IFERROR(F12/$F$66,"")
B13: =IFERROR(VLOOKUP(H13,'[1]Consolidado MP Planta'!$A$2:$M$823,3,0),"") | C13: =+A13 -> 0 | D13: =IFERROR(VLOOKUP(H13,'[1]Consolidado MP Planta'!$A$2:$M$823,13,0),"") | E13: =IFERROR(VLOOKUP(H13,'[1]Consolidado MP Planta'!$A$2:$M$823,12,0),"") | F13: =IFERROR(C13*E13,"") | G13: =IFERROR(F13/$F$66,"")
B14: =IFERROR(VLOOKUP(H14,'[1]Consolidado MP Planta'!$A$2:$M$823,3,0),"") | C14: =+A14 -> 0 | D14: =IFERROR(VLOOKUP(H14,'[1]Consolidado MP Planta'!$A$2:$M$823,13,0),"") | E14: =IFERROR(VLOOKUP(H14,'[1]Consolidado MP Planta'!$A$2:$M$823,12,0),"") | F14: =IFERROR(C14*E14,"") | G14: =IFERROR(F14/$F$66,"")
B15: =IFERROR(VLOOKUP(H15,'[2]ARTICULOS MP PLANTA'!$A$2:$G$589,2,0),"")
A16: UNIDADES | B16: MATERIA PRIMA SEMIELABORADOS | C16: UNIDADES | D16: UND MEDIDA | E16: COSTO UNITARIO | F16: TOTAL COSTO | G16: % PREC. DEFINIDO | H16: CODIGOS
A17: 1.25 | B17: ROSQUETE REDONDO BROWNIE CASERO 250G | C17: =+A17 -> 1.25 | D17: UND | E17: 375.24 | F17: =IFERROR(E17*C17,"") -> 469.05 | G17: =IFERROR(F17/$F$66,"") -> 0.14467304 | H17: 907000241
A18: 100 | B18: Empaque Fudge De Chocolate | C18: =+A18 -> 100 | D18: Gramos | E18: 2.44 | F18: =IFERROR(E18*C18,"") -> 244 | G18: =IFERROR(F18/$F$66,"") -> 0.075258975 | H18: SE00337
A19: 350 | B19: MOUSSE MARACUYA | C19: =+A19 -> 350 | D19: Gramos | E19: =+'Costo Mousse Maracuya'!E69 -> 3.0990095 | F19: =IFERROR(E19*C19,"") -> 1084.6533 | G19: =IFERROR(F19/$F$66,"") -> 0.33454876 | H19: NUEVO
A20: 20 | B20: Crema Chantilly Blanca (Spoon-Ind) | C20: =+A20 -> 20 | D20: Gramos | E20: =+'[3]costo Mouse Queso'!$E$14 -> 2.17 | F20: =IFERROR(E20*C20,"") -> 43.4 | G20: =IFERROR(F20/$F$66,"") -> 0.013386228 | H20: SE00010
A21: 140 | B21: SALSA DE MARACUYA | C21: =+A21 -> 140 | D21: Gramos | E21: =+'Costo Salsa Maracuya'!E69 -> 3.3042857 | F21: =IFERROR(E21*C21,"") -> 462.6 | G21: =IFERROR(F21/$F$66,"") -> 0.14268361
B22: =IFERROR(VLOOKUP(H22,[1]SEMIELABORADOS!$A$2:$M$6000,2,0),"") | C22: =+A22 -> 0 | D22: =IFERROR(VLOOKUP(H22,[1]SEMIELABORADOS!$A$2:$M$6000,6,0),"") | E22: =IFERROR(VLOOKUP(H22,[1]SEMIELABORADOS!$A$2:$H$65536,8,0),"") | F22: =IFERROR(E22*C22,"") | G22: =IFERROR(F22/$F$66,"")
B23: =IFERROR(VLOOKUP(H23,[1]SEMIELABORADOS!$A$2:$M$6000,2,0),"") | C23: =+A23 -> 0 | D23: =IFERROR(VLOOKUP(H23,[1]SEMIELABORADOS!$A$2:$M$6000,6,0),"") | E23: =IFERROR(VLOOKUP(H23,[1]SEMIELABORADOS!$A$2:$H$65536,8,0),"") | F23: =IFERROR(E23*C23,"") | G23: =IFERROR(F23/$F$66,"")
B24: =IFERROR(VLOOKUP(H24,[1]SEMIELABORADOS!$A$2:$M$6000,2,0),"") | C24: =+A24 -> 0 | D24: =IFERROR(VLOOKUP(H24,[1]SEMIELABORADOS!$A$2:$M$6000,6,0),"") | E24: =IFERROR(VLOOKUP(H24,[1]SEMIELABORADOS!$A$2:$H$65536,8,0),"") | F24: =IFERROR(E24*C24,"") | G24: =IFERROR(F24/$F$66,"")
A26: UNIDADES | B26: EMPAQUE | C26: UNIDADES | D26: UND MEDIDA | E26: COSTO UNITARIO | F26: TOTAL COSTO | G26: % PREC. DEFINIDO | H26: CODIGOS
A27: 1 | B27: QUEQUERA 8 PEQUEÑA | C27: =+A27 -> 1 | D27: UND | E27: 245.63 | F27: =IFERROR(C27*E27,"") -> 245.63 | G27: =IFERROR(F27/$F$65,"") -> 0.45571429 | H27: NUEVO
A28: 1 | B28: ETIQUETA POSTRE | C28: =+A28 -> 1 | D28: UND | E28: 85 | F28: =IFERROR(C28*E28,"") -> 85 | G28: =IFERROR(F28/$F$65,"") -> 0.15769944 | H28: NUEVO
A29: 1 | B29: ETIQ.BLANCA 1 1/4 * 3/4 | C29: =+A29 -> 1 | D29: UND | E29: 1.74 | F29: =IFERROR(C29*E29,"") -> 1.74 | G29: =IFERROR(F29/$F$65,"") -> 0.0032282004 | H29: EM10002
A30: 1 | B30: ETIQUETA BLANCA R-153 (UND) | C30: =+A30 -> 1 | D30: UND | E30: 0.39 | F30: =IFERROR(C30*E30,"") -> 0.39 | G30: =IFERROR(F30/$F$65,"") -> 0.00072356215 | H30: EM10124
A31: 1 | B31: ETIQUETA BLANCA 2 5/8X1 15/16 (UND) | C31: =+A31 -> 1 | D31: UND | E31: 2.13 | F31: =IFERROR(C31*E31,"") -> 2.13 | G31: =IFERROR(F31/$F$65,"") -> 0.0039517625 | H31: EM10011
B32: =IFERROR(VLOOKUP(H32,'[1]Consolidado MP Planta'!$A$2:$M$823,3,0),"") | C32: =+A32 -> 0 | D32: =IFERROR(VLOOKUP(H32,'[1]Consolidado MP Planta'!$A$2:$M$823,13,0),"") | E32: =IFERROR(VLOOKUP(H32,'[1]Consolidado MP Planta'!$A$2:$M$823,12,0),"") | F32: =IFERROR(C32*E32,"") | G32: =IFERROR(F32/$F$66,"")
A34: UNIDADES | B34: EMPAQUE SEMIELABORADOS | C34: UNIDADES | D34: UND MEDIDA | E34: COSTO UNITARIO | F34: TOTAL COSTO | G34: % PREC. DEFINIDO | H34: CODIGOS
A35: =+A17 -> 1.25 | B35: ROSQUETE REDONDO BROWNIE CASERO 250G | C35: =+A35 -> 1.25 | D35: UND | E35: 11.95 | F35: =IFERROR(E35*C35,"") -> 14.9375 | G35: =IFERROR(F35/$F$66,"") -> 0.0046072989 | H35: 907000241
A36: =+A18 -> 100 | B36: Empaque Fudge De Chocolate | C36: =+A36 -> 100 | D36: Gramos | E36: 0.01 | F36: =IFERROR(E36*C36,"") -> 1 | G36: =IFERROR(F36/$F$66,"") -> 0.00030843842 | H36: SE00337
A37: =+A19 -> 350 | B37: MOUSSE MARACUYA | C37: =+A37 -> 350 | D37: Gramos | E37: =+'Costo Mousse Maracuya'!E76 -> 0.0019047619 | F37: =IFERROR(E37*C37,"") -> 0.66666667 | G37: =IFERROR(F37/$F$66,"") -> 0.00020562561 | H37: NUEVO
A38: =+A20 -> 20 | B38: Crema Chantilly Blanca (Spoon-Ind) | C38: =+A38 -> 20 | D38: Gramos | E38: =+'[3]costo Mouse Queso'!$E$32 -> 0.01 | F38: =IFERROR(E38*C38,"") -> 0.2 | G38: =IFERROR(F38/$F$66,"") -> 6.1687684e-05 | H38: SE00010
A39: =+A21 -> 140 | B39: SALSA DE MARACUYA | C39: =+A39 -> 140 | D39: Gramos | E39: =+'Costo Salsa Maracuya'!E76 -> 0.011904762 | F39: =IFERROR(E39*C39,"") -> 1.6666667 | G39: =IFERROR(F39/$F$66,"") -> 0.00051406404
A40: =+A22 -> 0 | B40: =IFERROR(VLOOKUP(H40,[1]SEMIELABORADOS!$A$2:$M$6000,2,0),"") | C40: =+A40 -> 0 | D40: =IFERROR(VLOOKUP(H40,[1]SEMIELABORADOS!$A$2:$M$6000,6,0),"") | E40: =IFERROR(VLOOKUP(H40,[1]SEMIELABORADOS!$A$2:$M$65536,10,0),"") | F40: =IFERROR(E40*C40,"") | G40: =IFERROR(F40/$F$66,"")
A41: =+A23 -> 0 | B41: =IFERROR(VLOOKUP(H41,[1]SEMIELABORADOS!$A$2:$M$6000,2,0),"") | C41: =+A41 -> 0 | D41: =IFERROR(VLOOKUP(H41,[1]SEMIELABORADOS!$A$2:$M$6000,6,0),"") | E41: =IFERROR(VLOOKUP(H41,[1]SEMIELABORADOS!$A$2:$M$65536,10,0),"") | F41: =IFERROR(E41*C41,"") | G41: =IFERROR(F41/$F$66,"")
A43: UNIDADES | B43: MODI | C43: UNIDADES | D43: UND MEDIDA | E43: COSTO UNITARIO | F43: TOTAL COSTO | G43: % PREC. DEFINIDO | H43: CODIGOS
A44: =+A35 -> 1.25 | B44: ROSQUETE REDONDO BROWNIE CASERO 250G | C44: =+A44 -> 1.25 | D44: UND | E44: 33.8 | F44: =IFERROR(E44*C44,"") -> 42.25 | G44: =IFERROR(F44/$F$66,"") -> 0.013031523 | H44: 907000241
A45: =+A36 -> 100 | B45: Empaque Fudge De Chocolate | C45: =+A45 -> 100 | D45: Gramos | E45: 0.09 | F45: =IFERROR(E45*C45,"") -> 9 | G45: =IFERROR(F45/$F$66,"") -> 0.0027759458 | H45: SE00337
...
