Workbook

Sheet Hoja1
C1: SERVICIOS DE PASTELERIA S.A. | H1: CÓDIGO: | I1: ESP-RE-COCS-067
C2: ESPECIFICACION DE RECETA | H2: REVISIÓN: | I2: 01
C3: SE00543 Relleno carne mechada empanada | H3: FECHA DE APROBACIÓN: | I3: 45609
C4: Elaborado | D4: Javier Tong, Chef
C5: Aprobado | D5: Esteban Cartin, Gte Manufactura
A6: AREA QUE PRODUCE: | D6: Cocina | G6: AREA QUE EMPACA: | I6: Pastas
A7: # Código | B7: # Código Netsuite | C7: Descripción del ingrediente | D7: Marca | E7: Unidad Internacional | G7: Medida alternativa | I7: Costo - Referencia
E8: Cantidad | F8: Unidad medida | G8: Cantidad | H8: Unidad medida | I8: Colones
C9: Ensamble
A10: 310107 | B10: MP10022 | C10: LACTOCREMA GRANEL (CAJA:25 KG) | D10: FAS | E10: 90 | F10: g
A11: 101035 | B11: MP10020 | C11: CEBOLLA PICADA (PAQ:KILO) | E11: 250 | F11: g
A12: 512319 | B12: MP10019 | C12: PASTA AJO (PAQ: 1 KILO) | E12: 20 | F12: g
A13: 105000009 | B13: MP10058 | C13: ACHIOTE (UND:850G) | E13: 30 | F13: g
A14: 101150 | B14: MP10069 | C14: APIO PICADO (PAQ:500GR) | E14: 60 | F14: g
A15: 10100125 | B15: MP10287 | C15: PASTA TOMATE OLD CALI (UND:3.14 K) | E15: 100 | F15: g
A16: 105000058 | B16: MP10163 | C16: CONSOME CONCEN. DE RES (2000G) | D16: FAS | E16: 20 | F16: g
A17: 90100142 | B17: SE00104 | C17: EMPAQUE SAL KILO | E17: 10 | F17: g
A18: 610218 | B18: MP10158 | C18: COMINO (UND:454G) | E18: 2 | F18: g
A19: 710261 | B19: MP10035 | C19: PAN CUADRADO BLANCO (PAQ=22 REBANADAS ) | E19: 100 | F19: g
A20: 95460 | B20: SE00182 | C20: CARNE MECHADA EN COCCION | E20: 500 | F20: g
A21: 102000062 | B21: MP10392 | C21: VINO BLANCO | E21: 150 | F21: g
B22: MP10025 | C22: PRESERVANTE 1017S | E22: 2 | F22: g
A23: 10415 | C23: AGUA POTABLE (PLANTA) | E23: 200 | F23: g
C26: Decoración
C28: Empaque
D31: Cantidad | E31: Unidad
A32: PESO TOTAL OBTENIDO | D32: 1400 | E32: g | F32: Tiempo de Horneo:
A33: TIEMPO TOTAL DE PREPARACION | D33: 6 | E33: min | F33: Horno:
A34: CANTIDAD DE PORCIONES OBTENIDAS | D34: 1 | E34: ud | F34: Temperatura de Horneo:
A35: PESO DE CADA PORCIÓN | D35: 1400 | E35: g | F35: Otros
A36: MERMA | D36: 134 | E36: g
A37: PROCEDIMIENTO DE PREPARACION DE LA RECETA
A38: 1.- En la lactocrema y achiote saltear la cebolla, ajo y apio.
A39: 2.- Luego deglasear la preparacion con el vino blanco, despues agregar el agua, pasta de tomate, consome, comino, preservante y sal.
A40: 3.- Cuando la preparacion toma temperatura agregar la carne y el pan molido y mezclar.
A41: 4.- Dar temperatura y apagar.
A43: CONTROL DE CAMBIOS

Sheet Costo Relleno
E1: Precio Local | F1: Costo MP | G1: Costo EM | H1: Costo MO
E2: =IFERROR(O67,"") -> 7486.3073 | F2: =IFERROR(H58,"") -> 6576.0791 | G2: =IFERROR(H59,"") -> 0.036256 | H2: =IFERROR(H61,"") -> 466.56899
A5: ESTRUCTURA DE COSTOS
F6: Fecha: | H6: =TODAY() -> 46078
A7: UNIDADES | B7: DESCRIPCION MAT.PRIMA | C7: UNIDADES | D7: UND MEDIDA | E7: COSTO UNITARIO | F7: TOTAL COSTO | G7: % PREC. DEFINIDO | H7: CODIGOS
A8: 90 | B8: =IFERROR(VLOOKUP(H8,'[1]Consolidado MP Planta'!$A$2:$M$823,3,0),"") -> LACTOCREMA GRANEL (CAJA:25 KG) | C8: =+A8 -> 90 | D8: =IFERROR(VLOOKUP(H8,'[1]Consolidado MP Planta'!$A$2:$M$823,13,0),"") -> Gramos | E8: 3.49 | F8: =IFERROR(C8*E8,"") -> 314.1 | G8: =IFERROR(F8/$F$71,"") -> 0.044404315 | H8: 0310107
A9: 250 | B9: =IFERROR(VLOOKUP(H9,'[1]Consolidado MP Planta'!$A$2:$M$823,3,0),"") -> CEBOLLA PICADA (PAQ:KILO) | C9: =+A9 -> 250 | D9: =IFERROR(VLOOKUP(H9,'[1]Consolidado MP Planta'!$A$2:$M$823,13,0),"") -> Gramos | E9: 1.98 | F9: =IFERROR(C9*E9,"") -> 495 | G9: =IFERROR(F9/$F$71,"") -> 0.069978146 | H9: 101035
A10: 20 | B10: =IFERROR(VLOOKUP(H10,'[1]Consolidado MP Planta'!$A$2:$M$823,3,0),"") -> PASTA AJO (PAQ: 1 KILO) | C10: =+A10 -> 20 | D10: =IFERROR(VLOOKUP(H10,'[1]Consolidado MP Planta'!$A$2:$M$823,13,0),"") -> Gramos | E10: 4.75 | F10: =IFERROR(C10*E10,"") -> 95 | G10: =IFERROR(F10/$F$71,"") -> 0.013430149 | H10: 0512319
A11: 30 | B11: =IFERROR(VLOOKUP(H11,'[1]Consolidado MP Planta'!$A$2:$M$823,3,0),"") -> ACHIOTE (UND:850g) | C11: =+A11 -> 30 | D11: =IFERROR(VLOOKUP(H11,'[1]Consolidado MP Planta'!$A$2:$M$823,13,0),"") -> Gramos | E11: =IFERROR(VLOOKUP(H11,'[1]Consolidado MP Planta'!$A$2:$M$823,12,0),"") -> 4.4447059 | F11: =IFERROR(C11*E11,"") -> 133.34118 | G11: =IFERROR(F11/$F$71,"") -> 0.018850441 | H11: 105000009
A12: 60 | B12: =IFERROR(VLOOKUP(H12,'[1]Consolidado MP Planta'!$A$2:$M$823,3,0),"") -> APIO PICADO (PAQ:500gr) | C12: =+A12 -> 60 | D12: =IFERROR(VLOOKUP(H12,'[1]Consolidado MP Planta'!$A$2:$M$823,13,0),"") -> Gramos | E12: 1.99 | F12: =IFERROR(C12*E12,"") -> 119.4 | G12: =IFERROR(F12/$F$71,"") -> 0.016879577 | H12: 101150
A13: 100 | B13: =IFERROR(VLOOKUP(H13,'[1]Consolidado MP Planta'!$A$2:$M$823,3,0),"") -> PASTA TOMATE OLD CALI (UND:3.14 K) | C13: =+A13 -> 100 | D13: =IFERROR(VLOOKUP(H13,'[1]Consolidado MP Planta'!$A$2:$M$823,13,0),"") -> Gramos | E13: 1.84 | F13: =IFERROR(C13*E13,"") -> 184 | G13: =IFERROR(F13/$F$71,"") -> 0.026012079 | H13: 10100125
A14: 20 | B14: =IFERROR(VLOOKUP(H14,'[1]Consolidado MP Planta'!$A$2:$M$823,3,0),"") -> CONSOME CONCEN. DE RES (UND:2 K) | C14: =+A14 -> 20 | D14: =IFERROR(VLOOKUP(H14,'[1]Consolidado MP Planta'!$A$2:$M$823,13,0),"") -> Gramos | E14: 4.03 | F14: =IFERROR(C14*E14,"") -> 80.6 | G14: =IFERROR(F14/$F$71,"") -> 0.011394421 | H14: 105000029
A15: 2 | B15: =IFERROR(VLOOKUP(H15,'[1]Consolidado MP Planta'!$A$2:$M$823,3,0),"") -> COMINO (UND:454G) | C15: =+A15 -> 2 | D15: =IFERROR(VLOOKUP(H15,'[1]Consolidado MP Planta'!$A$2:$M$823,13,0),"") -> Gramos | E15: =IFERROR(VLOOKUP(H15,'[1]Consolidado MP Planta'!$A$2:$M$823,12,0),"") -> 6.9052863 | F15: =IFERROR(C15*E15,"") -> 13.810573 | G15: =IFERROR(F15/$F$71,"") -> 0.0019524006 | H15: 610218
A16: 100 | B16: PAN CUADRADO BLANCO (PAQ=22 REBANADAS ) | C16: =+A16 -> 100 | D16: =IFERROR(VLOOKUP(H16,'[1]Consolidado MP Planta'!$A$2:$M$823,13,0),"") -> Gramos | E16: =IFERROR(VLOOKUP(H16,'[1]Consolidado MP Planta'!$A$2:$M$823,12,0),"") -> 1.3820253 | F16: =IFERROR(C16*E16,"") -> 138.20253 | G16: =IFERROR(F16/$F$71,"") -> 0.019537691 | H16: 0710261
A17: 150 | B17: VINO BLANCO (UND: 750 ML) | C17: =+A17 -> 150 | D17: Mililitros | E17: 3.73 | F17: =IFERROR(C17*E17,"") -> 559.5 | G17: =IFERROR(F17/$F$71,"") -> 0.079096511 | H17: 102000004
A18: 200 | B18: =IFERROR(VLOOKUP(H18,'[1]Consolidado MP Planta'!$A$2:$M$823,3,0),"") -> AGUA PLANTA | C18: =+A18 -> 200 | D18: =IFERROR(VLOOKUP(H18,'[1]Consolidado MP Planta'!$A$2:$M$823,13,0),"") -> Mililitros | E18: =IFERROR(VLOOKUP(H18,'[1]Consolidado MP Planta'!$A$2:$M$823,12,0),"") -> 0.1 | F18: =IFERROR(C18*E18,"") -> 20 | G18: =IFERROR(F18/$F$71,"") -> 0.0028273999 | H18: 10415
B19: =IFERROR(VLOOKUP(H19,'[1]Consolidado MP Planta'!$A$2:$M$823,3,0),"") | C19: =+A19 -> 0 | D19: =IFERROR(VLOOKUP(H19,'[1]Consolidado MP Planta'!$A$2:$M$823,13,0),"") | E19: =IFERROR(VLOOKUP(H19,'[1]Consolidado MP Planta'!$A$2:$M$823,12,0),"") | F19: =IFERROR(C19*E19,"") | G19: =IFERROR(F19/$F$71,"")
B20: =IFERROR(VLOOKUP(H20,'[2]ARTICULOS MP PLANTA'!$A$2:$G$589,2,0),"")
A21: UNIDADES | B21: MATERIA PRIMA SEMIELABORADOS | C21: UNIDADES | D21: UND MEDIDA | E21: COSTO UNITARIO | F21: TOTAL COSTO | G21: % PREC. DEFINIDO | H21: CODIGOS
A22: 10 | B22: =IFERROR(VLOOKUP(H22,[1]SEMIELABORADOS!$A$2:$M$6000,2,0),"") -> EMPAQUE SAL KILO | C22: =+A22 -> 10 | D22: =IFERROR(VLOOKUP(H22,[1]SEMIELABORADOS!$A$2:$M$6000,6,0),"") -> Gramo | E22: =IFERROR(VLOOKUP(H22,[1]SEMIELABORADOS!$A$2:$H$65536,8,0),"") -> 0.31248 | F22: =IFERROR(E22*C22,"") -> 3.1248 | G22: =IFERROR(F22/$F$71,"") -> 0.00044175295 | H22: 90100142
A23: 500 | B23: COCCION CARNE CECINA P/MECHAR (KILO) | C23: =+A23 -> 500 | D23: Gramo | E23: 8.84 | F23: =IFERROR(E23*C23,"") -> 4420 | G23: =IFERROR(F23/$F$71,"") -> 0.62485537 | H23: 908000040
B24: =IFERROR(VLOOKUP(H24,[1]SEMIELABORADOS!$A$2:$M$6000,2,0),"") | C24: =+A24 -> 0 | D24: =IFERROR(VLOOKUP(H24,[1]SEMIELABORADOS!$A$2:$M$6000,6,0),"") | E24: =IFERROR(VLOOKUP(H24,[1]SEMIELABORADOS!$A$2:$H$65536,8,0),"") | F24: =IFERROR(E24*C24,"") | G24: =IFERROR(F24/$F$71,"")
B25: =IFERROR(VLOOKUP(H25,[1]SEMIELABORADOS!$A$2:$M$6000,2,0),"") | C25: =+A25 -> 0 | D25: =IFERROR(VLOOKUP(H25,[1]SEMIELABORADOS!$A$2:$M$6000,6,0),"") | E25: =IFERROR(VLOOKUP(H25,[1]SEMIELABORADOS!$A$2:$H$65536,8,0),"") | F25: =IFERROR(E25*C25,"") | G25: =IFERROR(F25/$F$71,"")
B26: =IFERROR(VLOOKUP(H26,[1]SEMIELABORADOS!$A$2:$M$6000,2,0),"") | C26: =+A26 -> 0 | D26: =IFERROR(VLOOKUP(H26,[1]SEMIELABORADOS!$A$2:$M$6000,6,0),"") | E26: =IFERROR(VLOOKUP(H26,[1]SEMIELABORADOS!$A$2:$H$65536,8,0),"") | F26: =IFERROR(E26*C26,"") | G26: =IFERROR(F26/$F$71,"")
B27: =IFERROR(VLOOKUP(H27,[1]SEMIELABORADOS!$A$2:$M$6000,2,0),"") | C27: =+A27 -> 0 | D27: =IFERROR(VLOOKUP(H27,[1]SEMIELABORADOS!$A$2:$M$6000,6,0),"") | E27: =IFERROR(VLOOKUP(H27,[1]SEMIELABORADOS!$A$2:$H$65536,8,0),"") | F27: =IFERROR(E27*C27,"") | G27: =IFERROR(F27/$F$71,"")
B28: =IFERROR(VLOOKUP(H28,[1]SEMIELABORADOS!$A$2:$M$6000,2,0),"") | C28: =+A28 -> 0 | D28: =IFERROR(VLOOKUP(H28,[1]SEMIELABORADOS!$A$2:$M$6000,6,0),"") | E28: =IFERROR(VLOOKUP(H28,[1]SEMIELABORADOS!$A$2:$H$65536,8,0),"") | F28: =IFERROR(E28*C28,"") | G28: =IFERROR(F28/$F$71,"")
B29: =IFERROR(VLOOKUP(H29,[1]SEMIELABORADOS!$A$2:$M$6000,2,0),"") | C29: =+A29 -> 0 | D29: =IFERROR(VLOOKUP(H29,[1]SEMIELABORADOS!$A$2:$M$6000,6,0),"") | E29: =IFERROR(VLOOKUP(H29,[1]SEMIELABORADOS!$A$2:$H$65536,8,0),"") | F29: =IFERROR(E29*C29,"") | G29: =IFERROR(F29/$F$71,"")
A31: UNIDADES | B31: EMPAQUE | C31: UNIDADES | D31: UND MEDIDA | E31: COSTO UNITARIO | F31: TOTAL COSTO | G31: % PREC. DEFINIDO | H31: CODIGOS
A32: 0 | B32: =IFERROR(VLOOKUP(H32,'[1]Consolidado MP Planta'!$A$2:$M$823,3,0),"") | C32: =+A32 -> 0 | D32: =IFERROR(VLOOKUP(H32,'[1]Consolidado MP Planta'!$A$2:$M$823,13,0),"") | E32: =IFERROR(VLOOKUP(H32,'[1]Consolidado MP Planta'!$A$2:$M$823,12,0),"") | F32: =IFERROR(C32*E32,"") | G32: =IFERROR(F32/$F$71,"")
B33: =IFERROR(VLOOKUP(H33,'[1]Consolidado MP Planta'!$A$2:$M$823,3,0),"") | C33: =+A33 -> 0 | D33: =IFERROR(VLOOKUP(H33,'[1]Consolidado MP Planta'!$A$2:$M$823,13,0),"") | E33: =IFERROR(VLOOKUP(H33,'[1]Consolidado MP Planta'!$A$2:$M$823,12,0),"") | F33: =IFERROR(C33*E33,"") | G33: =IFERROR(F33/$F$71,"")
B34: =IFERROR(VLOOKUP(H34,'[1]Consolidado MP Planta'!$A$2:$M$823,3,0),"") | C34: =+A34 -> 0 | D34: =IFERROR(VLOOKUP(H34,'[1]Consolidado MP Planta'!$A$2:$M$823,13,0),"") | E34: =IFERROR(VLOOKUP(H34,'[1]Consolidado MP Planta'!$A$2:$M$823,12,0),"") | F34: =IFERROR(C34*E34,"") | G34: =IFERROR(F34/$F$71,"")
B35: =IFERROR(VLOOKUP(H35,'[1]Consolidado MP Planta'!$A$2:$M$823,3,0),"") | C35: =+A35 -> 0 | D35: =IFERROR(VLOOKUP(H35,'[1]Consolidado MP Planta'!$A$2:$M$823,13,0),"") | E35: =IFERROR(VLOOKUP(H35,'[1]Consolidado MP Planta'!$A$2:$M$823,12,0),"") | F35: =IFERROR(C35*E35,"") | G35: =IFERROR(F35/$F$71,"")
B36: =IFERROR(VLOOKUP(H36,'[1]Consolidado MP Planta'!$A$2:$M$823,3,0),"") | C36: =+A36 -> 0 | D36: =IFERROR(VLOOKUP(H36,'[1]Consolidado MP Planta'!$A$2:$M$823,13,0),"") | E36: =IFERROR(VLOOKUP(H36,'[1]Consolidado MP Planta'!$A$2:$M$823,12,0),"") | F36: =IFERROR(C36*E36,"") | G36: =IFERROR(F36/$F$71,"")
B37: =IFERROR(VLOOKUP(H37,'[1]Consolidado MP Planta'!$A$2:$M$823,3,0),"") | C37: =+A37 -> 0 | D37: =IFERROR(VLOOKUP(H37,'[1]Consolidado MP Planta'!$A$2:$M$823,13,0),"") | E37: =IFERROR(VLOOKUP(H37,'[1]Consolidado MP Planta'!$A$2:$M$823,12,0),"") | F37: =IFERROR(C37*E37,"") | G37: =IFERROR(F37/$F$71,"")
A39: UNIDADES | B39: EMPAQUE SEMIELABORADOS | C39: UNIDADES | D39: UND MEDIDA | E39: COSTO UNITARIO | F39: TOTAL COSTO | G39: % PREC. DEFINIDO | H39: CODIGOS
A40: =+A22 -> 10 | B40: =IFERROR(VLOOKUP(H40,[1]SEMIELABORADOS!$A$2:$M$6000,2,0),"") -> EMPAQUE SAL KILO | C40: =+A40 -> 10 | D40: =IFERROR(VLOOKUP(H40,[1]SEMIELABORADOS!$A$2:$M$6000,6,0),"") -> Gramo | E40: =IFERROR(VLOOKUP(H40,[1]SEMIELABORADOS!$A$2:$M$65536,10,0),"") -> 0.0036256 | F40: =IFERROR(E40*C40,"") -> 0.036256 | G40: =IFERROR(F40/$F$71,"") -> 5.1255105e-06 | H40: 90100142
A41: =+A23 -> 500 | B41: COCCION CARNE CECINA P/MECHAR (KILO) | C41: =+A41 -> 500 | D41: Gramo | E41: 0 | F41: =IFERROR(E41*C41,"") -> 0 | G41: =IFERROR(F41/$F$71,"") -> 0 | H41: 908000040
A42: =+A24 -> 0 | B42: =IFERROR(VLOOKUP(H42,[1]SEMIELABORADOS!$A$2:$M$6000,2,0),"") | C42: =+A42 -> 0 | D42: =IFERROR(VLOOKUP(H42,[1]SEMIELABORADOS!$A$2:$M$6000,6,0),"") | E42: =IFERROR(VLOOKUP(H42,[1]SEMIELABORADOS!$A$2:$M$65536,10,0),"") | F42: =IFERROR(E42*C42,"") | G42: =IFERROR(F42/$F$71,"")
A43: =+A25 -> 0 | B43: =IFERROR(VLOOKUP(H43,[1]SEMIELABORADOS!$A$2:$M$6000,2,0),"") | C43: =+A43 -> 0 | D43: =IFERROR(VLOOKUP(H43,[1]SEMIELABORADOS!$A$2:$M$6000,6,0),"") | E43: =IFERROR(VLOOKUP(H43,[1]SEMIELABORADOS!$A$2:$M$65536,10,0),"") | F43: =IFERROR(E43*C43,"") | G43: =IFERROR(F43/$F$71,"")
A44: =+A26 -> 0 | B44: =IFERROR(VLOOKUP(H44,[1]SEMIELABORADOS!$A$2:$M$6000,2,0),"") | C44: =+A44 -> 0 | D44: =IFERROR(VLOOKUP(H44,[1]SEMIELABORADOS!$A$2:$M$6000,6,0),"") | E44: =IFERROR(VLOOKUP(H44,[1]SEMIELABORADOS!$A$2:$M$65536,10,0),"") | F44: =IFERROR(E44*C44,"") | G44: =IFERROR(F44/$F$71,"")
...

Sheet costo Empanada 
E1: Precio Local | F1: Costo MP | G1: Costo EM | H1: Costo MO
E2: =IFERROR(O62,"") -> 339.2428 | F2: =IFERROR(H53,"") -> 337.51252 | G2: =IFERROR(H54,"") -> 0.62105184 | H2: =IFERROR(H56,"") -> 34.115953
A5: ESTRUCTURA DE COSTOS
F6: Fecha: | H6: =TODAY() -> 46078
A7: UNIDADES | B7: DESCRIPCION MAT.PRIMA | C7: UNIDADES | D7: UND MEDIDA | E7: COSTO UNITARIO | F7: TOTAL COSTO | G7: % PREC. DEFINIDO | H7: CODIGOS
A8: 16 | B8: =IFERROR(VLOOKUP(H8,'[1]Consolidado MP Planta'!$A$2:$M$823,3,0),"") -> YEMA DE HUEVO PASTEURIZADA (CAJA:2 Kg) | C8: =+A8 -> 16 | D8: =IFERROR(VLOOKUP(H8,'[1]Consolidado MP Planta'!$A$2:$M$823,13,0),"") -> Gramos | E8: 2.73 | F8: =IFERROR(C8*E8,"") -> 43.68 | G8: =IFERROR(F8/$F$66,"") -> 0.0021046516 | H8: 1210443
B9: =IFERROR(VLOOKUP(H9,'[1]Consolidado MP Planta'!$A$2:$M$823,3,0),"") | C9: =+A9 -> 0 | D9: =IFERROR(VLOOKUP(H9,'[1]Consolidado MP Planta'!$A$2:$M$823,13,0),"") | E9: =IFERROR(VLOOKUP(H9,'[1]Consolidado MP Planta'!$A$2:$M$823,12,0),"") | F9: =IFERROR(C9*E9,"") | G9: =IFERROR(F9/$F$66,"")
B10: =IFERROR(VLOOKUP(H10,'[1]Consolidado MP Planta'!$A$2:$M$823,3,0),"") | C10: =+A10 -> 0 | D10: =IFERROR(VLOOKUP(H10,'[1]Consolidado MP Planta'!$A$2:$M$823,13,0),"") | E10: =IFERROR(VLOOKUP(H10,'[1]Consolidado MP Planta'!$A$2:$M$823,12,0),"") | F10: =IFERROR(C10*E10,"") | G10: =IFERROR(F10/$F$66,"")
B11: =IFERROR(VLOOKUP(H11,'[1]Consolidado MP Planta'!$A$2:$M$823,3,0),"") | C11: =+A11 -> 0 | D11: =IFERROR(VLOOKUP(H11,'[1]Consolidado MP Planta'!$A$2:$M$823,13,0),"") | E11: =IFERROR(VLOOKUP(H11,'[1]Consolidado MP Planta'!$A$2:$M$823,12,0),"") | F11: =IFERROR(C11*E11,"") | G11: =IFERROR(F11/$F$66,"")
B12: =IFERROR(VLOOKUP(H12,'[1]Consolidado MP Planta'!$A$2:$M$823,3,0),"") | C12: =+A12 -> 0 | D12: =IFERROR(VLOOKUP(H12,'[1]Consolidado MP Planta'!$A$2:$M$823,13,0),"") | E12: =IFERROR(VLOOKUP(H12,'[1]Consolidado MP Planta'!$A$2:$M$823,12,0),"") | F12: =IFERROR(C12*E12,"") | G12: =IFERROR(F12/$F$66,"")
B13: =IFERROR(VLOOKUP(H13,'[1]Consolidado MP Planta'!$A$2:$M$823,3,0),"") | C13: =+A13 -> 0 | D13: =IFERROR(VLOOKUP(H13,'[1]Consolidado MP Planta'!$A$2:$M$823,13,0),"") | E13: =IFERROR(VLOOKUP(H13,'[1]Consolidado MP Planta'!$A$2:$M$823,12,0),"") | F13: =IFERROR(C13*E13,"") | G13: =IFERROR(F13/$F$66,"")
B14: =IFERROR(VLOOKUP(H14,'[1]Consolidado MP Planta'!$A$2:$M$823,3,0),"") | C14: =+A14 -> 0 | D14: =IFERROR(VLOOKUP(H14,'[1]Consolidado MP Planta'!$A$2:$M$823,13,0),"") | E14: =IFERROR(VLOOKUP(H14,'[1]Consolidado MP Planta'!$A$2:$M$823,12,0),"") | F14: =IFERROR(C14*E14,"") | G14: =IFERROR(F14/$F$66,"")
B15: =IFERROR(VLOOKUP(H15,'[2]ARTICULOS MP PLANTA'!$A$2:$G$589,2,0),"")
A16: UNIDADES | B16: MATERIA PRIMA SEMIELABORADOS | C16: UNIDADES | D16: UND MEDIDA | E16: COSTO UNITARIO | F16: TOTAL COSTO | G16: % PREC. DEFINIDO | H16: CODIGOS
A17: 60 | B17: =IFERROR(VLOOKUP(H17,[1]SEMIELABORADOS!$A$2:$M$6000,2,0),"") -> RUEDA FROLA 14 CM | C17: =+A17 -> 60 | D17: =IFERROR(VLOOKUP(H17,[1]SEMIELABORADOS!$A$2:$M$6000,6,0),"") -> Und | E17: 62.24 | F17: =IFERROR(E17*C17,"") -> 3734.4 | G17: =IFERROR(F17/$F$66,"") -> 0.17993615 | H17: 903000144
A18: 3000 | B18: RELLENO CARNE MECHADA | C18: =+A18 -> 3000 | D18: Gramos | E18: =+'Costo Relleno'!E74 -> 5.4800659 | F18: =IFERROR(E18*C18,"") -> 16440.198 | G18: =IFERROR(F18/$F$66,"") -> 0.79214487 | H18: NUEVO
A19: 50 | B19: =IFERROR(VLOOKUP(H19,[1]SEMIELABORADOS!$A$2:$M$6000,2,0),"") -> EMPAQUE HARINA ESTANDAR (KILO) | C19: =+A19 -> 50 | D19: =IFERROR(VLOOKUP(H19,[1]SEMIELABORADOS!$A$2:$M$6000,6,0),"") -> Gramo | E19: =IFERROR(VLOOKUP(H19,[1]SEMIELABORADOS!$A$2:$H$65536,8,0),"") -> 0.64946406 | F19: =IFERROR(E19*C19,"") -> 32.473203 | G19: =IFERROR(F19/$F$66,"") -> 0.0015646698 | H19: 90100137
B20: =IFERROR(VLOOKUP(H20,[1]SEMIELABORADOS!$A$2:$M$6000,2,0),"") | C20: =+A20 -> 0 | D20: =IFERROR(VLOOKUP(H20,[1]SEMIELABORADOS!$A$2:$M$6000,6,0),"") | E20: =IFERROR(VLOOKUP(H20,[1]SEMIELABORADOS!$A$2:$H$65536,8,0),"") | F20: =IFERROR(E20*C20,"") | G20: =IFERROR(F20/$F$66,"")
B21: =IFERROR(VLOOKUP(H21,[1]SEMIELABORADOS!$A$2:$M$6000,2,0),"") | C21: =+A21 -> 0 | D21: =IFERROR(VLOOKUP(H21,[1]SEMIELABORADOS!$A$2:$M$6000,6,0),"") | E21: =IFERROR(VLOOKUP(H21,[1]SEMIELABORADOS!$A$2:$H$65536,8,0),"") | F21: =IFERROR(E21*C21,"") | G21: =IFERROR(F21/$F$66,"")
B22: =IFERROR(VLOOKUP(H22,[1]SEMIELABORADOS!$A$2:$M$6000,2,0),"") | C22: =+A22 -> 0 | D22: =IFERROR(VLOOKUP(H22,[1]SEMIELABORADOS!$A$2:$M$6000,6,0),"") | E22: =IFERROR(VLOOKUP(H22,[1]SEMIELABORADOS!$A$2:$H$65536,8,0),"") | F22: =IFERROR(E22*C22,"") | G22: =IFERROR(F22/$F$66,"")
B23: =IFERROR(VLOOKUP(H23,[1]SEMIELABORADOS!$A$2:$M$6000,2,0),"") | C23: =+A23 -> 0 | D23: =IFERROR(VLOOKUP(H23,[1]SEMIELABORADOS!$A$2:$M$6000,6,0),"") | E23: =IFERROR(VLOOKUP(H23,[1]SEMIELABORADOS!$A$2:$H$65536,8,0),"") | F23: =IFERROR(E23*C23,"") | G23: =IFERROR(F23/$F$66,"")
B24: =IFERROR(VLOOKUP(H24,[1]SEMIELABORADOS!$A$2:$M$6000,2,0),"") | C24: =+A24 -> 0 | D24: =IFERROR(VLOOKUP(H24,[1]SEMIELABORADOS!$A$2:$M$6000,6,0),"") | E24: =IFERROR(VLOOKUP(H24,[1]SEMIELABORADOS!$A$2:$H$65536,8,0),"") | F24: =IFERROR(E24*C24,"") | G24: =IFERROR(F24/$F$66,"")
A26: UNIDADES | B26: EMPAQUE | C26: UNIDADES | D26: UND MEDIDA | E26: COSTO UNITARIO | F26: TOTAL COSTO | G26: % PREC. DEFINIDO | H26: CODIGOS
A27: 0.25 | B27: =IFERROR(VLOOKUP(H27,'[1]Consolidado MP Planta'!$A$2:$M$823,3,0),"") -> PAPEL MANTEQUILLA (CAJA= 1000 UND) | C27: =+A27 -> 0.25 | D27: =IFERROR(VLOOKUP(H27,'[1]Consolidado MP Planta'!$A$2:$M$823,13,0),"") -> Und | E27: 43.5 | F27: =IFERROR(C27*E27,"") -> 10.875 | G27: =IFERROR(F27/$F$66,"") -> 0.00052399464 | H27: 0906036
B28: =IFERROR(VLOOKUP(H28,'[1]Consolidado MP Planta'!$A$2:$M$823,3,0),"") | C28: =+A28 -> 0 | D28: =IFERROR(VLOOKUP(H28,'[1]Consolidado MP Planta'!$A$2:$M$823,13,0),"") | E28: =IFERROR(VLOOKUP(H28,'[1]Consolidado MP Planta'!$A$2:$M$823,12,0),"") | F28: =IFERROR(C28*E28,"") | G28: =IFERROR(F28/$F$66,"")
B29: =IFERROR(VLOOKUP(H29,'[1]Consolidado MP Planta'!$A$2:$M$823,3,0),"") | C29: =+A29 -> 0 | D29: =IFERROR(VLOOKUP(H29,'[1]Consolidado MP Planta'!$A$2:$M$823,13,0),"") | E29: =IFERROR(VLOOKUP(H29,'[1]Consolidado MP Planta'!$A$2:$M$823,12,0),"") | F29: =IFERROR(C29*E29,"") | G29: =IFERROR(F29/$F$66,"")
B30: =IFERROR(VLOOKUP(H30,'[1]Consolidado MP Planta'!$A$2:$M$823,3,0),"") | C30: =+A30 -> 0 | D30: =IFERROR(VLOOKUP(H30,'[1]Consolidado MP Planta'!$A$2:$M$823,13,0),"") | E30: =IFERROR(VLOOKUP(H30,'[1]Consolidado MP Planta'!$A$2:$M$823,12,0),"") | F30: =IFERROR(C30*E30,"") | G30: =IFERROR(F30/$F$66,"")
B31: =IFERROR(VLOOKUP(H31,'[1]Consolidado MP Planta'!$A$2:$M$823,3,0),"") | C31: =+A31 -> 0 | D31: =IFERROR(VLOOKUP(H31,'[1]Consolidado MP Planta'!$A$2:$M$823,13,0),"") | E31: =IFERROR(VLOOKUP(H31,'[1]Consolidado MP Planta'!$A$2:$M$823,12,0),"") | F31: =IFERROR(C31*E31,"") | G31: =IFERROR(F31/$F$66,"")
B32: =IFERROR(VLOOKUP(H32,'[1]Consolidado MP Planta'!$A$2:$M$823,3,0),"") | C32: =+A32 -> 0 | D32: =IFERROR(VLOOKUP(H32,'[1]Consolidado MP Planta'!$A$2:$M$823,13,0),"") | E32: =IFERROR(VLOOKUP(H32,'[1]Consolidado MP Planta'!$A$2:$M$823,12,0),"") | F32: =IFERROR(C32*E32,"") | G32: =IFERROR(F32/$F$66,"")
A34: UNIDADES | B34: EMPAQUE SEMIELABORADOS | C34: UNIDADES | D34: UND MEDIDA | E34: COSTO UNITARIO | F34: TOTAL COSTO | G34: % PREC. DEFINIDO | H34: CODIGOS
A35: =+A17 -> 60 | B35: =IFERROR(VLOOKUP(H35,[1]SEMIELABORADOS!$A$2:$M$6000,2,0),"") -> RUEDA FROLA 14 CM | C35: =+A35 -> 60 | D35: =IFERROR(VLOOKUP(H35,[1]SEMIELABORADOS!$A$2:$M$6000,6,0),"") -> Und | E35: 0.43 | F35: =IFERROR(E35*C35,"") -> 25.8 | G35: =IFERROR(F35/$F$66,"") -> 0.0012431321 | H35: 903000144
A36: =+A18 -> 3000 | B36: RELLENO CARNE MECHADA | C36: =+A36 -> 3000 | D36: Gramos | E36: =+'Costo Relleno'!E81 -> 3.0213333e-05 | F36: =IFERROR(E36*C36,"") -> 0.09064 | G36: =IFERROR(F36/$F$66,"") -> 4.3673448e-06 | H36: NUEVO
A37: =+A19 -> 50 | B37: =IFERROR(VLOOKUP(H37,[1]SEMIELABORADOS!$A$2:$M$6000,2,0),"") -> EMPAQUE HARINA ESTANDAR (KILO) | C37: =+A37 -> 50 | D37: =IFERROR(VLOOKUP(H37,[1]SEMIELABORADOS!$A$2:$M$6000,6,0),"") -> Gramo | E37: =IFERROR(VLOOKUP(H37,[1]SEMIELABORADOS!$A$2:$M$65536,10,0),"") -> 0.0099494095 | F37: =IFERROR(E37*C37,"") -> 0.49747048 | G37: =IFERROR(F37/$F$66,"") -> 2.3969827e-05 | H37: 90100137
A38: =+A20 -> 0 | B38: =IFERROR(VLOOKUP(H38,[1]SEMIELABORADOS!$A$2:$M$6000,2,0),"") | C38: =+A38 -> 0 | D38: =IFERROR(VLOOKUP(H38,[1]SEMIELABORADOS!$A$2:$M$6000,6,0),"") | E38: =IFERROR(VLOOKUP(H38,[1]SEMIELABORADOS!$A$2:$M$65536,10,0),"") | F38: =IFERROR(E38*C38,"") | G38: =IFERROR(F38/$F$66,"")
A39: =+A21 -> 0 | B39: =IFERROR(VLOOKUP(H39,[1]SEMIELABORADOS!$A$2:$M$6000,2,0),"") | C39: =+A39 -> 0 | D39: =IFERROR(VLOOKUP(H39,[1]SEMIELABORADOS!$A$2:$M$6000,6,0),"") | E39: =IFERROR(VLOOKUP(H39,[1]SEMIELABORADOS!$A$2:$M$65536,10,0),"") | F39: =IFERROR(E39*C39,"") | G39: =IFERROR(F39/$F$66,"")
A40: =+A22 -> 0 | B40: =IFERROR(VLOOKUP(H40,[1]SEMIELABORADOS!$A$2:$M$6000,2,0),"") | C40: =+A40 -> 0 | D40: =IFERROR(VLOOKUP(H40,[1]SEMIELABORADOS!$A$2:$M$6000,6,0),"") | E40: =IFERROR(VLOOKUP(H40,[1]SEMIELABORADOS!$A$2:$M$65536,10,0),"") | F40: =IFERROR(E40*C40,"") | G40: =IFERROR(F40/$F$66,"")
A41: =+A23 -> 0 | B41: =IFERROR(VLOOKUP(H41,[1]SEMIELABORADOS!$A$2:$M$6000,2,0),"") | C41: =+A41 -> 0 | D41: =IFERROR(VLOOKUP(H41,[1]SEMIELABORADOS!$A$2:$M$6000,6,0),"") | E41: =IFERROR(VLOOKUP(H41,[1]SEMIELABORADOS!$A$2:$M$65536,10,0),"") | F41: =IFERROR(E41*C41,"") | G41: =IFERROR(F41/$F$66,"")
A43: UNIDADES | B43: MODI | C43: UNIDADES | D43: UND MEDIDA | E43: COSTO UNITARIO | F43: TOTAL COSTO | G43: % PREC. DEFINIDO | H43: CODIGOS
A44: =+A35 -> 60 | B44: =IFERROR(VLOOKUP(H44,[1]SEMIELABORADOS!$A$2:$M$6000,2,0),"") -> RUEDA FROLA 14 CM | C44: =+A44 -> 60 | D44: =IFERROR(VLOOKUP(H44,[1]SEMIELABORADOS!$A$2:$M$6000,6,0),"") -> Und | E44: 13.56 | F44: =IFERROR(E44*C44,"") -> 813.6 | G44: =IFERROR(F44/$F$66,"") -> 0.039202027 | H44: 903000144
A45: =+A36 -> 3000 | B45: RELLENO CARNE MECHADA | C45: =+A45 -> 3000 | D45: Gramos | E45: =+'Costo Relleno'!E79 -> 0.38880749 | F45: =IFERROR(E45*C45,"") -> 1166.4225 | G45: =IFERROR(F45/$F$66,"") -> 0.056202219 | H45: NUEVO
...

Sheet Costo Empaque
E1: Precio Local | F1: Costo MP | G1: Costo EM | H1: Costo MO
E2: =IFERROR(O62,"") -> 402.21709 | F2: =IFERROR(H53,"") -> 337.51252 | G2: =IFERROR(H54,"") -> 33.191052 | H2: =IFERROR(H56,"") -> 64.615953
A5: ESTRUCTURA DE COSTOS
F6: Fecha: | H6: =TODAY() -> 46078
A7: UNIDADES | B7: DESCRIPCION MAT.PRIMA | C7: UNIDADES | D7: UND MEDIDA | E7: COSTO UNITARIO | F7: TOTAL COSTO | G7: % PREC. DEFINIDO | H7: CODIGOS
B8: =IFERROR(VLOOKUP(H8,'[1]Consolidado MP Planta'!$A$2:$M$823,3,0),"") | C8: =+A8 -> 0 | D8: =IFERROR(VLOOKUP(H8,'[1]Consolidado MP Planta'!$A$2:$M$823,13,0),"") | E8: =IFERROR(VLOOKUP(H8,'[1]Consolidado MP Planta'!$A$2:$M$823,12,0),"") | F8: =IFERROR(C8*E8,"") | G8: =IFERROR(F8/$F$66,"")
B9: =IFERROR(VLOOKUP(H9,'[1]Consolidado MP Planta'!$A$2:$M$823,3,0),"") | C9: =+A9 -> 0 | D9: =IFERROR(VLOOKUP(H9,'[1]Consolidado MP Planta'!$A$2:$M$823,13,0),"") | E9: =IFERROR(VLOOKUP(H9,'[1]Consolidado MP Planta'!$A$2:$M$823,12,0),"") | F9: =IFERROR(C9*E9,"") | G9: =IFERROR(F9/$F$66,"")
B10: =IFERROR(VLOOKUP(H10,'[1]Consolidado MP Planta'!$A$2:$M$823,3,0),"") | C10: =+A10 -> 0 | D10: =IFERROR(VLOOKUP(H10,'[1]Consolidado MP Planta'!$A$2:$M$823,13,0),"") | E10: =IFERROR(VLOOKUP(H10,'[1]Consolidado MP Planta'!$A$2:$M$823,12,0),"") | F10: =IFERROR(C10*E10,"") | G10: =IFERROR(F10/$F$66,"")
B11: =IFERROR(VLOOKUP(H11,'[1]Consolidado MP Planta'!$A$2:$M$823,3,0),"") | C11: =+A11 -> 0 | D11: =IFERROR(VLOOKUP(H11,'[1]Consolidado MP Planta'!$A$2:$M$823,13,0),"") | E11: =IFERROR(VLOOKUP(H11,'[1]Consolidado MP Planta'!$A$2:$M$823,12,0),"") | F11: =IFERROR(C11*E11,"") | G11: =IFERROR(F11/$F$66,"")
B12: =IFERROR(VLOOKUP(H12,'[1]Consolidado MP Planta'!$A$2:$M$823,3,0),"") | C12: =+A12 -> 0 | D12: =IFERROR(VLOOKUP(H12,'[1]Consolidado MP Planta'!$A$2:$M$823,13,0),"") | E12: =IFERROR(VLOOKUP(H12,'[1]Consolidado MP Planta'!$A$2:$M$823,12,0),"") | F12: =IFERROR(C12*E12,"") | G12: =IFERROR(F12/$F$66,"")
B13: =IFERROR(VLOOKUP(H13,'[1]Consolidado MP Planta'!$A$2:$M$823,3,0),"") | C13: =+A13 -> 0 | D13: =IFERROR(VLOOKUP(H13,'[1]Consolidado MP Planta'!$A$2:$M$823,13,0),"") | E13: =IFERROR(VLOOKUP(H13,'[1]Consolidado MP Planta'!$A$2:$M$823,12,0),"") | F13: =IFERROR(C13*E13,"") | G13: =IFERROR(F13/$F$66,"")
B14: =IFERROR(VLOOKUP(H14,'[1]Consolidado MP Planta'!$A$2:$M$823,3,0),"") | C14: =+A14 -> 0 | D14: =IFERROR(VLOOKUP(H14,'[1]Consolidado MP Planta'!$A$2:$M$823,13,0),"") | E14: =IFERROR(VLOOKUP(H14,'[1]Consolidado MP Planta'!$A$2:$M$823,12,0),"") | F14: =IFERROR(C14*E14,"") | G14: =IFERROR(F14/$F$66,"")
B15: =IFERROR(VLOOKUP(H15,'[2]ARTICULOS MP PLANTA'!$A$2:$G$589,2,0),"")
A16: UNIDADES | B16: MATERIA PRIMA SEMIELABORADOS | C16: UNIDADES | D16: UND MEDIDA | E16: COSTO UNITARIO | F16: TOTAL COSTO | G16: % PREC. DEFINIDO | H16: CODIGOS
A17: 4 | B17: EMPANADA CARNE MECHADA TRADICIONAL | C17: =+A17 -> 4 | D17: und | E17: =+'costo Empanada '!H53 -> 337.51252 | F17: =IFERROR(E17*C17,"") -> 1350.0501 | G17: =IFERROR(F17/$F$66,"") -> 0.8273302
B18: =IFERROR(VLOOKUP(H18,[1]SEMIELABORADOS!$A$2:$M$6000,2,0),"") | C18: =+A18 -> 0 | D18: =IFERROR(VLOOKUP(H18,[1]SEMIELABORADOS!$A$2:$M$6000,6,0),"") | E18: =IFERROR(VLOOKUP(H18,[1]SEMIELABORADOS!$A$2:$H$65536,8,0),"") | F18: =IFERROR(E18*C18,"") | G18: =IFERROR(F18/$F$66,"")
B19: =IFERROR(VLOOKUP(H19,[1]SEMIELABORADOS!$A$2:$M$6000,2,0),"") | C19: =+A19 -> 0 | D19: =IFERROR(VLOOKUP(H19,[1]SEMIELABORADOS!$A$2:$M$6000,6,0),"") | E19: =IFERROR(VLOOKUP(H19,[1]SEMIELABORADOS!$A$2:$H$65536,8,0),"") | F19: =IFERROR(E19*C19,"") | G19: =IFERROR(F19/$F$66,"")
B20: =IFERROR(VLOOKUP(H20,[1]SEMIELABORADOS!$A$2:$M$6000,2,0),"") | C20: =+A20 -> 0 | D20: =IFERROR(VLOOKUP(H20,[1]SEMIELABORADOS!$A$2:$M$6000,6,0),"") | E20: =IFERROR(VLOOKUP(H20,[1]SEMIELABORADOS!$A$2:$H$65536,8,0),"") | F20: =IFERROR(E20*C20,"") | G20: =IFERROR(F20/$F$66,"")
B21: =IFERROR(VLOOKUP(H21,[1]SEMIELABORADOS!$A$2:$M$6000,2,0),"") | C21: =+A21 -> 0 | D21: =IFERROR(VLOOKUP(H21,[1]SEMIELABORADOS!$A$2:$M$6000,6,0),"") | E21: =IFERROR(VLOOKUP(H21,[1]SEMIELABORADOS!$A$2:$H$65536,8,0),"") | F21: =IFERROR(E21*C21,"") | G21: =IFERROR(F21/$F$66,"")
B22: =IFERROR(VLOOKUP(H22,[1]SEMIELABORADOS!$A$2:$M$6000,2,0),"") | C22: =+A22 -> 0 | D22: =IFERROR(VLOOKUP(H22,[1]SEMIELABORADOS!$A$2:$M$6000,6,0),"") | E22: =IFERROR(VLOOKUP(H22,[1]SEMIELABORADOS!$A$2:$H$65536,8,0),"") | F22: =IFERROR(E22*C22,"") | G22: =IFERROR(F22/$F$66,"")
B23: =IFERROR(VLOOKUP(H23,[1]SEMIELABORADOS!$A$2:$M$6000,2,0),"") | C23: =+A23 -> 0 | D23: =IFERROR(VLOOKUP(H23,[1]SEMIELABORADOS!$A$2:$M$6000,6,0),"") | E23: =IFERROR(VLOOKUP(H23,[1]SEMIELABORADOS!$A$2:$H$65536,8,0),"") | F23: =IFERROR(E23*C23,"") | G23: =IFERROR(F23/$F$66,"")
B24: =IFERROR(VLOOKUP(H24,[1]SEMIELABORADOS!$A$2:$M$6000,2,0),"") | C24: =+A24 -> 0 | D24: =IFERROR(VLOOKUP(H24,[1]SEMIELABORADOS!$A$2:$M$6000,6,0),"") | E24: =IFERROR(VLOOKUP(H24,[1]SEMIELABORADOS!$A$2:$H$65536,8,0),"") | F24: =IFERROR(E24*C24,"") | G24: =IFERROR(F24/$F$66,"")
A26: UNIDADES | B26: EMPAQUE | C26: UNIDADES | D26: UND MEDIDA | E26: COSTO UNITARIO | F26: TOTAL COSTO | G26: % PREC. DEFINIDO | H26: CODIGOS
A27: 2 | B27: =IFERROR(VLOOKUP(H27,'[1]Consolidado MP Planta'!$A$2:$M$823,3,0),"") -> CAJA BLANCA MEDIANA (PAQ:100 UND) | C27: =+A27 -> 2 | D27: =IFERROR(VLOOKUP(H27,'[1]Consolidado MP Planta'!$A$2:$M$823,13,0),"") -> Und | E27: 49.75 | F27: =IFERROR(C27*E27,"") -> 99.5 | G27: =IFERROR(F27/$F$66,"") -> 0.060975039 | H27: 1950729
A28: 1 | B28: =IFERROR(VLOOKUP(H28,'[1]Consolidado MP Planta'!$A$2:$M$823,3,0),"") -> PAPEL ENCERADO 10X10 (CAJA) | C28: =+A28 -> 1 | D28: =IFERROR(VLOOKUP(H28,'[1]Consolidado MP Planta'!$A$2:$M$823,13,0),"") -> Und | E28: 14.2 | F28: =IFERROR(C28*E28,"") -> 14.2 | G28: =IFERROR(F28/$F$66,"") -> 0.0087019654 | H28: 1950772
A29: 1 | B29: =IFERROR(VLOOKUP(H29,'[1]Consolidado MP Planta'!$A$2:$M$823,3,0),"") -> ETIQ.BLANCA 1 1/4 * 3/4 (UND) | C29: =+A29 -> 1 | D29: =IFERROR(VLOOKUP(H29,'[1]Consolidado MP Planta'!$A$2:$M$823,13,0),"") -> Und | E29: =IFERROR(VLOOKUP(H29,'[1]Consolidado MP Planta'!$A$2:$M$823,12,0),"") -> 0.58 | F29: =IFERROR(C29*E29,"") -> 0.58 | G29: =IFERROR(F29/$F$66,"") -> 0.00035543239 | H29: 0702069
A30: 1 | B30: =IFERROR(VLOOKUP(H30,'[1]Consolidado MP Planta'!$A$2:$M$823,3,0),"") -> BOLSA 12x18 TRANSP KILO | C30: =+A30 -> 1 | D30: =IFERROR(VLOOKUP(H30,'[1]Consolidado MP Planta'!$A$2:$M$823,13,0),"") -> Und | E30: =IFERROR(VLOOKUP(H30,'[1]Consolidado MP Planta'!$A$2:$M$823,12,0),"") -> 16 | F30: =IFERROR(C30*E30,"") -> 16 | G30: =IFERROR(F30/$F$66,"") -> 0.0098050314 | H30: 1950702
B31: =IFERROR(VLOOKUP(H31,'[1]Consolidado MP Planta'!$A$2:$M$823,3,0),"") | C31: =+A31 -> 0 | D31: =IFERROR(VLOOKUP(H31,'[1]Consolidado MP Planta'!$A$2:$M$823,13,0),"") | E31: =IFERROR(VLOOKUP(H31,'[1]Consolidado MP Planta'!$A$2:$M$823,12,0),"") | F31: =IFERROR(C31*E31,"") | G31: =IFERROR(F31/$F$66,"")
B32: =IFERROR(VLOOKUP(H32,'[1]Consolidado MP Planta'!$A$2:$M$823,3,0),"") | C32: =+A32 -> 0 | D32: =IFERROR(VLOOKUP(H32,'[1]Consolidado MP Planta'!$A$2:$M$823,13,0),"") | E32: =IFERROR(VLOOKUP(H32,'[1]Consolidado MP Planta'!$A$2:$M$823,12,0),"") | F32: =IFERROR(C32*E32,"") | G32: =IFERROR(F32/$F$66,"")
A34: UNIDADES | B34: EMPAQUE SEMIELABORADOS | C34: UNIDADES | D34: UND MEDIDA | E34: COSTO UNITARIO | F34: TOTAL COSTO | G34: % PREC. DEFINIDO | H34: CODIGOS
A35: =+A17 -> 4 | B35: EMPANADA CARNE MECHADA TRADICIONAL | C35: =+A35 -> 4 | D35: und | E35: =+'costo Empanada '!H54 -> 0.62105184 | F35: =IFERROR(E35*C35,"") -> 2.4842074 | G35: =IFERROR(F35/$F$66,"") -> 0.0015223582
A36: =+A18 -> 0 | B36: =IFERROR(VLOOKUP(H36,[1]SEMIELABORADOS!$A$2:$M$6000,2,0),"") | C36: =+A36 -> 0 | D36: =IFERROR(VLOOKUP(H36,[1]SEMIELABORADOS!$A$2:$M$6000,6,0),"") | E36: =IFERROR(VLOOKUP(H36,[1]SEMIELABORADOS!$A$2:$M$65536,10,0),"") | F36: =IFERROR(E36*C36,"") | G36: =IFERROR(F36/$F$66,"")
A37: =+A19 -> 0 | B37: =IFERROR(VLOOKUP(H37,[1]SEMIELABORADOS!$A$2:$M$6000,2,0),"") | C37: =+A37 -> 0 | D37: =IFERROR(VLOOKUP(H37,[1]SEMIELABORADOS!$A$2:$M$6000,6,0),"") | E37: =IFERROR(VLOOKUP(H37,[1]SEMIELABORADOS!$A$2:$M$65536,10,0),"") | F37: =IFERROR(E37*C37,"") | G37: =IFERROR(F37/$F$66,"")
A38: =+A20 -> 0 | B38: =IFERROR(VLOOKUP(H38,[1]SEMIELABORADOS!$A$2:$M$6000,2,0),"") | C38: =+A38 -> 0 | D38: =IFERROR(VLOOKUP(H38,[1]SEMIELABORADOS!$A$2:$M$6000,6,0),"") | E38: =IFERROR(VLOOKUP(H38,[1]SEMIELABORADOS!$A$2:$M$65536,10,0),"") | F38: =IFERROR(E38*C38,"") | G38: =IFERROR(F38/$F$66,"")
A39: =+A21 -> 0 | B39: =IFERROR(VLOOKUP(H39,[1]SEMIELABORADOS!$A$2:$M$6000,2,0),"") | C39: =+A39 -> 0 | D39: =IFERROR(VLOOKUP(H39,[1]SEMIELABORADOS!$A$2:$M$6000,6,0),"") | E39: =IFERROR(VLOOKUP(H39,[1]SEMIELABORADOS!$A$2:$M$65536,10,0),"") | F39: =IFERROR(E39*C39,"") | G39: =IFERROR(F39/$F$66,"")
A40: =+A22 -> 0 | B40: =IFERROR(VLOOKUP(H40,[1]SEMIELABORADOS!$A$2:$M$6000,2,0),"") | C40: =+A40 -> 0 | D40: =IFERROR(VLOOKUP(H40,[1]SEMIELABORADOS!$A$2:$M$6000,6,0),"") | E40: =IFERROR(VLOOKUP(H40,[1]SEMIELABORADOS!$A$2:$M$65536,10,0),"") | F40: =IFERROR(E40*C40,"") | G40: =IFERROR(F40/$F$66,"")
A41: =+A23 -> 0 | B41: =IFERROR(VLOOKUP(H41,[1]SEMIELABORADOS!$A$2:$M$6000,2,0),"") | C41: =+A41 -> 0 | D41: =IFERROR(VLOOKUP(H41,[1]SEMIELABORADOS!$A$2:$M$6000,6,0),"") | E41: =IFERROR(VLOOKUP(H41,[1]SEMIELABORADOS!$A$2:$M$65536,10,0),"") | F41: =IFERROR(E41*C41,"") | G41: =IFERROR(F41/$F$66,"")
A43: UNIDADES | B43: MODI | C43: UNIDADES | D43: UND MEDIDA | E43: COSTO UNITARIO | F43: TOTAL COSTO | G43: % PREC. DEFINIDO | H43: CODIGOS
A44: =+A35 -> 4 | B44: EMPANADA CARNE MECHADA TRADICIONAL | C44: =+A44 -> 4 | D44: und | E44: =+'costo Empanada '!H56 -> 34.115953 | F44: =IFERROR(E44*C44,"") -> 136.46381 | G44: =IFERROR(F44/$F$66,"") -> 0.083626999
A45: =+A36 -> 0 | B45: =IFERROR(VLOOKUP(H45,[1]SEMIELABORADOS!$A$2:$M$6000,2,0),"") | C45: =+A45 -> 0 | D45: =IFERROR(VLOOKUP(H45,[1]SEMIELABORADOS!$A$2:$M$6000,6,0),"") | E45: =IFERROR(VLOOKUP(H45,[1]SEMIELABORADOS!$A$2:$M$65536,12,0),"") | F45: =IFERROR(E45*C45,"") | G45: =IFERROR(F45/$F$66,"")
...
