Workbook

Sheet Emsamble Industria
C1: SERVICIOS DE PASTELERIA S.A. | H1: CÓDIGO:
C2: ESPECIFICACION DE RECETA | H2: REVISIÓN:
C3: Postre Nueces y Dulce Leche Navidad 2024 Industria | H3: FECHA DE APROBACIÓN:
C4: Elaborado | D4: Jose Brizuela, chef
C5: Aprobado | D5: Esteban Cartin, Gte Manufactura
A6: AREA QUE PRODUCE: | D6: Postres | G6: AREA QUE EMPACA: | I6: Postres
A7: # Código | B7: # Codigo Netsuite | C7: Descripción del ingrediente | D7: Marca | E7: Unidad Internacional | G7: Medida alternativa | I7: Costo - Referencia
E8: Cantidad | F8: Unidad medida | G8: Cantidad | H8: Unidad medida | I8: Colones
C9: Emsamble
C10: Rosquete Arrollado Spoon Kilo 100 g | D10: FAS | E10: 70 | F10: g | G10: 1 unidad | H10: Molde # 10 | I10: Circular
C11: Rosquete Arrollado Spoon Kilo 80 g | D11: FAS | E11: 56 | F11: g | G11: 3 unidad | H11: Molde Mini | I11: Circular
C12: Relleno # 1
A13: 908000021 | B13: SE00005 | C13: Almibar | D13: FAS | E13: 30 | F13: g | I13: 1/4 Taza
C14: Relleno de Suspiro con Manjar | D14: FAS | E14: 180 | F14: g | I14: 3/4 taza
C15: Relleno # 2 | F15: g
C16: Rosquete Arrollado Spoon Kilo 80 g | E16: 56 | F16: g
A17: 908000021 | B17: SE00005 | C17: Almibar | D17: FAS | E17: 30 | F17: g
C18: Relleno de Suspiro con Manjar | D18: FAS | E18: 100 | F18: g | I18: 3/4 taza
A19: 96344 | B19: SE00032 | C19: Crema Dulce Leche | D19: FAS | E19: 25 | F19: g | H19: Utilizar Boquilla 804 | I19: Arteco
A20: 905000098 | B20: SE00306 | C20: Pecana Triturada Y Horneada | D20: FAS | E20: 25 | F20: g | I20: 1/4 taza
C21: Relleno # 3 | F21: g
C22: Rosquete Arrollado Spoon Kilo 80 g | E22: 56 | F22: g | G22: 1 unidad
A23: 908000021 | B23: SE00005 | C23: Almibar | D23: FAS | E23: 30 | F23: g
C24: Relleno de Suspiro con Manjar | D24: FAS | E24: 100 | F24: g | I24: 3/4 taza
A25: 96344 | B25: SE00032 | C25: Crema Dulce Leche | D25: FAS | E25: 25 | F25: g | H25: Utilizar Boquilla 804 | I25: Arteco
A26: 905000098 | B26: SE00306 | C26: Pecana Triturada Y Horneada | D26: FAS | E26: 25 | F26: g | I26: 1/4 taza
C27: Relleno # 4
C28: Rosquete Arrollado Spoon Kilo 80 g | E28: 56 | F28: g | G28: 1 unidad
C29: Mousse de Manjar | E29: 350 | F29: g
C30: Decoracion
A31: 96344 | B31: SE00032 | C31: Crema Dulce Leche | D31: FAS | E31: 40 | F31: g | G31: Colocho Boquilla 127 Wilton
C32: Relleno de Suspiro con Manjar | D32: FAS | E32: 100 | F32: g | H32: En el Centro a Raz | I32: 3/4 Taza
A33: 11900028 | B33: MP10562 | C33: Pecana Entera | D33: FAS | E33: 5 | F33: ud | H33: Por postre
C34: Circulos de Chocolate de 7,5 cm | E34: 6 | F34: g | G34: 1 unidad | H34: Color Rojo Navidad
C35: Circulos de chocolate de 5,5 cm | E35: 4 | F35: g | G35: 2 unidades | H35: 2 Dorados
C36: Circulos de chocolate de 5,5 cm | E36: 4 | F36: g | G36: 2 unidades | H36: Color Rojo Navidad
C37: EMPAQUE
A39: 121603 | B39: EM10009 | C39: QUEQUERA RED BASE/DOMO 10 (CAJA:50) | D39: MAYCA | E39: 1 | F39: ud
A40: 1950692 | B40: EM10008 | C40: ORLA CARTON 10" DORADA UND | D40: Mayca | E40: 1 | F40: Ud
A41: 702069 | B41: EM10002 | C41: Etiq.Blanca 1 1/4 * 3/4 | D41: ETIPLAST | E41: 1 | F41: ud
...

Sheet Costo Industria

Sheet Locales
C1: SERVICIOS DE PASTELERIA S.A. | H1: CÓDIGO:
C2: ESPECIFICACION DE RECETA | H2: REVISIÓN:
C3: Postre Nueces y Dulce Leche Navidad 2024 Locales | H3: FECHA DE APROBACIÓN:
C4: Elaborado | D4: Jose Brizuela, chef
C5: Aprobado | D5: Esteban Cartin, Gte Manufactura
A6: AREA QUE PRODUCE: | D6: Postres | G6: AREA QUE EMPACA: | I6: Postres
A7: # Código | B7: # Codigo Netsuite | C7: Descripción del ingrediente | D7: Marca | E7: Unidad Internacional | G7: Medida alternativa | I7: Costo - Referencia
E8: Cantidad | F8: Unidad medida | G8: Cantidad | H8: Unidad medida | I8: Colones
C9: Emsamble
C10: Rosquete Arrollado Spoon Kilo 100 g | D10: FAS | E10: 70 | F10: g | G10: 1 unidad | H10: Molde # 10 | I10: Circular
C11: Rosquete Arrollado Spoon Kilo 80 g | D11: FAS | E11: 56 | F11: g | G11: 1 unidad | H11: Molde Mini | I11: Circular
C12: Relleno # 1
A13: 908000021 | B13: SE00005 | C13: Almibar | D13: FAS | E13: 30 | F13: g | I13: 1/4 Taza
C14: Relleno de Suspiro con Manjar | D14: FAS | E14: 180 | F14: g | I14: 3/4 taza
C15: Relleno # 2 | F15: g
C16: Rosquete Arrollado Spoon Kilo 80 g | E16: 56 | F16: g
A17: 908000021 | B17: SE00005 | C17: Almibar | D17: FAS | E17: 30 | F17: g
C18: Relleno de Suspiro con Manjar | D18: FAS | E18: 100 | F18: g | I18: 3/4 taza
A19: 96344 | B19: SE00032 | C19: Crema Dulce Leche | D19: FAS | E19: 25 | F19: g | H19: Utilizar Boquilla 804 | I19: Arteco
A20: 905000098 | B20: SE00306 | C20: Pecana Triturada Y Horneada | D20: FAS | E20: 25 | F20: g | I20: 1/4 taza
C21: Relleno # 3 | F21: g
C22: Batido Rosquete Arrollado Spoon Kilo 80 g | E22: 56 | F22: g
A23: 908000021 | B23: SE00005 | C23: Almibar | D23: FAS | E23: 30 | F23: g
C24: Relleno de Suspiro con Manjar | D24: FAS | E24: 100 | F24: g | I24: 3/4 taza
A25: 96344 | B25: SE00032 | C25: Crema Dulce Leche | D25: FAS | E25: 25 | F25: g | H25: Utilizar Boquilla 804 | I25: Arteco
A26: 905000098 | B26: SE00306 | C26: Pecana Triturada Y Horneada | D26: FAS | E26: 25 | F26: g | I26: 1/4 taza
C27: Relleno # 4
C28: Batido Rosquete Arrollado Spoon Kilo 80 g | E28: 56 | F28: g
C29: Mousse de Manjar | E29: 350 | F29: g
C30: Decoracion
A31: 96344 | B31: SE00032 | C31: Crema Dulce Leche | D31: FAS | E31: 40 | F31: g | G31: Colocho Boquilla 127 Wilton
C32: Relleno de Suspiro con Manjar | D32: FAS | E32: 100 | F32: g | H32: En el Centro a Raz | I32: 3/4 Taza
A33: 11900028 | B33: MP10562 | C33: Pecana Entera | D33: FAS | E33: 5 | F33: ud | H33: Por postre
C34: Circulos de Chocolate de 7,5 cm | E34: 6 | F34: g | G34: 1 unidad | H34: Color Rojo Navidad
C35: Circulos de chocolate de 5,5 cm | E35: 4 | F35: g | G35: 2 unidades | H35: 2 Dorados
C36: Circulos de chocolate de 5,5 cm | E36: 4 | F36: g | G36: 2 unidades | H36: Color Rojo Navidad
C37: EMPAQUE
A39: 121603 | B39: EM10009 | C39: QUEQUERA RED BASE/DOMO 10 (CAJA:50) | D39: MAYCA | E39: 1 | F39: ud
A40: 1950692 | B40: EM10008 | C40: ORLA CARTON 10" DORADA UND | D40: Mayca | E40: 1 | F40: Ud
A41: 702069 | B41: EM10002 | C41: Etiq.Blanca 1 1/4 * 3/4 | D41: ETIPLAST | E41: 1 | F41: ud
...

Sheet Costo Locales 
E1: Precio Local | F1: Costo MP | G1: Costo EM | H1: Costo MO
E2: =IFERROR(O62,"") -> 5617.2606 | F2: =IFERROR(H53,"") -> 3528.7574 | G2: =IFERROR(H54,"") -> 540.32824 | H2: =IFERROR(H56,"") -> 793.60229
A5: ESTRUCTURA DE COSTOS
F6: Fecha: | H6: =TODAY() -> 45715
A7: UNIDADES | B7: DESCRIPCION MAT.PRIMA | C7: UNIDADES | D7: UND MEDIDA | E7: COSTO UNITARIO | F7: TOTAL COSTO | G7: % PREC. DEFINIDO | H7: CODIGOS
A8: 5 | B8: Pecana Entera | C8: =+A8 -> 5 | D8: Gramos | E8: 8.35 | F8: =IFERROR(C8*E8,"") -> 41.75 | G8: =IFERROR(F8/$F$66,"") -> 0.0093932929 | H8: 11900028
A9: 1 | B9: Circulos de Chocolate de 7,5 cm | C9: =+A9 -> 1 | D9: UND | E9: 115 | F9: =IFERROR(C9*E9,"") -> 115 | G9: =IFERROR(F9/$F$66,"") -> 0.025873741
A10: 3 | B10: Circulos de chocolate de 5,5 cm | C10: =+A10 -> 3 | D10: UND | E10: 85 | F10: =IFERROR(C10*E10,"") -> 255 | G10: =IFERROR(F10/$F$66,"") -> 0.057372208
B11: =IFERROR(VLOOKUP(H11,'[1]Consolidado MP Planta'!$A$2:$M$823,3,0),"") | C11: =+A11 -> 0 | D11: =IFERROR(VLOOKUP(H11,'[1]Consolidado MP Planta'!$A$2:$M$823,13,0),"") | E11: =IFERROR(VLOOKUP(H11,'[1]Consolidado MP Planta'!$A$2:$M$823,12,0),"") | F11: =IFERROR(C11*E11,"") | G11: =IFERROR(F11/$F$66,"")
B12: =IFERROR(VLOOKUP(H12,'[1]Consolidado MP Planta'!$A$2:$M$823,3,0),"") | C12: =+A12 -> 0 | D12: =IFERROR(VLOOKUP(H12,'[1]Consolidado MP Planta'!$A$2:$M$823,13,0),"") | E12: =IFERROR(VLOOKUP(H12,'[1]Consolidado MP Planta'!$A$2:$M$823,12,0),"") | F12: =IFERROR(C12*E12,"") | G12: =IFERROR(F12/$F$66,"")
B13: =IFERROR(VLOOKUP(H13,'[1]Consolidado MP Planta'!$A$2:$M$823,3,0),"") | C13: =+A13 -> 0 | D13: =IFERROR(VLOOKUP(H13,'[1]Consolidado MP Planta'!$A$2:$M$823,13,0),"") | E13: =IFERROR(VLOOKUP(H13,'[1]Consolidado MP Planta'!$A$2:$M$823,12,0),"") | F13: =IFERROR(C13*E13,"") | G13: =IFERROR(F13/$F$66,"")
B14: =IFERROR(VLOOKUP(H14,'[1]Consolidado MP Planta'!$A$2:$M$823,3,0),"") | C14: =+A14 -> 0 | D14: =IFERROR(VLOOKUP(H14,'[1]Consolidado MP Planta'!$A$2:$M$823,13,0),"") | E14: =IFERROR(VLOOKUP(H14,'[1]Consolidado MP Planta'!$A$2:$M$823,12,0),"") | F14: =IFERROR(C14*E14,"") | G14: =IFERROR(F14/$F$66,"")
B15: =IFERROR(VLOOKUP(H15,'[2]ARTICULOS MP PLANTA'!$A$2:$G$589,2,0),"")
A16: UNIDADES | B16: MATERIA PRIMA SEMIELABORADOS | C16: UNIDADES | D16: UND MEDIDA | E16: COSTO UNITARIO | F16: TOTAL COSTO | G16: % PREC. DEFINIDO | H16: CODIGOS | M16: =174/1000 -> 0.174
A17: 1 | B17: Rosquete Arrollado Spoon Kilo 100 g | C17: =+A17 -> 1 | D17: UND | E17: =+'Costo Rosqute Arr 100'!H53 -> 187.2 | F17: =IFERROR(E17*C17,"") -> 187.2 | G17: =IFERROR(F17/$F$66,"") -> 0.04211795
A18: 3 | B18: Rosquete Arrollado Spoon Kilo 80 g | C18: =+A18 -> 3 | D18: UND | E18: =+'Costo Rosquete Arrollado 80'!H53 -> 151.8 | F18: =IFERROR(E18*C18,"") -> 455.4 | G18: =IFERROR(F18/$F$66,"") -> 0.10246001
A19: 300 | B19: Relleno de Suspiro con Manjar | C19: =+A19 -> 300 | D19: Gramos | E19: =+'Costo Relleno suspiro'!E69 -> 2.2121565 | F19: =IFERROR(E19*C19,"") -> 663.64696 | G19: =IFERROR(F19/$F$66,"") -> 0.1493133
A20: 90 | B20: =IFERROR(VLOOKUP(H20,[1]SEMIELABORADOS!$A$2:$M$6000,2,0),"") -> ALMIBAR KILO | C20: =+A20 -> 90 | D20: =IFERROR(VLOOKUP(H20,[1]SEMIELABORADOS!$A$2:$M$6000,6,0),"") -> Gramo | E20: 0.19 | F20: =IFERROR(E20*C20,"") -> 17.1 | G20: =IFERROR(F20/$F$66,"") -> 0.0038473128 | H20: 908000021
A21: 90 | B21: =IFERROR(VLOOKUP(H21,[1]SEMIELABORADOS!$A$2:$M$6000,2,0),"") -> CREMA DULCE LECHE KILO | C21: =+A21 -> 90 | D21: =IFERROR(VLOOKUP(H21,[1]SEMIELABORADOS!$A$2:$M$6000,6,0),"") -> Gramo | E21: 2.41 | F21: =IFERROR(E21*C21,"") -> 216.9 | G21: =IFERROR(F21/$F$66,"") -> 0.048800125 | H21: 96344
A22: 50 | B22: =IFERROR(VLOOKUP(H22,[1]SEMIELABORADOS!$A$2:$M$6000,2,0),"") -> PECANA TRITURADA KILO | C22: =+A22 -> 50 | D22: =IFERROR(VLOOKUP(H22,[1]SEMIELABORADOS!$A$2:$M$6000,6,0),"") -> Gramo | E22: 8.95 | F22: =IFERROR(E22*C22,"") -> 447.5 | G22: =IFERROR(F22/$F$66,"") -> 0.1006826 | H22: 905000098
A23: 530 | B23: Mousse de Manjar | C23: =+A23 -> 530 | D23: Gramos | E23: =+'Costo Mousse de Manjar'!E69 -> 2.13068 | F23: =IFERROR(E23*C23,"") -> 1129.2604 | G23: =IFERROR(F23/$F$66,"") -> 0.25407123
B24: =IFERROR(VLOOKUP(H24,[1]SEMIELABORADOS!$A$2:$M$6000,2,0),"") | C24: =+A24 -> 0 | D24: =IFERROR(VLOOKUP(H24,[1]SEMIELABORADOS!$A$2:$M$6000,6,0),"") | E24: =IFERROR(VLOOKUP(H24,[1]SEMIELABORADOS!$A$2:$H$65536,8,0),"") | F24: =IFERROR(E24*C24,"") | G24: =IFERROR(F24/$F$66,"")
A26: UNIDADES | B26: EMPAQUE | C26: UNIDADES | D26: UND MEDIDA | E26: COSTO UNITARIO | F26: TOTAL COSTO | G26: % PREC. DEFINIDO | H26: CODIGOS
A27: 1 | B27: =IFERROR(VLOOKUP(H27,'[1]Consolidado MP Planta'!$A$2:$M$823,3,0),"") -> QUEQUERA RED BASE/DOMO 10 (CAJA:50) | C27: =+A27 -> 1 | D27: =IFERROR(VLOOKUP(H27,'[1]Consolidado MP Planta'!$A$2:$M$823,13,0),"") -> UND | E27: 385 | F27: =IFERROR(C27*E27,"") -> 385 | G27: =IFERROR(F27/$F$66,"") -> 0.086620784 | H27: 121603
A28: 1 | B28: =IFERROR(VLOOKUP(H28,'[1]Consolidado MP Planta'!$A$2:$M$823,3,0),"") -> ORLA CARTON 10" DORADA (UND) | C28: =+A28 -> 1 | D28: =IFERROR(VLOOKUP(H28,'[1]Consolidado MP Planta'!$A$2:$M$823,13,0),"") -> Und | E28: 137 | F28: =IFERROR(C28*E28,"") -> 137 | G28: =IFERROR(F28/$F$66,"") -> 0.0308235 | H28: 1950692
A29: 1 | B29: =IFERROR(VLOOKUP(H29,'[1]Consolidado MP Planta'!$A$2:$M$823,3,0),"") -> ETIQ.BLANCA 1 1/4 * 3/4 (UND) | C29: =+A29 -> 1 | D29: =IFERROR(VLOOKUP(H29,'[1]Consolidado MP Planta'!$A$2:$M$823,13,0),"") -> Und | E29: =IFERROR(VLOOKUP(H29,'[1]Consolidado MP Planta'!$A$2:$M$823,12,0),"") -> 0.58 | F29: =IFERROR(C29*E29,"") -> 0.58 | G29: =IFERROR(F29/$F$66,"") -> 0.00013049365 | H29: 0702069
A30: 60 | B30: =IFERROR(VLOOKUP(H30,'[1]Consolidado MP Planta'!$A$2:$M$823,3,0),"") -> CINTA ADHESIVA TRANSPARENT 2*100 M (UND) | C30: =+A30 -> 60 | D30: =IFERROR(VLOOKUP(H30,'[1]Consolidado MP Planta'!$A$2:$M$823,13,0),"") -> Cm | E30: =IFERROR(VLOOKUP(H30,'[1]Consolidado MP Planta'!$A$2:$M$823,12,0),"") -> 0.175 | F30: =IFERROR(C30*E30,"") -> 10.5 | G30: =IFERROR(F30/$F$66,"") -> 0.002362385 | H30: 703020
A31: 1 | B31: =IFERROR(VLOOKUP(H31,'[1]Consolidado MP Planta'!$A$2:$M$823,3,0),"") -> ETIQUETA BLANCA R-153 (UND) | C31: =+A31 -> 1 | D31: =IFERROR(VLOOKUP(H31,'[1]Consolidado MP Planta'!$A$2:$M$823,13,0),"") -> Und | E31: =IFERROR(VLOOKUP(H31,'[1]Consolidado MP Planta'!$A$2:$M$823,12,0),"") -> 0.39 | F31: =IFERROR(C31*E31,"") -> 0.39 | G31: =IFERROR(F31/$F$66,"") -> 8.774573e-05 | H31: 701096
A32: 1 | B32: =IFERROR(VLOOKUP(H32,'[1]Consolidado MP Planta'!$A$2:$M$823,3,0),"") -> ETIQUETA BLANCA 2 5/8X1 15/16 (UND) | C32: =+A32 -> 1 | D32: =IFERROR(VLOOKUP(H32,'[1]Consolidado MP Planta'!$A$2:$M$823,13,0),"") -> Und | E32: =IFERROR(VLOOKUP(H32,'[1]Consolidado MP Planta'!$A$2:$M$823,12,0),"") -> 2.128 | F32: =IFERROR(C32*E32,"") -> 2.128 | G32: =IFERROR(F32/$F$66,"") -> 0.0004787767 | H32: 0702123
A34: UNIDADES | B34: EMPAQUE SEMIELABORADOS | C34: UNIDADES | D34: UND MEDIDA | E34: COSTO UNITARIO | F34: TOTAL COSTO | G34: % PREC. DEFINIDO | H34: CODIGOS
A35: =+A17 -> 1 | B35: Rosquete Arrollado Spoon Kilo 100 g | C35: =+A35 -> 1 | D35: UND | E35: =+'Costo Rosqute Arr 100'!H54 -> 1.1 | F35: =IFERROR(E35*C35,"") -> 1.1 | G35: =IFERROR(F35/$F$66,"") -> 0.00024748796
A36: =+A18 -> 3 | B36: Rosquete Arrollado Spoon Kilo 80 g | C36: =+A36 -> 3 | D36: UND | E36: =+'Costo Rosquete Arrollado 80'!H54 -> 0.9 | F36: =IFERROR(E36*C36,"") -> 2.7 | G36: =IFERROR(F36/$F$66,"") -> 0.00060747044
A37: =+A19 -> 300 | B37: Relleno de Suspiro con Manjar | C37: =+A37 -> 300 | D37: Gramo | E37: =+'Costo Relleno suspiro'!E76 -> 0 | F37: =IFERROR(E37*C37,"") -> 0 | G37: =IFERROR(F37/$F$66,"") -> 0
A38: =+A20 -> 90 | B38: =IFERROR(VLOOKUP(H38,[1]SEMIELABORADOS!$A$2:$M$6000,2,0),"") -> ALMIBAR KILO | C38: =+A38 -> 90 | D38: =IFERROR(VLOOKUP(H38,[1]SEMIELABORADOS!$A$2:$M$6000,6,0),"") -> Gramo | E38: =IFERROR(VLOOKUP(H38,[1]SEMIELABORADOS!$A$2:$M$65536,10,0),"") -> 0.010250838 | F38: =IFERROR(E38*C38,"") -> 0.92257542 | G38: =IFERROR(F38/$F$66,"") -> 0.00020756937 | H38: 908000021
A39: =+A21 -> 90 | B39: =IFERROR(VLOOKUP(H39,[1]SEMIELABORADOS!$A$2:$M$6000,2,0),"") -> CREMA DULCE LECHE KILO | C39: =+A39 -> 90 | D39: =IFERROR(VLOOKUP(H39,[1]SEMIELABORADOS!$A$2:$M$6000,6,0),"") -> Gramo | E39: =IFERROR(VLOOKUP(H39,[1]SEMIELABORADOS!$A$2:$M$65536,10,0),"") -> 8.512e-05 | F39: =IFERROR(E39*C39,"") -> 0.0076608 | G39: =IFERROR(F39/$F$66,"") -> 1.7235961e-06 | H39: 96344
A40: =+A22 -> 50 | B40: =IFERROR(VLOOKUP(H40,[1]SEMIELABORADOS!$A$2:$M$6000,2,0),"") -> PECANA TRITURADA KILO | C40: =+A40 -> 50 | D40: =IFERROR(VLOOKUP(H40,[1]SEMIELABORADOS!$A$2:$M$6000,6,0),"") -> Gramo | E40: =IFERROR(VLOOKUP(H40,[1]SEMIELABORADOS!$A$2:$M$65536,10,0),"") -> 0 | F40: =IFERROR(E40*C40,"") -> 0 | G40: =IFERROR(F40/$F$66,"") -> 0 | H40: 905000098
A41: =+A23 -> 530 | B41: Mousse de Manjar | C41: =+A41 -> 530 | D41: Gramo | E41: =+'Costo Mousse de Manjar'!E76 -> 0 | F41: =IFERROR(E41*C41,"") -> 0 | G41: =IFERROR(F41/$F$66,"") -> 0
A43: UNIDADES | B43: MODI | C43: UNIDADES | D43: UND MEDIDA | E43: COSTO UNITARIO | F43: TOTAL COSTO | G43: % PREC. DEFINIDO | H43: CODIGOS
A44: =+A35 -> 1 | B44: Rosquete Arrollado Spoon Kilo 100 g | C44: =+A44 -> 1 | D44: UND | E44: =+'Costo Rosqute Arr 100'!H56 -> 52.75 | F44: =IFERROR(E44*C44,"") -> 52.75 | G44: =IFERROR(F44/$F$66,"") -> 0.011868172
A45: =+A36 -> 3 | B45: Rosquete Arrollado Spoon Kilo 80 g | C45: =+A45 -> 3 | D45: UND | E45: =+'Costo Rosquete Arrollado 80'!H56 -> 48.55 | F45: =IFERROR(E45*C45,"") -> 145.65 | G45: =IFERROR(F45/$F$66,"") -> 0.032769655
...

Sheet Pecana triturada 
C1: SERVICIOS DE PASTELERIA S.A. | H1: CÓDIGO: | I1: ESP-RE-DES-133
C2: ESPECIFICACION DE RECETA | H2: REVISIÓN: | I2: 01
C3: 905000098(SE00306) Pecana triturada | H3: FECHA DE APROBACIÓN: | I3: 44006
C4: Elaborado | D4: Juan Pablo Brenes, Chef
C5: Aprobado | D5: Esteban Cartín. Gte de Manufactura
A6: AREA QUE PRODUCE: | D6: Decoración | G6: AREA QUE EMPACA: | I6: Decoración
A7: # Código | B7: # Codigo Netsuite | C7: Descripción del ingrediente | D7: Marca | E7: Unidad Internacional | G7: Medida alternativa | I7: Costo - Referencia
E8: Cantidad | F8: Unidad medida | G8: Cantidad | H8: Unidad medida | I8: Colones
A9: 11900028 | B9: MP10562 | C9: Pecana Entera | D9: NUECES IND | E9: 10000 | F9: g
D16: Cantidad | E16: Unidad
A17: PESO TOTAL OBTENIDO | D17: 9500 | E17: g | F17: Tiempo de Horneo:
A18: TIEMPO TOTAL DE PREPARACION | D18: 10 | E18: min | F18: Horno:
A19: CANTIDAD DE PORCIONES OBTENIDAS | D19: =+D17/D20 -> 1 | E19: ud | F19: Temperatura de Horneo:
A20: PESO DE CADA PORCIÓN | D20: 9500 | E20: g | F20: Otros
A21: MERMA | D21: =SUM(E9)-D17 -> 500 | E21: g
A22: PROCEDIMIENTO DE PREPARACION DE LA RECETA
A23: 1- Pasar por la trituradora con los engranes cerrados.

Sheet almibar 
D1: SERVICIOS DE PASTELERIA S.A. | I1: CÓDIGO: | J1: ESP-RE-COCS-034
D2: ESPECIFICACION DE RECETA | I2: REVISIÓN: | J2: 10
D3: 908000021(SE00005) - ALMIBAR | I3: FECHA DE APROBACIÓN: | J3: 44091
D4: Elaborado | E4: Javier Tong, Chef
D5: Aprobado | E5: Jeffry Rodriguez, gerente de manufactura
B6: # Código | C6: # Codigo Netsuite | D6: Descripción del ingrediente | E6: Marca | F6: Unidad Internacional | H6: Medida alternativa | J6: Costo - Referencia
F7: Cantidad | G7: Unidad medida | H7: Cantidad | I7: Unidad medida | J7: Colones
B9: 10415 | D9: AGUA POTABLE (PLANTA) | E9: FAS | F9: 21400 | G9: g
B10: 90100131 | C10: SE00016 | D10: AZUCAR BLANCO INDUSTRIAL KILO | E10: FAS | F10: 8000 | G10: g
B11: 10100311 | C11: MP10095 | D11: Canela En Astilla | E11: PRIMA | F11: 5 | G11: g
B12: 0810288 | C12: MP10598 | D12: Jugo de Naranja TB | E12: DOS PINOS | F12: 2000 | G12: g
B13: 1212410 | C13: MP10008 | D13: PRESERVANTE 1047S (PAQ=5 KILO) | E13: ASEAL | F13: 66 | G13: g
B15: 512000002 | C15: EM10259 | D15: PLASTICO AUTOAD (UND: 18 * 2000 M) | F15: 400 | G15: cm
B16: 0702123 | C16: EM10011 | D16: ETIQUETA BLANCA 2 5/8X1 15/16 (UND) | F16: 2 | G16: ud
B28: PESO TOTAL OBTENIDO | E28: 31300 | F28: g | G28: Tiempo de Horneo:
B29: TIEMPO TOTAL DE PREPARACION | E29: 15 | F29: min | G29: Horno:
B30: CANTIDAD DE PORCIONES OBTENIDAS | E30: =+E28/E31 -> 1 | F30: Porciones | G30: Temperatura de Horneo:
B31: PESO DE CADA PORCIÓN | E31: 31300 | F31: g | G31: Otros
B32: MERMA | E32: =(SUM(F9:F13))-E28 -> 171 | F32: g
B33: PROCEDIMIENTO DE PREPARACION DE LA RECETA
B34: 1 Colocar en una olla el agua, jugo de naranja, azúcar y mezclar bien. Añadir luego el preservante y disolverlo por completo.
B35: 2 Llevar a fuego alto hasta obtener el herbor, dejar herbir unos 5 minutos.sacar la astilla de canela
B36: 3 Despues de la cocción, retirar del fuego y colocar en un bote cubrir con plastico adhesivo y dejar enfirar. Guardar en Camaras de Refrige.
B38: Control de cambios
B39: 09: Cambio código
B40: 10: Actualizacion de codigos

Sheet Crema dulce de leche 
C1: SERVICIOS DE PASTELERIA S.A. | H1: CÓDIGO: | I1: ESP-RE-DES-040
C2: ESPECIFICACION DE RECETA | H2: REVISIÓN: | I2: 04
C3: Crema de Dulce de Leche(24500g) 96344(SE00032) | H3: FECHA DE APROBACIÓN: | I3: 44096
C4: Elaborado | D4: Javier Tong, Chef
C5: Aprobado | D5: Jeffry Rodriguez, Gerente de Manufactura
A6: AREA QUE PRODUCE: | D6: Decoracion | G6: AREA QUE EMPACA: | I6: Decoracion
A7: # Código | B7: # Codigo Netsuite | C7: Descripción del ingrediente | D7: Marca | E7: Unidad Internacional | G7: Medida alternativa | I7: Costo - Referencia
E8: Cantidad | F8: Unidad medida | G8: Cantidad | H8: Unidad medida | I8: Colones
A9: 11400029 | B9: MP10165 | C9: CREMA BETTER DULCE LECHE RICH (UND:4 K) | D9: Rich | E9: 16000 | F9: g | G9: 4 Galones
A10: 11400031 | B10: MP10048 | C10: CREMA PRESTIGE GRAND (UND:4 K) | D10: Rich | E10: 8000 | F10: g | G10: 2 Galones
A11: 10415 | C11: AGUA POTABLE (PLANTA) | D11: Spoon | E11: 1000 | F11: g
A12: 1212410 | B12: MP10008 | C12: PRESERVANTE 1047S (PAQ=5 KILO) | D12: Aseal | E12: 22 | F12: g
A13: 702123 | B13: EM10011 | C13: ETIQUETA BLANCA 2 5/8X1 15/16 (UND) | E13: 1 | F13: ud
D15: Cantidad | E15: Unidad
A16: PESO TOTAL OBTENIDO | D16: 24500 | E16: g | F16: Tiempo de Horneo:
A17: TIEMPO TOTAL DE PREPARACION | D17: 5 | E17: min | F17: Horno:
A18: CANTIDAD DE PORCIONES OBTENIDAS | D18: 1 | E18: ud | F18: Temperatura de Horneo:
A19: PESO DE CADA PORCIÓN | D19: =D16 -> 24500 | E19: g | F19: Otros
A20: MERMA | D20: 500 | E20: g
A21: PROCEDIMIENTO DE PREPARACION DE LA RECETA
A22: 1.- Colocar la crema de dulce de leche y la prestige en la top cream con el agua y preservante.
A23: 2.- Batir por 12 minutos, mantener en refrigeracin a 5°C.
A26: Control de cambios
A27: 4, Actualizacion de codigos

Sheet Costo Mousse de Manjar
E1: Precio Local | F1: Costo MP | G1: Costo EM | H1: Costo MO
E2: =IFERROR(O62,"") -> 2725.68 | F2: =IFERROR(H53,"") -> 2130.68 | G2: =IFERROR(H54,"") -> 0 | H2: =IFERROR(H56,"") -> 305
A5: ESTRUCTURA DE COSTOS
F6: Fecha: | H6: =TODAY() -> 45715
A7: UNIDADES | B7: DESCRIPCION MAT.PRIMA | C7: UNIDADES | D7: UND MEDIDA | E7: COSTO UNITARIO | F7: TOTAL COSTO | G7: % PREC. DEFINIDO | H7: CODIGOS
A8: 400 | B8: =IFERROR(VLOOKUP(H8,'[1]Consolidado MP Planta'!$A$2:$M$823,3,0),"") -> QUESO CREMA PANADERO (CAJA: 5 K) | C8: =+A8 -> 400 | D8: =IFERROR(VLOOKUP(H8,'[1]Consolidado MP Planta'!$A$2:$M$823,13,0),"") -> Gramos | E8: =IFERROR(VLOOKUP(H8,'[1]Consolidado MP Planta'!$A$2:$M$823,12,0),"") -> 3.0762 | F8: =IFERROR(C8*E8,"") -> 1230.48 | G8: =IFERROR(F8/$F$66,"") -> 0.49650292 | H8: 1730660
A9: 300 | B9: MANJAR DE LECHE CONDENSADA ( 6 KG ) | C9: =+A9 -> 300 | D9: Gramos | E9: 2.54 | F9: =IFERROR(C9*E9,"") -> 762 | G9: =IFERROR(F9/$F$66,"") -> 0.30746962 | H9: 11400066
A10: 10 | B10: Gelatina Pura | C10: =+A10 -> 10 | D10: Gramos | E10: 13.02 | F10: =IFERROR(C10*E10,"") -> 130.2 | G10: =IFERROR(F10/$F$66,"") -> 0.052536148 | H10: 1100022
A11: 80 | B11: =IFERROR(VLOOKUP(H11,'[1]Consolidado MP Planta'!$A$2:$M$823,3,0),"") -> AGUA PLANTA | C11: =+A11 -> 80 | D11: =IFERROR(VLOOKUP(H11,'[1]Consolidado MP Planta'!$A$2:$M$823,13,0),"") -> Mililitros | E11: =IFERROR(VLOOKUP(H11,'[1]Consolidado MP Planta'!$A$2:$M$823,12,0),"") -> 0.1 | F11: =IFERROR(C11*E11,"") -> 8 | G11: =IFERROR(F11/$F$66,"") -> 0.0032280275 | H11: 10415
B12: =IFERROR(VLOOKUP(H12,'[1]Consolidado MP Planta'!$A$2:$M$823,3,0),"") | C12: =+A12 -> 0 | D12: =IFERROR(VLOOKUP(H12,'[1]Consolidado MP Planta'!$A$2:$M$823,13,0),"") | E12: =IFERROR(VLOOKUP(H12,'[1]Consolidado MP Planta'!$A$2:$M$823,12,0),"") | F12: =IFERROR(C12*E12,"") | G12: =IFERROR(F12/$F$66,"")
B13: =IFERROR(VLOOKUP(H13,'[1]Consolidado MP Planta'!$A$2:$M$823,3,0),"") | C13: =+A13 -> 0 | D13: =IFERROR(VLOOKUP(H13,'[1]Consolidado MP Planta'!$A$2:$M$823,13,0),"") | E13: =IFERROR(VLOOKUP(H13,'[1]Consolidado MP Planta'!$A$2:$M$823,12,0),"") | F13: =IFERROR(C13*E13,"") | G13: =IFERROR(F13/$F$66,"")
B14: =IFERROR(VLOOKUP(H14,'[1]Consolidado MP Planta'!$A$2:$M$823,3,0),"") | C14: =+A14 -> 0 | D14: =IFERROR(VLOOKUP(H14,'[1]Consolidado MP Planta'!$A$2:$M$823,13,0),"") | E14: =IFERROR(VLOOKUP(H14,'[1]Consolidado MP Planta'!$A$2:$M$823,12,0),"") | F14: =IFERROR(C14*E14,"") | G14: =IFERROR(F14/$F$66,"")
B15: =IFERROR(VLOOKUP(H15,'[2]ARTICULOS MP PLANTA'!$A$2:$G$589,2,0),"")
A16: UNIDADES | B16: MATERIA PRIMA SEMIELABORADOS | C16: UNIDADES | D16: UND MEDIDA | E16: COSTO UNITARIO | F16: TOTAL COSTO | G16: % PREC. DEFINIDO | H16: CODIGOS
B17: =IFERROR(VLOOKUP(H17,[1]SEMIELABORADOS!$A$2:$M$6000,2,0),"") | C17: =+A17 -> 0 | D17: =IFERROR(VLOOKUP(H17,[1]SEMIELABORADOS!$A$2:$M$6000,6,0),"") | E17: =IFERROR(VLOOKUP(H17,[1]SEMIELABORADOS!$A$2:$H$65536,8,0),"") | F17: =IFERROR(E17*C17,"") | G17: =IFERROR(F17/$F$66,"")
B18: =IFERROR(VLOOKUP(H18,[1]SEMIELABORADOS!$A$2:$M$6000,2,0),"") | C18: =+A18 -> 0 | D18: =IFERROR(VLOOKUP(H18,[1]SEMIELABORADOS!$A$2:$M$6000,6,0),"") | E18: =IFERROR(VLOOKUP(H18,[1]SEMIELABORADOS!$A$2:$H$65536,8,0),"") | F18: =IFERROR(E18*C18,"") | G18: =IFERROR(F18/$F$66,"")
B19: =IFERROR(VLOOKUP(H19,[1]SEMIELABORADOS!$A$2:$M$6000,2,0),"") | C19: =+A19 -> 0 | D19: =IFERROR(VLOOKUP(H19,[1]SEMIELABORADOS!$A$2:$M$6000,6,0),"") | E19: =IFERROR(VLOOKUP(H19,[1]SEMIELABORADOS!$A$2:$H$65536,8,0),"") | F19: =IFERROR(E19*C19,"") | G19: =IFERROR(F19/$F$66,"")
B20: =IFERROR(VLOOKUP(H20,[1]SEMIELABORADOS!$A$2:$M$6000,2,0),"") | C20: =+A20 -> 0 | D20: =IFERROR(VLOOKUP(H20,[1]SEMIELABORADOS!$A$2:$M$6000,6,0),"") | E20: =IFERROR(VLOOKUP(H20,[1]SEMIELABORADOS!$A$2:$H$65536,8,0),"") | F20: =IFERROR(E20*C20,"") | G20: =IFERROR(F20/$F$66,"")
B21: =IFERROR(VLOOKUP(H21,[1]SEMIELABORADOS!$A$2:$M$6000,2,0),"") | C21: =+A21 -> 0 | D21: =IFERROR(VLOOKUP(H21,[1]SEMIELABORADOS!$A$2:$M$6000,6,0),"") | E21: =IFERROR(VLOOKUP(H21,[1]SEMIELABORADOS!$A$2:$H$65536,8,0),"") | F21: =IFERROR(E21*C21,"") | G21: =IFERROR(F21/$F$66,"")
B22: =IFERROR(VLOOKUP(H22,[1]SEMIELABORADOS!$A$2:$M$6000,2,0),"") | C22: =+A22 -> 0 | D22: =IFERROR(VLOOKUP(H22,[1]SEMIELABORADOS!$A$2:$M$6000,6,0),"") | E22: =IFERROR(VLOOKUP(H22,[1]SEMIELABORADOS!$A$2:$H$65536,8,0),"") | F22: =IFERROR(E22*C22,"") | G22: =IFERROR(F22/$F$66,"")
B23: =IFERROR(VLOOKUP(H23,[1]SEMIELABORADOS!$A$2:$M$6000,2,0),"") | C23: =+A23 -> 0 | D23: =IFERROR(VLOOKUP(H23,[1]SEMIELABORADOS!$A$2:$M$6000,6,0),"") | E23: =IFERROR(VLOOKUP(H23,[1]SEMIELABORADOS!$A$2:$H$65536,8,0),"") | F23: =IFERROR(E23*C23,"") | G23: =IFERROR(F23/$F$66,"")
B24: =IFERROR(VLOOKUP(H24,[1]SEMIELABORADOS!$A$2:$M$6000,2,0),"") | C24: =+A24 -> 0 | D24: =IFERROR(VLOOKUP(H24,[1]SEMIELABORADOS!$A$2:$M$6000,6,0),"") | E24: =IFERROR(VLOOKUP(H24,[1]SEMIELABORADOS!$A$2:$H$65536,8,0),"") | F24: =IFERROR(E24*C24,"") | G24: =IFERROR(F24/$F$66,"")
A26: UNIDADES | B26: EMPAQUE | C26: UNIDADES | D26: UND MEDIDA | E26: COSTO UNITARIO | F26: TOTAL COSTO | G26: % PREC. DEFINIDO | H26: CODIGOS
A27: 0 | B27: =IFERROR(VLOOKUP(H27,'[1]Consolidado MP Planta'!$A$2:$M$823,3,0),"") | C27: =+A27 -> 0 | D27: =IFERROR(VLOOKUP(H27,'[1]Consolidado MP Planta'!$A$2:$M$823,13,0),"") | E27: =IFERROR(VLOOKUP(H27,'[1]Consolidado MP Planta'!$A$2:$M$823,12,0),"") | F27: =IFERROR(C27*E27,"") | G27: =IFERROR(F27/$F$66,"")
B28: =IFERROR(VLOOKUP(H28,'[1]Consolidado MP Planta'!$A$2:$M$823,3,0),"") | C28: =+A28 -> 0 | D28: =IFERROR(VLOOKUP(H28,'[1]Consolidado MP Planta'!$A$2:$M$823,13,0),"") | E28: =IFERROR(VLOOKUP(H28,'[1]Consolidado MP Planta'!$A$2:$M$823,12,0),"") | F28: =IFERROR(C28*E28,"") | G28: =IFERROR(F28/$F$66,"")
B29: =IFERROR(VLOOKUP(H29,'[1]Consolidado MP Planta'!$A$2:$M$823,3,0),"") | C29: =+A29 -> 0 | D29: =IFERROR(VLOOKUP(H29,'[1]Consolidado MP Planta'!$A$2:$M$823,13,0),"") | E29: =IFERROR(VLOOKUP(H29,'[1]Consolidado MP Planta'!$A$2:$M$823,12,0),"") | F29: =IFERROR(C29*E29,"") | G29: =IFERROR(F29/$F$66,"")
B30: =IFERROR(VLOOKUP(H30,'[1]Consolidado MP Planta'!$A$2:$M$823,3,0),"") | C30: =+A30 -> 0 | D30: =IFERROR(VLOOKUP(H30,'[1]Consolidado MP Planta'!$A$2:$M$823,13,0),"") | E30: =IFERROR(VLOOKUP(H30,'[1]Consolidado MP Planta'!$A$2:$M$823,12,0),"") | F30: =IFERROR(C30*E30,"") | G30: =IFERROR(F30/$F$66,"")
B31: =IFERROR(VLOOKUP(H31,'[1]Consolidado MP Planta'!$A$2:$M$823,3,0),"") | C31: =+A31 -> 0 | D31: =IFERROR(VLOOKUP(H31,'[1]Consolidado MP Planta'!$A$2:$M$823,13,0),"") | E31: =IFERROR(VLOOKUP(H31,'[1]Consolidado MP Planta'!$A$2:$M$823,12,0),"") | F31: =IFERROR(C31*E31,"") | G31: =IFERROR(F31/$F$66,"")
B32: =IFERROR(VLOOKUP(H32,'[1]Consolidado MP Planta'!$A$2:$M$823,3,0),"") | C32: =+A32 -> 0 | D32: =IFERROR(VLOOKUP(H32,'[1]Consolidado MP Planta'!$A$2:$M$823,13,0),"") | E32: =IFERROR(VLOOKUP(H32,'[1]Consolidado MP Planta'!$A$2:$M$823,12,0),"") | F32: =IFERROR(C32*E32,"") | G32: =IFERROR(F32/$F$66,"")
A34: UNIDADES | B34: EMPAQUE SEMIELABORADOS | C34: UNIDADES | D34: UND MEDIDA | E34: COSTO UNITARIO | F34: TOTAL COSTO | G34: % PREC. DEFINIDO | H34: CODIGOS
A35: =+A17 -> 0 | B35: =IFERROR(VLOOKUP(H35,[1]SEMIELABORADOS!$A$2:$M$6000,2,0),"") | C35: =+A35 -> 0 | D35: =IFERROR(VLOOKUP(H35,[1]SEMIELABORADOS!$A$2:$M$6000,6,0),"") | E35: =IFERROR(VLOOKUP(H35,[1]SEMIELABORADOS!$A$2:$M$65536,10,0),"") | F35: =IFERROR(E35*C35,"") | G35: =IFERROR(F35/$F$66,"")
A36: =+A18 -> 0 | B36: =IFERROR(VLOOKUP(H36,[1]SEMIELABORADOS!$A$2:$M$6000,2,0),"") | C36: =+A36 -> 0 | D36: =IFERROR(VLOOKUP(H36,[1]SEMIELABORADOS!$A$2:$M$6000,6,0),"") | E36: =IFERROR(VLOOKUP(H36,[1]SEMIELABORADOS!$A$2:$M$65536,10,0),"") | F36: =IFERROR(E36*C36,"") | G36: =IFERROR(F36/$F$66,"")
A37: =+A19 -> 0 | B37: =IFERROR(VLOOKUP(H37,[1]SEMIELABORADOS!$A$2:$M$6000,2,0),"") | C37: =+A37 -> 0 | D37: =IFERROR(VLOOKUP(H37,[1]SEMIELABORADOS!$A$2:$M$6000,6,0),"") | E37: =IFERROR(VLOOKUP(H37,[1]SEMIELABORADOS!$A$2:$M$65536,10,0),"") | F37: =IFERROR(E37*C37,"") | G37: =IFERROR(F37/$F$66,"")
A38: =+A20 -> 0 | B38: =IFERROR(VLOOKUP(H38,[1]SEMIELABORADOS!$A$2:$M$6000,2,0),"") | C38: =+A38 -> 0 | D38: =IFERROR(VLOOKUP(H38,[1]SEMIELABORADOS!$A$2:$M$6000,6,0),"") | E38: =IFERROR(VLOOKUP(H38,[1]SEMIELABORADOS!$A$2:$M$65536,10,0),"") | F38: =IFERROR(E38*C38,"") | G38: =IFERROR(F38/$F$66,"")
A39: =+A21 -> 0 | B39: =IFERROR(VLOOKUP(H39,[1]SEMIELABORADOS!$A$2:$M$6000,2,0),"") | C39: =+A39 -> 0 | D39: =IFERROR(VLOOKUP(H39,[1]SEMIELABORADOS!$A$2:$M$6000,6,0),"") | E39: =IFERROR(VLOOKUP(H39,[1]SEMIELABORADOS!$A$2:$M$65536,10,0),"") | F39: =IFERROR(E39*C39,"") | G39: =IFERROR(F39/$F$66,"")
A40: =+A22 -> 0 | B40: =IFERROR(VLOOKUP(H40,[1]SEMIELABORADOS!$A$2:$M$6000,2,0),"") | C40: =+A40 -> 0 | D40: =IFERROR(VLOOKUP(H40,[1]SEMIELABORADOS!$A$2:$M$6000,6,0),"") | E40: =IFERROR(VLOOKUP(H40,[1]SEMIELABORADOS!$A$2:$M$65536,10,0),"") | F40: =IFERROR(E40*C40,"") | G40: =IFERROR(F40/$F$66,"")
A41: =+A23 -> 0 | B41: =IFERROR(VLOOKUP(H41,[1]SEMIELABORADOS!$A$2:$M$6000,2,0),"") | C41: =+A41 -> 0 | D41: =IFERROR(VLOOKUP(H41,[1]SEMIELABORADOS!$A$2:$M$6000,6,0),"") | E41: =IFERROR(VLOOKUP(H41,[1]SEMIELABORADOS!$A$2:$M$65536,10,0),"") | F41: =IFERROR(E41*C41,"") | G41: =IFERROR(F41/$F$66,"")
A43: UNIDADES | B43: MODI | C43: UNIDADES | D43: UND MEDIDA | E43: COSTO UNITARIO | F43: TOTAL COSTO | G43: % PREC. DEFINIDO | H43: CODIGOS
A44: =+A35 -> 0 | B44: =IFERROR(VLOOKUP(H44,[1]SEMIELABORADOS!$A$2:$M$6000,2,0),"") | C44: =+A44 -> 0 | D44: =IFERROR(VLOOKUP(H44,[1]SEMIELABORADOS!$A$2:$M$6000,6,0),"") | E44: =IFERROR(VLOOKUP(H44,[1]SEMIELABORADOS!$A$2:$M$65536,12,0),"") | F44: =IFERROR(E44*C44,"") | G44: =IFERROR(F44/$F$66,"")
A45: =+A36 -> 0 | B45: =IFERROR(VLOOKUP(H45,[1]SEMIELABORADOS!$A$2:$M$6000,2,0),"") | C45: =+A45 -> 0 | D45: =IFERROR(VLOOKUP(H45,[1]SEMIELABORADOS!$A$2:$M$6000,6,0),"") | E45: =IFERROR(VLOOKUP(H45,[1]SEMIELABORADOS!$A$2:$M$65536,12,0),"") | F45: =IFERROR(E45*C45,"") | G45: =IFERROR(F45/$F$66,"")
...

Sheet Costo Relleno suspiro
E1: Precio Local | F1: Costo MP | G1: Costo EM | H1: Costo MO
E2: =IFERROR(O62,"") -> 9416.94 | F2: =IFERROR(H53,"") -> 7631.94 | G2: =IFERROR(H54,"") -> 0 | H2: =IFERROR(H56,"") -> 915
A5: ESTRUCTURA DE COSTOS
F6: Fecha: | H6: =TODAY() -> 45715
A7: UNIDADES | B7: DESCRIPCION MAT.PRIMA | C7: UNIDADES | D7: UND MEDIDA | E7: COSTO UNITARIO | F7: TOTAL COSTO | G7: % PREC. DEFINIDO | H7: CODIGOS
A8: 1634 | B8: =IFERROR(VLOOKUP(H8,'[1]Consolidado MP Planta'!$A$2:$M$823,3,0),"") -> LECHE EVAPORADA (UND: 1 L) | C8: =+A8 -> 1634 | D8: =IFERROR(VLOOKUP(H8,'[1]Consolidado MP Planta'!$A$2:$M$823,13,0),"") -> Mililitros | E8: 1.97 | F8: =IFERROR(C8*E8,"") -> 3218.98 | G8: =IFERROR(F8/$F$66,"") -> 0.37001562 | H8: 1110414
A9: 1634 | B9: =IFERROR(VLOOKUP(H9,'[1]Consolidado MP Planta'!$A$2:$M$823,3,0),"") -> LECHE CONDENSADA (PAQ:11 K) | C9: =+A9 -> 1634 | D9: =IFERROR(VLOOKUP(H9,'[1]Consolidado MP Planta'!$A$2:$M$823,13,0),"") -> Gramos | E9: 2.15 | F9: =IFERROR(C9*E9,"") -> 3513.1 | G9: =IFERROR(F9/$F$66,"") -> 0.40382415 | H9: 11400046
A10: 326 | B10: =IFERROR(VLOOKUP(H10,'[1]Consolidado MP Planta'!$A$2:$M$823,3,0),"") -> YEMA DE HUEVO (UND: 8.34 K) | C10: =+A10 -> 326 | D10: Gramos | E10: 2.29 | F10: =IFERROR(C10*E10,"") -> 746.54 | G10: =IFERROR(F10/$F$66,"") -> 0.08581335 | H10: 11300011
A11: 40 | B11: MANJAR DE LECHE CONDENSADA ( 6 KG ) | C11: =+A11 -> 40 | D11: Gramos | E11: 2.54 | F11: =IFERROR(C11*E11,"") -> 101.6 | G11: =IFERROR(F11/$F$66,"") -> 0.011678726 | H11: 11400066
A12: 6 | B12: =IFERROR(VLOOKUP(H12,'[1]Consolidado MP Planta'!$A$2:$M$823,3,0),"") -> PRESERVANTE 1017S (PAQ=5 KILO) | C12: =+A12 -> 6 | D12: =IFERROR(VLOOKUP(H12,'[1]Consolidado MP Planta'!$A$2:$M$823,13,0),"") -> Gramos | E12: 8.62 | F12: =IFERROR(C12*E12,"") -> 51.72 | G12: =IFERROR(F12/$F$66,"") -> 0.0059451154 | H12: 1212412
B13: =IFERROR(VLOOKUP(H13,'[1]Consolidado MP Planta'!$A$2:$M$823,3,0),"") | C13: =+A13 -> 0 | D13: =IFERROR(VLOOKUP(H13,'[1]Consolidado MP Planta'!$A$2:$M$823,13,0),"") | E13: =IFERROR(VLOOKUP(H13,'[1]Consolidado MP Planta'!$A$2:$M$823,12,0),"") | F13: =IFERROR(C13*E13,"") | G13: =IFERROR(F13/$F$66,"")
B14: =IFERROR(VLOOKUP(H14,'[1]Consolidado MP Planta'!$A$2:$M$823,3,0),"") | C14: =+A14 -> 0 | D14: =IFERROR(VLOOKUP(H14,'[1]Consolidado MP Planta'!$A$2:$M$823,13,0),"") | E14: =IFERROR(VLOOKUP(H14,'[1]Consolidado MP Planta'!$A$2:$M$823,12,0),"") | F14: =IFERROR(C14*E14,"") | G14: =IFERROR(F14/$F$66,"")
B15: =IFERROR(VLOOKUP(H15,'[2]ARTICULOS MP PLANTA'!$A$2:$G$589,2,0),"")
A16: UNIDADES | B16: MATERIA PRIMA SEMIELABORADOS | C16: UNIDADES | D16: UND MEDIDA | E16: COSTO UNITARIO | F16: TOTAL COSTO | G16: % PREC. DEFINIDO | H16: CODIGOS
B17: =IFERROR(VLOOKUP(H17,[1]SEMIELABORADOS!$A$2:$M$6000,2,0),"") | C17: =+A17 -> 0 | D17: =IFERROR(VLOOKUP(H17,[1]SEMIELABORADOS!$A$2:$M$6000,6,0),"") | E17: =IFERROR(VLOOKUP(H17,[1]SEMIELABORADOS!$A$2:$H$65536,8,0),"") | F17: =IFERROR(E17*C17,"") | G17: =IFERROR(F17/$F$66,"")
B18: =IFERROR(VLOOKUP(H18,[1]SEMIELABORADOS!$A$2:$M$6000,2,0),"") | C18: =+A18 -> 0 | D18: =IFERROR(VLOOKUP(H18,[1]SEMIELABORADOS!$A$2:$M$6000,6,0),"") | E18: =IFERROR(VLOOKUP(H18,[1]SEMIELABORADOS!$A$2:$H$65536,8,0),"") | F18: =IFERROR(E18*C18,"") | G18: =IFERROR(F18/$F$66,"")
B19: =IFERROR(VLOOKUP(H19,[1]SEMIELABORADOS!$A$2:$M$6000,2,0),"") | C19: =+A19 -> 0 | D19: =IFERROR(VLOOKUP(H19,[1]SEMIELABORADOS!$A$2:$M$6000,6,0),"") | E19: =IFERROR(VLOOKUP(H19,[1]SEMIELABORADOS!$A$2:$H$65536,8,0),"") | F19: =IFERROR(E19*C19,"") | G19: =IFERROR(F19/$F$66,"")
B20: =IFERROR(VLOOKUP(H20,[1]SEMIELABORADOS!$A$2:$M$6000,2,0),"") | C20: =+A20 -> 0 | D20: =IFERROR(VLOOKUP(H20,[1]SEMIELABORADOS!$A$2:$M$6000,6,0),"") | E20: =IFERROR(VLOOKUP(H20,[1]SEMIELABORADOS!$A$2:$H$65536,8,0),"") | F20: =IFERROR(E20*C20,"") | G20: =IFERROR(F20/$F$66,"")
B21: =IFERROR(VLOOKUP(H21,[1]SEMIELABORADOS!$A$2:$M$6000,2,0),"") | C21: =+A21 -> 0 | D21: =IFERROR(VLOOKUP(H21,[1]SEMIELABORADOS!$A$2:$M$6000,6,0),"") | E21: =IFERROR(VLOOKUP(H21,[1]SEMIELABORADOS!$A$2:$H$65536,8,0),"") | F21: =IFERROR(E21*C21,"") | G21: =IFERROR(F21/$F$66,"")
B22: =IFERROR(VLOOKUP(H22,[1]SEMIELABORADOS!$A$2:$M$6000,2,0),"") | C22: =+A22 -> 0 | D22: =IFERROR(VLOOKUP(H22,[1]SEMIELABORADOS!$A$2:$M$6000,6,0),"") | E22: =IFERROR(VLOOKUP(H22,[1]SEMIELABORADOS!$A$2:$H$65536,8,0),"") | F22: =IFERROR(E22*C22,"") | G22: =IFERROR(F22/$F$66,"")
B23: =IFERROR(VLOOKUP(H23,[1]SEMIELABORADOS!$A$2:$M$6000,2,0),"") | C23: =+A23 -> 0 | D23: =IFERROR(VLOOKUP(H23,[1]SEMIELABORADOS!$A$2:$M$6000,6,0),"") | E23: =IFERROR(VLOOKUP(H23,[1]SEMIELABORADOS!$A$2:$H$65536,8,0),"") | F23: =IFERROR(E23*C23,"") | G23: =IFERROR(F23/$F$66,"")
B24: =IFERROR(VLOOKUP(H24,[1]SEMIELABORADOS!$A$2:$M$6000,2,0),"") | C24: =+A24 -> 0 | D24: =IFERROR(VLOOKUP(H24,[1]SEMIELABORADOS!$A$2:$M$6000,6,0),"") | E24: =IFERROR(VLOOKUP(H24,[1]SEMIELABORADOS!$A$2:$H$65536,8,0),"") | F24: =IFERROR(E24*C24,"") | G24: =IFERROR(F24/$F$66,"")
A26: UNIDADES | B26: EMPAQUE | C26: UNIDADES | D26: UND MEDIDA | E26: COSTO UNITARIO | F26: TOTAL COSTO | G26: % PREC. DEFINIDO | H26: CODIGOS
A27: 0 | B27: =IFERROR(VLOOKUP(H27,'[1]Consolidado MP Planta'!$A$2:$M$823,3,0),"") | C27: =+A27 -> 0 | D27: =IFERROR(VLOOKUP(H27,'[1]Consolidado MP Planta'!$A$2:$M$823,13,0),"") | E27: =IFERROR(VLOOKUP(H27,'[1]Consolidado MP Planta'!$A$2:$M$823,12,0),"") | F27: =IFERROR(C27*E27,"") | G27: =IFERROR(F27/$F$66,"")
B28: =IFERROR(VLOOKUP(H28,'[1]Consolidado MP Planta'!$A$2:$M$823,3,0),"") | C28: =+A28 -> 0 | D28: =IFERROR(VLOOKUP(H28,'[1]Consolidado MP Planta'!$A$2:$M$823,13,0),"") | E28: =IFERROR(VLOOKUP(H28,'[1]Consolidado MP Planta'!$A$2:$M$823,12,0),"") | F28: =IFERROR(C28*E28,"") | G28: =IFERROR(F28/$F$66,"")
B29: =IFERROR(VLOOKUP(H29,'[1]Consolidado MP Planta'!$A$2:$M$823,3,0),"") | C29: =+A29 -> 0 | D29: =IFERROR(VLOOKUP(H29,'[1]Consolidado MP Planta'!$A$2:$M$823,13,0),"") | E29: =IFERROR(VLOOKUP(H29,'[1]Consolidado MP Planta'!$A$2:$M$823,12,0),"") | F29: =IFERROR(C29*E29,"") | G29: =IFERROR(F29/$F$66,"")
B30: =IFERROR(VLOOKUP(H30,'[1]Consolidado MP Planta'!$A$2:$M$823,3,0),"") | C30: =+A30 -> 0 | D30: =IFERROR(VLOOKUP(H30,'[1]Consolidado MP Planta'!$A$2:$M$823,13,0),"") | E30: =IFERROR(VLOOKUP(H30,'[1]Consolidado MP Planta'!$A$2:$M$823,12,0),"") | F30: =IFERROR(C30*E30,"") | G30: =IFERROR(F30/$F$66,"")
B31: =IFERROR(VLOOKUP(H31,'[1]Consolidado MP Planta'!$A$2:$M$823,3,0),"") | C31: =+A31 -> 0 | D31: =IFERROR(VLOOKUP(H31,'[1]Consolidado MP Planta'!$A$2:$M$823,13,0),"") | E31: =IFERROR(VLOOKUP(H31,'[1]Consolidado MP Planta'!$A$2:$M$823,12,0),"") | F31: =IFERROR(C31*E31,"") | G31: =IFERROR(F31/$F$66,"")
B32: =IFERROR(VLOOKUP(H32,'[1]Consolidado MP Planta'!$A$2:$M$823,3,0),"") | C32: =+A32 -> 0 | D32: =IFERROR(VLOOKUP(H32,'[1]Consolidado MP Planta'!$A$2:$M$823,13,0),"") | E32: =IFERROR(VLOOKUP(H32,'[1]Consolidado MP Planta'!$A$2:$M$823,12,0),"") | F32: =IFERROR(C32*E32,"") | G32: =IFERROR(F32/$F$66,"")
A34: UNIDADES | B34: EMPAQUE SEMIELABORADOS | C34: UNIDADES | D34: UND MEDIDA | E34: COSTO UNITARIO | F34: TOTAL COSTO | G34: % PREC. DEFINIDO | H34: CODIGOS
A35: =+A17 -> 0 | B35: =IFERROR(VLOOKUP(H35,[1]SEMIELABORADOS!$A$2:$M$6000,2,0),"") | C35: =+A35 -> 0 | D35: =IFERROR(VLOOKUP(H35,[1]SEMIELABORADOS!$A$2:$M$6000,6,0),"") | E35: =IFERROR(VLOOKUP(H35,[1]SEMIELABORADOS!$A$2:$M$65536,10,0),"") | F35: =IFERROR(E35*C35,"") | G35: =IFERROR(F35/$F$66,"")
A36: =+A18 -> 0 | B36: =IFERROR(VLOOKUP(H36,[1]SEMIELABORADOS!$A$2:$M$6000,2,0),"") | C36: =+A36 -> 0 | D36: =IFERROR(VLOOKUP(H36,[1]SEMIELABORADOS!$A$2:$M$6000,6,0),"") | E36: =IFERROR(VLOOKUP(H36,[1]SEMIELABORADOS!$A$2:$M$65536,10,0),"") | F36: =IFERROR(E36*C36,"") | G36: =IFERROR(F36/$F$66,"")
A37: =+A19 -> 0 | B37: =IFERROR(VLOOKUP(H37,[1]SEMIELABORADOS!$A$2:$M$6000,2,0),"") | C37: =+A37 -> 0 | D37: =IFERROR(VLOOKUP(H37,[1]SEMIELABORADOS!$A$2:$M$6000,6,0),"") | E37: =IFERROR(VLOOKUP(H37,[1]SEMIELABORADOS!$A$2:$M$65536,10,0),"") | F37: =IFERROR(E37*C37,"") | G37: =IFERROR(F37/$F$66,"")
A38: =+A20 -> 0 | B38: =IFERROR(VLOOKUP(H38,[1]SEMIELABORADOS!$A$2:$M$6000,2,0),"") | C38: =+A38 -> 0 | D38: =IFERROR(VLOOKUP(H38,[1]SEMIELABORADOS!$A$2:$M$6000,6,0),"") | E38: =IFERROR(VLOOKUP(H38,[1]SEMIELABORADOS!$A$2:$M$65536,10,0),"") | F38: =IFERROR(E38*C38,"") | G38: =IFERROR(F38/$F$66,"")
A39: =+A21 -> 0 | B39: =IFERROR(VLOOKUP(H39,[1]SEMIELABORADOS!$A$2:$M$6000,2,0),"") | C39: =+A39 -> 0 | D39: =IFERROR(VLOOKUP(H39,[1]SEMIELABORADOS!$A$2:$M$6000,6,0),"") | E39: =IFERROR(VLOOKUP(H39,[1]SEMIELABORADOS!$A$2:$M$65536,10,0),"") | F39: =IFERROR(E39*C39,"") | G39: =IFERROR(F39/$F$66,"")
A40: =+A22 -> 0 | B40: =IFERROR(VLOOKUP(H40,[1]SEMIELABORADOS!$A$2:$M$6000,2,0),"") | C40: =+A40 -> 0 | D40: =IFERROR(VLOOKUP(H40,[1]SEMIELABORADOS!$A$2:$M$6000,6,0),"") | E40: =IFERROR(VLOOKUP(H40,[1]SEMIELABORADOS!$A$2:$M$65536,10,0),"") | F40: =IFERROR(E40*C40,"") | G40: =IFERROR(F40/$F$66,"")
A41: =+A23 -> 0 | B41: =IFERROR(VLOOKUP(H41,[1]SEMIELABORADOS!$A$2:$M$6000,2,0),"") | C41: =+A41 -> 0 | D41: =IFERROR(VLOOKUP(H41,[1]SEMIELABORADOS!$A$2:$M$6000,6,0),"") | E41: =IFERROR(VLOOKUP(H41,[1]SEMIELABORADOS!$A$2:$M$65536,10,0),"") | F41: =IFERROR(E41*C41,"") | G41: =IFERROR(F41/$F$66,"")
A43: UNIDADES | B43: MODI | C43: UNIDADES | D43: UND MEDIDA | E43: COSTO UNITARIO | F43: TOTAL COSTO | G43: % PREC. DEFINIDO | H43: CODIGOS
A44: =+A35 -> 0 | B44: =IFERROR(VLOOKUP(H44,[1]SEMIELABORADOS!$A$2:$M$6000,2,0),"") | C44: =+A44 -> 0 | D44: =IFERROR(VLOOKUP(H44,[1]SEMIELABORADOS!$A$2:$M$6000,6,0),"") | E44: =IFERROR(VLOOKUP(H44,[1]SEMIELABORADOS!$A$2:$M$65536,12,0),"") | F44: =IFERROR(E44*C44,"") | G44: =IFERROR(F44/$F$66,"")
A45: =+A36 -> 0 | B45: =IFERROR(VLOOKUP(H45,[1]SEMIELABORADOS!$A$2:$M$6000,2,0),"") | C45: =+A45 -> 0 | D45: =IFERROR(VLOOKUP(H45,[1]SEMIELABORADOS!$A$2:$M$6000,6,0),"") | E45: =IFERROR(VLOOKUP(H45,[1]SEMIELABORADOS!$A$2:$M$65536,12,0),"") | F45: =IFERROR(E45*C45,"") | G45: =IFERROR(F45/$F$66,"")
...

Sheet Costo Rosquete Arrollado 80
E1: Precio Local | F1: Costo MP | G1: Costo EM | H1: Costo MO
E2: =IFERROR(O62,"") -> 247.4123 | F2: =IFERROR(H53,"") -> 151.8 | G2: =IFERROR(H54,"") -> 0.9 | H2: =IFERROR(H56,"") -> 48.55
A5: ESTRUCTURA DE COSTOS
F6: Fecha: | H6: =TODAY() -> 45715
A7: UNIDADES | B7: DESCRIPCION MAT.PRIMA | C7: UNIDADES | D7: UND MEDIDA | E7: COSTO UNITARIO | F7: TOTAL COSTO | G7: % PREC. DEFINIDO | H7: CODIGOS
B8: =IFERROR(VLOOKUP(H8,'[1]Consolidado MP Planta'!$A$2:$M$823,3,0),"") | C8: =+A8 -> 0 | D8: =IFERROR(VLOOKUP(H8,'[1]Consolidado MP Planta'!$A$2:$M$823,13,0),"") | E8: =IFERROR(VLOOKUP(H8,'[1]Consolidado MP Planta'!$A$2:$M$823,12,0),"") | F8: =IFERROR(C8*E8,"") | G8: =IFERROR(F8/$F$66,"")
B9: =IFERROR(VLOOKUP(H9,'[1]Consolidado MP Planta'!$A$2:$M$823,3,0),"") | C9: =+A9 -> 0 | D9: =IFERROR(VLOOKUP(H9,'[1]Consolidado MP Planta'!$A$2:$M$823,13,0),"") | E9: =IFERROR(VLOOKUP(H9,'[1]Consolidado MP Planta'!$A$2:$M$823,12,0),"") | F9: =IFERROR(C9*E9,"") | G9: =IFERROR(F9/$F$66,"")
B10: =IFERROR(VLOOKUP(H10,'[1]Consolidado MP Planta'!$A$2:$M$823,3,0),"") | C10: =+A10 -> 0 | D10: =IFERROR(VLOOKUP(H10,'[1]Consolidado MP Planta'!$A$2:$M$823,13,0),"") | E10: =IFERROR(VLOOKUP(H10,'[1]Consolidado MP Planta'!$A$2:$M$823,12,0),"") | F10: =IFERROR(C10*E10,"") | G10: =IFERROR(F10/$F$66,"")
B11: =IFERROR(VLOOKUP(H11,'[1]Consolidado MP Planta'!$A$2:$M$823,3,0),"") | C11: =+A11 -> 0 | D11: =IFERROR(VLOOKUP(H11,'[1]Consolidado MP Planta'!$A$2:$M$823,13,0),"") | E11: =IFERROR(VLOOKUP(H11,'[1]Consolidado MP Planta'!$A$2:$M$823,12,0),"") | F11: =IFERROR(C11*E11,"") | G11: =IFERROR(F11/$F$66,"")
B12: =IFERROR(VLOOKUP(H12,'[1]Consolidado MP Planta'!$A$2:$M$823,3,0),"") | C12: =+A12 -> 0 | D12: =IFERROR(VLOOKUP(H12,'[1]Consolidado MP Planta'!$A$2:$M$823,13,0),"") | E12: =IFERROR(VLOOKUP(H12,'[1]Consolidado MP Planta'!$A$2:$M$823,12,0),"") | F12: =IFERROR(C12*E12,"") | G12: =IFERROR(F12/$F$66,"")
B13: =IFERROR(VLOOKUP(H13,'[1]Consolidado MP Planta'!$A$2:$M$823,3,0),"") | C13: =+A13 -> 0 | D13: =IFERROR(VLOOKUP(H13,'[1]Consolidado MP Planta'!$A$2:$M$823,13,0),"") | E13: =IFERROR(VLOOKUP(H13,'[1]Consolidado MP Planta'!$A$2:$M$823,12,0),"") | F13: =IFERROR(C13*E13,"") | G13: =IFERROR(F13/$F$66,"")
B14: =IFERROR(VLOOKUP(H14,'[1]Consolidado MP Planta'!$A$2:$M$823,3,0),"") | C14: =+A14 -> 0 | D14: =IFERROR(VLOOKUP(H14,'[1]Consolidado MP Planta'!$A$2:$M$823,13,0),"") | E14: =IFERROR(VLOOKUP(H14,'[1]Consolidado MP Planta'!$A$2:$M$823,12,0),"") | F14: =IFERROR(C14*E14,"") | G14: =IFERROR(F14/$F$66,"")
B15: =IFERROR(VLOOKUP(H15,'[2]ARTICULOS MP PLANTA'!$A$2:$G$589,2,0),"")
A16: UNIDADES | B16: MATERIA PRIMA SEMIELABORADOS | C16: UNIDADES | D16: UND MEDIDA | E16: COSTO UNITARIO | F16: TOTAL COSTO | G16: % PREC. DEFINIDO | H16: CODIGOS
A17: 80 | B17: =IFERROR(VLOOKUP(H17,[1]SEMIELABORADOS!$A$2:$M$6000,2,0),"") -> BATIDO ROSQUETE ARROLLADO KILO | C17: =+A17 -> 80 | D17: =IFERROR(VLOOKUP(H17,[1]SEMIELABORADOS!$A$2:$M$6000,6,0),"") -> Gramo | E17: 1.77 | F17: =IFERROR(E17*C17,"") -> 141.6 | G17: =IFERROR(F17/$F$66,"") -> 0.76032561 | H17: 907000200
A18: 5 | B18: =IFERROR(VLOOKUP(H18,[1]SEMIELABORADOS!$A$2:$M$6000,2,0),"") -> MEZCLA P/ENGRASE MOLDES KILO | C18: =+A18 -> 5 | D18: =IFERROR(VLOOKUP(H18,[1]SEMIELABORADOS!$A$2:$M$6000,6,0),"") -> Gramo | E18: 2.04 | F18: =IFERROR(E18*C18,"") -> 10.2 | G18: =IFERROR(F18/$F$66,"") -> 0.054769218 | H18: 902000019
B19: =IFERROR(VLOOKUP(H19,[1]SEMIELABORADOS!$A$2:$M$6000,2,0),"") | C19: =+A19 -> 0 | D19: =IFERROR(VLOOKUP(H19,[1]SEMIELABORADOS!$A$2:$M$6000,6,0),"") | E19: =IFERROR(VLOOKUP(H19,[1]SEMIELABORADOS!$A$2:$H$65536,8,0),"") | F19: =IFERROR(E19*C19,"") | G19: =IFERROR(F19/$F$66,"")
B20: =IFERROR(VLOOKUP(H20,[1]SEMIELABORADOS!$A$2:$M$6000,2,0),"") | C20: =+A20 -> 0 | D20: =IFERROR(VLOOKUP(H20,[1]SEMIELABORADOS!$A$2:$M$6000,6,0),"") | E20: =IFERROR(VLOOKUP(H20,[1]SEMIELABORADOS!$A$2:$H$65536,8,0),"") | F20: =IFERROR(E20*C20,"") | G20: =IFERROR(F20/$F$66,"")
B21: =IFERROR(VLOOKUP(H21,[1]SEMIELABORADOS!$A$2:$M$6000,2,0),"") | C21: =+A21 -> 0 | D21: =IFERROR(VLOOKUP(H21,[1]SEMIELABORADOS!$A$2:$M$6000,6,0),"") | E21: =IFERROR(VLOOKUP(H21,[1]SEMIELABORADOS!$A$2:$H$65536,8,0),"") | F21: =IFERROR(E21*C21,"") | G21: =IFERROR(F21/$F$66,"")
B22: =IFERROR(VLOOKUP(H22,[1]SEMIELABORADOS!$A$2:$M$6000,2,0),"") | C22: =+A22 -> 0 | D22: =IFERROR(VLOOKUP(H22,[1]SEMIELABORADOS!$A$2:$M$6000,6,0),"") | E22: =IFERROR(VLOOKUP(H22,[1]SEMIELABORADOS!$A$2:$H$65536,8,0),"") | F22: =IFERROR(E22*C22,"") | G22: =IFERROR(F22/$F$66,"")
B23: =IFERROR(VLOOKUP(H23,[1]SEMIELABORADOS!$A$2:$M$6000,2,0),"") | C23: =+A23 -> 0 | D23: =IFERROR(VLOOKUP(H23,[1]SEMIELABORADOS!$A$2:$M$6000,6,0),"") | E23: =IFERROR(VLOOKUP(H23,[1]SEMIELABORADOS!$A$2:$H$65536,8,0),"") | F23: =IFERROR(E23*C23,"") | G23: =IFERROR(F23/$F$66,"")
B24: =IFERROR(VLOOKUP(H24,[1]SEMIELABORADOS!$A$2:$M$6000,2,0),"") | C24: =+A24 -> 0 | D24: =IFERROR(VLOOKUP(H24,[1]SEMIELABORADOS!$A$2:$M$6000,6,0),"") | E24: =IFERROR(VLOOKUP(H24,[1]SEMIELABORADOS!$A$2:$H$65536,8,0),"") | F24: =IFERROR(E24*C24,"") | G24: =IFERROR(F24/$F$66,"")
A26: UNIDADES | B26: EMPAQUE | C26: UNIDADES | D26: UND MEDIDA | E26: COSTO UNITARIO | F26: TOTAL COSTO | G26: % PREC. DEFINIDO | H26: CODIGOS
A27: 0 | B27: =IFERROR(VLOOKUP(H27,'[1]Consolidado MP Planta'!$A$2:$M$823,3,0),"") | C27: =+A27 -> 0 | D27: =IFERROR(VLOOKUP(H27,'[1]Consolidado MP Planta'!$A$2:$M$823,13,0),"") | E27: =IFERROR(VLOOKUP(H27,'[1]Consolidado MP Planta'!$A$2:$M$823,12,0),"") | F27: =IFERROR(C27*E27,"") | G27: =IFERROR(F27/$F$66,"")
B28: =IFERROR(VLOOKUP(H28,'[1]Consolidado MP Planta'!$A$2:$M$823,3,0),"") | C28: =+A28 -> 0 | D28: =IFERROR(VLOOKUP(H28,'[1]Consolidado MP Planta'!$A$2:$M$823,13,0),"") | E28: =IFERROR(VLOOKUP(H28,'[1]Consolidado MP Planta'!$A$2:$M$823,12,0),"") | F28: =IFERROR(C28*E28,"") | G28: =IFERROR(F28/$F$66,"")
B29: =IFERROR(VLOOKUP(H29,'[1]Consolidado MP Planta'!$A$2:$M$823,3,0),"") | C29: =+A29 -> 0 | D29: =IFERROR(VLOOKUP(H29,'[1]Consolidado MP Planta'!$A$2:$M$823,13,0),"") | E29: =IFERROR(VLOOKUP(H29,'[1]Consolidado MP Planta'!$A$2:$M$823,12,0),"") | F29: =IFERROR(C29*E29,"") | G29: =IFERROR(F29/$F$66,"")
B30: =IFERROR(VLOOKUP(H30,'[1]Consolidado MP Planta'!$A$2:$M$823,3,0),"") | C30: =+A30 -> 0 | D30: =IFERROR(VLOOKUP(H30,'[1]Consolidado MP Planta'!$A$2:$M$823,13,0),"") | E30: =IFERROR(VLOOKUP(H30,'[1]Consolidado MP Planta'!$A$2:$M$823,12,0),"") | F30: =IFERROR(C30*E30,"") | G30: =IFERROR(F30/$F$66,"")
B31: =IFERROR(VLOOKUP(H31,'[1]Consolidado MP Planta'!$A$2:$M$823,3,0),"") | C31: =+A31 -> 0 | D31: =IFERROR(VLOOKUP(H31,'[1]Consolidado MP Planta'!$A$2:$M$823,13,0),"") | E31: =IFERROR(VLOOKUP(H31,'[1]Consolidado MP Planta'!$A$2:$M$823,12,0),"") | F31: =IFERROR(C31*E31,"") | G31: =IFERROR(F31/$F$66,"")
B32: =IFERROR(VLOOKUP(H32,'[1]Consolidado MP Planta'!$A$2:$M$823,3,0),"") | C32: =+A32 -> 0 | D32: =IFERROR(VLOOKUP(H32,'[1]Consolidado MP Planta'!$A$2:$M$823,13,0),"") | E32: =IFERROR(VLOOKUP(H32,'[1]Consolidado MP Planta'!$A$2:$M$823,12,0),"") | F32: =IFERROR(C32*E32,"") | G32: =IFERROR(F32/$F$66,"")
A34: UNIDADES | B34: EMPAQUE SEMIELABORADOS | C34: UNIDADES | D34: UND MEDIDA | E34: COSTO UNITARIO | F34: TOTAL COSTO | G34: % PREC. DEFINIDO | H34: CODIGOS
A35: =+A17 -> 80 | B35: =IFERROR(VLOOKUP(H35,[1]SEMIELABORADOS!$A$2:$M$6000,2,0),"") -> BATIDO ROSQUETE ARROLLADO KILO | C35: =+A35 -> 80 | D35: =IFERROR(VLOOKUP(H35,[1]SEMIELABORADOS!$A$2:$M$6000,6,0),"") -> Gramo | E35: 0.01 | F35: =IFERROR(E35*C35,"") -> 0.8 | G35: =IFERROR(F35/$F$66,"") -> 0.0042956249 | H35: 907000200
A36: =+A18 -> 5 | B36: =IFERROR(VLOOKUP(H36,[1]SEMIELABORADOS!$A$2:$M$6000,2,0),"") -> MEZCLA P/ENGRASE MOLDES KILO | C36: =+A36 -> 5 | D36: =IFERROR(VLOOKUP(H36,[1]SEMIELABORADOS!$A$2:$M$6000,6,0),"") -> Gramo | E36: 0.02 | F36: =IFERROR(E36*C36,"") -> 0.1 | G36: =IFERROR(F36/$F$66,"") -> 0.00053695311 | H36: 902000019
A37: =+A19 -> 0 | B37: =IFERROR(VLOOKUP(H37,[1]SEMIELABORADOS!$A$2:$M$6000,2,0),"") | C37: =+A37 -> 0 | D37: =IFERROR(VLOOKUP(H37,[1]SEMIELABORADOS!$A$2:$M$6000,6,0),"") | E37: =IFERROR(VLOOKUP(H37,[1]SEMIELABORADOS!$A$2:$M$65536,10,0),"") | F37: =IFERROR(E37*C37,"") | G37: =IFERROR(F37/$F$66,"")
A38: =+A20 -> 0 | B38: =IFERROR(VLOOKUP(H38,[1]SEMIELABORADOS!$A$2:$M$6000,2,0),"") | C38: =+A38 -> 0 | D38: =IFERROR(VLOOKUP(H38,[1]SEMIELABORADOS!$A$2:$M$6000,6,0),"") | E38: =IFERROR(VLOOKUP(H38,[1]SEMIELABORADOS!$A$2:$M$65536,10,0),"") | F38: =IFERROR(E38*C38,"") | G38: =IFERROR(F38/$F$66,"")
A39: =+A21 -> 0 | B39: =IFERROR(VLOOKUP(H39,[1]SEMIELABORADOS!$A$2:$M$6000,2,0),"") | C39: =+A39 -> 0 | D39: =IFERROR(VLOOKUP(H39,[1]SEMIELABORADOS!$A$2:$M$6000,6,0),"") | E39: =IFERROR(VLOOKUP(H39,[1]SEMIELABORADOS!$A$2:$M$65536,10,0),"") | F39: =IFERROR(E39*C39,"") | G39: =IFERROR(F39/$F$66,"")
A40: =+A22 -> 0 | B40: =IFERROR(VLOOKUP(H40,[1]SEMIELABORADOS!$A$2:$M$6000,2,0),"") | C40: =+A40 -> 0 | D40: =IFERROR(VLOOKUP(H40,[1]SEMIELABORADOS!$A$2:$M$6000,6,0),"") | E40: =IFERROR(VLOOKUP(H40,[1]SEMIELABORADOS!$A$2:$M$65536,10,0),"") | F40: =IFERROR(E40*C40,"") | G40: =IFERROR(F40/$F$66,"")
A41: =+A23 -> 0 | B41: =IFERROR(VLOOKUP(H41,[1]SEMIELABORADOS!$A$2:$M$6000,2,0),"") | C41: =+A41 -> 0 | D41: =IFERROR(VLOOKUP(H41,[1]SEMIELABORADOS!$A$2:$M$6000,6,0),"") | E41: =IFERROR(VLOOKUP(H41,[1]SEMIELABORADOS!$A$2:$M$65536,10,0),"") | F41: =IFERROR(E41*C41,"") | G41: =IFERROR(F41/$F$66,"")
A43: UNIDADES | B43: MODI | C43: UNIDADES | D43: UND MEDIDA | E43: COSTO UNITARIO | F43: TOTAL COSTO | G43: % PREC. DEFINIDO | H43: CODIGOS
A44: =+A35 -> 80 | B44: =IFERROR(VLOOKUP(H44,[1]SEMIELABORADOS!$A$2:$M$6000,2,0),"") -> BATIDO ROSQUETE ARROLLADO KILO | C44: =+A44 -> 80 | D44: =IFERROR(VLOOKUP(H44,[1]SEMIELABORADOS!$A$2:$M$6000,6,0),"") -> Gramo | E44: 0.21 | F44: =IFERROR(E44*C44,"") -> 16.8 | G44: =IFERROR(F44/$F$66,"") -> 0.090208123 | H44: 907000200
A45: =+A36 -> 5 | B45: =IFERROR(VLOOKUP(H45,[1]SEMIELABORADOS!$A$2:$M$6000,2,0),"") -> MEZCLA P/ENGRASE MOLDES KILO | C45: =+A45 -> 5 | D45: =IFERROR(VLOOKUP(H45,[1]SEMIELABORADOS!$A$2:$M$6000,6,0),"") -> Gramo | E45: 0.25 | F45: =IFERROR(E45*C45,"") -> 1.25 | G45: =IFERROR(F45/$F$66,"") -> 0.0067119139 | H45: 902000019
...

Sheet Hoja1
C1: SERVICIOS DE PASTELERIA S.A. | H1: CÓDIGO: | I1: ESP-RE-BAS-004
C2: ESPECIFICACION DE RECETA | H2: REVISIÓN: | I2: 01
C3: SE00651 Rosquete de Arrollado de 100 g | H3: FECHA DE APROBACIÓN: | I3: 45617
C4: Elaborado | D4: Javier Tong, Chef
C5: Aprobado | D5: Esteban Cartin, Gte Manufactura
A6: AREA QUE PRODUCE: | D6: Batidos | G6: AREA QUE EMPACA: | I6: Batidos
A7: # Código | B7: # Código Netsuite | C7: Descripción del ingrediente | D7: Marca | E7: Unidad Internacional | G7: Medida alternativa | I7: Costo - Referencia
E8: Cantidad | F8: Unidad medida | G8: Cantidad | H8: Unidad medida | I8: Colones
C9: Ensamble
A10: 907000200 | B10: SE00452 | C10: BATIDO ARROLLADO SPOON 100G | D10: FAS | E10: 100 | F10: g
A12: 902000019 | C12: MEZCLA P/ENGRASE MOLDES KILO | D12: FAS | E12: 5 | F12: g
C24: Decoración
C29: Empaque
D39: Cantidad | E39: Unidad
A40: PESO TOTAL OBTENIDO | D40: 100 | E40: g | F40: Tiempo de Horneo:
A41: TIEMPO TOTAL DE PREPARACION | D41: 0.5 | E41: min | F41: Horno:
A42: CANTIDAD DE PORCIONES OBTENIDAS | D42: 1 | E42: ud | F42: Temperatura de Horneo:
A43: PESO DE CADA PORCIÓN | D43: 100 | E43: g | F43: Otros
A44: MERMA | D44: 5 | E44: g
A45: PROCEDIMIENTO DE PREPARACION DE LA RECETA
A46: 1-En Molde 10 cm Colocar Papel de Horneo y engrasar y agregar 100 gramos de la mezcla de Batido de Arrollado Spoon
A47: 2-Hornear por un lapso de ?? a un tiempo de ?? En Horno ??
A48: 3-Desmoldar y dejar enfriar,
A54: CONTROL DE CAMBIOS

Sheet Batido arrollado 
C1: SERVICIOS DE PASTELERIA S.A. | H1: CÓDIGO: | I1: ESP-RE-BAS-004
C2: ESPECIFICACION DE RECETA | H2: REVISIÓN: | I2: 09
C3: BATIDO ROSQUETE ARROLLADO SPOON KILO 907000200(SE00452) | H3: FECHA DE APROBACIÓN: | I3: 44109
C4: Elaborado | D4: Enmanuel Madrigal, Chef
C5: Aprobado | D5: Jeffry Rodriguez. Gte de Manufactura
A6: AREA QUE PRODUCE: | D6: BATIDOS | G6: AREA QUE EMPACA: | I6: POSTRES
A7: # Código | B7: # Codigo Netsuite | C7: Descripción del ingrediente | D7: Marca | E7: Unidad Internacional | G7: Medida alternativa | I7: Costo - Referencia
E8: Cantidad | F8: Unidad medida | G8: Cantidad | H8: Unidad medida | I8: Colones
A10: 95362 | B10: SE00197 | C10: BASE PREMEZCLA ARROLLADO SPOON KILO | D10: FAS | E10: 1227 | F10: g
A11: 11300009 | B11: MP10141 | C11: CLARA HUEVO PASTE DEB-EL (CAJA:2.267 K) | D11: Mayca | E11: 1200 | F11: g
A12: 11300011 | B12: MP10037 | C12: Yema De Huevo Pasteurizada | D12: Innovo | E12: 650 | F12: g
D15: Cantidad | E15: Unidad
A16: PESO TOTAL OBTENIDO | D16: 3000 | E16: g | F16: Tiempo de Horneo: | H16: 15 min | I16: 15 min
A17: TIEMPO TOTAL DE PREPARACION | D17: 5 | E17: min | F17: Horno: | H17: Argental - Marshall | I17: Dicte
A18: CANTIDAD DE PORCIONES OBTENIDAS | D18: 3 | E18: uds | F18: Temperatura de Horneo: | H18: 175°C | I18: 170°C
A19: PESO DE CADA PORCIÓN | D19: =D16/D18 -> 1000 | E19: g | F19: Otros
A20: MERMA | D20: 77 | E20: g
A21: PROCEDIMIENTO DE PREPARACION DE LA RECETA
A22: 1-. Poner a crecer la yema y la clara en la batidora con el azúcar, preservante y polvo de hornear a velocidad maxima, hasta obetener punto cinta por 40 minutos aproximadamente.
A23: 2-. Bajar la velocidad de la batidora a mínimo y agregar la harina. No batir mucho.
A24: 3-. La mezcla debe de quedar homogénea y esponjosa, limpiar los bordes de la batidora con una espatula.
A25: 4-. Hornear por 15 minutos en Argental o Marshall a 175°C o en el Dicte 3 a 170°C por 15 minutos
A29: CONTROL DE CAMBIOS
A30: Versión #09 : Se actualiza formato, tiempos y temperaturas de horneos

Sheet Premezcla Batido arrollado
B1: SERVICIOS DE PASTELERIA S.A. | G1: CÓDIGO: | H1: ESP-RE-PRES-008
B2: ESPECIFICACION DE RECETA | G2: REVISIÓN: | H2: 11
B3: Pre Mezcla Arrollado Spoon (95362) | G3: FECHA DE APROBACIÓN: | H3: 15/03/2023
B4: Elaborado | C4: Javier Tong, Chef
B5: Aprobado | C5: Esteban Cartin, Gte Manofactura.
A6: AREA QUE PRODUCE: | C6: Premezcla | F6: AREA QUE EMPACA: | H6: Premezcla
A7: # Código | B7: Descripción del ingrediente | C7: Marca | D7: Unidad Internacional | F7: Medida alternativa | H7: Costo - Referencia
D8: Cantidad | E8: Unidad medida | F8: Cantidad | G8: Unidad medida | H8: Colones
A10: 510107 | B10: HARINA HARISOL WINTER (SACO:25 KG) | C10: Nacarina | D10: 500 | E10: g
A11: 510301 | B11: AZUCAR BLANCO (INDUSTRIAL) | C11: Laica | D11: 680 | E11: g
A12: 10100046 | B12: POLVO HORNEAR FLEISHMAN (PAQ:2.5 K) | C12: Fleishman | D12: 40 | E12: g
A13: 1212410 | B13: PRESERVANTE 1047S(PAQ=5 KILO) | C13: Alseal | D13: 7 | E13: g
A15: 1950705 | B15: BOLSA 8x12 TRANSPARENTE KILO | C15: Plasticos P | D15: 2 | E15: ud
A16: 1950704 | B16: BOLSA 5x8 TRANSP (KILO) | C16: Plasticos P | D16: 2 | E16: ud
A17: 0702123 | B17: ETIQUETA BLANCA 2 5/8X1 15/16 (UND) | C17: Etiplast | D17: 1 | E17: ud
A18: 60100010 | B18: ETIQUETA ROJA LETRA ALERJENO (UND) | C18: Etiplast | D18: 1 | E18: ud
C20: Cantidad | D20: Unidad
A21: PESO TOTAL OBTENIDO | C21: =SUM(D10:D13) -> 1227 | D21: g
A22: TIEMPO TOTAL DE PREPARACION | C22: 1 | D22: Minuto
A23: CANTIDAD DE PORCIONES OBTENIDAS | C23: 1 | D23: Tanda
A24: PESO DE CADA PORCIÓN | C24: =C21 -> 1227 | D24: g
A25: MERMA | C25: 0 | D25: g
A26: PROCEDIMIENTO DE PREPARACION DE LA RECETA
A27: 1.- Pesar todos los ingredientes por separado.
A28: 2.- En la bosa 8*12 pesar la harina.
A29: 3.- En la bolsa 8*12 pesar el azucar.
A30: 4.- En la bolsa 5*8 pesar el preservante y el la otra el polvo de hornear.
A31: 5.- Colocar todas las bolsas dentro de la bolsa del azucar.
A32: 6.- Etiquetar con fecha de vencimiento y alerjeno
A34: CONTROL DE CAMBIOS
A35: Revisión #9: Actualización de codigos y procedimiento.
A36: Revisión #10: Cambio de harina Nacarina
A37: Revisoin #11: Cambio de harina

Sheet Costo Rosqute Arr 100
E1: Precio Local | F1: Costo MP | G1: Costo EM | H1: Costo MO
E2: =IFERROR(O62,"") -> 291.20574 | F2: =IFERROR(H53,"") -> 187.2 | G2: =IFERROR(H54,"") -> 1.1 | H2: =IFERROR(H56,"") -> 52.75
A5: ESTRUCTURA DE COSTOS
F6: Fecha: | H6: =TODAY() -> 45715
A7: UNIDADES | B7: DESCRIPCION MAT.PRIMA | C7: UNIDADES | D7: UND MEDIDA | E7: COSTO UNITARIO | F7: TOTAL COSTO | G7: % PREC. DEFINIDO | H7: CODIGOS
B8: =IFERROR(VLOOKUP(H8,'[1]Consolidado MP Planta'!$A$2:$M$823,3,0),"") | C8: =+A8 -> 0 | D8: =IFERROR(VLOOKUP(H8,'[1]Consolidado MP Planta'!$A$2:$M$823,13,0),"") | E8: =IFERROR(VLOOKUP(H8,'[1]Consolidado MP Planta'!$A$2:$M$823,12,0),"") | F8: =IFERROR(C8*E8,"") | G8: =IFERROR(F8/$F$66,"")
B9: =IFERROR(VLOOKUP(H9,'[1]Consolidado MP Planta'!$A$2:$M$823,3,0),"") | C9: =+A9 -> 0 | D9: =IFERROR(VLOOKUP(H9,'[1]Consolidado MP Planta'!$A$2:$M$823,13,0),"") | E9: =IFERROR(VLOOKUP(H9,'[1]Consolidado MP Planta'!$A$2:$M$823,12,0),"") | F9: =IFERROR(C9*E9,"") | G9: =IFERROR(F9/$F$66,"")
B10: =IFERROR(VLOOKUP(H10,'[1]Consolidado MP Planta'!$A$2:$M$823,3,0),"") | C10: =+A10 -> 0 | D10: =IFERROR(VLOOKUP(H10,'[1]Consolidado MP Planta'!$A$2:$M$823,13,0),"") | E10: =IFERROR(VLOOKUP(H10,'[1]Consolidado MP Planta'!$A$2:$M$823,12,0),"") | F10: =IFERROR(C10*E10,"") | G10: =IFERROR(F10/$F$66,"")
B11: =IFERROR(VLOOKUP(H11,'[1]Consolidado MP Planta'!$A$2:$M$823,3,0),"") | C11: =+A11 -> 0 | D11: =IFERROR(VLOOKUP(H11,'[1]Consolidado MP Planta'!$A$2:$M$823,13,0),"") | E11: =IFERROR(VLOOKUP(H11,'[1]Consolidado MP Planta'!$A$2:$M$823,12,0),"") | F11: =IFERROR(C11*E11,"") | G11: =IFERROR(F11/$F$66,"")
B12: =IFERROR(VLOOKUP(H12,'[1]Consolidado MP Planta'!$A$2:$M$823,3,0),"") | C12: =+A12 -> 0 | D12: =IFERROR(VLOOKUP(H12,'[1]Consolidado MP Planta'!$A$2:$M$823,13,0),"") | E12: =IFERROR(VLOOKUP(H12,'[1]Consolidado MP Planta'!$A$2:$M$823,12,0),"") | F12: =IFERROR(C12*E12,"") | G12: =IFERROR(F12/$F$66,"")
B13: =IFERROR(VLOOKUP(H13,'[1]Consolidado MP Planta'!$A$2:$M$823,3,0),"") | C13: =+A13 -> 0 | D13: =IFERROR(VLOOKUP(H13,'[1]Consolidado MP Planta'!$A$2:$M$823,13,0),"") | E13: =IFERROR(VLOOKUP(H13,'[1]Consolidado MP Planta'!$A$2:$M$823,12,0),"") | F13: =IFERROR(C13*E13,"") | G13: =IFERROR(F13/$F$66,"")
B14: =IFERROR(VLOOKUP(H14,'[1]Consolidado MP Planta'!$A$2:$M$823,3,0),"") | C14: =+A14 -> 0 | D14: =IFERROR(VLOOKUP(H14,'[1]Consolidado MP Planta'!$A$2:$M$823,13,0),"") | E14: =IFERROR(VLOOKUP(H14,'[1]Consolidado MP Planta'!$A$2:$M$823,12,0),"") | F14: =IFERROR(C14*E14,"") | G14: =IFERROR(F14/$F$66,"")
B15: =IFERROR(VLOOKUP(H15,'[2]ARTICULOS MP PLANTA'!$A$2:$G$589,2,0),"")
A16: UNIDADES | B16: MATERIA PRIMA SEMIELABORADOS | C16: UNIDADES | D16: UND MEDIDA | E16: COSTO UNITARIO | F16: TOTAL COSTO | G16: % PREC. DEFINIDO | H16: CODIGOS
A17: 100 | B17: =IFERROR(VLOOKUP(H17,[1]SEMIELABORADOS!$A$2:$M$6000,2,0),"") -> BATIDO ROSQUETE ARROLLADO KILO | C17: =+A17 -> 100 | D17: =IFERROR(VLOOKUP(H17,[1]SEMIELABORADOS!$A$2:$M$6000,6,0),"") -> Gramo | E17: 1.77 | F17: =IFERROR(E17*C17,"") -> 177 | G17: =IFERROR(F17/$F$66,"") -> 0.79534834 | H17: 907000200
A18: 5 | B18: =IFERROR(VLOOKUP(H18,[1]SEMIELABORADOS!$A$2:$M$6000,2,0),"") -> MEZCLA P/ENGRASE MOLDES KILO | C18: =+A18 -> 5 | D18: =IFERROR(VLOOKUP(H18,[1]SEMIELABORADOS!$A$2:$M$6000,6,0),"") -> Gramo | E18: 2.04 | F18: =IFERROR(E18*C18,"") -> 10.2 | G18: =IFERROR(F18/$F$66,"") -> 0.045833633 | H18: 902000019
