Workbook

Sheet Premezcla Batido Zanahoria 
B1: SERVICIOS DE PASTELERIA S.A. | G1: CÓDIGO:
B2: ESPECIFICACION DE RECETA | G2: REVISIÓN:
B3: Premezcla Batido de Zanahoria | G3: FECHA DE APROBACIÓN:
B4: Elaborado | C4: Maria Jose Rodriguez, Chef
B5: Aprobado | C5: Esteban Cartin, Gte Manufactura
A6: # Código | B6: Descripción del ingrediente | C6: Marca | D6: Unidad Internacional | F6: Medida alternativa | H6: Costo - Referencia
D7: Cantidad | E7: Unidad medida | F7: Cantidad | G7: Unidad medida | H7: Colones
A8: 11200064 | B8: Harina Trigo Nacarina | C8: Nacarina | D8: 2275 | E8: g
A9: 503000036 | B9: BICARBONATO DE SODIO (PAQ:2.5 K) | C9: Pastelero | D9: 50 | E9: g
A10: 10100046 | B10: POLVO HORNEAR FLEISHMAN (PAQ:2.5 K) | C10: Royal | D10: 50 | E10: g
A11: 10100122 | B11: CANELA EN POLVO BADIA (UND: 1.82 K) | C11: Badia | D11: 50 | E11: g
A12: 5000001 | B12: SAL INDUSTRIA (SACO:25 Kg) | C12: Atlantida | D12: 50 | E12: g
A13: 0512262 | B13: PROPIONATO DE CALCIO | C13: Crystal Pro | D13: 7 | E13: g
A14: 0512261 | B14: ACIDO SORBICO | C14: Beyco | D14: 7 | E14: g
A16: 10100045 | B16: MP10075 | C16: Azucar Caramelo | D16: Zukra | E16: 1100 | F16: g | I16: Falta precio actualizado
A17: 510301 | B17: Azucar Blanco Industrial | C17: Maria | D17: 1100 | E17: g
A19: 510262 | B19: PECANA ENTERA (CAJA:13.6 K) | C19: Nueces Ind | D19: 800 | E19: g
B21: EMPAQUE
A22: 1950702 | B22: Bolsa 12X18 Transparente | C22: Plasticos P | D22: 1 | E22: ud
A23: 1950708 | B23: Bolsa 17X25 Transparente | C23: Plasticos P | D23: 2 | E23: ud
A24: 60100010 | B24: ETIQUETA ROJA LETRA ALERJENO (UND) | C24: Etiplast | D24: 2 | E24: ud
A25: 0702123 | B25: ETIQUETA BLANCA 2 5/8X1 15/16 (UND) | C25: Etiplast | D25: 2 | E25: ud
C27: Cantidad | D27: Unidad
A28: PESO TOTAL OBTENIDO | C28: 5400 | D28: g | E28: Tiempo de Horneo:
A29: TIEMPO TOTAL DE PREPARACION | C29: 5 | D29: Min. | E29: Horno:
A30: CANTIDAD DE PORCIONES OBTENIDAS | C30: 1 | D30: Tanda | E30: Temperatura de Horneo:
A31: PESO DE CADA PORCIÓN | C31: 5400 | D31: g | E31: Otros
A32: MERMA | C32: 0 | D32: g
A33: PROCEDIMIENTO DE PREPARACION DE LA RECETA
A34: 1.- Pesar en una bolsa 17x25 harina, polvo de hornear, bicarnonato, sal, canela y preservantes. Etiquetar
A35: 2,- Pesar en otra bolsa 17x 25 los azucares juntos. Etiquetar.
A36: 3,- Pesar en una bolsa 12x 18 la pecana.
A37: CONTROL DE CAMBIOS

Sheet Hoja1
C1: SERVICIOS DE PASTELERIA S.A. | H1: CÓDIGO: | I1: ESP-RE-PRES-032
C2: ESPECIFICACION DE RECETA | H2: REVISIÓN: | I2: 01
C3: SE00576 Premezcla zanahoria spoon | H3: FECHA DE APROBACIÓN: | I3: 45617
C4: Elaborado | D4: Javier Tong, Chef
C5: Aprobado | D5: Esteban Cartin, Gte Manufactura
A6: AREA QUE PRODUCE: | D6: Premezclas | G6: AREA QUE EMPACA: | I6: Premezclas
A7: # Código | B7: # Código Netsuite | C7: Descripción del ingrediente | D7: Marca | E7: Unidad Internacional | G7: Medida alternativa | I7: Costo - Referencia
E8: Cantidad | F8: Unidad medida | G8: Cantidad | H8: Unidad medida | I8: Colones
C9: Ensamble
A10: 11200064 | B10: MP10051 | C10: HARINA TRIGO NACARINA | D10: NACARINA | E10: 2275 | F10: g
A11: 503000036 | B11: MP10085 | C11: BICARBONATO DE SODIO | D11: PASTELERO | E11: 50 | F11: g
A12: 10100046 | B12: MP10304 | C12: POLVO HORNEAR | D12: ROYAL | E12: 50 | F12: g
A13: 10100122 | B13: MP10096 | C13: CANELA EN POLVO | D13: BADIA | E13: 50 | F13: g
A14: 5000001 | B14: MP10027 | C14: SAL INDUSTRIAL | D14: ATLANTIDA | E14: 50 | F14: g
A15: 0512262 | B15: MP10566 | C15: PROPIANATO DE CALCIO | D15: CRYSTAL PRO | E15: 7 | F15: g
A16: 512261 | B16: MP10579 | C16: ACIDO SORBICO | D16: BEYCO | E16: 7 | F16: g
A18: 10100045 | B18: MP10075 | C18: AZUCAR CARAMELO | D18: ZUKRA | E18: 1100 | F18: g
A19: 510301 | B19: MP10074 | C19: AZUCAR BLANCO INDUSTRIAL | D19: MARIA | E19: 1100 | F19: g
A21: 11900028 | B21: MP10562 | C21: PECANA ENTERA | D21: NUECES IND | E21: 800 | F21: g
C24: Decoración
C32: Empaque
A33: 1950702 | B33: EM10016 | C33: BOLSA 12X18 TRANSPARENTE | D33: PLASTICOS P | E33: 1 | F33: ud
A34: 1950708 | B34: EM10013 | C34: BOLSA 17X25 TRANSPARENTE | D34: PLASTICOS P | E34: 2 | F34: ud
A35: 60100010 | B35: EM10133 | C35: ETIQUETA ROJA LETRA ALERGENO | D35: ETIPLAST | E35: 2 | F35: ud
A36: 0702123 | B36: EM10011 | C36: ETIQUETA BLANCA 2 5/8X1 15/16 | D36: ETIPLAST | E36: 2 | F36: ud
D45: Cantidad | E45: Unidad
A46: PESO TOTAL OBTENIDO | D46: 5400 | E46: g | F46: Tiempo de Horneo:
A47: TIEMPO TOTAL DE PREPARACION | D47: 4 | E47: min | F47: Horno:
A48: CANTIDAD DE PORCIONES OBTENIDAS | D48: 1 | E48: ud | F48: Temperatura de Horneo:
A49: PESO DE CADA PORCIÓN | D49: 5400 | E49: g | F49: Otros
A50: MERMA | D50: 89 | E50: g
A51: PROCEDIMIENTO DE PREPARACION DE LA RECETA
A52: 1.- Pesar en la bolsa 12x18 el harina, bicarbonato, polvo de hornear, canela, sal, propionato y acido sorbico.
A53: 2.- En una bolsa 17x25 pesar los azucares y en otra la pecana.
A54: 3.- Etiquetar
A56: CONTROL DE CAMBIOS

Sheet Costo Premezcla 
E1: Precio Local | F1: Costo MP | G1: Costo EM | H1: Costo MO
E2: =IFERROR(O66,"") -> 15684.188 | F2: =IFERROR(H57,"") -> 11584.404 | G2: =IFERROR(H58,"") -> 120.2141 | H2: =IFERROR(H60,"") -> 244
A5: ESTRUCTURA DE COSTOS
F6: Fecha: | H6: =TODAY() -> 45887
A7: UNIDADES | B7: DESCRIPCION MAT.PRIMA | C7: UNIDADES | D7: UND MEDIDA | E7: COSTO UNITARIO | F7: TOTAL COSTO | G7: % PREC. DEFINIDO | H7: CODIGOS
A8: 2275 | B8: =IFERROR(VLOOKUP(H8,'[1]Consolidado MP Planta'!$A$2:$M$823,3,0),"") -> HARINA TRIGO NACARINA (SACO: 25 K) | C8: =+A8 -> 2275 | D8: =IFERROR(VLOOKUP(H8,'[1]Consolidado MP Planta'!$A$2:$M$823,13,0),"") -> Gramos | E8: 0.83 | F8: =IFERROR(C8*E8,"") -> 1888.25 | G8: =IFERROR(F8/$F$70,"") -> 0.15502484 | H8: 11200064
A9: 50 | B9: =IFERROR(VLOOKUP(H9,'[1]Consolidado MP Planta'!$A$2:$M$823,3,0),"") -> BICARBONATO DE SODIO (PAQ:2.5 K) | C9: =+A9 -> 50 | D9: =IFERROR(VLOOKUP(H9,'[1]Consolidado MP Planta'!$A$2:$M$823,13,0),"") -> Gramos | E9: 1.32 | F9: =IFERROR(C9*E9,"") -> 66 | G9: =IFERROR(F9/$F$70,"") -> 0.005418583 | H9: 503000036
A10: 50 | B10: =IFERROR(VLOOKUP(H10,'[1]Consolidado MP Planta'!$A$2:$M$823,3,0),"") -> POLVO HORNEAR FLEISHMAN (PAQ:2.5 K) | C10: =+A10 -> 50 | D10: =IFERROR(VLOOKUP(H10,'[1]Consolidado MP Planta'!$A$2:$M$823,13,0),"") -> Gramos | E10: 1.03 | F10: =IFERROR(C10*E10,"") -> 51.5 | G10: =IFERROR(F10/$F$70,"") -> 0.0042281367 | H10: 10100046
A11: 0 | B11: =IFERROR(VLOOKUP(H11,'[1]Consolidado MP Planta'!$A$2:$M$823,3,0),"") -> CANELA EN POLVO BADIA (UND: 1.82 K) | C11: =+A11 -> 0 | D11: =IFERROR(VLOOKUP(H11,'[1]Consolidado MP Planta'!$A$2:$M$823,13,0),"") -> Gramos | E11: 9.39 | F11: =IFERROR(C11*E11,"") -> 0 | G11: =IFERROR(F11/$F$70,"") -> 0 | H11: 10100122
A12: 800 | B12: =IFERROR(VLOOKUP(H12,'[1]Consolidado MP Planta'!$A$2:$M$823,3,0),"") -> PECANA ENTERA (CAJA:13.6 K) | C12: =+A12 -> 800 | D12: =IFERROR(VLOOKUP(H12,'[1]Consolidado MP Planta'!$A$2:$M$823,13,0),"") -> Gramos | E12: 9.28 | F12: =IFERROR(C12*E12,"") -> 7424 | G12: =IFERROR(F12/$F$70,"") -> 0.60950849 | H12: 0510262
A13: 1100 | B13: =IFERROR(VLOOKUP(H13,'[1]Consolidado MP Planta'!$A$2:$M$823,3,0),"") -> AZUCAR BLANCO INDUSTRIAL (SACO:50 K) | C13: =+A13 -> 1100 | D13: =IFERROR(VLOOKUP(H13,'[1]Consolidado MP Planta'!$A$2:$M$823,13,0),"") -> Gramos | E13: =IFERROR(VLOOKUP(H13,'[1]Consolidado MP Planta'!$A$2:$M$823,12,0),"") -> 0.39034 | F13: =IFERROR(C13*E13,"") -> 429.374 | G13: =IFERROR(F13/$F$70,"") -> 0.035251495 | H13: 510301
A14: 50 | B14: =IFERROR(VLOOKUP(H14,'[1]Consolidado MP Planta'!$A$2:$M$823,3,0),"") -> CANELA EN POLVO BADIA (UND: 1.82 K) | C14: =+A14 -> 50 | D14: =IFERROR(VLOOKUP(H14,'[1]Consolidado MP Planta'!$A$2:$M$823,13,0),"") -> Gramos | E14: 9.39 | F14: =IFERROR(C14*E14,"") -> 469.5 | G14: =IFERROR(F14/$F$70,"") -> 0.038545829 | H14: 10100122
A15: 50 | B15: =IFERROR(VLOOKUP(H15,'[1]Consolidado MP Planta'!$A$2:$M$823,3,0),"") -> SAL INDUSTRIA (SACO:25 Kg) | C15: =+A15 -> 50 | D15: =IFERROR(VLOOKUP(H15,'[1]Consolidado MP Planta'!$A$2:$M$823,13,0),"") -> Gramos | E15: 0.28 | F15: =IFERROR(C15*E15,"") -> 14 | G15: =IFERROR(F15/$F$70,"") -> 0.0011493964 | H15: 5000001
A16: 7 | B16: =IFERROR(VLOOKUP(H16,'[1]Consolidado MP Planta'!$A$2:$M$823,3,0),"") -> PROPIANATO CALCIO (PAQ:2.5 K) | C16: =+A16 -> 7 | D16: =IFERROR(VLOOKUP(H16,'[1]Consolidado MP Planta'!$A$2:$M$823,13,0),"") -> Gramos | E16: 1.59 | F16: =IFERROR(C16*E16,"") -> 11.13 | G16: =IFERROR(F16/$F$70,"") -> 0.00091377013 | H16: 0512262
A17: 7 | B17: =IFERROR(VLOOKUP(H17,'[1]Consolidado MP Planta'!$A$2:$M$823,3,0),"") -> ACIDO SORBICO (PAQ:2.5 K) | C17: =+A17 -> 7 | D17: =IFERROR(VLOOKUP(H17,'[1]Consolidado MP Planta'!$A$2:$M$823,13,0),"") -> Gramos | E17: 2.95 | F17: =IFERROR(C17*E17,"") -> 20.65 | G17: =IFERROR(F17/$F$70,"") -> 0.0016953597 | H17: 512261
A18: 1100 | B18: Azucar Caramelo | C18: =+A18 -> 1100 | D18: Gramos | E18: 1.1 | F18: =IFERROR(C18*E18,"") -> 1210 | G18: =IFERROR(F18/$F$70,"") -> 0.099340688 | H18: 10100045 | M18: Falta precio actual
B19: =IFERROR(VLOOKUP(H19,'[2]ARTICULOS MP PLANTA'!$A$2:$G$589,2,0),"")
A20: UNIDADES | B20: MATERIA PRIMA SEMIELABORADOS | C20: UNIDADES | D20: UND MEDIDA | E20: COSTO UNITARIO | F20: TOTAL COSTO | G20: % PREC. DEFINIDO | H20: CODIGOS
B21: =IFERROR(VLOOKUP(H21,[1]SEMIELABORADOS!$A$2:$M$6000,2,0),"") | C21: =+A21 -> 0 | D21: =IFERROR(VLOOKUP(H21,[1]SEMIELABORADOS!$A$2:$M$6000,6,0),"") | E21: =IFERROR(VLOOKUP(H21,[1]SEMIELABORADOS!$A$2:$H$65536,8,0),"") | F21: =IFERROR(E21*C21,"") | G21: =IFERROR(F21/$F$70,"")
B22: =IFERROR(VLOOKUP(H22,[1]SEMIELABORADOS!$A$2:$M$6000,2,0),"") | C22: =+A22 -> 0 | D22: =IFERROR(VLOOKUP(H22,[1]SEMIELABORADOS!$A$2:$M$6000,6,0),"") | E22: =IFERROR(VLOOKUP(H22,[1]SEMIELABORADOS!$A$2:$H$65536,8,0),"") | F22: =IFERROR(E22*C22,"") | G22: =IFERROR(F22/$F$70,"")
B23: =IFERROR(VLOOKUP(H23,[1]SEMIELABORADOS!$A$2:$M$6000,2,0),"") | C23: =+A23 -> 0 | D23: =IFERROR(VLOOKUP(H23,[1]SEMIELABORADOS!$A$2:$M$6000,6,0),"") | E23: =IFERROR(VLOOKUP(H23,[1]SEMIELABORADOS!$A$2:$H$65536,8,0),"") | F23: =IFERROR(E23*C23,"") | G23: =IFERROR(F23/$F$70,"")
B24: =IFERROR(VLOOKUP(H24,[1]SEMIELABORADOS!$A$2:$M$6000,2,0),"") | C24: =+A24 -> 0 | D24: =IFERROR(VLOOKUP(H24,[1]SEMIELABORADOS!$A$2:$M$6000,6,0),"") | E24: =IFERROR(VLOOKUP(H24,[1]SEMIELABORADOS!$A$2:$H$65536,8,0),"") | F24: =IFERROR(E24*C24,"") | G24: =IFERROR(F24/$F$70,"")
B25: =IFERROR(VLOOKUP(H25,[1]SEMIELABORADOS!$A$2:$M$6000,2,0),"") | C25: =+A25 -> 0 | D25: =IFERROR(VLOOKUP(H25,[1]SEMIELABORADOS!$A$2:$M$6000,6,0),"") | E25: =IFERROR(VLOOKUP(H25,[1]SEMIELABORADOS!$A$2:$H$65536,8,0),"") | F25: =IFERROR(E25*C25,"") | G25: =IFERROR(F25/$F$70,"")
B26: =IFERROR(VLOOKUP(H26,[1]SEMIELABORADOS!$A$2:$M$6000,2,0),"") | C26: =+A26 -> 0 | D26: =IFERROR(VLOOKUP(H26,[1]SEMIELABORADOS!$A$2:$M$6000,6,0),"") | E26: =IFERROR(VLOOKUP(H26,[1]SEMIELABORADOS!$A$2:$H$65536,8,0),"") | F26: =IFERROR(E26*C26,"") | G26: =IFERROR(F26/$F$70,"")
B27: =IFERROR(VLOOKUP(H27,[1]SEMIELABORADOS!$A$2:$M$6000,2,0),"") | C27: =+A27 -> 0 | D27: =IFERROR(VLOOKUP(H27,[1]SEMIELABORADOS!$A$2:$M$6000,6,0),"") | E27: =IFERROR(VLOOKUP(H27,[1]SEMIELABORADOS!$A$2:$H$65536,8,0),"") | F27: =IFERROR(E27*C27,"") | G27: =IFERROR(F27/$F$70,"")
B28: =IFERROR(VLOOKUP(H28,[1]SEMIELABORADOS!$A$2:$M$6000,2,0),"") | C28: =+A28 -> 0 | D28: =IFERROR(VLOOKUP(H28,[1]SEMIELABORADOS!$A$2:$M$6000,6,0),"") | E28: =IFERROR(VLOOKUP(H28,[1]SEMIELABORADOS!$A$2:$H$65536,8,0),"") | F28: =IFERROR(E28*C28,"") | G28: =IFERROR(F28/$F$70,"")
A30: UNIDADES | B30: EMPAQUE | C30: UNIDADES | D30: UND MEDIDA | E30: COSTO UNITARIO | F30: TOTAL COSTO | G30: % PREC. DEFINIDO | H30: CODIGOS
A31: 1 | B31: =IFERROR(VLOOKUP(H31,'[1]Consolidado MP Planta'!$A$2:$M$823,3,0),"") -> BOLSA 12x18 TRANSP KILO | C31: =+A31 -> 1 | D31: =IFERROR(VLOOKUP(H31,'[1]Consolidado MP Planta'!$A$2:$M$823,13,0),"") -> Und | E31: 13.52 | F31: =IFERROR(C31*E31,"") -> 13.52 | G31: =IFERROR(F31/$F$70,"") -> 0.0011099885 | H31: 1950702
A32: 2 | B32: =IFERROR(VLOOKUP(H32,'[1]Consolidado MP Planta'!$A$2:$M$823,3,0),"") -> BOLSA 17x25 TRANSP KILO | C32: =+A32 -> 2 | D32: =IFERROR(VLOOKUP(H32,'[1]Consolidado MP Planta'!$A$2:$M$823,13,0),"") -> Und | E32: =IFERROR(VLOOKUP(H32,'[1]Consolidado MP Planta'!$A$2:$M$823,12,0),"") -> 47.619048 | F32: =IFERROR(C32*E32,"") -> 95.238095 | G32: =IFERROR(F32/$F$70,"") -> 0.0078190231 | H32: 1950708
A33: 2 | B33: =IFERROR(VLOOKUP(H33,'[1]Consolidado MP Planta'!$A$2:$M$823,3,0),"") -> ETIQUETA ROJA LETRA ALERJENO (UND) | C33: =+A33 -> 2 | D33: =IFERROR(VLOOKUP(H33,'[1]Consolidado MP Planta'!$A$2:$M$823,13,0),"") -> Und | E33: =IFERROR(VLOOKUP(H33,'[1]Consolidado MP Planta'!$A$2:$M$823,12,0),"") -> 3.6 | F33: =IFERROR(C33*E33,"") -> 7.2 | G33: =IFERROR(F33/$F$70,"") -> 0.00059111815 | H33: 60100010
A34: 2 | B34: =IFERROR(VLOOKUP(H34,'[1]Consolidado MP Planta'!$A$2:$M$823,3,0),"") -> ETIQUETA BLANCA 2 5/8X1 15/16 (UND) | C34: =+A34 -> 2 | D34: =IFERROR(VLOOKUP(H34,'[1]Consolidado MP Planta'!$A$2:$M$823,13,0),"") -> Und | E34: =IFERROR(VLOOKUP(H34,'[1]Consolidado MP Planta'!$A$2:$M$823,12,0),"") -> 2.128 | F34: =IFERROR(C34*E34,"") -> 4.256 | G34: =IFERROR(F34/$F$70,"") -> 0.0003494165 | H34: 0702123
B35: =IFERROR(VLOOKUP(H35,'[1]Consolidado MP Planta'!$A$2:$M$823,3,0),"") | C35: =+A35 -> 0 | D35: =IFERROR(VLOOKUP(H35,'[1]Consolidado MP Planta'!$A$2:$M$823,13,0),"") | E35: =IFERROR(VLOOKUP(H35,'[1]Consolidado MP Planta'!$A$2:$M$823,12,0),"") | F35: =IFERROR(C35*E35,"") | G35: =IFERROR(F35/$F$70,"")
B36: =IFERROR(VLOOKUP(H36,'[1]Consolidado MP Planta'!$A$2:$M$823,3,0),"") | C36: =+A36 -> 0 | D36: =IFERROR(VLOOKUP(H36,'[1]Consolidado MP Planta'!$A$2:$M$823,13,0),"") | E36: =IFERROR(VLOOKUP(H36,'[1]Consolidado MP Planta'!$A$2:$M$823,12,0),"") | F36: =IFERROR(C36*E36,"") | G36: =IFERROR(F36/$F$70,"")
A38: UNIDADES | B38: EMPAQUE SEMIELABORADOS | C38: UNIDADES | D38: UND MEDIDA | E38: COSTO UNITARIO | F38: TOTAL COSTO | G38: % PREC. DEFINIDO | H38: CODIGOS
A39: =+A21 -> 0 | B39: =IFERROR(VLOOKUP(H39,[1]SEMIELABORADOS!$A$2:$M$6000,2,0),"") | C39: =+A39 -> 0 | D39: =IFERROR(VLOOKUP(H39,[1]SEMIELABORADOS!$A$2:$M$6000,6,0),"") | E39: =IFERROR(VLOOKUP(H39,[1]SEMIELABORADOS!$A$2:$M$65536,10,0),"") | F39: =IFERROR(E39*C39,"") | G39: =IFERROR(F39/$F$70,"")
A40: =+A22 -> 0 | B40: =IFERROR(VLOOKUP(H40,[1]SEMIELABORADOS!$A$2:$M$6000,2,0),"") | C40: =+A40 -> 0 | D40: =IFERROR(VLOOKUP(H40,[1]SEMIELABORADOS!$A$2:$M$6000,6,0),"") | E40: =IFERROR(VLOOKUP(H40,[1]SEMIELABORADOS!$A$2:$M$65536,10,0),"") | F40: =IFERROR(E40*C40,"") | G40: =IFERROR(F40/$F$70,"")
A41: =+A23 -> 0 | B41: =IFERROR(VLOOKUP(H41,[1]SEMIELABORADOS!$A$2:$M$6000,2,0),"") | C41: =+A41 -> 0 | D41: =IFERROR(VLOOKUP(H41,[1]SEMIELABORADOS!$A$2:$M$6000,6,0),"") | E41: =IFERROR(VLOOKUP(H41,[1]SEMIELABORADOS!$A$2:$M$65536,10,0),"") | F41: =IFERROR(E41*C41,"") | G41: =IFERROR(F41/$F$70,"")
A42: =+A24 -> 0 | B42: =IFERROR(VLOOKUP(H42,[1]SEMIELABORADOS!$A$2:$M$6000,2,0),"") | C42: =+A42 -> 0 | D42: =IFERROR(VLOOKUP(H42,[1]SEMIELABORADOS!$A$2:$M$6000,6,0),"") | E42: =IFERROR(VLOOKUP(H42,[1]SEMIELABORADOS!$A$2:$M$65536,10,0),"") | F42: =IFERROR(E42*C42,"") | G42: =IFERROR(F42/$F$70,"")
A43: =+A25 -> 0 | B43: =IFERROR(VLOOKUP(H43,[1]SEMIELABORADOS!$A$2:$M$6000,2,0),"") | C43: =+A43 -> 0 | D43: =IFERROR(VLOOKUP(H43,[1]SEMIELABORADOS!$A$2:$M$6000,6,0),"") | E43: =IFERROR(VLOOKUP(H43,[1]SEMIELABORADOS!$A$2:$M$65536,10,0),"") | F43: =IFERROR(E43*C43,"") | G43: =IFERROR(F43/$F$70,"")
A44: =+A26 -> 0 | B44: =IFERROR(VLOOKUP(H44,[1]SEMIELABORADOS!$A$2:$M$6000,2,0),"") | C44: =+A44 -> 0 | D44: =IFERROR(VLOOKUP(H44,[1]SEMIELABORADOS!$A$2:$M$6000,6,0),"") | E44: =IFERROR(VLOOKUP(H44,[1]SEMIELABORADOS!$A$2:$M$65536,10,0),"") | F44: =IFERROR(E44*C44,"") | G44: =IFERROR(F44/$F$70,"")
...

Sheet Batido Zanahoria y Yogurt
B1: SERVICIOS DE PASTELERIA SA | G1: CÓDIGO:
B2: ESPECIFICACION DE RECETA | G2: REVISIÓN:
B3: Batido Zanahoria y yogurt | G3: FECHA DE APROBACIÓN:
B4: Elaborado | C4: Maria Jose Rodriguez, Chef
B5: Aprobado | C5: Esteban Cartin, Gte Manufatcura
A6: # Código | B6: Descripción del ingrediente | C6: Marca | D6: Unidad Internacional | F6: Medida costos | H6: Costo - Referencia
D7: Cantidad | E7: Unidad medida | F7: Cantidad | G7: Unidad medida | H7: Colones
B8: PRE MEZCLA DE ZANAHORIA Y YOGURT | C8: Spoon | D8: 5400 | E8: g
A9: 10100050 | B9: ACEITE CAPULLO RBD (UND:17 L) | C9: Capullo | D9: 1170 | E9: g
A10: 1210482 | B10: HUEVO ENTERO PASTERI INNOVO (CAJA:10 K) | C10: Innovo | D10: 1300 | E10: g
A11: 118000004 | B11: Vainilla Oscura | C11: Mayca | D11: 65 | E11: g
A12: 101240 | B12: ZANAHORIA ENTERA (KILO) | C12: Presto | D12: 2900 | E12: g
A13: 11400040 | B13: Yogurt Batido Natural | D13: 325 | E13: g
B16: MERMA
A17: 101240 | B17: ZANAHORIA ENTERA (KILO) | C17: Presto | D17: 50 | E17: g
C19: Cantidad | D19: Unidad
A20: PESO TOTAL OBTENIDO | C20: 10900 | D20: g | E20: Tiempo de Horneo
A21: TIEMPO TOTAL DE PREPARACION | C21: 15 | D21: min | E21: Horno:
A22: CANTIDAD DE PORCIONES OBTENIDAS | C22: 1 | D22: Tanda | E22: Temperatura de Horneo
A23: PESO DE CADA PORCIÓN | C23: 10900 | D23: g | E23: Otros
A24: MERMA | C24: 349 | D24: g
A25: PROCEDIMIENTO DE PREPARACION DE LA RECETA
A26: 1.- Colocar los liquidos en el bowl de la batidora aceite, huevo, vanilla, zanahoria previamente rallada en la maquina y yogurt natural. Batir por 1 minuto en velocidad 1 utilizando el globo.
A27: 2.- Se agregan las harinas y batir por 1 minuto, limpiar bordes. Subir l a velocidad a 3 y batir por 3 minutos.
A28: 3.- Bajar la velocidad a 1 y agregar azucares y pecana picada. Subir la velocidad a 3 y batir por 3 minutos mas, limpiar bordes y fondo del bowl.
A29: * Los tiempoa de batidos de deben multiplicar por el # de tandas a realizar.
A30: CONTROL DE CAMBIOS

Sheet Costo Batido
E1: Precio Local | F1: Costo MP | G1: Costo EM | H1: Costo MO
E2: =IFERROR(O63,"") -> 24538.037 | F2: =IFERROR(H54,"") -> 18191.754 | G2: =IFERROR(H55,"") -> 120.2141 | H2: =IFERROR(H57,"") -> 732
A5: ESTRUCTURA DE COSTOS
F6: Fecha: | H6: =TODAY() -> 45887
A7: UNIDADES | B7: DESCRIPCION MAT.PRIMA | C7: UNIDADES | D7: UND MEDIDA | E7: COSTO UNITARIO | F7: TOTAL COSTO | G7: % PREC. DEFINIDO | H7: CODIGOS
A8: 1300 | B8: =IFERROR(VLOOKUP(H8,'[1]Consolidado MP Planta'!$A$2:$M$823,3,0),"") -> HUEVO ENTERO PASTERI INNOVO (CAJA:10 K) | C8: =+A8 -> 1300 | D8: =IFERROR(VLOOKUP(H8,'[1]Consolidado MP Planta'!$A$2:$M$823,13,0),"") -> Gramos | E8: 2.27 | F8: =IFERROR(C8*E8,"") -> 2951 | G8: =IFERROR(F8/$F$67,"") -> 0.15398822 | H8: 1210482
A9: 1170 | B9: =IFERROR(VLOOKUP(H9,'[1]Consolidado MP Planta'!$A$2:$M$823,3,0),"") -> ACEITE CAPULLO RBD (UND:17 L) | C9: =+A9 -> 1170 | D9: =IFERROR(VLOOKUP(H9,'[1]Consolidado MP Planta'!$A$2:$M$823,13,0),"") -> Mililitros | E9: 1.52 | F9: =IFERROR(C9*E9,"") -> 1778.4 | G9: =IFERROR(F9/$F$67,"") -> 0.092799951 | H9: 10100050
A10: 65 | B10: =IFERROR(VLOOKUP(H10,'[1]Consolidado MP Planta'!$A$2:$M$823,3,0),"") -> VAINILLA OSCURA (UND: 3.78 L) | C10: =+A10 -> 65 | D10: =IFERROR(VLOOKUP(H10,'[1]Consolidado MP Planta'!$A$2:$M$823,13,0),"") -> Mililitros | E10: 1.23 | F10: =IFERROR(C10*E10,"") -> 79.95 | G10: =IFERROR(F10/$F$67,"") -> 0.0041719276 | H10: 118000004
A11: 2900 | B11: =IFERROR(VLOOKUP(H11,'[1]Consolidado MP Planta'!$A$2:$M$823,3,0),"") -> ZANAHORIA ENTERA KILO | C11: =+A11 -> 2900 | D11: =IFERROR(VLOOKUP(H11,'[1]Consolidado MP Planta'!$A$2:$M$823,13,0),"") -> Gramos | E11: 0.62 | F11: =IFERROR(C11*E11,"") -> 1798 | G11: =IFERROR(F11/$F$67,"") -> 0.093822713 | H11: 0101240
A12: 0 | B12: =IFERROR(VLOOKUP(H12,'[1]Consolidado MP Planta'!$A$2:$M$823,3,0),"") | C12: =+A12 -> 0 | D12: =IFERROR(VLOOKUP(H12,'[1]Consolidado MP Planta'!$A$2:$M$823,13,0),"") | E12: 0 | F12: =IFERROR(C12*E12,"") -> 0 | G12: =IFERROR(F12/$F$67,"") -> 0
A13: 0 | B13: =IFERROR(VLOOKUP(H13,'[1]Consolidado MP Planta'!$A$2:$M$823,3,0),"") -> YOGURT BATIDO NATURAL (UND:1 K) | C13: =+A13 -> 0 | D13: =IFERROR(VLOOKUP(H13,'[1]Consolidado MP Planta'!$A$2:$M$823,13,0),"") -> 0 | E13: 1.93 | F13: =IFERROR(C13*E13,"") -> 0 | G13: =IFERROR(F13/$F$67,"") -> 0 | H13: 11400040
B14: =IFERROR(VLOOKUP(H14,'[1]Consolidado MP Planta'!$A$2:$M$823,3,0),"") | C14: =+A14 -> 0 | D14: =IFERROR(VLOOKUP(H14,'[1]Consolidado MP Planta'!$A$2:$M$823,13,0),"") | E14: =IFERROR(VLOOKUP(H14,'[1]Consolidado MP Planta'!$A$2:$M$823,12,0),"") | F14: =IFERROR(C14*E14,"") | G14: =IFERROR(F14/$F$67,"")
B15: =IFERROR(VLOOKUP(H15,'[1]Consolidado MP Planta'!$A$2:$M$823,3,0),"") | C15: =+A15 -> 0 | D15: =IFERROR(VLOOKUP(H15,'[1]Consolidado MP Planta'!$A$2:$M$823,13,0),"") | E15: =IFERROR(VLOOKUP(H15,'[1]Consolidado MP Planta'!$A$2:$M$823,12,0),"") | F15: =IFERROR(C15*E15,"") | G15: =IFERROR(F15/$F$67,"")
B16: =IFERROR(VLOOKUP(H16,'[2]ARTICULOS MP PLANTA'!$A$2:$G$589,2,0),"")
A17: UNIDADES | B17: MATERIA PRIMA SEMIELABORADOS | C17: UNIDADES | D17: UND MEDIDA | E17: COSTO UNITARIO | F17: TOTAL COSTO | G17: % PREC. DEFINIDO | H17: CODIGOS
A18: 5400 | B18: PRE MEZCLA DE ZANAHORIA Y YOGURT | C18: =+A18 -> 5400 | D18: Gramos | E18: =+'Costo Premezcla '!E73 -> 2.14526 | F18: =IFERROR(E18*C18,"") -> 11584.404 | G18: =IFERROR(F18/$F$67,"") -> 0.604494 | H18: nuevo
B19: =IFERROR(VLOOKUP(H19,[1]SEMIELABORADOS!$A$2:$M$6000,2,0),"") | C19: =+A19 -> 0 | D19: =IFERROR(VLOOKUP(H19,[1]SEMIELABORADOS!$A$2:$M$6000,6,0),"") | E19: =IFERROR(VLOOKUP(H19,[1]SEMIELABORADOS!$A$2:$H$65536,8,0),"") | F19: =IFERROR(E19*C19,"") | G19: =IFERROR(F19/$F$67,"")
B20: =IFERROR(VLOOKUP(H20,[1]SEMIELABORADOS!$A$2:$M$6000,2,0),"") | C20: =+A20 -> 0 | D20: =IFERROR(VLOOKUP(H20,[1]SEMIELABORADOS!$A$2:$M$6000,6,0),"") | E20: =IFERROR(VLOOKUP(H20,[1]SEMIELABORADOS!$A$2:$H$65536,8,0),"") | F20: =IFERROR(E20*C20,"") | G20: =IFERROR(F20/$F$67,"")
B21: =IFERROR(VLOOKUP(H21,[1]SEMIELABORADOS!$A$2:$M$6000,2,0),"") | C21: =+A21 -> 0 | D21: =IFERROR(VLOOKUP(H21,[1]SEMIELABORADOS!$A$2:$M$6000,6,0),"") | E21: =IFERROR(VLOOKUP(H21,[1]SEMIELABORADOS!$A$2:$H$65536,8,0),"") | F21: =IFERROR(E21*C21,"") | G21: =IFERROR(F21/$F$67,"")
B22: =IFERROR(VLOOKUP(H22,[1]SEMIELABORADOS!$A$2:$M$6000,2,0),"") | C22: =+A22 -> 0 | D22: =IFERROR(VLOOKUP(H22,[1]SEMIELABORADOS!$A$2:$M$6000,6,0),"") | E22: =IFERROR(VLOOKUP(H22,[1]SEMIELABORADOS!$A$2:$H$65536,8,0),"") | F22: =IFERROR(E22*C22,"") | G22: =IFERROR(F22/$F$67,"")
B23: =IFERROR(VLOOKUP(H23,[1]SEMIELABORADOS!$A$2:$M$6000,2,0),"") | C23: =+A23 -> 0 | D23: =IFERROR(VLOOKUP(H23,[1]SEMIELABORADOS!$A$2:$M$6000,6,0),"") | E23: =IFERROR(VLOOKUP(H23,[1]SEMIELABORADOS!$A$2:$H$65536,8,0),"") | F23: =IFERROR(E23*C23,"") | G23: =IFERROR(F23/$F$67,"")
B24: =IFERROR(VLOOKUP(H24,[1]SEMIELABORADOS!$A$2:$M$6000,2,0),"") | C24: =+A24 -> 0 | D24: =IFERROR(VLOOKUP(H24,[1]SEMIELABORADOS!$A$2:$M$6000,6,0),"") | E24: =IFERROR(VLOOKUP(H24,[1]SEMIELABORADOS!$A$2:$H$65536,8,0),"") | F24: =IFERROR(E24*C24,"") | G24: =IFERROR(F24/$F$67,"")
B25: =IFERROR(VLOOKUP(H25,[1]SEMIELABORADOS!$A$2:$M$6000,2,0),"") | C25: =+A25 -> 0 | D25: =IFERROR(VLOOKUP(H25,[1]SEMIELABORADOS!$A$2:$M$6000,6,0),"") | E25: =IFERROR(VLOOKUP(H25,[1]SEMIELABORADOS!$A$2:$H$65536,8,0),"") | F25: =IFERROR(E25*C25,"") | G25: =IFERROR(F25/$F$67,"")
A27: UNIDADES | B27: EMPAQUE | C27: UNIDADES | D27: UND MEDIDA | E27: COSTO UNITARIO | F27: TOTAL COSTO | G27: % PREC. DEFINIDO | H27: CODIGOS
A28: 0 | B28: =IFERROR(VLOOKUP(H28,'[1]Consolidado MP Planta'!$A$2:$M$823,3,0),"") | C28: =+A28 -> 0 | D28: =IFERROR(VLOOKUP(H28,'[1]Consolidado MP Planta'!$A$2:$M$823,13,0),"") | E28: =IFERROR(VLOOKUP(H28,'[1]Consolidado MP Planta'!$A$2:$M$823,12,0),"") | F28: =IFERROR(C28*E28,"") | G28: =IFERROR(F28/$F$67,"")
B29: =IFERROR(VLOOKUP(H29,'[1]Consolidado MP Planta'!$A$2:$M$823,3,0),"") | C29: =+A29 -> 0 | D29: =IFERROR(VLOOKUP(H29,'[1]Consolidado MP Planta'!$A$2:$M$823,13,0),"") | E29: =IFERROR(VLOOKUP(H29,'[1]Consolidado MP Planta'!$A$2:$M$823,12,0),"") | F29: =IFERROR(C29*E29,"") | G29: =IFERROR(F29/$F$67,"")
B30: =IFERROR(VLOOKUP(H30,'[1]Consolidado MP Planta'!$A$2:$M$823,3,0),"") | C30: =+A30 -> 0 | D30: =IFERROR(VLOOKUP(H30,'[1]Consolidado MP Planta'!$A$2:$M$823,13,0),"") | E30: =IFERROR(VLOOKUP(H30,'[1]Consolidado MP Planta'!$A$2:$M$823,12,0),"") | F30: =IFERROR(C30*E30,"") | G30: =IFERROR(F30/$F$67,"")
B31: =IFERROR(VLOOKUP(H31,'[1]Consolidado MP Planta'!$A$2:$M$823,3,0),"") | C31: =+A31 -> 0 | D31: =IFERROR(VLOOKUP(H31,'[1]Consolidado MP Planta'!$A$2:$M$823,13,0),"") | E31: =IFERROR(VLOOKUP(H31,'[1]Consolidado MP Planta'!$A$2:$M$823,12,0),"") | F31: =IFERROR(C31*E31,"") | G31: =IFERROR(F31/$F$67,"")
B32: =IFERROR(VLOOKUP(H32,'[1]Consolidado MP Planta'!$A$2:$M$823,3,0),"") | C32: =+A32 -> 0 | D32: =IFERROR(VLOOKUP(H32,'[1]Consolidado MP Planta'!$A$2:$M$823,13,0),"") | E32: =IFERROR(VLOOKUP(H32,'[1]Consolidado MP Planta'!$A$2:$M$823,12,0),"") | F32: =IFERROR(C32*E32,"") | G32: =IFERROR(F32/$F$67,"")
B33: =IFERROR(VLOOKUP(H33,'[1]Consolidado MP Planta'!$A$2:$M$823,3,0),"") | C33: =+A33 -> 0 | D33: =IFERROR(VLOOKUP(H33,'[1]Consolidado MP Planta'!$A$2:$M$823,13,0),"") | E33: =IFERROR(VLOOKUP(H33,'[1]Consolidado MP Planta'!$A$2:$M$823,12,0),"") | F33: =IFERROR(C33*E33,"") | G33: =IFERROR(F33/$F$67,"")
A35: UNIDADES | B35: EMPAQUE SEMIELABORADOS | C35: UNIDADES | D35: UND MEDIDA | E35: COSTO UNITARIO | F35: TOTAL COSTO | G35: % PREC. DEFINIDO | H35: CODIGOS
A36: =+A18 -> 5400 | B36: PRE MEZCLA DE ZANAHORIA Y YOGURT | C36: =+A36 -> 5400 | D36: Gramos | E36: =+'Costo Premezcla '!E80 -> 0.022261869 | F36: =IFERROR(E36*C36,"") -> 120.2141 | G36: =IFERROR(F36/$F$67,"") -> 0.0062729769
A37: =+A19 -> 0 | B37: =IFERROR(VLOOKUP(H37,[1]SEMIELABORADOS!$A$2:$M$6000,2,0),"") | C37: =+A37 -> 0 | D37: =IFERROR(VLOOKUP(H37,[1]SEMIELABORADOS!$A$2:$M$6000,6,0),"") | E37: =IFERROR(VLOOKUP(H37,[1]SEMIELABORADOS!$A$2:$M$65536,10,0),"") | F37: =IFERROR(E37*C37,"") | G37: =IFERROR(F37/$F$67,"")
A38: =+A20 -> 0 | B38: =IFERROR(VLOOKUP(H38,[1]SEMIELABORADOS!$A$2:$M$6000,2,0),"") | C38: =+A38 -> 0 | D38: =IFERROR(VLOOKUP(H38,[1]SEMIELABORADOS!$A$2:$M$6000,6,0),"") | E38: =IFERROR(VLOOKUP(H38,[1]SEMIELABORADOS!$A$2:$M$65536,10,0),"") | F38: =IFERROR(E38*C38,"") | G38: =IFERROR(F38/$F$67,"")
A39: =+A21 -> 0 | B39: =IFERROR(VLOOKUP(H39,[1]SEMIELABORADOS!$A$2:$M$6000,2,0),"") | C39: =+A39 -> 0 | D39: =IFERROR(VLOOKUP(H39,[1]SEMIELABORADOS!$A$2:$M$6000,6,0),"") | E39: =IFERROR(VLOOKUP(H39,[1]SEMIELABORADOS!$A$2:$M$65536,10,0),"") | F39: =IFERROR(E39*C39,"") | G39: =IFERROR(F39/$F$67,"")
A40: =+A22 -> 0 | B40: =IFERROR(VLOOKUP(H40,[1]SEMIELABORADOS!$A$2:$M$6000,2,0),"") | C40: =+A40 -> 0 | D40: =IFERROR(VLOOKUP(H40,[1]SEMIELABORADOS!$A$2:$M$6000,6,0),"") | E40: =IFERROR(VLOOKUP(H40,[1]SEMIELABORADOS!$A$2:$M$65536,10,0),"") | F40: =IFERROR(E40*C40,"") | G40: =IFERROR(F40/$F$67,"")
A41: =+A23 -> 0 | B41: =IFERROR(VLOOKUP(H41,[1]SEMIELABORADOS!$A$2:$M$6000,2,0),"") | C41: =+A41 -> 0 | D41: =IFERROR(VLOOKUP(H41,[1]SEMIELABORADOS!$A$2:$M$6000,6,0),"") | E41: =IFERROR(VLOOKUP(H41,[1]SEMIELABORADOS!$A$2:$M$65536,10,0),"") | F41: =IFERROR(E41*C41,"") | G41: =IFERROR(F41/$F$67,"")
A42: =+A24 -> 0 | B42: =IFERROR(VLOOKUP(H42,[1]SEMIELABORADOS!$A$2:$M$6000,2,0),"") | C42: =+A42 -> 0 | D42: =IFERROR(VLOOKUP(H42,[1]SEMIELABORADOS!$A$2:$M$6000,6,0),"") | E42: =IFERROR(VLOOKUP(H42,[1]SEMIELABORADOS!$A$2:$M$65536,10,0),"") | F42: =IFERROR(E42*C42,"") | G42: =IFERROR(F42/$F$67,"")
A44: UNIDADES | B44: MODI | C44: UNIDADES | D44: UND MEDIDA | E44: COSTO UNITARIO | F44: TOTAL COSTO | G44: % PREC. DEFINIDO | H44: CODIGOS
A45: =+A36 -> 5400 | B45: PRE MEZCLA DE ZANAHORIA Y YOGURT | C45: =+A45 -> 5400 | D45: Gramos | E45: =+'Costo Premezcla '!E78 -> 0.045185185 | F45: =IFERROR(E45*C45,"") -> 244 | G45: =IFERROR(F45/$F$67,"") -> 0.012732337
...

Sheet QQ Zanahoria 900 g
B1: SERVICIOS DE PASTELERIA SA | G1: CÓDIGO:
B2: ESPECIFICACION DE RECETA | G2: REVISIÓN:
B3: Queque de zanahoria y yogurt Rect 900g | G3: FECHA DE APROBACIÓN:
B4: Elaborado | C4: Maria Jose Rodriguez, Chef
B5: Aprobado | C5: Jorge, Montero. Gte de Manufactura
A6: # Código | B6: Rosquete Zanahoria Rect 900 g 95801 | C6: Marca | D6: Unidad Internacional | F6: Medida alternativa | H6: Costo - Referencia
D7: Cantidad | E7: Unidad medida | F7: Cantidad | G7: Unidad medida | H7: Colones
B8: BATIDO ZANAHORIA Y YOGURT | C8: Spoon | D8: 10900 | E8: g | F8: 1 | G8: Tanda
A10: 902000019 | B10: MANTECA PARA ENGRASAR | C10: Spoon | D10: 270 | E10: g
A11: 1950772 | B11: PAPEL ENCERADO 12 X 10 (PAQ*500) | C11: Mayca | D11: 12 | E11: Unids
A12: 1840639 | B12: BOLSAS TRANSP GRANDE (KILO) | C12: Plasticos P | D12: 2 | E12: Unid
A13: 0702012 | B13: ETIQ.FECHA VENCIMIENTO | C13: Etiplast | D13: 2 | E13: Unid
C16: Cantidad | D16: Unidad
A17: PESO TOTAL OBTENIDO | C17: =C20*C19 -> 10800 | D17: g | E17: Tiempo de Horneo | G17: 120°C
A18: TIEMPO TOTAL DE PREPARACION | C18: 10 | D18: Min | E18: Horno: | G18: Curitiba
A19: CANTIDAD DE PORCIONES OBTENIDAS | C19: 12 | D19: Unidades | E19: Temperatura de Horneo | G19: 74 Minutos
A20: PESO DE CADA PORCIÓN | C20: 900 | D20: g | E20: Otros
A21: MERMA | C21: =SUM(D8)-C17 -> 100 | D21: g
A22: PROCEDIMIENTO DE PREPARACION DE LA RECETA
A23: 1.- Pesar la mezcla en los moldes previamente engrasados con manteca y papel encerado.
A24: 2.- Hornear, enfriar, desmoldar y empacar en una lata de aluminio, cubrir con una bolsa plastica y etiquetar con fecha.
A26: Peso: Rectangular 900g

Sheet Costo Rosquete 
E1: Precio Local | F1: Costo MP | G1: Costo EM | H1: Costo MO
E2: =IFERROR(O62,"") -> 209.85472 | F2: =IFERROR(H53,"") -> 207.90576 | G2: =IFERROR(H54,"") -> 1.3738754 | H2: =IFERROR(H56,"") -> 25.794286
A5: ESTRUCTURA DE COSTOS
F6: Fecha: | H6: =TODAY() -> 45887
A7: UNIDADES | B7: DESCRIPCION MAT.PRIMA | C7: UNIDADES | D7: UND MEDIDA | E7: COSTO UNITARIO | F7: TOTAL COSTO | G7: % PREC. DEFINIDO | H7: CODIGOS
B8: =IFERROR(VLOOKUP(H8,'[1]Consolidado MP Planta'!$A$2:$M$823,3,0),"") | C8: =+A8 -> 0 | D8: =IFERROR(VLOOKUP(H8,'[1]Consolidado MP Planta'!$A$2:$M$823,13,0),"") | E8: =IFERROR(VLOOKUP(H8,'[1]Consolidado MP Planta'!$A$2:$M$823,12,0),"") | F8: =IFERROR(C8*E8,"") | G8: =IFERROR(F8/$F$66,"")
B9: =IFERROR(VLOOKUP(H9,'[1]Consolidado MP Planta'!$A$2:$M$823,3,0),"") | C9: =+A9 -> 0 | D9: =IFERROR(VLOOKUP(H9,'[1]Consolidado MP Planta'!$A$2:$M$823,13,0),"") | E9: =IFERROR(VLOOKUP(H9,'[1]Consolidado MP Planta'!$A$2:$M$823,12,0),"") | F9: =IFERROR(C9*E9,"") | G9: =IFERROR(F9/$F$66,"")
B10: =IFERROR(VLOOKUP(H10,'[1]Consolidado MP Planta'!$A$2:$M$823,3,0),"") | C10: =+A10 -> 0 | D10: =IFERROR(VLOOKUP(H10,'[1]Consolidado MP Planta'!$A$2:$M$823,13,0),"") | E10: =IFERROR(VLOOKUP(H10,'[1]Consolidado MP Planta'!$A$2:$M$823,12,0),"") | F10: =IFERROR(C10*E10,"") | G10: =IFERROR(F10/$F$66,"")
B11: =IFERROR(VLOOKUP(H11,'[1]Consolidado MP Planta'!$A$2:$M$823,3,0),"") | C11: =+A11 -> 0 | D11: =IFERROR(VLOOKUP(H11,'[1]Consolidado MP Planta'!$A$2:$M$823,13,0),"") | E11: =IFERROR(VLOOKUP(H11,'[1]Consolidado MP Planta'!$A$2:$M$823,12,0),"") | F11: =IFERROR(C11*E11,"") | G11: =IFERROR(F11/$F$66,"")
B12: =IFERROR(VLOOKUP(H12,'[1]Consolidado MP Planta'!$A$2:$M$823,3,0),"") | C12: =+A12 -> 0 | D12: =IFERROR(VLOOKUP(H12,'[1]Consolidado MP Planta'!$A$2:$M$823,13,0),"") | E12: =IFERROR(VLOOKUP(H12,'[1]Consolidado MP Planta'!$A$2:$M$823,12,0),"") | F12: =IFERROR(C12*E12,"") | G12: =IFERROR(F12/$F$66,"")
B13: =IFERROR(VLOOKUP(H13,'[1]Consolidado MP Planta'!$A$2:$M$823,3,0),"") | C13: =+A13 -> 0 | D13: =IFERROR(VLOOKUP(H13,'[1]Consolidado MP Planta'!$A$2:$M$823,13,0),"") | E13: =IFERROR(VLOOKUP(H13,'[1]Consolidado MP Planta'!$A$2:$M$823,12,0),"") | F13: =IFERROR(C13*E13,"") | G13: =IFERROR(F13/$F$66,"")
B14: =IFERROR(VLOOKUP(H14,'[1]Consolidado MP Planta'!$A$2:$M$823,3,0),"") | C14: =+A14 -> 0 | D14: =IFERROR(VLOOKUP(H14,'[1]Consolidado MP Planta'!$A$2:$M$823,13,0),"") | E14: =IFERROR(VLOOKUP(H14,'[1]Consolidado MP Planta'!$A$2:$M$823,12,0),"") | F14: =IFERROR(C14*E14,"") | G14: =IFERROR(F14/$F$66,"")
B15: =IFERROR(VLOOKUP(H15,'[2]ARTICULOS MP PLANTA'!$A$2:$G$589,2,0),"")
A16: UNIDADES | B16: MATERIA PRIMA SEMIELABORADOS | C16: UNIDADES | D16: UND MEDIDA | E16: COSTO UNITARIO | F16: TOTAL COSTO | G16: % PREC. DEFINIDO | H16: CODIGOS
A17: 10500 | B17: BATIDO ZANAHORIA Y YOGURT | C17: =+A17 -> 10500 | D17: Gramos | E17: =+'Costo Batido'!E70 -> 1.732548 | F17: =IFERROR(E17*C17,"") -> 18191.754 | G17: =IFERROR(F17/$F$66,"") -> 0.90054607
A18: 0 | B18: =IFERROR(VLOOKUP(H18,[1]SEMIELABORADOS!$A$2:$M$6000,2,0),"") -> MEZCLA P/ENGRASE MOLDES KILO | C18: =+A18 -> 0 | D18: =IFERROR(VLOOKUP(H18,[1]SEMIELABORADOS!$A$2:$M$6000,6,0),"") -> Gramo | E18: 2.04 | F18: =IFERROR(E18*C18,"") -> 0 | G18: =IFERROR(F18/$F$66,"") -> 0 | H18: 902000019
B19: =IFERROR(VLOOKUP(H19,[1]SEMIELABORADOS!$A$2:$M$6000,2,0),"") | C19: =+A19 -> 0 | D19: =IFERROR(VLOOKUP(H19,[1]SEMIELABORADOS!$A$2:$M$6000,6,0),"") | E19: =IFERROR(VLOOKUP(H19,[1]SEMIELABORADOS!$A$2:$H$65536,8,0),"") | F19: =IFERROR(E19*C19,"") | G19: =IFERROR(F19/$F$66,"")
B20: =IFERROR(VLOOKUP(H20,[1]SEMIELABORADOS!$A$2:$M$6000,2,0),"") | C20: =+A20 -> 0 | D20: =IFERROR(VLOOKUP(H20,[1]SEMIELABORADOS!$A$2:$M$6000,6,0),"") | E20: =IFERROR(VLOOKUP(H20,[1]SEMIELABORADOS!$A$2:$H$65536,8,0),"") | F20: =IFERROR(E20*C20,"") | G20: =IFERROR(F20/$F$66,"")
B21: =IFERROR(VLOOKUP(H21,[1]SEMIELABORADOS!$A$2:$M$6000,2,0),"") | C21: =+A21 -> 0 | D21: =IFERROR(VLOOKUP(H21,[1]SEMIELABORADOS!$A$2:$M$6000,6,0),"") | E21: =IFERROR(VLOOKUP(H21,[1]SEMIELABORADOS!$A$2:$H$65536,8,0),"") | F21: =IFERROR(E21*C21,"") | G21: =IFERROR(F21/$F$66,"")
B22: =IFERROR(VLOOKUP(H22,[1]SEMIELABORADOS!$A$2:$M$6000,2,0),"") | C22: =+A22 -> 0 | D22: =IFERROR(VLOOKUP(H22,[1]SEMIELABORADOS!$A$2:$M$6000,6,0),"") | E22: =IFERROR(VLOOKUP(H22,[1]SEMIELABORADOS!$A$2:$H$65536,8,0),"") | F22: =IFERROR(E22*C22,"") | G22: =IFERROR(F22/$F$66,"")
B23: =IFERROR(VLOOKUP(H23,[1]SEMIELABORADOS!$A$2:$M$6000,2,0),"") | C23: =+A23 -> 0 | D23: =IFERROR(VLOOKUP(H23,[1]SEMIELABORADOS!$A$2:$M$6000,6,0),"") | E23: =IFERROR(VLOOKUP(H23,[1]SEMIELABORADOS!$A$2:$H$65536,8,0),"") | F23: =IFERROR(E23*C23,"") | G23: =IFERROR(F23/$F$66,"")
B24: =IFERROR(VLOOKUP(H24,[1]SEMIELABORADOS!$A$2:$M$6000,2,0),"") | C24: =+A24 -> 0 | D24: =IFERROR(VLOOKUP(H24,[1]SEMIELABORADOS!$A$2:$M$6000,6,0),"") | E24: =IFERROR(VLOOKUP(H24,[1]SEMIELABORADOS!$A$2:$H$65536,8,0),"") | F24: =IFERROR(E24*C24,"") | G24: =IFERROR(F24/$F$66,"")
A26: UNIDADES | B26: EMPAQUE | C26: UNIDADES | D26: UND MEDIDA | E26: COSTO UNITARIO | F26: TOTAL COSTO | G26: % PREC. DEFINIDO | H26: CODIGOS
A27: 0 | B27: =IFERROR(VLOOKUP(H27,'[1]Consolidado MP Planta'!$A$2:$M$823,3,0),"") -> PAPEL ENCERADO 10X10 (CAJA) | C27: =+A27 -> 0 | D27: =IFERROR(VLOOKUP(H27,'[1]Consolidado MP Planta'!$A$2:$M$823,13,0),"") -> Und | E27: =IFERROR(VLOOKUP(H27,'[1]Consolidado MP Planta'!$A$2:$M$823,12,0),"") -> 10.642 | F27: =IFERROR(C27*E27,"") -> 0 | G27: =IFERROR(F27/$F$66,"") -> 0 | H27: 1950772
A28: 0 | B28: =IFERROR(VLOOKUP(H28,'[1]Consolidado MP Planta'!$A$2:$M$823,3,0),"") -> BOLSA TRANSPARENTE 56X96X1.80 KILO | C28: =+A28 -> 0 | D28: =IFERROR(VLOOKUP(H28,'[1]Consolidado MP Planta'!$A$2:$M$823,13,0),"") -> Und | E28: =IFERROR(VLOOKUP(H28,'[1]Consolidado MP Planta'!$A$2:$M$823,12,0),"") -> 50 | F28: =IFERROR(C28*E28,"") -> 0 | G28: =IFERROR(F28/$F$66,"") -> 0 | H28: 1950928
A29: 0 | B29: =IFERROR(VLOOKUP(H29,'[1]Consolidado MP Planta'!$A$2:$M$823,3,0),"") -> ETIQ.FECHA VENCIMIENTO VERDE (ROLLO) | C29: =+A29 -> 0 | D29: =IFERROR(VLOOKUP(H29,'[1]Consolidado MP Planta'!$A$2:$M$823,13,0),"") -> Und | E29: =IFERROR(VLOOKUP(H29,'[1]Consolidado MP Planta'!$A$2:$M$823,12,0),"") -> 0.33333333 | F29: =IFERROR(C29*E29,"") -> 0 | G29: =IFERROR(F29/$F$66,"") -> 0 | H29: 0702012
B30: =IFERROR(VLOOKUP(H30,'[1]Consolidado MP Planta'!$A$2:$M$823,3,0),"") | C30: =+A30 -> 0 | D30: =IFERROR(VLOOKUP(H30,'[1]Consolidado MP Planta'!$A$2:$M$823,13,0),"") | E30: =IFERROR(VLOOKUP(H30,'[1]Consolidado MP Planta'!$A$2:$M$823,12,0),"") | F30: =IFERROR(C30*E30,"") | G30: =IFERROR(F30/$F$66,"")
B31: =IFERROR(VLOOKUP(H31,'[1]Consolidado MP Planta'!$A$2:$M$823,3,0),"") | C31: =+A31 -> 0 | D31: =IFERROR(VLOOKUP(H31,'[1]Consolidado MP Planta'!$A$2:$M$823,13,0),"") | E31: =IFERROR(VLOOKUP(H31,'[1]Consolidado MP Planta'!$A$2:$M$823,12,0),"") | F31: =IFERROR(C31*E31,"") | G31: =IFERROR(F31/$F$66,"")
B32: =IFERROR(VLOOKUP(H32,'[1]Consolidado MP Planta'!$A$2:$M$823,3,0),"") | C32: =+A32 -> 0 | D32: =IFERROR(VLOOKUP(H32,'[1]Consolidado MP Planta'!$A$2:$M$823,13,0),"") | E32: =IFERROR(VLOOKUP(H32,'[1]Consolidado MP Planta'!$A$2:$M$823,12,0),"") | F32: =IFERROR(C32*E32,"") | G32: =IFERROR(F32/$F$66,"")
A34: UNIDADES | B34: EMPAQUE SEMIELABORADOS | C34: UNIDADES | D34: UND MEDIDA | E34: COSTO UNITARIO | F34: TOTAL COSTO | G34: % PREC. DEFINIDO | H34: CODIGOS
A35: 10500 | B35: BATIDO ZANAHORIA Y YOGURT | C35: =+A35 -> 10500 | D35: Gramos | E35: =+'Costo Batido'!E77 -> 0.011448961 | F35: =IFERROR(E35*C35,"") -> 120.2141 | G35: =IFERROR(F35/$F$66,"") -> 0.0059509562
A36: 0 | B36: =IFERROR(VLOOKUP(H36,[1]SEMIELABORADOS!$A$2:$M$6000,2,0),"") -> MEZCLA P/ENGRASE MOLDES KILO | C36: =+A36 -> 0 | D36: =IFERROR(VLOOKUP(H36,[1]SEMIELABORADOS!$A$2:$M$6000,6,0),"") -> Gramo | E36: =IFERROR(VLOOKUP(H36,[1]SEMIELABORADOS!$A$2:$M$65536,10,0),"") -> 0.021536385 | F36: =IFERROR(E36*C36,"") -> 0 | G36: =IFERROR(F36/$F$66,"") -> 0 | H36: 902000019
A37: =+A19 -> 0 | B37: =IFERROR(VLOOKUP(H37,[1]SEMIELABORADOS!$A$2:$M$6000,2,0),"") | C37: =+A37 -> 0 | D37: =IFERROR(VLOOKUP(H37,[1]SEMIELABORADOS!$A$2:$M$6000,6,0),"") | E37: =IFERROR(VLOOKUP(H37,[1]SEMIELABORADOS!$A$2:$M$65536,10,0),"") | F37: =IFERROR(E37*C37,"") | G37: =IFERROR(F37/$F$66,"")
A38: =+A20 -> 0 | B38: =IFERROR(VLOOKUP(H38,[1]SEMIELABORADOS!$A$2:$M$6000,2,0),"") | C38: =+A38 -> 0 | D38: =IFERROR(VLOOKUP(H38,[1]SEMIELABORADOS!$A$2:$M$6000,6,0),"") | E38: =IFERROR(VLOOKUP(H38,[1]SEMIELABORADOS!$A$2:$M$65536,10,0),"") | F38: =IFERROR(E38*C38,"") | G38: =IFERROR(F38/$F$66,"")
A39: =+A21 -> 0 | B39: =IFERROR(VLOOKUP(H39,[1]SEMIELABORADOS!$A$2:$M$6000,2,0),"") | C39: =+A39 -> 0 | D39: =IFERROR(VLOOKUP(H39,[1]SEMIELABORADOS!$A$2:$M$6000,6,0),"") | E39: =IFERROR(VLOOKUP(H39,[1]SEMIELABORADOS!$A$2:$M$65536,10,0),"") | F39: =IFERROR(E39*C39,"") | G39: =IFERROR(F39/$F$66,"")
A40: =+A22 -> 0 | B40: =IFERROR(VLOOKUP(H40,[1]SEMIELABORADOS!$A$2:$M$6000,2,0),"") | C40: =+A40 -> 0 | D40: =IFERROR(VLOOKUP(H40,[1]SEMIELABORADOS!$A$2:$M$6000,6,0),"") | E40: =IFERROR(VLOOKUP(H40,[1]SEMIELABORADOS!$A$2:$M$65536,10,0),"") | F40: =IFERROR(E40*C40,"") | G40: =IFERROR(F40/$F$66,"")
A41: =+A23 -> 0 | B41: =IFERROR(VLOOKUP(H41,[1]SEMIELABORADOS!$A$2:$M$6000,2,0),"") | C41: =+A41 -> 0 | D41: =IFERROR(VLOOKUP(H41,[1]SEMIELABORADOS!$A$2:$M$6000,6,0),"") | E41: =IFERROR(VLOOKUP(H41,[1]SEMIELABORADOS!$A$2:$M$65536,10,0),"") | F41: =IFERROR(E41*C41,"") | G41: =IFERROR(F41/$F$66,"")
A43: UNIDADES | B43: MODI | C43: UNIDADES | D43: UND MEDIDA | E43: COSTO UNITARIO | F43: TOTAL COSTO | G43: % PREC. DEFINIDO | H43: CODIGOS
A44: =+A35 -> 10500 | B44: BATIDO ZANAHORIA Y YOGURT | C44: =+A44 -> 10500 | D44: Gramos | E44: =+'Costo Batido'!E75 -> 0.069714286 | F44: =IFERROR(E44*C44,"") -> 732 | G44: =IFERROR(F44/$F$66,"") -> 0.036236183
A45: =+A36 -> 0 | B45: =IFERROR(VLOOKUP(H45,[1]SEMIELABORADOS!$A$2:$M$6000,2,0),"") -> MEZCLA P/ENGRASE MOLDES KILO | C45: =+A45 -> 0 | D45: =IFERROR(VLOOKUP(H45,[1]SEMIELABORADOS!$A$2:$M$6000,6,0),"") -> Gramo | E45: =IFERROR(VLOOKUP(H45,[1]SEMIELABORADOS!$A$2:$M$65536,12,0),"") -> 0.2512758 | F45: =IFERROR(E45*C45,"") -> 0 | G45: =IFERROR(F45/$F$66,"") -> 0 | H45: 902000019
...

Sheet Empaque QQ seco 7 porc
B1: SERVICIOS DE PASTELERIA S.A. | G1: CÓDIGO:
B2: ESPECIFICACION DE RECETA | G2: REVISIÓN:
B3: Empaque Porcion Queque Zanahoria y yogurt (7 porc) | G3: FECHA DE APROBACIÓN:
B4: Elaborado | C4: Maria Jose Rodriguez, Chef
B5: Aprobado | C5: Esteban Cartin, Gte Manufatcura
A6: # Código | B6: Descripción del ingrediente | C6: Marca | D6: Unidad Internacional | F6: Medida alternativa | H6: Costo - Referencia
D7: Cantidad | E7: Unidad medida | F7: Cantidad | G7: Unidad medida | H7: Colones
B8: QUEQUE ZANAHORIA Y YOGURT RECTANGULAR 900g | C8: FAS | D8: 855 | E8: g | F8: 1 | G8: Queque
B9: EMPAQUE
A10: 51600004 | B10: LAZO DE TELA | D10: 1 | E10: unidad
A11: 1950895 | B11: BOLSA DE CELOFAN 6*9 | C11: Alim Tec | D11: 7 | E11: Unids
A12: 0702006 | B12: ETIQ.FECHA VENCIMIENTO | C12: Etiplast | D12: 7 | E12: Unids
A13: 1959752 | B13: CAJA BLANCA MINI | D13: 2 | E13: Unid
C16: Cantidad | D16: Unidad
A17: PESO TOTAL OBTENIDO | C17: 800 | D17: g | E17: Tiempo de Horneo:
A18: TIEMPO TOTAL DE PREPARACION | C18: 4 | D18: Minutos | E18: Horno:
A19: CANTIDAD DE PORCIONES OBTENIDAS | C19: 7 | D19: Porciones | E19: Temperatura de Horneo:
A20: PESO DE CADA PORCIÓN | C20: 115 | D20: g | E20: Otros
A21: MERMA | C21: 55 | D21: g
A22: PROCEDIMIENTO DE PREPARACION DE LA RECETA
A23: 1.- Una vez horneado el queque, dejar enfriar y cortar los extremos. Luego porcionar luego en 7 partes iguales. Con ayuda del porcionador.
A24: 2.- Colocar cada una de las porciones en una bolsa de celofan.
A25: 3.- Sellar las bolsas y colocar el lazo de tela, etiquetar con fecha de vencimiento.
A26: 4.- Colocar las 4 porciones en una caja blanca MINI.
A27: CONTROL DE CAMBIOS

Sheet Costo Empaque QQ sec
E1: Precio Local | F1: Costo MP | G1: Costo EM | H1: Costo MO
E2: =IFERROR(O62,"") -> 2134.0078 | F2: =IFERROR(H53,"") -> 1247.4346 | G2: =IFERROR(H54,"") -> 108.65325 | H2: =IFERROR(H56,"") -> 398.76571
A5: ESTRUCTURA DE COSTOS
F6: Fecha: | H6: =TODAY() -> 45887
A7: UNIDADES | B7: DESCRIPCION MAT.PRIMA | C7: UNIDADES | D7: UND MEDIDA | E7: COSTO UNITARIO | F7: TOTAL COSTO | G7: % PREC. DEFINIDO | H7: CODIGOS
B8: =IFERROR(VLOOKUP(H8,'[1]Consolidado MP Planta'!$A$2:$M$823,3,0),"") | C8: =+A8 -> 0 | D8: =IFERROR(VLOOKUP(H8,'[1]Consolidado MP Planta'!$A$2:$M$823,13,0),"") | E8: =IFERROR(VLOOKUP(H8,'[1]Consolidado MP Planta'!$A$2:$M$823,12,0),"") | F8: =IFERROR(C8*E8,"") | G8: =IFERROR(F8/$F$66,"")
B9: =IFERROR(VLOOKUP(H9,'[1]Consolidado MP Planta'!$A$2:$M$823,3,0),"") | C9: =+A9 -> 0 | D9: =IFERROR(VLOOKUP(H9,'[1]Consolidado MP Planta'!$A$2:$M$823,13,0),"") | E9: =IFERROR(VLOOKUP(H9,'[1]Consolidado MP Planta'!$A$2:$M$823,12,0),"") | F9: =IFERROR(C9*E9,"") | G9: =IFERROR(F9/$F$66,"")
B10: =IFERROR(VLOOKUP(H10,'[1]Consolidado MP Planta'!$A$2:$M$823,3,0),"") | C10: =+A10 -> 0 | D10: =IFERROR(VLOOKUP(H10,'[1]Consolidado MP Planta'!$A$2:$M$823,13,0),"") | E10: =IFERROR(VLOOKUP(H10,'[1]Consolidado MP Planta'!$A$2:$M$823,12,0),"") | F10: =IFERROR(C10*E10,"") | G10: =IFERROR(F10/$F$66,"")
B11: =IFERROR(VLOOKUP(H11,'[1]Consolidado MP Planta'!$A$2:$M$823,3,0),"") | C11: =+A11 -> 0 | D11: =IFERROR(VLOOKUP(H11,'[1]Consolidado MP Planta'!$A$2:$M$823,13,0),"") | E11: =IFERROR(VLOOKUP(H11,'[1]Consolidado MP Planta'!$A$2:$M$823,12,0),"") | F11: =IFERROR(C11*E11,"") | G11: =IFERROR(F11/$F$66,"")
B12: =IFERROR(VLOOKUP(H12,'[1]Consolidado MP Planta'!$A$2:$M$823,3,0),"") | C12: =+A12 -> 0 | D12: =IFERROR(VLOOKUP(H12,'[1]Consolidado MP Planta'!$A$2:$M$823,13,0),"") | E12: =IFERROR(VLOOKUP(H12,'[1]Consolidado MP Planta'!$A$2:$M$823,12,0),"") | F12: =IFERROR(C12*E12,"") | G12: =IFERROR(F12/$F$66,"")
B13: =IFERROR(VLOOKUP(H13,'[1]Consolidado MP Planta'!$A$2:$M$823,3,0),"") | C13: =+A13 -> 0 | D13: =IFERROR(VLOOKUP(H13,'[1]Consolidado MP Planta'!$A$2:$M$823,13,0),"") | E13: =IFERROR(VLOOKUP(H13,'[1]Consolidado MP Planta'!$A$2:$M$823,12,0),"") | F13: =IFERROR(C13*E13,"") | G13: =IFERROR(F13/$F$66,"")
B14: =IFERROR(VLOOKUP(H14,'[1]Consolidado MP Planta'!$A$2:$M$823,3,0),"") | C14: =+A14 -> 0 | D14: =IFERROR(VLOOKUP(H14,'[1]Consolidado MP Planta'!$A$2:$M$823,13,0),"") | E14: =IFERROR(VLOOKUP(H14,'[1]Consolidado MP Planta'!$A$2:$M$823,12,0),"") | F14: =IFERROR(C14*E14,"") | G14: =IFERROR(F14/$F$66,"")
B15: =IFERROR(VLOOKUP(H15,'[2]ARTICULOS MP PLANTA'!$A$2:$G$589,2,0),"")
A16: UNIDADES | B16: MATERIA PRIMA SEMIELABORADOS | C16: UNIDADES | D16: UND MEDIDA | E16: COSTO UNITARIO | F16: TOTAL COSTO | G16: % PREC. DEFINIDO | H16: CODIGOS
A17: 6 | B17: QUEQUE ZANAHORIA Y YOGURT RECTANGULAR 900g | C17: =+A17 -> 6 | D17: UND | E17: =+'Costo Rosquete '!H53 -> 207.90576 | F17: =IFERROR(E17*C17,"") -> 1247.4346 | G17: =IFERROR(F17/$F$66,"") -> 0.76763479
B18: =IFERROR(VLOOKUP(H18,[1]SEMIELABORADOS!$A$2:$M$6000,2,0),"") | C18: =+A18 -> 0 | D18: =IFERROR(VLOOKUP(H18,[1]SEMIELABORADOS!$A$2:$M$6000,6,0),"") | E18: =IFERROR(VLOOKUP(H18,[1]SEMIELABORADOS!$A$2:$H$65536,8,0),"") | F18: =IFERROR(E18*C18,"") | G18: =IFERROR(F18/$F$66,"")
B19: =IFERROR(VLOOKUP(H19,[1]SEMIELABORADOS!$A$2:$M$6000,2,0),"") | C19: =+A19 -> 0 | D19: =IFERROR(VLOOKUP(H19,[1]SEMIELABORADOS!$A$2:$M$6000,6,0),"") | E19: =IFERROR(VLOOKUP(H19,[1]SEMIELABORADOS!$A$2:$H$65536,8,0),"") | F19: =IFERROR(E19*C19,"") | G19: =IFERROR(F19/$F$66,"")
B20: =IFERROR(VLOOKUP(H20,[1]SEMIELABORADOS!$A$2:$M$6000,2,0),"") | C20: =+A20 -> 0 | D20: =IFERROR(VLOOKUP(H20,[1]SEMIELABORADOS!$A$2:$M$6000,6,0),"") | E20: =IFERROR(VLOOKUP(H20,[1]SEMIELABORADOS!$A$2:$H$65536,8,0),"") | F20: =IFERROR(E20*C20,"") | G20: =IFERROR(F20/$F$66,"")
B21: =IFERROR(VLOOKUP(H21,[1]SEMIELABORADOS!$A$2:$M$6000,2,0),"") | C21: =+A21 -> 0 | D21: =IFERROR(VLOOKUP(H21,[1]SEMIELABORADOS!$A$2:$M$6000,6,0),"") | E21: =IFERROR(VLOOKUP(H21,[1]SEMIELABORADOS!$A$2:$H$65536,8,0),"") | F21: =IFERROR(E21*C21,"") | G21: =IFERROR(F21/$F$66,"")
B22: =IFERROR(VLOOKUP(H22,[1]SEMIELABORADOS!$A$2:$M$6000,2,0),"") | C22: =+A22 -> 0 | D22: =IFERROR(VLOOKUP(H22,[1]SEMIELABORADOS!$A$2:$M$6000,6,0),"") | E22: =IFERROR(VLOOKUP(H22,[1]SEMIELABORADOS!$A$2:$H$65536,8,0),"") | F22: =IFERROR(E22*C22,"") | G22: =IFERROR(F22/$F$66,"")
B23: =IFERROR(VLOOKUP(H23,[1]SEMIELABORADOS!$A$2:$M$6000,2,0),"") | C23: =+A23 -> 0 | D23: =IFERROR(VLOOKUP(H23,[1]SEMIELABORADOS!$A$2:$M$6000,6,0),"") | E23: =IFERROR(VLOOKUP(H23,[1]SEMIELABORADOS!$A$2:$H$65536,8,0),"") | F23: =IFERROR(E23*C23,"") | G23: =IFERROR(F23/$F$66,"")
B24: =IFERROR(VLOOKUP(H24,[1]SEMIELABORADOS!$A$2:$M$6000,2,0),"") | C24: =+A24 -> 0 | D24: =IFERROR(VLOOKUP(H24,[1]SEMIELABORADOS!$A$2:$M$6000,6,0),"") | E24: =IFERROR(VLOOKUP(H24,[1]SEMIELABORADOS!$A$2:$H$65536,8,0),"") | F24: =IFERROR(E24*C24,"") | G24: =IFERROR(F24/$F$66,"")
A26: UNIDADES | B26: EMPAQUE | C26: UNIDADES | D26: UND MEDIDA | E26: COSTO UNITARIO | F26: TOTAL COSTO | G26: % PREC. DEFINIDO | H26: CODIGOS
A27: 0 | B27: =IFERROR(VLOOKUP(H27,'[1]Consolidado MP Planta'!$A$2:$M$823,3,0),"") -> LAZOS ROJOS (UND) | C27: =+A27 -> 0 | D27: 1 | E27: 85 | F27: =IFERROR(C27*E27,"") -> 0 | G27: =IFERROR(F27/$F$66,"") -> 0 | H27: 51600004
A28: 0 | B28: =IFERROR(VLOOKUP(H28,'[1]Consolidado MP Planta'!$A$2:$M$823,3,0),"") -> BOLSA CELOFAN 6 X 9 (KILO) | C28: =+A28 -> 0 | D28: =IFERROR(VLOOKUP(H28,'[1]Consolidado MP Planta'!$A$2:$M$823,13,0),"") -> Unidades | E28: 14.89 | F28: =IFERROR(C28*E28,"") -> 0 | G28: =IFERROR(F28/$F$66,"") -> 0 | H28: 1950895
A29: 1 | B29: =IFERROR(VLOOKUP(H29,'[1]Consolidado MP Planta'!$A$2:$M$823,3,0),"") -> ETIQ.FECHA VENCIMIENTO BLANCO (ROLLO) | C29: =+A29 -> 1 | D29: =IFERROR(VLOOKUP(H29,'[1]Consolidado MP Planta'!$A$2:$M$823,13,0),"") -> Gramos | E29: 0.33 | F29: =IFERROR(C29*E29,"") -> 0.33 | G29: =IFERROR(F29/$F$66,"") -> 0.00020307236 | H29: 0702007
A30: 2 | B30: =IFERROR(VLOOKUP(H30,'[1]Consolidado MP Planta'!$A$2:$M$823,3,0),"") -> CAJA BLANCA MEDIANA (PAQ:100 UND) | C30: =+A30 -> 2 | D30: =IFERROR(VLOOKUP(H30,'[1]Consolidado MP Planta'!$A$2:$M$823,13,0),"") -> Und | E30: 49.75 | F30: =IFERROR(C30*E30,"") -> 99.5 | G30: =IFERROR(F30/$F$66,"") -> 0.061229394 | H30: 1950729
A31: 1 | B31: =IFERROR(VLOOKUP(H31,'[1]Consolidado MP Planta'!$A$2:$M$823,3,0),"") -> ETIQ.BLANCA 1 1/4 * 3/4 (UND) | C31: =+A31 -> 1 | D31: =IFERROR(VLOOKUP(H31,'[1]Consolidado MP Planta'!$A$2:$M$823,13,0),"") -> Und | E31: =IFERROR(VLOOKUP(H31,'[1]Consolidado MP Planta'!$A$2:$M$823,12,0),"") -> 0.58 | F31: =IFERROR(C31*E31,"") -> 0.58 | G31: =IFERROR(F31/$F$66,"") -> 0.00035691506 | H31: 0702069
B32: =IFERROR(VLOOKUP(H32,'[1]Consolidado MP Planta'!$A$2:$M$823,3,0),"") | C32: =+A32 -> 0 | D32: =IFERROR(VLOOKUP(H32,'[1]Consolidado MP Planta'!$A$2:$M$823,13,0),"") | E32: =IFERROR(VLOOKUP(H32,'[1]Consolidado MP Planta'!$A$2:$M$823,12,0),"") | F32: =IFERROR(C32*E32,"") | G32: =IFERROR(F32/$F$66,"")
A34: UNIDADES | B34: EMPAQUE SEMIELABORADOS | C34: UNIDADES | D34: UND MEDIDA | E34: COSTO UNITARIO | F34: TOTAL COSTO | G34: % PREC. DEFINIDO | H34: CODIGOS
A35: =+A17 -> 6 | B35: QUEQUE ZANAHORIA Y YOGURT RECTANGULAR 900g | C35: =+A35 -> 6 | D35: UND | E35: =+'Costo Rosquete '!H54 -> 1.3738754 | F35: =IFERROR(E35*C35,"") -> 8.2432522 | G35: =IFERROR(F35/$F$66,"") -> 0.0050726567
A36: =+A18 -> 0 | B36: =IFERROR(VLOOKUP(H36,[1]SEMIELABORADOS!$A$2:$M$6000,2,0),"") | C36: =+A36 -> 0 | D36: =IFERROR(VLOOKUP(H36,[1]SEMIELABORADOS!$A$2:$M$6000,6,0),"") | E36: =IFERROR(VLOOKUP(H36,[1]SEMIELABORADOS!$A$2:$M$65536,10,0),"") | F36: =IFERROR(E36*C36,"") | G36: =IFERROR(F36/$F$66,"")
A37: =+A19 -> 0 | B37: =IFERROR(VLOOKUP(H37,[1]SEMIELABORADOS!$A$2:$M$6000,2,0),"") | C37: =+A37 -> 0 | D37: =IFERROR(VLOOKUP(H37,[1]SEMIELABORADOS!$A$2:$M$6000,6,0),"") | E37: =IFERROR(VLOOKUP(H37,[1]SEMIELABORADOS!$A$2:$M$65536,10,0),"") | F37: =IFERROR(E37*C37,"") | G37: =IFERROR(F37/$F$66,"")
A38: =+A20 -> 0 | B38: =IFERROR(VLOOKUP(H38,[1]SEMIELABORADOS!$A$2:$M$6000,2,0),"") | C38: =+A38 -> 0 | D38: =IFERROR(VLOOKUP(H38,[1]SEMIELABORADOS!$A$2:$M$6000,6,0),"") | E38: =IFERROR(VLOOKUP(H38,[1]SEMIELABORADOS!$A$2:$M$65536,10,0),"") | F38: =IFERROR(E38*C38,"") | G38: =IFERROR(F38/$F$66,"")
A39: =+A21 -> 0 | B39: =IFERROR(VLOOKUP(H39,[1]SEMIELABORADOS!$A$2:$M$6000,2,0),"") | C39: =+A39 -> 0 | D39: =IFERROR(VLOOKUP(H39,[1]SEMIELABORADOS!$A$2:$M$6000,6,0),"") | E39: =IFERROR(VLOOKUP(H39,[1]SEMIELABORADOS!$A$2:$M$65536,10,0),"") | F39: =IFERROR(E39*C39,"") | G39: =IFERROR(F39/$F$66,"")
A40: =+A22 -> 0 | B40: =IFERROR(VLOOKUP(H40,[1]SEMIELABORADOS!$A$2:$M$6000,2,0),"") | C40: =+A40 -> 0 | D40: =IFERROR(VLOOKUP(H40,[1]SEMIELABORADOS!$A$2:$M$6000,6,0),"") | E40: =IFERROR(VLOOKUP(H40,[1]SEMIELABORADOS!$A$2:$M$65536,10,0),"") | F40: =IFERROR(E40*C40,"") | G40: =IFERROR(F40/$F$66,"")
A41: =+A23 -> 0 | B41: =IFERROR(VLOOKUP(H41,[1]SEMIELABORADOS!$A$2:$M$6000,2,0),"") | C41: =+A41 -> 0 | D41: =IFERROR(VLOOKUP(H41,[1]SEMIELABORADOS!$A$2:$M$6000,6,0),"") | E41: =IFERROR(VLOOKUP(H41,[1]SEMIELABORADOS!$A$2:$M$65536,10,0),"") | F41: =IFERROR(E41*C41,"") | G41: =IFERROR(F41/$F$66,"")
A43: UNIDADES | B43: MODI | C43: UNIDADES | D43: UND MEDIDA | E43: COSTO UNITARIO | F43: TOTAL COSTO | G43: % PREC. DEFINIDO | H43: CODIGOS
A44: =+A35 -> 6 | B44: QUEQUE ZANAHORIA Y YOGURT RECTANGULAR 900g | C44: =+A44 -> 6 | D44: UND | E44: =+'Costo Rosquete '!H56 -> 25.794286 | F44: =IFERROR(E44*C44,"") -> 154.76571 | G44: =IFERROR(F44/$F$66,"") -> 0.0952383
A45: =+A36 -> 0 | B45: =IFERROR(VLOOKUP(H45,[1]SEMIELABORADOS!$A$2:$M$6000,2,0),"") | C45: =+A45 -> 0 | D45: =IFERROR(VLOOKUP(H45,[1]SEMIELABORADOS!$A$2:$M$6000,6,0),"") | E45: =IFERROR(VLOOKUP(H45,[1]SEMIELABORADOS!$A$2:$M$65536,12,0),"") | F45: =IFERROR(E45*C45,"") | G45: =IFERROR(F45/$F$66,"")
...

Sheet QQ ZANAH MOLD RECT
B1: SERVICIOS DE PASTELERIA S.A. | G1: CÓDIGO:
B2: ESPECIFICACION DE RECETA | G2: REVISIÓN:
B3: Queque zanahoria y yogurt en molde rectangular de carton | G3: FECHA DE APROBACIÓN:
B4: Elaborado | C4: Maria Jose Rodriguez, Chef
B5: Aprobado | C5: Jorge, Montero. Gte de Manufactura
A6: # Código | B6: Descripción del ingrediente | C6: Marca | D6: Unidad Internacional | F6: Medida alternativa | H6: Costo - Referencia
D7: Cantidad | E7: Unidad medida | F7: Cantidad | G7: Unidad medida | H7: Colones
B8: BATIDO P/ROSQUETE ZANAHORIA (10200g) | C8: Spoon | D8: 10900 | E8: g
B10: BANDEJA HORNEABLE 65X2000 mm | D10: 25 | E10: Unidades
A11: 1950928 | B11: BOLSA TRANSPARENTE 56X96X1.80 ** | D11: 2 | E11: Unidades
A12: 0702007 | B12: ETIQ.FECHA VENCIMIENTO BLANCO | D12: 2 | E12: Unidades
K14: 740
C15: Cantidad | D15: Unidad
A16: PESO TOTAL OBTENIDO | C16: 10800 | D16: g | E16: Tiempo de Horneo: | G16: 28 Minutos
A17: TIEMPO TOTAL DE PREPARACION | C17: 20 | D17: Min. | E17: Horno: | G17: Marshall
A18: CANTIDAD DE PORCIONES OBTENIDAS | C18: 27 | D18: Undades | E18: Temperatura de Horneo: | G18: 170°C
A19: PESO DE CADA PORCIÓN | C19: 400 | D19: g | E19: Otros
A20: MERMA | C20: 350 | D20: g
A21: PROCEDIMIENTO DE PREPARACION DE LA RECETA
A22: 1.- Pesar 400g de mezcla en el molde.
A23: 2.- Hornear en el Marshall a 170°C por 28 minutos.

Sheet COSTO QQ ZANAH MOLD RECT
E1: Precio Local | F1: Costo MP | G1: Costo EM | H1: Costo MO
E2: =IFERROR(O62,"") -> 945.67161 | F2: =IFERROR(H53,"") -> 699.43604 | G2: =IFERROR(H54,"") -> 103.18372 | H2: =IFERROR(H56,"") -> 73.329101
A5: ESTRUCTURA DE COSTOS
F6: Fecha: | H6: =TODAY() -> 45887
A7: UNIDADES | B7: DESCRIPCION MAT.PRIMA | C7: UNIDADES | D7: UND MEDIDA | E7: COSTO UNITARIO | F7: TOTAL COSTO | G7: % PREC. DEFINIDO | H7: CODIGOS
B8: =IFERROR(VLOOKUP(H8,'[1]Consolidado MP Planta'!$A$2:$M$823,3,0),"") | C8: =+A8 -> 0 | D8: =IFERROR(VLOOKUP(H8,'[1]Consolidado MP Planta'!$A$2:$M$823,13,0),"") | E8: =IFERROR(VLOOKUP(H8,'[1]Consolidado MP Planta'!$A$2:$M$823,12,0),"") | F8: =IFERROR(C8*E8,"") | G8: =IFERROR(F8/$F$66,"")
B9: =IFERROR(VLOOKUP(H9,'[1]Consolidado MP Planta'!$A$2:$M$823,3,0),"") | C9: =+A9 -> 0 | D9: =IFERROR(VLOOKUP(H9,'[1]Consolidado MP Planta'!$A$2:$M$823,13,0),"") | E9: =IFERROR(VLOOKUP(H9,'[1]Consolidado MP Planta'!$A$2:$M$823,12,0),"") | F9: =IFERROR(C9*E9,"") | G9: =IFERROR(F9/$F$66,"")
B10: =IFERROR(VLOOKUP(H10,'[1]Consolidado MP Planta'!$A$2:$M$823,3,0),"") | C10: =+A10 -> 0 | D10: =IFERROR(VLOOKUP(H10,'[1]Consolidado MP Planta'!$A$2:$M$823,13,0),"") | E10: =IFERROR(VLOOKUP(H10,'[1]Consolidado MP Planta'!$A$2:$M$823,12,0),"") | F10: =IFERROR(C10*E10,"") | G10: =IFERROR(F10/$F$66,"")
B11: =IFERROR(VLOOKUP(H11,'[1]Consolidado MP Planta'!$A$2:$M$823,3,0),"") | C11: =+A11 -> 0 | D11: =IFERROR(VLOOKUP(H11,'[1]Consolidado MP Planta'!$A$2:$M$823,13,0),"") | E11: =IFERROR(VLOOKUP(H11,'[1]Consolidado MP Planta'!$A$2:$M$823,12,0),"") | F11: =IFERROR(C11*E11,"") | G11: =IFERROR(F11/$F$66,"")
B12: =IFERROR(VLOOKUP(H12,'[1]Consolidado MP Planta'!$A$2:$M$823,3,0),"") | C12: =+A12 -> 0 | D12: =IFERROR(VLOOKUP(H12,'[1]Consolidado MP Planta'!$A$2:$M$823,13,0),"") | E12: =IFERROR(VLOOKUP(H12,'[1]Consolidado MP Planta'!$A$2:$M$823,12,0),"") | F12: =IFERROR(C12*E12,"") | G12: =IFERROR(F12/$F$66,"")
B13: =IFERROR(VLOOKUP(H13,'[1]Consolidado MP Planta'!$A$2:$M$823,3,0),"") | C13: =+A13 -> 0 | D13: =IFERROR(VLOOKUP(H13,'[1]Consolidado MP Planta'!$A$2:$M$823,13,0),"") | E13: =IFERROR(VLOOKUP(H13,'[1]Consolidado MP Planta'!$A$2:$M$823,12,0),"") | F13: =IFERROR(C13*E13,"") | G13: =IFERROR(F13/$F$66,"")
B14: =IFERROR(VLOOKUP(H14,'[1]Consolidado MP Planta'!$A$2:$M$823,3,0),"") | C14: =+A14 -> 0 | D14: =IFERROR(VLOOKUP(H14,'[1]Consolidado MP Planta'!$A$2:$M$823,13,0),"") | E14: =IFERROR(VLOOKUP(H14,'[1]Consolidado MP Planta'!$A$2:$M$823,12,0),"") | F14: =IFERROR(C14*E14,"") | G14: =IFERROR(F14/$F$66,"")
B15: =IFERROR(VLOOKUP(H15,'[2]ARTICULOS MP PLANTA'!$A$2:$G$589,2,0),"")
A16: UNIDADES | B16: MATERIA PRIMA SEMIELABORADOS | C16: UNIDADES | D16: UND MEDIDA | E16: COSTO UNITARIO | F16: TOTAL COSTO | G16: % PREC. DEFINIDO | H16: CODIGOS
A17: 10900 | B17: BATIDO P/ROSQUETE ZANAHORIA (10200g) | C17: =+A17 -> 10900 | D17: Gramos | E17: =+'Costo Batido'!E70 -> 1.732548 | F17: =IFERROR(E17*C17,"") -> 18884.773 | G17: =IFERROR(F17/$F$66,"") -> 0.81160499
B18: =IFERROR(VLOOKUP(H18,[1]SEMIELABORADOS!$A$2:$M$6000,2,0),"") | C18: =+A18 -> 0 | D18: =IFERROR(VLOOKUP(H18,[1]SEMIELABORADOS!$A$2:$M$6000,6,0),"") | E18: =IFERROR(VLOOKUP(H18,[1]SEMIELABORADOS!$A$2:$H$65536,8,0),"") | F18: =IFERROR(E18*C18,"") | G18: =IFERROR(F18/$F$66,"")
B19: =IFERROR(VLOOKUP(H19,[1]SEMIELABORADOS!$A$2:$M$6000,2,0),"") | C19: =+A19 -> 0 | D19: =IFERROR(VLOOKUP(H19,[1]SEMIELABORADOS!$A$2:$M$6000,6,0),"") | E19: =IFERROR(VLOOKUP(H19,[1]SEMIELABORADOS!$A$2:$H$65536,8,0),"") | F19: =IFERROR(E19*C19,"") | G19: =IFERROR(F19/$F$66,"")
B20: =IFERROR(VLOOKUP(H20,[1]SEMIELABORADOS!$A$2:$M$6000,2,0),"") | C20: =+A20 -> 0 | D20: =IFERROR(VLOOKUP(H20,[1]SEMIELABORADOS!$A$2:$M$6000,6,0),"") | E20: =IFERROR(VLOOKUP(H20,[1]SEMIELABORADOS!$A$2:$H$65536,8,0),"") | F20: =IFERROR(E20*C20,"") | G20: =IFERROR(F20/$F$66,"")
B21: =IFERROR(VLOOKUP(H21,[1]SEMIELABORADOS!$A$2:$M$6000,2,0),"") | C21: =+A21 -> 0 | D21: =IFERROR(VLOOKUP(H21,[1]SEMIELABORADOS!$A$2:$M$6000,6,0),"") | E21: =IFERROR(VLOOKUP(H21,[1]SEMIELABORADOS!$A$2:$H$65536,8,0),"") | F21: =IFERROR(E21*C21,"") | G21: =IFERROR(F21/$F$66,"")
B22: =IFERROR(VLOOKUP(H22,[1]SEMIELABORADOS!$A$2:$M$6000,2,0),"") | C22: =+A22 -> 0 | D22: =IFERROR(VLOOKUP(H22,[1]SEMIELABORADOS!$A$2:$M$6000,6,0),"") | E22: =IFERROR(VLOOKUP(H22,[1]SEMIELABORADOS!$A$2:$H$65536,8,0),"") | F22: =IFERROR(E22*C22,"") | G22: =IFERROR(F22/$F$66,"")
B23: =IFERROR(VLOOKUP(H23,[1]SEMIELABORADOS!$A$2:$M$6000,2,0),"") | C23: =+A23 -> 0 | D23: =IFERROR(VLOOKUP(H23,[1]SEMIELABORADOS!$A$2:$M$6000,6,0),"") | E23: =IFERROR(VLOOKUP(H23,[1]SEMIELABORADOS!$A$2:$H$65536,8,0),"") | F23: =IFERROR(E23*C23,"") | G23: =IFERROR(F23/$F$66,"")
B24: =IFERROR(VLOOKUP(H24,[1]SEMIELABORADOS!$A$2:$M$6000,2,0),"") | C24: =+A24 -> 0 | D24: =IFERROR(VLOOKUP(H24,[1]SEMIELABORADOS!$A$2:$M$6000,6,0),"") | E24: =IFERROR(VLOOKUP(H24,[1]SEMIELABORADOS!$A$2:$H$65536,8,0),"") | F24: =IFERROR(E24*C24,"") | G24: =IFERROR(F24/$F$66,"")
A26: UNIDADES | B26: EMPAQUE | C26: UNIDADES | D26: UND MEDIDA | E26: COSTO UNITARIO | F26: TOTAL COSTO | G26: % PREC. DEFINIDO | H26: CODIGOS
A27: 25 | B27: BANDEJA HORNEABLE 65X2000 mm | C27: =+A27 -> 25 | D27: Und | E27: 102.42 | F27: =IFERROR(C27*E27,"") -> 2560.5 | G27: =IFERROR(F27/$F$66,"") -> 0.11004181 | H27: 5160008
A28: 2 | B28: =IFERROR(VLOOKUP(H28,'[1]Consolidado MP Planta'!$A$2:$M$823,3,0),"") -> BOLSA TRANSPARENTE 56X96X1.80 KILO | C28: =+A28 -> 2 | D28: =IFERROR(VLOOKUP(H28,'[1]Consolidado MP Planta'!$A$2:$M$823,13,0),"") -> Und | E28: =IFERROR(VLOOKUP(H28,'[1]Consolidado MP Planta'!$A$2:$M$823,12,0),"") -> 50 | F28: =IFERROR(C28*E28,"") -> 100 | G28: =IFERROR(F28/$F$66,"") -> 0.0042976687 | H28: 1950928
A29: 2 | B29: =IFERROR(VLOOKUP(H29,'[1]Consolidado MP Planta'!$A$2:$M$823,3,0),"") -> ETIQ.FECHA VENCIMIENTO BLANCO (ROLLO) | C29: =+A29 -> 2 | D29: =IFERROR(VLOOKUP(H29,'[1]Consolidado MP Planta'!$A$2:$M$823,13,0),"") -> Gramos | E29: =IFERROR(VLOOKUP(H29,'[1]Consolidado MP Planta'!$A$2:$M$823,12,0),"") -> 0.33333333 | F29: =IFERROR(C29*E29,"") -> 0.66666667 | G29: =IFERROR(F29/$F$66,"") -> 2.8651125e-05 | H29: 0702007
B30: =IFERROR(VLOOKUP(H30,'[1]Consolidado MP Planta'!$A$2:$M$823,3,0),"") | C30: =+A30 -> 0 | D30: =IFERROR(VLOOKUP(H30,'[1]Consolidado MP Planta'!$A$2:$M$823,13,0),"") | E30: =IFERROR(VLOOKUP(H30,'[1]Consolidado MP Planta'!$A$2:$M$823,12,0),"") | F30: =IFERROR(C30*E30,"") | G30: =IFERROR(F30/$F$66,"")
B31: =IFERROR(VLOOKUP(H31,'[1]Consolidado MP Planta'!$A$2:$M$823,3,0),"") | C31: =+A31 -> 0 | D31: =IFERROR(VLOOKUP(H31,'[1]Consolidado MP Planta'!$A$2:$M$823,13,0),"") | E31: =IFERROR(VLOOKUP(H31,'[1]Consolidado MP Planta'!$A$2:$M$823,12,0),"") | F31: =IFERROR(C31*E31,"") | G31: =IFERROR(F31/$F$66,"")
B32: =IFERROR(VLOOKUP(H32,'[1]Consolidado MP Planta'!$A$2:$M$823,3,0),"") | C32: =+A32 -> 0 | D32: =IFERROR(VLOOKUP(H32,'[1]Consolidado MP Planta'!$A$2:$M$823,13,0),"") | E32: =IFERROR(VLOOKUP(H32,'[1]Consolidado MP Planta'!$A$2:$M$823,12,0),"") | F32: =IFERROR(C32*E32,"") | G32: =IFERROR(F32/$F$66,"")
A34: UNIDADES | B34: EMPAQUE SEMIELABORADOS | C34: UNIDADES | D34: UND MEDIDA | E34: COSTO UNITARIO | F34: TOTAL COSTO | G34: % PREC. DEFINIDO | H34: CODIGOS
A35: =+A17 -> 10900 | B35: BATIDO P/ROSQUETE ZANAHORIA (10200g) | C35: =+A35 -> 10900 | D35: Gramos | E35: =+'Costo Batido'!E77 -> 0.011448961 | F35: =IFERROR(E35*C35,"") -> 124.79368 | G35: =IFERROR(F35/$F$66,"") -> 0.005363219
A36: =+A18 -> 0 | B36: =IFERROR(VLOOKUP(H36,[1]SEMIELABORADOS!$A$2:$M$6000,2,0),"") | C36: =+A36 -> 0 | D36: =IFERROR(VLOOKUP(H36,[1]SEMIELABORADOS!$A$2:$M$6000,6,0),"") | E36: =IFERROR(VLOOKUP(H36,[1]SEMIELABORADOS!$A$2:$M$65536,10,0),"") | F36: =IFERROR(E36*C36,"") | G36: =IFERROR(F36/$F$66,"")
