Workbook

Sheet Emsamble Industria
C1: SERVICIOS DE PASTELERIA S.A. | H1: CÓDIGO:
C2: ESPECIFICACION DE RECETA | H2: REVISIÓN:
C3: Torta Tutto Baileys Navidad 2024 Spoon | H3: FECHA DE APROBACIÓN:
C4: Elaborado | D4: Jose Brizuela, chef
C5: Aprobado | D5: Esteban Cartin, Gte Manufactura
A6: AREA QUE PRODUCE: | D6: Decoracion | G6: AREA QUE EMPACA: | I6: Decoracion
A7: # Código | B7: # Codigo Netsuite | C7: Descripción del ingrediente | D7: Marca | E7: Unidad Internacional | G7: Medida alternativa | I7: Costo - Referencia
E8: Cantidad | F8: Unidad medida | G8: Cantidad | H8: Unidad medida | I8: Colones
C10: EMSABLE
C11: Rosquette Melo 400 g | D11: FAS | E11: 340 | F11: g | I11: Partido a la mitad
C13: Relleno
A14: 910000007 | B14: SE00084 | C14: Mezcla Tres Leches C/Baileys | D14: FAS | E14: 70 | F14: g | I14: 1/3 Taza por capa
A15: 908000048 | B15: SE00087 | C15: Ganache Baileys | D15: FAS | E15: 100 | F15: g | I15: 1/3 Taza
A16: 902000168 | B16: SE00468 | C16: Mousse Chocolate de Leche | D16: FAS | E16: 230 | F16: g | I16: 1 taza y media
A17: 902000167 | B17: SE00467 | C17: Caramelo Crocante Bañado chocolate De Leche | D17: FAS | E17: 86 | F17: g | I17: 1/2 Taza
C18: Decoracion
A19: 910000018 | B19: SE00069 | C19: Crema Beidge | D19: FAS | E19: 150 | F19: g | I19: Encremado
A20: 910000018 | B20: SE00069 | C20: Crema Beidge | D20: FAS | E20: 120 | F20: g | H20: Decorado | I20: Boquilla 127 Wilton
A21: 20100163 | B21: SE00337 | C21: Empaque Fudge De Chocolate | D21: FAS | E21: 130 | F21: g | H21: Decorado | I21: Boquilla 127 Wilton
C22: Monedas Color Rojo Navidad Chocolate 7,5 | E22: 8 | F22: g | G22: 1 | H22: unidad
C23: Moneda Color Dorada Chocolate 7,5 | E23: 8 | F23: g | G23: 1 | H23: unidad
C24: Moneda Color Dorada Chocolate 5,5 | E24: 6 | F24: g | G24: 2 | H24: unidad
C25: Moneda Color Rojo NavidaChocolate 5,5 | E25: 6 | F25: g | G25: 2 | H25: unidad
C27: Empaque
A29: 121603 | B29: EM10009 | C29: QUEQUERA RED BASE/DOMO 10 (CAJA:50) | D29: MAYCA | E29: 1 | F29: ud
A30: 1950692 | B30: EM10008 | C30: ORLA CARTON 10" DORADA UND | D30: Mayca | E30: 1 | F30: Ud
A31: 702069 | B31: EM10002 | C31: Etiq.Blanca 1 1/4 * 3/4 | D31: ETIPLAST | E31: 1 | F31: ud
A32: 0703020 | B32: EM10248 | C32: CINTA ADHESIVA TRANSPARENTE 2*100 | D32: Mayca | E32: 60 | F32: cm
A33: 701096 | B33: EM10124 | C33: ETIQUETA BLANCA R-153 | D33: Cemusa | E33: 1 | F33: ud
A34: 0702123 | B34: EM10011 | C34: ETIQUETA BLANCA 2 5/8X1 15/16 PRE BLANCA | D34: Etiplast | E34: 1 | F34: ud
A35: 60100120 | B35: EM10314 | C35: Etiqueta Edicion Especial | D35: ETIPLAST | E35: 1 | F35: ud
D37: Cantidad | E37: Unidad
A38: PESO TOTAL OBTENIDO | D38: 1200 | E38: g | F38: Tiempo de Horneo:
A39: TIEMPO TOTAL DE PREPARACION | D39: 5 | E39: min | F39: Horno:
A40: CANTIDAD DE PORCIONES OBTENIDAS | D40: =D38/D41 -> 1 | E40: ud | F40: Temperatura de Horneo:
A41: PESO DE CADA PORCIÓN | D41: 1200 | E41: g | F41: Otros
A42: MERMA | D42: =SUM(E10:E25)-D38 -> 54 | E42: g
A43: PROCEDIMIENTO DE PREPARACION DE LA RECETA
A44: 1-Colocar (un) Rosquete entero
A45: 2,Rellenar con leche condensada cocinada y Agregarle al Rosquete y Exparsir bien en el Rosquete a su centro y costado,y agregar la galleta con chocolate
...

Sheet Ensamble Industria 2
C1: SERVICIOS DE PASTELERIA S.A. | H1: CÓDIGO:
C2: ESPECIFICACION DE RECETA | H2: REVISIÓN:
C3: Torta Tutto Baileys Navidad 2024 Spoon | H3: FECHA DE APROBACIÓN:
C4: Elaborado | D4: Jose Brizuela, chef
C5: Aprobado | D5: Esteban Cartin, Gte Manufactura
A6: AREA QUE PRODUCE: | D6: Decoracion | G6: AREA QUE EMPACA: | I6: Decoracion
A7: # Código | B7: # Codigo Netsuite | C7: Descripción del ingrediente | D7: Marca | E7: Unidad Internacional | G7: Medida alternativa | I7: Costo - Referencia
E8: Cantidad | F8: Unidad medida | G8: Cantidad | H8: Unidad medida | I8: Colones
C10: EMSABLE
C11: Rosquette Melo 400 g | D11: FAS | E11: 340 | F11: g | I11: Partido a la mitad
C13: Relleno
A14: 910000007 | B14: SE00084 | C14: Mezcla Tres Leches C/Baileys | D14: FAS | E14: 70 | F14: g | I14: 1/3 Taza por capa
A15: 908000048 | B15: SE00087 | C15: Ganache Baileys | D15: FAS | E15: 100 | F15: g | I15: 1/3 Taza
A16: 902000168 | B16: SE00468 | C16: Mousse Chocolate de Leche | D16: FAS | E16: 230 | F16: g | I16: 1 taza y media
A17: 902000167 | B17: SE00467 | C17: Caramelo Crocante Bañado chocolate De Leche | D17: FAS | E17: 86 | F17: g | I17: 1/2 Taza
C18: Decoracion
A19: 910000018 | B19: SE00069 | C19: Crema Beidge | D19: FAS | E19: 150 | F19: g | I19: Encremado
A20: 910000018 | B20: SE00069 | C20: Crema Beidge | D20: FAS | E20: 120 | F20: g | H20: Decorado | I20: Boquilla 127 Wilton
A21: 20100163 | B21: SE00337 | C21: Empaque Fudge De Chocolate | D21: FAS | E21: 130 | F21: g | H21: Decorado | I21: Boquilla 127 Wilton
C22: Monedas Color Rojo Navidad Chocolate 7,5 | E22: 8 | F22: g | G22: 1 | H22: unidad
C23: Moneda Color Dorada Chocolate 7,5 | E23: 8 | F23: g | G23: 1 | H23: unidad
C24: Moneda Color Dorada Chocolate 5,5 | E24: 6 | F24: g | G24: 2 | H24: unidad
C25: Moneda Color Rojo NavidaChocolate 5,5 | E25: 6 | F25: g | G25: 2 | H25: unidad
C26: Barra de Tutto Baileys | E26: 42 | F26: g | H26: 5 cabos de 2 unidades | I26: 1 tableta x torta
C27: Empaque
A29: 121603 | B29: EM10009 | C29: QUEQUERA RED BASE/DOMO 10 (CAJA:50) | D29: MAYCA | E29: 1 | F29: ud
A30: 1950692 | B30: EM10008 | C30: ORLA CARTON 10" DORADA UND | D30: Mayca | E30: 1 | F30: Ud
A31: 702069 | B31: EM10002 | C31: Etiq.Blanca 1 1/4 * 3/4 | D31: ETIPLAST | E31: 1 | F31: ud
A32: 0703020 | B32: EM10248 | C32: CINTA ADHESIVA TRANSPARENTE 2*100 | D32: Mayca | E32: 60 | F32: cm
A33: 701096 | B33: EM10124 | C33: ETIQUETA BLANCA R-153 | D33: Cemusa | E33: 1 | F33: ud
A34: 0702123 | B34: EM10011 | C34: ETIQUETA BLANCA 2 5/8X1 15/16 PRE BLANCA | D34: Etiplast | E34: 1 | F34: ud
A35: 60100120 | B35: EM10314 | C35: Etiqueta Edicion Especial | D35: ETIPLAST | E35: 1 | F35: ud
D37: Cantidad | E37: Unidad
A38: PESO TOTAL OBTENIDO | D38: 1200 | E38: g | F38: Tiempo de Horneo:
A39: TIEMPO TOTAL DE PREPARACION | D39: 5 | E39: min | F39: Horno:
A40: CANTIDAD DE PORCIONES OBTENIDAS | D40: 1 | E40: ud | F40: Temperatura de Horneo:
A41: PESO DE CADA PORCIÓN | D41: 1200 | E41: g | F41: Otros
A42: MERMA | D42: 54 | E42: g
A43: PROCEDIMIENTO DE PREPARACION DE LA RECETA
A44: 1-Colocar la mitad del Rosquete
...

Sheet Hoja1
C1: SERVICIOS DE PASTELERIA S.A. | H1: CÓDIGO: | I1: ESP-RE-DES-053
C2: ESPECIFICACION DE RECETA | H2: REVISIÓN: | I2: 01
C3: PTI00231 Torta Tutto Baileys 1200 g AM PM / Fresh | H3: FECHA DE APROBACIÓN: | I3: 45618
C4: Elaborado | D4: Javier Tong, Chef
C5: Aprobado | D5: Esteban Cartin, Gte Manufactura
A6: AREA QUE PRODUCE: | D6: Decoración | G6: AREA QUE EMPACA: | I6: Decoración
A7: # Código | B7: # Código Netsuite | C7: Descripción del ingrediente | D7: Marca | E7: Unidad Internacional | G7: Medida alternativa | I7: Costo - Referencia
E8: Cantidad | F8: Unidad medida | G8: Cantidad | H8: Unidad medida | I8: Colones
C9: Ensamble
B10: SE00655 | C10: ROSQUETE NUCLEO VAINILLA DAWN REDONDO 450 G | D10: FAS | E10: 420 | F10: g | H10: 1 UND
C12: RELLENO
A13: 910000007 | B13: SE00084 | C13: MEZCLA TRES LECHES C/BAILEYS | D13: FAS | E13: 160 | F13: g | H13: 80 GRAMOS CAPA
A14: 908000048 | B14: SE00087 | C14: GANACHE BAILEYS | D14: FAS | E14: 100 | F14: g | H14: 1/2 TAZA
A15: 902000168 | B15: SE00468 | C15: MOUSSE CHOCOLATE DE LECHE | D15: FAS | E15: 270 | F15: g | H15: 1 TAZA + 1/2 TAZA
A16: 902000167 | B16: SE00467 | C16: CARAMELO CROCANTE BAÑADO CHOCOLATE DE LECHE | D16: FAS | E16: 50 | F16: g | H16: 1/3 TAZA
C20: Decoración
A21: 910000018 | B21: SE00069 | C21: Crema Beidge | D21: FAS | E21: 150 | F21: g | H21: ENCREMAR
A22: 20100163 | B22: SE00337 | C22: Empaque Fudge De Chocolate | D22: FAS | E22: 130 | F22: g | H22: COLOCHO BOQUILLA 127
B23: MP10724 | C23: Moneda Color Dorada Chocolate 5,5 | E23: 9 | F23: g | H23: 3 UND
B24: MP10725 | C24: Moneda Color Rojo NavidaChocolate 5,5 | E24: 6 | F24: g | H24: 2 UND
B25: MP10720 | C25: Barra de Tutto Baileys | E25: 42 | F25: g | H25: 1 TABLETA
C27: Empaque
A28: 121603 | B28: EM10009 | C28: QUEQUERA RED BASE/DOMO 10 (CAJA:50) | D28: MAYCA | E28: 1 | F28: ud
A29: 1950692 | B29: EM10008 | C29: ORLA CARTON 10" DORADA UND | D29: MAYCA | E29: 1 | F29: Ud
A30: 702069 | B30: EM10002 | C30: ETIQ.BLANCA 1 1/4 * 3/4 | D30: ETIPLAST | E30: 1 | F30: ud
A31: 0703020 | B31: EM10248 | C31: CINTA ADHESIVA TRANSPARENTE 2*100 | D31: MAYCA | E31: 60 | F31: cm
A32: 701096 | B32: EM10124 | C32: ETIQUETA BLANCA R-153 | D32: CEMUSA | E32: 1 | F32: ud
A33: 0702123 | B33: EM10011 | C33: ETIQUETA BLANCA 2 5/8X1 15/16 PRE BLANCA | D33: ETIPLAST | E33: 1 | F33: ud
B34: EM10408 | C34: ETIQUETA NAVIDAD TUTTO BAILEYS | D34: ETIPLAST | E34: 1 | F34: ud
B35: EM10296 | C35: STICKER AZUL | E35: 1 | F35: ud
D37: Cantidad | E37: Unidad
A38: PESO TOTAL OBTENIDO | D38: 1200 | E38: g | F38: Tiempo de Horneo:
A39: TIEMPO TOTAL DE PREPARACION | D39: 5 | E39: min | F39: Horno:
A40: CANTIDAD DE PORCIONES OBTENIDAS | D40: 1 | E40: ud | F40: Temperatura de Horneo:
A41: PESO DE CADA PORCIÓN | D41: 1200 | E41: g | F41: Otros
A42: MERMA | D42: 54 | E42: g
A43: PROCEDIMIENTO DE PREPARACION DE LA RECETA
A44: 1. Partir el Rosquette a la mitad
A45: 2. Bañar con la leche de Baileys cada tapa del rosquete
A46: 3. Colocar el Ganache de Baileys
...

Sheet Costo Ensamble Industria 
E1: Precio Local | F1: Costo MP | G1: Costo EM | H1: Costo MO
E2: =IFERROR(O62,"") -> 7225.2357 | F2: =IFERROR(H53,"") -> 4940.4562 | G2: =IFERROR(H54,"") -> 652.4945 | H2: =IFERROR(H56,"") -> 836.7175
A5: ESTRUCTURA DE COSTOS
F6: Fecha: | H6: =TODAY() -> 45741
A7: UNIDADES | B7: DESCRIPCION MAT.PRIMA | C7: UNIDADES | D7: UND MEDIDA | E7: COSTO UNITARIO | F7: TOTAL COSTO | G7: % PREC. DEFINIDO | H7: CODIGOS
A8: 0 | B8: Monedas Color Rojo Navidad Chocolate 7,5 | C8: =+A8 -> 0 | D8: UND | E8: 352 | F8: =IFERROR(C8*E8,"") -> 0 | G8: =IFERROR(F8/$F$66,"") -> 0
A9: 0 | B9: Moneda Color Dorada Chocolate 7,5 | C9: =+A9 -> 0 | D9: UND | E9: 352 | F9: =IFERROR(C9*E9,"") -> 0 | G9: =IFERROR(F9/$F$66,"") -> 0
A10: 3 | B10: Moneda Color Dorada Chocolate 5,5 | C10: =+A10 -> 3 | D10: UND | E10: 85 | F10: =IFERROR(C10*E10,"") -> 255 | G10: =IFERROR(F10/$F$66,"") -> 0.042522963
A11: 2 | B11: Moneda Color Rojo NavidaChocolate 5,5 | C11: =+A11 -> 2 | D11: UND | E11: 85 | F11: =IFERROR(C11*E11,"") -> 170 | G11: =IFERROR(F11/$F$66,"") -> 0.028348642
A12: 1 | B12: Barra de Tutto Baileys | C12: =+A12 -> 1 | D12: UND | E12: 413 | F12: =IFERROR(C12*E12,"") -> 413 | G12: =IFERROR(F12/$F$66,"") -> 0.068870525
A13: 20 | B13: =IFERROR(VLOOKUP(H13,'[1]Consolidado MP Planta'!$A$2:$M$823,3,0),"") -> CREMA BETTERCREAM DOBLE CHOCO (UND:4 K) | C13: =+A13 -> 20 | D13: =IFERROR(VLOOKUP(H13,'[1]Consolidado MP Planta'!$A$2:$M$823,13,0),"") -> Gramos | E13: 2.5 | F13: =IFERROR(C13*E13,"") -> 50 | G13: =IFERROR(F13/$F$66,"") -> 0.0083378359 | H13: 11400027
B14: =IFERROR(VLOOKUP(H14,'[1]Consolidado MP Planta'!$A$2:$M$823,3,0),"") | C14: =+A14 -> 0 | D14: =IFERROR(VLOOKUP(H14,'[1]Consolidado MP Planta'!$A$2:$M$823,13,0),"") | E14: =IFERROR(VLOOKUP(H14,'[1]Consolidado MP Planta'!$A$2:$M$823,12,0),"") | F14: =IFERROR(C14*E14,"") | G14: =IFERROR(F14/$F$66,"")
B15: =IFERROR(VLOOKUP(H15,'[2]ARTICULOS MP PLANTA'!$A$2:$G$589,2,0),"")
A16: UNIDADES | B16: MATERIA PRIMA SEMIELABORADOS | C16: UNIDADES | D16: UND MEDIDA | E16: COSTO UNITARIO | F16: TOTAL COSTO | G16: % PREC. DEFINIDO | H16: CODIGOS
A17: 1 | B17: Rosquette Melo 450 g | C17: =+A17 -> 1 | D17: UND | E17: =+'Costo Rosquete 450'!H53 -> 837.35625 | F17: =IFERROR(E17*C17,"") -> 837.35625 | G17: =IFERROR(F17/$F$66,"") -> 0.13963478
A18: 160 | B18: =IFERROR(VLOOKUP(H18,[1]SEMIELABORADOS!$A$2:$M$6000,2,0),"") -> MEZCLA TRES LECHES C/BAILEYS LITRO | C18: =+A18 -> 160 | D18: =IFERROR(VLOOKUP(H18,[1]SEMIELABORADOS!$A$2:$M$6000,6,0),"") -> Gramo | E18: 7.9 | F18: =IFERROR(E18*C18,"") -> 1264 | G18: =IFERROR(F18/$F$66,"") -> 0.21078049 | H18: 910000007
A19: 100 | B19: =IFERROR(VLOOKUP(H19,[1]SEMIELABORADOS!$A$2:$M$6000,2,0),"") -> GANACHE BAILEYS (KILO) | C19: =+A19 -> 100 | D19: =IFERROR(VLOOKUP(H19,[1]SEMIELABORADOS!$A$2:$M$6000,6,0),"") -> Gramo | E19: 4.88 | F19: =IFERROR(E19*C19,"") -> 488 | G19: =IFERROR(F19/$F$66,"") -> 0.081377279 | H19: 908000048
A20: 230 | B20: Mousse Chocolate de Leche | C20: =+A20 -> 230 | D20: Gramo | E20: 2.94 | F20: =IFERROR(E20*C20,"") -> 676.2 | G20: =IFERROR(F20/$F$66,"") -> 0.11276089 | H20: 902000168
A21: 50 | B21: Caramelo Crocante Bañado chocolate De Leche | C21: =+A21 -> 50 | D21: Gramo | E21: 2.7 | F21: =IFERROR(E21*C21,"") -> 135 | G21: =IFERROR(F21/$F$66,"") -> 0.022512157 | H21: 902000167
A22: 150 | B22: =IFERROR(VLOOKUP(H22,[1]SEMIELABORADOS!$A$2:$M$6000,2,0),"") -> CREMA BEIDGE (KILO) | C22: =+A22 -> 150 | D22: =IFERROR(VLOOKUP(H22,[1]SEMIELABORADOS!$A$2:$M$6000,6,0),"") -> Gramo | E22: 2.24 | F22: =IFERROR(E22*C22,"") -> 336 | G22: =IFERROR(F22/$F$66,"") -> 0.056030258 | H22: 910000018
A23: 130 | B23: Empaque Fudge De Chocolate | C23: =+A23 -> 130 | D23: Gramo | E23: 2.43 | F23: =IFERROR(E23*C23,"") -> 315.9 | G23: =IFERROR(F23/$F$66,"") -> 0.052678447 | H23: 20100163
B24: =IFERROR(VLOOKUP(H24,[1]SEMIELABORADOS!$A$2:$M$6000,2,0),"") | C24: =+A24 -> 0 | D24: =IFERROR(VLOOKUP(H24,[1]SEMIELABORADOS!$A$2:$M$6000,6,0),"") | E24: =IFERROR(VLOOKUP(H24,[1]SEMIELABORADOS!$A$2:$H$65536,8,0),"") | F24: =IFERROR(E24*C24,"") | G24: =IFERROR(F24/$F$66,"")
A26: UNIDADES | B26: EMPAQUE | C26: UNIDADES | D26: UND MEDIDA | E26: COSTO UNITARIO | F26: TOTAL COSTO | G26: % PREC. DEFINIDO | H26: CODIGOS
A27: 1 | B27: =IFERROR(VLOOKUP(H27,'[1]Consolidado MP Planta'!$A$2:$M$823,3,0),"") -> QUEQUERA RED BASE/DOMO 10 (CAJA:50) | C27: =+A27 -> 1 | D27: =IFERROR(VLOOKUP(H27,'[1]Consolidado MP Planta'!$A$2:$M$823,13,0),"") -> UND | E27: 346 | F27: =IFERROR(C27*E27,"") -> 346 | G27: =IFERROR(F27/$F$66,"") -> 0.057697825 | H27: 121603
A28: 1 | B28: =IFERROR(VLOOKUP(H28,'[1]Consolidado MP Planta'!$A$2:$M$823,3,0),"") -> ORLA CARTON 10" DORADA (UND) | C28: =+A28 -> 1 | D28: =IFERROR(VLOOKUP(H28,'[1]Consolidado MP Planta'!$A$2:$M$823,13,0),"") -> Und | E28: 117 | F28: =IFERROR(C28*E28,"") -> 117 | G28: =IFERROR(F28/$F$66,"") -> 0.019510536 | H28: 1950692
A29: 1 | B29: =IFERROR(VLOOKUP(H29,'[1]Consolidado MP Planta'!$A$2:$M$823,3,0),"") -> ETIQ.BLANCA 1 1/4 * 3/4 (UND) | C29: =+A29 -> 1 | D29: =IFERROR(VLOOKUP(H29,'[1]Consolidado MP Planta'!$A$2:$M$823,13,0),"") -> Und | E29: =IFERROR(VLOOKUP(H29,'[1]Consolidado MP Planta'!$A$2:$M$823,12,0),"") -> 0.58 | F29: =IFERROR(C29*E29,"") -> 0.58 | G29: =IFERROR(F29/$F$66,"") -> 9.6718897e-05 | H29: 0702069
A30: 1 | B30: =IFERROR(VLOOKUP(H30,'[1]Consolidado MP Planta'!$A$2:$M$823,3,0),"") -> ETIQUETA BLANCA R-153 (UND) | C30: =+A30 -> 1 | D30: =IFERROR(VLOOKUP(H30,'[1]Consolidado MP Planta'!$A$2:$M$823,13,0),"") -> Und | E30: =IFERROR(VLOOKUP(H30,'[1]Consolidado MP Planta'!$A$2:$M$823,12,0),"") -> 0.39 | F30: =IFERROR(C30*E30,"") -> 0.39 | G30: =IFERROR(F30/$F$66,"") -> 6.503512e-05 | H30: 701096
A31: 1 | B31: =IFERROR(VLOOKUP(H31,'[1]Consolidado MP Planta'!$A$2:$M$823,3,0),"") -> ETIQUETA BLANCA 2 5/8X1 15/16 (UND) | C31: =+A31 -> 1 | D31: =IFERROR(VLOOKUP(H31,'[1]Consolidado MP Planta'!$A$2:$M$823,13,0),"") -> Und | E31: =IFERROR(VLOOKUP(H31,'[1]Consolidado MP Planta'!$A$2:$M$823,12,0),"") -> 2.128 | F31: =IFERROR(C31*E31,"") -> 2.128 | G31: =IFERROR(F31/$F$66,"") -> 0.0003548583 | H31: 0702123
A32: 1 | B32: Etiqueta Edicion Especial | C32: =+A32 -> 1 | D32: UND | E32: 110 | F32: =IFERROR(C32*E32,"") -> 110 | G32: =IFERROR(F32/$F$66,"") -> 0.018343239 | H32: 60100120
A34: UNIDADES | B34: EMPAQUE SEMIELABORADOS | C34: UNIDADES | D34: UND MEDIDA | E34: COSTO UNITARIO | F34: TOTAL COSTO | G34: % PREC. DEFINIDO | H34: CODIGOS
A35: =+A17 -> 1 | B35: Rosquette Melo 450 g | C35: =+A35 -> 1 | D35: UND | E35: =+'Costo Rosquete 450'!H54 -> 10.3815 | F35: =IFERROR(E35*C35,"") -> 10.3815 | G35: =IFERROR(F35/$F$66,"") -> 0.0017311849
A36: =+A18 -> 160 | B36: =IFERROR(VLOOKUP(H36,[1]SEMIELABORADOS!$A$2:$M$6000,2,0),"") -> MEZCLA TRES LECHES C/BAILEYS LITRO | C36: =+A36 -> 160 | D36: =IFERROR(VLOOKUP(H36,[1]SEMIELABORADOS!$A$2:$M$6000,6,0),"") -> Gramo | E36: 0 | F36: =IFERROR(E36*C36,"") -> 0 | G36: =IFERROR(F36/$F$66,"") -> 0 | H36: 910000007
A37: =+A19 -> 100 | B37: =IFERROR(VLOOKUP(H37,[1]SEMIELABORADOS!$A$2:$M$6000,2,0),"") -> GANACHE BAILEYS (KILO) | C37: =+A37 -> 100 | D37: =IFERROR(VLOOKUP(H37,[1]SEMIELABORADOS!$A$2:$M$6000,6,0),"") -> Gramo | E37: 0.02 | F37: =IFERROR(E37*C37,"") -> 2 | G37: =IFERROR(F37/$F$66,"") -> 0.00033351344 | H37: 908000048
A38: =+A20 -> 230 | B38: Mousse Chocolate de Leche | C38: =+A38 -> 230 | D38: Gramo | E38: 0.09 | F38: =IFERROR(E38*C38,"") -> 20.7 | G38: =IFERROR(F38/$F$66,"") -> 0.0034518641 | H38: 902000168
A39: =+A21 -> 50 | B39: Caramelo Crocante Bañado chocolate De Leche | C39: =+A39 -> 50 | D39: Gramo | E39: 0.84 | F39: =IFERROR(E39*C39,"") -> 42 | G39: =IFERROR(F39/$F$66,"") -> 0.0070037822 | H39: 902000167
A40: =+A22 -> 150 | B40: =IFERROR(VLOOKUP(H40,[1]SEMIELABORADOS!$A$2:$M$6000,2,0),"") -> CREMA BEIDGE (KILO) | C40: =+A40 -> 150 | D40: =IFERROR(VLOOKUP(H40,[1]SEMIELABORADOS!$A$2:$M$6000,6,0),"") -> Gramo | E40: 0.0001 | F40: =IFERROR(E40*C40,"") -> 0.015 | G40: =IFERROR(F40/$F$66,"") -> 2.5013508e-06 | H40: 910000018
A41: =+A23 -> 130 | B41: Empaque Fudge De Chocolate | C41: =+A41 -> 130 | D41: gramo | E41: 0.01 | F41: =IFERROR(E41*C41,"") -> 1.3 | G41: =IFERROR(F41/$F$66,"") -> 0.00021678373 | H41: 20100163
A43: UNIDADES | B43: MODI | C43: UNIDADES | D43: UND MEDIDA | E43: COSTO UNITARIO | F43: TOTAL COSTO | G43: % PREC. DEFINIDO | H43: CODIGOS
A44: =+A35 -> 1 | B44: Rosquette Melo 450 g | C44: =+A44 -> 1 | D44: UND | E44: =+'Costo Rosquete 450'!H56 -> 31.1175 | F44: =IFERROR(E44*C44,"") -> 31.1175 | G44: =IFERROR(F44/$F$66,"") -> 0.0051890522
A45: =+A36 -> 160 | B45: =IFERROR(VLOOKUP(H45,[1]SEMIELABORADOS!$A$2:$M$6000,2,0),"") -> MEZCLA TRES LECHES C/BAILEYS LITRO | C45: =+A45 -> 160 | D45: =IFERROR(VLOOKUP(H45,[1]SEMIELABORADOS!$A$2:$M$6000,6,0),"") -> Gramo | E45: 1.39 | F45: =IFERROR(E45*C45,"") -> 222.4 | G45: =IFERROR(F45/$F$66,"") -> 0.037086694 | H45: 910000007
...

Sheet Emsamble Locales
C1: SERVICIOS DE PASTELERIA S.A. | H1: CÓDIGO:
C2: ESPECIFICACION DE RECETA | H2: REVISIÓN:
C3: Torta Tutto Baileys Navidad 2024 Spoon | H3: FECHA DE APROBACIÓN:
C4: Elaborado | D4: Jose Brizuela, chef
C5: Aprobado | D5: Esteban Cartin, Gte Manufactura
A6: AREA QUE PRODUCE: | D6: Decoracion | G6: AREA QUE EMPACA: | I6: Decoracion
A7: # Código | B7: # Codigo Netsuite | C7: Descripción del ingrediente | D7: Marca | E7: Unidad Internacional | G7: Medida alternativa | I7: Costo - Referencia
E8: Cantidad | F8: Unidad medida | G8: Cantidad | H8: Unidad medida | I8: Colones
C10: EMSABLE
C11: Rosquette Melo 400 g | D11: FAS | E11: 340 | F11: g | I11: Partido a la mitad
C13: Relleno
A14: 910000007 | B14: SE00084 | C14: Mezcla Tres Leches C/Baileys | D14: FAS | E14: 70 | F14: g | I14: 1/3 Taza por capa
A15: 908000048 | B15: SE00087 | C15: Ganache Baileys | D15: FAS | E15: 100 | F15: g | I15: 1/3 Taza
A16: 902000168 | B16: SE00468 | C16: Mousse Chocolate de Leche | D16: FAS | E16: 230 | F16: g | I16: 1 taza y media
A17: 902000167 | B17: SE00467 | C17: Caramelo Crocante Bañado chocolate De Leche | D17: FAS | E17: 86 | F17: g | I17: 1/2 Taza
C18: Decoracion
A19: 910000018 | B19: SE00069 | C19: Crema Beidge | D19: FAS | E19: 150 | F19: g | I19: Encremado
A20: 910000018 | B20: SE00069 | C20: Crema Beidge | D20: FAS | E20: 120 | F20: g | H20: Decorado | I20: Boquilla 127 Wilton
A21: 20100163 | B21: SE00337 | C21: Empaque Fudge De Chocolate | D21: FAS | E21: 130 | F21: g | H21: Decorado | I21: Boquilla 127 Wilton
C22: Monedas Color Rojo Navidad Chocolate 7,5 | E22: 8 | F22: g | G22: 1 | H22: unidad
C23: Moneda Color Dorada Chocolate 7,5 | E23: 8 | F23: g | G23: 1 | H23: unidad
C24: Moneda Color Dorada Chocolate 5,5 | E24: 6 | F24: g | G24: 2 | H24: unidad
C25: Moneda Color Rojo NavidaChocolate 5,5 | E25: 6 | F25: g | G25: 2 | H25: unidad
C27: Empaque
A29: 121603 | B29: EM10009 | C29: QUEQUERA RED BASE/DOMO 10 (CAJA:50) | D29: MAYCA | E29: 1 | F29: ud
A30: 1950692 | B30: EM10008 | C30: ORLA CARTON 10" DORADA UND | D30: Mayca | E30: 1 | F30: Ud
A31: 702069 | B31: EM10002 | C31: Etiq.Blanca 1 1/4 * 3/4 | D31: ETIPLAST | E31: 1 | F31: ud
A32: 0703020 | B32: EM10248 | C32: CINTA ADHESIVA TRANSPARENTE 2*100 | D32: Mayca | E32: 60 | F32: cm
A33: 701096 | B33: EM10124 | C33: ETIQUETA BLANCA R-153 | D33: Cemusa | E33: 1 | F33: ud
A34: 0702123 | B34: EM10011 | C34: ETIQUETA BLANCA 2 5/8X1 15/16 PRE BLANCA | D34: Etiplast | E34: 1 | F34: ud
A35: 60100120 | B35: EM10314 | C35: Etiqueta Edicion Especial | D35: ETIPLAST | E35: 1 | F35: ud
D37: Cantidad | E37: Unidad
A38: PESO TOTAL OBTENIDO | D38: 1200 | E38: g | F38: Tiempo de Horneo:
A39: TIEMPO TOTAL DE PREPARACION | D39: 5 | E39: min | F39: Horno:
A40: CANTIDAD DE PORCIONES OBTENIDAS | D40: =D38/D41 -> 1 | E40: ud | F40: Temperatura de Horneo:
A41: PESO DE CADA PORCIÓN | D41: 1200 | E41: g | F41: Otros
A42: MERMA | D42: =SUM(E10:E25)-D38 -> 54 | E42: g
A43: PROCEDIMIENTO DE PREPARACION DE LA RECETA
A44: 1-Colocar (un) Rosquete entero
A45: 2,Rellenar con leche condensada cocinada y Agregarle al Rosquete y Exparsir bien en el Rosquete a su centro y costado,y agregar la galleta con chocolate
...

Sheet Ensamble locales 2
C1: SERVICIOS DE PASTELERIA S.A. | H1: CÓDIGO:
C2: ESPECIFICACION DE RECETA | H2: REVISIÓN:
C3: Torta Tutto Baileys Navidad 2024 Spoon | H3: FECHA DE APROBACIÓN:
C4: Elaborado | D4: Jose Brizuela, chef
C5: Aprobado | D5: Esteban Cartin, Gte Manufactura
A6: AREA QUE PRODUCE: | D6: Decoracion | G6: AREA QUE EMPACA: | I6: Decoracion
A7: # Código | B7: # Codigo Netsuite | C7: Descripción del ingrediente | D7: Marca | E7: Unidad Internacional | G7: Medida alternativa | I7: Costo - Referencia
E8: Cantidad | F8: Unidad medida | G8: Cantidad | H8: Unidad medida | I8: Colones
C10: EMSABLE
C11: Rosquette Melo 400 g | D11: FAS | E11: 340 | F11: g | I11: Partido a la mitad
C13: Relleno
A14: 910000007 | B14: SE00084 | C14: Mezcla Tres Leches C/Baileys | D14: FAS | E14: 70 | F14: g | I14: 1/3 Taza por capa
A15: 908000048 | B15: SE00087 | C15: Ganache Baileys | D15: FAS | E15: 100 | F15: g | I15: 1/3 Taza
A16: 902000168 | B16: SE00468 | C16: Mousse Chocolate de Leche | D16: FAS | E16: 230 | F16: g | I16: 1 taza y media
A17: 902000167 | B17: SE00467 | C17: Caramelo Crocante Bañado chocolate De Leche | D17: FAS | E17: 86 | F17: g | I17: 1/2 Taza
C18: Decoracion
A19: 910000018 | B19: SE00069 | C19: Crema Beidge | D19: FAS | E19: 150 | F19: g | I19: Encremado
A20: 910000018 | B20: SE00069 | C20: Crema Beidge | D20: FAS | E20: 120 | F20: g | H20: Decorado | I20: Boquilla 127 Wilton
A21: 20100163 | B21: SE00337 | C21: Empaque Fudge De Chocolate | D21: FAS | E21: 130 | F21: g | H21: Decorado | I21: Boquilla 127 Wilton
C22: Monedas Color Rojo Navidad Chocolate 7,5 | E22: 8 | F22: g | G22: 1 | H22: unidad
C23: Moneda Color Dorada Chocolate 7,5 | E23: 8 | F23: g | G23: 1 | H23: unidad
C24: Moneda Color Dorada Chocolate 5,5 | E24: 6 | F24: g | G24: 2 | H24: unidad
C25: Moneda Color Rojo NavidaChocolate 5,5 | E25: 6 | F25: g | G25: 2 | H25: unidad
C26: Barra de Tutto Baileys | E26: 42 | F26: g | H26: 5 cabos de 2 unidades | I26: 1 tableta x torta
C27: Empaque
A29: 121603 | B29: EM10009 | C29: QUEQUERA RED BASE/DOMO 10 (CAJA:50) | D29: MAYCA | E29: 1 | F29: ud
A30: 1950692 | B30: EM10008 | C30: ORLA CARTON 10" DORADA UND | D30: Mayca | E30: 1 | F30: Ud
A31: 702069 | B31: EM10002 | C31: Etiq.Blanca 1 1/4 * 3/4 | D31: ETIPLAST | E31: 1 | F31: ud
A32: 0703020 | B32: EM10248 | C32: CINTA ADHESIVA TRANSPARENTE 2*100 | D32: Mayca | E32: 60 | F32: cm
A33: 701096 | B33: EM10124 | C33: ETIQUETA BLANCA R-153 | D33: Cemusa | E33: 1 | F33: ud
A34: 0702123 | B34: EM10011 | C34: ETIQUETA BLANCA 2 5/8X1 15/16 PRE BLANCA | D34: Etiplast | E34: 1 | F34: ud
A35: 60100120 | B35: EM10314 | C35: Etiqueta Edicion Especial | D35: ETIPLAST | E35: 1 | F35: ud
D37: Cantidad | E37: Unidad
A38: PESO TOTAL OBTENIDO | D38: 1200 | E38: g | F38: Tiempo de Horneo:
A39: TIEMPO TOTAL DE PREPARACION | D39: 5 | E39: min | F39: Horno:
A40: CANTIDAD DE PORCIONES OBTENIDAS | D40: 1 | E40: ud | F40: Temperatura de Horneo:
A41: PESO DE CADA PORCIÓN | D41: 1200 | E41: g | F41: Otros
A42: MERMA | D42: 54 | E42: g
A43: PROCEDIMIENTO DE PREPARACION DE LA RECETA
A44: 1-Colocar la mitad del Rosquete
...

Sheet Ensamble locales 3
C1: SERVICIOS DE PASTELERIA S.A. | H1: CÓDIGO:
C2: ESPECIFICACION DE RECETA | H2: REVISIÓN:
C3: Torta Tutto Baileys Navidad 2024 Spoon | H3: FECHA DE APROBACIÓN:
C4: Elaborado | D4: Jose Brizuela, chef
C5: Aprobado | D5: Esteban Cartin, Gte Manufactura
A6: AREA QUE PRODUCE: | D6: Decoracion | G6: AREA QUE EMPACA: | I6: Decoracion
A7: # Código | B7: # Codigo Netsuite | C7: Descripción del ingrediente | D7: Marca | E7: Unidad Internacional | G7: Medida alternativa | I7: Costo - Referencia
E8: Cantidad | F8: Unidad medida | G8: Cantidad | H8: Unidad medida | I8: Colones
C10: EMSABLE
C11: Rosquette Vainilla Dawn 400 g | D11: FAS | E11: 340 | F11: g | I11: Partido a la mitad
C13: Relleno
A14: 910000007 | B14: SE00084 | C14: Mezcla Tres Leches C/Baileys | D14: FAS | E14: 140 | F14: g
A15: 908000048 | B15: SE00087 | C15: Ganache Baileys | D15: FAS | E15: 100 | F15: g | I15: 1/3 Taza
A16: 902000168 | B16: SE00468 | C16: Mousse Chocolate de Leche | D16: FAS | E16: 230 | F16: g | I16: 1 taza y media
A17: 902000167 | B17: SE00467 | C17: Caramelo Crocante Bañado chocolate De Leche | D17: FAS | E17: 86 | F17: g | I17: 1/2 Taza
C18: Decoracion
A19: 910000018 | B19: SE00069 | C19: Crema Beidge | D19: FAS | E19: 150 | F19: g | I19: Encremado
A20: 910000018 | B20: SE00069 | C20: Crema Beidge | D20: FAS | E20: 120 | F20: g | H20: Decorado | I20: Boquilla 127 Wilton
A21: 20100163 | B21: SE00337 | C21: Empaque Fudge De Chocolate | D21: FAS | E21: 130 | F21: g | H21: Decorado | I21: Boquilla 127 Wilton
C22: Monedas Color Rojo Navidad Chocolate 7,5 | E22: 8 | F22: g | G22: 1 | H22: unidad
C23: Moneda Color Dorada Chocolate 7,5 | E23: 8 | F23: g | G23: 1 | H23: unidad
C24: Moneda Color Dorada Chocolate 5,5 | E24: 6 | F24: g | G24: 2 | H24: unidad
C25: Moneda Color Rojo NavidaChocolate 5,5 | E25: 6 | F25: g | G25: 2 | H25: unidad
C26: Barra de Tutto Baileys | E26: 42 | F26: g | H26: 5 cabos de 2 unidades | I26: 1 tableta x torta
C27: Empaque
A29: 121603 | B29: EM10009 | C29: QUEQUERA RED BASE/DOMO 10 (CAJA:50) | D29: MAYCA | E29: 1 | F29: ud
A30: 1950692 | B30: EM10008 | C30: ORLA CARTON 10" DORADA UND | D30: Mayca | E30: 1 | F30: Ud
A31: 702069 | B31: EM10002 | C31: Etiq.Blanca 1 1/4 * 3/4 | D31: ETIPLAST | E31: 1 | F31: ud
A32: 0703020 | B32: EM10248 | C32: CINTA ADHESIVA TRANSPARENTE 2*100 | D32: Mayca | E32: 60 | F32: cm
A33: 701096 | B33: EM10124 | C33: ETIQUETA BLANCA R-153 | D33: Cemusa | E33: 1 | F33: ud
A34: 0702123 | B34: EM10011 | C34: ETIQUETA BLANCA 2 5/8X1 15/16 PRE BLANCA | D34: Etiplast | E34: 1 | F34: ud
C35: Etiqueta Temporada navideña SPOON | D35: ETIPLAST | E35: 1 | F35: ud
D37: Cantidad | E37: Unidad
A38: PESO TOTAL OBTENIDO | D38: 1200 | E38: g | F38: Tiempo de Horneo:
A39: TIEMPO TOTAL DE PREPARACION | D39: 5 | E39: min | F39: Horno:
A40: CANTIDAD DE PORCIONES OBTENIDAS | D40: 1 | E40: ud | F40: Temperatura de Horneo:
A41: PESO DE CADA PORCIÓN | D41: 1200 | E41: g | F41: Otros
A42: MERMA | D42: 54 | E42: g
A43: PROCEDIMIENTO DE PREPARACION DE LA RECETA
A44: 1-Colocar la mitad del Rosquete
...

Sheet Empaque Fudge Chocolate
C1: SERVICIOS DE PASTELERIA S.A. | H1: CÓDIGO: | I1: ESP-RE-EMPS-246
C2: ESPECIFICACION DE RECETA | H2: REVISIÓN: | I2: 02
C3: 20100163(SE00337) Empaque Fudge de chocolate Spoon | H3: FECHA DE APROBACIÓN: | I3: 45235
C4: Elaborado | D4: Javier Tong, Chef
C5: Aprobado | D5: Esteban Cartin, Gte Manufactura
A6: AREA QUE PRODUCE: | D6: COCINA | G6: AREA QUE EMPACA: | I6: Cocina
A7: # Código | B7: # Codigo Netsuite | C7: Descripción del ingrediente | D7: Marca | E7: Unidad Internacional | G7: Medida alternativa | I7: Costo - Referencia
E8: Cantidad | F8: Unidad medida | G8: Cantidad | H8: Unidad medida | I8: Colones
A10: 90100354 | B10: SE00338 | C10: FUDGE DE CHOCOLATE SPOON | D10: FAS | E10: 5000 | F10: g
C12: EMPAQUE
A13: 51600050 | B13: EM10307 | C13: BOLSA MARMITA 14 x 20 (KILO) | E13: 1 | F13: ud
A14: 702123 | B14: EM10011 | C14: ETIQUETA BLANCA 2 5/8X1 15/16 (UND) | D14: Etiplas | E14: 1 | F14: ud
G15: 16.07
D19: Cantidad | E19: Unidad
A20: PESO TOTAL OBTENIDO | D20: 5000 | E20: g | F20: Tiempo de Horneo:
A21: TIEMPO TOTAL DE PREPARACION | D21: 3 | E21: Minutos | F21: Horno:
A22: CANTIDAD DE PORCIONES OBTENIDAS | D22: 1 | E22: Bolsas | F22: Temperatura de Horneo:
A23: PESO DE CADA PORCIÓN | D23: =D20/D22 -> 5000 | E23: g | F23: Otros
A24: MERMA | E24: g
A25: PROCEDIMIENTO DE PREPARACION DE LA RECETA
A26: 1. Vaciar la marmita en bolsas de 5kg aprox.
A27: 2. Amarrar la bolsa y etiquetar
A29: CONTROL DE CAMBIOS
A30: 2, Se cambia la bolsa termica

Sheet Fudge Chocolate 
C1: SERVICIOS DE PASTELERIA S.A. | H1: CÓDIGO: | I1: ESP-RE-COCS-355
C2: ESPECIFICACION DE RECETA | H2: REVISIÓN: | I2: 03
C3: 90100354(SE00338) Fudge de chocolate Spoon | H3: FECHA DE APROBACIÓN: | I3: 44929
C4: Elaborado | D4: Javier Tong, Chef
C5: Aprobado | D5: Esteban Cartin, Gte Manufactura
A6: AREA QUE PRODUCE: | D6: COCINA | G6: AREA QUE EMPACA: | I6: COCINA
A7: # Código | B7: # Codigo Netsuite | C7: Descripción del ingrediente | D7: Marca | E7: Unidad Internacional | G7: Medida alternativa | I7: Costo - Referencia
E8: Cantidad | F8: Unidad medida | G8: Cantidad | H8: Unidad medida | I8: Colones
A9: 11400066 | B9: MP10007 | C9: Manjar Leche Condensada | D9: Nestle | E9: 72000 | F9: g | G9: =E9/80.361 -> 895.95699
A10: 1110414 | B10: MP10024 | C10: LECHE EVAPORADA (LITRO) | D10: Nestle | E10: 13000 | F10: g | G10: =E10/80.361 -> 161.77001
A11: 0512255 | B11: MP10146 | C11: Cocoa Dutch Process | D11: Cia Nacional | E11: 1700 | F11: g | G11: =E11/80.361 -> 21.15454
A12: 10200035 | B12: MP10476 | C12: CHOCOLATE JOHNNYS MARMITA (CAJA: 12K) | D12: JOHNNYS | E12: 1000 | F12: g | G12: =E12/80.361 -> 12.443847
A13: 0310107 | B13: MP10022 | C13: Lactocrema Granel | D13: Dos Pinos | E13: 1320 | F13: g | G13: =E13/80.361 -> 16.425878
A14: 1212410 | B14: MP10008 | C14: PRESERVANTE 1047 (PAQ=5 KILOS) | D14: Aseal | E14: 270 | F14: g | G14: =E14/80.361 -> 3.3598387
G15: =E15/80.361 -> 0
G16: =E16/80.361 -> 0
G17: =E17/80.361 -> 0
D20: Cantidad | E20: Unidad
A21: PESO TOTAL OBTENIDO | D21: =SUM(E9:E14)*0.9 -> 80361 | E21: g
A22: TIEMPO TOTAL DE PREPARACION | D22: 58 | E22: MIN | J22: =58/80.361 -> 0.72174313
A23: CANTIDAD DE PORCIONES OBTENIDAS | D23: 1 | E23: TANDA
A24: PESO DE CADA PORCIÓN | D24: 5000 | E24: GRAMOS
A25: MERMA | D25: =SUM(E9:E14)-D21 -> 8929 | E25: GRAMOS
A26: PROCEDIMIENTO DE PREPARACION DE LA RECETA
A27: 1. Licuar la cocoa, el preservante y el Johnnys con la leche. Colocar el licuado en olla y agregar el resto de ingredientes.
A28: 2. Encender la marmita en progrmacion Fudge.
A29: 3. Apagar y empezar el proceso de empaque
A32: CONTROL DE CAMBIOS
A33: 2, Se cambia el Milo por Johnnys
A34: 3; Cambio de preservante 1017 al 1047

Sheet Crema Beidge 
D1: SERVICIOS DE PASTELERIA S.A. | I1: CÓDIGO: | J1: ESP-RE-DES-042
D2: ESPECIFICACION DE RECETA | I2: REVISIÓN: | J2: 07
D3: Crema Beidge 910000018(SE00069) | I3: FECHA DE APROBACIÓN: | J3: 24/04/2023
D4: Elaborado | E4: Javier Tong, Chef
D5: Aprobado | E5: Esteban Cartin, Gte Manufactura
B6: # Código | C6: # Codigo Netsuite | D6: Descripción del ingrediente | E6: Marca | F6: Unidad Internacional | H6: Medida alternativa | J6: Costo - Referencia
F7: Cantidad | G7: Unidad medida | H7: Cantidad | I7: Unidad medida | J7: Colones
B8: 95717 | C8: SE00010 | D8: CREMA CHANTILLY BLANCA SPOON-IND KILO | E8: FAS | F8: 20800 | G8: g | H8: =F8/20.8 -> 1000
A9: 104000001 | B9: 10400008 | C9: MP10150 | D9: COLORANTE GEL EGG YELLOW (UND= 130 ML) | E9: Master Pack | F9: 7 | G9: g | H9: =F9/20.8 -> 0.33653846
B10: 0702069 | C10: EM10002 | D10: ETIQ.BLANCA 1 1/4 * 3/4 | E10: Etiplas | F10: 1 | G10: ud | H10: =F10/20.8 -> 0.048076923
E13: Cantidad | F13: Unidad
B14: PESO TOTAL OBTENIDO | E14: 20800 | F14: g | G14: Tiempo de Horneo:
B15: TIEMPO TOTAL DE PREPARACION | E15: 2 | F15: Min | G15: Horno:
B16: CANTIDAD DE PORCIONES OBTENIDAS | E16: 1 | F16: Tanda | G16: Temperatura de Horneo:
B17: PESO POR PORCION | E17: =+E14 -> 20800 | F17: g | G17: Otros
B18: MERMA | E18: =SUM(F8:F10)-E14 -> 8 | F18: g
B19: PROCEDIMIENTO DE PREPARACION DE LA RECETA
B20: 1, Mezclar la crema con los colorantes, hatsa homogeneo
B21: 2.- Mantener en refrigeración.
B25: CONTROL DE CAMBIOS
B26: 4: Actualización de codigos.
B27: 5: Actualización de rendimiento
B28: 6: Actualizacion del peso del colorante
B29: 7: Se Elimina la crema supremo, la crema prestige, el preservante, el agua. Se agrega el subproducto crema chantilly Spoon

Sheet Crema Chantilly Blanca 
D1: SERVICIOS DE PASTELERIA S.A. | I1: CÓDIGO: | J1: ESP-RE-DES-036
D2: ESPECIFICACION DE RECETA | I2: REVISIÓN: | J2: 11
D3: Crema Blanca Spoon (20800g) SE00010 | I3: FECHA DE APROBACIÓN: | J3: 45383
D4: Elaborado | E4: Javier Tong, Chef
D5: Aprobado | E5: Esteban Cartin, Gte Manufactura
A6: # Código | B6: # Código | C6: # Codigo Netsuite | D6: Descripción del ingrediente | E6: Marca | F6: Unidad Internacional | H6: Medida alternativa | J6: Costo - Referencia
F7: Cantidad | G7: Unidad medida | H7: Cantidad | I7: Unidad medida | J7: Colones
A8: ICG
A9: 310148 | B9: 310148 | C9: MP10047 | D9: BETTERCREME SUPREMO (UND:4 K) | E9: Richs | F9: 12800 | G9: g
A10: 11400031 | B10: 11400031 | C10: MP10048 | D10: CREMA PRESTIGE GRAND (UND:4 K) | E10: Richs | F10: 3200 | G10: g
A11: 10415 | B11: 10415 | D11: AGUA POTABLE (PLANTA) | E11: AyA | F11: 800 | G11: g
A12: 1212410 | B12: 1212410 | C12: MP10008 | D12: PRESERVANTE 1047S (PAQ=5 KILO) | E12: Aseal | F12: 12 | G12: g
A13: 702069 | B13: 702123 | C13: EM10011 | D13: ETIQUETA BLANCA 2 5/8X1 15/16 (UND) | E13: Etiplas | F13: 1 | G13: ud
E28: Cantidad | F28: Unidad
B29: PESO TOTAL OBTENIDO | E29: =SUM(F9:F12)-E33 -> 16597 | F29: g | G29: Tiempo de Horneo: | I29: 16597
B30: TIEMPO TOTAL DE PREPARACION | E30: 10 | F30: min | G30: Horno:
B31: CANTIDAD DE PORCIONES OBTENIDAS | E31: 1 | F31: Tanda | G31: Temperatura de Horneo:
B32: PESO DE CADA PORCIÓN | E32: =E29 -> 16597 | F32: g | G32: Otros
B33: MERMA | E33: 215 | F33: g
B34: PROCEDIMIENTO DE PREPARACION DE LA RECETA
B35: 1.- Abrir los galones de crema y verter dentro de la top cream.
B36: 2.- Disolver el preservante en el agua. Agregar a la top cream.
B37: 3.- Batir por 12 a 15 minutos. Colocar en una tina plastica, tapar.
B38: 4.- Etiquetar con nombre y fecha de vencimiento.
B39: 5.- Mantener en refrigeración.
B40: Control de Cambios
B41: 9, Actuaizacion de codigos
B42: 10, Actuaizacion de procedimiento
B43: 11,Cambio de Pesos

Sheet Mezcla tres leches c Baileys 
D1: SERVICIOS DE PASTELERIA S.A. | I1: CÓDIGO: | J1: ESP-RE-POS-247
D2: ESPECIFICACION DE RECETA | I2: REVISIÓN: | J2: 02
D3: Mezcla Tres Leches con Baileys(3600g) 910000007(SE00084) | I3: FECHA DE APROBACIÓN: | J3: 44459
D4: Elaborado | E4: Juan Pablo Brenes, Chef
D5: Aprobado | E5: Esteban Cartin. Gte de Manufactura
B6: # Código | C6: # Codigo Netsuite | D6: Descripción del ingrediente | E6: Marca | F6: Unidad Internacional | H6: Medida alternativa | J6: Costo - Referencia
F7: Cantidad | G7: Unidad medida | H7: Cantidad | I7: Unidad medida | J7: Colones
B8: 907000001 | C8: SE00031 | D8: MEZCLA TRES LECHES PASTEURIZADA KILO | E8: SPOON | F8: 1500 | G8: g
B9: 10415 | D9: AGUA POTABLE | E9: Spoon | F9: 300 | G9: g
A10: 102000013 | B10: 1012341 | C10: MP10406 | D10: Licor de Baileys | E10: Baileys | F10: 1800 | G10: g
A11: 116000001 | B11: 1212410 | C11: MP10008 | D11: PRESERVANTE 1047S KILO (pre mezclas) | E11: Aseal | F11: 4 | G11: g
B13: 702069 | C13: EM10002 | D13: Etiq.Blanca 1 1/4 * 3/4 | E13: Cemusa | F13: 1 | G13: Unid
B14: 512000002 | C14: EM10259 | D14: Plástico Autoaderible 1/ 18*2000 | E14: Mayca | F14: 20 | G14: Cm
E17: Cantidad | F17: Unidad
B18: PESO TOTAL OBTENIDO | E18: 3600 | F18: g | G18: Tiempo de Horneo:
B19: TIEMPO TOTAL DE PREPARACION | E19: 2 | F19: Min. | G19: Horno:
B20: CANTIDAD DE PORCIONES OBTENIDAS | E20: 10 | F20: Tortas | G20: Temperatura de Horneo:
B21: PESO DE CADA PORCIÓN | E21: 3600 | F21: g | G21: Otros
B22: MERMA | E22: 0 | F22: g
B23: PROCEDIMIENTO DE PREPARACION DE LA RECETA
B24: 1.- Mezclar en un bote de acero inoxidable mezcla de tres leches, preservante, el agua y el baileys.
B25: Si sobra tiene 1 dia de vida util
B27: CONTROL DE CAMBIOS
B28: Revisión #2: Actualización de codigo y codigo de la mezcla de leches

Sheet Mezcla 3 leches Pasteurizada
C1: SERVICIOS DE PASTELERÍA S.A. | H1: CODIGO: | I1: ESP-RE-POS-072
C2: ESPECIFICACIÓN DE RECETA | H2: REVISION: | I2: 15
C3: Mezcla para Tres Leches Pasteurizada SE00031 | H3: FECHA DE APROBACION: | I3: 45235
C4: ELABORADO: | D4: Javier, Tong. Chef
C5: APROBADO: | D5: Esteban Cartin. Gte de Manufactura
A6: # Código | B6: # Código Netsuite | C6: Descripción del ingrediente | D6: Marca | E6: Unidad Internacional | G6: Medida alternativa | I6: Costo - Referencia
E7: Cantidad | F7: Unidad medida | G7: Cantidad | H7: Unidad medida | I7: Colones
A8: 11400047 | B8: MP10030 | C8: LECHE 2% PASTEURIZADA (UND) | D8: Dos Pinos | E8: 12230 | F8: g
A9: 1110414 | B9: MP10024 | C9: LECHE EVAPORADA (LITRO) | D9: Nestle | E9: 17430 | F9: g
A10: 11400046 | B10: MP10050 | C10: LECHE CONDENSADA | D10: Nestle | E10: 17430 | F10: g
A11: 11400031 | B11: MP10048 | C11: CREMA PRESTIGE GRAND | D11: Rich | E11: 14000 | F11: g
A12: 90100131 | B12: SE00016 | C12: AZUCAR BLANCO INDUSTRIAL KILO | D12: FAS | E12: 1475 | F12: g
A13: 1212410 | B13: MP10008 | C13: PRESERVANTE 1047S (PAQ=5 KILO) | D13: Aseal | E13: 140 | F13: g
D14: Cantidad | E14: Unidad
A15: TIEMPO mano obra directa | D15: 8 Min
A16: MANO OBRA EMPACANDO | D16: 3 Min
A17: PESO TOTAL OBTENIDO | D17: 62500g | F17: MERMA | H17: 205g
A18: PORCIONES OBTENIDAS | D18: 1 Tanda
A19: TIEMPO PASTEURIZACIÓN EN MAQUINA | D19: 1 HORA
A20: DESCRIPCION DE LA PREPARACION DE LA RECETA
A21: 1. Disolver completamente el preservante en un litro de leche estandar empleando el homogenizador manual.
A22: 2. Colocar en la batidora, la leche fluida, la leche evaporada, el litro de leche con el preservante ya disuelto, el azúcar, la crema prestige líquida y la leche condensada.
A23: 3. Dosificar la mezcla pasteurizada en recipientes de acero inoxidable previamente lavado de acuerdo a INS-LMP-019 Recipiente para el Almacenamiento de Leche Pasteurizada, tapar el recipiente hermeticamente y reservar hasta su uso.
A24: 4. Identificar los recipientes con nombre del producto, fecha de producción y responsable.
A25: 5. Esta mezcla tiene una vida útil de 2 días envasada en recipientes de acero inoxidable herméticamente cerrados y mantenida en refrigeración
A26: 0ºC y 5ªC. Terminado el proceso proceder a la limpieza del equipo y a la sanitización.
A27: Control de cambios
A28: 14, Actualizacion de codigos
A30: Revision #15: Actualizacion del procedimiento.

Sheet MOusse de chocolate de leche 
C1: SERVICIOS DE PASTELERIA S.A. | H1: CÓDIGO: | I1: ESP-RE-POS-260
C2: ESPECIFICACION DE RECETA | H2: REVISIÓN: | I2: 03
C3: SE00468 902000168 MOUSSE DE CHOCOLATE DE LECHE | H3: FECHA DE APROBACIÓN: | I3: 45117
C4: Elaborado | D4: Maria Jose Rodriguez, Chef
C5: Aprobado | D5: Esteban Cartin, Gte Manufactura
A7: AREA QUE PRODUCE: | D7: POSTRES | G7: AREA QUE EMPACA: | I7: POSTRES
A8: # Código | C8: Descripción del ingrediente | D8: Marca | E8: Unidad Internacional | G8: Medida alternativa | I8: Costo - Referencia
E9: Cantidad | F9: Unidad medida | G9: Cantidad | H9: Unidad medida | I9: Colones
A10: 10100331 | B10: MP10492 | C10: CHOCOLATE SEMI AMARGO 54% (PAQ 5 k) | E10: 1500 | J10: =+E10/4.2 -> 357.14286
A11: 11400031 | B11: MP10048 | C11: CREMA PRESTIGE GRAND (UND:4 K) | D11: RICHS | E11: 1000 | F11: g | J11: =+E11/4.2 -> 238.09524
J12: =+E12/4.2 -> 0
A13: 11400031 | B13: MP10048 | C13: CREMA PRESTIGE GRAND (UND:4 K) | D13: RICHS | E13: 2000 | F13: g | G13: Para batir | J13: =+E13/4.2 -> 476.19048
J14: =+E14/4.2 -> 0
D18: Cantidad | E18: Unidad
A19: PESO TOTAL OBTENIDO | D19: 4200 | E19: g
A20: TIEMPO TOTAL DE PREPARACION | D20: 15 | E20: min | J20: =15/4.2 -> 3.5714286
A21: CANTIDAD DE PORCIONES OBTENIDAS | D21: 13 | E21: ud
A22: PESO DE CADA PORCIÓN | D22: 300 | E22: g
A23: MERMA | D23: 300 | E23: g
A24: PROCEDIMIENTO DE PREPARACION DE LA RECETA
A25: 1, Colocar el chocolate en un recipiente junto con la crema del ganache y derretir en microondas o Baño maria.
A26: 2, Batir la otra cantidad de crema hasta punto yogurt con globo en velocidad alta.
A27: 3, Agregar el chocolate derretido a la crema batida en velocidad media hasta homogeneo.
A28: 4, Utilizar de inmediato
A34: CONTROL DE CAMBIOS
A35: 2,- Se aumenta la cantida de prestige por tanda
A36: 3,- Se ajusta el rendimiento.
A37: 4- Se agrega codigo netsuite

Sheet Caramelo Crocante bañado choco 
C1: SERVICIOS DE PASTELERIA S.A. | H1: CÓDIGO: | I1: ESP-RE-POS-261
C2: ESPECIFICACION DE RECETA | H2: REVISIÓN: | I2: 02
C3: SE00467 Caramelo Crocante bañado con chocolate de leche | H3: FECHA DE APROBACIÓN: | I3: 45422
C4: Elaborado | D4: Maria Jose Rodriguez, Chef
C5: Aprobado | D5: Esteban Cartin. Gte de Manufactura
A6: AREA QUE PRODUCE: | D6: Postres | G6: AREA QUE EMPACA: | I6: Postres
A7: # Código | B7: # Codigo Netsuite | C7: Descripción del ingrediente | D7: Marca | E7: Unidad Internacional | G7: Medida alternativa | I7: Costo - Referencia
E8: Cantidad | F8: Unidad medida | G8: Cantidad | H8: Unidad medida | I8: Colones
C9: Emsamble
A10: 907000027 | B10: SE00355 | C10: Caramelo Crocante | D10: Victoria | E10: 1000 | F10: g
A11: 1210386 | B11: MP10001 | C11: Cobertura Chocolate Leche | D11: Nacional | E11: 1000 | F11: g
A13: 1950702 | B13: EM10016 | C13: Bolsa 12X18 Transparente | D13: Plasticos P | E13: 1 | F13: Unid
A14: 702067 | B14: EM10120 | C14: Etiq.Blanca 1 13/16 * 1 7/8 | D14: Mayca | E14: 1 | F14: Unid
A20: 60100120 | B20: EM10314 | C20: Etiqueta Edicion Especial | D20: ETIPLAST | E20: 1 | F20: ud
D22: Cantidad | E22: Unidad
A23: PESO TOTAL OBTENIDO | D23: 1950 | E23: g | F23: Tiempo de Horneo:
A24: TIEMPO TOTAL DE PREPARACION | D24: 8 | E24: min | F24: Horno:
A25: CANTIDAD DE PORCIONES OBTENIDAS | D25: 1 | E25: ud | F25: Temperatura de Horneo:
A26: PESO DE CADA PORCIÓN | D26: 1950 | E26: g | F26: Otros
A27: MERMA | D27: 50 | E27: g
A28: PROCEDIMIENTO DE PREPARACION DE LA RECETA
A29: 1.- Derretir el chocolate y mezclar con el caramelo picado.
A30: 2.- Refrigerar.
A31: 3.- Partir en la maquina hasta obtener cuadros pequeños.
A32: 4.- Mantener en refrigeracion hasta utilizar.
A33: 5-Empacar y etiquetar
A37: CONTROL DE CAMBIOS
A38: 1,- Se cambia el chocolate oscuro por chocolate de leche.
A39: 2-Actualizacion de Codigos y Netsuit

Sheet Caramelo Crocante 
C1: SERVICIOS DE PASTELERIA S.A. | H1: CÓDIGO: | I1: ESP-RE-POS-100
C2: ESPECIFICACION DE RECETA | H2: REVISIÓN: | I2: 02
C3: Caramelo Crocante 1000g Spoon SE00355 | H3: FECHA DE APROBACIÓN: | I3: 45432
C4: Elaborado | D4: Javier Tong ,Chef
C5: Aprobado | D5: Esteban Cartin. Gte de Manufactura
A6: AREA QUE PRODUCE: | D6: Postres | G6: AREA QUE EMPACA: | I6: Postres
A7: # Código | B7: # Codigo Netsuite | C7: Descripción del ingrediente | D7: Marca | E7: Unidad Internacional | G7: Medida alternativa | I7: Costo - Referencia
E8: Cantidad | F8: Unidad medida | G8: Cantidad | H8: Unidad medida | I8: Colones
C9: Emsamble
A10: 510302 | B10: MP10078 | C10: Azucar Refino Industrial | D10: Mayca | E10: 1100 | F10: g
A12: 1950702 | B12: EM10016 | C12: Bolsa 12X18 Transparente | D12: Plasticos P | E12: 1 | F12: Unid
A13: 702067 | B13: EM10120 | C13: Etiq.Blanca 1 13/16 * 1 7/8 | D13: Mayca | E13: 1 | F13: Unid
A20: 60100120 | B20: EM10314 | C20: Etiqueta Edicion Especial | D20: ETIPLAST | E20: 1 | F20: ud
D22: Cantidad | E22: Unidad
A23: PESO TOTAL OBTENIDO | D23: 1000 | E23: g | F23: Tiempo de Horneo:
A24: TIEMPO TOTAL DE PREPARACION | D24: 6 | E24: min | F24: Horno:
A25: CANTIDAD DE PORCIONES OBTENIDAS | D25: 1 | E25: ud | F25: Temperatura de Horneo:
A26: PESO DE CADA PORCIÓN | D26: 1000 | E26: g | F26: Otros
A27: MERMA | D27: 100 | E27: g
A28: PROCEDIMIENTO DE PREPARACION DE LA RECETA
A29: 1.- Derretir el azucar hasta tomar color caramelo. Tener cuidado de no quemar.
A30: 2.- Retirar del fuego y colocar en una blonda de teflon, dejar enfriar.
A31: 3.- Partir con un maso, trozos pequeños.
A32: 4.- Enviar a figuras.
A37: CONTROL DE CAMBIOS
A38: 2- Actualizacion con Codigos Netsuit

Sheet Ganache de Baileys 
C1: SERVICIOS DE PASTELERIA S.A. | H1: CÓDIGO: | I1: ESP-RE-COCS-071
C2: ESPECIFICACION DE RECETA | H2: REVISIÓN: | I2: 04
C3: GANACHE BAILEYS SE00087 | H3: FECHA DE APROBACIÓN: | I3: 45400
C4: Elaborado | D4: Javier Tong, chef
C5: Aprobado | D5: Jeffry Rodriguez. Gte de Manufactura
A6: AREA QUE PRODUCE: | D6: COCINA | G6: AREA QUE EMPACA: | I6: EMPAQUE
A7: # Código | B7: # Codigo Netsuite | C7: Descripción del ingrediente | D7: Marca | E7: Unidad Internacional | G7: Medida alternativa | I7: Costo - Referencia
E8: Cantidad | F8: Unidad medida | G8: Cantidad | H8: Unidad medida | I8: Colones
A9: 11400031 | B9: MP10048 | C9: CREMA PRESTIGE GRAND (UND=4 K) | D9: RICHS | E9: 7050 | F9: g
A10: 1210387 | B10: MP10143 | C10: COBERTURA CHOCOLATE BLANCO (PAQ:5 K) | D10: NACIONAL | E10: 11400 | F10: g
A11: 1012341 | B11: MP10406 | C11: BAILEYS (BOTELLA=1 LITRO) | D11: BAILEYS | E11: 3450 | F11: g
A13: 0702069 | B13: EM10002 | C13: ETIQ.BLANCA 1 1/4 * 3/4 | D13: Cemusa | E13: 1 | F13: ud
A14: 512000002 | B14: EM10259 | C14: PLAST. AUTOAD 18 * 2000 | D14: Mayca | E14: 20 | F14: cm
D17: Cantidad | E17: Unidad
A18: PESO TOTAL OBTENIDO | D18: 21000 | E18: g | F18: Tiempo de Horneo:
A19: TIEMPO TOTAL DE PREPARACION | D19: 5 | E19: min | F19: Horno:
A20: CANTIDAD DE PORCIONES OBTENIDAS | D20: 1 | E20: TANDAS | F20: Temperatura de Horneo:
A21: PESO DE CADA PORCIÓN | D21: 21000 | E21: g | F21: Otros
A22: MERMA | D22: =SUM(E9:E11)-D18 -> 900 | E22: g
A23: PROCEDIMIENTO DE PREPARACION DE LA RECETA
A24: 1, Colocar en una olla la crema Prestige a 55 grados . Calentar
A25: 2, Agregar el chocolate en trozos. Mezclar hasta que se derrita el chocolate.
A26: 3, Agregar el Baileys.
A27: 4, Colocar en bandejas, hacer choque térmico.
A29: CONTROL DE CAMBIOS
A30: Versión #3 : Se actualiza instructivo
A31: Version # 4 : Se agrega temperatura

Sheet Costo Ensamble Locales
E1: Precio Local | F1: Costo MP | G1: Costo EM | H1: Costo MO
E2: =IFERROR(O62,"") -> 7225.2357 | F2: =IFERROR(H53,"") -> 4940.4562 | G2: =IFERROR(H54,"") -> 652.4945 | H2: =IFERROR(H56,"") -> 836.7175
A5: ESTRUCTURA DE COSTOS
F6: Fecha: | H6: =TODAY() -> 45741
A7: UNIDADES | B7: DESCRIPCION MAT.PRIMA | C7: UNIDADES | D7: UND MEDIDA | E7: COSTO UNITARIO | F7: TOTAL COSTO | G7: % PREC. DEFINIDO | H7: CODIGOS
A8: 0 | B8: Monedas Color Rojo Navidad Chocolate 7,5 | C8: =+A8 -> 0 | D8: UND | E8: 115 | F8: =IFERROR(C8*E8,"") -> 0 | G8: =IFERROR(F8/$F$66,"") -> 0
A9: 0 | B9: Moneda Color Dorada Chocolate 7,5 | C9: =+A9 -> 0 | D9: UND | E9: 115 | F9: =IFERROR(C9*E9,"") -> 0 | G9: =IFERROR(F9/$F$66,"") -> 0
A10: 3 | B10: Moneda Color Dorada Chocolate 5,5 | C10: =+A10 -> 3 | D10: UND | E10: 85 | F10: =IFERROR(C10*E10,"") -> 255 | G10: =IFERROR(F10/$F$66,"") -> 0.042522963
A11: 2 | B11: Moneda Color Rojo NavidaChocolate 5,5 | C11: =+A11 -> 2 | D11: UND | E11: 85 | F11: =IFERROR(C11*E11,"") -> 170 | G11: =IFERROR(F11/$F$66,"") -> 0.028348642
A12: 1 | B12: Barra de Tutto Baileys | C12: =+A12 -> 1 | D12: UND | E12: 413 | F12: =IFERROR(C12*E12,"") -> 413 | G12: =IFERROR(F12/$F$66,"") -> 0.068870525
A13: 20 | B13: =IFERROR(VLOOKUP(H13,'[1]Consolidado MP Planta'!$A$2:$M$823,3,0),"") -> CREMA BETTERCREAM DOBLE CHOCO (UND:4 K) | C13: =+A13 -> 20 | D13: =IFERROR(VLOOKUP(H13,'[1]Consolidado MP Planta'!$A$2:$M$823,13,0),"") -> Gramos | E13: 2.5 | F13: =IFERROR(C13*E13,"") -> 50 | G13: =IFERROR(F13/$F$66,"") -> 0.0083378359 | H13: 11400027
B14: =IFERROR(VLOOKUP(H14,'[1]Consolidado MP Planta'!$A$2:$M$823,3,0),"") | C14: =+A14 -> 0 | D14: =IFERROR(VLOOKUP(H14,'[1]Consolidado MP Planta'!$A$2:$M$823,13,0),"") | E14: =IFERROR(VLOOKUP(H14,'[1]Consolidado MP Planta'!$A$2:$M$823,12,0),"") | F14: =IFERROR(C14*E14,"") | G14: =IFERROR(F14/$F$66,"")
B15: =IFERROR(VLOOKUP(H15,'[2]ARTICULOS MP PLANTA'!$A$2:$G$589,2,0),"")
A16: UNIDADES | B16: MATERIA PRIMA SEMIELABORADOS | C16: UNIDADES | D16: UND MEDIDA | E16: COSTO UNITARIO | F16: TOTAL COSTO | G16: % PREC. DEFINIDO | H16: CODIGOS
A17: 1 | B17: Rosquette Melo 450 g | C17: =+A17 -> 1 | D17: UND | E17: =+'Costo Rosquete 450'!H53 -> 837.35625 | F17: =IFERROR(E17*C17,"") -> 837.35625 | G17: =IFERROR(F17/$F$66,"") -> 0.13963478
A18: 160 | B18: =IFERROR(VLOOKUP(H18,[1]SEMIELABORADOS!$A$2:$M$6000,2,0),"") -> MEZCLA TRES LECHES C/BAILEYS LITRO | C18: =+A18 -> 160 | D18: =IFERROR(VLOOKUP(H18,[1]SEMIELABORADOS!$A$2:$M$6000,6,0),"") -> Gramo | E18: 7.9 | F18: =IFERROR(E18*C18,"") -> 1264 | G18: =IFERROR(F18/$F$66,"") -> 0.21078049 | H18: 910000007
A19: 100 | B19: =IFERROR(VLOOKUP(H19,[1]SEMIELABORADOS!$A$2:$M$6000,2,0),"") -> GANACHE BAILEYS (KILO) | C19: =+A19 -> 100 | D19: =IFERROR(VLOOKUP(H19,[1]SEMIELABORADOS!$A$2:$M$6000,6,0),"") -> Gramo | E19: 4.88 | F19: =IFERROR(E19*C19,"") -> 488 | G19: =IFERROR(F19/$F$66,"") -> 0.081377279 | H19: 908000048
A20: 230 | B20: Mousse Chocolate de Leche | C20: =+A20 -> 230 | D20: Gramo | E20: 2.94 | F20: =IFERROR(E20*C20,"") -> 676.2 | G20: =IFERROR(F20/$F$66,"") -> 0.11276089 | H20: 902000168
A21: 50 | B21: Caramelo Crocante Bañado chocolate De Leche | C21: =+A21 -> 50 | D21: Gramo | E21: 2.7 | F21: =IFERROR(E21*C21,"") -> 135 | G21: =IFERROR(F21/$F$66,"") -> 0.022512157 | H21: 902000167
A22: 150 | B22: =IFERROR(VLOOKUP(H22,[1]SEMIELABORADOS!$A$2:$M$6000,2,0),"") -> CREMA BEIDGE (KILO) | C22: =+A22 -> 150 | D22: =IFERROR(VLOOKUP(H22,[1]SEMIELABORADOS!$A$2:$M$6000,6,0),"") -> Gramo | E22: 2.24 | F22: =IFERROR(E22*C22,"") -> 336 | G22: =IFERROR(F22/$F$66,"") -> 0.056030258 | H22: 910000018
A23: 130 | B23: Empaque Fudge De Chocolate | C23: =+A23 -> 130 | D23: Gramo | E23: 2.43 | F23: =IFERROR(E23*C23,"") -> 315.9 | G23: =IFERROR(F23/$F$66,"") -> 0.052678447 | H23: 20100163
B24: =IFERROR(VLOOKUP(H24,[1]SEMIELABORADOS!$A$2:$M$6000,2,0),"") | C24: =+A24 -> 0 | D24: =IFERROR(VLOOKUP(H24,[1]SEMIELABORADOS!$A$2:$M$6000,6,0),"") | E24: =IFERROR(VLOOKUP(H24,[1]SEMIELABORADOS!$A$2:$H$65536,8,0),"") | F24: =IFERROR(E24*C24,"") | G24: =IFERROR(F24/$F$66,"")
A26: UNIDADES | B26: EMPAQUE | C26: UNIDADES | D26: UND MEDIDA | E26: COSTO UNITARIO | F26: TOTAL COSTO | G26: % PREC. DEFINIDO | H26: CODIGOS
A27: 1 | B27: =IFERROR(VLOOKUP(H27,'[1]Consolidado MP Planta'!$A$2:$M$823,3,0),"") -> QUEQUERA RED BASE/DOMO 10 (CAJA:50) | C27: =+A27 -> 1 | D27: =IFERROR(VLOOKUP(H27,'[1]Consolidado MP Planta'!$A$2:$M$823,13,0),"") -> UND | E27: 346 | F27: =IFERROR(C27*E27,"") -> 346 | G27: =IFERROR(F27/$F$66,"") -> 0.057697825 | H27: 121603
A28: 1 | B28: =IFERROR(VLOOKUP(H28,'[1]Consolidado MP Planta'!$A$2:$M$823,3,0),"") -> ORLA CARTON 10" DORADA (UND) | C28: =+A28 -> 1 | D28: =IFERROR(VLOOKUP(H28,'[1]Consolidado MP Planta'!$A$2:$M$823,13,0),"") -> Und | E28: 117 | F28: =IFERROR(C28*E28,"") -> 117 | G28: =IFERROR(F28/$F$66,"") -> 0.019510536 | H28: 1950692
A29: 1 | B29: =IFERROR(VLOOKUP(H29,'[1]Consolidado MP Planta'!$A$2:$M$823,3,0),"") -> ETIQ.BLANCA 1 1/4 * 3/4 (UND) | C29: =+A29 -> 1 | D29: =IFERROR(VLOOKUP(H29,'[1]Consolidado MP Planta'!$A$2:$M$823,13,0),"") -> Und | E29: =IFERROR(VLOOKUP(H29,'[1]Consolidado MP Planta'!$A$2:$M$823,12,0),"") -> 0.58 | F29: =IFERROR(C29*E29,"") -> 0.58 | G29: =IFERROR(F29/$F$66,"") -> 9.6718897e-05 | H29: 0702069
A30: 1 | B30: =IFERROR(VLOOKUP(H30,'[1]Consolidado MP Planta'!$A$2:$M$823,3,0),"") -> ETIQUETA BLANCA R-153 (UND) | C30: =+A30 -> 1 | D30: =IFERROR(VLOOKUP(H30,'[1]Consolidado MP Planta'!$A$2:$M$823,13,0),"") -> Und | E30: =IFERROR(VLOOKUP(H30,'[1]Consolidado MP Planta'!$A$2:$M$823,12,0),"") -> 0.39 | F30: =IFERROR(C30*E30,"") -> 0.39 | G30: =IFERROR(F30/$F$66,"") -> 6.503512e-05 | H30: 701096
A31: 1 | B31: =IFERROR(VLOOKUP(H31,'[1]Consolidado MP Planta'!$A$2:$M$823,3,0),"") -> ETIQUETA BLANCA 2 5/8X1 15/16 (UND) | C31: =+A31 -> 1 | D31: =IFERROR(VLOOKUP(H31,'[1]Consolidado MP Planta'!$A$2:$M$823,13,0),"") -> Und | E31: =IFERROR(VLOOKUP(H31,'[1]Consolidado MP Planta'!$A$2:$M$823,12,0),"") -> 2.128 | F31: =IFERROR(C31*E31,"") -> 2.128 | G31: =IFERROR(F31/$F$66,"") -> 0.0003548583 | H31: 0702123
A32: 1 | B32: Etiqueta Edicion Especial | C32: =+A32 -> 1 | D32: UND | E32: 110 | F32: =IFERROR(C32*E32,"") -> 110 | G32: =IFERROR(F32/$F$66,"") -> 0.018343239 | H32: 60100120
A34: UNIDADES | B34: EMPAQUE SEMIELABORADOS | C34: UNIDADES | D34: UND MEDIDA | E34: COSTO UNITARIO | F34: TOTAL COSTO | G34: % PREC. DEFINIDO | H34: CODIGOS
A35: =+A17 -> 1 | B35: Rosquette Melo 400 g | C35: =+A35 -> 1 | D35: UND | E35: =+'Costo Rosquete 450'!H54 -> 10.3815 | F35: =IFERROR(E35*C35,"") -> 10.3815 | G35: =IFERROR(F35/$F$66,"") -> 0.0017311849
A36: =+A18 -> 160 | B36: =IFERROR(VLOOKUP(H36,[1]SEMIELABORADOS!$A$2:$M$6000,2,0),"") -> MEZCLA TRES LECHES C/BAILEYS LITRO | C36: =+A36 -> 160 | D36: =IFERROR(VLOOKUP(H36,[1]SEMIELABORADOS!$A$2:$M$6000,6,0),"") -> Gramo | E36: 0 | F36: =IFERROR(E36*C36,"") -> 0 | G36: =IFERROR(F36/$F$66,"") -> 0 | H36: 910000007
A37: =+A19 -> 100 | B37: =IFERROR(VLOOKUP(H37,[1]SEMIELABORADOS!$A$2:$M$6000,2,0),"") -> GANACHE BAILEYS (KILO) | C37: =+A37 -> 100 | D37: =IFERROR(VLOOKUP(H37,[1]SEMIELABORADOS!$A$2:$M$6000,6,0),"") -> Gramo | E37: 0.02 | F37: =IFERROR(E37*C37,"") -> 2 | G37: =IFERROR(F37/$F$66,"") -> 0.00033351344 | H37: 908000048
A38: =+A20 -> 230 | B38: Mousse Chocolate de Leche | C38: =+A38 -> 230 | D38: Gramo | E38: 0.09 | F38: =IFERROR(E38*C38,"") -> 20.7 | G38: =IFERROR(F38/$F$66,"") -> 0.0034518641 | H38: 902000168
A39: =+A21 -> 50 | B39: Caramelo Crocante Bañado chocolate De Leche | C39: =+A39 -> 50 | D39: Gramo | E39: 0.84 | F39: =IFERROR(E39*C39,"") -> 42 | G39: =IFERROR(F39/$F$66,"") -> 0.0070037822 | H39: 902000167
A40: =+A22 -> 150 | B40: =IFERROR(VLOOKUP(H40,[1]SEMIELABORADOS!$A$2:$M$6000,2,0),"") -> CREMA BEIDGE (KILO) | C40: =+A40 -> 150 | D40: =IFERROR(VLOOKUP(H40,[1]SEMIELABORADOS!$A$2:$M$6000,6,0),"") -> Gramo | E40: 0.0001 | F40: =IFERROR(E40*C40,"") -> 0.015 | G40: =IFERROR(F40/$F$66,"") -> 2.5013508e-06 | H40: 910000018
A41: =+A23 -> 130 | B41: Empaque Fudge De Chocolate | C41: =+A41 -> 130 | D41: gramo | E41: 0.01 | F41: =IFERROR(E41*C41,"") -> 1.3 | G41: =IFERROR(F41/$F$66,"") -> 0.00021678373 | H41: 20100163
A43: UNIDADES | B43: MODI | C43: UNIDADES | D43: UND MEDIDA | E43: COSTO UNITARIO | F43: TOTAL COSTO | G43: % PREC. DEFINIDO | H43: CODIGOS
A44: =+A35 -> 1 | B44: Rosquette Melo 400 g | C44: =+A44 -> 1 | D44: UND | E44: =+'Costo Rosquete 450'!H56 -> 31.1175 | F44: =IFERROR(E44*C44,"") -> 31.1175 | G44: =IFERROR(F44/$F$66,"") -> 0.0051890522
A45: =+A36 -> 160 | B45: =IFERROR(VLOOKUP(H45,[1]SEMIELABORADOS!$A$2:$M$6000,2,0),"") -> MEZCLA TRES LECHES C/BAILEYS LITRO | C45: =+A45 -> 160 | D45: =IFERROR(VLOOKUP(H45,[1]SEMIELABORADOS!$A$2:$M$6000,6,0),"") -> Gramo | E45: 1.39 | F45: =IFERROR(E45*C45,"") -> 222.4 | G45: =IFERROR(F45/$F$66,"") -> 0.037086694 | H45: 910000007
...

Sheet Rosquette 400 g
C1: SERVICIOS DE PASTELERIA S.A. | H1: CÓDIGO:
C2: ESPECIFICACION DE RECETA | H2: REVISIÓN:
C3: Rosquete nucleo vainilla Dawn Redondo 400 g | H3: FECHA DE APROBACIÓN:
C4: Elaborado | D4: Jose Brizuela, Chef
C5: Aprobado | D5: Esteban Cartín. Gte de Manufactura
A6: # Código | B6: # Codigo Netsuite | C6: Descripción del ingrediente | D6: Marca | E6: Unidad Internacional | G6: Medida alternativa | I6: Costo - Referencia
E7: Cantidad | F7: Unidad medida | G7: Cantidad | H7: Unidad medida | I7: Colones
B8: SE00444 | C8: BATIDO NUCLEO VAINILLA DAWN | D8: FAS | E8: 24820 | F8: g
C10: EMPAQUE
A11: 902000019 | C11: MEZCLA P/ENGRASE MOLDES KILO | D11: FAS | E11: =10*D21 -> 687.05882 | F11: g
A12: 1950928 | B12: AS00028 | C12: BOLSA TRANSPARENTE 56X96X1.80 KILO | D12: Plasticos P | E12: 6 | F12: ud
A13: 0702007 | B13: EM10004 | C13: ETIQ.FECHA VENCIMIENTO BLANCO (ROLLO) | D13: Etiplast | E13: 6 | F13: ud
A14: 0702069 | B14: EM10002 | C14: ETIQ.BLANCA 1 1/4 * 3/4 (UND) | D14: Cemusa | E14: 6 | F14: ud
D18: Cantidad | E18: Unidad
A19: PESO TOTAL OBTENIDO | D19: =73*320 -> 23360 | E19: g | F19: Tiempo de Horneo:
A20: TIEMPO TOTAL DE PREPARACION | D20: 15 | E20: Min | F20: Horno:
A21: CANTIDAD DE PORCIONES OBTENIDAS | D21: =+D19/D22 -> 68.705882 | E21: ud | F21: Temperatura de Horneo:
A22: PESO DE CADA PORCIÓN | D22: 340 | E22: g | F22: Otros
A23: MERMA | D23: =+E8-D19 -> 1460 | E23: g
A24: PROCEDIMIENTO DE PREPARACION DE LA RECETA
A25: 1.- Pesar 400 g de mezcla en los moldes previamente engrasados.
A26: 2.- Hornear por Dicte 1 o 2 a 175°C por 50 min
A27: 3.- Enfriar, desmoldar, colocar 12 rosquetes por lata, etiquetar con nombre y fecha de producción.
A29: Control de cambios

Sheet Rosquete 400 g 2
C1: SERVICIOS DE PASTELERIA S.A. | H1: CÓDIGO:
C2: ESPECIFICACION DE RECETA | H2: REVISIÓN:
C3: Rosquete nucleo vainilla Dawn Redondo 400 g | H3: FECHA DE APROBACIÓN:
C4: Elaborado | D4: Jose Brizuela, Chef
C5: Aprobado | D5: Esteban Cartín. Gte de Manufactura
A6: # Código | B6: # Codigo Netsuite | C6: Descripción del ingrediente | D6: Marca | E6: Unidad Internacional | G6: Medida alternativa | I6: Costo - Referencia
E7: Cantidad | F7: Unidad medida | G7: Cantidad | H7: Unidad medida | I7: Colones
B8: SE00444 | C8: BATIDO NUCLEO VAINILLA DAWN | D8: FAS | E8: 24820 | F8: g | G8: 62.05
C10: EMPAQUE
A11: 902000019 | C11: MEZCLA P/ENGRASE MOLDES KILO | D11: FAS | E11: 600 | F11: g
A12: 1950928 | B12: AS00028 | C12: BOLSA TRANSPARENTE 56X96X1.80 KILO | D12: Plasticos P | E12: 6 | F12: ud
A13: 0702007 | B13: EM10004 | C13: ETIQ.FECHA VENCIMIENTO BLANCO (ROLLO) | D13: Etiplast | E13: 6 | F13: ud
A14: 0702069 | B14: EM10002 | C14: ETIQ.BLANCA 1 1/4 * 3/4 (UND) | D14: Cemusa | E14: 6 | F14: ud
D18: Cantidad | E18: Unidad
A19: PESO TOTAL OBTENIDO | D19: 24000 | E19: g | F19: Tiempo de Horneo:
A20: TIEMPO TOTAL DE PREPARACION | D20: 15 | E20: Min | F20: Horno:
A21: CANTIDAD DE PORCIONES OBTENIDAS | D21: 60 | E21: ud | F21: Temperatura de Horneo:
A22: PESO DE CADA PORCIÓN | D22: 400 | E22: g | F22: Otros
A23: MERMA | D23: 820 | E23: g
A24: PROCEDIMIENTO DE PREPARACION DE LA RECETA
A25: 1.- Pesar 400 g de mezcla en los moldes previamente engrasados.
A26: 2.- Hornear por Dicte 1 o 2 a 175°C por 50 min
A27: 3.- Enfriar, desmoldar, colocar 12 rosquetes por lata, etiquetar con nombre y fecha de producción.
A29: Control de cambios

Sheet Batido nucleo vainilla Dawn
C1: SERVICIOS DE PASTELERIA S.A. | H1: CÓDIGO: | I1: ESP-RE-BAS-169
C2: ESPECIFICACION DE RECETA | H2: REVISIÓN: | I2: 03
C3: SE00444 Batido Nucleo vainilla Dawn | H3: FECHA DE APROBACIÓN: | I3: 45411
C4: Elaborado | D4: Javier Tong, chef
C5: Aprobado | D5: Esteban Cartin, Gte Manufactura
A7: AREA QUE PRODUCE: | D7: Batidos | G7: AREA QUE EMPACA: | I7: Batidos
A8: # Código | B8: # Codigo Netsuite | C8: Descripción del ingrediente | D8: Marca | E8: Unidad Internacional | G8: Medida alternativa | I8: Costo - Referencia
E9: Cantidad | F9: Unidad medida | H9: Unidad medida | I9: Colones
A10: 906000138 | B10: SE00443 | C10: PREMEZCLA BATIDO NUCLEO VAINILLA DAWN | D10: FAS | E10: 13995 | F10: g
A11: 1210482 | B11: MP10005 | C11: HUEVO ENTERO PASTERI INNOVO ( CAJA: 10 K) | D11: INNOVO | E11: 9055 | F11: g
A12: 10415 | C12: AGUA POTABLE (PLANTA) | D12: FAS | E12: 1940 | F12: g
A13: 1212437 | B13: MP10315 | C13: PRESERVANTE MIXTO (UND:17 K) | D13: PURATOS | E13: 855 | F13: g
D25: Cantidad | E25: Unidad
A26: PESO TOTAL OBTENIDO | D26: 24000 | E26: g
