Workbook

Sheet Hoja1
C1: SERVICIOS DE PASTELERIA S.A. | H1: CÓDIGO: | I1: ESP-RE-DES-001
C2: ESPECIFICACION DE RECETA | H2: REVISIÓN: | I2: 01
C3: PTI00156 Torta Baileys mediana | H3: FECHA DE APROBACIÓN: | I3: 45613
C4: Elaborado | D4: Javier Tong, Chef
C5: Aprobado | D5: Esteban Cartin, Gte Manufactura
A6: AREA QUE PRODUCE: | D6: Decoración | G6: AREA QUE EMPACA: | I6: Decoracion
A7: # Código | B7: # Código Netsuite | C7: Descripción del ingrediente | D7: Marca | E7: Unidad Internacional | G7: Medida alternativa | I7: Costo - Referencia
E8: Cantidad | F8: Unidad medida | G8: Cantidad | H8: Unidad medida | I8: Colones
C9: Ensamble
A10: 907000311 | B10: SE00462 | C10: ROSQUETE NUCLEO VAINILLA DAWN REDONDO 360G | D10: FAS | E10: 313 | F10: g | H10: 1 UND
A11: 910000007 | B11: SE00084 | C11: MEZCLA TRES LECHES C/BAILEYS LITRO | D11: FAS | E11: 200 | F11: g
A12: 11400066 | B12: MP10007 | C12: MANJAR LECHE CONDENSADA (PAQ:6 K) | D12: NESTLE | E12: 145 | F12: g | H12: 1/2 TAZA
A13: 905000031 | B13: SE00085 | C13: RELLENO CREMA MOKA C/BAILEYS (KILO) | D13: FAS | E13: 130 | F13: g | H13: 3/4 TAZA
A14: 907000015 | B14: SE00086 | C14: MEZCLA CHOCOLATE BLANCO C/PECANA (KILO) | D14: FAS | E14: 25 | F14: g | H14: 1/3 TAZA
C17: Decoración
A18: 96344 | B18: SE00032 | C18: CREMA DULCE LECHE KILO | D18: FAS | E18: 100 | F18: g | H18: ENCREMAR
A19: 96344 | B19: SE00032 | C19: CREMA DULCE LECHE KILO | D19: FAS | E19: 36 | F19: g | H19: COLOCHO BOQUILLA 842
A20: 908000032 | B20: SE00001 | C20: GANACHE CHOCOLATE OSCURO (KILO) | D20: FAS | E20: 3 | F20: g | H20: GOTAS
A21: 908000048 | B21: SE00087 | C21: GANACHE BAILEYS (KILO) | D21: FAS | E21: 55 | F21: g | H21: ESPEJO ARRIBA
A22: 10700013 | B22: MP10011 | C22: STICK DORADO (CAJA:100 UND) | D22: KAROL LEDEZMA | E22: 1 | F22: ud
C26: Empaque
A27: 1950692 | B27: EM10008 | C27: ORLA CARTON 10" DORADA (UND) | D27: RAPIBOX | E27: 1 | F27: ud
A28: 121603 | B28: EM10009 | C28: QUEQUERA RED BASE/DOMO 10 (CAJA:50) | D28: EXP PMT | E28: 1 | F28: ud
A29: 702069 | B29: EM10002 | C29: ETIQ.BLANCA 1 1/4 * 3/4 | D29: ETIPLAST | E29: 1 | F29: ud
A30: 702175 | B30: EM10006 | C30: ETIQUETA IMPRES SPOON GRANDE V-272 (UND) | D30: LITOGRAFIA CR | E30: 1 | F30: ud
A31: 702123 | B31: EM10011 | C31: ETIQUETA BLANCA 2 5/8X1 15/16 | D31: CEMSUA | E31: 1 | F31: ud
A32: 701096 | B32: EM10124 | C32: ETIQUETA BLANCA R-153 (UND) | D32: CEMSUA | E32: 1 | F32: ud
A33: 702167 | B33: EM10283 | C33: ETIQUETA D-31 TORTA BAILEYS (ROLLO) | D33: ETIPLAST | E33: 1 | F33: ud
H34: =UPPER(D34)
D37: Cantidad | E37: Unidad
A38: PESO TOTAL OBTENIDO | D38: 1000 | E38: g | F38: Tiempo de Horneo:
A39: TIEMPO TOTAL DE PREPARACION | D39: 6 | E39: min | F39: Horno:
A40: CANTIDAD DE PORCIONES OBTENIDAS | D40: 1 | E40: ud | F40: Temperatura de Horneo:
A41: PESO DE CADA PORCIÓN | D41: 1000 | E41: g | F41: Otros
A42: MERMA | D42: 23 | E42: g
A43: PROCEDIMIENTO DE PREPARACION DE LA RECETA
A44: 1.- Partir el rosquete por la mitad y humedecer ambas mitades
A45: 2.- Colocar en la capa el manjar, relleno de moka y la chocopecana.
A46: 3.- Tapar con rosquete humedecido.
A47: 4.- Encremar con crema de dulce de leche. Hacer el colocho marmoleado con la boquilla de 842.
...

Sheet Hoja2
A1: =Hoja1!I1 -> ESP-RE-DES-001 | B1: =Hoja1!C9 -> Ensamble | C1: =Hoja1!B10 -> SE00462 | D1: =+Hoja1!C10 -> ROSQUETE NUCLEO VAINILLA DAWN REDONDO 360G
A2: =+A1 -> ESP-RE-DES-001 | B2: =+B1 -> Ensamble | C2: =Hoja1!B11 -> SE00084 | D2: =+Hoja1!C11 -> MEZCLA TRES LECHES C/BAILEYS LITRO
A3: =+A2 -> ESP-RE-DES-001 | B3: =+B2 -> Ensamble | C3: =Hoja1!B12 -> MP10007 | D3: =+Hoja1!C12 -> MANJAR LECHE CONDENSADA (PAQ:6 K)
A4: =+A3 -> ESP-RE-DES-001 | B4: =+B3 -> Ensamble | C4: =Hoja1!B13 -> SE00085 | D4: =+Hoja1!C13 -> RELLENO CREMA MOKA C/BAILEYS (KILO)
A5: =+A4 -> ESP-RE-DES-001 | B5: =+B4 -> Ensamble | C5: =Hoja1!B14 -> SE00086 | D5: =+Hoja1!C14 -> MEZCLA CHOCOLATE BLANCO C/PECANA (KILO)
