Workbook

Sheet Costo de Relleno
E1: Precio Local | F1: Costo MP | G1: Costo EM | H1: Costo MO
E2: =IFERROR(O62,"") -> 4298.3273 | F2: =IFERROR(H53,"") -> 3702.1 | G2: =IFERROR(H54,"") -> 13 | H2: =IFERROR(H56,"") -> 318.5
A5: ESTRUCTURA DE COSTOS
F6: Fecha: | H6: =TODAY() -> 46034
A7: UNIDADES | B7: DESCRIPCION MAT.PRIMA | C7: UNIDADES | D7: UND MEDIDA | E7: COSTO UNITARIO | F7: TOTAL COSTO | G7: % PREC. DEFINIDO | H7: CODIGOS
A8: 1000 | B8: MANZANA PICADA | C8: =+A8 -> 1000 | D8: Gramos | E8: 3.45 | F8: =IFERROR(C8*E8,"") -> 3450 | G8: =IFERROR(F8/$F$66,"") -> 0.84205039 | H8: MP10625
A9: 3 | B9: Limon En Polvo | C9: =+A9 -> 3 | D9: Gramos | E9: 6 | F9: =IFERROR(C9*E9,"") -> 18 | G9: =IFERROR(F9/$F$66,"") -> 0.0043933064 | H9: MP10239
A10: 2 | B10: Canela En Polvo | C10: =+A10 -> 2 | D10: Gramos | E10: 6.8 | F10: =IFERROR(C10*E10,"") -> 13.6 | G10: =IFERROR(F10/$F$66,"") -> 0.003319387 | H10: MP10096
B11: =IFERROR(VLOOKUP(H11,'[1]Consolidado MP Planta'!$A$2:$M$823,3,0),"") | C11: =+A11 -> 0 | D11: =IFERROR(VLOOKUP(H11,'[1]Consolidado MP Planta'!$A$2:$M$823,13,0),"") | E11: =IFERROR(VLOOKUP(H11,'[1]Consolidado MP Planta'!$A$2:$M$823,12,0),"") | F11: =IFERROR(C11*E11,"") | G11: =IFERROR(F11/$F$66,"")
B12: =IFERROR(VLOOKUP(H12,'[1]Consolidado MP Planta'!$A$2:$M$823,3,0),"") | C12: =+A12 -> 0 | D12: =IFERROR(VLOOKUP(H12,'[1]Consolidado MP Planta'!$A$2:$M$823,13,0),"") | E12: =IFERROR(VLOOKUP(H12,'[1]Consolidado MP Planta'!$A$2:$M$823,12,0),"") | F12: =IFERROR(C12*E12,"") | G12: =IFERROR(F12/$F$66,"")
B13: =IFERROR(VLOOKUP(H13,'[1]Consolidado MP Planta'!$A$2:$M$823,3,0),"") | C13: =+A13 -> 0 | D13: =IFERROR(VLOOKUP(H13,'[1]Consolidado MP Planta'!$A$2:$M$823,13,0),"") | E13: =IFERROR(VLOOKUP(H13,'[1]Consolidado MP Planta'!$A$2:$M$823,12,0),"") | F13: =IFERROR(C13*E13,"") | G13: =IFERROR(F13/$F$66,"")
B14: =IFERROR(VLOOKUP(H14,'[1]Consolidado MP Planta'!$A$2:$M$823,3,0),"") | C14: =+A14 -> 0 | D14: =IFERROR(VLOOKUP(H14,'[1]Consolidado MP Planta'!$A$2:$M$823,13,0),"") | E14: =IFERROR(VLOOKUP(H14,'[1]Consolidado MP Planta'!$A$2:$M$823,12,0),"") | F14: =IFERROR(C14*E14,"") | G14: =IFERROR(F14/$F$66,"")
B15: =IFERROR(VLOOKUP(H15,'[2]ARTICULOS MP PLANTA'!$A$2:$G$589,2,0),"")
A16: UNIDADES | B16: MATERIA PRIMA SEMIELABORADOS | C16: UNIDADES | D16: UND MEDIDA | E16: COSTO UNITARIO | F16: TOTAL COSTO | G16: % PREC. DEFINIDO | H16: CODIGOS
A17: 250 | B17: Empaque Azucar Industrial | C17: =+A17 -> 250 | D17: Gramos | E17: 0.47 | F17: =IFERROR(E17*C17,"") -> 117.5 | G17: =IFERROR(F17/$F$66,"") -> 0.028678528 | H17: SE00016
A18: 50 | B18: Empaque Almidon Modificado | C18: =+A18 -> 50 | D18: Gramos | E18: 2.06 | F18: =IFERROR(E18*C18,"") -> 103 | G18: =IFERROR(F18/$F$66,"") -> 0.025139475 | H18: SE00014
B19: =IFERROR(VLOOKUP(H19,[1]SEMIELABORADOS!$A$2:$M$6000,2,0),"") | C19: =+A19 -> 0 | D19: =IFERROR(VLOOKUP(H19,[1]SEMIELABORADOS!$A$2:$M$6000,6,0),"") | E19: =IFERROR(VLOOKUP(H19,[1]SEMIELABORADOS!$A$2:$H$65536,8,0),"") | F19: =IFERROR(E19*C19,"") | G19: =IFERROR(F19/$F$66,"")
B20: =IFERROR(VLOOKUP(H20,[1]SEMIELABORADOS!$A$2:$M$6000,2,0),"") | C20: =+A20 -> 0 | D20: =IFERROR(VLOOKUP(H20,[1]SEMIELABORADOS!$A$2:$M$6000,6,0),"") | E20: =IFERROR(VLOOKUP(H20,[1]SEMIELABORADOS!$A$2:$H$65536,8,0),"") | F20: =IFERROR(E20*C20,"") | G20: =IFERROR(F20/$F$66,"")
B21: =IFERROR(VLOOKUP(H21,[1]SEMIELABORADOS!$A$2:$M$6000,2,0),"") | C21: =+A21 -> 0 | D21: =IFERROR(VLOOKUP(H21,[1]SEMIELABORADOS!$A$2:$M$6000,6,0),"") | E21: =IFERROR(VLOOKUP(H21,[1]SEMIELABORADOS!$A$2:$H$65536,8,0),"") | F21: =IFERROR(E21*C21,"") | G21: =IFERROR(F21/$F$66,"")
B22: =IFERROR(VLOOKUP(H22,[1]SEMIELABORADOS!$A$2:$M$6000,2,0),"") | C22: =+A22 -> 0 | D22: =IFERROR(VLOOKUP(H22,[1]SEMIELABORADOS!$A$2:$M$6000,6,0),"") | E22: =IFERROR(VLOOKUP(H22,[1]SEMIELABORADOS!$A$2:$H$65536,8,0),"") | F22: =IFERROR(E22*C22,"") | G22: =IFERROR(F22/$F$66,"")
B23: =IFERROR(VLOOKUP(H23,[1]SEMIELABORADOS!$A$2:$M$6000,2,0),"") | C23: =+A23 -> 0 | D23: =IFERROR(VLOOKUP(H23,[1]SEMIELABORADOS!$A$2:$M$6000,6,0),"") | E23: =IFERROR(VLOOKUP(H23,[1]SEMIELABORADOS!$A$2:$H$65536,8,0),"") | F23: =IFERROR(E23*C23,"") | G23: =IFERROR(F23/$F$66,"")
B24: =IFERROR(VLOOKUP(H24,[1]SEMIELABORADOS!$A$2:$M$6000,2,0),"") | C24: =+A24 -> 0 | D24: =IFERROR(VLOOKUP(H24,[1]SEMIELABORADOS!$A$2:$M$6000,6,0),"") | E24: =IFERROR(VLOOKUP(H24,[1]SEMIELABORADOS!$A$2:$H$65536,8,0),"") | F24: =IFERROR(E24*C24,"") | G24: =IFERROR(F24/$F$66,"")
A26: UNIDADES | B26: EMPAQUE | C26: UNIDADES | D26: UND MEDIDA | E26: COSTO UNITARIO | F26: TOTAL COSTO | G26: % PREC. DEFINIDO | H26: CODIGOS
A27: 0 | B27: =IFERROR(VLOOKUP(H27,'[1]Consolidado MP Planta'!$A$2:$M$823,3,0),"") | C27: =+A27 -> 0 | D27: =IFERROR(VLOOKUP(H27,'[1]Consolidado MP Planta'!$A$2:$M$823,13,0),"") | E27: =IFERROR(VLOOKUP(H27,'[1]Consolidado MP Planta'!$A$2:$M$823,12,0),"") | F27: =IFERROR(C27*E27,"") | G27: =IFERROR(F27/$F$66,"")
B28: =IFERROR(VLOOKUP(H28,'[1]Consolidado MP Planta'!$A$2:$M$823,3,0),"") | C28: =+A28 -> 0 | D28: =IFERROR(VLOOKUP(H28,'[1]Consolidado MP Planta'!$A$2:$M$823,13,0),"") | E28: =IFERROR(VLOOKUP(H28,'[1]Consolidado MP Planta'!$A$2:$M$823,12,0),"") | F28: =IFERROR(C28*E28,"") | G28: =IFERROR(F28/$F$66,"")
B29: =IFERROR(VLOOKUP(H29,'[1]Consolidado MP Planta'!$A$2:$M$823,3,0),"") | C29: =+A29 -> 0 | D29: =IFERROR(VLOOKUP(H29,'[1]Consolidado MP Planta'!$A$2:$M$823,13,0),"") | E29: =IFERROR(VLOOKUP(H29,'[1]Consolidado MP Planta'!$A$2:$M$823,12,0),"") | F29: =IFERROR(C29*E29,"") | G29: =IFERROR(F29/$F$66,"")
B30: =IFERROR(VLOOKUP(H30,'[1]Consolidado MP Planta'!$A$2:$M$823,3,0),"") | C30: =+A30 -> 0 | D30: =IFERROR(VLOOKUP(H30,'[1]Consolidado MP Planta'!$A$2:$M$823,13,0),"") | E30: =IFERROR(VLOOKUP(H30,'[1]Consolidado MP Planta'!$A$2:$M$823,12,0),"") | F30: =IFERROR(C30*E30,"") | G30: =IFERROR(F30/$F$66,"")
B31: =IFERROR(VLOOKUP(H31,'[1]Consolidado MP Planta'!$A$2:$M$823,3,0),"") | C31: =+A31 -> 0 | D31: =IFERROR(VLOOKUP(H31,'[1]Consolidado MP Planta'!$A$2:$M$823,13,0),"") | E31: =IFERROR(VLOOKUP(H31,'[1]Consolidado MP Planta'!$A$2:$M$823,12,0),"") | F31: =IFERROR(C31*E31,"") | G31: =IFERROR(F31/$F$66,"")
B32: =IFERROR(VLOOKUP(H32,'[1]Consolidado MP Planta'!$A$2:$M$823,3,0),"") | C32: =+A32 -> 0 | D32: =IFERROR(VLOOKUP(H32,'[1]Consolidado MP Planta'!$A$2:$M$823,13,0),"") | E32: =IFERROR(VLOOKUP(H32,'[1]Consolidado MP Planta'!$A$2:$M$823,12,0),"") | F32: =IFERROR(C32*E32,"") | G32: =IFERROR(F32/$F$66,"")
A34: UNIDADES | B34: EMPAQUE SEMIELABORADOS | C34: UNIDADES | D34: UND MEDIDA | E34: COSTO UNITARIO | F34: TOTAL COSTO | G34: % PREC. DEFINIDO | H34: CODIGOS
A35: =+A17 -> 250 | B35: Empaque Azucar Industrial | C35: =+A35 -> 250 | D35: Gramos | E35: 0.05 | F35: =IFERROR(E35*C35,"") -> 12.5 | G35: =IFERROR(F35/$F$66,"") -> 0.0030509072 | H35: SE00016
A36: =+A18 -> 50 | B36: Empaque Almidon Modificado | C36: =+A36 -> 50 | D36: Gramos | E36: 0.01 | F36: =IFERROR(E36*C36,"") -> 0.5 | G36: =IFERROR(F36/$F$66,"") -> 0.00012203629 | H36: SE00014
A37: =+A19 -> 0 | B37: =IFERROR(VLOOKUP(H37,[1]SEMIELABORADOS!$A$2:$M$6000,2,0),"") | C37: =+A37 -> 0 | D37: =IFERROR(VLOOKUP(H37,[1]SEMIELABORADOS!$A$2:$M$6000,6,0),"") | E37: =IFERROR(VLOOKUP(H37,[1]SEMIELABORADOS!$A$2:$M$65536,10,0),"") | F37: =IFERROR(E37*C37,"") | G37: =IFERROR(F37/$F$66,"")
A38: =+A20 -> 0 | B38: =IFERROR(VLOOKUP(H38,[1]SEMIELABORADOS!$A$2:$M$6000,2,0),"") | C38: =+A38 -> 0 | D38: =IFERROR(VLOOKUP(H38,[1]SEMIELABORADOS!$A$2:$M$6000,6,0),"") | E38: =IFERROR(VLOOKUP(H38,[1]SEMIELABORADOS!$A$2:$M$65536,10,0),"") | F38: =IFERROR(E38*C38,"") | G38: =IFERROR(F38/$F$66,"")
A39: =+A21 -> 0 | B39: =IFERROR(VLOOKUP(H39,[1]SEMIELABORADOS!$A$2:$M$6000,2,0),"") | C39: =+A39 -> 0 | D39: =IFERROR(VLOOKUP(H39,[1]SEMIELABORADOS!$A$2:$M$6000,6,0),"") | E39: =IFERROR(VLOOKUP(H39,[1]SEMIELABORADOS!$A$2:$M$65536,10,0),"") | F39: =IFERROR(E39*C39,"") | G39: =IFERROR(F39/$F$66,"")
A40: =+A22 -> 0 | B40: =IFERROR(VLOOKUP(H40,[1]SEMIELABORADOS!$A$2:$M$6000,2,0),"") | C40: =+A40 -> 0 | D40: =IFERROR(VLOOKUP(H40,[1]SEMIELABORADOS!$A$2:$M$6000,6,0),"") | E40: =IFERROR(VLOOKUP(H40,[1]SEMIELABORADOS!$A$2:$M$65536,10,0),"") | F40: =IFERROR(E40*C40,"") | G40: =IFERROR(F40/$F$66,"")
A41: =+A23 -> 0 | B41: =IFERROR(VLOOKUP(H41,[1]SEMIELABORADOS!$A$2:$M$6000,2,0),"") | C41: =+A41 -> 0 | D41: =IFERROR(VLOOKUP(H41,[1]SEMIELABORADOS!$A$2:$M$6000,6,0),"") | E41: =IFERROR(VLOOKUP(H41,[1]SEMIELABORADOS!$A$2:$M$65536,10,0),"") | F41: =IFERROR(E41*C41,"") | G41: =IFERROR(F41/$F$66,"")
A43: UNIDADES | B43: MODI | C43: UNIDADES | D43: UND MEDIDA | E43: COSTO UNITARIO | F43: TOTAL COSTO | G43: % PREC. DEFINIDO | H43: CODIGOS
A44: =+A35 -> 250 | B44: Empaque Azucar Industrial | C44: =+A44 -> 250 | D44: Gramos | E44: 0.04 | F44: =IFERROR(E44*C44,"") -> 10 | G44: =IFERROR(F44/$F$66,"") -> 0.0024407258 | H44: SE00016
A45: =+A36 -> 50 | B45: Empaque Almidon Modificado | C45: =+A45 -> 50 | D45: Gramos | E45: 0.01 | F45: =IFERROR(E45*C45,"") -> 0.5 | G45: =IFERROR(F45/$F$66,"") -> 0.00012203629 | H45: SE00014
...

Sheet Costo Crumble
E1: Precio Local | F1: Costo MP | G1: Costo EM | H1: Costo MO
E2: =IFERROR(O62,"") -> 4439.1169 | F2: =IFERROR(H53,"") -> 3916.5 | G2: =IFERROR(H54,"") -> 57.5 | H2: =IFERROR(H56,"") -> 254
A5: ESTRUCTURA DE COSTOS
F6: Fecha: | H6: =TODAY() -> 46034
A7: UNIDADES | B7: DESCRIPCION MAT.PRIMA | C7: UNIDADES | D7: UND MEDIDA | E7: COSTO UNITARIO | F7: TOTAL COSTO | G7: % PREC. DEFINIDO | H7: CODIGOS
A8: 750 | B8: Harina Silver Cake | C8: =+A8 -> 750 | D8: Gramos | E8: 0.52 | F8: =IFERROR(C8*E8,"") -> 390 | G8: =IFERROR(F8/$F$66,"") -> 0.091050655 | H8: MP10478
A9: 450 | B9: Nucleo Vainilla Dawn | C9: =+A9 -> 450 | D9: Gramos | E9: 2.09 | F9: =IFERROR(C9*E9,"") -> 940.5 | G9: =IFERROR(F9/$F$66,"") -> 0.21957216 | H9: MP10493
A10: 1500 | B10: Margarina Bloque | C10: =+A10 -> 1500 | D10: Gramos | E10: 1.22 | F10: =IFERROR(C10*E10,"") -> 1830 | G10: =IFERROR(F10/$F$66,"") -> 0.42723769 | H10: MP10530
A11: 30 | B11: Canela En Polvo | C11: =+A11 -> 30 | D11: Gramos | E11: 6.8 | F11: =IFERROR(C11*E11,"") -> 204 | G11: =IFERROR(F11/$F$66,"") -> 0.047626496 | H11: MP10096
B12: =IFERROR(VLOOKUP(H12,'[1]Consolidado MP Planta'!$A$2:$M$823,3,0),"") | C12: =+A12 -> 0 | D12: =IFERROR(VLOOKUP(H12,'[1]Consolidado MP Planta'!$A$2:$M$823,13,0),"") | E12: =IFERROR(VLOOKUP(H12,'[1]Consolidado MP Planta'!$A$2:$M$823,12,0),"") | F12: =IFERROR(C12*E12,"") | G12: =IFERROR(F12/$F$66,"")
B13: =IFERROR(VLOOKUP(H13,'[1]Consolidado MP Planta'!$A$2:$M$823,3,0),"") | C13: =+A13 -> 0 | D13: =IFERROR(VLOOKUP(H13,'[1]Consolidado MP Planta'!$A$2:$M$823,13,0),"") | E13: =IFERROR(VLOOKUP(H13,'[1]Consolidado MP Planta'!$A$2:$M$823,12,0),"") | F13: =IFERROR(C13*E13,"") | G13: =IFERROR(F13/$F$66,"")
B14: =IFERROR(VLOOKUP(H14,'[1]Consolidado MP Planta'!$A$2:$M$823,3,0),"") | C14: =+A14 -> 0 | D14: =IFERROR(VLOOKUP(H14,'[1]Consolidado MP Planta'!$A$2:$M$823,13,0),"") | E14: =IFERROR(VLOOKUP(H14,'[1]Consolidado MP Planta'!$A$2:$M$823,12,0),"") | F14: =IFERROR(C14*E14,"") | G14: =IFERROR(F14/$F$66,"")
B15: =IFERROR(VLOOKUP(H15,'[2]ARTICULOS MP PLANTA'!$A$2:$G$589,2,0),"")
A16: UNIDADES | B16: MATERIA PRIMA SEMIELABORADOS | C16: UNIDADES | D16: UND MEDIDA | E16: COSTO UNITARIO | F16: TOTAL COSTO | G16: % PREC. DEFINIDO | H16: CODIGOS
A17: 1150 | B17: Empaque Azucar Industrial | C17: =+A17 -> 1150 | D17: Gramos | E17: 0.48 | F17: =IFERROR(E17*C17,"") -> 552 | G17: =IFERROR(F17/$F$66,"") -> 0.1288717 | H17: SE00016
B18: =IFERROR(VLOOKUP(H18,[1]SEMIELABORADOS!$A$2:$M$6000,2,0),"") | C18: =+A18 -> 0 | D18: =IFERROR(VLOOKUP(H18,[1]SEMIELABORADOS!$A$2:$M$6000,6,0),"") | E18: =IFERROR(VLOOKUP(H18,[1]SEMIELABORADOS!$A$2:$H$65536,8,0),"") | F18: =IFERROR(E18*C18,"") | G18: =IFERROR(F18/$F$66,"")
B19: =IFERROR(VLOOKUP(H19,[1]SEMIELABORADOS!$A$2:$M$6000,2,0),"") | C19: =+A19 -> 0 | D19: =IFERROR(VLOOKUP(H19,[1]SEMIELABORADOS!$A$2:$M$6000,6,0),"") | E19: =IFERROR(VLOOKUP(H19,[1]SEMIELABORADOS!$A$2:$H$65536,8,0),"") | F19: =IFERROR(E19*C19,"") | G19: =IFERROR(F19/$F$66,"")
B20: =IFERROR(VLOOKUP(H20,[1]SEMIELABORADOS!$A$2:$M$6000,2,0),"") | C20: =+A20 -> 0 | D20: =IFERROR(VLOOKUP(H20,[1]SEMIELABORADOS!$A$2:$M$6000,6,0),"") | E20: =IFERROR(VLOOKUP(H20,[1]SEMIELABORADOS!$A$2:$H$65536,8,0),"") | F20: =IFERROR(E20*C20,"") | G20: =IFERROR(F20/$F$66,"")
B21: =IFERROR(VLOOKUP(H21,[1]SEMIELABORADOS!$A$2:$M$6000,2,0),"") | C21: =+A21 -> 0 | D21: =IFERROR(VLOOKUP(H21,[1]SEMIELABORADOS!$A$2:$M$6000,6,0),"") | E21: =IFERROR(VLOOKUP(H21,[1]SEMIELABORADOS!$A$2:$H$65536,8,0),"") | F21: =IFERROR(E21*C21,"") | G21: =IFERROR(F21/$F$66,"")
B22: =IFERROR(VLOOKUP(H22,[1]SEMIELABORADOS!$A$2:$M$6000,2,0),"") | C22: =+A22 -> 0 | D22: =IFERROR(VLOOKUP(H22,[1]SEMIELABORADOS!$A$2:$M$6000,6,0),"") | E22: =IFERROR(VLOOKUP(H22,[1]SEMIELABORADOS!$A$2:$H$65536,8,0),"") | F22: =IFERROR(E22*C22,"") | G22: =IFERROR(F22/$F$66,"")
B23: =IFERROR(VLOOKUP(H23,[1]SEMIELABORADOS!$A$2:$M$6000,2,0),"") | C23: =+A23 -> 0 | D23: =IFERROR(VLOOKUP(H23,[1]SEMIELABORADOS!$A$2:$M$6000,6,0),"") | E23: =IFERROR(VLOOKUP(H23,[1]SEMIELABORADOS!$A$2:$H$65536,8,0),"") | F23: =IFERROR(E23*C23,"") | G23: =IFERROR(F23/$F$66,"")
B24: =IFERROR(VLOOKUP(H24,[1]SEMIELABORADOS!$A$2:$M$6000,2,0),"") | C24: =+A24 -> 0 | D24: =IFERROR(VLOOKUP(H24,[1]SEMIELABORADOS!$A$2:$M$6000,6,0),"") | E24: =IFERROR(VLOOKUP(H24,[1]SEMIELABORADOS!$A$2:$H$65536,8,0),"") | F24: =IFERROR(E24*C24,"") | G24: =IFERROR(F24/$F$66,"")
A26: UNIDADES | B26: EMPAQUE | C26: UNIDADES | D26: UND MEDIDA | E26: COSTO UNITARIO | F26: TOTAL COSTO | G26: % PREC. DEFINIDO | H26: CODIGOS
A27: 0 | B27: =IFERROR(VLOOKUP(H27,'[1]Consolidado MP Planta'!$A$2:$M$823,3,0),"") | C27: =+A27 -> 0 | D27: =IFERROR(VLOOKUP(H27,'[1]Consolidado MP Planta'!$A$2:$M$823,13,0),"") | E27: =IFERROR(VLOOKUP(H27,'[1]Consolidado MP Planta'!$A$2:$M$823,12,0),"") | F27: =IFERROR(C27*E27,"") | G27: =IFERROR(F27/$F$66,"")
B28: =IFERROR(VLOOKUP(H28,'[1]Consolidado MP Planta'!$A$2:$M$823,3,0),"") | C28: =+A28 -> 0 | D28: =IFERROR(VLOOKUP(H28,'[1]Consolidado MP Planta'!$A$2:$M$823,13,0),"") | E28: =IFERROR(VLOOKUP(H28,'[1]Consolidado MP Planta'!$A$2:$M$823,12,0),"") | F28: =IFERROR(C28*E28,"") | G28: =IFERROR(F28/$F$66,"")
B29: =IFERROR(VLOOKUP(H29,'[1]Consolidado MP Planta'!$A$2:$M$823,3,0),"") | C29: =+A29 -> 0 | D29: =IFERROR(VLOOKUP(H29,'[1]Consolidado MP Planta'!$A$2:$M$823,13,0),"") | E29: =IFERROR(VLOOKUP(H29,'[1]Consolidado MP Planta'!$A$2:$M$823,12,0),"") | F29: =IFERROR(C29*E29,"") | G29: =IFERROR(F29/$F$66,"")
B30: =IFERROR(VLOOKUP(H30,'[1]Consolidado MP Planta'!$A$2:$M$823,3,0),"") | C30: =+A30 -> 0 | D30: =IFERROR(VLOOKUP(H30,'[1]Consolidado MP Planta'!$A$2:$M$823,13,0),"") | E30: =IFERROR(VLOOKUP(H30,'[1]Consolidado MP Planta'!$A$2:$M$823,12,0),"") | F30: =IFERROR(C30*E30,"") | G30: =IFERROR(F30/$F$66,"")
B31: =IFERROR(VLOOKUP(H31,'[1]Consolidado MP Planta'!$A$2:$M$823,3,0),"") | C31: =+A31 -> 0 | D31: =IFERROR(VLOOKUP(H31,'[1]Consolidado MP Planta'!$A$2:$M$823,13,0),"") | E31: =IFERROR(VLOOKUP(H31,'[1]Consolidado MP Planta'!$A$2:$M$823,12,0),"") | F31: =IFERROR(C31*E31,"") | G31: =IFERROR(F31/$F$66,"")
B32: =IFERROR(VLOOKUP(H32,'[1]Consolidado MP Planta'!$A$2:$M$823,3,0),"") | C32: =+A32 -> 0 | D32: =IFERROR(VLOOKUP(H32,'[1]Consolidado MP Planta'!$A$2:$M$823,13,0),"") | E32: =IFERROR(VLOOKUP(H32,'[1]Consolidado MP Planta'!$A$2:$M$823,12,0),"") | F32: =IFERROR(C32*E32,"") | G32: =IFERROR(F32/$F$66,"")
A34: UNIDADES | B34: EMPAQUE SEMIELABORADOS | C34: UNIDADES | D34: UND MEDIDA | E34: COSTO UNITARIO | F34: TOTAL COSTO | G34: % PREC. DEFINIDO | H34: CODIGOS
A35: =+A17 -> 1150 | B35: Empaque Azucar Industrial | C35: =+A35 -> 1150 | D35: Gramos | E35: 0.05 | F35: =IFERROR(E35*C35,"") -> 57.5 | G35: =IFERROR(F35/$F$66,"") -> 0.013424135 | H35: SE00016
A36: =+A18 -> 0 | B36: =IFERROR(VLOOKUP(H36,[1]SEMIELABORADOS!$A$2:$M$6000,2,0),"") | C36: =+A36 -> 0 | D36: =IFERROR(VLOOKUP(H36,[1]SEMIELABORADOS!$A$2:$M$6000,6,0),"") | E36: =IFERROR(VLOOKUP(H36,[1]SEMIELABORADOS!$A$2:$M$65536,10,0),"") | F36: =IFERROR(E36*C36,"") | G36: =IFERROR(F36/$F$66,"")
A37: =+A19 -> 0 | B37: =IFERROR(VLOOKUP(H37,[1]SEMIELABORADOS!$A$2:$M$6000,2,0),"") | C37: =+A37 -> 0 | D37: =IFERROR(VLOOKUP(H37,[1]SEMIELABORADOS!$A$2:$M$6000,6,0),"") | E37: =IFERROR(VLOOKUP(H37,[1]SEMIELABORADOS!$A$2:$M$65536,10,0),"") | F37: =IFERROR(E37*C37,"") | G37: =IFERROR(F37/$F$66,"")
A38: =+A20 -> 0 | B38: =IFERROR(VLOOKUP(H38,[1]SEMIELABORADOS!$A$2:$M$6000,2,0),"") | C38: =+A38 -> 0 | D38: =IFERROR(VLOOKUP(H38,[1]SEMIELABORADOS!$A$2:$M$6000,6,0),"") | E38: =IFERROR(VLOOKUP(H38,[1]SEMIELABORADOS!$A$2:$M$65536,10,0),"") | F38: =IFERROR(E38*C38,"") | G38: =IFERROR(F38/$F$66,"")
A39: =+A21 -> 0 | B39: =IFERROR(VLOOKUP(H39,[1]SEMIELABORADOS!$A$2:$M$6000,2,0),"") | C39: =+A39 -> 0 | D39: =IFERROR(VLOOKUP(H39,[1]SEMIELABORADOS!$A$2:$M$6000,6,0),"") | E39: =IFERROR(VLOOKUP(H39,[1]SEMIELABORADOS!$A$2:$M$65536,10,0),"") | F39: =IFERROR(E39*C39,"") | G39: =IFERROR(F39/$F$66,"")
A40: =+A22 -> 0 | B40: =IFERROR(VLOOKUP(H40,[1]SEMIELABORADOS!$A$2:$M$6000,2,0),"") | C40: =+A40 -> 0 | D40: =IFERROR(VLOOKUP(H40,[1]SEMIELABORADOS!$A$2:$M$6000,6,0),"") | E40: =IFERROR(VLOOKUP(H40,[1]SEMIELABORADOS!$A$2:$M$65536,10,0),"") | F40: =IFERROR(E40*C40,"") | G40: =IFERROR(F40/$F$66,"")
A41: =+A23 -> 0 | B41: =IFERROR(VLOOKUP(H41,[1]SEMIELABORADOS!$A$2:$M$6000,2,0),"") | C41: =+A41 -> 0 | D41: =IFERROR(VLOOKUP(H41,[1]SEMIELABORADOS!$A$2:$M$6000,6,0),"") | E41: =IFERROR(VLOOKUP(H41,[1]SEMIELABORADOS!$A$2:$M$65536,10,0),"") | F41: =IFERROR(E41*C41,"") | G41: =IFERROR(F41/$F$66,"")
A43: UNIDADES | B43: MODI | C43: UNIDADES | D43: UND MEDIDA | E43: COSTO UNITARIO | F43: TOTAL COSTO | G43: % PREC. DEFINIDO | H43: CODIGOS
A44: =+A35 -> 1150 | B44: Empaque Azucar Industrial | C44: =+A44 -> 1150 | D44: Gramos | E44: 0.02 | F44: =IFERROR(E44*C44,"") -> 23 | G44: =IFERROR(F44/$F$66,"") -> 0.005369654 | H44: SE00016
A45: =+A36 -> 0 | B45: =IFERROR(VLOOKUP(H45,[1]SEMIELABORADOS!$A$2:$M$6000,2,0),"") | C45: =+A45 -> 0 | D45: =IFERROR(VLOOKUP(H45,[1]SEMIELABORADOS!$A$2:$M$6000,6,0),"") | E45: =IFERROR(VLOOKUP(H45,[1]SEMIELABORADOS!$A$2:$M$65536,12,0),"") | F45: =IFERROR(E45*C45,"") | G45: =IFERROR(F45/$F$66,"")
...

Sheet Leche cond cocinada dura
C1: SERVICIOS DE PASTELERIA S.A. | H1: CÓDIGO: | I1: ESP-RE-COCS-066
C2: ESPECIFICACION DE RECETA | H2: REVISIÓN: | I2: 01
C3: 90100409 (SE00572) Leche condensada cocinada Dura | H3: FECHA DE APROBACIÓN: | I3: 45609
C4: Elaborado | D4: Javier Tong, Chef
C5: Aprobado | D5: Esteban Cartin, Gte Manufactura
A6: AREA QUE PRODUCE: | D6: Cocina | G6: AREA QUE EMPACA: | I6: Empaque
A7: # Código | B7: # Código Netsuite | C7: Descripción del ingrediente | D7: Marca | E7: Unidad Internacional | G7: Medida alternativa | I7: Costo - Referencia
E8: Cantidad | F8: Unidad medida | G8: Cantidad | H8: Unidad medida | I8: Colones
C9: Ensamble
A10: 505605 | B10: MP10477 | C10: LATA LECHE CONDENSADA | D10: NESTLE | E10: 204 | F10: ud
A11: 10415 | C11: AGUA POTABLE (PLANTA) | D11: FAS | E11: 60000 | F11: g
C27: Decoración
C33: Empaque
A34: 702069 | B34: EM10002 | C34: ETIQ.BLANCA 1 1/4 * 3/4 (UND) | E34: 208 | F34: ud
D44: Cantidad | E44: Unidad
A45: PESO TOTAL OBTENIDO | D45: 80580 | E45: ud | F45: Tiempo de Horneo:
A46: TIEMPO TOTAL DE PREPARACION | D46: 75 | E46: min | F46: Horno:
A47: CANTIDAD DE PORCIONES OBTENIDAS | D47: 4.25 | E47: cajas | F47: Temperatura de Horneo:
A48: PESO DE CADA PORCIÓN | D48: 18960 | E48: g | F48: Otros
A49: MERMA | D49: 60000 | E49: g
A50: PROCEDIMIENTO DE PREPARACION DE LA RECETA
A51: 1, Retirar las etiquetas de cada lata de leche condensada
A52: 2, Colocar las latas en la marmita (sin aspas). Cerrar a presion.
A53: #, Cocinar en programa "Leche Cocinada dura"
A54: 4, Retirar con mucho cuidado el tapon para liberar presion. Luego que ya este liberada toda la presion, proceder a abrir la olla.
A55: 5, Con ayuda de una pinza o guantes colocar las latas en una caja esperar a que se sequen, Etiquetar con fecha de vencimiento.
A56: 6, Empacar en las mismas cajas en las que llegaron y etiquetar con fecha de vencimeinto la caja tambien
A62: CONTROL DE CAMBIOS

Sheet Trasvasado leche cond
C1: SERVICIOS DE PASTELERIA S.A. | H1: CÓDIGO: | I1: ESP-RE-COCS-058
C2: ESPECIFICACION DE RECETA | H2: REVISIÓN: | I2: 01
C3: SE00386 TRASVASADO LECHE CONDENSADA COCINADA | H3: FECHA DE APROBACIÓN: | I3: 45609
C4: Elaborado | D4: Javier Tong, Chef
C5: Aprobado | D5: Esteban Cartin, Gte Manufactura
A6: AREA QUE PRODUCE: | D6: Cocina | G6: AREA QUE EMPACA: | I6: Cocina
A7: # Código | B7: # Código Netsuite | C7: Descripción del ingrediente | D7: Marca | E7: Unidad Internacional | G7: Medida alternativa | I7: Costo - Referencia
E8: Cantidad | F8: Unidad medida | G8: Cantidad | H8: Unidad medida | I8: Colones
C9: Ensamble
A10: 90100409 | B10: SE00572 | C10: LECHE CONDENSADA COCINADA DURA | D10: FAS | E10: 43 | F10: Latas | G10: =+E10*395 -> 16985 | H10: GRAMOS
C27: Decoración
C33: Empaque
A34: 702123 | B34: EM10011 | C34: ETIQUETA BLANCA 2 5/8X1 15/16 (UND) | D34: ETIPLAST | E34: 4 | F34: ud
A35: 51600050 | B35: EM10307 | C35: BOLSA MARMITA 14 x 20 (KILO) | E35: 4 | F35: ud
D44: Cantidad | E44: Unidad
A45: PESO TOTAL OBTENIDO | D45: 16000 | E45: g | F45: Tiempo de Horneo:
A46: TIEMPO TOTAL DE PREPARACION | D46: 15 | E46: min | F46: Horno:
A47: CANTIDAD DE PORCIONES OBTENIDAS | D47: 4 | E47: bolsas | F47: Temperatura de Horneo:
A48: PESO DE CADA PORCIÓN | D48: 4000 | E48: g | F48: Otros
A49: MERMA | D49: 985 | E49: g
A50: PROCEDIMIENTO DE PREPARACION DE LA RECETA
A51: 1, Abril las latas de leche condensada y con ayuda de una espatula colocar el contenido en bolsas de 4 kg.
A52: 2, hacer nudo y etiquetar
A53: =D46/D45 -> 0.0009375
A62: CONTROL DE CAMBIOS

Sheet Premez pasta Chilena 
C1: SERVICIOS DE PASTELERIA S.A. | H1: CÓDIGO: | I1: ESP-RE-PRES-008
C2: ESPECIFICACION DE RECETA | H2: REVISIÓN: | I2: 01
C3: PREMEZCLA P/PASTA CHILENA SPOON 901000014(SE00178) | H3: FECHA DE APROBACIÓN: | I3: 45616
C4: Elaborado | D4: Javier Tong, Chef
C5: Aprobado | D5: Esteban Cartin, Gte Manufactura
A6: AREA QUE PRODUCE: | D6: Premezclas | G6: AREA QUE EMPACA: | I6: Premezclas
A7: # Código | B7: # Código Netsuite | C7: Descripción del ingrediente | D7: Marca | E7: Unidad Internacional | G7: Medida alternativa | I7: Costo - Referencia
E8: Cantidad | F8: Unidad medida | G8: Cantidad | H8: Unidad medida | I8: Colones
C9: Ensamble
B10: MP10040 | C10: MARGARINA BAKER TABLETA (CAJA: 25 K) | D10: NUMAR | E10: 9000 | F10: g
B11: MP10049 | C11: AZUCAR POLVO P.REAL (PAQ:2.5 Kg) | D11: PASTELERO REAL | E11: 1 | F11: Bolsa
B12: MP10051 | C12: HARINA TRIGO NACARINA (SACO: 25 K) | D12: NACARINA | E12: 12000 | F12: g
B13: MP10008 | C13: PRESERVANTE 1047S (PAQ=5 KILO) | D13: ASEAL | E13: 24 | F13: g
C18: Decoración
C25: Empaque
B26: EM10011 | C26: ETIQUETA BLANCA 2 5/8X1 15/16 (UND) | D26: ETIPLAST | E26: 2 | F26: ud
B27: EM10013 | C27: BOLSA 17x25 TRANSP | D27: PLASTICOS P | E27: 2 | F27: ud
B28: EM10133 | C28: ETIQUETA ROJA LETRA ALERJENO (UND) | D28: ETIPLAST | E28: 1 | F28: ud
B29: AS00020 | C29: GUANTE LATEX CORRIENTE (CAJA:100 UND) | D29: MAYCA | E29: 2 | F29: ud
D38: Cantidad | E38: Unidad
A39: PESO TOTAL OBTENIDO | D39: 23524 | E39: g | F39: Tiempo de Horneo:
A40: TIEMPO TOTAL DE PREPARACION | D40: 0.14583333 | E40: Minutos | F40: Horno:
A41: CANTIDAD DE PORCIONES OBTENIDAS | D41: 1 | E41: Tanda | F41: Temperatura de Horneo:
A42: PESO DE CADA PORCIÓN | D42: 23524 | E42: g | F42: Otros
A43: MERMA | D43: 0 | E43: g
A44: PROCEDIMIENTO DE PREPARACION DE LA RECETA
A45: 1.- Colocar en 1 bolsa 17*25 la margarina. Etiquetar con nombre y alerjeno
A46: 2.- Colocar la harina, preservante en otra bolsa 17*25, enviar 1 bolsa de azucar en polvo entera.
A47: 3.- Etiquetar ambas bolsas con nombre y alerjeno.
A53: CONTROL DE CAMBIOS

Sheet Pasta Galleta Chilena 
C1: SERVICIOS DE PASTELERIA S.A. | H1: CÓDIGO: | I1: ESP-RE-PAPS-011
C2: ESPECIFICACION DE RECETA | H2: REVISIÓN: | I2: 01
C3: PASTA TORTA CHILENA SPOON KILO SE00177 | H3: FECHA DE APROBACIÓN: | I3: 45611
C4: Elaborado | D4: Javier Tong, Chef
C5: Aprobado | D5: Esteban Cartin, Gte Manufactura
A6: AREA QUE PRODUCE: | D6: Pastas | G6: AREA QUE EMPACA: | I6: Pastas
A7: # Código | B7: # Código Netsuite | C7: Descripción del ingrediente | D7: Marca | E7: Unidad Internacional | G7: Medida alternativa | I7: Costo - Referencia
E8: Cantidad | F8: Unidad medida | G8: Cantidad | H8: Unidad medida | I8: Colones
C9: Ensamble
A10: 901000014 | B10: SE00178 | C10: PREMEZCLA P/PASTA CHILENA SPOON | D10: Spoon | E10: 23524 | F10: g
C16: Decoración
C22: Empaque
D33: Cantidad | E33: Unidad
A34: PESO TOTAL OBTENIDO | D34: 23300 | E34: g | F34: Tiempo de Horneo: | H34: 60 min
A35: TIEMPO TOTAL DE PREPARACION | D35: 8 | E35: min | F35: Horno: | H35: Dicte 1,2,3
A36: CANTIDAD DE PORCIONES OBTENIDAS | D36: 1 | E36: Tanda | F36: Temperatura de Horneo: | H36: 185 C
A37: PESO DE CADA PORCIÓN | D37: 23300 | E37: g | F37: Otros
A38: MERMA | D38: 224 | E38: g
A39: PROCEDIMIENTO DE PREPARACION DE LA RECETA
A40: 1.- Colocar la margarina, azucar y harina y preservante. Batir en velocidad 1 por 3 minutos, con ayuda de la paleta.
A41: 2.- Utilizar de inmediato.
A49: CONTROL DE CAMBIOS

Sheet Corte Galleta Chilena 
C1: SERVICIOS DE PASTELERIA S.A. | H1: CÓDIGO: | I1: ESP-RE-PAPS-002
C2: ESPECIFICACION DE RECETA | H2: REVISIÓN: | I2: 01
C3: Corte Galleta Chilena Grande 143g 906000002(SE00204) | H3: FECHA DE APROBACIÓN: | I3: 45611
C4: Elaborado | D4: Javier Tong, Chef
C5: Aprobado | D5: Esteban Cartin, Gte Manufactura
A6: AREA QUE PRODUCE: | D6: Pastas | G6: AREA QUE EMPACA: | I6: Pastas
A7: # Código | B7: # Código Netsuite | C7: Descripción del ingrediente | D7: Marca | E7: Unidad Internacional | G7: Medida alternativa | I7: Costo - Referencia
E8: Cantidad | F8: Unidad medida | G8: Cantidad | H8: Unidad medida | I8: Colones
C9: Ensamble
A10: 906000035 | B10: SE00177 | C10: PASTA TORTA CHILENA SPOON KILO | D10: FAS | E10: 1001 | F10: g
A11: 90100137 | B11: SE00183 | C11: EMPAQUE HARINA ESTANDAR (KILO) | D11: FAS | E11: 20 | F11: g
C18: Decoración
C24: Empaque
D35: Cantidad | E35: Unidad
A36: PESO TOTAL OBTENIDO | D36: 1001 | E36: g | F36: Tiempo de Horneo:
A37: TIEMPO TOTAL DE PREPARACION | D37: 2 | E37: min | F37: Horno:
A38: CANTIDAD DE PORCIONES OBTENIDAS | D38: 7 | E38: Galletas | F38: Temperatura de Horneo:
A39: PESO DE CADA PORCIÓN | D39: 143 | E39: g | F39: Otros
A40: MERMA | D40: 0 | E40: g
A41: PROCEDIMIENTO DE PREPARACION DE LA RECETA
A42: 1-. Laminar la masa hasta 4 mm con ayuda e la maquina, hacer huecos con el zorro. En la laminadora Rondo a 2.8, en la laminadora Kemplex 3.
A43: 2-. Cortar con cortador redondo de 23 cm diametro y colocar los 7 circulos en la bandeja
A44: 3-. Llevar al horno en Dicte 1 por 23 min a 170°C o Dicte 2 por 22 a 24 min a 170°C.
A45: 4-. Enfriar.
A51: CONTROL DE CAMBIOS

Sheet Base de galleta para CK
C1: SERVICIOS DE PASTELERIA S.A. | H1: CÓDIGO: | I1: ESP-RE-POS-031
C2: ESPECIFICACION DE RECETA | H2: REVISIÓN: | I2: 15
C3: Base Galleta Cheesecake SE00041 | H3: FECHA DE APROBACIÓN: | I3: 45546
C4: Elaborado | D4: Javier Tong, Chef
C5: Aprobado | D5: Esteban Cartin, Gte Manufactura
A6: AREA QUE PRODUCE: | D6: Postres | G6: AREA QUE EMPACA: | I6: Postres
A7: # Código | B7: # Codigo Netsuite | C7: Descripción del ingrediente | D7: Marca | E7: Unidad Internacional | G7: Medida Costos | I7: Costo - Referencia
E8: Cantidad | F8: Unidad medida | G8: Cantidad | H8: Unidad medida | I8: Colones
A9: 10100344 | B9: MP10523 | C9: GALLETA SODA MOLIDA (PAQ:1 KILO) | D9: POZUELO | E9: 2500 | F9: g
A10: 10100345 | B10: MP10555 | C10: GALLETA YEMITA (KILO) | D10: POZUELO | E10: 1500 | F10: g
A11: 906000002 | B11: SE00204 | C11: Corte Galleta Chilena Grande | D11: FAS | E11: 1000 | F11: g | G11: RECORTE DE CHILENA
A12: 0310107 | B12: MP10022 | C12: LACTOCREMA GRANEL (CAJA:25 KG) | D12: DOS PINOS | E12: 3000 | F12: g
A13: 101000073 | B13: MP10041 | C13: AZUCAR GLASS MOLIDA (PAQ: 4 K) | E13: 1400 | F13: g
A14: 1212410 | B14: MP10008 | C14: PRESERVANTE 1047S (PAQ=5 KILO) | E14: 10 | F14: g
D17: Cantidad | E17: Unidad
A18: PESO TOTAL OBTENIDO | D18: 9000 | E18: g | F18: TIEMPO DE HORNEO
A19: TIEMPO TOTAL DE PREPARACION | D19: 15 | E19: min | F19: HORNO
A20: CANTIDAD DE PORCIONES OBTENIDAS | D20: =D18/D21 -> 1 | E20: Tanda | F20: TEMPERATURA HORNEO | H20: =15/9 -> 1.6666667
A21: PESO DE CADA PORCIÓN | D21: 9000 | E21: g | F21: OTROS
A22: MERMA | D22: =SUM(E9:E15)-D18 -> 410 | E22: g
A23: PROCEDIMIENTO DE PREPARACION DE LA RECETA
A24: 1.- Derretir la lactocrema. No hervir.
A25: 2.- Mezclar todos los ingredientes en un bowl con el azucar en polvo.
A26: 2, Mezclar la galletas procesada con el azucar y la lactocrema, en batidora con paleta, hasta homogeneo.
A28: CONTROL DE CAMBIOS
A30: Revisión #9: Actualización de codigos
A31: Revisión #10: Actualizacion de peso final, y productos de reproceso.
A32: Revisión #11: Actualizacion completa por cambio de galletas y rendimiento.
A33: Revision #12: Actualizacion del peso de la lactocrema y el rendimiento.
A34: Revision #13: Se elimina galleta Maria y se agrega recorte de galleta chilena Spoon
A35: Revision #14: Se le bajo Lactocrema
A36: Revisión# 15:Se le aumenta la cantidad de lactocrema a la receta

Sheet Costo Mousse de Queso
E1: Precio Local | F1: Costo MP | G1: Costo EM | H1: Costo MO
E2: =IFERROR(O62,"") -> 17151.629 | F2: =IFERROR(H53,"") -> 14803.2 | G2: =IFERROR(H54,"") -> 32 | H2: =IFERROR(H56,"") -> 1265
A5: ESTRUCTURA DE COSTOS
F6: Fecha: | H6: =TODAY() -> 46034
A7: UNIDADES | B7: DESCRIPCION MAT.PRIMA | C7: UNIDADES | D7: UND MEDIDA | E7: COSTO UNITARIO | F7: TOTAL COSTO | G7: % PREC. DEFINIDO | H7: CODIGOS
A8: 2000 | B8: Crema Prestige Grand | C8: =+A8 -> 2000 | D8: Gramos | E8: 2.03 | F8: =IFERROR(C8*E8,"") -> 4060 | G8: =IFERROR(F8/$F$66,"") -> 0.26166093 | H8: MP10048
A9: 1800 | B9: Queso Crema Panadero | C9: =+A9 -> 1800 | D9: Gramos | E9: 3.07 | F9: =IFERROR(C9*E9,"") -> 5526 | G9: =IFERROR(F9/$F$66,"") -> 0.35614243 | H9: MP10046
A10: 20 | B10: Canela En Polvo | C10: =+A10 -> 20 | D10: Gramos | E10: 6.8 | F10: =IFERROR(C10*E10,"") -> 136 | G10: =IFERROR(F10/$F$66,"") -> 0.0087649965 | H10: MP10096
A11: 120 | B11: Gelatina Pura | C11: =+A11 -> 120 | D11: Gramos | E11: 13.01 | F11: =IFERROR(C11*E11,"") -> 1561.2 | G11: =IFERROR(F11/$F$66,"") -> 0.100617 | H11: MP10043
B12: =IFERROR(VLOOKUP(H12,'[1]Consolidado MP Planta'!$A$2:$M$823,3,0),"") | C12: =+A12 -> 0 | D12: =IFERROR(VLOOKUP(H12,'[1]Consolidado MP Planta'!$A$2:$M$823,13,0),"") | E12: =IFERROR(VLOOKUP(H12,'[1]Consolidado MP Planta'!$A$2:$M$823,12,0),"") | F12: =IFERROR(C12*E12,"") | G12: =IFERROR(F12/$F$66,"")
B13: =IFERROR(VLOOKUP(H13,'[1]Consolidado MP Planta'!$A$2:$M$823,3,0),"") | C13: =+A13 -> 0 | D13: =IFERROR(VLOOKUP(H13,'[1]Consolidado MP Planta'!$A$2:$M$823,13,0),"") | E13: =IFERROR(VLOOKUP(H13,'[1]Consolidado MP Planta'!$A$2:$M$823,12,0),"") | F13: =IFERROR(C13*E13,"") | G13: =IFERROR(F13/$F$66,"")
B14: =IFERROR(VLOOKUP(H14,'[1]Consolidado MP Planta'!$A$2:$M$823,3,0),"") | C14: =+A14 -> 0 | D14: =IFERROR(VLOOKUP(H14,'[1]Consolidado MP Planta'!$A$2:$M$823,13,0),"") | E14: =IFERROR(VLOOKUP(H14,'[1]Consolidado MP Planta'!$A$2:$M$823,12,0),"") | F14: =IFERROR(C14*E14,"") | G14: =IFERROR(F14/$F$66,"")
B15: =IFERROR(VLOOKUP(H15,'[2]ARTICULOS MP PLANTA'!$A$2:$G$589,2,0),"")
A16: UNIDADES | B16: MATERIA PRIMA SEMIELABORADOS | C16: UNIDADES | D16: UND MEDIDA | E16: COSTO UNITARIO | F16: TOTAL COSTO | G16: % PREC. DEFINIDO | H16: CODIGOS
A17: 1600 | B17: Trasvasado de leche condensada cocinada | C17: =+A17 -> 1600 | D17: Gramos | E17: 2.2 | F17: =IFERROR(E17*C17,"") -> 3520 | G17: =IFERROR(F17/$F$66,"") -> 0.22685873 | H17: SE00386
B18: =IFERROR(VLOOKUP(H18,[1]SEMIELABORADOS!$A$2:$M$6000,2,0),"") | C18: =+A18 -> 0 | D18: =IFERROR(VLOOKUP(H18,[1]SEMIELABORADOS!$A$2:$M$6000,6,0),"") | E18: =IFERROR(VLOOKUP(H18,[1]SEMIELABORADOS!$A$2:$H$65536,8,0),"") | F18: =IFERROR(E18*C18,"") | G18: =IFERROR(F18/$F$66,"")
B19: =IFERROR(VLOOKUP(H19,[1]SEMIELABORADOS!$A$2:$M$6000,2,0),"") | C19: =+A19 -> 0 | D19: =IFERROR(VLOOKUP(H19,[1]SEMIELABORADOS!$A$2:$M$6000,6,0),"") | E19: =IFERROR(VLOOKUP(H19,[1]SEMIELABORADOS!$A$2:$H$65536,8,0),"") | F19: =IFERROR(E19*C19,"") | G19: =IFERROR(F19/$F$66,"")
B20: =IFERROR(VLOOKUP(H20,[1]SEMIELABORADOS!$A$2:$M$6000,2,0),"") | C20: =+A20 -> 0 | D20: =IFERROR(VLOOKUP(H20,[1]SEMIELABORADOS!$A$2:$M$6000,6,0),"") | E20: =IFERROR(VLOOKUP(H20,[1]SEMIELABORADOS!$A$2:$H$65536,8,0),"") | F20: =IFERROR(E20*C20,"") | G20: =IFERROR(F20/$F$66,"")
B21: =IFERROR(VLOOKUP(H21,[1]SEMIELABORADOS!$A$2:$M$6000,2,0),"") | C21: =+A21 -> 0 | D21: =IFERROR(VLOOKUP(H21,[1]SEMIELABORADOS!$A$2:$M$6000,6,0),"") | E21: =IFERROR(VLOOKUP(H21,[1]SEMIELABORADOS!$A$2:$H$65536,8,0),"") | F21: =IFERROR(E21*C21,"") | G21: =IFERROR(F21/$F$66,"")
B22: =IFERROR(VLOOKUP(H22,[1]SEMIELABORADOS!$A$2:$M$6000,2,0),"") | C22: =+A22 -> 0 | D22: =IFERROR(VLOOKUP(H22,[1]SEMIELABORADOS!$A$2:$M$6000,6,0),"") | E22: =IFERROR(VLOOKUP(H22,[1]SEMIELABORADOS!$A$2:$H$65536,8,0),"") | F22: =IFERROR(E22*C22,"") | G22: =IFERROR(F22/$F$66,"")
B23: =IFERROR(VLOOKUP(H23,[1]SEMIELABORADOS!$A$2:$M$6000,2,0),"") | C23: =+A23 -> 0 | D23: =IFERROR(VLOOKUP(H23,[1]SEMIELABORADOS!$A$2:$M$6000,6,0),"") | E23: =IFERROR(VLOOKUP(H23,[1]SEMIELABORADOS!$A$2:$H$65536,8,0),"") | F23: =IFERROR(E23*C23,"") | G23: =IFERROR(F23/$F$66,"")
B24: =IFERROR(VLOOKUP(H24,[1]SEMIELABORADOS!$A$2:$M$6000,2,0),"") | C24: =+A24 -> 0 | D24: =IFERROR(VLOOKUP(H24,[1]SEMIELABORADOS!$A$2:$M$6000,6,0),"") | E24: =IFERROR(VLOOKUP(H24,[1]SEMIELABORADOS!$A$2:$H$65536,8,0),"") | F24: =IFERROR(E24*C24,"") | G24: =IFERROR(F24/$F$66,"")
A26: UNIDADES | B26: EMPAQUE | C26: UNIDADES | D26: UND MEDIDA | E26: COSTO UNITARIO | F26: TOTAL COSTO | G26: % PREC. DEFINIDO | H26: CODIGOS
A27: 0 | B27: =IFERROR(VLOOKUP(H27,'[1]Consolidado MP Planta'!$A$2:$M$823,3,0),"") | C27: =+A27 -> 0 | D27: =IFERROR(VLOOKUP(H27,'[1]Consolidado MP Planta'!$A$2:$M$823,13,0),"") | E27: =IFERROR(VLOOKUP(H27,'[1]Consolidado MP Planta'!$A$2:$M$823,12,0),"") | F27: =IFERROR(C27*E27,"") | G27: =IFERROR(F27/$F$66,"")
B28: =IFERROR(VLOOKUP(H28,'[1]Consolidado MP Planta'!$A$2:$M$823,3,0),"") | C28: =+A28 -> 0 | D28: =IFERROR(VLOOKUP(H28,'[1]Consolidado MP Planta'!$A$2:$M$823,13,0),"") | E28: =IFERROR(VLOOKUP(H28,'[1]Consolidado MP Planta'!$A$2:$M$823,12,0),"") | F28: =IFERROR(C28*E28,"") | G28: =IFERROR(F28/$F$66,"")
B29: =IFERROR(VLOOKUP(H29,'[1]Consolidado MP Planta'!$A$2:$M$823,3,0),"") | C29: =+A29 -> 0 | D29: =IFERROR(VLOOKUP(H29,'[1]Consolidado MP Planta'!$A$2:$M$823,13,0),"") | E29: =IFERROR(VLOOKUP(H29,'[1]Consolidado MP Planta'!$A$2:$M$823,12,0),"") | F29: =IFERROR(C29*E29,"") | G29: =IFERROR(F29/$F$66,"")
B30: =IFERROR(VLOOKUP(H30,'[1]Consolidado MP Planta'!$A$2:$M$823,3,0),"") | C30: =+A30 -> 0 | D30: =IFERROR(VLOOKUP(H30,'[1]Consolidado MP Planta'!$A$2:$M$823,13,0),"") | E30: =IFERROR(VLOOKUP(H30,'[1]Consolidado MP Planta'!$A$2:$M$823,12,0),"") | F30: =IFERROR(C30*E30,"") | G30: =IFERROR(F30/$F$66,"")
B31: =IFERROR(VLOOKUP(H31,'[1]Consolidado MP Planta'!$A$2:$M$823,3,0),"") | C31: =+A31 -> 0 | D31: =IFERROR(VLOOKUP(H31,'[1]Consolidado MP Planta'!$A$2:$M$823,13,0),"") | E31: =IFERROR(VLOOKUP(H31,'[1]Consolidado MP Planta'!$A$2:$M$823,12,0),"") | F31: =IFERROR(C31*E31,"") | G31: =IFERROR(F31/$F$66,"")
B32: =IFERROR(VLOOKUP(H32,'[1]Consolidado MP Planta'!$A$2:$M$823,3,0),"") | C32: =+A32 -> 0 | D32: =IFERROR(VLOOKUP(H32,'[1]Consolidado MP Planta'!$A$2:$M$823,13,0),"") | E32: =IFERROR(VLOOKUP(H32,'[1]Consolidado MP Planta'!$A$2:$M$823,12,0),"") | F32: =IFERROR(C32*E32,"") | G32: =IFERROR(F32/$F$66,"")
A34: UNIDADES | B34: EMPAQUE SEMIELABORADOS | C34: UNIDADES | D34: UND MEDIDA | E34: COSTO UNITARIO | F34: TOTAL COSTO | G34: % PREC. DEFINIDO | H34: CODIGOS
A35: =+A17 -> 1600 | B35: Trasvasado de leche condensada cocinada | C35: =+A35 -> 1600 | D35: Gramos | E35: 0.02 | F35: =IFERROR(E35*C35,"") -> 32 | G35: =IFERROR(F35/$F$66,"") -> 0.0020623521 | H35: SE00386
A36: =+A18 -> 0 | B36: =IFERROR(VLOOKUP(H36,[1]SEMIELABORADOS!$A$2:$M$6000,2,0),"") | C36: =+A36 -> 0 | D36: =IFERROR(VLOOKUP(H36,[1]SEMIELABORADOS!$A$2:$M$6000,6,0),"") | E36: =IFERROR(VLOOKUP(H36,[1]SEMIELABORADOS!$A$2:$M$65536,10,0),"") | F36: =IFERROR(E36*C36,"") | G36: =IFERROR(F36/$F$66,"")
A37: =+A19 -> 0 | B37: =IFERROR(VLOOKUP(H37,[1]SEMIELABORADOS!$A$2:$M$6000,2,0),"") | C37: =+A37 -> 0 | D37: =IFERROR(VLOOKUP(H37,[1]SEMIELABORADOS!$A$2:$M$6000,6,0),"") | E37: =IFERROR(VLOOKUP(H37,[1]SEMIELABORADOS!$A$2:$M$65536,10,0),"") | F37: =IFERROR(E37*C37,"") | G37: =IFERROR(F37/$F$66,"")
A38: =+A20 -> 0 | B38: =IFERROR(VLOOKUP(H38,[1]SEMIELABORADOS!$A$2:$M$6000,2,0),"") | C38: =+A38 -> 0 | D38: =IFERROR(VLOOKUP(H38,[1]SEMIELABORADOS!$A$2:$M$6000,6,0),"") | E38: =IFERROR(VLOOKUP(H38,[1]SEMIELABORADOS!$A$2:$M$65536,10,0),"") | F38: =IFERROR(E38*C38,"") | G38: =IFERROR(F38/$F$66,"")
A39: =+A21 -> 0 | B39: =IFERROR(VLOOKUP(H39,[1]SEMIELABORADOS!$A$2:$M$6000,2,0),"") | C39: =+A39 -> 0 | D39: =IFERROR(VLOOKUP(H39,[1]SEMIELABORADOS!$A$2:$M$6000,6,0),"") | E39: =IFERROR(VLOOKUP(H39,[1]SEMIELABORADOS!$A$2:$M$65536,10,0),"") | F39: =IFERROR(E39*C39,"") | G39: =IFERROR(F39/$F$66,"")
A40: =+A22 -> 0 | B40: =IFERROR(VLOOKUP(H40,[1]SEMIELABORADOS!$A$2:$M$6000,2,0),"") | C40: =+A40 -> 0 | D40: =IFERROR(VLOOKUP(H40,[1]SEMIELABORADOS!$A$2:$M$6000,6,0),"") | E40: =IFERROR(VLOOKUP(H40,[1]SEMIELABORADOS!$A$2:$M$65536,10,0),"") | F40: =IFERROR(E40*C40,"") | G40: =IFERROR(F40/$F$66,"")
A41: =+A23 -> 0 | B41: =IFERROR(VLOOKUP(H41,[1]SEMIELABORADOS!$A$2:$M$6000,2,0),"") | C41: =+A41 -> 0 | D41: =IFERROR(VLOOKUP(H41,[1]SEMIELABORADOS!$A$2:$M$6000,6,0),"") | E41: =IFERROR(VLOOKUP(H41,[1]SEMIELABORADOS!$A$2:$M$65536,10,0),"") | F41: =IFERROR(E41*C41,"") | G41: =IFERROR(F41/$F$66,"")
A43: UNIDADES | B43: MODI | C43: UNIDADES | D43: UND MEDIDA | E43: COSTO UNITARIO | F43: TOTAL COSTO | G43: % PREC. DEFINIDO | H43: CODIGOS
A44: =+A35 -> 1600 | B44: Trasvasado de leche condensada cocinada | C44: =+A44 -> 1600 | D44: Gramos | E44: 0.55 | F44: =IFERROR(E44*C44,"") -> 880 | G44: =IFERROR(F44/$F$66,"") -> 0.056714683 | H44: SE00386
A45: =+A36 -> 0 | B45: =IFERROR(VLOOKUP(H45,[1]SEMIELABORADOS!$A$2:$M$6000,2,0),"") | C45: =+A45 -> 0 | D45: =IFERROR(VLOOKUP(H45,[1]SEMIELABORADOS!$A$2:$M$6000,6,0),"") | E45: =IFERROR(VLOOKUP(H45,[1]SEMIELABORADOS!$A$2:$M$65536,12,0),"") | F45: =IFERROR(E45*C45,"") | G45: =IFERROR(F45/$F$66,"")
...

Sheet Ensamble
C1: SERVICIOS DE PASTELERIA S.A. | H1: CÓDIGO: | I1: ESP-RE-POS-122
C2: ESPECIFICACION DE RECETA | H2: REVISIÓN: | I2: 01
C3: PTI00266 Crumble de manzana Spoon | H3: FECHA DE APROBACIÓN: | I3: 45988
C4: Elaborado | D4: Juan Pablo Brenes, Chef
C5: Aprobado | D5: Esteban Cartin, Gte Manufactura
A6: AREA QUE PRODUCE: | D6: Postres | G6: AREA QUE EMPACA: | I6: Postres
A7: # Código | B7: # Código Netsuite | C7: Descripción del ingrediente | D7: Marca | E7: Unidad Internacional | G7: Medida alternativa | I7: Costo - Referencia
E8: Cantidad | F8: Unidad medida | G8: Cantidad | H8: Unidad medida | I8: Colones
A9: 907000002 | B9: SE00041 | C9: BASE GALLETA P/CHEESE CAKE (KILO) | D9: FAS | E9: 100 | F9: g | H9: molde pequeño
B10: SE00768 | C10: MOUSSE QUESO CONDENSADA | D10: FAS | E10: 300 | F10: g
B11: SE00766 | C11: RELLENO DE MANZANA | D11: FAS | E11: 100 | F11: g | H11: 1/3 taza
B12: MP10007 | C12: Manjar Leche Condensada | D12: Nestle | E12: 90 | F12: g | H12: 1/3 taza
C14: DECORACION
B15: MP10007 | C15: Manjar Leche Condensada | D15: Nestle | E15: 10 | F15: g
B16: SE00032 | C16: Crema Dulce Leche | D16: FAS | E16: 30 | F16: g | H16: Boquilla 805
B17: SE00766 | C17: RELLENO DE MANZANA | D17: FAS | E17: 150 | F17: g | H17: 1/2 taza
B18: SE00767 | C18: CRUMBLE SPOON | D18: FAS | E18: 30 | F18: g
C20: EMPAQUE
B21: EM10455 | C21: QUEQUERA REDONDA CON BASE 7 ALTA | D21: FAS | E21: 1 | F21: ud
B22: MP10007 | C22: Manjar Leche Condensada | D22: Nestle | E22: 10 | F22: g
A23: 702069 | B23: EM10002 | C23: ETIQ.BLANCA 1 1/4 * 3/4 | D23: CEMUSA | E23: 1 | F23: ud
A24: 701096 | B24: EM10124 | C24: ETIQUETA BLANCA R-153 | D24: CEMUSA | E24: 1 | F24: ud
B25: EM10011 | C25: Etiqueta Blanca 2 5/8X1 15/16 | D25: CEMUSA | E25: 1 | F25: ud
D29: Cantidad | E29: Unidad
A30: PESO TOTAL OBTENIDO | D30: 800 | E30: g | F30: Tiempo de Horneo:
A31: TIEMPO TOTAL DE PREPARACION | D31: 7 | E31: min | F31: Horno:
A32: CANTIDAD DE PORCIONES OBTENIDAS | D32: 1 | E32: uds | F32: Temperatura de Horneo:
A33: PESO DE CADA PORCIÓN | D33: 800 | E33: g | F33: Otros
A34: MERMA | D34: =SUM(E9:E18)-D30 -> 10 | E34: g
A35: PROCEDIMIENTO DE PREPARACION DE LA RECETA
A36: 1.- En la base de galleta horneada agregar al centro 1/3 taza de manzana y de manjar.
A37: 2.- Dosificar los otros 300g de relleno de queso y llevar a refrigeracion por minimo 4 horas.
A38: 3.- Desmoldar y pegar con manjar en la orla
A39: 4.- Con la boquilla redonda hacer colocho en el borde, luego colocar el relleno de manzana y el crumble al borde del colocho
A40: 5.- Tapar y etiquetar.
A43: CONTROL DE CAMBIOS

Sheet Costo Ensamble 
E1: Precio Local | F1: Costo MP | G1: Costo EM | H1: Costo MO
E2: =IFERROR(O61,"") -> 3472.975 | F2: =IFERROR(H52,"") -> 1906.4867 | G2: =IFERROR(H53,"") -> 340.04952 | H2: =IFERROR(H55,"") -> 669.75735
A5: ESTRUCTURA DE COSTOS
F6: Fecha: | H6: =TODAY() -> 46034
A7: UNIDADES | B7: DESCRIPCION MAT.PRIMA | C7: UNIDADES | D7: UND MEDIDA | E7: COSTO UNITARIO | F7: TOTAL COSTO | G7: % PREC. DEFINIDO | H7: CODIGOS
A8: 110 | B8: Manjar Leche Condensada | C8: =+A8 -> 110 | D8: Gramos | E8: 2.56 | F8: =IFERROR(C8*E8,"") -> 281.6 | G8: =IFERROR(F8/$F$65,"") -> 0.099728512 | H8: MP10007
B9: =IFERROR(VLOOKUP(H9,'[1]Consolidado MP Planta'!$A$2:$M$823,3,0),"") | C9: =+A9 -> 0 | D9: =IFERROR(VLOOKUP(H9,'[1]Consolidado MP Planta'!$A$2:$M$823,13,0),"") | E9: =IFERROR(VLOOKUP(H9,'[1]Consolidado MP Planta'!$A$2:$M$823,12,0),"") | F9: =IFERROR(C9*E9,"") | G9: =IFERROR(F9/$F$65,"")
B10: =IFERROR(VLOOKUP(H10,'[1]Consolidado MP Planta'!$A$2:$M$823,3,0),"") | C10: =+A10 -> 0 | D10: =IFERROR(VLOOKUP(H10,'[1]Consolidado MP Planta'!$A$2:$M$823,13,0),"") | E10: =IFERROR(VLOOKUP(H10,'[1]Consolidado MP Planta'!$A$2:$M$823,12,0),"") | F10: =IFERROR(C10*E10,"") | G10: =IFERROR(F10/$F$65,"")
B11: =IFERROR(VLOOKUP(H11,'[1]Consolidado MP Planta'!$A$2:$M$823,3,0),"") | C11: =+A11 -> 0 | D11: =IFERROR(VLOOKUP(H11,'[1]Consolidado MP Planta'!$A$2:$M$823,13,0),"") | E11: =IFERROR(VLOOKUP(H11,'[1]Consolidado MP Planta'!$A$2:$M$823,12,0),"") | F11: =IFERROR(C11*E11,"") | G11: =IFERROR(F11/$F$65,"")
B12: =IFERROR(VLOOKUP(H12,'[1]Consolidado MP Planta'!$A$2:$M$823,3,0),"") | C12: =+A12 -> 0 | D12: =IFERROR(VLOOKUP(H12,'[1]Consolidado MP Planta'!$A$2:$M$823,13,0),"") | E12: =IFERROR(VLOOKUP(H12,'[1]Consolidado MP Planta'!$A$2:$M$823,12,0),"") | F12: =IFERROR(C12*E12,"") | G12: =IFERROR(F12/$F$65,"")
B13: =IFERROR(VLOOKUP(H13,'[1]Consolidado MP Planta'!$A$2:$M$823,3,0),"") | C13: =+A13 -> 0 | D13: =IFERROR(VLOOKUP(H13,'[1]Consolidado MP Planta'!$A$2:$M$823,13,0),"") | E13: =IFERROR(VLOOKUP(H13,'[1]Consolidado MP Planta'!$A$2:$M$823,12,0),"") | F13: =IFERROR(C13*E13,"") | G13: =IFERROR(F13/$F$65,"")
B14: =IFERROR(VLOOKUP(H14,'[1]Consolidado MP Planta'!$A$2:$M$823,3,0),"") | C14: =+A14 -> 0 | D14: =IFERROR(VLOOKUP(H14,'[1]Consolidado MP Planta'!$A$2:$M$823,13,0),"") | E14: =IFERROR(VLOOKUP(H14,'[1]Consolidado MP Planta'!$A$2:$M$823,12,0),"") | F14: =IFERROR(C14*E14,"") | G14: =IFERROR(F14/$F$65,"")
B15: =IFERROR(VLOOKUP(H15,'[2]ARTICULOS MP PLANTA'!$A$2:$G$589,2,0),"")
A16: UNIDADES | B16: MATERIA PRIMA SEMIELABORADOS | C16: UNIDADES | D16: UND MEDIDA | E16: COSTO UNITARIO | F16: TOTAL COSTO | G16: % PREC. DEFINIDO | H16: CODIGOS
A17: 100 | B17: BASE GALLETA P/CHEESE CAKE (KILO) | C17: =+A17 -> 100 | D17: Gramos | E17: 2.35 | F17: =IFERROR(E17*C17,"") -> 235 | G17: =IFERROR(F17/$F$65,"") -> 0.083225143 | H17: SE00041
A18: 300 | B18: MOUSSE QUESO CONDENSADA | C18: =+A18 -> 300 | D18: Gramos | E18: =+'Costo Mousse de Queso'!E69 -> 2.313 | F18: =IFERROR(E18*C18,"") -> 693.9 | G18: =IFERROR(F18/$F$65,"") -> 0.24574437 | H18: NUEVO
A19: 250 | B19: RELLENO DE MANZANA | C19: =+A19 -> 250 | D19: Gramos | E19: =+'Costo de Relleno'!E69 -> 2.4680667 | F19: =IFERROR(E19*C19,"") -> 617.01667 | G19: =IFERROR(F19/$F$65,"") -> 0.21851617 | H19: NUEVO
A20: 20 | B20: Crema Dulce Leche | C20: =+A20 -> 20 | D20: Gramos | E20: 2.27 | F20: =IFERROR(E20*C20,"") -> 45.4 | G20: =IFERROR(F20/$F$65,"") -> 0.016078389 | H20: SE00032
A21: 30 | B21: CRUMBLE SPOON | C21: =+A21 -> 30 | D21: Gramos | E21: =+'Costo Crumble'!E69 -> 1.119 | F21: =IFERROR(E21*C21,"") -> 33.57 | G21: =IFERROR(F21/$F$65,"") -> 0.0118888 | H21: NUEVO
B22: =IFERROR(VLOOKUP(H22,[1]SEMIELABORADOS!$A$2:$M$6000,2,0),"") | C22: =+A22 -> 0 | D22: =IFERROR(VLOOKUP(H22,[1]SEMIELABORADOS!$A$2:$M$6000,6,0),"") | E22: =IFERROR(VLOOKUP(H22,[1]SEMIELABORADOS!$A$2:$H$65536,8,0),"") | F22: =IFERROR(E22*C22,"") | G22: =IFERROR(F22/$F$65,"")
B23: =IFERROR(VLOOKUP(H23,[1]SEMIELABORADOS!$A$2:$M$6000,2,0),"") | C23: =+A23 -> 0 | D23: =IFERROR(VLOOKUP(H23,[1]SEMIELABORADOS!$A$2:$M$6000,6,0),"") | E23: =IFERROR(VLOOKUP(H23,[1]SEMIELABORADOS!$A$2:$H$65536,8,0),"") | F23: =IFERROR(E23*C23,"") | G23: =IFERROR(F23/$F$65,"")
B24: =IFERROR(VLOOKUP(H24,[1]SEMIELABORADOS!$A$2:$M$6000,2,0),"") | C24: =+A24 -> 0 | D24: =IFERROR(VLOOKUP(H24,[1]SEMIELABORADOS!$A$2:$M$6000,6,0),"") | E24: =IFERROR(VLOOKUP(H24,[1]SEMIELABORADOS!$A$2:$H$65536,8,0),"") | F24: =IFERROR(E24*C24,"") | G24: =IFERROR(F24/$F$65,"")
A26: UNIDADES | B26: EMPAQUE | C26: UNIDADES | D26: UND MEDIDA | E26: COSTO UNITARIO | F26: TOTAL COSTO | G26: % PREC. DEFINIDO | H26: CODIGOS
A27: 1 | B27: QUEQUERA 8 PEQUEÑA | C27: =+A27 -> 1 | D27: UND | E27: 245.63 | F27: =IFERROR(C27*E27,"") -> 245.63 | G27: =IFERROR(F27/$F$65,"") -> 0.086989753 | H27: NUEVO
A28: 1 | B28: ETIQUETA POSTRE | C28: =+A28 -> 1 | D28: UND | E28: 85 | F28: =IFERROR(C28*E28,"") -> 85 | G28: =IFERROR(F28/$F$65,"") -> 0.030102711 | H28: NUEVO
A29: 1 | B29: ETIQ.BLANCA 1 1/4 * 3/4 | C29: =+A29 -> 1 | D29: UND | E29: 1.74 | F29: =IFERROR(C29*E29,"") -> 1.74 | G29: =IFERROR(F29/$F$65,"") -> 0.00061622021 | H29: EM10002
A30: 1 | B30: ETIQUETA BLANCA R-153 (UND) | C30: =+A30 -> 1 | D30: UND | E30: 0.39 | F30: =IFERROR(C30*E30,"") -> 0.39 | G30: =IFERROR(F30/$F$65,"") -> 0.00013811832 | H30: EM10124
A31: 1 | B31: ETIQUETA BLANCA 2 5/8X1 15/16 (UND) | C31: =+A31 -> 1 | D31: UND | E31: 2.13 | F31: =IFERROR(C31*E31,"") -> 2.13 | G31: =IFERROR(F31/$F$65,"") -> 0.00075433853 | H31: EM10011
A33: UNIDADES | B33: EMPAQUE SEMIELABORADOS | C33: UNIDADES | D33: UND MEDIDA | E33: COSTO UNITARIO | F33: TOTAL COSTO | G33: % PREC. DEFINIDO | H33: CODIGOS
A34: =+A17 -> 100 | B34: BASE GALLETA P/CHEESE CAKE (KILO) | C34: =+A34 -> 100 | D34: Gramos | E34: 0.01 | F34: =IFERROR(E34*C34,"") -> 1 | G34: =IFERROR(F34/$F$65,"") -> 0.00035414954 | H34: SE00041
A35: =+A18 -> 300 | B35: MOUSSE QUESO CONDENSADA | C35: =+A35 -> 300 | D35: Gramos | E35: =+'Costo Mousse de Queso'!E76 -> 0.005 | F35: =IFERROR(E35*C35,"") -> 1.5 | G35: =IFERROR(F35/$F$65,"") -> 0.00053122432 | H35: NUEVO
A36: =+A19 -> 250 | B36: RELLENO DE MANZANA | C36: =+A36 -> 250 | D36: Gramos | E36: =+'Costo de Relleno'!E76 -> 0.0086666667 | F36: =IFERROR(E36*C36,"") -> 2.1666667 | G36: =IFERROR(F36/$F$65,"") -> 0.00076732401 | H36: NUEVO
A37: =+A20 -> 20 | B37: Crema Dulce Leche | C37: =+A37 -> 20 | D37: Gramos | E37: 0 | F37: =IFERROR(E37*C37,"") -> 0 | G37: =IFERROR(F37/$F$65,"") -> 0 | H37: SE00032
A38: =+A21 -> 30 | B38: CRUMBLE SPOON | C38: =+A38 -> 30 | D38: Gramos | E38: =+'Costo Crumble'!E76 -> 0.016428571 | F38: =IFERROR(E38*C38,"") -> 0.49285714 | G38: =IFERROR(F38/$F$65,"") -> 0.00017454513 | H38: NUEVO
A39: =+A22 -> 0 | B39: =IFERROR(VLOOKUP(H39,[1]SEMIELABORADOS!$A$2:$M$6000,2,0),"") | C39: =+A39 -> 0 | D39: =IFERROR(VLOOKUP(H39,[1]SEMIELABORADOS!$A$2:$M$6000,6,0),"") | E39: =IFERROR(VLOOKUP(H39,[1]SEMIELABORADOS!$A$2:$M$65536,10,0),"") | F39: =IFERROR(E39*C39,"") | G39: =IFERROR(F39/$F$65,"")
A40: =+A23 -> 0 | B40: =IFERROR(VLOOKUP(H40,[1]SEMIELABORADOS!$A$2:$M$6000,2,0),"") | C40: =+A40 -> 0 | D40: =IFERROR(VLOOKUP(H40,[1]SEMIELABORADOS!$A$2:$M$6000,6,0),"") | E40: =IFERROR(VLOOKUP(H40,[1]SEMIELABORADOS!$A$2:$M$65536,10,0),"") | F40: =IFERROR(E40*C40,"") | G40: =IFERROR(F40/$F$65,"")
A42: UNIDADES | B42: MODI | C42: UNIDADES | D42: UND MEDIDA | E42: COSTO UNITARIO | F42: TOTAL COSTO | G42: % PREC. DEFINIDO | H42: CODIGOS
A43: =+A34 -> 100 | B43: BASE GALLETA P/CHEESE CAKE (KILO) | C43: =+A43 -> 100 | D43: Gramos | E43: 0.16 | F43: =IFERROR(E43*C43,"") -> 16 | G43: =IFERROR(F43/$F$65,"") -> 0.0056663927 | H43: SE00041
A44: =+A35 -> 300 | B44: MOUSSE QUESO CONDENSADA | C44: =+A44 -> 300 | D44: Gramos | E44: =+'Costo Mousse de Queso'!E74 -> 0.19765625 | F44: =IFERROR(E44*C44,"") -> 59.296875 | G44: =IFERROR(F44/$F$65,"") -> 0.020999961 | H44: NUEVO
A45: =+A36 -> 250 | B45: RELLENO DE MANZANA | C45: =+A45 -> 250 | D45: Gramos | E45: =+'Costo de Relleno'!E74 -> 0.21233333 | F45: =IFERROR(E45*C45,"") -> 53.083333 | G45: =IFERROR(F45/$F$65,"") -> 0.018799438 | H45: NUEVO
...
