Workbook

Sheet Batido brownie dawn
B1: SERVICIOS DE PASTELERIA S.A. | G1: CÓDIGO:
B2: ESPECIFICACION DE RECETA | G2: REVISIÓN:
B3: Batido brownie Dawn | G3: FECHA DE APROBACIÓN:
B4: Elaborado | C4: Juan Pablo Brenes,chef
B5: Aprobado | C5: Jeffry Rodriguez, Gerente de Manufactura
A7: AREA QUE PRODUCE: | C7: Batidos | F7: AREA QUE EMPACA: | H7: Batidos
A8: # Código | B8: Descripción del ingrediente | C8: Marca | D8: Unidad Internacional | F8: Medida alternativa | H8: Costo - Referencia
D9: Cantidad | E9: Unidad medida | F9: Cantidad | G9: Unidad medida | H9: Colones
A10: SE00341 | B10: Premezcla Batido Nucleo Chocolate Dawn | C10: FAS | D10: 21971 | E10: g
A11: MP10005 | B11: HUEVO ENTERO PASTERI INNOVO ( CAJA: 10 K) | C11: INNOVO | D11: 6687 | E11: g
A12: MP10002 | B12: ACEITE CAPULLO RBD (UND:17 L) | C12: CAPULLO | D12: 5732 | E12: g
B13: AGUA POTABLE (PLANTA) | C13: FAS | D13: 5350 | E13: g
A14: MP10022 | B14: Lactocrema Granel | C14: FAS | D14: 5850 | E14: g
A15: NUEVO | B15: FLAT ICING COBERTURA DONA LISA | C15: DAWN | D15: 9750 | E15: g
C18: Cantidad | D18: Unidad
A19: PESO TOTAL OBTENIDO | C19: 54600 | D19: g
A20: TIEMPO TOTAL DE PREPARACION | C20: 10 | D20: min
A21: CANTIDAD DE PORCIONES OBTENIDAS | C21: 1 | D21: ud
A22: PESO DE CADA PORCIÓN | C22: 54600 | D22: g
A23: MERMA | C23: =SUM(D10:D15)-C19 -> 740 | D23: g
A24: PROCEDIMIENTO DE PREPARACION DE LA RECETA
A25: 1, Disolver el preservante y el polvo de hornear con el agua y ayuda de un batidor de mano.
A26: 2, Colocar los liquidos, lactocrema derretida y el icing en la batidora, posterior agregar los ingredientes secos
A27: 3, Batir por 1 min en velocidad 1. Con paleta
A28: 4, Batir 5 min en velocidad 2. con Paleta

Sheet Costo Batido Brownie 
E1: Precio Local | F1: Costo MP | G1: Costo EM | H1: Costo MO
E2: =IFERROR(O62,"") -> 93273.366 | F2: =IFERROR(H53,"") -> 91461.04 | G2: =IFERROR(H54,"") -> 0 | H2: =IFERROR(H56,"") -> 989.71
A5: ESTRUCTURA DE COSTOS
F6: Fecha: | H6: =TODAY() -> 45901
A7: UNIDADES | B7: DESCRIPCION MAT.PRIMA | C7: UNIDADES | D7: UND MEDIDA | E7: COSTO UNITARIO | F7: TOTAL COSTO | G7: % PREC. DEFINIDO | H7: CODIGOS
A8: 6687 | B8: HUEVO ENTERO PASTERI INNOVO ( CAJA: 10 K) | C8: =+A8 -> 6687 | D8: Gramos | E8: 2.27 | F8: =IFERROR(C8*E8,"") -> 15179.49 | G8: =IFERROR(F8/$F$66,"") -> 0.16138048 | H8: MP10005
A9: 5732 | B9: ACEITE CAPULLO RBD (UND:17 L) | C9: =+A9 -> 5732 | D9: Gramos | E9: 0.89 | F9: =IFERROR(C9*E9,"") -> 5101.48 | G9: =IFERROR(F9/$F$66,"") -> 0.054236294 | H9: MP10002
A10: 5850 | B10: Lactocrema Granel | C10: =+A10 -> 5850 | D10: Gramos | E10: 3.49 | F10: =IFERROR(C10*E10,"") -> 20416.5 | G10: =IFERROR(F10/$F$66,"") -> 0.21705766 | H10: MP10022
A11: 9750 | B11: FLAT ICING COBERTURA DONA LISA | C11: =+A11 -> 9750 | D11: Gramos | E11: 2.57 | F11: =IFERROR(C11*E11,"") -> 25057.5 | G11: =IFERROR(F11/$F$66,"") -> 0.26639837
B12: =IFERROR(VLOOKUP(H12,'[1]Consolidado MP Planta'!$A$2:$M$823,3,0),"") | C12: =+A12 -> 0 | D12: =IFERROR(VLOOKUP(H12,'[1]Consolidado MP Planta'!$A$2:$M$823,13,0),"") | E12: =IFERROR(VLOOKUP(H12,'[1]Consolidado MP Planta'!$A$2:$M$823,12,0),"") | F12: =IFERROR(C12*E12,"") | G12: =IFERROR(F12/$F$66,"") | R12: =25628/9980 -> 2.5679359
B13: =IFERROR(VLOOKUP(H13,'[1]Consolidado MP Planta'!$A$2:$M$823,3,0),"") | C13: =+A13 -> 0 | D13: =IFERROR(VLOOKUP(H13,'[1]Consolidado MP Planta'!$A$2:$M$823,13,0),"") | E13: =IFERROR(VLOOKUP(H13,'[1]Consolidado MP Planta'!$A$2:$M$823,12,0),"") | F13: =IFERROR(C13*E13,"") | G13: =IFERROR(F13/$F$66,"")
B14: =IFERROR(VLOOKUP(H14,'[1]Consolidado MP Planta'!$A$2:$M$823,3,0),"") | C14: =+A14 -> 0 | D14: =IFERROR(VLOOKUP(H14,'[1]Consolidado MP Planta'!$A$2:$M$823,13,0),"") | E14: =IFERROR(VLOOKUP(H14,'[1]Consolidado MP Planta'!$A$2:$M$823,12,0),"") | F14: =IFERROR(C14*E14,"") | G14: =IFERROR(F14/$F$66,"")
B15: =IFERROR(VLOOKUP(H15,'[2]ARTICULOS MP PLANTA'!$A$2:$G$589,2,0),"")
A16: UNIDADES | B16: MATERIA PRIMA SEMIELABORADOS | C16: UNIDADES | D16: UND MEDIDA | E16: COSTO UNITARIO | F16: TOTAL COSTO | G16: % PREC. DEFINIDO | H16: CODIGOS
A17: 21971 | B17: Premezcla Batido Nucleo Chocolate Dawn | C17: =+A17 -> 21971 | D17: Gramos | E17: 1.17 | F17: =IFERROR(E17*C17,"") -> 25706.07 | G17: =IFERROR(F17/$F$66,"") -> 0.27329363 | H17: SE00341
B18: =IFERROR(VLOOKUP(H18,[1]SEMIELABORADOS!$A$2:$M$6000,2,0),"") | C18: =+A18 -> 0 | D18: =IFERROR(VLOOKUP(H18,[1]SEMIELABORADOS!$A$2:$M$6000,6,0),"") | E18: =IFERROR(VLOOKUP(H18,[1]SEMIELABORADOS!$A$2:$H$65536,8,0),"") | F18: =IFERROR(E18*C18,"") | G18: =IFERROR(F18/$F$66,"")
B19: =IFERROR(VLOOKUP(H19,[1]SEMIELABORADOS!$A$2:$M$6000,2,0),"") | C19: =+A19 -> 0 | D19: =IFERROR(VLOOKUP(H19,[1]SEMIELABORADOS!$A$2:$M$6000,6,0),"") | E19: =IFERROR(VLOOKUP(H19,[1]SEMIELABORADOS!$A$2:$H$65536,8,0),"") | F19: =IFERROR(E19*C19,"") | G19: =IFERROR(F19/$F$66,"")
B20: =IFERROR(VLOOKUP(H20,[1]SEMIELABORADOS!$A$2:$M$6000,2,0),"") | C20: =+A20 -> 0 | D20: =IFERROR(VLOOKUP(H20,[1]SEMIELABORADOS!$A$2:$M$6000,6,0),"") | E20: =IFERROR(VLOOKUP(H20,[1]SEMIELABORADOS!$A$2:$H$65536,8,0),"") | F20: =IFERROR(E20*C20,"") | G20: =IFERROR(F20/$F$66,"")
B21: =IFERROR(VLOOKUP(H21,[1]SEMIELABORADOS!$A$2:$M$6000,2,0),"") | C21: =+A21 -> 0 | D21: =IFERROR(VLOOKUP(H21,[1]SEMIELABORADOS!$A$2:$M$6000,6,0),"") | E21: =IFERROR(VLOOKUP(H21,[1]SEMIELABORADOS!$A$2:$H$65536,8,0),"") | F21: =IFERROR(E21*C21,"") | G21: =IFERROR(F21/$F$66,"")
B22: =IFERROR(VLOOKUP(H22,[1]SEMIELABORADOS!$A$2:$M$6000,2,0),"") | C22: =+A22 -> 0 | D22: =IFERROR(VLOOKUP(H22,[1]SEMIELABORADOS!$A$2:$M$6000,6,0),"") | E22: =IFERROR(VLOOKUP(H22,[1]SEMIELABORADOS!$A$2:$H$65536,8,0),"") | F22: =IFERROR(E22*C22,"") | G22: =IFERROR(F22/$F$66,"")
B23: =IFERROR(VLOOKUP(H23,[1]SEMIELABORADOS!$A$2:$M$6000,2,0),"") | C23: =+A23 -> 0 | D23: =IFERROR(VLOOKUP(H23,[1]SEMIELABORADOS!$A$2:$M$6000,6,0),"") | E23: =IFERROR(VLOOKUP(H23,[1]SEMIELABORADOS!$A$2:$H$65536,8,0),"") | F23: =IFERROR(E23*C23,"") | G23: =IFERROR(F23/$F$66,"")
B24: =IFERROR(VLOOKUP(H24,[1]SEMIELABORADOS!$A$2:$M$6000,2,0),"") | C24: =+A24 -> 0 | D24: =IFERROR(VLOOKUP(H24,[1]SEMIELABORADOS!$A$2:$M$6000,6,0),"") | E24: =IFERROR(VLOOKUP(H24,[1]SEMIELABORADOS!$A$2:$H$65536,8,0),"") | F24: =IFERROR(E24*C24,"") | G24: =IFERROR(F24/$F$66,"")
A26: UNIDADES | B26: EMPAQUE | C26: UNIDADES | D26: UND MEDIDA | E26: COSTO UNITARIO | F26: TOTAL COSTO | G26: % PREC. DEFINIDO | H26: CODIGOS
A27: 0 | B27: =IFERROR(VLOOKUP(H27,'[1]Consolidado MP Planta'!$A$2:$M$823,3,0),"") | C27: =+A27 -> 0 | D27: =IFERROR(VLOOKUP(H27,'[1]Consolidado MP Planta'!$A$2:$M$823,13,0),"") | E27: =IFERROR(VLOOKUP(H27,'[1]Consolidado MP Planta'!$A$2:$M$823,12,0),"") | F27: =IFERROR(C27*E27,"") | G27: =IFERROR(F27/$F$66,"")
B28: =IFERROR(VLOOKUP(H28,'[1]Consolidado MP Planta'!$A$2:$M$823,3,0),"") | C28: =+A28 -> 0 | D28: =IFERROR(VLOOKUP(H28,'[1]Consolidado MP Planta'!$A$2:$M$823,13,0),"") | E28: =IFERROR(VLOOKUP(H28,'[1]Consolidado MP Planta'!$A$2:$M$823,12,0),"") | F28: =IFERROR(C28*E28,"") | G28: =IFERROR(F28/$F$66,"")
B29: =IFERROR(VLOOKUP(H29,'[1]Consolidado MP Planta'!$A$2:$M$823,3,0),"") | C29: =+A29 -> 0 | D29: =IFERROR(VLOOKUP(H29,'[1]Consolidado MP Planta'!$A$2:$M$823,13,0),"") | E29: =IFERROR(VLOOKUP(H29,'[1]Consolidado MP Planta'!$A$2:$M$823,12,0),"") | F29: =IFERROR(C29*E29,"") | G29: =IFERROR(F29/$F$66,"")
B30: =IFERROR(VLOOKUP(H30,'[1]Consolidado MP Planta'!$A$2:$M$823,3,0),"") | C30: =+A30 -> 0 | D30: =IFERROR(VLOOKUP(H30,'[1]Consolidado MP Planta'!$A$2:$M$823,13,0),"") | E30: =IFERROR(VLOOKUP(H30,'[1]Consolidado MP Planta'!$A$2:$M$823,12,0),"") | F30: =IFERROR(C30*E30,"") | G30: =IFERROR(F30/$F$66,"")
B31: =IFERROR(VLOOKUP(H31,'[1]Consolidado MP Planta'!$A$2:$M$823,3,0),"") | C31: =+A31 -> 0 | D31: =IFERROR(VLOOKUP(H31,'[1]Consolidado MP Planta'!$A$2:$M$823,13,0),"") | E31: =IFERROR(VLOOKUP(H31,'[1]Consolidado MP Planta'!$A$2:$M$823,12,0),"") | F31: =IFERROR(C31*E31,"") | G31: =IFERROR(F31/$F$66,"")
B32: =IFERROR(VLOOKUP(H32,'[1]Consolidado MP Planta'!$A$2:$M$823,3,0),"") | C32: =+A32 -> 0 | D32: =IFERROR(VLOOKUP(H32,'[1]Consolidado MP Planta'!$A$2:$M$823,13,0),"") | E32: =IFERROR(VLOOKUP(H32,'[1]Consolidado MP Planta'!$A$2:$M$823,12,0),"") | F32: =IFERROR(C32*E32,"") | G32: =IFERROR(F32/$F$66,"")
A34: UNIDADES | B34: EMPAQUE SEMIELABORADOS | C34: UNIDADES | D34: UND MEDIDA | E34: COSTO UNITARIO | F34: TOTAL COSTO | G34: % PREC. DEFINIDO | H34: CODIGOS
A35: =+A17 -> 21971 | B35: Premezcla Batido Nucleo Chocolate Dawn | C35: =+A35 -> 21971 | D35: Gramos | E35: 0 | F35: =IFERROR(E35*C35,"") -> 0 | G35: =IFERROR(F35/$F$66,"") -> 0
A36: =+A18 -> 0 | B36: =IFERROR(VLOOKUP(H36,[1]SEMIELABORADOS!$A$2:$M$6000,2,0),"") | C36: =+A36 -> 0 | D36: =IFERROR(VLOOKUP(H36,[1]SEMIELABORADOS!$A$2:$M$6000,6,0),"") | E36: =IFERROR(VLOOKUP(H36,[1]SEMIELABORADOS!$A$2:$M$65536,10,0),"") | F36: =IFERROR(E36*C36,"") | G36: =IFERROR(F36/$F$66,"")
A37: =+A19 -> 0 | B37: =IFERROR(VLOOKUP(H37,[1]SEMIELABORADOS!$A$2:$M$6000,2,0),"") | C37: =+A37 -> 0 | D37: =IFERROR(VLOOKUP(H37,[1]SEMIELABORADOS!$A$2:$M$6000,6,0),"") | E37: =IFERROR(VLOOKUP(H37,[1]SEMIELABORADOS!$A$2:$M$65536,10,0),"") | F37: =IFERROR(E37*C37,"") | G37: =IFERROR(F37/$F$66,"")
A38: =+A20 -> 0 | B38: =IFERROR(VLOOKUP(H38,[1]SEMIELABORADOS!$A$2:$M$6000,2,0),"") | C38: =+A38 -> 0 | D38: =IFERROR(VLOOKUP(H38,[1]SEMIELABORADOS!$A$2:$M$6000,6,0),"") | E38: =IFERROR(VLOOKUP(H38,[1]SEMIELABORADOS!$A$2:$M$65536,10,0),"") | F38: =IFERROR(E38*C38,"") | G38: =IFERROR(F38/$F$66,"")
A39: =+A21 -> 0 | B39: =IFERROR(VLOOKUP(H39,[1]SEMIELABORADOS!$A$2:$M$6000,2,0),"") | C39: =+A39 -> 0 | D39: =IFERROR(VLOOKUP(H39,[1]SEMIELABORADOS!$A$2:$M$6000,6,0),"") | E39: =IFERROR(VLOOKUP(H39,[1]SEMIELABORADOS!$A$2:$M$65536,10,0),"") | F39: =IFERROR(E39*C39,"") | G39: =IFERROR(F39/$F$66,"")
A40: =+A22 -> 0 | B40: =IFERROR(VLOOKUP(H40,[1]SEMIELABORADOS!$A$2:$M$6000,2,0),"") | C40: =+A40 -> 0 | D40: =IFERROR(VLOOKUP(H40,[1]SEMIELABORADOS!$A$2:$M$6000,6,0),"") | E40: =IFERROR(VLOOKUP(H40,[1]SEMIELABORADOS!$A$2:$M$65536,10,0),"") | F40: =IFERROR(E40*C40,"") | G40: =IFERROR(F40/$F$66,"")
A41: =+A23 -> 0 | B41: =IFERROR(VLOOKUP(H41,[1]SEMIELABORADOS!$A$2:$M$6000,2,0),"") | C41: =+A41 -> 0 | D41: =IFERROR(VLOOKUP(H41,[1]SEMIELABORADOS!$A$2:$M$6000,6,0),"") | E41: =IFERROR(VLOOKUP(H41,[1]SEMIELABORADOS!$A$2:$M$65536,10,0),"") | F41: =IFERROR(E41*C41,"") | G41: =IFERROR(F41/$F$66,"")
A43: UNIDADES | B43: MODI | C43: UNIDADES | D43: UND MEDIDA | E43: COSTO UNITARIO | F43: TOTAL COSTO | G43: % PREC. DEFINIDO | H43: CODIGOS
A44: =+A35 -> 21971 | B44: Premezcla Batido Nucleo Chocolate Dawn | C44: =+A44 -> 21971 | D44: Gramos | E44: 0.01 | F44: =IFERROR(E44*C44,"") -> 219.71 | G44: =IFERROR(F44/$F$66,"") -> 0.002335843
A45: =+A36 -> 0 | B45: =IFERROR(VLOOKUP(H45,[1]SEMIELABORADOS!$A$2:$M$6000,2,0),"") | C45: =+A45 -> 0 | D45: =IFERROR(VLOOKUP(H45,[1]SEMIELABORADOS!$A$2:$M$6000,6,0),"") | E45: =IFERROR(VLOOKUP(H45,[1]SEMIELABORADOS!$A$2:$M$65536,12,0),"") | F45: =IFERROR(E45*C45,"") | G45: =IFERROR(F45/$F$66,"")
...

Sheet Rosquete brownie dawn
B1: SERVICIOS DE PASTELERIA S.A. | G1: CÓDIGO:
B2: ESPECIFICACION DE RECETA | G2: REVISIÓN:
B3: Rosquete brownie dawn 400g | G3: FECHA DE APROBACIÓN:
B4: Elaborado | C4: Juan Pablo Brenes,chef
B5: Aprobado | C5: Jeffry Rodriguez, Gerente de Manufactura
A7: AREA QUE PRODUCE: | C7: Batidos | F7: AREA QUE EMPACA: | H7: Batidos
A8: # Código | B8: Descripción del ingrediente | C8: Marca | D8: Unidad Internacional | F8: Medida alternativa | H8: Costo - Referencia
D9: Cantidad | E9: Unidad medida | F9: Cantidad | G9: Unidad medida | H9: Colones
A10: Nuevo | B10: BATIDO BROWNIE DAWN | D10: 54600 | E10: g
A12: 902000019 | B12: MEZCLA ENGRASE MOLDES (29800g) | C12: Spoon | D12: 1560 | E12: g
A13: EM10090 | B13: PAPEL ENCERADO 10X10 (PAQ * 500) | C13: Mayca | D13: 195 | E13: Unids
C16: Cantidad | D16: Unidad
A17: PESO TOTAL OBTENIDO | C17: 54600 | D17: g
A18: TIEMPO TOTAL DE PREPARACION | C18: 20 | D18: min
A19: CANTIDAD DE PORCIONES OBTENIDAS | C19: =C17/C20 -> 136.5 | D19: ud
A20: PESO DE CADA PORCIÓN | C20: 400 | D20: g
A21: MERMA | C21: =SUM(D10:D12)-C17 -> 1560 | D21: g
A22: PROCEDIMIENTO DE PREPARACION DE LA RECETA
A23: 1.- Dosificar 300g de batido en el molde engrasado con papel y llevar al horno a 180ºC por 30 minutos.

Sheet Costo Rosquete
E1: Precio Local | F1: Costo MP | G1: Costo EM | H1: Costo MO
E2: =IFERROR(O62,"") -> 712.29287 | F2: =IFERROR(H53,"") -> 693.47282 | G2: =IFERROR(H54,"") -> 18.571429 | H2: =IFERROR(H56,"") -> 18.532674
A5: ESTRUCTURA DE COSTOS
F6: Fecha: | H6: =TODAY() -> 45901
A7: UNIDADES | B7: DESCRIPCION MAT.PRIMA | C7: UNIDADES | D7: UND MEDIDA | E7: COSTO UNITARIO | F7: TOTAL COSTO | G7: % PREC. DEFINIDO | H7: CODIGOS
B8: =IFERROR(VLOOKUP(H8,'[1]Consolidado MP Planta'!$A$2:$M$823,3,0),"") | C8: =+A8 -> 0 | D8: =IFERROR(VLOOKUP(H8,'[1]Consolidado MP Planta'!$A$2:$M$823,13,0),"") | E8: =IFERROR(VLOOKUP(H8,'[1]Consolidado MP Planta'!$A$2:$M$823,12,0),"") | F8: =IFERROR(C8*E8,"") | G8: =IFERROR(F8/$F$66,"")
B9: =IFERROR(VLOOKUP(H9,'[1]Consolidado MP Planta'!$A$2:$M$823,3,0),"") | C9: =+A9 -> 0 | D9: =IFERROR(VLOOKUP(H9,'[1]Consolidado MP Planta'!$A$2:$M$823,13,0),"") | E9: =IFERROR(VLOOKUP(H9,'[1]Consolidado MP Planta'!$A$2:$M$823,12,0),"") | F9: =IFERROR(C9*E9,"") | G9: =IFERROR(F9/$F$66,"")
B10: =IFERROR(VLOOKUP(H10,'[1]Consolidado MP Planta'!$A$2:$M$823,3,0),"") | C10: =+A10 -> 0 | D10: =IFERROR(VLOOKUP(H10,'[1]Consolidado MP Planta'!$A$2:$M$823,13,0),"") | E10: =IFERROR(VLOOKUP(H10,'[1]Consolidado MP Planta'!$A$2:$M$823,12,0),"") | F10: =IFERROR(C10*E10,"") | G10: =IFERROR(F10/$F$66,"")
B11: =IFERROR(VLOOKUP(H11,'[1]Consolidado MP Planta'!$A$2:$M$823,3,0),"") | C11: =+A11 -> 0 | D11: =IFERROR(VLOOKUP(H11,'[1]Consolidado MP Planta'!$A$2:$M$823,13,0),"") | E11: =IFERROR(VLOOKUP(H11,'[1]Consolidado MP Planta'!$A$2:$M$823,12,0),"") | F11: =IFERROR(C11*E11,"") | G11: =IFERROR(F11/$F$66,"")
B12: =IFERROR(VLOOKUP(H12,'[1]Consolidado MP Planta'!$A$2:$M$823,3,0),"") | C12: =+A12 -> 0 | D12: =IFERROR(VLOOKUP(H12,'[1]Consolidado MP Planta'!$A$2:$M$823,13,0),"") | E12: =IFERROR(VLOOKUP(H12,'[1]Consolidado MP Planta'!$A$2:$M$823,12,0),"") | F12: =IFERROR(C12*E12,"") | G12: =IFERROR(F12/$F$66,"")
B13: =IFERROR(VLOOKUP(H13,'[1]Consolidado MP Planta'!$A$2:$M$823,3,0),"") | C13: =+A13 -> 0 | D13: =IFERROR(VLOOKUP(H13,'[1]Consolidado MP Planta'!$A$2:$M$823,13,0),"") | E13: =IFERROR(VLOOKUP(H13,'[1]Consolidado MP Planta'!$A$2:$M$823,12,0),"") | F13: =IFERROR(C13*E13,"") | G13: =IFERROR(F13/$F$66,"")
B14: =IFERROR(VLOOKUP(H14,'[1]Consolidado MP Planta'!$A$2:$M$823,3,0),"") | C14: =+A14 -> 0 | D14: =IFERROR(VLOOKUP(H14,'[1]Consolidado MP Planta'!$A$2:$M$823,13,0),"") | E14: =IFERROR(VLOOKUP(H14,'[1]Consolidado MP Planta'!$A$2:$M$823,12,0),"") | F14: =IFERROR(C14*E14,"") | G14: =IFERROR(F14/$F$66,"")
B15: =IFERROR(VLOOKUP(H15,'[2]ARTICULOS MP PLANTA'!$A$2:$G$589,2,0),"")
A16: UNIDADES | B16: MATERIA PRIMA SEMIELABORADOS | C16: UNIDADES | D16: UND MEDIDA | E16: COSTO UNITARIO | F16: TOTAL COSTO | G16: % PREC. DEFINIDO | H16: CODIGOS
A17: 54600 | B17: BATIDO BROWNIE DAWN | C17: =+A17 -> 54600 | D17: Gramos | E17: =+'Costo Batido Brownie '!E69 -> 1.6751106 | F17: =IFERROR(E17*C17,"") -> 91461.04 | G17: =IFERROR(F17/$F$66,"") -> 0.90890953 | H17: nuevo
A18: 1560 | B18: =IFERROR(VLOOKUP(H18,[1]SEMIELABORADOS!$A$2:$M$6000,2,0),"") -> MEZCLA P/ENGRASE MOLDES KILO | C18: =+A18 -> 1560 | D18: =IFERROR(VLOOKUP(H18,[1]SEMIELABORADOS!$A$2:$M$6000,6,0),"") -> Gramo | E18: 2.05 | F18: =IFERROR(E18*C18,"") -> 3198 | G18: =IFERROR(F18/$F$66,"") -> 0.031780665 | H18: 902000019
B19: =IFERROR(VLOOKUP(H19,[1]SEMIELABORADOS!$A$2:$M$6000,2,0),"") | C19: =+A19 -> 0 | D19: =IFERROR(VLOOKUP(H19,[1]SEMIELABORADOS!$A$2:$M$6000,6,0),"") | E19: =IFERROR(VLOOKUP(H19,[1]SEMIELABORADOS!$A$2:$H$65536,8,0),"") | F19: =IFERROR(E19*C19,"") | G19: =IFERROR(F19/$F$66,"")
B20: =IFERROR(VLOOKUP(H20,[1]SEMIELABORADOS!$A$2:$M$6000,2,0),"") | C20: =+A20 -> 0 | D20: =IFERROR(VLOOKUP(H20,[1]SEMIELABORADOS!$A$2:$M$6000,6,0),"") | E20: =IFERROR(VLOOKUP(H20,[1]SEMIELABORADOS!$A$2:$H$65536,8,0),"") | F20: =IFERROR(E20*C20,"") | G20: =IFERROR(F20/$F$66,"")
B21: =IFERROR(VLOOKUP(H21,[1]SEMIELABORADOS!$A$2:$M$6000,2,0),"") | C21: =+A21 -> 0 | D21: =IFERROR(VLOOKUP(H21,[1]SEMIELABORADOS!$A$2:$M$6000,6,0),"") | E21: =IFERROR(VLOOKUP(H21,[1]SEMIELABORADOS!$A$2:$H$65536,8,0),"") | F21: =IFERROR(E21*C21,"") | G21: =IFERROR(F21/$F$66,"")
B22: =IFERROR(VLOOKUP(H22,[1]SEMIELABORADOS!$A$2:$M$6000,2,0),"") | C22: =+A22 -> 0 | D22: =IFERROR(VLOOKUP(H22,[1]SEMIELABORADOS!$A$2:$M$6000,6,0),"") | E22: =IFERROR(VLOOKUP(H22,[1]SEMIELABORADOS!$A$2:$H$65536,8,0),"") | F22: =IFERROR(E22*C22,"") | G22: =IFERROR(F22/$F$66,"")
B23: =IFERROR(VLOOKUP(H23,[1]SEMIELABORADOS!$A$2:$M$6000,2,0),"") | C23: =+A23 -> 0 | D23: =IFERROR(VLOOKUP(H23,[1]SEMIELABORADOS!$A$2:$M$6000,6,0),"") | E23: =IFERROR(VLOOKUP(H23,[1]SEMIELABORADOS!$A$2:$H$65536,8,0),"") | F23: =IFERROR(E23*C23,"") | G23: =IFERROR(F23/$F$66,"")
B24: =IFERROR(VLOOKUP(H24,[1]SEMIELABORADOS!$A$2:$M$6000,2,0),"") | C24: =+A24 -> 0 | D24: =IFERROR(VLOOKUP(H24,[1]SEMIELABORADOS!$A$2:$M$6000,6,0),"") | E24: =IFERROR(VLOOKUP(H24,[1]SEMIELABORADOS!$A$2:$H$65536,8,0),"") | F24: =IFERROR(E24*C24,"") | G24: =IFERROR(F24/$F$66,"")
A26: UNIDADES | B26: EMPAQUE | C26: UNIDADES | D26: UND MEDIDA | E26: COSTO UNITARIO | F26: TOTAL COSTO | G26: % PREC. DEFINIDO | H26: CODIGOS
A27: 195 | B27: PAPEL ENCERADO 10X10 (PAQ * 500) | C27: =+A27 -> 195 | D27: UND | E27: 13 | F27: =IFERROR(C27*E27,"") -> 2535 | G27: =IFERROR(F27/$F$66,"") -> 0.025191991 | H27: EM10090
B28: =IFERROR(VLOOKUP(H28,'[1]Consolidado MP Planta'!$A$2:$M$823,3,0),"") | C28: =+A28 -> 0 | D28: =IFERROR(VLOOKUP(H28,'[1]Consolidado MP Planta'!$A$2:$M$823,13,0),"") | E28: =IFERROR(VLOOKUP(H28,'[1]Consolidado MP Planta'!$A$2:$M$823,12,0),"") | F28: =IFERROR(C28*E28,"") | G28: =IFERROR(F28/$F$66,"")
B29: =IFERROR(VLOOKUP(H29,'[1]Consolidado MP Planta'!$A$2:$M$823,3,0),"") | C29: =+A29 -> 0 | D29: =IFERROR(VLOOKUP(H29,'[1]Consolidado MP Planta'!$A$2:$M$823,13,0),"") | E29: =IFERROR(VLOOKUP(H29,'[1]Consolidado MP Planta'!$A$2:$M$823,12,0),"") | F29: =IFERROR(C29*E29,"") | G29: =IFERROR(F29/$F$66,"")
B30: =IFERROR(VLOOKUP(H30,'[1]Consolidado MP Planta'!$A$2:$M$823,3,0),"") | C30: =+A30 -> 0 | D30: =IFERROR(VLOOKUP(H30,'[1]Consolidado MP Planta'!$A$2:$M$823,13,0),"") | E30: =IFERROR(VLOOKUP(H30,'[1]Consolidado MP Planta'!$A$2:$M$823,12,0),"") | F30: =IFERROR(C30*E30,"") | G30: =IFERROR(F30/$F$66,"")
B31: =IFERROR(VLOOKUP(H31,'[1]Consolidado MP Planta'!$A$2:$M$823,3,0),"") | C31: =+A31 -> 0 | D31: =IFERROR(VLOOKUP(H31,'[1]Consolidado MP Planta'!$A$2:$M$823,13,0),"") | E31: =IFERROR(VLOOKUP(H31,'[1]Consolidado MP Planta'!$A$2:$M$823,12,0),"") | F31: =IFERROR(C31*E31,"") | G31: =IFERROR(F31/$F$66,"")
B32: =IFERROR(VLOOKUP(H32,'[1]Consolidado MP Planta'!$A$2:$M$823,3,0),"") | C32: =+A32 -> 0 | D32: =IFERROR(VLOOKUP(H32,'[1]Consolidado MP Planta'!$A$2:$M$823,13,0),"") | E32: =IFERROR(VLOOKUP(H32,'[1]Consolidado MP Planta'!$A$2:$M$823,12,0),"") | F32: =IFERROR(C32*E32,"") | G32: =IFERROR(F32/$F$66,"")
A34: UNIDADES | B34: EMPAQUE SEMIELABORADOS | C34: UNIDADES | D34: UND MEDIDA | E34: COSTO UNITARIO | F34: TOTAL COSTO | G34: % PREC. DEFINIDO | H34: CODIGOS
A35: =+A17 -> 54600 | B35: BATIDO BROWNIE DAWN | C35: =+A35 -> 54600 | D35: Gramos | E35: =+'Costo Batido Brownie '!E76 -> 0 | F35: =IFERROR(E35*C35,"") -> 0 | G35: =IFERROR(F35/$F$66,"") -> 0 | H35: Nuevo
A36: =+A18 -> 1560 | B36: =IFERROR(VLOOKUP(H36,[1]SEMIELABORADOS!$A$2:$M$6000,2,0),"") | C36: =+A36 -> 1560 | D36: =IFERROR(VLOOKUP(H36,[1]SEMIELABORADOS!$A$2:$M$6000,6,0),"") | E36: =IFERROR(VLOOKUP(H36,[1]SEMIELABORADOS!$A$2:$M$65536,10,0),"") | F36: =IFERROR(E36*C36,"") | G36: =IFERROR(F36/$F$66,"")
A37: =+A19 -> 0 | B37: =IFERROR(VLOOKUP(H37,[1]SEMIELABORADOS!$A$2:$M$6000,2,0),"") | C37: =+A37 -> 0 | D37: =IFERROR(VLOOKUP(H37,[1]SEMIELABORADOS!$A$2:$M$6000,6,0),"") | E37: =IFERROR(VLOOKUP(H37,[1]SEMIELABORADOS!$A$2:$M$65536,10,0),"") | F37: =IFERROR(E37*C37,"") | G37: =IFERROR(F37/$F$66,"")
A38: =+A20 -> 0 | B38: =IFERROR(VLOOKUP(H38,[1]SEMIELABORADOS!$A$2:$M$6000,2,0),"") | C38: =+A38 -> 0 | D38: =IFERROR(VLOOKUP(H38,[1]SEMIELABORADOS!$A$2:$M$6000,6,0),"") | E38: =IFERROR(VLOOKUP(H38,[1]SEMIELABORADOS!$A$2:$M$65536,10,0),"") | F38: =IFERROR(E38*C38,"") | G38: =IFERROR(F38/$F$66,"")
A39: =+A21 -> 0 | B39: =IFERROR(VLOOKUP(H39,[1]SEMIELABORADOS!$A$2:$M$6000,2,0),"") | C39: =+A39 -> 0 | D39: =IFERROR(VLOOKUP(H39,[1]SEMIELABORADOS!$A$2:$M$6000,6,0),"") | E39: =IFERROR(VLOOKUP(H39,[1]SEMIELABORADOS!$A$2:$M$65536,10,0),"") | F39: =IFERROR(E39*C39,"") | G39: =IFERROR(F39/$F$66,"")
A40: =+A22 -> 0 | B40: =IFERROR(VLOOKUP(H40,[1]SEMIELABORADOS!$A$2:$M$6000,2,0),"") | C40: =+A40 -> 0 | D40: =IFERROR(VLOOKUP(H40,[1]SEMIELABORADOS!$A$2:$M$6000,6,0),"") | E40: =IFERROR(VLOOKUP(H40,[1]SEMIELABORADOS!$A$2:$M$65536,10,0),"") | F40: =IFERROR(E40*C40,"") | G40: =IFERROR(F40/$F$66,"")
A41: =+A23 -> 0 | B41: =IFERROR(VLOOKUP(H41,[1]SEMIELABORADOS!$A$2:$M$6000,2,0),"") | C41: =+A41 -> 0 | D41: =IFERROR(VLOOKUP(H41,[1]SEMIELABORADOS!$A$2:$M$6000,6,0),"") | E41: =IFERROR(VLOOKUP(H41,[1]SEMIELABORADOS!$A$2:$M$65536,10,0),"") | F41: =IFERROR(E41*C41,"") | G41: =IFERROR(F41/$F$66,"")
A43: UNIDADES | B43: MODI | C43: UNIDADES | D43: UND MEDIDA | E43: COSTO UNITARIO | F43: TOTAL COSTO | G43: % PREC. DEFINIDO | H43: CODIGOS
A44: =+A35 -> 54600 | B44: BATIDO BROWNIE DAWN | C44: =+A44 -> 54600 | D44: Gramos | E44: =+'Costo Batido Brownie '!E74 -> 0.018126557 | F44: =IFERROR(E44*C44,"") -> 989.71 | G44: =IFERROR(F44/$F$66,"") -> 0.0098354103 | H44: Nuevo
A45: =+A36 -> 1560 | B45: =IFERROR(VLOOKUP(H45,[1]SEMIELABORADOS!$A$2:$M$6000,2,0),"") | C45: =+A45 -> 1560 | D45: =IFERROR(VLOOKUP(H45,[1]SEMIELABORADOS!$A$2:$M$6000,6,0),"") | E45: =IFERROR(VLOOKUP(H45,[1]SEMIELABORADOS!$A$2:$M$65536,12,0),"") | F45: =IFERROR(E45*C45,"") | G45: =IFERROR(F45/$F$66,"")
...

Sheet Costo Relleno de Queso 

Sheet Crema Blanca Bucca 
C1: SERVICIOS DE PASTELERIA S.A. | H1: CÓDIGO: | I1: ESP-RE-DEF-026
C2: ESPECIFICACION DE RECETA | H2: REVISIÓN: | I2: 02
C3: SE00634 Crema blanca Bucca | H3: FECHA DE APROBACIÓN: | I3: 45612
C4: Elaborado | D4: Javier Tong, Chef
C5: Aprobado | D5: Esteban Cartin, Gte Manufactura
A6: AREA QUE PRODUCE: | D6: Decoración | G6: AREA QUE EMPACA: | I6: Decoracion
A7: # Código | B7: # Código Netsuite | C7: Descripción del ingrediente | D7: Marca | E7: Unidad Internacional | G7: Medida alternativa | I7: Costo - Referencia
E8: Cantidad | F8: Unidad medida | G8: Cantidad | H8: Unidad medida | I8: Colones
C9: Ensamble
A10: 310148 | B10: MP10047 | C10: BETTERCREME SUPREMO (UND:4 K) | D10: RICHS | E10: 8000 | F10: g | H10: 2 GALON
A11: 11400031 | B11: MP10048 | C11: CREMA PRESTIGE GRAND (UND:4 K) | D11: RICHS | E11: 12000 | F11: g | H11: 3 GALON
A12: 10415 | C12: AGUA POTABLE (PLANTA) | D12: AYA | E12: 50 | F12: g
A13: 1212410 | B13: MP10008 | C13: PRESERVANTE 1047S (PAQ=5 KILO) | D13: ASEAL | E13: 15 | F13: g
C17: Decoración
C26: Empaque
A27: 702123 | B27: EM10011 | C27: ETIQUETA BLANCA 2 5/8X1 15/16 (UND) | D27: ETIPLAST | E27: 1 | F27: ud
D37: Cantidad | E37: Unidad
A38: PESO TOTAL OBTENIDO | D38: 20000 | E38: g | F38: Tiempo de Horneo:
A39: TIEMPO TOTAL DE PREPARACION | D39: 17 | E39: min | F39: Horno:
A40: CANTIDAD DE PORCIONES OBTENIDAS | D40: 1 | E40: Tanda | F40: Temperatura de Horneo:
A41: PESO DE CADA PORCIÓN | D41: 20000 | E41: g | F41: Otros
A42: MERMA | D42: 66 | E42: g
A43: PROCEDIMIENTO DE PREPARACION DE LA RECETA
A44: 1.- Abrir los galones de crema y verter dentro de la top cream (5° en liquido )
A45: 2.- Disolver el preservante en el agua. Agregar a la top cream.
A46: 3.- Batir por 12 a 15 minutos. Colocar en una tina plastica, tapar. (Temperatura de 18°)
A47: 4.- Etiquetar con nombre y fecha de vencimiento.
A48: 5.- Mantener en refrigeración.
A53: CONTROL DE CAMBIOS
A54: Revisión#2, Se actualizan tiempos de preparación y se agrega temperaturas adecuadas.

Sheet Costo Salsa de guayaba
E1: Precio Local | F1: Costo MP | G1: Costo EM | H1: Costo MO
E2: =IFERROR(O62,"") -> 986.72974 | F2: =IFERROR(H53,"") -> 422.39 | G2: =IFERROR(H54,"") -> 0.12 | H2: =IFERROR(H56,"") -> 308.12
A5: ESTRUCTURA DE COSTOS
F6: Fecha: | H6: =TODAY() -> 45901
A7: UNIDADES | B7: DESCRIPCION MAT.PRIMA | C7: UNIDADES | D7: UND MEDIDA | E7: COSTO UNITARIO | F7: TOTAL COSTO | G7: % PREC. DEFINIDO | H7: CODIGOS
A8: 100 | B8: Azucar Blanco Industrial | C8: =+A8 -> 100 | D8: Gramos | E8: 0.43 | F8: =IFERROR(C8*E8,"") -> 43 | G8: =IFERROR(F8/$F$66,"") -> 0.058190062 | H8: MP10074
A9: 200 | B9: RELLENO GUAYABA TRICOPILIA | C9: =+A9 -> 200 | D9: Gramos | E9: 1.55 | F9: =IFERROR(C9*E9,"") -> 310 | G9: =IFERROR(F9/$F$66,"") -> 0.41950975 | H9: NUEVO
A10: 2 | B10: Colorante Gel Super Red | C10: =+A10 -> 2 | D10: Gramos | E10: 18.46 | F10: =IFERROR(C10*E10,"") -> 36.92 | G10: =IFERROR(F10/$F$66,"") -> 0.049962258 | H10: MP10157
A11: 1 | B11: SABORIZANTE GUAYABA MADURA | C11: =+A11 -> 1 | D11: Gramos | E11: 7.15 | F11: =IFERROR(C11*E11,"") -> 7.15 | G11: =IFERROR(F11/$F$66,"") -> 0.0096757893 | H11: NUEVO
B12: =IFERROR(VLOOKUP(H12,'[1]Consolidado MP Planta'!$A$2:$M$823,3,0),"") | C12: =+A12 -> 0 | D12: =IFERROR(VLOOKUP(H12,'[1]Consolidado MP Planta'!$A$2:$M$823,13,0),"") | E12: =IFERROR(VLOOKUP(H12,'[1]Consolidado MP Planta'!$A$2:$M$823,12,0),"") | F12: =IFERROR(C12*E12,"") | G12: =IFERROR(F12/$F$66,"")
B13: =IFERROR(VLOOKUP(H13,'[1]Consolidado MP Planta'!$A$2:$M$823,3,0),"") | C13: =+A13 -> 0 | D13: =IFERROR(VLOOKUP(H13,'[1]Consolidado MP Planta'!$A$2:$M$823,13,0),"") | E13: =IFERROR(VLOOKUP(H13,'[1]Consolidado MP Planta'!$A$2:$M$823,12,0),"") | F13: =IFERROR(C13*E13,"") | G13: =IFERROR(F13/$F$66,"")
B14: =IFERROR(VLOOKUP(H14,'[1]Consolidado MP Planta'!$A$2:$M$823,3,0),"") | C14: =+A14 -> 0 | D14: =IFERROR(VLOOKUP(H14,'[1]Consolidado MP Planta'!$A$2:$M$823,13,0),"") | E14: =IFERROR(VLOOKUP(H14,'[1]Consolidado MP Planta'!$A$2:$M$823,12,0),"") | F14: =IFERROR(C14*E14,"") | G14: =IFERROR(F14/$F$66,"")
B15: =IFERROR(VLOOKUP(H15,'[2]ARTICULOS MP PLANTA'!$A$2:$G$589,2,0),"")
A16: UNIDADES | B16: MATERIA PRIMA SEMIELABORADOS | C16: UNIDADES | D16: UND MEDIDA | E16: COSTO UNITARIO | F16: TOTAL COSTO | G16: % PREC. DEFINIDO | H16: CODIGOS
A17: 12 | B17: Empaque Almidon Modificado | C17: =+A17 -> 12 | D17: Gramos | E17: 2.11 | F17: =IFERROR(E17*C17,"") -> 25.32 | G17: =IFERROR(F17/$F$66,"") -> 0.034264474 | H17: SE00014
B18: =IFERROR(VLOOKUP(H18,[1]SEMIELABORADOS!$A$2:$M$6000,2,0),"") | C18: =+A18 -> 0 | D18: =IFERROR(VLOOKUP(H18,[1]SEMIELABORADOS!$A$2:$M$6000,6,0),"") | E18: =IFERROR(VLOOKUP(H18,[1]SEMIELABORADOS!$A$2:$H$65536,8,0),"") | F18: =IFERROR(E18*C18,"") | G18: =IFERROR(F18/$F$66,"")
B19: =IFERROR(VLOOKUP(H19,[1]SEMIELABORADOS!$A$2:$M$6000,2,0),"") | C19: =+A19 -> 0 | D19: =IFERROR(VLOOKUP(H19,[1]SEMIELABORADOS!$A$2:$M$6000,6,0),"") | E19: =IFERROR(VLOOKUP(H19,[1]SEMIELABORADOS!$A$2:$H$65536,8,0),"") | F19: =IFERROR(E19*C19,"") | G19: =IFERROR(F19/$F$66,"")
B20: =IFERROR(VLOOKUP(H20,[1]SEMIELABORADOS!$A$2:$M$6000,2,0),"") | C20: =+A20 -> 0 | D20: =IFERROR(VLOOKUP(H20,[1]SEMIELABORADOS!$A$2:$M$6000,6,0),"") | E20: =IFERROR(VLOOKUP(H20,[1]SEMIELABORADOS!$A$2:$H$65536,8,0),"") | F20: =IFERROR(E20*C20,"") | G20: =IFERROR(F20/$F$66,"")
B21: =IFERROR(VLOOKUP(H21,[1]SEMIELABORADOS!$A$2:$M$6000,2,0),"") | C21: =+A21 -> 0 | D21: =IFERROR(VLOOKUP(H21,[1]SEMIELABORADOS!$A$2:$M$6000,6,0),"") | E21: =IFERROR(VLOOKUP(H21,[1]SEMIELABORADOS!$A$2:$H$65536,8,0),"") | F21: =IFERROR(E21*C21,"") | G21: =IFERROR(F21/$F$66,"")
B22: =IFERROR(VLOOKUP(H22,[1]SEMIELABORADOS!$A$2:$M$6000,2,0),"") | C22: =+A22 -> 0 | D22: =IFERROR(VLOOKUP(H22,[1]SEMIELABORADOS!$A$2:$M$6000,6,0),"") | E22: =IFERROR(VLOOKUP(H22,[1]SEMIELABORADOS!$A$2:$H$65536,8,0),"") | F22: =IFERROR(E22*C22,"") | G22: =IFERROR(F22/$F$66,"")
B23: =IFERROR(VLOOKUP(H23,[1]SEMIELABORADOS!$A$2:$M$6000,2,0),"") | C23: =+A23 -> 0 | D23: =IFERROR(VLOOKUP(H23,[1]SEMIELABORADOS!$A$2:$M$6000,6,0),"") | E23: =IFERROR(VLOOKUP(H23,[1]SEMIELABORADOS!$A$2:$H$65536,8,0),"") | F23: =IFERROR(E23*C23,"") | G23: =IFERROR(F23/$F$66,"")
B24: =IFERROR(VLOOKUP(H24,[1]SEMIELABORADOS!$A$2:$M$6000,2,0),"") | C24: =+A24 -> 0 | D24: =IFERROR(VLOOKUP(H24,[1]SEMIELABORADOS!$A$2:$M$6000,6,0),"") | E24: =IFERROR(VLOOKUP(H24,[1]SEMIELABORADOS!$A$2:$H$65536,8,0),"") | F24: =IFERROR(E24*C24,"") | G24: =IFERROR(F24/$F$66,"")
A26: UNIDADES | B26: EMPAQUE | C26: UNIDADES | D26: UND MEDIDA | E26: COSTO UNITARIO | F26: TOTAL COSTO | G26: % PREC. DEFINIDO | H26: CODIGOS
A27: 0 | B27: =IFERROR(VLOOKUP(H27,'[1]Consolidado MP Planta'!$A$2:$M$823,3,0),"") | C27: =+A27 -> 0 | D27: =IFERROR(VLOOKUP(H27,'[1]Consolidado MP Planta'!$A$2:$M$823,13,0),"") | E27: =IFERROR(VLOOKUP(H27,'[1]Consolidado MP Planta'!$A$2:$M$823,12,0),"") | F27: =IFERROR(C27*E27,"") | G27: =IFERROR(F27/$F$66,"")
B28: =IFERROR(VLOOKUP(H28,'[1]Consolidado MP Planta'!$A$2:$M$823,3,0),"") | C28: =+A28 -> 0 | D28: =IFERROR(VLOOKUP(H28,'[1]Consolidado MP Planta'!$A$2:$M$823,13,0),"") | E28: =IFERROR(VLOOKUP(H28,'[1]Consolidado MP Planta'!$A$2:$M$823,12,0),"") | F28: =IFERROR(C28*E28,"") | G28: =IFERROR(F28/$F$66,"")
B29: =IFERROR(VLOOKUP(H29,'[1]Consolidado MP Planta'!$A$2:$M$823,3,0),"") | C29: =+A29 -> 0 | D29: =IFERROR(VLOOKUP(H29,'[1]Consolidado MP Planta'!$A$2:$M$823,13,0),"") | E29: =IFERROR(VLOOKUP(H29,'[1]Consolidado MP Planta'!$A$2:$M$823,12,0),"") | F29: =IFERROR(C29*E29,"") | G29: =IFERROR(F29/$F$66,"")
B30: =IFERROR(VLOOKUP(H30,'[1]Consolidado MP Planta'!$A$2:$M$823,3,0),"") | C30: =+A30 -> 0 | D30: =IFERROR(VLOOKUP(H30,'[1]Consolidado MP Planta'!$A$2:$M$823,13,0),"") | E30: =IFERROR(VLOOKUP(H30,'[1]Consolidado MP Planta'!$A$2:$M$823,12,0),"") | F30: =IFERROR(C30*E30,"") | G30: =IFERROR(F30/$F$66,"")
B31: =IFERROR(VLOOKUP(H31,'[1]Consolidado MP Planta'!$A$2:$M$823,3,0),"") | C31: =+A31 -> 0 | D31: =IFERROR(VLOOKUP(H31,'[1]Consolidado MP Planta'!$A$2:$M$823,13,0),"") | E31: =IFERROR(VLOOKUP(H31,'[1]Consolidado MP Planta'!$A$2:$M$823,12,0),"") | F31: =IFERROR(C31*E31,"") | G31: =IFERROR(F31/$F$66,"")
B32: =IFERROR(VLOOKUP(H32,'[1]Consolidado MP Planta'!$A$2:$M$823,3,0),"") | C32: =+A32 -> 0 | D32: =IFERROR(VLOOKUP(H32,'[1]Consolidado MP Planta'!$A$2:$M$823,13,0),"") | E32: =IFERROR(VLOOKUP(H32,'[1]Consolidado MP Planta'!$A$2:$M$823,12,0),"") | F32: =IFERROR(C32*E32,"") | G32: =IFERROR(F32/$F$66,"")
A34: UNIDADES | B34: EMPAQUE SEMIELABORADOS | C34: UNIDADES | D34: UND MEDIDA | E34: COSTO UNITARIO | F34: TOTAL COSTO | G34: % PREC. DEFINIDO | H34: CODIGOS
A35: =+A17 -> 12 | B35: Empaque Almidon Modificado | C35: =+A35 -> 12 | D35: Gramos | E35: 0.01 | F35: =IFERROR(E35*C35,"") -> 0.12 | G35: =IFERROR(F35/$F$66,"") -> 0.00016239087 | H35: SE00014
A36: =+A18 -> 0 | B36: =IFERROR(VLOOKUP(H36,[1]SEMIELABORADOS!$A$2:$M$6000,2,0),"") | C36: =+A36 -> 0 | D36: =IFERROR(VLOOKUP(H36,[1]SEMIELABORADOS!$A$2:$M$6000,6,0),"") | E36: =IFERROR(VLOOKUP(H36,[1]SEMIELABORADOS!$A$2:$M$65536,10,0),"") | F36: =IFERROR(E36*C36,"") | G36: =IFERROR(F36/$F$66,"")
A37: =+A19 -> 0 | B37: =IFERROR(VLOOKUP(H37,[1]SEMIELABORADOS!$A$2:$M$6000,2,0),"") | C37: =+A37 -> 0 | D37: =IFERROR(VLOOKUP(H37,[1]SEMIELABORADOS!$A$2:$M$6000,6,0),"") | E37: =IFERROR(VLOOKUP(H37,[1]SEMIELABORADOS!$A$2:$M$65536,10,0),"") | F37: =IFERROR(E37*C37,"") | G37: =IFERROR(F37/$F$66,"")
A38: =+A20 -> 0 | B38: =IFERROR(VLOOKUP(H38,[1]SEMIELABORADOS!$A$2:$M$6000,2,0),"") | C38: =+A38 -> 0 | D38: =IFERROR(VLOOKUP(H38,[1]SEMIELABORADOS!$A$2:$M$6000,6,0),"") | E38: =IFERROR(VLOOKUP(H38,[1]SEMIELABORADOS!$A$2:$M$65536,10,0),"") | F38: =IFERROR(E38*C38,"") | G38: =IFERROR(F38/$F$66,"")
A39: =+A21 -> 0 | B39: =IFERROR(VLOOKUP(H39,[1]SEMIELABORADOS!$A$2:$M$6000,2,0),"") | C39: =+A39 -> 0 | D39: =IFERROR(VLOOKUP(H39,[1]SEMIELABORADOS!$A$2:$M$6000,6,0),"") | E39: =IFERROR(VLOOKUP(H39,[1]SEMIELABORADOS!$A$2:$M$65536,10,0),"") | F39: =IFERROR(E39*C39,"") | G39: =IFERROR(F39/$F$66,"")
A40: =+A22 -> 0 | B40: =IFERROR(VLOOKUP(H40,[1]SEMIELABORADOS!$A$2:$M$6000,2,0),"") | C40: =+A40 -> 0 | D40: =IFERROR(VLOOKUP(H40,[1]SEMIELABORADOS!$A$2:$M$6000,6,0),"") | E40: =IFERROR(VLOOKUP(H40,[1]SEMIELABORADOS!$A$2:$M$65536,10,0),"") | F40: =IFERROR(E40*C40,"") | G40: =IFERROR(F40/$F$66,"")
A41: =+A23 -> 0 | B41: =IFERROR(VLOOKUP(H41,[1]SEMIELABORADOS!$A$2:$M$6000,2,0),"") | C41: =+A41 -> 0 | D41: =IFERROR(VLOOKUP(H41,[1]SEMIELABORADOS!$A$2:$M$6000,6,0),"") | E41: =IFERROR(VLOOKUP(H41,[1]SEMIELABORADOS!$A$2:$M$65536,10,0),"") | F41: =IFERROR(E41*C41,"") | G41: =IFERROR(F41/$F$66,"")
A43: UNIDADES | B43: MODI | C43: UNIDADES | D43: UND MEDIDA | E43: COSTO UNITARIO | F43: TOTAL COSTO | G43: % PREC. DEFINIDO | H43: CODIGOS
A44: =+A35 -> 12 | B44: Empaque Almidon Modificado | C44: =+A44 -> 12 | D44: Gramos | E44: 0.01 | F44: =IFERROR(E44*C44,"") -> 0.12 | G44: =IFERROR(F44/$F$66,"") -> 0.00016239087 | H44: SE00014
A45: =+A36 -> 0 | B45: =IFERROR(VLOOKUP(H45,[1]SEMIELABORADOS!$A$2:$M$6000,2,0),"") | C45: =+A45 -> 0 | D45: =IFERROR(VLOOKUP(H45,[1]SEMIELABORADOS!$A$2:$M$6000,6,0),"") | E45: =IFERROR(VLOOKUP(H45,[1]SEMIELABORADOS!$A$2:$M$65536,12,0),"") | F45: =IFERROR(E45*C45,"") | G45: =IFERROR(F45/$F$66,"")
...

Sheet Almibar
C1: SERVICIOS DE PASTELERIA S.A. | H1: CÓDIGO: | I1: ESP-RE-COCS-017
C2: ESPECIFICACION DE RECETA | H2: REVISIÓN: | I2: 01
C3: SE00005 - ALMIBAR | H3: FECHA DE APROBACIÓN: | I3: 45608
C4: Elaborado | D4: Javier Tong, Chef
C5: Aprobado | D5: Esteban Cartin, Gte Manufactura
A6: AREA QUE PRODUCE: | D6: Cocina | G6: AREA QUE EMPACA: | I6: Cocina
A7: # Código | B7: # Código Netsuite | C7: Descripción del ingrediente | D7: Marca | E7: Unidad Internacional | G7: Medida alternativa | I7: Costo - Referencia
E8: Cantidad | F8: Unidad medida | G8: Cantidad | H8: Unidad medida | I8: Colones
C9: Ensamble
A10: 10415 | C10: AGUA POTABLE (PLANTA) | D10: FAS | E10: 21400 | F10: g
A11: 90100131 | B11: SE00016 | C11: AZUCAR BLANCO INDUSTRIAL KILO | D11: FAS | E11: 8000 | F11: g
A12: 10100311 | B12: MP10095 | C12: CANELA EN ASTILLA | D12: PRIMA | E12: 5 | F12: g
A13: 0810288 | B13: MP10598 | C13: JUGO DE NARANJA TB | D13: DOS PINOS | E13: 2000 | F13: g
A14: 1212410 | B14: MP10008 | C14: PRESERVANTE 1047S (PAQ=5 KILO) | D14: ASEAL | E14: 66 | F14: g
C29: Decoración
C35: Empaque
A36: 512000002 | B36: EM10259 | C36: PLAST. AUTOAD 18 * 2000 | D36: Mayca | E36: 90 | F36: Cm
A37: 0702123 | B37: EM10011 | C37: ETIQUETA BLANCA 2 5/8X1 15/16 (UND) | E37: 2 | F37: ud
D46: Cantidad | E46: Unidad
A47: PESO TOTAL OBTENIDO | D47: 31300 | E47: g | F47: Tiempo de Horneo:
A48: TIEMPO TOTAL DE PREPARACION | D48: 15 | E48: min | F48: Horno:
A49: CANTIDAD DE PORCIONES OBTENIDAS | D49: 1 | E49: Porciones | F49: Temperatura de Horneo:
A50: PESO DE CADA PORCIÓN | D50: 31300 | E50: g | F50: Otros
A51: MERMA | D51: 171 | E51: g
A52: PROCEDIMIENTO DE PREPARACION DE LA RECETA
A53: 1 Colocar en una olla el agua, jugo de naranja, azúcar y mezclar bien. Añadir luego el preservante y disolverlo por completo.
A54: 2 Llevar a fuego alto hasta obtener el herbor, dejar herbir unos 5 minutos.sacar la astilla de canela
A55: 3 Despues de la cocción, retirar del fuego y colocar en un bote cubrir con plastico adhesivo y dejar enfirar. Guardar en Camaras de Refrige.
A62: CONTROL DE CAMBIOS

Sheet Costo Almibar Guayaba
E1: Precio Local | F1: Costo MP | G1: Costo EM | H1: Costo MO
E2: =IFERROR(O62,"") -> 250.12403 | F2: =IFERROR(H53,"") -> 83.15 | G2: =IFERROR(H54,"") -> 4 | H2: =IFERROR(H56,"") -> 89
A5: ESTRUCTURA DE COSTOS
F6: Fecha: | H6: =TODAY() -> 45901
A7: UNIDADES | B7: DESCRIPCION MAT.PRIMA | C7: UNIDADES | D7: UND MEDIDA | E7: COSTO UNITARIO | F7: TOTAL COSTO | G7: % PREC. DEFINIDO | H7: CODIGOS
A8: 1 | B8: SABORIZANTE GUAYABA MADURA | C8: =+A8 -> 1 | D8: Gramos | E8: 7.15 | F8: =IFERROR(C8*E8,"") -> 7.15 | G8: =IFERROR(F8/$F$66,"") -> 0.043120865
B9: =IFERROR(VLOOKUP(H9,'[1]Consolidado MP Planta'!$A$2:$M$823,3,0),"") | C9: =+A9 -> 0 | D9: =IFERROR(VLOOKUP(H9,'[1]Consolidado MP Planta'!$A$2:$M$823,13,0),"") | E9: =IFERROR(VLOOKUP(H9,'[1]Consolidado MP Planta'!$A$2:$M$823,12,0),"") | F9: =IFERROR(C9*E9,"") | G9: =IFERROR(F9/$F$66,"")
B10: =IFERROR(VLOOKUP(H10,'[1]Consolidado MP Planta'!$A$2:$M$823,3,0),"") | C10: =+A10 -> 0 | D10: =IFERROR(VLOOKUP(H10,'[1]Consolidado MP Planta'!$A$2:$M$823,13,0),"") | E10: =IFERROR(VLOOKUP(H10,'[1]Consolidado MP Planta'!$A$2:$M$823,12,0),"") | F10: =IFERROR(C10*E10,"") | G10: =IFERROR(F10/$F$66,"")
B11: =IFERROR(VLOOKUP(H11,'[1]Consolidado MP Planta'!$A$2:$M$823,3,0),"") | C11: =+A11 -> 0 | D11: =IFERROR(VLOOKUP(H11,'[1]Consolidado MP Planta'!$A$2:$M$823,13,0),"") | E11: =IFERROR(VLOOKUP(H11,'[1]Consolidado MP Planta'!$A$2:$M$823,12,0),"") | F11: =IFERROR(C11*E11,"") | G11: =IFERROR(F11/$F$66,"")
B12: =IFERROR(VLOOKUP(H12,'[1]Consolidado MP Planta'!$A$2:$M$823,3,0),"") | C12: =+A12 -> 0 | D12: =IFERROR(VLOOKUP(H12,'[1]Consolidado MP Planta'!$A$2:$M$823,13,0),"") | E12: =IFERROR(VLOOKUP(H12,'[1]Consolidado MP Planta'!$A$2:$M$823,12,0),"") | F12: =IFERROR(C12*E12,"") | G12: =IFERROR(F12/$F$66,"")
B13: =IFERROR(VLOOKUP(H13,'[1]Consolidado MP Planta'!$A$2:$M$823,3,0),"") | C13: =+A13 -> 0 | D13: =IFERROR(VLOOKUP(H13,'[1]Consolidado MP Planta'!$A$2:$M$823,13,0),"") | E13: =IFERROR(VLOOKUP(H13,'[1]Consolidado MP Planta'!$A$2:$M$823,12,0),"") | F13: =IFERROR(C13*E13,"") | G13: =IFERROR(F13/$F$66,"")
B14: =IFERROR(VLOOKUP(H14,'[1]Consolidado MP Planta'!$A$2:$M$823,3,0),"") | C14: =+A14 -> 0 | D14: =IFERROR(VLOOKUP(H14,'[1]Consolidado MP Planta'!$A$2:$M$823,13,0),"") | E14: =IFERROR(VLOOKUP(H14,'[1]Consolidado MP Planta'!$A$2:$M$823,12,0),"") | F14: =IFERROR(C14*E14,"") | G14: =IFERROR(F14/$F$66,"")
B15: =IFERROR(VLOOKUP(H15,'[2]ARTICULOS MP PLANTA'!$A$2:$G$589,2,0),"")
A16: UNIDADES | B16: MATERIA PRIMA SEMIELABORADOS | C16: UNIDADES | D16: UND MEDIDA | E16: COSTO UNITARIO | F16: TOTAL COSTO | G16: % PREC. DEFINIDO | H16: CODIGOS
A17: 400 | B17: Almibar | C17: =+A17 -> 400 | D17: Gramos | E17: 0.19 | F17: =IFERROR(E17*C17,"") -> 76 | G17: =IFERROR(F17/$F$66,"") -> 0.45834766 | H17: SE00005
B18: =IFERROR(VLOOKUP(H18,[1]SEMIELABORADOS!$A$2:$M$6000,2,0),"") | C18: =+A18 -> 0 | D18: =IFERROR(VLOOKUP(H18,[1]SEMIELABORADOS!$A$2:$M$6000,6,0),"") | E18: =IFERROR(VLOOKUP(H18,[1]SEMIELABORADOS!$A$2:$H$65536,8,0),"") | F18: =IFERROR(E18*C18,"") | G18: =IFERROR(F18/$F$66,"")
B19: =IFERROR(VLOOKUP(H19,[1]SEMIELABORADOS!$A$2:$M$6000,2,0),"") | C19: =+A19 -> 0 | D19: =IFERROR(VLOOKUP(H19,[1]SEMIELABORADOS!$A$2:$M$6000,6,0),"") | E19: =IFERROR(VLOOKUP(H19,[1]SEMIELABORADOS!$A$2:$H$65536,8,0),"") | F19: =IFERROR(E19*C19,"") | G19: =IFERROR(F19/$F$66,"")
B20: =IFERROR(VLOOKUP(H20,[1]SEMIELABORADOS!$A$2:$M$6000,2,0),"") | C20: =+A20 -> 0 | D20: =IFERROR(VLOOKUP(H20,[1]SEMIELABORADOS!$A$2:$M$6000,6,0),"") | E20: =IFERROR(VLOOKUP(H20,[1]SEMIELABORADOS!$A$2:$H$65536,8,0),"") | F20: =IFERROR(E20*C20,"") | G20: =IFERROR(F20/$F$66,"")
B21: =IFERROR(VLOOKUP(H21,[1]SEMIELABORADOS!$A$2:$M$6000,2,0),"") | C21: =+A21 -> 0 | D21: =IFERROR(VLOOKUP(H21,[1]SEMIELABORADOS!$A$2:$M$6000,6,0),"") | E21: =IFERROR(VLOOKUP(H21,[1]SEMIELABORADOS!$A$2:$H$65536,8,0),"") | F21: =IFERROR(E21*C21,"") | G21: =IFERROR(F21/$F$66,"")
B22: =IFERROR(VLOOKUP(H22,[1]SEMIELABORADOS!$A$2:$M$6000,2,0),"") | C22: =+A22 -> 0 | D22: =IFERROR(VLOOKUP(H22,[1]SEMIELABORADOS!$A$2:$M$6000,6,0),"") | E22: =IFERROR(VLOOKUP(H22,[1]SEMIELABORADOS!$A$2:$H$65536,8,0),"") | F22: =IFERROR(E22*C22,"") | G22: =IFERROR(F22/$F$66,"")
B23: =IFERROR(VLOOKUP(H23,[1]SEMIELABORADOS!$A$2:$M$6000,2,0),"") | C23: =+A23 -> 0 | D23: =IFERROR(VLOOKUP(H23,[1]SEMIELABORADOS!$A$2:$M$6000,6,0),"") | E23: =IFERROR(VLOOKUP(H23,[1]SEMIELABORADOS!$A$2:$H$65536,8,0),"") | F23: =IFERROR(E23*C23,"") | G23: =IFERROR(F23/$F$66,"")
B24: =IFERROR(VLOOKUP(H24,[1]SEMIELABORADOS!$A$2:$M$6000,2,0),"") | C24: =+A24 -> 0 | D24: =IFERROR(VLOOKUP(H24,[1]SEMIELABORADOS!$A$2:$M$6000,6,0),"") | E24: =IFERROR(VLOOKUP(H24,[1]SEMIELABORADOS!$A$2:$H$65536,8,0),"") | F24: =IFERROR(E24*C24,"") | G24: =IFERROR(F24/$F$66,"")
A26: UNIDADES | B26: EMPAQUE | C26: UNIDADES | D26: UND MEDIDA | E26: COSTO UNITARIO | F26: TOTAL COSTO | G26: % PREC. DEFINIDO | H26: CODIGOS
A27: 0 | B27: =IFERROR(VLOOKUP(H27,'[1]Consolidado MP Planta'!$A$2:$M$823,3,0),"") | C27: =+A27 -> 0 | D27: =IFERROR(VLOOKUP(H27,'[1]Consolidado MP Planta'!$A$2:$M$823,13,0),"") | E27: =IFERROR(VLOOKUP(H27,'[1]Consolidado MP Planta'!$A$2:$M$823,12,0),"") | F27: =IFERROR(C27*E27,"") | G27: =IFERROR(F27/$F$66,"")
B28: =IFERROR(VLOOKUP(H28,'[1]Consolidado MP Planta'!$A$2:$M$823,3,0),"") | C28: =+A28 -> 0 | D28: =IFERROR(VLOOKUP(H28,'[1]Consolidado MP Planta'!$A$2:$M$823,13,0),"") | E28: =IFERROR(VLOOKUP(H28,'[1]Consolidado MP Planta'!$A$2:$M$823,12,0),"") | F28: =IFERROR(C28*E28,"") | G28: =IFERROR(F28/$F$66,"")
B29: =IFERROR(VLOOKUP(H29,'[1]Consolidado MP Planta'!$A$2:$M$823,3,0),"") | C29: =+A29 -> 0 | D29: =IFERROR(VLOOKUP(H29,'[1]Consolidado MP Planta'!$A$2:$M$823,13,0),"") | E29: =IFERROR(VLOOKUP(H29,'[1]Consolidado MP Planta'!$A$2:$M$823,12,0),"") | F29: =IFERROR(C29*E29,"") | G29: =IFERROR(F29/$F$66,"")
B30: =IFERROR(VLOOKUP(H30,'[1]Consolidado MP Planta'!$A$2:$M$823,3,0),"") | C30: =+A30 -> 0 | D30: =IFERROR(VLOOKUP(H30,'[1]Consolidado MP Planta'!$A$2:$M$823,13,0),"") | E30: =IFERROR(VLOOKUP(H30,'[1]Consolidado MP Planta'!$A$2:$M$823,12,0),"") | F30: =IFERROR(C30*E30,"") | G30: =IFERROR(F30/$F$66,"")
B31: =IFERROR(VLOOKUP(H31,'[1]Consolidado MP Planta'!$A$2:$M$823,3,0),"") | C31: =+A31 -> 0 | D31: =IFERROR(VLOOKUP(H31,'[1]Consolidado MP Planta'!$A$2:$M$823,13,0),"") | E31: =IFERROR(VLOOKUP(H31,'[1]Consolidado MP Planta'!$A$2:$M$823,12,0),"") | F31: =IFERROR(C31*E31,"") | G31: =IFERROR(F31/$F$66,"")
B32: =IFERROR(VLOOKUP(H32,'[1]Consolidado MP Planta'!$A$2:$M$823,3,0),"") | C32: =+A32 -> 0 | D32: =IFERROR(VLOOKUP(H32,'[1]Consolidado MP Planta'!$A$2:$M$823,13,0),"") | E32: =IFERROR(VLOOKUP(H32,'[1]Consolidado MP Planta'!$A$2:$M$823,12,0),"") | F32: =IFERROR(C32*E32,"") | G32: =IFERROR(F32/$F$66,"")
A34: UNIDADES | B34: EMPAQUE SEMIELABORADOS | C34: UNIDADES | D34: UND MEDIDA | E34: COSTO UNITARIO | F34: TOTAL COSTO | G34: % PREC. DEFINIDO | H34: CODIGOS
A35: =+A17 -> 400 | B35: Almibar | C35: =+A35 -> 400 | D35: Gramos | E35: 0.01 | F35: =IFERROR(E35*C35,"") -> 4 | G35: =IFERROR(F35/$F$66,"") -> 0.024123561 | H35: SE00005
A36: =+A18 -> 0 | B36: =IFERROR(VLOOKUP(H36,[1]SEMIELABORADOS!$A$2:$M$6000,2,0),"") | C36: =+A36 -> 0 | D36: =IFERROR(VLOOKUP(H36,[1]SEMIELABORADOS!$A$2:$M$6000,6,0),"") | E36: =IFERROR(VLOOKUP(H36,[1]SEMIELABORADOS!$A$2:$M$65536,10,0),"") | F36: =IFERROR(E36*C36,"") | G36: =IFERROR(F36/$F$66,"")
A37: =+A19 -> 0 | B37: =IFERROR(VLOOKUP(H37,[1]SEMIELABORADOS!$A$2:$M$6000,2,0),"") | C37: =+A37 -> 0 | D37: =IFERROR(VLOOKUP(H37,[1]SEMIELABORADOS!$A$2:$M$6000,6,0),"") | E37: =IFERROR(VLOOKUP(H37,[1]SEMIELABORADOS!$A$2:$M$65536,10,0),"") | F37: =IFERROR(E37*C37,"") | G37: =IFERROR(F37/$F$66,"")
A38: =+A20 -> 0 | B38: =IFERROR(VLOOKUP(H38,[1]SEMIELABORADOS!$A$2:$M$6000,2,0),"") | C38: =+A38 -> 0 | D38: =IFERROR(VLOOKUP(H38,[1]SEMIELABORADOS!$A$2:$M$6000,6,0),"") | E38: =IFERROR(VLOOKUP(H38,[1]SEMIELABORADOS!$A$2:$M$65536,10,0),"") | F38: =IFERROR(E38*C38,"") | G38: =IFERROR(F38/$F$66,"")
A39: =+A21 -> 0 | B39: =IFERROR(VLOOKUP(H39,[1]SEMIELABORADOS!$A$2:$M$6000,2,0),"") | C39: =+A39 -> 0 | D39: =IFERROR(VLOOKUP(H39,[1]SEMIELABORADOS!$A$2:$M$6000,6,0),"") | E39: =IFERROR(VLOOKUP(H39,[1]SEMIELABORADOS!$A$2:$M$65536,10,0),"") | F39: =IFERROR(E39*C39,"") | G39: =IFERROR(F39/$F$66,"")
A40: =+A22 -> 0 | B40: =IFERROR(VLOOKUP(H40,[1]SEMIELABORADOS!$A$2:$M$6000,2,0),"") | C40: =+A40 -> 0 | D40: =IFERROR(VLOOKUP(H40,[1]SEMIELABORADOS!$A$2:$M$6000,6,0),"") | E40: =IFERROR(VLOOKUP(H40,[1]SEMIELABORADOS!$A$2:$M$65536,10,0),"") | F40: =IFERROR(E40*C40,"") | G40: =IFERROR(F40/$F$66,"")
A41: =+A23 -> 0 | B41: =IFERROR(VLOOKUP(H41,[1]SEMIELABORADOS!$A$2:$M$6000,2,0),"") | C41: =+A41 -> 0 | D41: =IFERROR(VLOOKUP(H41,[1]SEMIELABORADOS!$A$2:$M$6000,6,0),"") | E41: =IFERROR(VLOOKUP(H41,[1]SEMIELABORADOS!$A$2:$M$65536,10,0),"") | F41: =IFERROR(E41*C41,"") | G41: =IFERROR(F41/$F$66,"")
A43: UNIDADES | B43: MODI | C43: UNIDADES | D43: UND MEDIDA | E43: COSTO UNITARIO | F43: TOTAL COSTO | G43: % PREC. DEFINIDO | H43: CODIGOS
A44: =+A35 -> 400 | B44: Almibar | C44: =+A44 -> 400 | D44: Gramos | E44: 0.03 | F44: =IFERROR(E44*C44,"") -> 12 | G44: =IFERROR(F44/$F$66,"") -> 0.072370683 | H44: SE00005
A45: =+A36 -> 0 | B45: =IFERROR(VLOOKUP(H45,[1]SEMIELABORADOS!$A$2:$M$6000,2,0),"") | C45: =+A45 -> 0 | D45: =IFERROR(VLOOKUP(H45,[1]SEMIELABORADOS!$A$2:$M$6000,6,0),"") | E45: =IFERROR(VLOOKUP(H45,[1]SEMIELABORADOS!$A$2:$M$65536,12,0),"") | F45: =IFERROR(E45*C45,"") | G45: =IFERROR(F45/$F$66,"")
...

Sheet Crema Chantilly Blanca 
D1: SERVICIOS DE PASTELERIA S.A. | I1: CÓDIGO: | J1: ESP-RE-DES-036
D2: ESPECIFICACION DE RECETA | I2: REVISIÓN: | J2: 11
D3: Crema Blanca Spoon (20800g) SE00010 | I3: FECHA DE APROBACIÓN: | J3: 45383
D4: Elaborado | E4: Javier Tong, Chef
D5: Aprobado | E5: Esteban Cartin, Gte Manufactura
A6: # Código | B6: # Código | C6: # Codigo Netsuite | D6: Descripción del ingrediente | E6: Marca | F6: Unidad Internacional | H6: Medida alternativa | J6: Costo - Referencia
F7: Cantidad | G7: Unidad medida | H7: Cantidad | I7: Unidad medida | J7: Colones
A8: ICG
A9: 310148 | B9: 310148 | C9: MP10047 | D9: BETTERCREME SUPREMO (UND:4 K) | E9: Richs | F9: 12800 | G9: g
A10: 11400031 | B10: 11400031 | C10: MP10048 | D10: CREMA PRESTIGE GRAND (UND:4 K) | E10: Richs | F10: 3200 | G10: g
A11: 10415 | B11: 10415 | D11: AGUA POTABLE (PLANTA) | E11: AyA | F11: 800 | G11: g
A12: 1212410 | B12: 1212410 | C12: MP10008 | D12: PRESERVANTE 1047S (PAQ=5 KILO) | E12: Aseal | F12: 12 | G12: g
A13: 702069 | B13: 702123 | C13: EM10011 | D13: ETIQUETA BLANCA 2 5/8X1 15/16 (UND) | E13: Etiplas | F13: 1 | G13: ud
E28: Cantidad | F28: Unidad
B29: PESO TOTAL OBTENIDO | E29: =SUM(F9:F12)-E33 -> 16597 | F29: g | G29: Tiempo de Horneo: | I29: 16597
B30: TIEMPO TOTAL DE PREPARACION | E30: 10 | F30: min | G30: Horno:
B31: CANTIDAD DE PORCIONES OBTENIDAS | E31: 1 | F31: Tanda | G31: Temperatura de Horneo: | I31: 0.6
B32: PESO DE CADA PORCIÓN | E32: =E29 -> 16597 | F32: g | G32: Otros
B33: MERMA | E33: 215 | F33: g
B34: PROCEDIMIENTO DE PREPARACION DE LA RECETA
B35: 1.- Abrir los galones de crema y verter dentro de la top cream.
B36: 2.- Disolver el preservante en el agua. Agregar a la top cream.
B37: 3.- Batir por 12 a 15 minutos. Colocar en una tina plastica, tapar.
B38: 4.- Etiquetar con nombre y fecha de vencimiento.
B39: 5.- Mantener en refrigeración.
B40: Control de Cambios
B41: 9, Actuaizacion de codigos
B42: 10, Actuaizacion de procedimiento
B43: 11,Cambio de Pesos

Sheet Premezcla Easy Vainilla 
C1: SERVICIOS DE PASTELERIA S.A. | H1: CÓDIGO: | I1: ESP-RE-PRES-130
C2: ESPECIFICACION DE RECETA | H2: REVISIÓN: | I2: 01
C3: SE00435 Premezcla Easy Queque Vainilla SP | H3: FECHA DE APROBACIÓN: | I3: 45316
C4: Elaborado | D4: Juan Pablo Brenes,chef
C5: Aprobado | D5: Esteban Cartin, Gte Manufactura
A6: AREA QUE PRODUCE: | D6: Premezclas | G6: AREA QUE EMPACA: | I6: Premezclas
A7: # Código | B7: # Código Netsuite | C7: Descripción del ingrediente | D7: Marca | E7: Unidad Internacional | G7: Medida alternativa | I7: Costo - Referencia
E8: Cantidad | F8: Unidad medida | G8: Cantidad | H8: Unidad medida | I8: Colones
A9: 11200082 | B9: MP10490 | C9: Núcleo Vainilla Easy Sp 20% | D9: Puratos | E9: 5100 | F9: g | J9: =+E9/$D$21 -> 0.19626708 | K9: =+J9*1000 -> 196.26708
A10: 510301 | B10: MP10074 | C10: Azucar Blanco Industrial | D10: Layca | E10: 11300 | F10: g | J10: =+E10/$D$21 -> 0.43486627 | K10: =+J10*1000 -> 434.86627
A11: 11200072 | B11: MP10478 | C11: Harina Silver Cake | D11: Silvercake | E11: 8600 | F11: g | J11: =+E11/$D$21 -> 0.33096017 | K11: =+J11*1000 -> 330.96017
A12: 1212410 | B12: MP10008 | C12: Preservante 1047S | D12: Mayca | E12: 50 | F12: g | J12: =+E12/$D$21 -> 0.001924187 | K12: =+J12*1000 -> 1.924187
A13: 11300012 | B13: MP10517 | C13: Acti Egg | D13: Puratos | E13: 335 | F13: g | J13: =+E13/$D$21 -> 0.012892053 | K13: =+J13*1000 -> 12.892053
B14: MP10142 | C14: Clara De Huevo Deshidratada | D14: Quimica Masias | E14: 650 | F14: g | J14: =+E14/$D$21 -> 0.025014431 | K14: =+J14*1000 -> 25.014431
J15: =+E15/$D$21 -> 0 | K15: =+J15*1000 -> 0
A16: 1950708 | B16: EM10013 | C16: Bolsa 17X25 Transparente | E16: 2 | F16: ud | J16: =+E16/$D$21 -> 7.6967481e-05 | K16: =+J16*1000 -> 0.076967481 | L16: =+K16*15 -> 1.1545122 | M16: =+L16/1000 -> 0.0011545122
A17: 702123 | B17: EM10011 | C17: Etiqueta Blanca 2 5/8X1 15/16 | E17: 2 | F17: ud | J17: =+E17/$D$21 -> 7.6967481e-05 | K17: =+J17*1000 -> 0.076967481
D20: Cantidad | E20: Unidad
A21: PESO TOTAL OBTENIDO | D21: 25985 | E21: g | F21: Tiempo de Horneo:
A22: TIEMPO TOTAL DE PREPARACION | D22: 4 | E22: min | F22: Horno:
A23: CANTIDAD DE PORCIONES OBTENIDAS | D23: 1 | E23: TANDA | F23: Temperatura de Horneo:
A24: PESO DE CADA PORCIÓN | D24: 25985 | E24: g | F24: Otros
A25: MERMA | D25: =SUM(E9:E14)-D21 -> 50 | E25: g
A26: PROCEDIMIENTO DE PREPARACION DE LA RECETA
A27: 1.- En una bolsa 17x25 empacar el nucleo easy queque vainilla sp con el azucar, y etiquetar.
A28: 2.- En la otra bolsa 17x25 empacar el harina silver cake con el preservante, actiegg, clara y etiquetar.
A33: Control de cambios
A34: Revision #2: Se agrega clara en polvo

Sheet Batido Easy Vainilla 
C1: SERVICIOS DE PASTELERIA S.A. | H1: CÓDIGO: | I1: ESP-RE-BAF-016
C2: ESPECIFICACION DE RECETA | H2: REVISIÓN: | I2: 02
C3: 907000285(SE00434) Batido Easy queque vainilla SP | H3: FECHA DE APROBACIÓN: | I3: 45618
C4: Elaborado | D4: Javier Tong, Chef
C5: Aprobado | D5: Esteban Cartin, Gte Manufactura
A6: AREA QUE PRODUCE: | D6: Batidos | G6: AREA QUE EMPACA: | I6: Batidos
A7: # Código | B7: # Código Netsuite | C7: Descripción del ingrediente | D7: Marca | E7: Unidad Internacional | G7: Medida alternativa | I7: Costo - Referencia
E8: Cantidad | F8: Unidad medida | G8: Cantidad | H8: Unidad medida | I8: Colones
C9: Ensamble
A10: 906000135 | B10: SE00435 | C10: PREMEZCLA EASY QUEQUE VAINILLA SP | D10: FAS | E10: 25050 | F10: g | J10: =+E10/$D$39 -> 0.42529711
A11: 1210482 | B11: MP10005 | C11: HUEVO LIQUIDO ESPECIAL INNOV (CAJA:10 K) | D11: INNOVO | E11: 8900 | F11: g | J11: =+E11/$D$39 -> 0.15110357 | K11: =+J11*1000 -> 151.10357
A12: 10415 | C12: AGUA POTABLE (PLANTA) | D12: FAS | E12: 5900 | F12: g | J12: =+E12/$D$39 -> 0.10016978
A13: 10100050 | B13: MP10002 | C13: ACEITE CAPULLO RBD (UND:17 L) | D13: CAPULLO | E13: 8200 | F13: g | J13: =+E13/$D$39 -> 0.13921902 | K13: =+J13*1000 -> 139.21902
C21: Decoración
C28: Empaque
D38: Cantidad | E38: Unidad
A39: PESO TOTAL OBTENIDO | D39: 58900 | E39: g | F39: Tiempo de Horneo:
A40: TIEMPO TOTAL DE PREPARACION | D40: 10 | E40: min | F40: Horno:
A41: CANTIDAD DE PORCIONES OBTENIDAS | D41: 1 | E41: ud | F41: Temperatura de Horneo:
A42: PESO DE CADA PORCIÓN | D42: 58900 | E42: g | F42: Otros
A43: MERMA | D43: 650 | E43: g
A44: PROCEDIMIENTO DE PREPARACION DE LA RECETA
A45: 1.- Colocar todos los ingredientes en la batidora y batir con paleta.
A46: 2.- Batir por 1 minutos en velocidad 1.
A47: 3.- Luego batir por 5 minutos a velocidad 2.
A48: 4.- Pasar a dosificar.
A55: CONTROL DE CAMBIOS
A56: 2, Actualizacion de procedimeinto

Sheet Rosquete Vainilla 
C1: SERVICIOS DE PASTELERIA S.A. | H1: CÓDIGO: | I1: ESP-RE-BAF-013
C2: ESPECIFICACION DE RECETA | H2: REVISIÓN: | I2: 01
C3: 907000287(SE00454) Rosquete easy vainilla BC 310g | H3: FECHA DE APROBACIÓN: | I3: 45618
C4: Elaborado | D4: Javier Tong, Chef
C5: Aprobado | D5: Esteban Cartin, Gte Manufactura
A6: AREA QUE PRODUCE: | D6: Batidos | G6: AREA QUE EMPACA: | I6: Batidos
A7: # Código | B7: # Código Netsuite | C7: Descripción del ingrediente | D7: Marca | E7: Unidad Internacional | G7: Medida alternativa | I7: Costo - Referencia
E8: Cantidad | F8: Unidad medida | G8: Cantidad | H8: Unidad medida | I8: Colones
C9: Ensamble
A10: 907000286 | B10: SE00437 | C10: BATIDO EASY VAINILLA BC | D10: FAS | E10: 46000 | F10: g | K10: =+E10/D41 -> 313.40659 | L10: =+K10/1000 -> 0.31340659
A11: 902000019 | C11: MEZCLA P/ENGRASE MOLDES KILO | D11: FAS | E11: 2600 | F11: g | K11: =+E11/D41 -> 17.714286
K19: =SUM(E10:E11) -> 48600
C21: Decoración
C28: Empaque
A29: 702007 | B29: EM10004 | C29: ETIQ.FECHA VENCIMIENTO BLANCO (ROLLO) | D29: ETIPLAST | E29: 11.821429 | F29: ud
A30: 702123 | B30: EM10011 | C30: ETIQUETA BLANCA 2 5/8X1 15/16 (UND) | D30: FAS | E30: 10 | F30: ud
B31: EM10259 | C31: Plastico Autoaderible 1/ 18*2000 | E31: 17 | F31: metros
D38: Cantidad | E38: Unidad
A39: PESO TOTAL OBTENIDO | D39: 45500 | E39: g | F39: Tiempo de Horneo:
A40: TIEMPO TOTAL DE PREPARACION | D40: 50 | E40: min | F40: Horno:
A41: CANTIDAD DE PORCIONES OBTENIDAS | D41: =D39/D42 -> 146.77419 | E41: ud | F41: Temperatura de Horneo:
A42: PESO DE CADA PORCIÓN | D42: 310 | E42: g | F42: Otros
A43: MERMA | D43: =SUM(E10:E11)-D39 -> 3100 | E43: g
A44: PROCEDIMIENTO DE PREPARACION DE LA RECETA
A45: 1.- Dosificar en moldes engrasados 350g de mezcla.
A46: 2.- Hornear por 30 minutos en el Dicte 1 a 175°C, en el Dicte 2 por 20 minutos a 175°C, en el Argental por 20 minutos a 175°C, en el Marshall por 18 minutos a 175°C, en el vulcan a 325°F por 25 minutos y en el Curitiba a 130°C por 28.
A47: 3.- Enfriar, desmoldar, colocar las bandejas en el coche y rapearlo con el plastico, dejando solamente la bandeja superior en bolsa plastica.
A48: 4, Etiquetar
A55: CONTROL DE CAMBIOS
A56: 2, Se actualizan pesos, datos receta y procedimiento.

Sheet Ensamble torta
B1: SERVICIOS DE PASTELERIA S.A. | G1: CÓDIGO:
B2: ESPECIFICACION DE RECETA | G2: REVISIÓN:
B3: Torta brownie y guayaba tricopilia Bucca | G3: FECHA DE APROBACIÓN:
B4: Elaborado | C4: Juan Pablo Brenes,chef
B5: Aprobado | C5: Esteban Cartin, Gerente de Manufactura
A7: AREA QUE PRODUCE: | C7: Decoracion | F7: AREA QUE EMPACA: | H7: Decoracion
A8: # Código | B8: Descripción del ingrediente | C8: Marca | D8: Unidad Internacional | F8: Medida alternativa | H8: Costo - Referencia
D9: Cantidad | E9: Unidad medida | F9: Cantidad | G9: Unidad medida | H9: Colones
A10: SE00454 | B10: Rosquete Vainilla BC 350g | C10: FAS | D10: 300 | E10: g | F10: 1 ud
A11: NUEVO | B11: ALMIBAR GUAYABA | C11: FAS | D11: 120 | E11: g | F11: 60 c/u
A12: NUEVO | B12: RELLENO GUAYABA TRICOPILIA | C12: TRICOPILIA | D12: 380 | E12: g | F12: 3/4 TAZA POR CAPA
A13: NUEVO | B13: ROSQUETE BROWNIE DAWN 400 | C13: FAS | D13: 380 | E13: g | F13: 1 UD
B15: DECORACION
A16: SE00010 | B16: Crema Chantilly Blanca (Spoon-Ind) | C16: FAS | D16: 90 | E16: g
A17: SE00010 | B17: Crema Chantilly Blanca (Spoon-Ind) | C17: FAS | D17: 70 | E17: g | F17: boquilla 4ft | J17: 1800/6
A18: NUEVO | B18: SALSA DE GUAYABA | C18: FAS | D18: 20 | E18: g | F18: marmoleado
A19: NUEVO | B19: SALSA DE GUAYABA | C19: FAS | D19: 85 | E19: g | F19: 1/3 TAZA | J19: =1800/6 -> 300
A20: NUEVO | B20: ROSQUETE BROWNIE DAWN 300 | C20: FAS | D20: 35 | E20: g | F20: 0.1 UD
A21: NUEVO | B21: TRICOPILIA GUAYABA | C21: TRICOPILIA | D21: 32 | E21: g | F21: 2 UD
A22: MP10089 | B22: Brillo Glit | D22: 5 | E22: g | F22: sobre las guayabitas
B24: EMPAQUE
A25: EM10009 | B25: Quequera Red Base/Domo 10 | C25: Export pmt | D25: 1 | E25: ud
A26: EM10084 | B26: Orla # 10 Bucca | D26: 1 | E26: ud
A27: EM10112 | B27: ET. TORTA BUCCA GENERICA | C27: Litografia CR | D27: 1 | E27: ud
A28: EM10005 | B28: ETIQ.FECHA VENCIMIENTO | C28: Etiplast | D28: 1 | E28: ud
A29: EM10002 | B29: ETIQ.BLANCA 1 1/4 * 3/4 | C29: Cemusa | D29: 1 | E29: ud
A30: EM10011 | B30: ETIQUETA BLANCA 2 5/8X1 15/16 PRE BLANCA | C30: Etiplast | D30: 1 | E30: ud
A31: EM10248 | B31: CINTA ADHESIVA TRANSPARENTE 2*100 | C31: Mayca | D31: 60 | E31: cm
B32: ETIQUETA TEMPORADA BUCCA | C32: Litografia CR | D32: 1 | E32: ud
C35: Cantidad | D35: Unidad
A36: PESO TOTAL OBTENIDO | C36: 1500 | D36: g
A37: TIEMPO TOTAL DE PREPARACION | C37: 6 | D37: min
A38: CANTIDAD DE PORCIONES OBTENIDAS | C38: 1 | D38: ud
A39: PESO DE CADA PORCIÓN | C39: 1500 | D39: g
A40: MERMA | C40: =SUM(D10:D21)-C36 -> 12 | D40: g
A41: PROCEDIMIENTO DE PREPARACION DE LA RECETA
A42: 1.- Partir el rosquete por la mitad y bañarlos con 60g de almibar cada uno.
A43: 2.- Colocar 3/4 de taza de relleno de guayaba, luego colocar el brownie y luego 3/4 de taza de relleno de guayaba, y colocar en la orla.
A44: 3.- Encremar con crema blanca y marmolear con la salsa de guayaba.
A45: 4.- Hacer un hueco al centro con la crema para colocar el 1/3 taza de salsa de guayaba
...

Sheet Ensamble 2
B1: SERVICIOS DE PASTELERIA S.A. | G1: CÓDIGO: | H1: ESP-RE-DEF-045
B2: ESPECIFICACION DE RECETA | G2: REVISIÓN: | H2: 05
B3: PTI00245 Torta guayaba tricopilia Bucca | G3: FECHA DE APROBACIÓN: | H3: 45783
B4: Elaborado | C4: Juan Pablo Brenes,chef
B5: Aprobado | C5: Esteban Cartin, Gerente de Manufactura
A7: AREA QUE PRODUCE: | C7: Decoracion | F7: AREA QUE EMPACA: | H7: Decoracion
A8: # Código | B8: Descripción del ingrediente | C8: Marca | D8: Unidad Internacional | F8: Medida alternativa | H8: Costo - Referencia
D9: Cantidad | E9: Unidad medida | F9: Cantidad | G9: Unidad medida | H9: Colones
A10: SE00454 | B10: Rosquete Vainilla BC 350g | C10: FAS | D10: 450 | E10: g | F10: 1 1/2 ud
A11: SE00717 | B11: ALMIBAR GUAYABA | C11: FAS | D11: 150 | E11: g | F11: 50 c/u
A12: MP10763 | B12: RELLENO GUAYABA TRICOPILIA | C12: TRICOPILIA | D12: 220 | E12: g | F12: 1/3 TAZA POR CAPA
A13: SE00718 | B13: RELLENO QUESO BUCCA | C13: FAS | D13: 200 | E13: g | F13: 3/4 taza por capa
B15: DECORACION
A16: SE00010 | B16: Crema Chantilly Blanca (Spoon-Ind) | C16: FAS | D16: 140 | E16: g
A17: SE00010 | B17: Crema Chantilly Blanca (Spoon-Ind) | C17: FAS | D17: 70 | E17: g | F17: boquilla 4ft
A18: SE00719 | B18: SALSA DE GUAYABA | C18: FAS | D18: 10 | E18: g | F18: marmoleado
A19: SE00719 | B19: SALSA DE GUAYABA | C19: FAS | D19: 60 | E19: g | F19: 1/4 TAZA
A20: MP10762 | B20: BOCADITOS TRICOPILIA GUAYABA | C20: TRICOPILIA | D20: 32 | E20: g | F20: 2 UD
A21: MP10089 | B21: Brillo Glit | D21: 5 | E21: g | F21: sobre las guayabitas
B23: EMPAQUE
A24: EM10009 | B24: Quequera Red Base/Domo 10 | C24: Export pmt | D24: 1 | E24: ud
A25: EM10084 | B25: Orla # 10 Bucca | D25: 1 | E25: ud
A26: EM10112 | B26: ET. TORTA BUCCA GENERICA | C26: Litografia CR | D26: 1 | E26: ud
A27: EM10005 | B27: ETIQ.FECHA VENCIMIENTO | C27: Etiplast | D27: 1 | E27: ud
A28: EM10002 | B28: ETIQ.BLANCA 1 1/4 * 3/4 | C28: Cemusa | D28: 1 | E28: ud
A29: EM10443 | B29: Etiqueta Blanca Lisa Bopp Brillante | C29: Etiplast | D29: 1 | E29: ud
A30: EM10248 | B30: CINTA ADHESIVA TRANSPARENTE 2*100 | C30: Mayca | D30: 60 | E30: cm
A31: EM10448 | B31: Etiqueta Torta Tricopilia Guayaba | C31: Litografia CR | D31: 1 | E31: ud
C34: Cantidad | D34: Unidad
A35: PESO TOTAL OBTENIDO | C35: 1272 | D35: g
A36: TIEMPO TOTAL DE PREPARACION | C36: 6 | D36: min
A37: CANTIDAD DE PORCIONES OBTENIDAS | C37: 1 | D37: ud
A38: PESO DE CADA PORCIÓN | C38: 1272 | D38: g
A39: MERMA | C39: =SUM(D10:D21)-C35 -> 65 | D39: g
A40: PROCEDIMIENTO DE PREPARACION DE LA RECETA
A41: 1.- Partir el rosquete por la mitad y bañarlos con 50g de almibar cada uno.
A42: 2.- Colocar 1/3 taza de relleno de guayaba y 3/4 de taza de relleno de queso en ambas capas y colocar en la orla
A43: 3.- Encremar con crema blanca y marmolear con la salsa de guayaba.
A44: 4.- Hacer colochos con la boquilla 4ft del borde al centro en doble fila, al centro colocar la salsa de guayaba
A45: 5.- Colocar las guayabas en un borde y bañarlas con el brillo glit.
...

Sheet Costo Ensamble 
E1: Precio Local | F1: Costo MP | G1: Costo EM | H1: Costo MO
E2: =IFERROR(O64,"") -> 4155.2356 | F2: =IFERROR(H55,"") -> 2438.2308 | G2: =IFERROR(H56,"") -> 661.00814 | H2: =IFERROR(H58,"") -> 576.679
A5: ESTRUCTURA DE COSTOS
F6: Fecha: | H6: =TODAY() -> 45901
A7: UNIDADES | B7: DESCRIPCION MAT.PRIMA | C7: UNIDADES | D7: UND MEDIDA | E7: COSTO UNITARIO | F7: TOTAL COSTO | G7: % PREC. DEFINIDO | H7: CODIGOS
