Workbook

Sheet Emsamble Industria
C1: SERVICIOS DE PASTELERIA S.A. | H1: CÓDIGO:
C2: ESPECIFICACION DE RECETA | H2: REVISIÓN:
C3: Ensamble de Hershey"s Kisses Industria | H3: FECHA DE APROBACIÓN:
C4: Elaborado | D4: Jose Brizuela, chef
C5: Aprobado | D5: Esteban Cartin, Gte Manufactura
A6: AREA QUE PRODUCE: | D6: Decoracion | G6: AREA QUE EMPACA: | I6: Decoracion
A7: # Código | B7: # Codigo Netsuite | C7: Descripción del ingrediente | D7: Marca | E7: Unidad Internacional | G7: Medida alternativa | I7: Costo - Referencia
E8: Cantidad | F8: Unidad medida | G8: Cantidad | H8: Unidad medida | I8: Colones
C9: Emsamble
A10: 907000268 | B10: SE00345 | C10: ROSQUETE CHOCOLATE DAWN 400g | D10: FAS | E10: 335 | F10: g | G10: ud | H10: Partido a la mitad
A11: 910000003 | B11: SE00254 | C11: Leches Pasteurizada Con Agua | D11: FAS | E11: 100 | F11: g | H11: 50 g por tapa
A12: 902000168 | B12: SE00468 | C12: MOUSSE DE CHOCOLATE DE LECHE | D12: FAS | E12: 150 | F12: g | H12: 1 Taza
C13: Rosquete Brownie Redondo de 450 gramos | D13: FAS | E13: 430 | F13: g | H13: 1 unidad
A14: 908000032 | B14: SE00001 | C14: Ganache Chocolate Oscuro | D14: FAS | E14: 90 | F14: g | H14: 1/3 Taza
C15: Semi Sweet Chocolate Chips | D15: Hershey"s | E15: 60 | F15: g | H15: 1/3 taza
C16: Decoracion
A17: 910000018 | B17: SE00069 | C17: Crema Beidge | D17: FAS | E17: 150 | F17: g | I17: Encremado
A18: 11400027 | B18: MP10006 | C18: Crema Bettercream Doble Chocolate | D18: Richt | E18: 20 | F18: g | I18: Paredes
A19: 908000032 | B19: SE00001 | C19: Ganache Chocolate Oscuro | D19: FAS | E19: 20 | F19: g | I19: Para decoracion
C20: Rosquete Brownie Redondo de 450 gramos | D20: FAS | E20: 215 | F20: g | H20: 1/2 media Unidad | I20: por torta
C21: Hershey"s Kisses | D21: Hershey"s | E21: 12 | F21: ud
C22: EMPAQUE
A24: 121603 | B24: EM10009 | C24: QUEQUERA RED BASE/DOMO 10 (CAJA:50) | D24: MAYCA | E24: 1 | F24: ud
A25: 1950692 | B25: EM10008 | C25: ORLA CARTON 10" DORADA UND | D25: Mayca | E25: 1 | F25: Ud
A26: 702069 | B26: EM10002 | C26: Etiq.Blanca 1 1/4 * 3/4 | D26: ETIPLAST | E26: 1 | F26: ud
A27: 0703020 | B27: EM10248 | C27: CINTA ADHESIVA TRANSPARENTE 2*100 | D27: Mayca | E27: 60 | F27: cm
A28: 701096 | B28: EM10124 | C28: ETIQUETA BLANCA R-153 | D28: Cemusa | E28: 1 | F28: ud
A29: 0702123 | B29: EM10011 | C29: ETIQUETA BLANCA 2 5/8X1 15/16 PRE BLANCA | D29: Etiplast | E29: 1 | F29: ud
A30: 60100120 | B30: EM10314 | C30: Etiqueta Edicion Especial | D30: ETIPLAST | E30: 1 | F30: ud
C31: Etiqueta Especial | E31: 1 | F31: ud
D32: Cantidad | E32: Unidad
A33: PESO TOTAL OBTENIDO | D33: 1500 | E33: g | F33: Tiempo de Horneo:
A34: TIEMPO TOTAL DE PREPARACION | D34: 4 | E34: min | F34: Horno:
A35: CANTIDAD DE PORCIONES OBTENIDAS | D35: 1 | E35: ud | F35: Temperatura de Horneo:
A36: PESO DE CADA PORCIÓN | D36: 1500 | E36: g | F36: Otros
A37: MERMA | D37: =SUM(E10:E20)-D33 -> 70 | E37: g
A38: PROCEDIMIENTO DE PREPARACION DE LA RECETA
A39: 1-Partir el Rosquette por la mitad y bañar con la leche ambas tapas ,Colocar la mousse sobre una capa y el Rosquete de Brownie
A40: 2-Sobre el rosquete de Brownie colocar el ganache de chocolate y exparsir uniformemente, luego agregar los Semi Sweet chocolate
A41: 3-Tapar con la otra mitad del rosquette
...

Sheet Ensamble Industria 2
C1: SERVICIOS DE PASTELERIA S.A. | H1: CÓDIGO:
C2: ESPECIFICACION DE RECETA | H2: REVISIÓN:
C3: Ensamble de Hershey"s Kisses Industria | H3: FECHA DE APROBACIÓN:
C4: Elaborado | D4: Javier Tong, chef
C5: Aprobado | D5: Esteban Cartin, Gte Manufactura
A6: AREA QUE PRODUCE: | D6: Decoracion | G6: AREA QUE EMPACA: | I6: Decoracion
A7: # Código | B7: # Codigo Netsuite | C7: Descripción del ingrediente | D7: Marca | E7: Unidad Internacional | G7: Medida alternativa | I7: Costo - Referencia
E8: Cantidad | F8: Unidad medida | G8: Cantidad | H8: Unidad medida | I8: Colones
C9: Emsamble
A10: 907000268 | B10: SE00345 | C10: ROSQUETE CHOCOLATE DAWN 400g | D10: FAS | E10: 335 | F10: g | G10: 1 ud | H10: Partido a la mitad
A11: 910000003 | B11: SE00254 | C11: Leches Pasteurizada Con Agua | D11: FAS | E11: 100 | F11: g | H11: 50 g por tapa
A12: 902000168 | B12: SE00468 | C12: MOUSSE DE CHOCOLATE DE LECHE | D12: FAS | E12: 150 | F12: g | H12: 1 Taza
C13: Rosquete Brownie Redondo de 450 gramos | D13: FAS | E13: 170 | F13: g | H13: 1/2 unidad | I13: Cortado en Trozos
A14: 908000032 | B14: SE00001 | C14: Ganache Chocolate Oscuro | D14: FAS | E14: 90 | F14: g | H14: 1/3 Taza
C15: Semi Sweet Chocolate Chips | D15: Hershey"s | E15: 40 | F15: g | H15: 1/4 taza
C16: Decoracion
A17: 910000018 | B17: SE00069 | C17: Crema Beidge | D17: FAS | E17: 150 | F17: g | I17: Encremado
A18: 11400027 | B18: MP10006 | C18: Crema Bettercream Doble Chocolate | D18: Richt | E18: 20 | F18: g | I18: Marmolear Paredes
A19: 908000032 | B19: SE00001 | C19: Ganache Chocolate Oscuro | D19: FAS | E19: 20 | F19: g | I19: Para decoracion
C20: Rosquete Brownie Redondo de 450 gramos | D20: FAS | E20: 170 | F20: g | H20: 1/2 unidad por torta | I20: Cortado en Trozos
C21: Hershey"s Kisses | D21: Hershey"s | E21: 12 | F21: ud
C22: EMPAQUE
A24: 121603 | B24: EM10009 | C24: QUEQUERA RED BASE/DOMO 10 (CAJA:50) | D24: MAYCA | E24: 1 | F24: ud
A25: 1950692 | B25: EM10008 | C25: ORLA CARTON 10" DORADA UND | D25: Mayca | E25: 1 | F25: Ud
A26: 702069 | B26: EM10002 | C26: Etiq.Blanca 1 1/4 * 3/4 | D26: ETIPLAST | E26: 1 | F26: ud
A27: 0703020 | B27: EM10248 | C27: CINTA ADHESIVA TRANSPARENTE 2*100 | D27: Mayca | E27: 60 | F27: cm
A28: 701096 | B28: EM10124 | C28: ETIQUETA BLANCA R-153 | D28: Cemusa | E28: 1 | F28: ud
A29: 0702123 | B29: EM10011 | C29: ETIQUETA BLANCA 2 5/8X1 15/16 PRE BLANCA | D29: Etiplast | E29: 1 | F29: ud
A30: 60100120 | B30: EM10314 | C30: Etiqueta Edicion Especial | D30: ETIPLAST | E30: 1 | F30: ud
C31: Etiqueta Especial Temporada | E31: 1 | F31: ud
D32: Cantidad | E32: Unidad
A33: PESO TOTAL OBTENIDO | D33: 1150 | E33: g | F33: Tiempo de Horneo:
A34: TIEMPO TOTAL DE PREPARACION | D34: 10 | E34: min | F34: Horno:
A35: CANTIDAD DE PORCIONES OBTENIDAS | D35: 1 | E35: ud | F35: Temperatura de Horneo:
A36: PESO DE CADA PORCIÓN | D36: 1150 | E36: g | F36: Otros
A37: MERMA | D37: 107 | E37: g
A38: PROCEDIMIENTO DE PREPARACION DE LA RECETA
A39: 1- Partir el Rosquette por la mitad y bañar con la leche ambas tapas ,la mousse y Rosquete de Brownie en trozos.
A40: 2- Agregar los Semi Sweet chocolate
A41: 3-Tapar con la otra mitad del rosquette untada con ganache
...

Sheet Rosquete Choco Dawn
C1: SERVICIOS DE PASTELERIA S.A. | H1: CÓDIGO: | I1: ESP-RE-BAS-152
C2: ESPECIFICACION DE RECETA | H2: REVISIÓN: | I2: 02
C3: 907000268(SE00345) ROSQUETE CHOCOLATE DAWN 400g | H3: FECHA DE APROBACIÓN: | I3: 23/03/2023
C4: Elaborado | D4: Javier Tong, Chef
C5: Aprobado | D5: Esteban Cartin, Gte Manufactura
A6: # Código | B6: # Codigo Netsuite | C6: Descripción del ingrediente | D6: Marca | E6: Unidad Internacional | G6: Medida alternativa | I6: Costo - Referencia
E7: Cantidad | F7: Unidad medida | G7: Cantidad | H7: Unidad medida | I7: Colones
A8: 907000264 | B8: SE00342 | C8: BATIDO NUCLEO CHOCOLATE DAWN | D8: FAS | E8: 39000 | F8: g
C10: EMPAQUE
A11: 902000019 | C11: MEZCLA P/ENGRASE MOLDES KILO | D11: Fas | E11: =15*97 -> 1455 | F11: g
A12: 1950928 | B12: AS00028 | C12: BOLSA TRANSPARENTE 56X96X1.80 KILO | D12: Plasticos P | E12: 8 | F12: ud
A13: 702123 | B13: EM10011 | C13: ETIQUETA BLANCA 2 5/8X1 15/16 (UND) | D13: Etiplast | E13: 8 | F13: ud
A14: 0702007 | B14: EM10004 | C14: ETIQ.FECHA VENCIMIENTO BLANCO (ROLLO) | D14: Etiplast | E14: 8 | F14: ud
D16: Cantidad | E16: Unidad
A17: PESO TOTAL OBTENIDO | D17: =97*400 -> 38800 | E17: g | F17: Tiempo de Horneo:
A18: TIEMPO TOTAL DE PREPARACION | D18: 40 | E18: Min | F18: Horno:
A19: CANTIDAD DE PORCIONES OBTENIDAS | D19: =+D17/D20 -> 97 | E19: ud | F19: Temperatura de Horneo:
A20: PESO POR PORCION | D20: 400 | E20: g | F20: Otros | K20: =97/2 -> 48.5
A21: MERMA | D21: =+E8-D17 -> 200 | E21: g
A22: PROCEDIMIENTO DE PREPARACION DE LA RECETA
A23: 1.- Dosificar 400g de mezcla en moldes engrasados. Hornear en Dicte 1 o 2 a 185°C por 50 min
A24: 2.- Enfriar y colocar en latas limpias, 12 unidades por lata, envolver en bolsa plastica y etiquetar con fecha de producción.
A26: Control de cambios
A27: 2, Cambio de horneo

Sheet Batido Nucleo chocolate Dawn
C1: SERVICIOS DE PASTELERIA S.A. | H1: CÓDIGO: | I1: ESP-RE-BAS-148
C2: ESPECIFICACION DE RECETA | H2: REVISIÓN: | I2: 02
C3: 907000264(SE00342) Batido Nucleo Chocolate Dawn | H3: FECHA DE APROBACIÓN: | I3: 44671
C4: Elaborado | D4: Javier Tong, chf
C5: Aprobado | D5: Esteban Cartin, Gte Manufactura
A7: AREA QUE PRODUCE: | D7: Premezcla | G7: AREA QUE EMPACA: | I7: Premezcla
A8: # Código | B8: # Codigo Netsuite | C8: Descripción del ingrediente | D8: Marca | E8: Unidad Internacional | G8: Medida alternativa | I8: Costo - Referencia
E9: Cantidad | F9: Unidad medida | G9: Cantidad | H9: Unidad medida | I9: Colones
A10: 906000130 | B10: SE00341 | C10: Premezcla Batido Nucleo Chocolate Dawn | D10: FAS | E10: 21971 | F10: g | G10: =E10/39 -> 563.35897
A11: 1210482 | B11: MP10005 | C11: HUEVO ENTERO PASTERI INNOVO ( CAJA: 10 K) | D11: INNOVO | E11: 6687 | F11: g | G11: =66*2 -> 132
A12: 10100050 | B12: MP10002 | C12: ACEITE CAPULLO RBD (UND:17 L) | D12: CAPULLO | E12: 5732 | F12: g | G12: =57*2 -> 114
A13: 10415 | C13: AGUA POTABLE (PLANTA) | D13: FAS | E13: 5350 | F13: g | G13: =53*2 -> 106
E23: =10/39 -> 0.25641026
D26: Cantidad | E26: Unidad
A27: PESO TOTAL OBTENIDO | D27: 39000 | E27: g
A28: TIEMPO TOTAL DE PREPARACION | D28: 10 | E28: min
A29: CANTIDAD DE PORCIONES OBTENIDAS | D29: 1 | E29: Tanda
A30: PESO DE CADA PORCIÓN | D30: =+D27 -> 39000 | E30: g
A31: MERMA | D31: =SUM(E10:E13)-D27 -> 740 | E31: g
A32: PROCEDIMIENTO DE PREPARACION DE LA RECETA
A33: 1, Disolver el preservante y el polvo de hornear con el agua y ayuda de un batidor de mano.
A34: 2, Colocar los liquidos en la batidora, posterior agregar los ingredientes secos
A35: 3, Batir por 1 min en velocidad 1. Con paleta
A36: 4, Batir 5 min en velocidad 2. con Paleta
A42: Control de cambios
A43: 2, Cambio en procedimiento

Sheet Premezcla Batido Choco Dawn
C1: SERVICIOS DE PASTELERIA S.A. | H1: CÓDIGO: | I1: ESP-RE-PRES-127
C2: ESPECIFICACION DE RECETA | H2: REVISIÓN: | I2: 05
C3: SE00341 Premezcla Batido Nucleo Chocolate Dawn | H3: FECHA DE APROBACIÓN: | I3: 45187
C4: Elaborado | D4: Javier Tong, chf
C5: Aprobado | D5: Esteban Cartin, Gte Manufactura
A7: AREA QUE PRODUCE: | D7: Premezcla | G7: AREA QUE EMPACA: | I7: Premezcla
A8: # Código | B8: # Codigo Netsuite | C8: Descripción del ingrediente | D8: Marca | E8: Unidad Internacional | G8: Medida alternativa | I8: Costo - Referencia
E9: Cantidad | F9: Unidad medida | G9: Cantidad | H9: Unidad medida | I9: Colones
A10: 510301 | B10: MP10074 | C10: AZUCAR BLANCO INDUSTRIAL (SACO:50 K) | D10: LAICA | E10: 10028 | F10: g
A11: 11200072 | B11: MP10478 | C11: HARINA SILVER CAKE | D11: FAHACASA | E11: 3800 | F11: g
A12: 11200071 | B12: MP10479 | C12: HARINA VERDE | D12: FAHACASA | E12: 2012 | F12: g
A13: 10100046 | B13: MP10304 | C13: POLVO HORNEAR FLEISHMAN (PAQ:2.5 K) | D13: FLEISHMAN | E13: 134 | F13: g
A14: 1212410 | B14: MP10008 | C14: PRESERVANTE 1047S (PAQ=5 KILO) | D14: ASEAL | E14: 80 | F14: g
A15: 0512255 | B15: MP10146 | C15: Cocoa Dutch Process | D15: DUTCH | E15: 573 | F15: g
A16: 1160001 | B16: MP10203 | C16: GOMA XANTANA | D16: MABAKER & CHEF | E16: 92 | F16: g
A17: 11200073 | B17: MP10482 | C17: COCENTRADO CHOCOLATE DAWN | D17: DAWN | E17: 5278 | F17: g
A19: 1950708 | B19: EM10013 | C19: BOLSA 17x25 TRANSP KILO | E19: 2 | F19: ud
A20: 60100010 | B20: EM10133 | C20: ETIQUETA ROJA LETRA ALERJENO (UND) | E20: 1 | F20: ud
A21: 702123 | B21: EM10011 | C21: ETIQUETA BLANCA 2 5/8X1 15/16 (UND) | E21: 2 | F21: ud
A22: 1950705 | B22: EM10037 | C22: BOLSA 8x12 TRANSPARENTE KILO | E22: 1 | F22: ud
E25: =3/21 -> 0.14285714
D27: Cantidad | E27: Unidad
A28: PESO TOTAL OBTENIDO | D28: =SUM(E10:E17) -> 21997 | E28: g
A29: TIEMPO TOTAL DE PREPARACION | D29: 3 | E29: min
A30: CANTIDAD DE PORCIONES OBTENIDAS | D30: 1 | E30: ud
A31: PESO DE CADA PORCIÓN | D31: =+D28 -> 21997 | E31: g
A32: MERMA | D32: 0 | E32: g
A33: PROCEDIMIENTO DE PREPARACION DE LA RECETA
A34: 1, En una bolsa 17x25 empacar el azucar. Etiquetar
A35: 2, En una bolsa 17x25 empacar las harinas, concentrado, la cocoa y la goma. Etiquetar
A36: 3, En una bolsa 8*12 pesar el polvo de hornear y el preservante. Colcoarla dentro de la bolsa de harinas.
A43: Control de cambios
A44: 2, Se pesa el preservante y el polvo de hornear por aparte.
A45: Revision #3 : actualizacion de la cocoa
A46: 4, Actualizacion de procedimiento y bolsas
A47: Revision #5: Actualizacion en el peso de la goma xantana.

Sheet Leches Pasteurizada c Agua
C1: SERVICIOS DE PASTELERIA S.A. | H1: CÓDIGO: | I1: ESP-RE-DES-063
C2: ESPECIFICACION DE RECETA | H2: REVISIÓN: | I2: 02
C3: Leches pasteurizadas con Agua 320g Spoon 910000003(SE00254) | H3: FECHA DE APROBACIÓN: | I3: 24/04/2023
C4: Elaborado | D4: Javier Tong, chef
C5: Aprobado | D5: Esteban Cartin, Gte Manufactura
A6: # Código | B6: # Codigo Netsuite | C6: Descripción del ingrediente | D6: Marca | E6: Unidad Internacional | G6: Medida alternativa | I6: Costo - Referencia
E7: Cantidad | F7: Unidad medida | G7: Cantidad | H7: Unidad medida | I7: Colones
A9: 907000001 | B9: SE00031 | C9: MEZCLA DE LECHE PASTEURIZADA | D9: FAS | E9: 1600 | F9: g
C10: AGUA | D10: FAS | E10: 1600 | F10: g
A11: 1212412 | B11: MP10025 | C11: PRESERVANTE 1017 (PAQ=5 KILO) | D11: Aseal | E11: 3 | F11: g
D15: Cantidad | E15: Unidad
A16: PESO TOTAL OBTENIDO | D16: =SUM(E9:E11)-D20 -> 3200 | E16: g | F16: Tiempo de Horneo:
A17: TIEMPO TOTAL DE PREPARACION | D17: 5 | E17: Minutos | F17: Horno:
A18: CANTIDAD DE PORCIONES OBTENIDAS | D18: 10 | E18: Tortas | F18: Temperatura de Horneo:
A19: PESO DE CADA PORCIÓN | D19: 320 | E19: g | F19: Otros
A20: MERMA | D20: 3 | E20: g
A21: PROCEDIMIENTO DE PREPARACION DE LA RECETA
A22: 1.- Colocar la mezcla de leches con agua y preservante en un balde.
A25: Control de cambios
A26: 2, Actualizacion coigo de leche pasteurizada.

Sheet Mezcla leche Pasteuriza 
C1: SERVICIOS DE PASTELERÍA S.A. | H1: CODIGO: | I1: ESP-RE-POS-072
C2: ESPECIFICACIÓN DE RECETA | H2: REVISION: | I2: 15
C3: Mezcla para Tres Leches Pasteurizada SE00031 | H3: FECHA DE APROBACION: | I3: 45235
C4: ELABORADO: | D4: Javier, Tong. Chef
C5: APROBADO: | D5: Esteban Cartin. Gte de Manufactura
A6: # Código | B6: # Código Netsuite | C6: Descripción del ingrediente | D6: Marca | E6: Unidad Internacional | G6: Medida alternativa | I6: Costo - Referencia
E7: Cantidad | F7: Unidad medida | G7: Cantidad | H7: Unidad medida | I7: Colones
A8: 11400047 | B8: MP10030 | C8: LECHE 2% PASTEURIZADA (UND) | D8: Dos Pinos | E8: 12230 | F8: g
A9: 1110414 | B9: MP10024 | C9: LECHE EVAPORADA (LITRO) | D9: Nestle | E9: 17430 | F9: g
A10: 11400046 | B10: MP10050 | C10: LECHE CONDENSADA | D10: Nestle | E10: 17430 | F10: g
A11: 11400031 | B11: MP10048 | C11: CREMA PRESTIGE GRAND | D11: Rich | E11: 14000 | F11: g
A12: 90100131 | B12: SE00016 | C12: AZUCAR BLANCO INDUSTRIAL KILO | D12: FAS | E12: 1475 | F12: g
A13: 1212410 | B13: MP10008 | C13: PRESERVANTE 1047S (PAQ=5 KILO) | D13: Aseal | E13: 140 | F13: g
D14: Cantidad | E14: Unidad
A15: TIEMPO mano obra directa | D15: 8 Min
A16: MANO OBRA EMPACANDO | D16: 3 Min
A17: PESO TOTAL OBTENIDO | D17: 62500g | F17: MERMA | H17: 205g
A18: PORCIONES OBTENIDAS | D18: 1 Tanda
A19: TIEMPO PASTEURIZACIÓN EN MAQUINA | D19: 1 HORA
A20: DESCRIPCION DE LA PREPARACION DE LA RECETA
A21: 1. Disolver completamente el preservante en un litro de leche estandar empleando el homogenizador manual.
A22: 2. Colocar en la batidora, la leche fluida, la leche evaporada, el litro de leche con el preservante ya disuelto, el azúcar, la crema prestige líquida y la leche condensada.
A23: 3. Dosificar la mezcla pasteurizada en recipientes de acero inoxidable previamente lavado de acuerdo a INS-LMP-019 Recipiente para el Almacenamiento de Leche Pasteurizada, tapar el recipiente hermeticamente y reservar hasta su uso.
A24: 4. Identificar los recipientes con nombre del producto, fecha de producción y responsable.
A25: 5. Esta mezcla tiene una vida útil de 2 días envasada en recipientes de acero inoxidable herméticamente cerrados y mantenida en refrigeración
A26: 0ºC y 5ªC. Terminado el proceso proceder a la limpieza del equipo y a la sanitización.
A27: Control de cambios
A28: 14, Actualizacion de codigos
A30: Revision #15: Actualizacion del procedimiento.

Sheet Mousse Chocolate Leche 
C1: SERVICIOS DE PASTELERIA S.A. | H1: CÓDIGO: | I1: ESP-RE-POS-260
C2: ESPECIFICACION DE RECETA | H2: REVISIÓN: | I2: 05
C3: SE00468 MOUSSE DE CHOCOLATE DE LECHE | H3: FECHA DE APROBACIÓN: | I3: 45520
C4: Elaborado | D4: Javier Tong, Chef
C5: Aprobado | D5: Esteban Cartin, Gte Manufactura
A7: AREA QUE PRODUCE: | D7: POSTRES | G7: AREA QUE EMPACA: | I7: POSTRES
A8: # Código | B8: # Código Netsuite | C8: Descripción del ingrediente | D8: Marca | E8: Unidad Internacional | G8: Medida alternativa | I8: Costo - Referencia
E9: Cantidad | F9: Unidad medida | G9: Cantidad | H9: Unidad medida | I9: Colones
A10: 10100331 | B10: MP10492 | C10: CHOCOLATE SEMI AMARGO 54% (PAQ 5 k) | D10: NACIONAL DE CHOCOLATES | E10: 1500 | F10: g
A11: 11400031 | B11: MP10048 | C11: CREMA PRESTIGE GRAND (UND:4 K) | D11: RICHS | E11: 1000 | F11: g
A13: 11400031 | B13: MP10048 | C13: CREMA PRESTIGE GRAND (UND:4 K) | D13: RICHS | E13: 2000 | F13: g | G13: Para batir
B14: MP10008 | C14: Preservante 1047S | D14: ASEAL | E14: 8 | F14: g
D18: Cantidad | E18: Unidad
A19: PESO TOTAL OBTENIDO | D19: 4200 | E19: g
A20: TIEMPO TOTAL DE PREPARACION | D20: 15 | E20: min
A21: CANTIDAD DE PORCIONES OBTENIDAS | D21: 1 | E21: ud
A22: PESO DE CADA PORCIÓN | D22: 4200 | E22: g
A23: MERMA | D23: 300 | E23: g
A24: PROCEDIMIENTO DE PREPARACION DE LA RECETA
A25: 1, Colocar el chocolate en un recipiente junto con la crema del ganache y derretir en microondas o Baño maria.
A26: 2, Batir la otra cantidad de crema hasta punto yogurt con globo en velocidad alta.
A27: 3, Agregar el chocolate derretido y el preservante a la crema batida en velocidad media hasta homogeneo.
A28: 4, Utilizar de inmediato
A34: CONTROL DE CAMBIOS
A35: 2,- Se aumenta la cantida de prestige por tanda
A36: 3,- Se ajusta el rendimiento.
A37: 4- Se agrega codigo netsuite
A38: 5- Agregar preservante

Sheet Ganache Chocolate Oscuro
D1: SERVICIOS DE PASTELERIA S.A. | I1: CÓDIGO: | J1: ESP-RE-COCS-048
D2: ESPECIFICACION DE RECETA | I2: REVISIÓN: | J2: 10
D3: 908000032(SE00001) Ganache De chocolate Oscuro 40700g | I3: FECHA DE APROBACIÓN: | J3: 45400
D4: Elaborado | E4: Javier Tong, Chef
D5: Aprobado | E5: Jeffry Rodriguez. Gte de Manufactura
B6: # Código | C6: # Codigo Netsuite | D6: Descripción del ingrediente | E6: Marca | F6: Unidad Internacional | H6: Medida alternativa | J6: Costo - Referencia
F7: Cantidad | G7: Unidad medida | H7: Cantidad | I7: Unidad medida | J7: Colones
B9: 1210386 | C9: MP10001 | D9: COBERTURA CHOCOLATE LECHE ( 5KG ) | E9: Nacional Chocolate | F9: 22000 | G9: g | K9: =+F9/40.7 -> 540.54054
B10: 11400027 | C10: MP10006 | D10: CREMA BETTERCREAM DOBLE CHOCO 4K | E10: Richs | F10: 20000 | G10: g | K10: =+F10/40.7 -> 491.40049
K11: =+F11/40.7 -> 0
B12: 0702069 | C12: EM10002 | D12: ETIQ.BLANCA 1 1/4 * 3/4 | E12: Cemusa | F12: 1 | G12: ud | K12: =+F12/40.7 -> 0.024570025
E15: Cantidad | F15: Unidad
B16: PESO TOTAL OBTENIDO | E16: 40700 | F16: g | G16: Tiempo de Horneo:
B17: TIEMPO TOTAL DE PREPARACION | E17: 30 | F17: Minutos | G17: Horno: | L17: =30/40.7 -> 0.73710074
B18: CANTIDAD DE PORCIONES OBTENIDAS | E18: 1 | F18: Tanda | G18: Temperatura de Horneo:
B19: PESO DE CADA PORCIÓN | E19: =E16 -> 40700 | F19: g | G19: Otros
B20: MERMA | E20: =SUM(F9:F10)-E16 -> 1300 | F20: g
B21: PROCEDIMIENTO DE PREPARACION DE LA RECETA
B22: 1- Colocar la crema de chocolate en una olla y calentar hasta 55 grados hasta hervir, agregar primero la mitad del chocolate. Mezclar hasta derretir.
B23: 2.- Añadir luego la mitad restante de chocolate, mezclar bien hasta derretir completamente el chocolate.
B24: 3- Pasar el ganache caliente por un colador para evitar que queden grumos de chocolate.
B25: 4.- Colocar en cheffing de acero y enfriar.
B27: Control Cambios
B28: 10-Se Agrega temperatura de crema Chocolate

Sheet Crema Beidge
D1: SERVICIOS DE PASTELERIA S.A. | I1: CÓDIGO: | J1: ESP-RE-DES-042
D2: ESPECIFICACION DE RECETA | I2: REVISIÓN: | J2: 08
D3: Crema Beidge SE00069 | I3: FECHA DE APROBACIÓN: | J3: 45513
D4: Elaborado | E4: Javier Tong, Chef
D5: Aprobado | E5: Esteban Cartin, Gte Manufactura
B6: # Código | C6: # Codigo Netsuite | D6: Descripción del ingrediente | E6: Marca | F6: Unidad Internacional | H6: Medida alternativa | J6: Costo - Referencia
F7: Cantidad | G7: Unidad medida | H7: Cantidad | I7: Unidad medida | J7: Colones
B8: 95717 | C8: SE00010 | D8: CREMA CHANTILLY BLANCA SPOON-IND KILO | E8: FAS | F8: 16580 | G8: g | H8: =F8/20.8 -> 797.11538
A9: 104000001 | B9: 10400008 | C9: MP10150 | D9: COLORANTE GEL EGG YELLOW (UND= 130 ML) | E9: Master Pack | F9: 7 | G9: g | H9: =F9/20.8 -> 0.33653846
B10: 0702069 | C10: EM10002 | D10: ETIQ.BLANCA 1 1/4 * 3/4 | E10: Etiplas | F10: 1 | G10: ud | H10: =F10/20.8 -> 0.048076923
E13: Cantidad | F13: Unidad
B14: PESO TOTAL OBTENIDO | E14: 16580 | F14: g | G14: Tiempo de Horneo:
B15: TIEMPO TOTAL DE PREPARACION | E15: 2 | F15: Min | G15: Horno:
B16: CANTIDAD DE PORCIONES OBTENIDAS | E16: 1 | F16: Tanda | G16: Temperatura de Horneo:
B17: PESO POR PORCION | E17: =+E14 -> 16580 | F17: g | G17: Otros
B18: MERMA | E18: =SUM(F8:F10)-E14 -> 8 | F18: g
B19: PROCEDIMIENTO DE PREPARACION DE LA RECETA
B20: 1, Mezclar la crema con los colorantes, hatsa homogeneo
B21: 2.- Mantener en refrigeración.
B25: CONTROL DE CAMBIOS
B26: 4: Actualización de codigos.
B27: 5: Actualización de rendimiento
B28: 6: Actualizacion del peso del colorante
B29: 7: Se Elimina la crema supremo, la crema prestige, el preservante, el agua. Se agrega el subproducto crema chantilly Spoon
B30: 8: Ajuste del peso de la crema

Sheet Crema Chantilly blanca 
D1: SERVICIOS DE PASTELERIA S.A. | I1: CÓDIGO: | J1: ESP-RE-DES-036
D2: ESPECIFICACION DE RECETA | I2: REVISIÓN: | J2: 11
D3: Crema Blanca Spoon (20800g) SE00010 | I3: FECHA DE APROBACIÓN: | J3: 45383
D4: Elaborado | E4: Javier Tong, Chef
D5: Aprobado | E5: Esteban Cartin, Gte Manufactura
A6: # Código | B6: # Código | C6: # Codigo Netsuite | D6: Descripción del ingrediente | E6: Marca | F6: Unidad Internacional | H6: Medida alternativa | J6: Costo - Referencia
F7: Cantidad | G7: Unidad medida | H7: Cantidad | I7: Unidad medida | J7: Colones
A8: ICG
A9: 310148 | B9: 310148 | C9: MP10047 | D9: BETTERCREME SUPREMO (UND:4 K) | E9: Richs | F9: 12800 | G9: g
A10: 11400031 | B10: 11400031 | C10: MP10048 | D10: CREMA PRESTIGE GRAND (UND:4 K) | E10: Richs | F10: 3200 | G10: g
A11: 10415 | B11: 10415 | D11: AGUA POTABLE (PLANTA) | E11: AyA | F11: 800 | G11: g
A12: 1212410 | B12: 1212410 | C12: MP10008 | D12: PRESERVANTE 1047S (PAQ=5 KILO) | E12: Aseal | F12: 12 | G12: g
A13: 702069 | B13: 702123 | C13: EM10011 | D13: ETIQUETA BLANCA 2 5/8X1 15/16 (UND) | E13: Etiplas | F13: 1 | G13: ud
E28: Cantidad | F28: Unidad
B29: PESO TOTAL OBTENIDO | E29: =SUM(F9:F12)-E33 -> 16597 | F29: g | G29: Tiempo de Horneo: | I29: 16597
B30: TIEMPO TOTAL DE PREPARACION | E30: 10 | F30: min | G30: Horno:
B31: CANTIDAD DE PORCIONES OBTENIDAS | E31: 1 | F31: Tanda | G31: Temperatura de Horneo: | I31: 0.6
B32: PESO DE CADA PORCIÓN | E32: =E29 -> 16597 | F32: g | G32: Otros
B33: MERMA | E33: 215 | F33: g
B34: PROCEDIMIENTO DE PREPARACION DE LA RECETA
B35: 1.- Abrir los galones de crema y verter dentro de la top cream.
B36: 2.- Disolver el preservante en el agua. Agregar a la top cream.
B37: 3.- Batir por 12 a 15 minutos. Colocar en una tina plastica, tapar.
B38: 4.- Etiquetar con nombre y fecha de vencimiento.
B39: 5.- Mantener en refrigeración.
B40: Control de Cambios
B41: 9, Actuaizacion de codigos
B42: 10, Actuaizacion de procedimiento
B43: 11,Cambio de Pesos

Sheet Emsamble Locales
C1: SERVICIOS DE PASTELERIA S.A. | H1: CÓDIGO:
C2: ESPECIFICACION DE RECETA | H2: REVISIÓN:
C3: Ensamble de Hershey"s Kisses | H3: FECHA DE APROBACIÓN:
C4: Elaborado | D4: Jose Brizuela, chef
C5: Aprobado | D5: Esteban Cartin, Gte Manufactura
A6: AREA QUE PRODUCE: | D6: Decoracion | G6: AREA QUE EMPACA: | I6: Decoracion
A7: # Código | B7: # Codigo Netsuite | C7: Descripción del ingrediente | D7: Marca | E7: Unidad Internacional | G7: Medida alternativa | I7: Costo - Referencia
E8: Cantidad | F8: Unidad medida | G8: Cantidad | H8: Unidad medida | I8: Colones
C9: Emsamble
A10: 907000268 | B10: SE00345 | C10: ROSQUETE CHOCOLATE DAWN 400g | D10: FAS | E10: 335 | F10: g | G10: ud | H10: Partido a la mitad
A11: 910000003 | B11: SE00254 | C11: Leches Pasteurizada Con Agua | D11: FAS | E11: 100 | F11: g | H11: 50 g por tapa
A12: 902000168 | B12: SE00468 | C12: MOUSSE DE CHOCOLATE DE LECHE | D12: FAS | E12: 150 | F12: g | H12: 1 Taza
C13: Rosquete Brownie Redondo de 450 gramos | D13: FAS | E13: 430 | F13: g | H13: 1 unidad
A14: 908000032 | B14: SE00001 | C14: Ganache Chocolate Oscuro | D14: FAS | E14: 90 | F14: g | H14: 1/3 Taza
C15: Semi Sweet Chocolate Chips | D15: Hershey"s | E15: 60 | F15: g | H15: 1/3 taza
C16: Decoracion
A17: 910000018 | B17: SE00069 | C17: Crema Beidge | D17: FAS | E17: 150 | F17: g | I17: Encremado
A18: 11400027 | B18: MP10006 | C18: Crema Bettercream Doble Chocolate | D18: Richt | E18: 20 | F18: g | I18: Paredes
A19: 908000032 | B19: SE00001 | C19: Ganache Chocolate Oscuro | D19: FAS | E19: 20 | F19: g | I19: Para decoracion
C20: Rosquete Brownie Redondo de 450 gramos | D20: FAS | E20: 215 | F20: g | H20: 1/2 media Unidad | I20: por torta
C21: Hershey"s Kisses | D21: Hershey"s | E21: 12 | F21: ud
C22: EMPAQUE
A24: 121603 | B24: EM10009 | C24: QUEQUERA RED BASE/DOMO 10 (CAJA:50) | D24: MAYCA | E24: 1 | F24: ud
A25: 1950692 | B25: EM10008 | C25: ORLA CARTON 10" DORADA UND | D25: Mayca | E25: 1 | F25: Ud
A26: 702069 | B26: EM10002 | C26: Etiq.Blanca 1 1/4 * 3/4 | D26: ETIPLAST | E26: 1 | F26: ud
A27: 0703020 | B27: EM10248 | C27: CINTA ADHESIVA TRANSPARENTE 2*100 | D27: Mayca | E27: 60 | F27: cm
A28: 701096 | B28: EM10124 | C28: ETIQUETA BLANCA R-153 | D28: Cemusa | E28: 1 | F28: ud
A29: 0702123 | B29: EM10011 | C29: ETIQUETA BLANCA 2 5/8X1 15/16 PRE BLANCA | D29: Etiplast | E29: 1 | F29: ud
A30: 60100120 | B30: EM10314 | C30: Etiqueta Edicion Especial | D30: ETIPLAST | E30: 1 | F30: ud
C31: Etiqueta Especial | E31: 1 | F31: ud
D32: Cantidad | E32: Unidad
A33: PESO TOTAL OBTENIDO | D33: 1500 | E33: g | F33: Tiempo de Horneo:
A34: TIEMPO TOTAL DE PREPARACION | D34: 4 | E34: min | F34: Horno:
A35: CANTIDAD DE PORCIONES OBTENIDAS | D35: 1 | E35: ud | F35: Temperatura de Horneo:
A36: PESO DE CADA PORCIÓN | D36: 1500 | E36: g | F36: Otros
A37: MERMA | D37: =SUM(E10:E20)-D33 -> 70 | E37: g
A38: PROCEDIMIENTO DE PREPARACION DE LA RECETA
A39: 1-Partir el Rosquette por la mitad y bañar con la leche ambas tapas ,Colocar la mousse sobre una capa y el Rosquete de Brownie
A40: 2-Sobre el rosquete de Brownie colocar el ganache de chocolate y exparsir uniformemente, luego agregar los Semi Sweet chocolate
A41: 3-Tapar con la otra mitad del rosquette
...

Sheet costo ensamble
E1: Precio Local | F1: Costo MP | G1: Costo EM | H1: Costo MO
E2: =IFERROR(O65,"") -> 5366.5007 | F2: =IFERROR(H56,"") -> 2892.4611 | G2: =IFERROR(H57,"") -> 648.07822 | H2: =IFERROR(H59,"") -> 997.15625
A5: ESTRUCTURA DE COSTOS
F6: Fecha: | H6: =TODAY() -> 46055
A7: UNIDADES | B7: DESCRIPCION MAT.PRIMA | C7: UNIDADES | D7: UND MEDIDA | E7: COSTO UNITARIO | F7: TOTAL COSTO | G7: % PREC. DEFINIDO | H7: CODIGOS
A8: 40 | B8: Semi Sweet Chocolate Chips | C8: =+A8 -> 40 | D8: Gramos | E8: 0.67 | F8: =IFERROR(C8*E8,"") -> 26.8 | G8: =IFERROR(F8/$F$69,"") -> 0.0063591669
A9: 20 | B9: =IFERROR(VLOOKUP(H9,'[1]Consolidado MP Planta'!$A$2:$M$823,3,0),"") -> CREMA BETTERCREAM DOBLE CHOCO (UND:4 K) | C9: =+A9 -> 20 | D9: =IFERROR(VLOOKUP(H9,'[1]Consolidado MP Planta'!$A$2:$M$823,13,0),"") -> Gramos | E9: 2.5 | F9: =IFERROR(C9*E9,"") -> 50 | G9: =IFERROR(F9/$F$69,"") -> 0.011864117 | H9: 11400027
A10: 12 | B10: Hershey"s Kisses | C10: =+A10 -> 12 | D10: und | E10: 31.55 | F10: =IFERROR(E10*C10,"") -> 378.6 | G10: =IFERROR(F10/$F$69,"") -> 0.089835097
B11: =IFERROR(VLOOKUP(H11,'[1]Consolidado MP Planta'!$A$2:$M$823,3,0),"") | C11: =+A11 -> 0 | D11: =IFERROR(VLOOKUP(H11,'[1]Consolidado MP Planta'!$A$2:$M$823,13,0),"") | E11: =IFERROR(VLOOKUP(H11,'[1]Consolidado MP Planta'!$A$2:$M$823,12,0),"") | F11: =IFERROR(C11*E11,"") | G11: =IFERROR(F11/$F$69,"")
B12: =IFERROR(VLOOKUP(H12,'[1]Consolidado MP Planta'!$A$2:$M$823,3,0),"") | C12: =+A12 -> 0 | D12: =IFERROR(VLOOKUP(H12,'[1]Consolidado MP Planta'!$A$2:$M$823,13,0),"") | E12: =IFERROR(VLOOKUP(H12,'[1]Consolidado MP Planta'!$A$2:$M$823,12,0),"") | F12: =IFERROR(C12*E12,"") | G12: =IFERROR(F12/$F$69,"")
B13: =IFERROR(VLOOKUP(H13,'[1]Consolidado MP Planta'!$A$2:$M$823,3,0),"") | C13: =+A13 -> 0 | D13: =IFERROR(VLOOKUP(H13,'[1]Consolidado MP Planta'!$A$2:$M$823,13,0),"") | E13: =IFERROR(VLOOKUP(H13,'[1]Consolidado MP Planta'!$A$2:$M$823,12,0),"") | F13: =IFERROR(C13*E13,"") | G13: =IFERROR(F13/$F$69,"")
B14: =IFERROR(VLOOKUP(H14,'[1]Consolidado MP Planta'!$A$2:$M$823,3,0),"") | C14: =+A14 -> 0 | D14: =IFERROR(VLOOKUP(H14,'[1]Consolidado MP Planta'!$A$2:$M$823,13,0),"") | E14: =IFERROR(VLOOKUP(H14,'[1]Consolidado MP Planta'!$A$2:$M$823,12,0),"") | F14: =IFERROR(C14*E14,"") | G14: =IFERROR(F14/$F$69,"")
B15: =IFERROR(VLOOKUP(H15,'[2]ARTICULOS MP PLANTA'!$A$2:$G$589,2,0),"")
A16: UNIDADES | B16: MATERIA PRIMA SEMIELABORADOS | C16: UNIDADES | D16: UND MEDIDA | E16: COSTO UNITARIO | F16: TOTAL COSTO | G16: % PREC. DEFINIDO | H16: CODIGOS
A17: 1 | B17: ROSQUETE CHOCOLATE DAWN 400g | C17: =+A17 -> 1 | D17: und | E17: 482 | F17: =IFERROR(E17*C17,"") -> 482 | G17: =IFERROR(F17/$F$69,"") -> 0.11437009 | H17: 907000268
A18: 100 | B18: =IFERROR(VLOOKUP(H18,[1]SEMIELABORADOS!$A$2:$M$6000,2,0),"") -> MEZCLA TRES LECHES C/AGUA (KILO) | C18: =+A18 -> 100 | D18: =IFERROR(VLOOKUP(H18,[1]SEMIELABORADOS!$A$2:$M$6000,6,0),"") -> Gramo | E18: 1.15 | F18: =IFERROR(E18*C18,"") -> 115 | G18: =IFERROR(F18/$F$69,"") -> 0.02728747 | H18: 910000003
A19: 150 | B19: MOUSSE DE CHOCOLATE DE LECHE | C19: =+A19 -> 150 | D19: Gramos | E19: 3.38 | F19: =IFERROR(E19*C19,"") -> 507 | G19: =IFERROR(F19/$F$69,"") -> 0.12030215 | H19: 902000168
A20: 1 | B20: Rosquete Brownie Redondo de 400 gramos | C20: =+A20 -> 1 | D20: UND | E20: =+'costo Rosquete'!H53 -> 581.26105 | F20: =IFERROR(E20*C20,"") -> 581.26105 | G20: =IFERROR(F20/$F$69,"") -> 0.13792299
A21: 110 | B21: =IFERROR(VLOOKUP(H21,[1]SEMIELABORADOS!$A$2:$M$6000,2,0),"") -> GANACHE CHOCOLATE OSCURO (KILO) | C21: =+A21 -> 110 | D21: =IFERROR(VLOOKUP(H21,[1]SEMIELABORADOS!$A$2:$M$6000,6,0),"") -> Gramo | E21: 3.78 | F21: =IFERROR(E21*C21,"") -> 415.8 | G21: =IFERROR(F21/$F$69,"") -> 0.098662001 | H21: 908000032
A22: 150 | B22: =IFERROR(VLOOKUP(H22,[1]SEMIELABORADOS!$A$2:$M$6000,2,0),"") -> CREMA BEIDGE (KILO) | C22: =+A22 -> 150 | D22: =IFERROR(VLOOKUP(H22,[1]SEMIELABORADOS!$A$2:$M$6000,6,0),"") -> Gramo | E22: 2.24 | F22: =IFERROR(E22*C22,"") -> 336 | G22: =IFERROR(F22/$F$69,"") -> 0.079726869 | H22: 910000018
A23: 0 | C23: =+A23 -> 0 | D23: und | E23: 0 | F23: =IFERROR(E23*C23,"") -> 0 | G23: =IFERROR(F23/$F$69,"") -> 0
B24: =IFERROR(VLOOKUP(H24,[1]SEMIELABORADOS!$A$2:$M$6000,2,0),"") | C24: =+A24 -> 0 | D24: =IFERROR(VLOOKUP(H24,[1]SEMIELABORADOS!$A$2:$M$6000,6,0),"") | E24: =IFERROR(VLOOKUP(H24,[1]SEMIELABORADOS!$A$2:$H$65536,8,0),"") | F24: =IFERROR(E24*C24,"") | G24: =IFERROR(F24/$F$69,"")
A26: UNIDADES | B26: EMPAQUE | C26: UNIDADES | D26: UND MEDIDA | E26: COSTO UNITARIO | F26: TOTAL COSTO | G26: % PREC. DEFINIDO | H26: CODIGOS
A27: 1 | B27: =IFERROR(VLOOKUP(H27,'[1]Consolidado MP Planta'!$A$2:$M$823,3,0),"") -> QUEQUERA RED BASE/DOMO 10 (CAJA:50) | C27: =+A27 -> 1 | D27: =IFERROR(VLOOKUP(H27,'[1]Consolidado MP Planta'!$A$2:$M$823,13,0),"") -> UND | E27: 367 | F27: =IFERROR(C27*E27,"") -> 367 | G27: =IFERROR(F27/$F$69,"") -> 0.087082622 | H27: 121603
A28: 1 | B28: =IFERROR(VLOOKUP(H28,'[1]Consolidado MP Planta'!$A$2:$M$823,3,0),"") -> ORLA CARTON 10" DORADA (UND) | C28: =+A28 -> 1 | D28: =IFERROR(VLOOKUP(H28,'[1]Consolidado MP Planta'!$A$2:$M$823,13,0),"") -> Und | E28: 137 | F28: =IFERROR(C28*E28,"") -> 137 | G28: =IFERROR(F28/$F$69,"") -> 0.032507682 | H28: 1950692
A29: 1 | B29: =IFERROR(VLOOKUP(H29,'[1]Consolidado MP Planta'!$A$2:$M$823,3,0),"") -> ETIQ.BLANCA 1 1/4 * 3/4 (UND) | C29: =+A29 -> 1 | D29: =IFERROR(VLOOKUP(H29,'[1]Consolidado MP Planta'!$A$2:$M$823,13,0),"") -> Und | E29: =IFERROR(VLOOKUP(H29,'[1]Consolidado MP Planta'!$A$2:$M$823,12,0),"") -> 0.58 | F29: =IFERROR(C29*E29,"") -> 0.58 | G29: =IFERROR(F29/$F$69,"") -> 0.00013762376 | H29: 0702069
A30: 60 | B30: =IFERROR(VLOOKUP(H30,'[1]Consolidado MP Planta'!$A$2:$M$823,3,0),"") -> CINTA ADHESIVA TRANSPARENT 2*100 M (UND) | C30: =+A30 -> 60 | D30: =IFERROR(VLOOKUP(H30,'[1]Consolidado MP Planta'!$A$2:$M$823,13,0),"") -> Cm | E30: =IFERROR(VLOOKUP(H30,'[1]Consolidado MP Planta'!$A$2:$M$823,12,0),"") -> 0.175 | F30: =IFERROR(C30*E30,"") -> 10.5 | G30: =IFERROR(F30/$F$69,"") -> 0.0024914647 | H30: 703020
A31: 1 | B31: =IFERROR(VLOOKUP(H31,'[1]Consolidado MP Planta'!$A$2:$M$823,3,0),"") -> ETIQUETA BLANCA R-153 (UND) | C31: =+A31 -> 1 | D31: =IFERROR(VLOOKUP(H31,'[1]Consolidado MP Planta'!$A$2:$M$823,13,0),"") -> Und | E31: =IFERROR(VLOOKUP(H31,'[1]Consolidado MP Planta'!$A$2:$M$823,12,0),"") -> 0.39 | F31: =IFERROR(C31*E31,"") -> 0.39 | G31: =IFERROR(F31/$F$69,"") -> 9.2540116e-05 | H31: 701096
A32: 1 | B32: =IFERROR(VLOOKUP(H32,'[1]Consolidado MP Planta'!$A$2:$M$823,3,0),"") -> ETIQUETA BLANCA 2 5/8X1 15/16 (UND) | C32: =+A32 -> 1 | D32: =IFERROR(VLOOKUP(H32,'[1]Consolidado MP Planta'!$A$2:$M$823,13,0),"") -> Und | E32: =IFERROR(VLOOKUP(H32,'[1]Consolidado MP Planta'!$A$2:$M$823,12,0),"") -> 2.128 | F32: =IFERROR(C32*E32,"") -> 2.128 | G32: =IFERROR(F32/$F$69,"") -> 0.00050493684 | H32: 0702123
A33: 1 | B33: Etiqueta Especial | C33: =+A33 -> 1 | D33: UND | E33: 115 | F33: =IFERROR(C33*E33,"") -> 115 | G33: =IFERROR(F33/$F$69,"") -> 0.02728747
A34: 1 | B34: =IFERROR(VLOOKUP(H34,'[1]Consolidado MP Planta'!$A$2:$M$823,3,0),"") | C34: =+A34 -> 1 | D34: =IFERROR(VLOOKUP(H34,'[1]Consolidado MP Planta'!$A$2:$M$823,13,0),"") | E34: =IFERROR(VLOOKUP(H34,'[1]Consolidado MP Planta'!$A$2:$M$823,12,0),"") | F34: =IFERROR(C34*E34,"") | G34: =IFERROR(F34/$F$69,"")
B35: =IFERROR(VLOOKUP(H35,'[1]Consolidado MP Planta'!$A$2:$M$823,3,0),"") | C35: =+A35 -> 0 | D35: =IFERROR(VLOOKUP(H35,'[1]Consolidado MP Planta'!$A$2:$M$823,13,0),"") | E35: =IFERROR(VLOOKUP(H35,'[1]Consolidado MP Planta'!$A$2:$M$823,12,0),"") | F35: =IFERROR(C35*E35,"") | G35: =IFERROR(F35/$F$69,"")
A37: UNIDADES | B37: EMPAQUE SEMIELABORADOS | C37: UNIDADES | D37: UND MEDIDA | E37: COSTO UNITARIO | F37: TOTAL COSTO | G37: % PREC. DEFINIDO | H37: CODIGOS
A38: =+A17 -> 1 | B38: ROSQUETE CHOCOLATE DAWN 400g | C38: =+A38 -> 1 | D38: UND | E38: 5.29 | F38: =IFERROR(E38*C38,"") -> 5.29 | G38: =IFERROR(F38/$F$69,"") -> 0.0012552236 | H38: 907000268
A39: =+A18 -> 100 | B39: =IFERROR(VLOOKUP(H39,[1]SEMIELABORADOS!$A$2:$M$6000,2,0),"") -> MEZCLA TRES LECHES C/AGUA (KILO) | C39: =+A39 -> 100 | D39: =IFERROR(VLOOKUP(H39,[1]SEMIELABORADOS!$A$2:$M$6000,6,0),"") -> Gramo | E39: =IFERROR(VLOOKUP(H39,[1]SEMIELABORADOS!$A$2:$M$65536,10,0),"") -> 0.0048511202 | F39: =IFERROR(E39*C39,"") -> 0.48511202 | G39: =IFERROR(F39/$F$69,"") -> 0.00011510852 | H39: 910000003
A40: =+A19 -> 150 | B40: MOUSSE DE CHOCOLATE DE LECHE | C40: =+A40 -> 150 | D40: Gramo | E40: 0 | F40: =IFERROR(E40*C40,"") -> 0 | G40: =IFERROR(F40/$F$69,"") -> 0 | H40: 902000168
A41: =+A20 -> 1 | B41: Rosquete Brownie Redondo de 400 gramos | C41: =+A41 -> 1 | D41: UND | E41: =+'costo Rosquete'!H54 -> 9.6951779 | F41: =IFERROR(E41*C41,"") -> 9.6951779 | G41: =IFERROR(F41/$F$69,"") -> 0.0023004946
A42: =+A21 -> 110 | B42: =IFERROR(VLOOKUP(H42,[1]SEMIELABORADOS!$A$2:$M$6000,2,0),"") -> GANACHE CHOCOLATE OSCURO (KILO) | C42: =+A42 -> 110 | D42: =IFERROR(VLOOKUP(H42,[1]SEMIELABORADOS!$A$2:$M$6000,6,0),"") -> Gramo | E42: =IFERROR(VLOOKUP(H42,[1]SEMIELABORADOS!$A$2:$M$65536,10,0),"") -> 1.4250614e-05 | F42: =IFERROR(E42*C42,"") -> 0.0015675676 | G42: =IFERROR(F42/$F$69,"") -> 3.7195611e-07 | H42: 908000032
A43: =+A22 -> 150 | B43: =IFERROR(VLOOKUP(H43,[1]SEMIELABORADOS!$A$2:$M$6000,2,0),"") -> CREMA BEIDGE (KILO) | C43: =+A43 -> 150 | D43: =IFERROR(VLOOKUP(H43,[1]SEMIELABORADOS!$A$2:$M$6000,6,0),"") -> Gramo | E43: =IFERROR(VLOOKUP(H43,[1]SEMIELABORADOS!$A$2:$M$65536,10,0),"") -> 5.5769231e-05 | F43: =IFERROR(E43*C43,"") -> 0.0083653846 | G43: =IFERROR(F43/$F$69,"") -> 1.9849581e-06 | H43: 910000018
A44: =+A23 -> 0 | B44: Hershey"s Kisses | C44: =+A44 -> 0 | D44: UND | E44: =+'Costo pelado de chocolate'!E76 -> 1.8617143 | F44: =IFERROR(E44*C44,"") -> 0 | G44: =IFERROR(F44/$F$69,"") -> 0
...

Sheet Pelado de chocolate
C1: SERVICIOS DE PASTELERIA S.A. | H1: CÓDIGO: | I1: ESP-RE-DES-056
C2: ESPECIFICACION DE RECETA | H2: REVISIÓN: | I2: 2
C3: SE00669 Pelado y Empaque de Chocolate Kisses Hersheys | H3: FECHA DE APROBACIÓN: | I3: 45663
C4: Elaborado | D4: Jose Brizuela, chef
C5: Aprobado | D5: Esteban Cartin, Gte Manufactura
A6: AREA QUE PRODUCE: | D6: Decoracion | G6: AREA QUE EMPACA: | I6: Decoracion
A7: # Código | B7: # Codigo Netsuite | C7: Descripción del ingrediente | D7: Marca | E7: Unidad Internacional | G7: Medida alternativa | I7: Costo - Referencia
E8: Cantidad | F8: Unidad medida | G8: Cantidad | H8: Unidad medida | I8: Colones
C9: Pelado de Chocolate Kisses Hersheys
B11: MP10744 | C11: Chocolate Kisses Hersheys | D11: Hersheys | E11: 137 | F11: g | G11: 28 und
K12: 1577,7*50 und
C13: Empaque | K13: =1577.7/50 -> 31.554
A14: 1950928 | B14: AS00028 | C14: BOLSA TRANSPARENTE 56X96X1.80 (KILO) | D14: Plasticos P | E14: 1 | F14: ud
A15: 0702123 | B15: EM10011 | C15: ETIQUETA BLANCA 2 5/8X1 15/16 (UND) | D15: cemusa | E15: 1 | F15: ud
D17: Cantidad | E17: Unidad
A18: PESO TOTAL OBTENIDO | D18: 128 | E18: g | F18: Tiempo de Horneo:
A19: TIEMPO TOTAL DE PREPARACION | D19: 5 | E19: min | F19: Horno:
A20: CANTIDAD DE PORCIONES OBTENIDAS | D20: 1 | E20: ud | F20: Temperatura de Horneo:
A21: PESO DE CADA PORCIÓN | D21: 128 | E21: g | F21: Otros
A22: MERMA | D22: =SUM(E11)-D18 -> 9 | E22: g
A23: PROCEDIMIENTO DE PREPARACION DE LA RECETA
A24: 1-Pelar los Kisses y Separar en una bandeja.
A25: 2- Tapar, Etiquetar con fecha de vencimiento y etiqueta con nombre.
A26: 3-Llevar al Frio hasta Utilizar
A32: CONTROL DE CAMBIOS
A33: 2, Se actualiza tiempo de preparación

Sheet Costo pelado de chocolate
E1: Precio Local | F1: Costo MP | G1: Costo EM | H1: Costo MO
E2: =IFERROR(O62,"") -> 1358.528 | F2: =IFERROR(H53,"") -> 883.4 | G2: =IFERROR(H54,"") -> 52.128 | H2: =IFERROR(H56,"") -> 231
A5: ESTRUCTURA DE COSTOS
F6: Fecha: | H6: =TODAY() -> 46055
A7: UNIDADES | B7: DESCRIPCION MAT.PRIMA | C7: UNIDADES | D7: UND MEDIDA | E7: COSTO UNITARIO | F7: TOTAL COSTO | G7: % PREC. DEFINIDO | H7: CODIGOS
A8: 28 | B8: Chocolate Kisses Hersheys | C8: =+A8 -> 28 | D8: UND | E8: 31.55 | F8: =IFERROR(C8*E8,"") -> 883.4 | G8: =IFERROR(F8/$F$66,"") -> 0.74599137
B9: =IFERROR(VLOOKUP(H9,'[1]Consolidado MP Planta'!$A$2:$M$823,3,0),"") | C9: =+A9 -> 0 | D9: =IFERROR(VLOOKUP(H9,'[1]Consolidado MP Planta'!$A$2:$M$823,13,0),"") | E9: =IFERROR(VLOOKUP(H9,'[1]Consolidado MP Planta'!$A$2:$M$823,12,0),"") | F9: =IFERROR(C9*E9,"") | G9: =IFERROR(F9/$F$66,"")
B10: =IFERROR(VLOOKUP(H10,'[1]Consolidado MP Planta'!$A$2:$M$823,3,0),"") | C10: =+A10 -> 0 | D10: =IFERROR(VLOOKUP(H10,'[1]Consolidado MP Planta'!$A$2:$M$823,13,0),"") | E10: =IFERROR(VLOOKUP(H10,'[1]Consolidado MP Planta'!$A$2:$M$823,12,0),"") | F10: =IFERROR(C10*E10,"") | G10: =IFERROR(F10/$F$66,"")
B11: =IFERROR(VLOOKUP(H11,'[1]Consolidado MP Planta'!$A$2:$M$823,3,0),"") | C11: =+A11 -> 0 | D11: =IFERROR(VLOOKUP(H11,'[1]Consolidado MP Planta'!$A$2:$M$823,13,0),"") | E11: =IFERROR(VLOOKUP(H11,'[1]Consolidado MP Planta'!$A$2:$M$823,12,0),"") | F11: =IFERROR(C11*E11,"") | G11: =IFERROR(F11/$F$66,"")
B12: =IFERROR(VLOOKUP(H12,'[1]Consolidado MP Planta'!$A$2:$M$823,3,0),"") | C12: =+A12 -> 0 | D12: =IFERROR(VLOOKUP(H12,'[1]Consolidado MP Planta'!$A$2:$M$823,13,0),"") | E12: =IFERROR(VLOOKUP(H12,'[1]Consolidado MP Planta'!$A$2:$M$823,12,0),"") | F12: =IFERROR(C12*E12,"") | G12: =IFERROR(F12/$F$66,"")
B13: =IFERROR(VLOOKUP(H13,'[1]Consolidado MP Planta'!$A$2:$M$823,3,0),"") | C13: =+A13 -> 0 | D13: =IFERROR(VLOOKUP(H13,'[1]Consolidado MP Planta'!$A$2:$M$823,13,0),"") | E13: =IFERROR(VLOOKUP(H13,'[1]Consolidado MP Planta'!$A$2:$M$823,12,0),"") | F13: =IFERROR(C13*E13,"") | G13: =IFERROR(F13/$F$66,"")
B14: =IFERROR(VLOOKUP(H14,'[1]Consolidado MP Planta'!$A$2:$M$823,3,0),"") | C14: =+A14 -> 0 | D14: =IFERROR(VLOOKUP(H14,'[1]Consolidado MP Planta'!$A$2:$M$823,13,0),"") | E14: =IFERROR(VLOOKUP(H14,'[1]Consolidado MP Planta'!$A$2:$M$823,12,0),"") | F14: =IFERROR(C14*E14,"") | G14: =IFERROR(F14/$F$66,"")
B15: =IFERROR(VLOOKUP(H15,'[2]ARTICULOS MP PLANTA'!$A$2:$G$589,2,0),"")
A16: UNIDADES | B16: MATERIA PRIMA SEMIELABORADOS | C16: UNIDADES | D16: UND MEDIDA | E16: COSTO UNITARIO | F16: TOTAL COSTO | G16: % PREC. DEFINIDO | H16: CODIGOS
B17: =IFERROR(VLOOKUP(H17,[1]SEMIELABORADOS!$A$2:$M$6000,2,0),"") | C17: =+A17 -> 0 | D17: =IFERROR(VLOOKUP(H17,[1]SEMIELABORADOS!$A$2:$M$6000,6,0),"") | E17: =IFERROR(VLOOKUP(H17,[1]SEMIELABORADOS!$A$2:$H$65536,8,0),"") | F17: =IFERROR(E17*C17,"") | G17: =IFERROR(F17/$F$66,"")
B18: =IFERROR(VLOOKUP(H18,[1]SEMIELABORADOS!$A$2:$M$6000,2,0),"") | C18: =+A18 -> 0 | D18: =IFERROR(VLOOKUP(H18,[1]SEMIELABORADOS!$A$2:$M$6000,6,0),"") | E18: =IFERROR(VLOOKUP(H18,[1]SEMIELABORADOS!$A$2:$H$65536,8,0),"") | F18: =IFERROR(E18*C18,"") | G18: =IFERROR(F18/$F$66,"")
B19: =IFERROR(VLOOKUP(H19,[1]SEMIELABORADOS!$A$2:$M$6000,2,0),"") | C19: =+A19 -> 0 | D19: =IFERROR(VLOOKUP(H19,[1]SEMIELABORADOS!$A$2:$M$6000,6,0),"") | E19: =IFERROR(VLOOKUP(H19,[1]SEMIELABORADOS!$A$2:$H$65536,8,0),"") | F19: =IFERROR(E19*C19,"") | G19: =IFERROR(F19/$F$66,"")
B20: =IFERROR(VLOOKUP(H20,[1]SEMIELABORADOS!$A$2:$M$6000,2,0),"") | C20: =+A20 -> 0 | D20: =IFERROR(VLOOKUP(H20,[1]SEMIELABORADOS!$A$2:$M$6000,6,0),"") | E20: =IFERROR(VLOOKUP(H20,[1]SEMIELABORADOS!$A$2:$H$65536,8,0),"") | F20: =IFERROR(E20*C20,"") | G20: =IFERROR(F20/$F$66,"")
B21: =IFERROR(VLOOKUP(H21,[1]SEMIELABORADOS!$A$2:$M$6000,2,0),"") | C21: =+A21 -> 0 | D21: =IFERROR(VLOOKUP(H21,[1]SEMIELABORADOS!$A$2:$M$6000,6,0),"") | E21: =IFERROR(VLOOKUP(H21,[1]SEMIELABORADOS!$A$2:$H$65536,8,0),"") | F21: =IFERROR(E21*C21,"") | G21: =IFERROR(F21/$F$66,"")
B22: =IFERROR(VLOOKUP(H22,[1]SEMIELABORADOS!$A$2:$M$6000,2,0),"") | C22: =+A22 -> 0 | D22: =IFERROR(VLOOKUP(H22,[1]SEMIELABORADOS!$A$2:$M$6000,6,0),"") | E22: =IFERROR(VLOOKUP(H22,[1]SEMIELABORADOS!$A$2:$H$65536,8,0),"") | F22: =IFERROR(E22*C22,"") | G22: =IFERROR(F22/$F$66,"")
B23: =IFERROR(VLOOKUP(H23,[1]SEMIELABORADOS!$A$2:$M$6000,2,0),"") | C23: =+A23 -> 0 | D23: =IFERROR(VLOOKUP(H23,[1]SEMIELABORADOS!$A$2:$M$6000,6,0),"") | E23: =IFERROR(VLOOKUP(H23,[1]SEMIELABORADOS!$A$2:$H$65536,8,0),"") | F23: =IFERROR(E23*C23,"") | G23: =IFERROR(F23/$F$66,"")
B24: =IFERROR(VLOOKUP(H24,[1]SEMIELABORADOS!$A$2:$M$6000,2,0),"") | C24: =+A24 -> 0 | D24: =IFERROR(VLOOKUP(H24,[1]SEMIELABORADOS!$A$2:$M$6000,6,0),"") | E24: =IFERROR(VLOOKUP(H24,[1]SEMIELABORADOS!$A$2:$H$65536,8,0),"") | F24: =IFERROR(E24*C24,"") | G24: =IFERROR(F24/$F$66,"")
A26: UNIDADES | B26: EMPAQUE | C26: UNIDADES | D26: UND MEDIDA | E26: COSTO UNITARIO | F26: TOTAL COSTO | G26: % PREC. DEFINIDO | H26: CODIGOS
A27: 1 | B27: =IFERROR(VLOOKUP(H27,'[1]Consolidado MP Planta'!$A$2:$M$823,3,0),"") -> BOLSA TRANSPARENTE 56X96X1.80 KILO | C27: =+A27 -> 1 | D27: =IFERROR(VLOOKUP(H27,'[1]Consolidado MP Planta'!$A$2:$M$823,13,0),"") -> Und | E27: =IFERROR(VLOOKUP(H27,'[1]Consolidado MP Planta'!$A$2:$M$823,12,0),"") -> 50 | F27: =IFERROR(C27*E27,"") -> 50 | G27: =IFERROR(F27/$F$66,"") -> 0.04222274 | H27: 1950928
A28: 1 | B28: =IFERROR(VLOOKUP(H28,'[1]Consolidado MP Planta'!$A$2:$M$823,3,0),"") -> ETIQUETA BLANCA 2 5/8X1 15/16 (UND) | C28: =+A28 -> 1 | D28: =IFERROR(VLOOKUP(H28,'[1]Consolidado MP Planta'!$A$2:$M$823,13,0),"") -> Und | E28: =IFERROR(VLOOKUP(H28,'[1]Consolidado MP Planta'!$A$2:$M$823,12,0),"") -> 2.128 | F28: =IFERROR(C28*E28,"") -> 2.128 | G28: =IFERROR(F28/$F$66,"") -> 0.0017969998 | H28: 0702123
B29: =IFERROR(VLOOKUP(H29,'[1]Consolidado MP Planta'!$A$2:$M$823,3,0),"") | C29: =+A29 -> 0 | D29: =IFERROR(VLOOKUP(H29,'[1]Consolidado MP Planta'!$A$2:$M$823,13,0),"") | E29: =IFERROR(VLOOKUP(H29,'[1]Consolidado MP Planta'!$A$2:$M$823,12,0),"") | F29: =IFERROR(C29*E29,"") | G29: =IFERROR(F29/$F$66,"")
B30: =IFERROR(VLOOKUP(H30,'[1]Consolidado MP Planta'!$A$2:$M$823,3,0),"") | C30: =+A30 -> 0 | D30: =IFERROR(VLOOKUP(H30,'[1]Consolidado MP Planta'!$A$2:$M$823,13,0),"") | E30: =IFERROR(VLOOKUP(H30,'[1]Consolidado MP Planta'!$A$2:$M$823,12,0),"") | F30: =IFERROR(C30*E30,"") | G30: =IFERROR(F30/$F$66,"")
B31: =IFERROR(VLOOKUP(H31,'[1]Consolidado MP Planta'!$A$2:$M$823,3,0),"") | C31: =+A31 -> 0 | D31: =IFERROR(VLOOKUP(H31,'[1]Consolidado MP Planta'!$A$2:$M$823,13,0),"") | E31: =IFERROR(VLOOKUP(H31,'[1]Consolidado MP Planta'!$A$2:$M$823,12,0),"") | F31: =IFERROR(C31*E31,"") | G31: =IFERROR(F31/$F$66,"")
B32: =IFERROR(VLOOKUP(H32,'[1]Consolidado MP Planta'!$A$2:$M$823,3,0),"") | C32: =+A32 -> 0 | D32: =IFERROR(VLOOKUP(H32,'[1]Consolidado MP Planta'!$A$2:$M$823,13,0),"") | E32: =IFERROR(VLOOKUP(H32,'[1]Consolidado MP Planta'!$A$2:$M$823,12,0),"") | F32: =IFERROR(C32*E32,"") | G32: =IFERROR(F32/$F$66,"")
A34: UNIDADES | B34: EMPAQUE SEMIELABORADOS | C34: UNIDADES | D34: UND MEDIDA | E34: COSTO UNITARIO | F34: TOTAL COSTO | G34: % PREC. DEFINIDO | H34: CODIGOS
A35: =+A17 -> 0 | B35: =IFERROR(VLOOKUP(H35,[1]SEMIELABORADOS!$A$2:$M$6000,2,0),"") | C35: =+A35 -> 0 | D35: =IFERROR(VLOOKUP(H35,[1]SEMIELABORADOS!$A$2:$M$6000,6,0),"") | E35: =IFERROR(VLOOKUP(H35,[1]SEMIELABORADOS!$A$2:$M$65536,10,0),"") | F35: =IFERROR(E35*C35,"") | G35: =IFERROR(F35/$F$66,"")
A36: =+A18 -> 0 | B36: =IFERROR(VLOOKUP(H36,[1]SEMIELABORADOS!$A$2:$M$6000,2,0),"") | C36: =+A36 -> 0 | D36: =IFERROR(VLOOKUP(H36,[1]SEMIELABORADOS!$A$2:$M$6000,6,0),"") | E36: =IFERROR(VLOOKUP(H36,[1]SEMIELABORADOS!$A$2:$M$65536,10,0),"") | F36: =IFERROR(E36*C36,"") | G36: =IFERROR(F36/$F$66,"")
A37: =+A19 -> 0 | B37: =IFERROR(VLOOKUP(H37,[1]SEMIELABORADOS!$A$2:$M$6000,2,0),"") | C37: =+A37 -> 0 | D37: =IFERROR(VLOOKUP(H37,[1]SEMIELABORADOS!$A$2:$M$6000,6,0),"") | E37: =IFERROR(VLOOKUP(H37,[1]SEMIELABORADOS!$A$2:$M$65536,10,0),"") | F37: =IFERROR(E37*C37,"") | G37: =IFERROR(F37/$F$66,"")
A38: =+A20 -> 0 | B38: =IFERROR(VLOOKUP(H38,[1]SEMIELABORADOS!$A$2:$M$6000,2,0),"") | C38: =+A38 -> 0 | D38: =IFERROR(VLOOKUP(H38,[1]SEMIELABORADOS!$A$2:$M$6000,6,0),"") | E38: =IFERROR(VLOOKUP(H38,[1]SEMIELABORADOS!$A$2:$M$65536,10,0),"") | F38: =IFERROR(E38*C38,"") | G38: =IFERROR(F38/$F$66,"")
A39: =+A21 -> 0 | B39: =IFERROR(VLOOKUP(H39,[1]SEMIELABORADOS!$A$2:$M$6000,2,0),"") | C39: =+A39 -> 0 | D39: =IFERROR(VLOOKUP(H39,[1]SEMIELABORADOS!$A$2:$M$6000,6,0),"") | E39: =IFERROR(VLOOKUP(H39,[1]SEMIELABORADOS!$A$2:$M$65536,10,0),"") | F39: =IFERROR(E39*C39,"") | G39: =IFERROR(F39/$F$66,"")
A40: =+A22 -> 0 | B40: =IFERROR(VLOOKUP(H40,[1]SEMIELABORADOS!$A$2:$M$6000,2,0),"") | C40: =+A40 -> 0 | D40: =IFERROR(VLOOKUP(H40,[1]SEMIELABORADOS!$A$2:$M$6000,6,0),"") | E40: =IFERROR(VLOOKUP(H40,[1]SEMIELABORADOS!$A$2:$M$65536,10,0),"") | F40: =IFERROR(E40*C40,"") | G40: =IFERROR(F40/$F$66,"")
A41: =+A23 -> 0 | B41: =IFERROR(VLOOKUP(H41,[1]SEMIELABORADOS!$A$2:$M$6000,2,0),"") | C41: =+A41 -> 0 | D41: =IFERROR(VLOOKUP(H41,[1]SEMIELABORADOS!$A$2:$M$6000,6,0),"") | E41: =IFERROR(VLOOKUP(H41,[1]SEMIELABORADOS!$A$2:$M$65536,10,0),"") | F41: =IFERROR(E41*C41,"") | G41: =IFERROR(F41/$F$66,"")
A43: UNIDADES | B43: MODI | C43: UNIDADES | D43: UND MEDIDA | E43: COSTO UNITARIO | F43: TOTAL COSTO | G43: % PREC. DEFINIDO | H43: CODIGOS
A44: =+A35 -> 0 | B44: =IFERROR(VLOOKUP(H44,[1]SEMIELABORADOS!$A$2:$M$6000,2,0),"") | C44: =+A44 -> 0 | D44: =IFERROR(VLOOKUP(H44,[1]SEMIELABORADOS!$A$2:$M$6000,6,0),"") | E44: =IFERROR(VLOOKUP(H44,[1]SEMIELABORADOS!$A$2:$M$65536,12,0),"") | F44: =IFERROR(E44*C44,"") | G44: =IFERROR(F44/$F$66,"")
A45: =+A36 -> 0 | B45: =IFERROR(VLOOKUP(H45,[1]SEMIELABORADOS!$A$2:$M$6000,2,0),"") | C45: =+A45 -> 0 | D45: =IFERROR(VLOOKUP(H45,[1]SEMIELABORADOS!$A$2:$M$6000,6,0),"") | E45: =IFERROR(VLOOKUP(H45,[1]SEMIELABORADOS!$A$2:$M$65536,12,0),"") | F45: =IFERROR(E45*C45,"") | G45: =IFERROR(F45/$F$66,"")
...

Sheet Rosquete Brownie 2
C1: SERVICIOS DE PASTELERIA S.A. | H1: CÓDIGO:
C2: ESPECIFICACION DE RECETA | H2: REVISIÓN:
C3: Rosquete Brownie Redondo de 450 gramos | H3: FECHA DE APROBACIÓN:
C4: Elaborado | D4: Javier Tong, chef
C5: Aprobado | D5: Esteban Cartin, Gte Manufactura
A6: AREA QUE PRODUCE: | D6: Batidos | G6: AREA QUE EMPACA: | I6: Batidos
A7: # Código | B7: # Código Netsuite | C7: Descripción del ingrediente | D7: Marca | E7: Unidad Internacional | G7: Medida alternativa | I7: Costo - Referencia
E8: Cantidad | F8: Unidad medida | G8: Cantidad | H8: Unidad medida | I8: Colones
C9: ENSAMBLE
A10: 902000014 | B10: SE00169 | C10: Batido Brownie Casero | D10: FAS | E10: 8000 | F10: g
A11: 95720 | C11: MEZCLA ENGRASE MOLDES (29800g) | E11: 300 | F11: g
C13: EMPAQUE
A14: 1950928 | B14: AS00028 | C14: BOLSA TRANSPARENTE 56X96X1.80 (KILO) | D14: Plasticos P | E14: 1.5 | F14: ud
A15: 0702123 | B15: EM10011 | C15: ETIQUETA BLANCA 2 5/8X1 15/16 (UND) | D15: cemusa | E15: 1.5 | F15: ud
A16: 906036 | B16: EM10018 | C16: Papel Mantequilla | E16: 2 | F16: ud
D20: Cantidad | E20: Unidad
A21: PESO TOTAL OBTENIDO | D21: 7650 | E21: g | F21: Tiempo de Horneo:
A22: TIEMPO TOTAL DE PREPARACION | D22: 10 | E22: min | F22: Horno:
A23: CANTIDAD DE PORCIONES OBTENIDAS | D23: 17 | E23: ud | F23: Temperatura de Horneo:
A24: PESO DE CADA PORCIÓN | D24: 450 | E24: g | F24: Otros
A25: MERMA | D25: 650 | E25: g
A26: PROCEDIMIENTO DE PREPARACION DE LA RECETA
A27: 1, Dosificar 450g de batidoen molde engrasado y con papel mantequilla y hornear por 30 min.
A28: 3.- Enfriar, desmoldar.Tapar, Etiquetar con fecha de vencimiento y etiqueta con nombre
A29: Control de cambios

Sheet Batido Brownie Casero
D1: SERVICIOS DE PASTELERIA S.A. | I1: CÓDIGO: | J1: ESP-RE-BAS-036
D2: ESPECIFICACION DE RECETA | I2: REVISIÓN: | J2: 06
D3: Batido De Brownie Casero 8000g 902000014(SE00169) | I3: FECHA DE APROBACIÓN: | J3: 44089
D4: Elaborado | E4: Javier Tong, chef
D5: Aprobado | E5: Jeffry Rodriguez. Gte de Manufactura
B6: # Código | C6: # Codigo Netsuite | D6: Descripción del ingrediente | E6: Marca | F6: Unidad Internacional | H6: Medida alternativa | J6: Costo - Referencia
F7: Cantidad | G7: Unidad medida | H7: Cantidad | I7: Unidad medida | J7: Colones
B9: 95361 | C9: SE00170 | D9: PREMEZCLA PARA BROWNIE CASERO | E9: SPOON | F9: 4763 | G9: g
A10: 111000001 | B10: 10100289 | C10: MP10040 | D10: MARGARINA MULTIUSO (CAJA: 25 k) | E10: NUMAR | F10: 1725 | G10: g
B11: 118000004 | C11: MP10385 | D11: VAINILLA OSCURA (UND: 3.78 L) | E11: VAINOL | F11: 22 | G11: g
A12: 113000004 | B12: 1210482 | C12: MP10005 | D12: HUEVO LIQUIDO REFRIG (UND:13.6 K) | E12: INNOVO | F12: 1650 | G12: g
D13: Empaque
B14: 0702123 | C14: EM10011 | D14: ETIQUETA BLANCA 2 5/8X1 15/16 (UND) | E14: cemusa | F14: 1 | G14: ud
B15: 1950928 | C15: AS00028 | D15: BOLSA TRANSPARENTE 56X96X1.80 (KILO) | E15: Plasticos P | F15: 1 | G15: ud
B18: PESO TOTAL OBTENIDO | E18: 8000 | F18: g | G18: Tiempo de Horneo | I18: 40 minutos
B19: TIEMPO TOTAL DE PREPARACION | E19: 5 | F19: min | G19: Horno: | I19: argental
B20: CANTIDAD DE PORCIONES OBTENIDAS | E20: 4 | F20: Moldes | G20: Temperatura de Horneo
B21: PESO DE CADA PORCIÓN | E21: =+E18/E20 -> 2000 | F21: g | G21: 24 unid por plancha
B22: MERMA | E22: 80 | F22: g
B24: 1- DERRETIR LA MARGARINA.
B25: 2- COLOCAR LA MARGARINA DERRETIDA EN EL BATIDOR, EN VELOC 1, AGREGAR LA COCOA, EL AZUCAR, NADA MÁS A MEZCLAR
B26: 3- ADICIONAR LOS HUEVOS A UNIR, AGREGAR HARINA Y VAINILLA, RAPIDAMENTE OJO NO DISOLVER EL AZÚCAR PARA QUE QUEDE CHICLOSO
B27: 4- PESAR ACORDE A LO DESEADO
B30: Control de Cambios
B31: 5, Actualizacion de Codigos
B32: 6, Actualizacion de Codigos (vainilla)

Sheet Premezcla Brownie Casero
B1: SERVICIOS DE PASTELERIA S.A. | G1: CÓDIGO: | H1: ESP-RE-PRES-075
B2: ESPECIFICACION DE RECETA | G2: REVISIÓN:
B3: SE00170 Pre mezcla BROWNIES CASERO | G3: FECHA DE APROBACIÓN:
B4: Elaborado | C4: Maria Jose Rodriguez, Chef
B5: Aprobado | C5: Jorge, Montero. Gte de Manufactura
A6: # Código | B6: Descripción del ingrediente | C6: Marca | D6: Unidad Internacional | F6: Medida alternativa | H6: Costo - Referencia
D7: Cantidad | E7: Unidad medida | F7: Cantidad | G7: Unidad medida | H7: Colones
A9: 1730482 | B9: HARINA NACARINA ( 2.5 kg ) 145g 1 tz | C9: Nacarina | D9: 825 | E9: g
A10: 510301 | B10: AZUCAR BLANCO (INDUSTRIAL) | C10: Maria | D10: 3300 | E10: g
A11: 512255 | B11: COCOA DUTCH PROCESS 1 tz 110g | C11: CR Cocoa | D11: 638 | E11: g
B12: Empaque
A13: 1950702 | B13: BOLSA 12x18 TRANSP (KILO) | C13: Plasticos P | D13: 3 | E13: Undidades
A14: 0702007 | B14: ETIQ.FECHA VENCIMIENTO BLANCO | C14: Etiplast | D14: 1 | E14: und
A15: 1950708 | B15: BOLSA 17x25 TRANSP (KILO) | C15: Plasticos P | D15: 1 | E15: und
C19: Cantidad | D19: Unidad
A20: PESO TOTAL OBTENIDO | C20: 4763 | D20: g
A21: TIEMPO TOTAL DE PREPARACION | C21: 0.10416667 | D21: Minutos
A22: CANTIDAD DE PORCIONES OBTENIDAS | C22: 1 | D22: tanda
A23: PESO CADA PORCION | C23: =+C20 -> 4763 | D23: g | E23: brownies
A24: MERMA | C24: =SUM(D9:D11)-C20 -> 0 | D24: g
A25: PROCEDIMIENTO DE PREPARACION DE LA RECETA
A26: 1- Colocar los ingredientes por separados
A27: 2- Colocar las bolsas dentro de una más grande y etiquetar y fechar

Sheet Rosquete
C1: SERVICIOS DE PASTELERIA S.A. | H1: CÓDIGO:
C2: ESPECIFICACION DE RECETA | H2: REVISIÓN:
C3: Rosquete Brownie Redondo de 450 gramos | H3: FECHA DE APROBACIÓN:
C4: Elaborado | D4: Jose Brizuela ,Chef
C5: Aprobado | D5: Esteban Cartin, Gte Manufactura
A6: AREA QUE PRODUCE: | D6: Batidos | G6: AREA QUE EMPACA: | I6: Batidos
A7: # Código | B7: # Código Netsuite | C7: Descripción del ingrediente | D7: Marca | E7: Unidad Internacional | G7: Medida alternativa | I7: Costo - Referencia
E8: Cantidad | F8: Unidad medida | G8: Cantidad | H8: Unidad medida | I8: Colones
C9: ENSAMBLE
C10: Batido De Brownie Casero 450 gramos | D10: FAS | E10: 430
C14: EMPAQUE
A15: 1950928 | B15: AS00028 | C15: BOLSA TRANSPARENTE 56X96X1.80 (KILO) | D15: Plasticos P | E15: 1 | F15: ud
A16: 0702123 | B16: EM10011 | C16: ETIQUETA BLANCA 2 5/8X1 15/16 (UND) | D16: cemusa | E16: 1 | F16: ud
D21: Cantidad | E21: Unidad
A22: PESO TOTAL OBTENIDO | D22: 430 | E22: g | F22: Tiempo de Horneo:
A23: TIEMPO TOTAL DE PREPARACION | D23: 1 | E23: min | F23: Horno:
A24: CANTIDAD DE PORCIONES OBTENIDAS | D24: 1 | E24: cajas | F24: Temperatura de Horneo:
A25: PESO DE CADA PORCIÓN | D25: 430 | E25: g | F25: Otros
A26: MERMA | D26: 0 | E26: g
A27: PROCEDIMIENTO DE PREPARACION DE LA RECETA
A28: 1-Desmoldar y Colocar en una bandeja 6 unidades
A29: 3.- Tapar, Etiquetar con fecha de vencimiento y etiqueta con nombre
A30: Control de cambios

Sheet costo Rosquete
E1: Precio Local | F1: Costo MP | G1: Costo EM | H1: Costo MO
E2: =IFERROR(O62,"") -> 600.81575 | F2: =IFERROR(H53,"") -> 581.26105 | G2: =IFERROR(H54,"") -> 9.6951779 | H2: =IFERROR(H56,"") -> 102.30128
A5: ESTRUCTURA DE COSTOS
F6: Fecha: | H6: =TODAY() -> 46055
A7: UNIDADES | B7: DESCRIPCION MAT.PRIMA | C7: UNIDADES | D7: UND MEDIDA | E7: COSTO UNITARIO | F7: TOTAL COSTO | G7: % PREC. DEFINIDO | H7: CODIGOS
B8: =IFERROR(VLOOKUP(H8,'[1]Consolidado MP Planta'!$A$2:$M$823,3,0),"") | C8: =+A8 -> 0 | D8: =IFERROR(VLOOKUP(H8,'[1]Consolidado MP Planta'!$A$2:$M$823,13,0),"") | E8: =IFERROR(VLOOKUP(H8,'[1]Consolidado MP Planta'!$A$2:$M$823,12,0),"") | F8: =IFERROR(C8*E8,"") | G8: =IFERROR(F8/$F$66,"")
B9: =IFERROR(VLOOKUP(H9,'[1]Consolidado MP Planta'!$A$2:$M$823,3,0),"") | C9: =+A9 -> 0 | D9: =IFERROR(VLOOKUP(H9,'[1]Consolidado MP Planta'!$A$2:$M$823,13,0),"") | E9: =IFERROR(VLOOKUP(H9,'[1]Consolidado MP Planta'!$A$2:$M$823,12,0),"") | F9: =IFERROR(C9*E9,"") | G9: =IFERROR(F9/$F$66,"")
B10: =IFERROR(VLOOKUP(H10,'[1]Consolidado MP Planta'!$A$2:$M$823,3,0),"") | C10: =+A10 -> 0 | D10: =IFERROR(VLOOKUP(H10,'[1]Consolidado MP Planta'!$A$2:$M$823,13,0),"") | E10: =IFERROR(VLOOKUP(H10,'[1]Consolidado MP Planta'!$A$2:$M$823,12,0),"") | F10: =IFERROR(C10*E10,"") | G10: =IFERROR(F10/$F$66,"")
B11: =IFERROR(VLOOKUP(H11,'[1]Consolidado MP Planta'!$A$2:$M$823,3,0),"") | C11: =+A11 -> 0 | D11: =IFERROR(VLOOKUP(H11,'[1]Consolidado MP Planta'!$A$2:$M$823,13,0),"") | E11: =IFERROR(VLOOKUP(H11,'[1]Consolidado MP Planta'!$A$2:$M$823,12,0),"") | F11: =IFERROR(C11*E11,"") | G11: =IFERROR(F11/$F$66,"")
B12: =IFERROR(VLOOKUP(H12,'[1]Consolidado MP Planta'!$A$2:$M$823,3,0),"") | C12: =+A12 -> 0 | D12: =IFERROR(VLOOKUP(H12,'[1]Consolidado MP Planta'!$A$2:$M$823,13,0),"") | E12: =IFERROR(VLOOKUP(H12,'[1]Consolidado MP Planta'!$A$2:$M$823,12,0),"") | F12: =IFERROR(C12*E12,"") | G12: =IFERROR(F12/$F$66,"")
B13: =IFERROR(VLOOKUP(H13,'[1]Consolidado MP Planta'!$A$2:$M$823,3,0),"") | C13: =+A13 -> 0 | D13: =IFERROR(VLOOKUP(H13,'[1]Consolidado MP Planta'!$A$2:$M$823,13,0),"") | E13: =IFERROR(VLOOKUP(H13,'[1]Consolidado MP Planta'!$A$2:$M$823,12,0),"") | F13: =IFERROR(C13*E13,"") | G13: =IFERROR(F13/$F$66,"")
B14: =IFERROR(VLOOKUP(H14,'[1]Consolidado MP Planta'!$A$2:$M$823,3,0),"") | C14: =+A14 -> 0 | D14: =IFERROR(VLOOKUP(H14,'[1]Consolidado MP Planta'!$A$2:$M$823,13,0),"") | E14: =IFERROR(VLOOKUP(H14,'[1]Consolidado MP Planta'!$A$2:$M$823,12,0),"") | F14: =IFERROR(C14*E14,"") | G14: =IFERROR(F14/$F$66,"")
B15: =IFERROR(VLOOKUP(H15,'[2]ARTICULOS MP PLANTA'!$A$2:$G$589,2,0),"")
A16: UNIDADES | B16: MATERIA PRIMA SEMIELABORADOS | C16: UNIDADES | D16: UND MEDIDA | E16: COSTO UNITARIO | F16: TOTAL COSTO | G16: % PREC. DEFINIDO | H16: CODIGOS
A17: 8000 | B17: Batido De Brownie Casero 450 gramos | C17: =+A17 -> 8000 | D17: Gramos | E17: =+'Costo Batido'!E69 -> 1.303995 | F17: =IFERROR(E17*C17,"") -> 10431.96 | G17: =IFERROR(F17/$F$66,"") -> 0.85374575 | H17: 902000014
A18: 300 | B18: MEZCLA ENGRASE MOLDES (29800g) | C18: =+A18 -> 300 | D18: Gramos | E18: 2.04 | F18: =IFERROR(E18*C18,"") -> 612 | G18: =IFERROR(F18/$F$66,"") -> 0.050085737 | H18: 95720
B19: =IFERROR(VLOOKUP(H19,[1]SEMIELABORADOS!$A$2:$M$6000,2,0),"") | C19: =+A19 -> 0 | D19: =IFERROR(VLOOKUP(H19,[1]SEMIELABORADOS!$A$2:$M$6000,6,0),"") | E19: =IFERROR(VLOOKUP(H19,[1]SEMIELABORADOS!$A$2:$H$65536,8,0),"") | F19: =IFERROR(E19*C19,"") | G19: =IFERROR(F19/$F$66,"")
B20: =IFERROR(VLOOKUP(H20,[1]SEMIELABORADOS!$A$2:$M$6000,2,0),"") | C20: =+A20 -> 0 | D20: =IFERROR(VLOOKUP(H20,[1]SEMIELABORADOS!$A$2:$M$6000,6,0),"") | E20: =IFERROR(VLOOKUP(H20,[1]SEMIELABORADOS!$A$2:$H$65536,8,0),"") | F20: =IFERROR(E20*C20,"") | G20: =IFERROR(F20/$F$66,"")
B21: =IFERROR(VLOOKUP(H21,[1]SEMIELABORADOS!$A$2:$M$6000,2,0),"") | C21: =+A21 -> 0 | D21: =IFERROR(VLOOKUP(H21,[1]SEMIELABORADOS!$A$2:$M$6000,6,0),"") | E21: =IFERROR(VLOOKUP(H21,[1]SEMIELABORADOS!$A$2:$H$65536,8,0),"") | F21: =IFERROR(E21*C21,"") | G21: =IFERROR(F21/$F$66,"")
B22: =IFERROR(VLOOKUP(H22,[1]SEMIELABORADOS!$A$2:$M$6000,2,0),"") | C22: =+A22 -> 0 | D22: =IFERROR(VLOOKUP(H22,[1]SEMIELABORADOS!$A$2:$M$6000,6,0),"") | E22: =IFERROR(VLOOKUP(H22,[1]SEMIELABORADOS!$A$2:$H$65536,8,0),"") | F22: =IFERROR(E22*C22,"") | G22: =IFERROR(F22/$F$66,"")
