Workbook

Sheet Premezcla Easy BC
C1: SERVICIOS DE PASTELERIA S.A. | H1: CÓDIGO: | I1: ESP-RE-PRES-129
C2: ESPECIFICACION DE RECETA | H2: REVISIÓN: | I2: 02
C3: 906000136(SE00436) Premezcla Easy vainilla BC | H3: FECHA DE APROBACIÓN: | I3: 15/03/2023
C4: Elaborado | D4: Javier Tong, Chef
C5: Aprobado | D5: Esteban Cartin, Gerente de Manufactura
A7: AREA QUE PRODUCE: | D7: Premezclas | G7: AREA QUE EMPACA: | I7: Premezclas
A8: # Código | B8: # Codigo Netsuite | C8: Descripción del ingrediente | D8: Marca | E8: Unidad Internacional | G8: Medida alternativa | I8: Costo - Referencia
E9: Cantidad | F9: Unidad medida | G9: Cantidad | H9: Unidad medida | I9: Colones
A10: 11200080 | B10: MP10491 | C10: EASY VAINILLA BC | D10: Puratos | E10: 4600 | F10: g
A11: 510301 | B11: MP10074 | C11: AZUCAR BLANCO INDUSTRIAL (SACO:50 K) | D11: Layca | E11: 11000 | F11: g
A12: 11200072 | B12: MP10478 | C12: HARINA SILVER CAKE (SACO: 25K) | D12: Fhacasa | E12: 7500 | F12: g
A13: 0510107 | B13: MP10036 | C13: Harina Harisol Winter | D13: Fhacasa | E13: 1900
A14: 1212410 | B14: MP10008 | C14: PRESERVANTE 1047S (PAQ=5 KILO) | D14: Mayca | E14: 50 | F14: g
A15: 10100046 | B15: MP10304 | C15: POLVO HORNEAR FLEISHMAN (PAQ:2.5 K) | D15: Fleishman | E15: 300 | F15: g
A17: 1950708 | B17: EM10013 | C17: BOLSA 17x25 TRANSP KILO | E17: 1 | F17: ud
A18: 503000042 | B18: EM10258 | C18: BOLSA TRANSP 20x30x2000 | E18: 1 | F18: ud
A19: 0702123 | B19: EM10011 | C19: ETIQUETA BLANCA 2 5/8X1 15/16 (UND) | E19: 2 | F19: ud
A20: 1950705 | B20: EM10037 | C20: BOLSA 8x12 TRANSPARENTE KILO | E20: 1 | F20: ud
A21: 60100010 | B21: EM10133 | C21: ETIQUETA ROJA LETRA ALERJENO (UND) | E21: 1 | F21: ud
D22: Cantidad | E22: Unidad
A23: PESO TOTAL OBTENIDO | D23: 25350 | E23: g
A24: TIEMPO TOTAL DE PREPARACION | D24: 4 | E24: min
A25: CANTIDAD DE PORCIONES OBTENIDAS | D25: 1 | E25: tanda
A26: PESO DE CADA PORCIÓN | D26: 25350 | E26: g
A27: MERMA | D27: 0 | E27: g
A28: PROCEDIMIENTO DE PREPARACION DE LA RECETA
A29: 1.- En una bolsa 20x30 empacar el nucleo easy con el harina. En una bolsa 17x25 empacar el azucar, y etiquetar.
A30: 2.- En la otra bolsa 8x12 empacar el preservante, polvo de hornear. Colocar en la misma bolsa del harina.
A38: Control de cambios
A39: 2, Actualizacion de procedimiento y de bolsas

Sheet Batido Easy Vainilla BC 
C1: SERVICIOS DE PASTELERIA S.A. | H1: CÓDIGO: | I1: ESP-RE-BAF-118
C2: ESPECIFICACION DE RECETA | H2: REVISIÓN: | I2: 02
C3: 907000286(SE00437) Batido Easy Vainilla BC | H3: FECHA DE APROBACIÓN: | I3: 45167
C4: Elaborado | D4: Javier Tong, Chef
C5: Aprobado | D5: Esteban Cartin, Gerente de Manufactura
A7: AREA QUE PRODUCE: | D7: Batidos | G7: AREA QUE EMPACA: | I7: Batidos
A8: # Código | B8: # Codigo Netsuite | C8: Descripción del ingrediente | D8: Marca | E8: Unidad Internacional | G8: Medida alternativa | I8: Costo - Referencia
E9: Cantidad | F9: Unidad medida | G9: Cantidad | H9: Unidad medida | I9: Colones
A10: 906000136 | B10: SE00436 | C10: PREMEZCLA EASY VAINILLA BC | D10: FAS | E10: 25350 | F10: g
A11: 1210482 | B11: MP10005 | C11: HUEVO LIQUIDO ESPECIAL INNOV (CAJA:10 K) | D11: INNOVO | E11: 9600 | F11: g
A12: 10415 | C12: AGUA POTABLE (PLANTA) | D12: FAS | E12: 10200 | F12: g
A13: 10100050 | B13: MP10002 | C13: ACEITE CAPULLO RBD (UND:17 L) | D13: CAPULLO | E13: 1400 | F13: g
G14: 4600
F15: =+G14/D18 -> 0.1
D17: Cantidad | E17: Unidad
A18: PESO TOTAL OBTENIDO | D18: 46000 | E18: g
A19: TIEMPO TOTAL DE PREPARACION | D19: 11 | E19: min
A20: CANTIDAD DE PORCIONES OBTENIDAS | D20: 1 | E20: ud
A21: PESO DE CADA PORCIÓN | D21: 49000 | E21: g
A22: MERMA | D22: =SUM(E10:E13)-D18 -> 550 | E22: g
A23: PROCEDIMIENTO DE PREPARACION DE LA RECETA
A24: 1.- Agregar el huevo y la mitad del agua con los secos, batir 1 minuto a velocidad 1, luego 2 minutos en 2.
A25: 2.- Agregar la otra mitad del agua y el aceite y batir por 2 minutos en velocidad 2.
A26: 3.- Dosificar.
A30: CONTROL DE CAMBIOS
A31: Revision #2: Actualizacion del procedimiento.

Sheet Costo de borona 
E1: Precio Local | F1: Costo MP | G1: Costo EM | H1: Costo MO
E2: =IFERROR(O62,"") -> 3331.39 | F2: =IFERROR(H53,"") -> 2341.98 | G2: =IFERROR(H54,"") -> 2.41 | H2: =IFERROR(H56,"") -> 539
A5: ESTRUCTURA DE COSTOS
F6: Fecha: | H6: =TODAY() -> 46149
A7: UNIDADES | B7: DESCRIPCION MAT.PRIMA | C7: UNIDADES | D7: UND MEDIDA | E7: COSTO UNITARIO | F7: TOTAL COSTO | G7: % PREC. DEFINIDO | H7: CODIGOS
B8: =IFERROR(VLOOKUP(H8,'[1]Consolidado MP Planta'!$A$2:$M$823,3,0),"") | C8: =+A8 -> 0 | D8: =IFERROR(VLOOKUP(H8,'[1]Consolidado MP Planta'!$A$2:$M$823,13,0),"") | E8: =IFERROR(VLOOKUP(H8,'[1]Consolidado MP Planta'!$A$2:$M$823,12,0),"") | F8: =IFERROR(C8*E8,"") | G8: =IFERROR(F8/$F$66,"")
B9: =IFERROR(VLOOKUP(H9,'[1]Consolidado MP Planta'!$A$2:$M$823,3,0),"") | C9: =+A9 -> 0 | D9: =IFERROR(VLOOKUP(H9,'[1]Consolidado MP Planta'!$A$2:$M$823,13,0),"") | E9: =IFERROR(VLOOKUP(H9,'[1]Consolidado MP Planta'!$A$2:$M$823,12,0),"") | F9: =IFERROR(C9*E9,"") | G9: =IFERROR(F9/$F$66,"")
B10: =IFERROR(VLOOKUP(H10,'[1]Consolidado MP Planta'!$A$2:$M$823,3,0),"") | C10: =+A10 -> 0 | D10: =IFERROR(VLOOKUP(H10,'[1]Consolidado MP Planta'!$A$2:$M$823,13,0),"") | E10: =IFERROR(VLOOKUP(H10,'[1]Consolidado MP Planta'!$A$2:$M$823,12,0),"") | F10: =IFERROR(C10*E10,"") | G10: =IFERROR(F10/$F$66,"")
B11: =IFERROR(VLOOKUP(H11,'[1]Consolidado MP Planta'!$A$2:$M$823,3,0),"") | C11: =+A11 -> 0 | D11: =IFERROR(VLOOKUP(H11,'[1]Consolidado MP Planta'!$A$2:$M$823,13,0),"") | E11: =IFERROR(VLOOKUP(H11,'[1]Consolidado MP Planta'!$A$2:$M$823,12,0),"") | F11: =IFERROR(C11*E11,"") | G11: =IFERROR(F11/$F$66,"")
B12: =IFERROR(VLOOKUP(H12,'[1]Consolidado MP Planta'!$A$2:$M$823,3,0),"") | C12: =+A12 -> 0 | D12: =IFERROR(VLOOKUP(H12,'[1]Consolidado MP Planta'!$A$2:$M$823,13,0),"") | E12: =IFERROR(VLOOKUP(H12,'[1]Consolidado MP Planta'!$A$2:$M$823,12,0),"") | F12: =IFERROR(C12*E12,"") | G12: =IFERROR(F12/$F$66,"")
B13: =IFERROR(VLOOKUP(H13,'[1]Consolidado MP Planta'!$A$2:$M$823,3,0),"") | C13: =+A13 -> 0 | D13: =IFERROR(VLOOKUP(H13,'[1]Consolidado MP Planta'!$A$2:$M$823,13,0),"") | E13: =IFERROR(VLOOKUP(H13,'[1]Consolidado MP Planta'!$A$2:$M$823,12,0),"") | F13: =IFERROR(C13*E13,"") | G13: =IFERROR(F13/$F$66,"")
B14: =IFERROR(VLOOKUP(H14,'[1]Consolidado MP Planta'!$A$2:$M$823,3,0),"") | C14: =+A14 -> 0 | D14: =IFERROR(VLOOKUP(H14,'[1]Consolidado MP Planta'!$A$2:$M$823,13,0),"") | E14: =IFERROR(VLOOKUP(H14,'[1]Consolidado MP Planta'!$A$2:$M$823,12,0),"") | F14: =IFERROR(C14*E14,"") | G14: =IFERROR(F14/$F$66,"")
B15: =IFERROR(VLOOKUP(H15,'[2]ARTICULOS MP PLANTA'!$A$2:$G$589,2,0),"")
A16: UNIDADES | B16: MATERIA PRIMA SEMIELABORADOS | C16: UNIDADES | D16: UND MEDIDA | E16: COSTO UNITARIO | F16: TOTAL COSTO | G16: % PREC. DEFINIDO | H16: CODIGOS
A17: 6 | B17: Rosquete easy vainilla BC 300g | C17: =+A17 -> 6 | D17: UND | E17: 390.33 | F17: =IFERROR(E17*C17,"") -> 2341.98 | G17: =IFERROR(F17/$F$66,"") -> 0.79924795 | H17: SE00624
B18: =IFERROR(VLOOKUP(H18,[1]SEMIELABORADOS!$A$2:$M$6000,2,0),"") | C18: =+A18 -> 0 | D18: =IFERROR(VLOOKUP(H18,[1]SEMIELABORADOS!$A$2:$M$6000,6,0),"") | E18: =IFERROR(VLOOKUP(H18,[1]SEMIELABORADOS!$A$2:$H$65536,8,0),"") | F18: =IFERROR(E18*C18,"") | G18: =IFERROR(F18/$F$66,"")
B19: =IFERROR(VLOOKUP(H19,[1]SEMIELABORADOS!$A$2:$M$6000,2,0),"") | C19: =+A19 -> 0 | D19: =IFERROR(VLOOKUP(H19,[1]SEMIELABORADOS!$A$2:$M$6000,6,0),"") | E19: =IFERROR(VLOOKUP(H19,[1]SEMIELABORADOS!$A$2:$H$65536,8,0),"") | F19: =IFERROR(E19*C19,"") | G19: =IFERROR(F19/$F$66,"")
B20: =IFERROR(VLOOKUP(H20,[1]SEMIELABORADOS!$A$2:$M$6000,2,0),"") | C20: =+A20 -> 0 | D20: =IFERROR(VLOOKUP(H20,[1]SEMIELABORADOS!$A$2:$M$6000,6,0),"") | E20: =IFERROR(VLOOKUP(H20,[1]SEMIELABORADOS!$A$2:$H$65536,8,0),"") | F20: =IFERROR(E20*C20,"") | G20: =IFERROR(F20/$F$66,"")
B21: =IFERROR(VLOOKUP(H21,[1]SEMIELABORADOS!$A$2:$M$6000,2,0),"") | C21: =+A21 -> 0 | D21: =IFERROR(VLOOKUP(H21,[1]SEMIELABORADOS!$A$2:$M$6000,6,0),"") | E21: =IFERROR(VLOOKUP(H21,[1]SEMIELABORADOS!$A$2:$H$65536,8,0),"") | F21: =IFERROR(E21*C21,"") | G21: =IFERROR(F21/$F$66,"")
B22: =IFERROR(VLOOKUP(H22,[1]SEMIELABORADOS!$A$2:$M$6000,2,0),"") | C22: =+A22 -> 0 | D22: =IFERROR(VLOOKUP(H22,[1]SEMIELABORADOS!$A$2:$M$6000,6,0),"") | E22: =IFERROR(VLOOKUP(H22,[1]SEMIELABORADOS!$A$2:$H$65536,8,0),"") | F22: =IFERROR(E22*C22,"") | G22: =IFERROR(F22/$F$66,"")
B23: =IFERROR(VLOOKUP(H23,[1]SEMIELABORADOS!$A$2:$M$6000,2,0),"") | C23: =+A23 -> 0 | D23: =IFERROR(VLOOKUP(H23,[1]SEMIELABORADOS!$A$2:$M$6000,6,0),"") | E23: =IFERROR(VLOOKUP(H23,[1]SEMIELABORADOS!$A$2:$H$65536,8,0),"") | F23: =IFERROR(E23*C23,"") | G23: =IFERROR(F23/$F$66,"")
B24: =IFERROR(VLOOKUP(H24,[1]SEMIELABORADOS!$A$2:$M$6000,2,0),"") | C24: =+A24 -> 0 | D24: =IFERROR(VLOOKUP(H24,[1]SEMIELABORADOS!$A$2:$M$6000,6,0),"") | E24: =IFERROR(VLOOKUP(H24,[1]SEMIELABORADOS!$A$2:$H$65536,8,0),"") | F24: =IFERROR(E24*C24,"") | G24: =IFERROR(F24/$F$66,"")
A26: UNIDADES | B26: EMPAQUE | C26: UNIDADES | D26: UND MEDIDA | E26: COSTO UNITARIO | F26: TOTAL COSTO | G26: % PREC. DEFINIDO | H26: CODIGOS
A27: 1 | B27: ETIQUETA BLANCA 2 5/8X1 15/16 (UND) | C27: =+A27 -> 1 | D27: UND | E27: 2.13 | F27: =IFERROR(C27*E27,"") -> 2.13 | G27: =IFERROR(F27/$F$66,"") -> 0.0007269055 | H27: EM10011
A28: 1 | B28: ETIQ.FECHA VENCIMIENTO BLANCO (ROLLO) | C28: =+A28 -> 1 | D28: UND | E28: 0.28 | F28: =IFERROR(C28*E28,"") -> 0.28 | G28: =IFERROR(F28/$F$66,"") -> 9.5555652e-05 | H28: EM10004
B29: =IFERROR(VLOOKUP(H29,'[1]Consolidado MP Planta'!$A$2:$M$823,3,0),"") | C29: =+A29 -> 0 | D29: =IFERROR(VLOOKUP(H29,'[1]Consolidado MP Planta'!$A$2:$M$823,13,0),"") | E29: =IFERROR(VLOOKUP(H29,'[1]Consolidado MP Planta'!$A$2:$M$823,12,0),"") | F29: =IFERROR(C29*E29,"") | G29: =IFERROR(F29/$F$66,"")
B30: =IFERROR(VLOOKUP(H30,'[1]Consolidado MP Planta'!$A$2:$M$823,3,0),"") | C30: =+A30 -> 0 | D30: =IFERROR(VLOOKUP(H30,'[1]Consolidado MP Planta'!$A$2:$M$823,13,0),"") | E30: =IFERROR(VLOOKUP(H30,'[1]Consolidado MP Planta'!$A$2:$M$823,12,0),"") | F30: =IFERROR(C30*E30,"") | G30: =IFERROR(F30/$F$66,"")
B31: =IFERROR(VLOOKUP(H31,'[1]Consolidado MP Planta'!$A$2:$M$823,3,0),"") | C31: =+A31 -> 0 | D31: =IFERROR(VLOOKUP(H31,'[1]Consolidado MP Planta'!$A$2:$M$823,13,0),"") | E31: =IFERROR(VLOOKUP(H31,'[1]Consolidado MP Planta'!$A$2:$M$823,12,0),"") | F31: =IFERROR(C31*E31,"") | G31: =IFERROR(F31/$F$66,"")
B32: =IFERROR(VLOOKUP(H32,'[1]Consolidado MP Planta'!$A$2:$M$823,3,0),"") | C32: =+A32 -> 0 | D32: =IFERROR(VLOOKUP(H32,'[1]Consolidado MP Planta'!$A$2:$M$823,13,0),"") | E32: =IFERROR(VLOOKUP(H32,'[1]Consolidado MP Planta'!$A$2:$M$823,12,0),"") | F32: =IFERROR(C32*E32,"") | G32: =IFERROR(F32/$F$66,"")
A34: UNIDADES | B34: EMPAQUE SEMIELABORADOS | C34: UNIDADES | D34: UND MEDIDA | E34: COSTO UNITARIO | F34: TOTAL COSTO | G34: % PREC. DEFINIDO | H34: CODIGOS
A35: =+A17 -> 6 | B35: =IFERROR(VLOOKUP(H35,[1]SEMIELABORADOS!$A$2:$M$6000,2,0),"") | C35: =+A35 -> 6 | D35: =IFERROR(VLOOKUP(H35,[1]SEMIELABORADOS!$A$2:$M$6000,6,0),"") | E35: =IFERROR(VLOOKUP(H35,[1]SEMIELABORADOS!$A$2:$M$65536,10,0),"") | F35: =IFERROR(E35*C35,"") | G35: =IFERROR(F35/$F$66,"")
A36: =+A18 -> 0 | B36: =IFERROR(VLOOKUP(H36,[1]SEMIELABORADOS!$A$2:$M$6000,2,0),"") | C36: =+A36 -> 0 | D36: =IFERROR(VLOOKUP(H36,[1]SEMIELABORADOS!$A$2:$M$6000,6,0),"") | E36: =IFERROR(VLOOKUP(H36,[1]SEMIELABORADOS!$A$2:$M$65536,10,0),"") | F36: =IFERROR(E36*C36,"") | G36: =IFERROR(F36/$F$66,"")
A37: =+A19 -> 0 | B37: =IFERROR(VLOOKUP(H37,[1]SEMIELABORADOS!$A$2:$M$6000,2,0),"") | C37: =+A37 -> 0 | D37: =IFERROR(VLOOKUP(H37,[1]SEMIELABORADOS!$A$2:$M$6000,6,0),"") | E37: =IFERROR(VLOOKUP(H37,[1]SEMIELABORADOS!$A$2:$M$65536,10,0),"") | F37: =IFERROR(E37*C37,"") | G37: =IFERROR(F37/$F$66,"")
A38: =+A20 -> 0 | B38: =IFERROR(VLOOKUP(H38,[1]SEMIELABORADOS!$A$2:$M$6000,2,0),"") | C38: =+A38 -> 0 | D38: =IFERROR(VLOOKUP(H38,[1]SEMIELABORADOS!$A$2:$M$6000,6,0),"") | E38: =IFERROR(VLOOKUP(H38,[1]SEMIELABORADOS!$A$2:$M$65536,10,0),"") | F38: =IFERROR(E38*C38,"") | G38: =IFERROR(F38/$F$66,"")
A39: =+A21 -> 0 | B39: =IFERROR(VLOOKUP(H39,[1]SEMIELABORADOS!$A$2:$M$6000,2,0),"") | C39: =+A39 -> 0 | D39: =IFERROR(VLOOKUP(H39,[1]SEMIELABORADOS!$A$2:$M$6000,6,0),"") | E39: =IFERROR(VLOOKUP(H39,[1]SEMIELABORADOS!$A$2:$M$65536,10,0),"") | F39: =IFERROR(E39*C39,"") | G39: =IFERROR(F39/$F$66,"")
A40: =+A22 -> 0 | B40: =IFERROR(VLOOKUP(H40,[1]SEMIELABORADOS!$A$2:$M$6000,2,0),"") | C40: =+A40 -> 0 | D40: =IFERROR(VLOOKUP(H40,[1]SEMIELABORADOS!$A$2:$M$6000,6,0),"") | E40: =IFERROR(VLOOKUP(H40,[1]SEMIELABORADOS!$A$2:$M$65536,10,0),"") | F40: =IFERROR(E40*C40,"") | G40: =IFERROR(F40/$F$66,"")
A41: =+A23 -> 0 | B41: =IFERROR(VLOOKUP(H41,[1]SEMIELABORADOS!$A$2:$M$6000,2,0),"") | C41: =+A41 -> 0 | D41: =IFERROR(VLOOKUP(H41,[1]SEMIELABORADOS!$A$2:$M$6000,6,0),"") | E41: =IFERROR(VLOOKUP(H41,[1]SEMIELABORADOS!$A$2:$M$65536,10,0),"") | F41: =IFERROR(E41*C41,"") | G41: =IFERROR(F41/$F$66,"")
A43: UNIDADES | B43: MODI | C43: UNIDADES | D43: UND MEDIDA | E43: COSTO UNITARIO | F43: TOTAL COSTO | G43: % PREC. DEFINIDO | H43: CODIGOS
A44: =+A35 -> 6 | B44: =IFERROR(VLOOKUP(H44,[1]SEMIELABORADOS!$A$2:$M$6000,2,0),"") | C44: =+A44 -> 6 | D44: =IFERROR(VLOOKUP(H44,[1]SEMIELABORADOS!$A$2:$M$6000,6,0),"") | E44: =IFERROR(VLOOKUP(H44,[1]SEMIELABORADOS!$A$2:$M$65536,12,0),"") | F44: =IFERROR(E44*C44,"") | G44: =IFERROR(F44/$F$66,"")
A45: =+A36 -> 0 | B45: =IFERROR(VLOOKUP(H45,[1]SEMIELABORADOS!$A$2:$M$6000,2,0),"") | C45: =+A45 -> 0 | D45: =IFERROR(VLOOKUP(H45,[1]SEMIELABORADOS!$A$2:$M$6000,6,0),"") | E45: =IFERROR(VLOOKUP(H45,[1]SEMIELABORADOS!$A$2:$M$65536,12,0),"") | F45: =IFERROR(E45*C45,"") | G45: =IFERROR(F45/$F$66,"")
...

Sheet Rosquete Easy 300
C1: SERVICIOS DE PASTELERIA S.A. | H1: CÓDIGO:
C2: ESPECIFICACION DE RECETA | H2: REVISIÓN:
C3: SE00624 Rosquete easy vainilla BC 300g | H3: FECHA DE APROBACIÓN:
C4: Elaborado | D4: Juan Pablo Brenes, Chef
C5: Aprobado | D5: Esteban Cartin, Gte Manufactura
A6: # Código | B6: # Codigo Netsuite | C6: Descripción del ingrediente | D6: Marca | E6: Unidad Internacional | G6: Medida alternativa | I6: Costo - Referencia
E7: Cantidad | F7: Unidad medida | G7: Cantidad | H7: Unidad medida | I7: Colones
A8: 907000286 | B8: SE00437 | C8: BATIDO EASY VAINILLA BC | D8: FAS | E8: 46000 | F8: g
A9: 902000019 | C9: MEZCLA P/ENGRASE MOLDES KILO | D9: FAS | E9: =20*D19 -> 3033.3333 | F9: g
A11: 702007 | B11: EM10004 | C11: ETIQ.FECHA VENCIMIENTO BLANCO (ROLLO) | D11: Etiplast | E11: 11.821429 | F11: ud
A12: 702123 | B12: EM10011 | C12: ETIQUETA BLANCA 2 5/8X1 15/16 (UND) | D12: FAS | E12: 10 | F12: ud
A13: 1950928 | B13: AS00028 | C13: BOLSA TRANSPARENTE 56X96X1.80 KILO | D13: Plasticos P | E13: 10 | F13: ud
D16: Cantidad | E16: Unidad
A17: PESO TOTAL OBTENIDO | D17: =130*350 -> 45500 | E17: g | F17: Tiempo de Horneo:
A18: TIEMPO TOTAL DE PREPARACION | D18: 50 | E18: min | F18: Horno:
A19: CANTIDAD DE PORCIONES OBTENIDAS | D19: =+D17/D20 -> 151.66667 | E19: ud | F19: Temperatura de Horneo:
A20: PESO POR PORCION | D20: 300 | E20: g | F20: Otros
A21: MERMA | D21: =+E8-D17 -> 500 | E21: g
A22: PROCEDIMIENTO DE PREPARACION DE LA RECETA
A23: 1.- Dosificar en moldes engrasados 300g de mezcla.
A24: 2.- Hornear por 30 minutos en el Dicte 1 a 175°C, en el Dicte 2 por 20 minutos a 175°C, en el Argental por 20 minutos a 175°C, en el Marshall por 18 minutos a 175°C, en el vulcan a 325°F por 25 minutos y en el Curitiba a 130°C por 28.
A25: 3.- Enfriar, desmoldar y empacar 12 unidades por lata, cubrir con bolsa plastica. Etiqueta nombre y fecha.
A26: Control de cambios

Sheet Costo Rosquete 300 g
E1: Precio Local | F1: Costo MP | G1: Costo EM | H1: Costo MO
E2: =IFERROR(O62,"") -> 384.29561 | F2: =IFERROR(H53,"") -> 380.48782 | G2: =IFERROR(H54,"") -> 3.4633846 | H2: =IFERROR(H56,"") -> 26.775758
A5: ESTRUCTURA DE COSTOS
F6: Fecha: | H6: =TODAY() -> 46149
A7: UNIDADES | B7: DESCRIPCION MAT.PRIMA | C7: UNIDADES | D7: UND MEDIDA | E7: COSTO UNITARIO | F7: TOTAL COSTO | G7: % PREC. DEFINIDO | H7: CODIGOS
B8: =IFERROR(VLOOKUP(H8,'[1]Consolidado MP Planta'!$A$2:$M$823,3,0),"") | C8: =+A8 -> 0 | D8: =IFERROR(VLOOKUP(H8,'[1]Consolidado MP Planta'!$A$2:$M$823,13,0),"") | E8: =IFERROR(VLOOKUP(H8,'[1]Consolidado MP Planta'!$A$2:$M$823,12,0),"") | F8: =IFERROR(C8*E8,"") | G8: =IFERROR(F8/$F$66,"")
B9: =IFERROR(VLOOKUP(H9,'[1]Consolidado MP Planta'!$A$2:$M$823,3,0),"") | C9: =+A9 -> 0 | D9: =IFERROR(VLOOKUP(H9,'[1]Consolidado MP Planta'!$A$2:$M$823,13,0),"") | E9: =IFERROR(VLOOKUP(H9,'[1]Consolidado MP Planta'!$A$2:$M$823,12,0),"") | F9: =IFERROR(C9*E9,"") | G9: =IFERROR(F9/$F$66,"")
B10: =IFERROR(VLOOKUP(H10,'[1]Consolidado MP Planta'!$A$2:$M$823,3,0),"") | C10: =+A10 -> 0 | D10: =IFERROR(VLOOKUP(H10,'[1]Consolidado MP Planta'!$A$2:$M$823,13,0),"") | E10: =IFERROR(VLOOKUP(H10,'[1]Consolidado MP Planta'!$A$2:$M$823,12,0),"") | F10: =IFERROR(C10*E10,"") | G10: =IFERROR(F10/$F$66,"")
B11: =IFERROR(VLOOKUP(H11,'[1]Consolidado MP Planta'!$A$2:$M$823,3,0),"") | C11: =+A11 -> 0 | D11: =IFERROR(VLOOKUP(H11,'[1]Consolidado MP Planta'!$A$2:$M$823,13,0),"") | E11: =IFERROR(VLOOKUP(H11,'[1]Consolidado MP Planta'!$A$2:$M$823,12,0),"") | F11: =IFERROR(C11*E11,"") | G11: =IFERROR(F11/$F$66,"")
B12: =IFERROR(VLOOKUP(H12,'[1]Consolidado MP Planta'!$A$2:$M$823,3,0),"") | C12: =+A12 -> 0 | D12: =IFERROR(VLOOKUP(H12,'[1]Consolidado MP Planta'!$A$2:$M$823,13,0),"") | E12: =IFERROR(VLOOKUP(H12,'[1]Consolidado MP Planta'!$A$2:$M$823,12,0),"") | F12: =IFERROR(C12*E12,"") | G12: =IFERROR(F12/$F$66,"")
B13: =IFERROR(VLOOKUP(H13,'[1]Consolidado MP Planta'!$A$2:$M$823,3,0),"") | C13: =+A13 -> 0 | D13: =IFERROR(VLOOKUP(H13,'[1]Consolidado MP Planta'!$A$2:$M$823,13,0),"") | E13: =IFERROR(VLOOKUP(H13,'[1]Consolidado MP Planta'!$A$2:$M$823,12,0),"") | F13: =IFERROR(C13*E13,"") | G13: =IFERROR(F13/$F$66,"")
B14: =IFERROR(VLOOKUP(H14,'[1]Consolidado MP Planta'!$A$2:$M$823,3,0),"") | C14: =+A14 -> 0 | D14: =IFERROR(VLOOKUP(H14,'[1]Consolidado MP Planta'!$A$2:$M$823,13,0),"") | E14: =IFERROR(VLOOKUP(H14,'[1]Consolidado MP Planta'!$A$2:$M$823,12,0),"") | F14: =IFERROR(C14*E14,"") | G14: =IFERROR(F14/$F$66,"")
B15: =IFERROR(VLOOKUP(H15,'[2]ARTICULOS MP PLANTA'!$A$2:$G$589,2,0),"")
A16: UNIDADES | B16: MATERIA PRIMA SEMIELABORADOS | C16: UNIDADES | D16: UND MEDIDA | E16: COSTO UNITARIO | F16: TOTAL COSTO | G16: % PREC. DEFINIDO | H16: CODIGOS
A17: 46000 | B17: BATIDO EASY VAINILLA BC | C17: =+A17 -> 46000 | D17: Gramos | E17: 1.12 | F17: =IFERROR(E17*C17,"") -> 51520 | G17: =IFERROR(F17/$F$66,"") -> 0.8251551 | H17: 907000286
A18: 3033 | B18: =IFERROR(VLOOKUP(H18,[1]SEMIELABORADOS!$A$2:$M$6000,2,0),"") -> MEZCLA P/ENGRASE MOLDES KILO | C18: =+A18 -> 3033 | D18: =IFERROR(VLOOKUP(H18,[1]SEMIELABORADOS!$A$2:$M$6000,6,0),"") -> Gramo | E18: 2.04 | F18: =IFERROR(E18*C18,"") -> 6187.32 | G18: =IFERROR(F18/$F$66,"") -> 0.099097412 | H18: 902000019
B19: =IFERROR(VLOOKUP(H19,[1]SEMIELABORADOS!$A$2:$M$6000,2,0),"") | C19: =+A19 -> 0 | D19: =IFERROR(VLOOKUP(H19,[1]SEMIELABORADOS!$A$2:$M$6000,6,0),"") | E19: =IFERROR(VLOOKUP(H19,[1]SEMIELABORADOS!$A$2:$H$65536,8,0),"") | F19: =IFERROR(E19*C19,"") | G19: =IFERROR(F19/$F$66,"")
B20: =IFERROR(VLOOKUP(H20,[1]SEMIELABORADOS!$A$2:$M$6000,2,0),"") | C20: =+A20 -> 0 | D20: =IFERROR(VLOOKUP(H20,[1]SEMIELABORADOS!$A$2:$M$6000,6,0),"") | E20: =IFERROR(VLOOKUP(H20,[1]SEMIELABORADOS!$A$2:$H$65536,8,0),"") | F20: =IFERROR(E20*C20,"") | G20: =IFERROR(F20/$F$66,"")
B21: =IFERROR(VLOOKUP(H21,[1]SEMIELABORADOS!$A$2:$M$6000,2,0),"") | C21: =+A21 -> 0 | D21: =IFERROR(VLOOKUP(H21,[1]SEMIELABORADOS!$A$2:$M$6000,6,0),"") | E21: =IFERROR(VLOOKUP(H21,[1]SEMIELABORADOS!$A$2:$H$65536,8,0),"") | F21: =IFERROR(E21*C21,"") | G21: =IFERROR(F21/$F$66,"")
B22: =IFERROR(VLOOKUP(H22,[1]SEMIELABORADOS!$A$2:$M$6000,2,0),"") | C22: =+A22 -> 0 | D22: =IFERROR(VLOOKUP(H22,[1]SEMIELABORADOS!$A$2:$M$6000,6,0),"") | E22: =IFERROR(VLOOKUP(H22,[1]SEMIELABORADOS!$A$2:$H$65536,8,0),"") | F22: =IFERROR(E22*C22,"") | G22: =IFERROR(F22/$F$66,"")
B23: =IFERROR(VLOOKUP(H23,[1]SEMIELABORADOS!$A$2:$M$6000,2,0),"") | C23: =+A23 -> 0 | D23: =IFERROR(VLOOKUP(H23,[1]SEMIELABORADOS!$A$2:$M$6000,6,0),"") | E23: =IFERROR(VLOOKUP(H23,[1]SEMIELABORADOS!$A$2:$H$65536,8,0),"") | F23: =IFERROR(E23*C23,"") | G23: =IFERROR(F23/$F$66,"")
B24: =IFERROR(VLOOKUP(H24,[1]SEMIELABORADOS!$A$2:$M$6000,2,0),"") | C24: =+A24 -> 0 | D24: =IFERROR(VLOOKUP(H24,[1]SEMIELABORADOS!$A$2:$M$6000,6,0),"") | E24: =IFERROR(VLOOKUP(H24,[1]SEMIELABORADOS!$A$2:$H$65536,8,0),"") | F24: =IFERROR(E24*C24,"") | G24: =IFERROR(F24/$F$66,"")
A26: UNIDADES | B26: EMPAQUE | C26: UNIDADES | D26: UND MEDIDA | E26: COSTO UNITARIO | F26: TOTAL COSTO | G26: % PREC. DEFINIDO | H26: CODIGOS
A27: 12 | B27: =IFERROR(VLOOKUP(H27,'[1]Consolidado MP Planta'!$A$2:$M$823,3,0),"") -> ETIQ.FECHA VENCIMIENTO BLANCO (ROLLO) | C27: =+A27 -> 12 | D27: =IFERROR(VLOOKUP(H27,'[1]Consolidado MP Planta'!$A$2:$M$823,13,0),"") -> Gramos | E27: =IFERROR(VLOOKUP(H27,'[1]Consolidado MP Planta'!$A$2:$M$823,12,0),"") -> 0.33333333 | F27: =IFERROR(C27*E27,"") -> 4 | G27: =IFERROR(F27/$F$66,"") -> 6.4064837e-05 | H27: 0702007
A28: 10 | B28: =IFERROR(VLOOKUP(H28,'[1]Consolidado MP Planta'!$A$2:$M$823,3,0),"") -> ETIQUETA BLANCA 2 5/8X1 15/16 (UND) | C28: =+A28 -> 10 | D28: =IFERROR(VLOOKUP(H28,'[1]Consolidado MP Planta'!$A$2:$M$823,13,0),"") -> Und | E28: =IFERROR(VLOOKUP(H28,'[1]Consolidado MP Planta'!$A$2:$M$823,12,0),"") -> 2.128 | F28: =IFERROR(C28*E28,"") -> 21.28 | G28: =IFERROR(F28/$F$66,"") -> 0.00034082493 | H28: 0702123
A29: 10 | B29: =IFERROR(VLOOKUP(H29,'[1]Consolidado MP Planta'!$A$2:$M$823,3,0),"") -> BOLSA TRANSPARENTE 56X96X1.80 KILO | C29: =+A29 -> 10 | D29: =IFERROR(VLOOKUP(H29,'[1]Consolidado MP Planta'!$A$2:$M$823,13,0),"") -> Und | E29: =IFERROR(VLOOKUP(H29,'[1]Consolidado MP Planta'!$A$2:$M$823,12,0),"") -> 50 | F29: =IFERROR(C29*E29,"") -> 500 | G29: =IFERROR(F29/$F$66,"") -> 0.0080081047 | H29: 1950928
B30: =IFERROR(VLOOKUP(H30,'[1]Consolidado MP Planta'!$A$2:$M$823,3,0),"") | C30: =+A30 -> 0 | D30: =IFERROR(VLOOKUP(H30,'[1]Consolidado MP Planta'!$A$2:$M$823,13,0),"") | E30: =IFERROR(VLOOKUP(H30,'[1]Consolidado MP Planta'!$A$2:$M$823,12,0),"") | F30: =IFERROR(C30*E30,"") | G30: =IFERROR(F30/$F$66,"")
B31: =IFERROR(VLOOKUP(H31,'[1]Consolidado MP Planta'!$A$2:$M$823,3,0),"") | C31: =+A31 -> 0 | D31: =IFERROR(VLOOKUP(H31,'[1]Consolidado MP Planta'!$A$2:$M$823,13,0),"") | E31: =IFERROR(VLOOKUP(H31,'[1]Consolidado MP Planta'!$A$2:$M$823,12,0),"") | F31: =IFERROR(C31*E31,"") | G31: =IFERROR(F31/$F$66,"")
B32: =IFERROR(VLOOKUP(H32,'[1]Consolidado MP Planta'!$A$2:$M$823,3,0),"") | C32: =+A32 -> 0 | D32: =IFERROR(VLOOKUP(H32,'[1]Consolidado MP Planta'!$A$2:$M$823,13,0),"") | E32: =IFERROR(VLOOKUP(H32,'[1]Consolidado MP Planta'!$A$2:$M$823,12,0),"") | F32: =IFERROR(C32*E32,"") | G32: =IFERROR(F32/$F$66,"")
A34: UNIDADES | B34: EMPAQUE SEMIELABORADOS | C34: UNIDADES | D34: UND MEDIDA | E34: COSTO UNITARIO | F34: TOTAL COSTO | G34: % PREC. DEFINIDO | H34: CODIGOS
A35: =+A17 -> 46000 | B35: BATIDO EASY VAINILLA BC | C35: =+A35 -> 46000 | D35: Gramos | E35: 0 | F35: =IFERROR(E35*C35,"") -> 0 | G35: =IFERROR(F35/$F$66,"") -> 0 | H35: 907000286
A36: =+A18 -> 3033 | B36: MEZCLA P/ENGRASE MOLDES KILO | C36: =+A36 -> 3033 | D36: Gramos | E36: 0 | F36: =IFERROR(E36*C36,"") -> 0 | G36: =IFERROR(F36/$F$66,"") -> 0
A37: =+A19 -> 0 | B37: =IFERROR(VLOOKUP(H37,[1]SEMIELABORADOS!$A$2:$M$6000,2,0),"") | C37: =+A37 -> 0 | D37: =IFERROR(VLOOKUP(H37,[1]SEMIELABORADOS!$A$2:$M$6000,6,0),"") | E37: =IFERROR(VLOOKUP(H37,[1]SEMIELABORADOS!$A$2:$M$65536,10,0),"") | F37: =IFERROR(E37*C37,"") | G37: =IFERROR(F37/$F$66,"")
A38: =+A20 -> 0 | B38: =IFERROR(VLOOKUP(H38,[1]SEMIELABORADOS!$A$2:$M$6000,2,0),"") | C38: =+A38 -> 0 | D38: =IFERROR(VLOOKUP(H38,[1]SEMIELABORADOS!$A$2:$M$6000,6,0),"") | E38: =IFERROR(VLOOKUP(H38,[1]SEMIELABORADOS!$A$2:$M$65536,10,0),"") | F38: =IFERROR(E38*C38,"") | G38: =IFERROR(F38/$F$66,"")
A39: =+A21 -> 0 | B39: =IFERROR(VLOOKUP(H39,[1]SEMIELABORADOS!$A$2:$M$6000,2,0),"") | C39: =+A39 -> 0 | D39: =IFERROR(VLOOKUP(H39,[1]SEMIELABORADOS!$A$2:$M$6000,6,0),"") | E39: =IFERROR(VLOOKUP(H39,[1]SEMIELABORADOS!$A$2:$M$65536,10,0),"") | F39: =IFERROR(E39*C39,"") | G39: =IFERROR(F39/$F$66,"")
A40: =+A22 -> 0 | B40: =IFERROR(VLOOKUP(H40,[1]SEMIELABORADOS!$A$2:$M$6000,2,0),"") | C40: =+A40 -> 0 | D40: =IFERROR(VLOOKUP(H40,[1]SEMIELABORADOS!$A$2:$M$6000,6,0),"") | E40: =IFERROR(VLOOKUP(H40,[1]SEMIELABORADOS!$A$2:$M$65536,10,0),"") | F40: =IFERROR(E40*C40,"") | G40: =IFERROR(F40/$F$66,"")
A41: =+A23 -> 0 | B41: =IFERROR(VLOOKUP(H41,[1]SEMIELABORADOS!$A$2:$M$6000,2,0),"") | C41: =+A41 -> 0 | D41: =IFERROR(VLOOKUP(H41,[1]SEMIELABORADOS!$A$2:$M$6000,6,0),"") | E41: =IFERROR(VLOOKUP(H41,[1]SEMIELABORADOS!$A$2:$M$65536,10,0),"") | F41: =IFERROR(E41*C41,"") | G41: =IFERROR(F41/$F$66,"")
A43: UNIDADES | B43: MODI | C43: UNIDADES | D43: UND MEDIDA | E43: COSTO UNITARIO | F43: TOTAL COSTO | G43: % PREC. DEFINIDO | H43: CODIGOS
A44: =+A35 -> 46000 | B44: BATIDO EASY VAINILLA BC | C44: =+A44 -> 46000 | D44: Gramos | E44: 0.02 | F44: =IFERROR(E44*C44,"") -> 920 | G44: =IFERROR(F44/$F$66,"") -> 0.014734913 | H44: 907000286
A45: =+A36 -> 3033 | B45: MEZCLA P/ENGRASE MOLDES KILO | C45: =+A45 -> 3033 | D45: Gramos | E45: 0.03 | F45: =IFERROR(E45*C45,"") -> 90.99 | G45: =IFERROR(F45/$F$66,"") -> 0.0014573149
...

Sheet Ensamble
C1: SERVICIOS DE PASTELERIA S.A. | H1: CÓDIGO:
C2: ESPECIFICACION DE RECETA | H2: REVISIÓN:
C3: Torta Fiestera Walmart ambiente | H3: FECHA DE APROBACIÓN:
C4: Elaborado | D4: Juan Pablo Brenes , chef
C5: Aprobado | D5: Esteban Cartin, Gte Manufactura
A6: AREA QUE PRODUCE: | D6: DECORACIÓN | G6: AREA QUE EMPACA: | I6: DECORACIÓN
A7: # Código | B7: # Codigo Netsuite | C7: Descripción del ingrediente | D7: Marca | E7: Unidad Internacional | G7: Medida alternativa | I7: Costo - Referencia
E8: Cantidad | F8: Unidad medida | G8: Cantidad | H8: Unidad medida | I8: Colones
A9: 907000287 | B9: SE00454 | C9: ROSQUETE EASY VAINILLA BC 350 G | D9: FAS | E9: 456 | F9: g | G9: 1 1/2 ud
A10: 96344 | B10: SE00032 | C10: CREMA DULCE LECHE KILO | D10: FAS | E10: 60 | F10: g | G10: 1/2 taza por capa
C12: DECORACION
A13: 95717 | B13: SE00010 | C13: CREMA CHANTILLY BLANCA (SPOON-IND) | D13: FAS | E13: 120 | F13: g
A14: 905000060 | C14: CREMA NARANJA BUCCA 20000G | D14: FAS | E14: 60 | F14: g
A15: 905000063 | B15: SE00457 | C15: Crema Chantilly Verde Electrico | D15: FAS | E15: 40 | F15: g
A16: 905000101 | B16: SE00066 | C16: CREMA CHANTILLY MORADO BARNIE KILO | D16: FAS | E16: 30 | F16: g
A17: 902000149 | B17: SE00392 | C17: CHOCOLATE RALLADO OSCURO | D17: FAS | E17: 10 | F17: g
C19: EMPAQUE
A20: 121603 | B20: EM10009 | C20: Quequera Red Base/Domo 10 | D20: Export pmt | E20: 1 | F20: ud
A21: 1952875 | B21: EM10084 | C21: Orla # 10 Bucca | E21: 1 | F21: ud
A22: 702012 | B22: EM10005 | C22: ETIQ.FECHA VENCIMIENTO | D22: Etiplast | E22: 1 | F22: ud
A23: 702069 | B23: EM10002 | C23: ETIQ.BLANCA 1 1/4 * 3/4 | D23: Cemusa | E23: 1 | F23: ud
A24: 702123 | B24: EM10011 | C24: ETIQUETA BLANCA 2 5/8X1 15/16 PRE BLANCA | D24: Etiplast | E24: 1 | F24: ud
A25: 703020 | B25: EM10248 | C25: CINTA ADHESIVA TRANSPARENTE 2*100 | D25: Mayca | E25: 60 | F25: cm
D30: Cantidad | E30: Unidad
A31: PESO TOTAL OBTENIDO | D31: 770 | E31: g | F31: Tiempo de Horneo:
A32: TIEMPO TOTAL DE PREPARACION | D32: 8 | E32: min | F32: Horno:
A33: CANTIDAD DE PORCIONES OBTENIDAS | D33: 1 | E33: ud | F33: Temperatura de Horneo:
A34: PESO DE CADA PORCIÓN | D34: 770 | E34: g | F34: Otros
A35: MERMA | D35: =SUM(E9:E17)-D31 -> 6 | E35: g
A36: PROCEDIMIENTO DE PREPARACION DE LA RECETA
A37: 1.- Partir los rosquetes por la mitad y rellenar dos capas con 1/2 taza de crema dulce de leche.
A38: 2.- Encremar con crema chantilly blanca de forma lisa.
A39: 3.- Con boquilla 2C hacer al borde un circulo de conchas con la crema naranja, luego la verde y luego la morada barnie, al centro colocar el chocolate rallado oscuro.
A40: 4.- Tapar y etiquetar
A43: CONTROL DE CAMBIOS

Sheet Crema chantilly Blanca
D1: SERVICIOS DE PASTELERIA S.A. | I1: CÓDIGO: | J1: ESP-RE-DES-036
D2: ESPECIFICACION DE RECETA | I2: REVISIÓN: | J2: 10
D3: Crema Blanca Spoon (20800g) (95717(SE00010)) | I3: FECHA DE APROBACIÓN: | J3: 44320
D4: Elaborado | E4: Javier Tong, Chef
D5: Aprobado | E5: Esteban Cartin, Gte Manufactura
A6: # Código | B6: # Código | C6: # Codigo Netsuite | D6: Descripción del ingrediente | E6: Marca | F6: Unidad Internacional | H6: Medida alternativa | J6: Costo - Referencia
F7: Cantidad | G7: Unidad medida | H7: Cantidad | I7: Unidad medida | J7: Colones
A8: ICG
A9: 310148 | B9: 310148 | C9: MP10047 | D9: BETTERCREME SUPREMO (UND:4 K) | E9: Richs | F9: 16000 | G9: g | H9: 4 galones
A10: 11400031 | B10: 11400031 | C10: MP10048 | D10: CREMA PRESTIGE GRAND (UND:4 K) | E10: Richs | F10: 4000 | G10: g | H10: 1 galones
A11: 10415 | B11: 10415 | D11: AGUA POTABLE (PLANTA) | E11: AyA | F11: 1000 | G11: g
A12: 1212410 | B12: 1212410 | C12: MP10008 | D12: PRESERVANTE 1047S (PAQ=5 KILO) | E12: Aseal | F12: 15 | G12: g
A13: 702069 | B13: 702123 | C13: EM10011 | D13: ETIQUETA BLANCA 2 5/8X1 15/16 (UND) | E13: Etiplas | F13: 1 | G13: ud
E28: Cantidad | F28: Unidad
B29: PESO TOTAL OBTENIDO | E29: =SUM(F9:F12)-E33 -> 20800 | F29: g | G29: Tiempo de Horneo:
B30: TIEMPO TOTAL DE PREPARACION | E30: 10 | F30: min | G30: Horno:
B31: CANTIDAD DE PORCIONES OBTENIDAS | E31: 1 | F31: Tanda | G31: Temperatura de Horneo:
B32: PESO DE CADA PORCIÓN | E32: =E29 -> 20800 | F32: g | G32: Otros
B33: MERMA | E33: 215 | F33: g
B34: PROCEDIMIENTO DE PREPARACION DE LA RECETA
B35: 1.- Abrir los galones de crema y verter dentro de la top cream.
B36: 2.- Disolver el preservante en el agua. Agregar a la top cream.
B37: 3.- Batir por 12 a 15 minutos. Colocar en una tina plastica, tapar.
B38: 4.- Etiquetar con nombre y fecha de vencimiento.
B39: 5.- Mantener en refrigeración.
B40: Control de Cambios
B41: 9, Actuaizacion de codigos
B42: 10, Actuaizacion de procedimiento

Sheet Crema Verde electrico
D1: SERVICIOS DE PASTELERIA S.A. | I1: CÓDIGO: | J1: ESP-RE-DES-080
D2: ESPECIFICACION DE RECETA | I2: REVISIÓN: | J2: 04
D3: Crema Verde Electrico 905000063(SE00457) | I3: FECHA DE APROBACIÓN: | J3: 24/04/2023
D4: Elaborado | E4: Javier Tong, Chef
D5: Aprobado | E5: Esteban Cartin, Gte Manufactura
B6: # Código | C6: # Codigo Netsuite | D6: Descripción del ingrediente | E6: Marca | F6: Unidad Internacional | H6: Medida alternativa | J6: Costo - Referencia
F7: Cantidad | G7: Unidad medida | H7: Cantidad | I7: Unidad medida | J7: Colones
B8: 95717 | C8: SE00010 | D8: CREMA CHANTILLY BLANCA SPOON-IND KILO | E8: FAS | F8: 10400 | G8: g
B9: 10400001 | C9: MP10152 | D9: COLORANTE GEL ELECTRIC GREEN (UD=130ml) | E9: Master Pack | F9: 100 | G9: g
B10: 10400006 | C10: MP10156 | D10: COLORANTE GEL LEMON YELLOW UND 130 ML | E10: Master Pack | F10: 100 | G10: g
E12: Cantidad | F12: Unidad
B13: PESO TOTAL OBTENIDO | E13: 10400 | F13: g | G13: Tiempo de Horneo:
B14: TIEMPO TOTAL DE PREPARACION | E14: 2 | F14: Minutos | G14: Horno:
B15: CANTIDAD DE PORCIONES OBTENIDAS | E15: 1 | F15: Tanda | G15: Temperatura de Horneo:
B16: PESO DE CADA PORCIÓN | E16: =E13 -> 10400 | F16: g | G16: Otros
B17: MERMA | E17: =SUM(F8:F10)-E13 -> 200 | F17: g
B18: PROCEDIMIENTO DE PREPARACION DE LA RECETA
B19: 1, Mezclar la crema con los colorantes, hatsa homogeneo
B20: 2.- Mantener en refrigeración.
B25: CONTROL DE CAMBIOS
B26: 2: Se agrega el codigo del producto.
B27: 3: Actualizacion de colorantes y codigos y cantidades.
B28: 4: Se Elimina la crema supremo, la crema prestige, el preservante, el agua. Se agrega el subproducto crema chantilly Spoon

Sheet Crema Naranja Bucca
C1: SERVICIOS DE PASTELERIA S.A. | H1: CÓDIGO: | I1: ESP-RE-DES-060
C2: ESPECIFICACION DE RECETA | H2: REVISIÓN: | I2: 07
C3: ESP-RE-DES-060 Crema naranja Bucca 905000060 SE00401 | H3: FECHA DE APROBACIÓN: | I3: 45268
C4: Elaborado | D4: Juan Pablo Brenes, Chef
C5: Aprobado | D5: Esteban Cartin. Gte de Manufactura
A6: # Código | B6: # Código | C6: Descripción del ingrediente | D6: Marca | E6: Unidad Internacional | G6: Medida alternativa | I6: Costo - Referencia
E7: Cantidad | F7: Unidad medida | G7: Cantidad | H7: Unidad medida | I7: Colones
A9: 0310148 | B9: MP10047 | C9: BETTERCREME SUPREMO 4K | D9: Rich´s | E9: 8000 | F9: g | G9: 2 Galones
A10: 11400031 | B10: MP10048 | C10: CREMA PRESTIGE GRAND 4 KILOS | D10: Rich´s | E10: 12000 | F10: g | G10: 3 Galones
A11: 99999 | C11: AGUA | D11: AyA | E11: 100 | F11: g
A12: 1212410 | B12: MP10008 | C12: PRESERVANTE 1047S KILO | D12: Aseal | E12: 15 | F12: g
A13: 10400007 | B13: MP10153 | C13: COLORANTE GEL ELECTRIC ORANGE (UND=4.5 OZ) | D13: American Colors | E13: 35 | F13: g
A15: 0702012 | B15: EM10005 | C15: ETIQ.FECHA VENCIMIENTO VERDE | D15: Etiplast | E15: 1 | F15: ud
D19: Cantidad | E19: Unidad
A20: PESO TOTAL OBTENIDO | D20: =SUM(E9:E13)-D24 -> 19925 | E20: g | F20: Tiempo de Horneo:
A21: TIEMPO TOTAL DE PREPARACION | D21: 8 | E21: min | F21: Horno:
A22: CANTIDAD DE PORCIONES OBTENIDAS | D22: 1 | E22: tanda | F22: Temperatura de Horneo:
A23: PESO DE CADA PORCIÓN | D23: =D20 -> 19925 | E23: g | F23: Otros
A24: MERMA | D24: 225 | E24: g
A25: PROCEDIMIENTO DE PREPARACION DE LA RECETA
A26: 1.- Colocar todos los ingredientes (preservante disuelto con agua) en la top cream, Batir por 10 a 12 minutos, hasta que se obtenga la consistencia deseada.
A27: 2.- Colocar en una tina, etiquetar con fecha de producción.
A29: CONTROL DE CAMBIOS
A30: Revisión #6: Actualización de codigo interno.
A31: Revision #7 : Codigos Netsuite

Sheet Premezcla Batido Vainilla Dawn
C1: SERVICIOS DE PASTELERIA S.A. | H1: CÓDIGO: | I1: ESP-RE-PRES-132
C2: ESPECIFICACION DE RECETA | H2: REVISIÓN: | I2: 02
C3: 906000138(SE00443) Premezcla Batido Nucleo Vainilla Dawn | H3: FECHA DE APROBACIÓN: | I3: 45187
C4: Elaborado | D4: Javier Tong, chef
C5: Aprobado | D5: Esteban Cartin, Gte Manufactura
A7: AREA QUE PRODUCE: | D7: Premezcla | G7: AREA QUE EMPACA: | I7: Premezcla
A8: # Código | B8: # Codigo Netsuite | C8: Descripción del ingrediente | D8: Marca | E8: Unidad Internacional | G8: Medida alternativa | I8: Costo - Referencia
E9: Cantidad | F9: Unidad medida | G9: Cantidad | H9: Unidad medida | I9: Colones
A10: 510301 | B10: MP10074 | C10: AZUCAR BLANCO INDUSTRIAL (SACO:50 K) | D10: LAICA | E10: 5820 | F10: g | G10: =E10/13.547 -> 429.61541
A11: 11200072 | B11: MP10478 | C11: HARINA SILVER CAKE | D11: FAHACASA | E11: 3622 | F11: g | G11: =E11/13.547 -> 267.36547
A12: 11200087 | B12: MP10493 | C12: COCENTRADO VAINILLA DAWN | D12: DAWN | E12: 3492 | F12: g | G12: =E12/13.547 -> 257.76925
A13: 1160001 | B13: MP10481 | C13: GOMA XANTANA | D13: MABAKER & CHEF | E13: 60 | F13: g | G13: =E13/13.547 -> 4.4290249
A14: 1212410 | B14: MP10008 | C14: PRESERVANTE 1047S (PAQ=5 KILO) | D14: ASEAL | E14: 38 | F14: g | G14: =E14/13.547 -> 2.8050491
A15: 10100337 | B15: MP10494 | C15: CMC | D15: UNIVERSAL DE ALIMENTOS | E15: 30 | F15: g | G15: =E15/13.547 -> 2.2145124
A16: 310145 | B16: MP10234 | C16: LECHE POLVO INDUSTRIAL (SACO:25 KG) | D16: DOS PINOS | E16: 518 | F16: g | G16: =E16/13.547 -> 38.237248
A17: 503000036 | B17: MP10085 | C17: BICARBONATO DE SODIO (PAQ:2.5 K) | E17: 65 | F17: g | G17: =E17/13.547 -> 4.7981103
G18: =E18/13.547 -> 0
A19: 1950708 | B19: EM10013 | C19: BOLSA 17x25 TRANSP KILO | E19: 2 | F19: ud | G19: =E19/13.547 -> 0.14763416
A20: 60100010 | B20: EM10133 | C20: ETIQUETA ROJA LETRA ALERJENO (UND) | E20: 2 | F20: ud | G20: =E20/13.547 -> 0.14763416
A21: 702123 | B21: EM10011 | C21: ETIQUETA BLANCA 2 5/8X1 15/16 (UND) | E21: 2 | F21: ud | G21: =E21/13.547 -> 0.14763416
A22: 1950705 | B22: EM10037 | C22: BOLSA 8x12 TRANSPARENTE KILO | E22: 1 | F22: ud | G22: =E22/13.547 -> 0.073817081
G25: 24000 | H25: =+E12/G25 -> 0.1455
D27: Cantidad | E27: Unidad
A28: PESO TOTAL OBTENIDO | D28: =SUM(E10:E16) -> 13580 | E28: g
A29: TIEMPO TOTAL DE PREPARACION | D29: 3 | E29: min
A30: CANTIDAD DE PORCIONES OBTENIDAS | D30: 1 | E30: ud
A31: PESO DE CADA PORCIÓN | D31: =+D28 -> 13580 | E31: g
A32: MERMA | D32: 0 | E32: g
A33: PROCEDIMIENTO DE PREPARACION DE LA RECETA
A34: 1, En una bolsa 17x25 empacar el azucar. Etiquetar
A35: 2, En una bolsa 17x25 empacar las harinas, concentrado,cmc, leche en polvo y la goma. Etiquetar
A36: 3, En una bolsa 8*12 pesar el preservante y el bicarbonato (se debe pesar justo antes de su uso)
A43: Control de cambios
A44: Revision #2: Ajuste en la cantidad de goma xantana y cmc

Sheet Batido Vainilla Easy Dawn
C1: SERVICIOS DE PASTELERIA S.A. | H1: CÓDIGO: | I1: ESP-RE-BAS-169
C2: ESPECIFICACION DE RECETA | H2: REVISIÓN: | I2: 02
C3: 907000306(SE00444) Batido Nucleo vainilla Dawn | H3: FECHA DE APROBACIÓN: | I3: 27/01/2023
C4: Elaborado | D4: Javier Tong, chef
C5: Aprobado | D5: Esteban Cartin, Gte Manufactura
A7: AREA QUE PRODUCE: | D7: Batidos | G7: AREA QUE EMPACA: | I7: Batidos
A8: # Código | B8: # Codigo Netsuite | C8: Descripción del ingrediente | D8: Marca | E8: Unidad Internacional | G8: Medida alternativa | I8: Costo - Referencia
E9: Cantidad | F9: Unidad medida | H9: Unidad medida | I9: Colones
A10: 906000138 | B10: SE00443 | C10: PREMEZCLA BATIDO NUCLEO VAINILLA DAWN | D10: FAS | E10: 13547 | F10: g | G10: =E10/24 -> 564.45833 | H10: =E10/24 -> 564.45833
A11: 1210482 | B11: MP10005 | C11: HUEVO ENTERO PASTERI INNOVO ( CAJA: 10 K) | D11: INNOVO | E11: 9055 | F11: g | G11: =E11/24 -> 377.29167 | H11: =E11/24 -> 377.29167
A12: 10415 | C12: AGUA POTABLE (PLANTA) | D12: FAS | E12: 1940 | F12: g | G12: =E12/24 -> 80.833333 | H12: =E12/24 -> 80.833333
A13: 1212437 | B13: MP10315 | C13: PRESERVANTE MIXTO (UND:17 K) | D13: PURATOS | E13: 855 | F13: g | G13: =E13/24 -> 35.625 | H13: =E13/24 -> 35.625
G14: =E14/24 -> 0 | H14: =E14/24 -> 0
D25: Cantidad | E25: Unidad
A26: PESO TOTAL OBTENIDO | D26: 24000 | E26: g
A27: TIEMPO TOTAL DE PREPARACION | D27: 10 | E27: min
A28: CANTIDAD DE PORCIONES OBTENIDAS | D28: 1 | E28: Tanda
A29: PESO DE CADA PORCIÓN | D29: =+D26 -> 24000 | E29: g
A30: MERMA | D30: =SUM(E10:E13)-D26 -> 1397 | E30: g
A31: PROCEDIMIENTO DE PREPARACION DE LA RECETA
A32: 1, Disolver el preservante y el polvo de hornear con el agua y ayuda de un batidor de mano.
A33: 2, Colocar los liquidos en la batidora, posterior agregar los ingredientes secos
A34: 3, Batir por 1 min en velocidad 1. Con paleta
A35: 4, Batir 7 min en velocidad 3. con globo
A41: Control de cambios
A42: 2, Se reduce la cantidad de Mixo.

Sheet Rosquete Easy 320
C1: SERVICIOS DE PASTELERIA S.A. | H1: CÓDIGO: | I1: ESP-RE-BAS-178
C2: ESPECIFICACION DE RECETA | H2: REVISIÓN: | I2: 02
C3: 907000310(SE00448) Rosquete nucleo vainilla Dawn Redondo 320g | H3: FECHA DE APROBACIÓN: | I3: 23/03/2023
C4: Elaborado | D4: Javier Tong, Chef
C5: Aprobado | D5: Esteban Cartín. Gte de Manufactura
A6: # Código | B6: # Codigo Netsuite | C6: Descripción del ingrediente | D6: Marca | E6: Unidad Internacional | G6: Medida alternativa | I6: Costo - Referencia
E7: Cantidad | F7: Unidad medida | G7: Cantidad | H7: Unidad medida | I7: Colones
A8: 907000306 | B8: SE00444 | C8: BATIDO NUCLEO VAINILLA DAWN | D8: FAS | E8: 24000 | F8: g | G8: =E8/23.36 -> 1027.3973
G9: =E9/23.36 -> 0
C10: EMPAQUE | G10: =E10/23.36 -> 0
A11: 902000019 | C11: MEZCLA P/ENGRASE MOLDES KILO | D11: FAS | E11: =10*D21 -> 730 | F11: g | G11: =E11/23.36 -> 31.25
A12: 1950928 | B12: AS00028 | C12: BOLSA TRANSPARENTE 56X96X1.80 KILO | D12: Plasticos P | E12: 6 | F12: ud | G12: =E12/23.36 -> 0.25684932
A13: 0702007 | B13: EM10004 | C13: ETIQ.FECHA VENCIMIENTO BLANCO (ROLLO) | D13: Etiplast | E13: 6 | F13: ud | G13: =E13/23.36 -> 0.25684932
A14: 0702069 | B14: EM10002 | C14: ETIQ.BLANCA 1 1/4 * 3/4 (UND) | D14: Cemusa | E14: 6 | F14: ud | G14: =E14/23.36 -> 0.25684932
D18: Cantidad | E18: Unidad
A19: PESO TOTAL OBTENIDO | D19: =73*320 -> 23360 | E19: g | F19: Tiempo de Horneo:
A20: TIEMPO TOTAL DE PREPARACION | D20: 15 | E20: Min | F20: Horno:
A21: CANTIDAD DE PORCIONES OBTENIDAS | D21: =+D19/D22 -> 73 | E21: ud | F21: Temperatura de Horneo:
A22: PESO DE CADA PORCIÓN | D22: 320 | E22: g | F22: Otros
A23: MERMA | D23: =+E8-D19 -> 640 | E23: g
A24: PROCEDIMIENTO DE PREPARACION DE LA RECETA
A25: 1.- Pesar 320g de mezcla en los moldes previamente engrasados.
A26: 2.- Hornear por Dicte 1 o 2 a 175°C por 50 min
A27: 3.- Enfriar, desmoldar, colocar 12 rosquetes por lata, etiquetar con nombre y fecha de producción.
A29: Control de cambios
A30: 2, Cambio de horneo

Sheet Procesado de Borona 
C1: SERVICIOS DE PASTELERIA S.A. | H1: CÓDIGO: | I1: ESP-RE-DES-032
C2: ESPECIFICACION DE RECETA | H2: REVISIÓN: | I2: 02
C3: Procesado de Borona (1206g) 910000011(SE00071) | H3: FECHA DE APROBACIÓN: | I3: 44109
C4: Elaborado | D4: Javier Tong, Chef
C5: Aprobado | D5: Esteban Cartin, Gte Manufactura
A6: AREA QUE PRODUCE: | D6: DECORACIÓN | G6: AREA QUE EMPACA: | I6: DECORACIÓN
A7: # Código | B7: # Codigo Netsuite | C7: Descripción del ingrediente | D7: Marca | E7: Unidad Internacional | G7: Medida alternativa | I7: Costo - Referencia
E8: Cantidad | F8: Unidad medida | G8: Cantidad | H8: Unidad medida | I8: Colones
A10: 907000310 | B10: SE00448 | C10: Rosquete Vainilla Dawn 320g | D10: FAS | E10: 1500 | F10: g
A12: 512000003 | B12: EM10252 | C12: Plástico Autoaderible 1/ 12*2000 | D12: BELCA | E12: 40 | F12: cm
A13: 702123 | B13: EM10011 | C13: ETIQUETA BLANCA 2 5/8X1 15/16 (UND) | D13: CEMUSA | E13: 1 | F13: ud
A14: 702007 | B14: EM10004 | C14: ETIQ.FECHA VENCIMIENTO BLANCO (ROLLO) | D14: CEMUSA | E14: 1 | F14: ud
D17: Cantidad | E17: Unidad
A18: PESO TOTAL OBTENIDO | D18: 1206 | E18: g | F18: Tiempo de Horneo: | H18: 25 min | I18: 20 min
A19: TIEMPO TOTAL DE PREPARACION | D19: 7 | E19: min | F19: Horno: | H19: Marshall | I19: Vulcan
A20: CANTIDAD DE PORCIONES OBTENIDAS | D20: 1 | E20: tanda | F20: Temperatura de Horneo: | H20: 175°C | I20: 300°F
A21: PESO DE CADA PORCIÓN | D21: =D18/D20 -> 1206 | E21: g | F21: Otros
A22: MERMA | D22: =E10-D21 -> 294 | E22: g
A23: PROCEDIMIENTO DE PREPARACION DE LA RECETA
A24: 1-. Colocar los rosquetes en una bandeja limpia, en pedazos y bien separados unos de otros
A25: 2-. Hornear por 25 minutos a 175°C en el Marshall o 20 minutos a 300°F en el Vulcan. Sacar y enfriar
A26: 3-. Colocar el producto en el procesador y procesar por impulsos hasta formar la borona o deshacer el rosquete
A27: 4-. Colocar en baldes sellados y sanitizados. No procesar grandes cantidades para evitar la formación de moho
A31: CONTROL DE CAMBIOS
A32: Versión #02 : Se actualiza formato, receta, tiempos y temperaturas de horneos
A33: Version #3: Se cambian los rosquetes.

Sheet Crema Chantilly Morado Barnie
C1: SERVICIOS DE PASTELERIA S.A. | H1: CÓDIGO: | I1: ESP-RE-DEF-077
C2: ESPECIFICACION DE RECETA | H2: REVISIÓN: | I2: 04
C3: 905000101(SE00066) Crema Chantilly Morado Barnie | H3: FECHA DE APROBACIÓN: | I3: 24/04/2023
C4: Elaborado | D4: Javier Tong, Chef
C5: Aprobado | D5: Esteban Cartin, Gte Manufactura
A6: AREA QUE PRODUCE: | D6: Decoracion | G6: AREA QUE EMPACA: | I6: Decoracion
A7: # Código | B7: # Codigo Netsuite | C7: Descripción del ingrediente | D7: Marca | E7: Unidad Internacional | G7: Medida alternativa | I7: Costo - Referencia
E8: Cantidad | F8: Unidad medida | G8: Cantidad | H8: Unidad medida | I8: Colones
A9: 95717 | B9: SE00010 | C9: CREMA CHANTILLY BLANCA SPOON-IND KILO | D9: FAS | E9: 20800 | F9: g | G9: =E9/20.8 -> 1000
A10: 10400002 | B10: MP10155 | C10: COLORANTE EXOTIC PURPLE | D10: Master Pack | E10: 80 | F10: g | G10: =E10/20.8 -> 3.8461538
A11: 10400011 | B11: MP10149 | C11: COLORANTE ARTIFICIAL ROSADO F225 (LITRO) | D11: Azteck | E11: 200 | F11: g | G11: =E11/20.8 -> 9.6153846
A12: 0702123 | B12: EM10011 | C12: ETIQUETA BLANCA 2 5/8X1 15/16 (UND) | D12: Etiplas | E12: 1 | F12: ud | G12: =E12/20.8 -> 0.048076923
G13: =E13/20.8 -> 0
D15: Cantidad | E15: Unidad
A16: PESO TOTAL OBTENIDO | D16: 20800 | E16: g | F16: Tiempo de Horneo:
A17: TIEMPO TOTAL DE PREPARACION | D17: 2 | E17: min | F17: Horno:
A18: CANTIDAD DE PORCIONES OBTENIDAS | D18: 1 | E18: Tanda | F18: Temperatura de Horneo:
A19: PESO DE CADA PORCIÓN | D19: =D16 -> 20800 | E19: g | F19: Otros
A20: MERMA | D20: =SUM(E9:E12)-D16 -> 281 | E20: g
A21: PROCEDIMIENTO DE PREPARACION DE LA RECETA
A22: 1, Mezclar la crema con los colorantes, hatsa homogeneo
A23: 2.- Mantener en refrigeración.
A25: Control de cambios
A26: 2, Se cambia el colorante rosado y se aumenta cantidad
A27: 3: Se aumenta el colorante rosado.
A28: 4: Se Elimina la crema supremo, la crema prestige, el preservante, el agua. Se agrega el subproducto crema chantilly Spoon

Sheet Crema Dulce de leche
C1: SERVICIOS DE PASTELERIA S.A. | H1: CÓDIGO: | I1: ESP-RE-DES-040
C2: ESPECIFICACION DE RECETA | H2: REVISIÓN: | I2: 04
C3: Crema de Dulce de Leche(24500g) 96344(SE00032) | H3: FECHA DE APROBACIÓN: | I3: 44096
C4: Elaborado | D4: Javier Tong, Chef
C5: Aprobado | D5: Jeffry Rodriguez, Gerente de Manufactura
A6: AREA QUE PRODUCE: | D6: Decoracion | G6: AREA QUE EMPACA: | I6: Decoracion
A7: # Código | B7: # Codigo Netsuite | C7: Descripción del ingrediente | D7: Marca | E7: Unidad Internacional | G7: Medida alternativa | I7: Costo - Referencia
E8: Cantidad | F8: Unidad medida | G8: Cantidad | H8: Unidad medida | I8: Colones
A9: 11400029 | B9: MP10165 | C9: CREMA BETTER DULCE LECHE RICH (UND:4 K) | D9: Rich | E9: 16000 | F9: g | G9: 4 Galones
A10: 11400031 | B10: MP10048 | C10: CREMA PRESTIGE GRAND (UND:4 K) | D10: Rich | E10: 8000 | F10: g | G10: 2 Galones
A11: 10415 | C11: AGUA POTABLE (PLANTA) | D11: Spoon | E11: 1000 | F11: g
A12: 1212410 | B12: MP10008 | C12: PRESERVANTE 1047S (PAQ=5 KILO) | D12: Aseal | E12: 22 | F12: g
A13: 702123 | B13: EM10011 | C13: ETIQUETA BLANCA 2 5/8X1 15/16 (UND) | E13: 1 | F13: ud
D15: Cantidad | E15: Unidad
A16: PESO TOTAL OBTENIDO | D16: 24500 | E16: g | F16: Tiempo de Horneo:
A17: TIEMPO TOTAL DE PREPARACION | D17: 5 | E17: min | F17: Horno:
A18: CANTIDAD DE PORCIONES OBTENIDAS | D18: 1 | E18: ud | F18: Temperatura de Horneo:
A19: PESO DE CADA PORCIÓN | D19: =D16 -> 24500 | E19: g | F19: Otros
A20: MERMA | D20: 500 | E20: g
A21: PROCEDIMIENTO DE PREPARACION DE LA RECETA
A22: 1.- Colocar la crema de dulce de leche y la prestige en la top cream con el agua y preservante.
A23: 2.- Batir por 12 minutos, mantener en refrigeracin a 5°C.
A26: Control de cambios
A27: 4, Actualizacion de codigos

Sheet Hoja1

Sheet Ensamble 2
C1: SERVICIOS DE PASTELERIA S.A. | H1: CÓDIGO:
C2: ESPECIFICACION DE RECETA | H2: REVISIÓN:
C3: PTI00216 Torta Fiestera Walmart ambiente | H3: FECHA DE APROBACIÓN:
C4: Elaborado | D4: Juan Pablo Brenes , chef
C5: Aprobado | D5: Esteban Cartin, Gte Manufactura
A6: AREA QUE PRODUCE: | D6: DECORACIÓN | G6: AREA QUE EMPACA: | I6: DECORACIÓN
A7: # Código | B7: # Codigo Netsuite | C7: Descripción del ingrediente | D7: Marca | E7: Unidad Internacional | G7: Medida alternativa | I7: Costo - Referencia
E8: Cantidad | F8: Unidad medida | G8: Cantidad | H8: Unidad medida | I8: Colones
A9: NUEVO | B9: SE00624 | C9: Rosquete easy vainilla BC 300g | D9: FAS | E9: 410 | F9: g | G9: 1 1/2 ud
A10: 96344 | B10: SE00032 | C10: CREMA DULCE LECHE KILO | D10: FAS | E10: 60 | F10: g | G10: 1/2 taza por capa
C12: DECORACION
A13: 95717 | B13: SE00010 | C13: CREMA CHANTILLY BLANCA (SPOON-IND) | D13: FAS | E13: 120 | F13: g
A14: 905000060 | B14: SE00401 | C14: CREMA NARANJA BUCCA 20000G | D14: FAS | E14: 60 | F14: g
A15: 905000063 | B15: SE00457 | C15: Crema Chantilly Verde Electrico | D15: FAS | E15: 40 | F15: g
A16: 905000101 | B16: SE00066 | C16: CREMA CHANTILLY MORADO BARNIE KILO | D16: FAS | E16: 30 | F16: g
A17: 910000011 | B17: SE00071 | C17: Borona P/Decorar | D17: FAS | E17: 5 | F17: g
C19: EMPAQUE
A20: 121603 | B20: EM10009 | C20: Quequera Red Base/Domo 10 | D20: Export pmt | E20: 1 | F20: ud
A21: 702012 | B21: EM10005 | C21: ETIQ.FECHA VENCIMIENTO | D21: Etiplast | E21: 1 | F21: ud
A22: 702069 | B22: EM10002 | C22: ETIQ.BLANCA 1 1/4 * 3/4 | D22: Cemusa | E22: 1 | F22: ud
A23: 702123 | B23: EM10011 | C23: ETIQUETA BLANCA 2 5/8X1 15/16 PRE BLANCA | D23: Etiplast | E23: 1 | F23: ud
A24: 703020 | B24: EM10248 | C24: CINTA ADHESIVA TRANSPARENTE 2*100 | D24: Mayca | E24: 60 | F24: cm
D29: Cantidad | E29: Unidad
A30: PESO TOTAL OBTENIDO | D30: 720 | E30: g | F30: Tiempo de Horneo:
A31: TIEMPO TOTAL DE PREPARACION | D31: 8 | E31: min | F31: Horno:
A32: CANTIDAD DE PORCIONES OBTENIDAS | D32: 1 | E32: ud | F32: Temperatura de Horneo:
A33: PESO DE CADA PORCIÓN | D33: 720 | E33: g | F33: Otros
A34: MERMA | D34: =SUM(E9:E17)-D30 -> 5 | E34: g
A35: PROCEDIMIENTO DE PREPARACION DE LA RECETA
A36: 1.- Partir los rosquetes por la mitad y rellenar dos capas con 1/2 taza de crema dulce de leche.
A37: 2.- Encremar con crema chantilly blanca de forma lisa.
A38: 3.- Con boquilla 2C hacer al borde un circulo de conchas con la crema naranja, luego la verde y luego la morada barnie, al centro colocar el chocolate rallado oscuro.
A39: 4.- Tapar y etiquetar
A42: CONTROL DE CAMBIOS

Sheet Ensamble 3
C1: SERVICIOS DE PASTELERIA S.A. | H1: CÓDIGO: | I1: ESP-RE-DEF-107
C2: ESPECIFICACION DE RECETA | H2: REVISIÓN: | I2: 3
C3: PTI00216 Torta Fiestera Walmart ambiente | H3: FECHA DE APROBACIÓN: | I3: 45534
C4: Elaborado | D4: Nathalie Hume , chef
C5: Aprobado | D5: Esteban Cartin, Gte Manufactura
A6: AREA QUE PRODUCE: | D6: DECORACIÓN | G6: AREA QUE EMPACA: | I6: DECORACIÓN
A7: # Código | B7: # Codigo Netsuite | C7: Descripción del ingrediente | D7: Marca | E7: Unidad Internacional | G7: Medida alternativa | I7: Costo - Referencia
E8: Cantidad | F8: Unidad medida | G8: Cantidad | H8: Unidad medida | I8: Colones
A9: NUEVO | B9: SE00624 | C9: Rosquete easy vainilla BC 300g | D9: FAS | E9: 410 | F9: g | G9: 1 1/2 ud
A10: 96344 | B10: SE00032 | C10: CREMA DULCE LECHE KILO | D10: FAS | E10: 120 | F10: g | G10: 3/4 taza por capa
C12: DECORACION
A13: 95717 | B13: SE00010 | C13: CREMA CHANTILLY BLANCA (SPOON-IND) | D13: FAS | E13: 120 | F13: g
B14: SE00639 | C14: CREMA CHANTILLY AMARILLA BUCCA | D14: FAS | E14: 5 | F14: g | G14: marmoleado
B15: SE00640 | C15: CREMA CHANTILLY AMARILLA BUCCA | D15: FAS | E15: 70 | F15: g | G15: Boquilla 2c
A16: 905000063 | B16: SE00457 | C16: Crema Chantilly Verde Electrico | D16: FAS | E16: 40 | F16: g | G16: Boquilla 2c
A17: 905000101 | B17: SE00066 | C17: CREMA CHANTILLY MORADO BARNIE KILO | D17: FAS | E17: 30 | F17: g | G17: Boquilla 2c
A18: 910000011 | B18: SE00071 | C18: Borona P/Decorar | D18: FAS | E18: 5 | F18: g | G18: 1 cucharada
C20: EMPAQUE
A21: 121603 | B21: EM10009 | C21: Quequera Red Base/Domo 10 | D21: Export pmt | E21: 1 | F21: ud
B22: EM10084 | C22: Orla # 10 Bucca | E22: 1 | F22: ud
A23: 702012 | B23: EM10005 | C23: ETIQ.FECHA VENCIMIENTO | D23: Etiplast | E23: 1 | F23: ud
A24: 702069 | B24: EM10002 | C24: ETIQ.BLANCA 1 1/4 * 3/4 | D24: Cemusa | E24: 1 | F24: ud
A25: 702123 | B25: EM10011 | C25: ETIQUETA BLANCA 2 5/8X1 15/16 PRE BLANCA | D25: Etiplast | E25: 1 | F25: ud
A26: 703020 | B26: EM10248 | C26: CINTA ADHESIVA TRANSPARENTE 2*100 | D26: Mayca | E26: 60 | F26: cm
D31: Cantidad | E31: Unidad
A32: PESO TOTAL OBTENIDO | D32: 780 | E32: g | F32: Tiempo de Horneo:
A33: TIEMPO TOTAL DE PREPARACION | D33: 8 | E33: min | F33: Horno:
A34: CANTIDAD DE PORCIONES OBTENIDAS | D34: 1 | E34: ud | F34: Temperatura de Horneo:
A35: PESO DE CADA PORCIÓN | D35: 780 | E35: g | F35: Otros
A36: MERMA | D36: =SUM(E9:E18)-D32 -> 20 | E36: g
A37: PROCEDIMIENTO DE PREPARACION DE LA RECETA
A38: 1.- Partir los rosquetes por la mitad y rellenar dos capas con 3/4 taza de crema dulce de leche.
A39: 2.- Encremar con crema chantilly blanca de forma lisa.
A40: 3.- Con boquilla 2C hacer al borde un circulo de conchas con la crema amarilla, luego la verde y luego la morada barnie, al centro colocar la borona de queque.
A41: 4.- Tapar y etiquetar
A44: CONTROL DE CAMBIOS
A45: Revicion 2- Actualizacion post corrida.
A46: Revision #3: Se agrega orla azul
A47: Revision #4: Reingenieria de torta, se cambia el color naranja a amarillo y se aumenta relleno.

Sheet Costo Ensamble 
E1: Precio Local | F1: Costo MP | G1: Costo EM | H1: Costo MO
E2: =IFERROR(O62,"") -> 2879.4514 | F2: =IFERROR(H53,"") -> 1541.0817 | G2: =IFERROR(H54,"") -> 293.05171 | H2: =IFERROR(H56,"") -> 535.83525
A5: ESTRUCTURA DE COSTOS
F6: Fecha: | H6: =TODAY() -> 46149
A7: UNIDADES | B7: DESCRIPCION MAT.PRIMA | C7: UNIDADES | D7: UND MEDIDA | E7: COSTO UNITARIO | F7: TOTAL COSTO | G7: % PREC. DEFINIDO | H7: CODIGOS
B8: =IFERROR(VLOOKUP(H8,'[1]Consolidado MP Planta'!$A$2:$M$823,3,0),"") | C8: =+A8 -> 0 | D8: =IFERROR(VLOOKUP(H8,'[1]Consolidado MP Planta'!$A$2:$M$823,13,0),"") | E8: =IFERROR(VLOOKUP(H8,'[1]Consolidado MP Planta'!$A$2:$M$823,12,0),"") | F8: =IFERROR(C8*E8,"") | G8: =IFERROR(F8/$F$66,"")
B9: =IFERROR(VLOOKUP(H9,'[1]Consolidado MP Planta'!$A$2:$M$823,3,0),"") | C9: =+A9 -> 0 | D9: =IFERROR(VLOOKUP(H9,'[1]Consolidado MP Planta'!$A$2:$M$823,13,0),"") | E9: =IFERROR(VLOOKUP(H9,'[1]Consolidado MP Planta'!$A$2:$M$823,12,0),"") | F9: =IFERROR(C9*E9,"") | G9: =IFERROR(F9/$F$66,"")
B10: =IFERROR(VLOOKUP(H10,'[1]Consolidado MP Planta'!$A$2:$M$823,3,0),"") | C10: =+A10 -> 0 | D10: =IFERROR(VLOOKUP(H10,'[1]Consolidado MP Planta'!$A$2:$M$823,13,0),"") | E10: =IFERROR(VLOOKUP(H10,'[1]Consolidado MP Planta'!$A$2:$M$823,12,0),"") | F10: =IFERROR(C10*E10,"") | G10: =IFERROR(F10/$F$66,"")
B11: =IFERROR(VLOOKUP(H11,'[1]Consolidado MP Planta'!$A$2:$M$823,3,0),"") | C11: =+A11 -> 0 | D11: =IFERROR(VLOOKUP(H11,'[1]Consolidado MP Planta'!$A$2:$M$823,13,0),"") | E11: =IFERROR(VLOOKUP(H11,'[1]Consolidado MP Planta'!$A$2:$M$823,12,0),"") | F11: =IFERROR(C11*E11,"") | G11: =IFERROR(F11/$F$66,"")
B12: =IFERROR(VLOOKUP(H12,'[1]Consolidado MP Planta'!$A$2:$M$823,3,0),"") | C12: =+A12 -> 0 | D12: =IFERROR(VLOOKUP(H12,'[1]Consolidado MP Planta'!$A$2:$M$823,13,0),"") | E12: =IFERROR(VLOOKUP(H12,'[1]Consolidado MP Planta'!$A$2:$M$823,12,0),"") | F12: =IFERROR(C12*E12,"") | G12: =IFERROR(F12/$F$66,"")
B13: =IFERROR(VLOOKUP(H13,'[1]Consolidado MP Planta'!$A$2:$M$823,3,0),"") | C13: =+A13 -> 0 | D13: =IFERROR(VLOOKUP(H13,'[1]Consolidado MP Planta'!$A$2:$M$823,13,0),"") | E13: =IFERROR(VLOOKUP(H13,'[1]Consolidado MP Planta'!$A$2:$M$823,12,0),"") | F13: =IFERROR(C13*E13,"") | G13: =IFERROR(F13/$F$66,"")
B14: =IFERROR(VLOOKUP(H14,'[1]Consolidado MP Planta'!$A$2:$M$823,3,0),"") | C14: =+A14 -> 0 | D14: =IFERROR(VLOOKUP(H14,'[1]Consolidado MP Planta'!$A$2:$M$823,13,0),"") | E14: =IFERROR(VLOOKUP(H14,'[1]Consolidado MP Planta'!$A$2:$M$823,12,0),"") | F14: =IFERROR(C14*E14,"") | G14: =IFERROR(F14/$F$66,"")
B15: =IFERROR(VLOOKUP(H15,'[2]ARTICULOS MP PLANTA'!$A$2:$G$589,2,0),"")
A16: UNIDADES | B16: MATERIA PRIMA SEMIELABORADOS | C16: UNIDADES | D16: UND MEDIDA | E16: COSTO UNITARIO | F16: TOTAL COSTO | G16: % PREC. DEFINIDO | H16: CODIGOS
A17: 1.5 | B17: Rosquete easy vainilla BC 300g | C17: =+A17 -> 1.5 | D17: UND | E17: =+'Costo Rosquete 300 g'!H53 -> 380.48782 | F17: =IFERROR(E17*C17,"") -> 570.73174 | G17: =IFERROR(F17/$F$66,"") -> 0.25582395 | H17: NUEVO
A18: 120 | B18: =IFERROR(VLOOKUP(H18,[1]SEMIELABORADOS!$A$2:$M$6000,2,0),"") -> CREMA DULCE LECHE KILO | C18: =+A18 -> 120 | D18: =IFERROR(VLOOKUP(H18,[1]SEMIELABORADOS!$A$2:$M$6000,6,0),"") -> Gramo | E18: 2.68 | F18: =IFERROR(E18*C18,"") -> 321.6 | G18: =IFERROR(F18/$F$66,"") -> 0.14415351 | H18: 96344
A19: 120 | B19: =IFERROR(VLOOKUP(H19,[1]SEMIELABORADOS!$A$2:$M$6000,2,0),"") -> CREMA CHANTILLY BLANCA SPOON-IND KILO | C19: =+A19 -> 120 | D19: =IFERROR(VLOOKUP(H19,[1]SEMIELABORADOS!$A$2:$M$6000,6,0),"") -> Gramo | E19: 2.31 | F19: =IFERROR(E19*C19,"") -> 277.2 | G19: =IFERROR(F19/$F$66,"") -> 0.12425172 | H19: 95717
A20: 75 | B20: CREMA CHANTILLY AMARILLA BUCCA | C20: =+A20 -> 75 | D20: Gramo | E20: 2.37 | F20: =IFERROR(E20*C20,"") -> 177.75 | G20: =IFERROR(F20/$F$66,"") -> 0.079674397 | H20: 905000060
A21: 40 | B21: Crema Chantilly Verde Electrico | C21: =+A21 -> 40 | D21: Gramo | E21: 2.69 | F21: =IFERROR(E21*C21,"") -> 107.6 | G21: =IFERROR(F21/$F$66,"") -> 0.048230465 | H21: 905000063
A22: 30 | B22: =IFERROR(VLOOKUP(H22,[1]SEMIELABORADOS!$A$2:$M$6000,2,0),"") -> CREMA CHANTILLY MORADO BARNIE KILO | C22: =+A22 -> 30 | D22: =IFERROR(VLOOKUP(H22,[1]SEMIELABORADOS!$A$2:$M$6000,6,0),"") -> Gramo | E22: 2.42 | F22: =IFERROR(E22*C22,"") -> 72.6 | G22: =IFERROR(F22/$F$66,"") -> 0.032542116 | H22: 905000101
A23: 5 | B23: Borona P/Decorar | C23: =+A23 -> 5 | D23: Gramo | E23: 2.72 | F23: =IFERROR(E23*C23,"") -> 13.6 | G23: =IFERROR(F23/$F$66,"") -> 0.0060960439 | H23: 910000011
B24: =IFERROR(VLOOKUP(H24,[1]SEMIELABORADOS!$A$2:$M$6000,2,0),"") | C24: =+A24 -> 0 | D24: =IFERROR(VLOOKUP(H24,[1]SEMIELABORADOS!$A$2:$M$6000,6,0),"") | E24: =IFERROR(VLOOKUP(H24,[1]SEMIELABORADOS!$A$2:$H$65536,8,0),"") | F24: =IFERROR(E24*C24,"") | G24: =IFERROR(F24/$F$66,"")
A26: UNIDADES | B26: EMPAQUE | C26: UNIDADES | D26: UND MEDIDA | E26: COSTO UNITARIO | F26: TOTAL COSTO | G26: % PREC. DEFINIDO | H26: CODIGOS
A27: 1 | B27: =IFERROR(VLOOKUP(H27,'[1]Consolidado MP Planta'!$A$2:$M$823,3,0),"") -> QUEQUERA RED BASE/DOMO 10 (CAJA:50) | C27: =+A27 -> 1 | D27: =IFERROR(VLOOKUP(H27,'[1]Consolidado MP Planta'!$A$2:$M$823,13,0),"") -> UND | E27: 274 | F27: =IFERROR(C27*E27,"") -> 274 | G27: =IFERROR(F27/$F$66,"") -> 0.12281735 | H27: 121603 | K27: 420.9
A28: 0 | B28: =IFERROR(VLOOKUP(H28,'[1]Consolidado MP Planta'!$A$2:$M$823,3,0),"") -> ORLA # 10 BUCCA (UND) | C28: =+A28 -> 0 | D28: UND | E28: 137 | F28: =IFERROR(C28*E28,"") -> 0 | G28: =IFERROR(F28/$F$66,"") -> 0 | H28: 1952875
A29: 1 | B29: =IFERROR(VLOOKUP(H29,'[1]Consolidado MP Planta'!$A$2:$M$823,3,0),"") -> ETIQ.FECHA VENCIMIENTO VERDE (ROLLO) | C29: =+A29 -> 1 | D29: =IFERROR(VLOOKUP(H29,'[1]Consolidado MP Planta'!$A$2:$M$823,13,0),"") -> Und | E29: 0.33 | F29: =IFERROR(C29*E29,"") -> 0.33 | G29: =IFERROR(F29/$F$66,"") -> 0.00014791871 | H29: 0702012
A30: 1 | B30: =IFERROR(VLOOKUP(H30,'[1]Consolidado MP Planta'!$A$2:$M$823,3,0),"") -> ETIQ.BLANCA 1 1/4 * 3/4 (UND) | C30: =+A30 -> 1 | D30: =IFERROR(VLOOKUP(H30,'[1]Consolidado MP Planta'!$A$2:$M$823,13,0),"") -> Und | E30: 0.58 | F30: =IFERROR(C30*E30,"") -> 0.58 | G30: =IFERROR(F30/$F$66,"") -> 0.00025997834 | H30: 0702069
A31: 1 | B31: =IFERROR(VLOOKUP(H31,'[1]Consolidado MP Planta'!$A$2:$M$823,3,0),"") -> ETIQUETA BLANCA 2 5/8X1 15/16 (UND) | C31: =+A31 -> 1 | D31: =IFERROR(VLOOKUP(H31,'[1]Consolidado MP Planta'!$A$2:$M$823,13,0),"") -> Und | E31: 2.13 | F31: =IFERROR(C31*E31,"") -> 2.13 | G31: =IFERROR(F31/$F$66,"") -> 0.00095474805 | H31: 0702123
A32: 60 | B32: =IFERROR(VLOOKUP(H32,'[1]Consolidado MP Planta'!$A$2:$M$823,3,0),"") -> CINTA ADHESIVA TRANSPARENT 2*100 M (UND) | C32: =+A32 -> 60 | D32: =IFERROR(VLOOKUP(H32,'[1]Consolidado MP Planta'!$A$2:$M$823,13,0),"") -> Cm | E32: 0.18 | F32: =IFERROR(C32*E32,"") -> 10.8 | G32: =IFERROR(F32/$F$66,"") -> 0.004840976 | H32: 703020
A34: UNIDADES | B34: EMPAQUE SEMIELABORADOS | C34: UNIDADES | D34: UND MEDIDA | E34: COSTO UNITARIO | F34: TOTAL COSTO | G34: % PREC. DEFINIDO | H34: CODIGOS
A35: =+A17 -> 1.5 | B35: Rosquete easy vainilla BC 300g | C35: =+A35 -> 1.5 | D35: UND | E35: =+'Costo Rosquete 300 g'!H54 -> 3.4633846 | F35: =IFERROR(E35*C35,"") -> 5.1950769 | G35: =IFERROR(F35/$F$66,"") -> 0.0023286336 | H35: NUEVO
A36: =+A18 -> 120 | B36: =IFERROR(VLOOKUP(H36,[1]SEMIELABORADOS!$A$2:$M$6000,2,0),"") -> CREMA DULCE LECHE KILO | C36: =+A36 -> 120 | D36: =IFERROR(VLOOKUP(H36,[1]SEMIELABORADOS!$A$2:$M$6000,6,0),"") -> Gramo | E36: =IFERROR(VLOOKUP(H36,[1]SEMIELABORADOS!$A$2:$M$65536,10,0),"") -> 8.512e-05 | F36: =IFERROR(E36*C36,"") -> 0.0102144 | G36: =IFERROR(F36/$F$66,"") -> 4.5784875e-06 | H36: 96344
A37: =+A19 -> 120 | B37: =IFERROR(VLOOKUP(H37,[1]SEMIELABORADOS!$A$2:$M$6000,2,0),"") -> CREMA CHANTILLY BLANCA SPOON-IND KILO | C37: =+A37 -> 120 | D37: =IFERROR(VLOOKUP(H37,[1]SEMIELABORADOS!$A$2:$M$6000,6,0),"") -> Gramo | E37: =IFERROR(VLOOKUP(H37,[1]SEMIELABORADOS!$A$2:$M$65536,10,0),"") -> 2.7884615e-05 | F37: =IFERROR(E37*C37,"") -> 0.0033461538 | G37: =IFERROR(F37/$F$66,"") -> 1.499875e-06 | H37: 95717
