Workbook

Sheet Costo Ensamble 
E1: Precio Local | F1: Costo MP | G1: Costo EM | H1: Costo MO
E2: =IFERROR(O69,"") -> 4504.6845 | F2: =IFERROR(H60,"") -> 2542.9287 | G2: =IFERROR(H61,"") -> 658.93846 | H2: =IFERROR(H63,"") -> 626.98085
A5: ESTRUCTURA DE COSTOS
F6: Fecha: | H6: =TODAY() -> 46139
A7: UNIDADES | B7: DESCRIPCION MAT.PRIMA | C7: UNIDADES | D7: UND MEDIDA | E7: COSTO UNITARIO | F7: TOTAL COSTO | G7: % PREC. DEFINIDO | H7: CODIGOS
A8: 30 | B8: =IFERROR(VLOOKUP(H8,'[1]Consolidado MP Planta'!$A$2:$M$823,3,0),"") -> LECHE POLVO INDUSTRIAL (SACO:25 KG) | C8: =+A8 -> 30 | D8: =IFERROR(VLOOKUP(H8,'[1]Consolidado MP Planta'!$A$2:$M$823,13,0),"") -> Gramos | E8: 3.15 | F8: =IFERROR(C8*E8,"") -> 94.5 | G8: =IFERROR(F8/$F$73,"") -> 0.02597777 | H8: 0310145
B9: =IFERROR(VLOOKUP(H9,'[1]Consolidado MP Planta'!$A$2:$M$823,3,0),"") | C9: =+A9 -> 0 | D9: =IFERROR(VLOOKUP(H9,'[1]Consolidado MP Planta'!$A$2:$M$823,13,0),"") | E9: =IFERROR(VLOOKUP(H9,'[1]Consolidado MP Planta'!$A$2:$M$823,12,0),"") | F9: =IFERROR(C9*E9,"") | G9: =IFERROR(F9/$F$73,"")
B10: =IFERROR(VLOOKUP(H10,'[1]Consolidado MP Planta'!$A$2:$M$823,3,0),"") | C10: =+A10 -> 0 | D10: =IFERROR(VLOOKUP(H10,'[1]Consolidado MP Planta'!$A$2:$M$823,13,0),"") | E10: =IFERROR(VLOOKUP(H10,'[1]Consolidado MP Planta'!$A$2:$M$823,12,0),"") | F10: =IFERROR(C10*E10,"") | G10: =IFERROR(F10/$F$73,"")
B11: =IFERROR(VLOOKUP(H11,'[1]Consolidado MP Planta'!$A$2:$M$823,3,0),"") | C11: =+A11 -> 0 | D11: =IFERROR(VLOOKUP(H11,'[1]Consolidado MP Planta'!$A$2:$M$823,13,0),"") | E11: =IFERROR(VLOOKUP(H11,'[1]Consolidado MP Planta'!$A$2:$M$823,12,0),"") | F11: =IFERROR(C11*E11,"") | G11: =IFERROR(F11/$F$73,"")
B12: =IFERROR(VLOOKUP(H12,'[1]Consolidado MP Planta'!$A$2:$M$823,3,0),"") | C12: =+A12 -> 0 | D12: =IFERROR(VLOOKUP(H12,'[1]Consolidado MP Planta'!$A$2:$M$823,13,0),"") | E12: =IFERROR(VLOOKUP(H12,'[1]Consolidado MP Planta'!$A$2:$M$823,12,0),"") | F12: =IFERROR(C12*E12,"") | G12: =IFERROR(F12/$F$73,"")
B13: =IFERROR(VLOOKUP(H13,'[1]Consolidado MP Planta'!$A$2:$M$823,3,0),"") | C13: =+A13 -> 0 | D13: =IFERROR(VLOOKUP(H13,'[1]Consolidado MP Planta'!$A$2:$M$823,13,0),"") | E13: =IFERROR(VLOOKUP(H13,'[1]Consolidado MP Planta'!$A$2:$M$823,12,0),"") | F13: =IFERROR(C13*E13,"") | G13: =IFERROR(F13/$F$73,"")
B14: =IFERROR(VLOOKUP(H14,'[1]Consolidado MP Planta'!$A$2:$M$823,3,0),"") | C14: =+A14 -> 0 | D14: =IFERROR(VLOOKUP(H14,'[1]Consolidado MP Planta'!$A$2:$M$823,13,0),"") | E14: =IFERROR(VLOOKUP(H14,'[1]Consolidado MP Planta'!$A$2:$M$823,12,0),"") | F14: =IFERROR(C14*E14,"") | G14: =IFERROR(F14/$F$73,"")
B15: =IFERROR(VLOOKUP(H15,[2]Hoja2!$A$2:$G$589,2,0),"")
A16: UNIDADES | B16: MATERIA PRIMA SEMIELABORADOS | C16: UNIDADES | D16: UND MEDIDA | E16: COSTO UNITARIO | F16: TOTAL COSTO | G16: % PREC. DEFINIDO | H16: CODIGOS
A17: 1.5 | B17: ROSQUETE EASY VAINILLA BC 310 G | C17: =+A17 -> 1.5 | D17: UND | E17: 391.01 | F17: =IFERROR(E17*C17,"") -> 586.515 | G17: =IFERROR(F17/$F$73,"") -> 0.16123123 | H17: SE00454
A18: 150 | B18: =IFERROR(VLOOKUP(H18,[1]SEMIELABORADOS!$A$2:$M$6000,2,0),"") -> MEZCLA TRES LECHES Y KOLITA (LITRO) | C18: =+A18 -> 150 | D18: =IFERROR(VLOOKUP(H18,[1]SEMIELABORADOS!$A$2:$M$6000,6,0),"") -> Gramo | E18: 1.34 | F18: =IFERROR(E18*C18,"") -> 201 | G18: =IFERROR(F18/$F$73,"") -> 0.055254303 | H18: 907000026
A19: 240 | B19: Relleno Cajeta | C19: =+A19 -> 240 | D19: Gramo | E19: =+'Costo relleno Cajeta'!E69 -> 2.435 | F19: =IFERROR(E19*C19,"") -> 584.4 | G19: =IFERROR(F19/$F$73,"") -> 0.16064983 | H19: NUEVO
A20: 100 | B20: Relleno Crema-Pinito | C20: =+A20 -> 100 | D20: Gramo | E20: =+'Costo Relleno Crema Pinito'!E69 -> 2.3852667 | F20: =IFERROR(E20*C20,"") -> 238.52667 | G20: =IFERROR(F20/$F$73,"") -> 0.065570273 | H20: NUEVO
A21: 190 | B21: EMPAQUE RELLENO DE FRESA NATURAL | C21: =+A21 -> 190 | D21: Gramo | E21: 1.51 | F21: =IFERROR(E21*C21,"") -> 286.9 | G21: =IFERROR(F21/$F$73,"") -> 0.078867959 | H21: SE00504
A22: 180 | B22: =IFERROR(VLOOKUP(H22,[1]SEMIELABORADOS!$A$2:$M$6000,2,0),"") -> CREMA BEIDGE (KILO) | C22: =+A22 -> 180 | D22: =IFERROR(VLOOKUP(H22,[1]SEMIELABORADOS!$A$2:$M$6000,6,0),"") -> Gramo | E22: 2.3 | F22: =IFERROR(E22*C22,"") -> 414 | G22: =IFERROR(F22/$F$73,"") -> 0.11380737 | H22: 910000018
A23: 30 | B23: Crema Chantilly Roja Claro | C23: =+A23 -> 30 | D23: Gramo | E23: =+'Costo Crema Roja Clara Bucca'!E69 -> 2.4469 | F23: =IFERROR(E23*C23,"") -> 73.407 | G23: =IFERROR(F23/$F$73,"") -> 0.020179366 | H23: NUEVO
A24: 4 | B24: Sirope Rojo Bucca | C24: =+A24 -> 4 | D24: Gramo | E24: 0.22 | F24: =IFERROR(E24*C24,"") -> 0.88 | G24: =IFERROR(F24/$F$73,"") -> 0.00024190939 | H24: SE00633
A25: 20 | B25: Ganache Chocolate Blanco | C25: =+A25 -> 20 | D25: Gramo | E25: 3.14 | F25: =IFERROR(E25*C25,"") -> 62.8 | G25: =IFERROR(F25/$F$73,"") -> 0.017263534 | H25: SE00051
A27: UNIDADES | B27: EMPAQUE | C27: UNIDADES | D27: UND MEDIDA | E27: COSTO UNITARIO | F27: TOTAL COSTO | G27: % PREC. DEFINIDO | H27: CODIGOS
A28: 1 | B28: =IFERROR(VLOOKUP(H28,'[1]Consolidado MP Planta'!$A$2:$M$823,3,0),"") -> QUEQUERA RED BASE/DOMO 10 (CAJA:50) | C28: =+A28 -> 1 | D28: =IFERROR(VLOOKUP(H28,'[1]Consolidado MP Planta'!$A$2:$M$823,13,0),"") -> UND | E28: 410 | F28: =IFERROR(C28*E28,"") -> 410 | G28: =IFERROR(F28/$F$73,"") -> 0.11270778 | H28: 121603
A29: 1 | B29: =IFERROR(VLOOKUP(H29,'[1]Consolidado MP Planta'!$A$2:$M$823,3,0),"") -> ORLA # 10 BUCCA (UND) | C29: =+A29 -> 1 | D29: =IFERROR(VLOOKUP(H29,'[1]Consolidado MP Planta'!$A$2:$M$823,13,0),"") -> 0 | E29: 137 | F29: =IFERROR(C29*E29,"") -> 137 | G29: =IFERROR(F29/$F$73,"") -> 0.037660893 | H29: 1952875
A30: 1 | B30: =IFERROR(VLOOKUP(H30,'[1]Consolidado MP Planta'!$A$2:$M$823,3,0),"") -> ETIQ.FECHA VENCIMIENTO BLANCO (ROLLO) | C30: =+A30 -> 1 | D30: =IFERROR(VLOOKUP(H30,'[1]Consolidado MP Planta'!$A$2:$M$823,13,0),"") -> Gramos | E30: =IFERROR(VLOOKUP(H30,'[1]Consolidado MP Planta'!$A$2:$M$823,12,0),"") -> 0.33333333 | F30: =IFERROR(C30*E30,"") -> 0.33333333 | G30: =IFERROR(F30/$F$73,"") -> 9.1632344e-05 | H30: 0702007
A31: 1 | B31: =IFERROR(VLOOKUP(H31,'[1]Consolidado MP Planta'!$A$2:$M$823,3,0),"") -> ETIQ.BLANCA 1 1/4 * 3/4 (UND) | C31: =+A31 -> 1 | D31: =IFERROR(VLOOKUP(H31,'[1]Consolidado MP Planta'!$A$2:$M$823,13,0),"") -> Und | E31: =IFERROR(VLOOKUP(H31,'[1]Consolidado MP Planta'!$A$2:$M$823,12,0),"") -> 0.58 | F31: =IFERROR(C31*E31,"") -> 0.58 | G31: =IFERROR(F31/$F$73,"") -> 0.00015944028 | H31: 0702069
A32: 1 | B32: =IFERROR(VLOOKUP(H32,'[1]Consolidado MP Planta'!$A$2:$M$823,3,0),"") -> ETIQUETA BLANCA 2 5/8X1 15/16 (UND) | C32: =+A32 -> 1 | D32: =IFERROR(VLOOKUP(H32,'[1]Consolidado MP Planta'!$A$2:$M$823,13,0),"") -> Und | E32: =IFERROR(VLOOKUP(H32,'[1]Consolidado MP Planta'!$A$2:$M$823,12,0),"") -> 2.128 | F32: =IFERROR(C32*E32,"") -> 2.128 | G32: =IFERROR(F32/$F$73,"") -> 0.00058498088 | H32: 0702123
A33: 1 | B33: Etiqueta especial Mamá 2026 | C33: =+A33 -> 1 | D33: UND | E33: 100 | F33: =IFERROR(C33*E33,"") -> 100 | G33: =IFERROR(F33/$F$73,"") -> 0.027489703 | H33: nuevo
B34: =IFERROR(VLOOKUP(H34,'[1]Consolidado MP Planta'!$A$2:$M$823,3,0),"") | C34: =+A34 -> 0 | D34: =IFERROR(VLOOKUP(H34,'[1]Consolidado MP Planta'!$A$2:$M$823,13,0),"") | E34: =IFERROR(VLOOKUP(H34,'[1]Consolidado MP Planta'!$A$2:$M$823,12,0),"") | F34: =IFERROR(C34*E34,"") | G34: =IFERROR(F34/$F$73,"")
B35: =IFERROR(VLOOKUP(H35,'[1]Consolidado MP Planta'!$A$2:$M$823,3,0),"") | C35: =+A35 -> 0 | D35: =IFERROR(VLOOKUP(H35,'[1]Consolidado MP Planta'!$A$2:$M$823,13,0),"") | E35: =IFERROR(VLOOKUP(H35,'[1]Consolidado MP Planta'!$A$2:$M$823,12,0),"") | F35: =IFERROR(C35*E35,"") | G35: =IFERROR(F35/$F$73,"")
A37: UNIDADES | B37: EMPAQUE SEMIELABORADOS | C37: UNIDADES | D37: UND MEDIDA | E37: COSTO UNITARIO | F37: TOTAL COSTO | G37: % PREC. DEFINIDO | H37: CODIGOS
A38: =+A17 -> 1.5 | B38: ROSQUETE EASY VAINILLA BC 310 G | C38: =+A38 -> 1.5 | D38: und | E38: 2.4 | F38: =IFERROR(E38*C38,"") -> 3.6 | G38: =IFERROR(F38/$F$73,"") -> 0.00098962932 | H38: SE00454
A39: =+A18 -> 150 | B39: MEZCLA TRES LECHES Y KOLITA (LITRO) | C39: =+A39 -> 150 | D39: =IFERROR(VLOOKUP(H39,[1]SEMIELABORADOS!$A$2:$M$6000,6,0),"") -> Gramo | E39: =IFERROR(VLOOKUP(H39,[1]SEMIELABORADOS!$A$2:$M$65536,10,0),"") -> 0.007380603 | F39: =IFERROR(E39*C39,"") -> 1.1070904 | G39: =IFERROR(F39/$F$73,"") -> 0.00030433588 | H39: 907000026
A40: =+A19 -> 240 | B40: Relleno Cajeta | C40: =+A40 -> 240 | D40: Gramo | E40: =+'Costo relleno Cajeta'!E76 -> 0 | F40: =IFERROR(E40*C40,"") -> 0 | G40: =IFERROR(F40/$F$73,"") -> 0 | H40: NUEVO
A41: =+A20 -> 100 | B41: Relleno Crema-Pinito | C41: =+A41 -> 100 | D41: Gramo | E41: =+'Costo Relleno Crema Pinito'!E76 -> 0 | F41: =IFERROR(E41*C41,"") -> 0 | G41: =IFERROR(F41/$F$73,"") -> 0 | H41: NUEVO
A42: =+A21 -> 190 | B42: EMPAQUE RELLENO DE FRESA NATURAL | C42: =+A42 -> 190 | D42: Gramo | E42: 0.02 | F42: =IFERROR(E42*C42,"") -> 3.8 | G42: =IFERROR(F42/$F$73,"") -> 0.0010446087 | H42: SE00504
A43: =+A22 -> 180 | B43: CREMA BEIDGE (KILO) | C43: =+A43 -> 180 | D43: =IFERROR(VLOOKUP(H43,[1]SEMIELABORADOS!$A$2:$M$6000,6,0),"") -> Gramo | E43: =IFERROR(VLOOKUP(H43,[1]SEMIELABORADOS!$A$2:$M$65536,10,0),"") -> 5.5769231e-05 | F43: =IFERROR(E43*C43,"") -> 0.010038462 | G43: =IFERROR(F43/$F$73,"") -> 2.7595433e-06 | H43: 910000018
A44: =+A23 -> 30 | B44: Crema Chantilly Roja Claro | C44: =+A44 -> 30 | D44: Gramo | E44: =+'Costo Crema Roja Clara Bucca'!E76 -> 0.01 | F44: =IFERROR(E44*C44,"") -> 0.3 | G44: =IFERROR(F44/$F$73,"") -> 8.246911e-05 | H44: NUEVO
...

Sheet Rosquete Easy Vainilla 
C1: SERVICIOS DE PASTELERIA S.A. | H1: CÓDIGO: | I1: ESP-RE-BAF-013
C2: ESPECIFICACION DE RECETA | H2: REVISIÓN: | I2: 02
C3: ESP-RE-BAF-013(2) 907000287(SE00454) Rosquete easy vainilla BC 310g | H3: FECHA DE APROBACIÓN: | I3: 45618
C4: Elaborado | D4: Javier Tong, Chef
C5: Aprobado | D5: Esteban Cartin, Gte Manufactura
A6: AREA QUE PRODUCE: | D6: Batidos | G6: AREA QUE EMPACA: | I6: Batidos
A7: # Código | B7: # Código Netsuite | C7: Descripción del ingrediente | D7: Marca | E7: Unidad Internacional | G7: Medida alternativa | I7: Costo - Referencia
E8: Cantidad | F8: Unidad medida | G8: Cantidad | H8: Unidad medida | I8: Colones
C9: Ensamble
A10: 907000286 | B10: SE00437 | C10: BATIDO EASY VAINILLA BC | D10: FAS | E10: 46000 | F10: g
A11: 902000019 | C11: MEZCLA P/ENGRASE MOLDES KILO | D11: FAS | E11: 2600 | F11: g
K19: =SUM(E10:E11) -> 48600
C21: Decoración
C28: Empaque
A29: 702007 | B29: EM10004 | C29: ETIQ.FECHA VENCIMIENTO BLANCO (ROLLO) | D29: ETIPLAST | E29: 11.821429 | F29: ud
A30: 702123 | B30: EM10011 | C30: ETIQUETA BLANCA 2 5/8X1 15/16 (UND) | D30: FAS | E30: 10 | F30: ud
B31: EM10259 | C31: Plastico Autoaderible 1/ 18*2000 | E31: 17 | F31: metros
D38: Cantidad | E38: Unidad
A39: PESO TOTAL OBTENIDO | D39: 45500 | E39: g | F39: Tiempo de Horneo:
A40: TIEMPO TOTAL DE PREPARACION | D40: 50 | E40: min | F40: Horno:
A41: CANTIDAD DE PORCIONES OBTENIDAS | D41: =D39/D42 -> 146.77419 | E41: ud | F41: Temperatura de Horneo:
A42: PESO DE CADA PORCIÓN | D42: 310 | E42: g | F42: Otros
A43: MERMA | D43: =SUM(E10:E11)-D39 -> 3100 | E43: g
A44: PROCEDIMIENTO DE PREPARACION DE LA RECETA
A45: 1.- Dosificar en moldes engrasados 350g de mezcla.
A46: 2.- Hornear por 30 minutos en el Dicte 1 a 175°C, en el Dicte 2 por 20 minutos a 175°C, en el Argental por 20 minutos a 175°C, en el Marshall por 18 minutos a 175°C, en el vulcan a 325°F por 25 minutos y en el Curitiba a 130°C por 28.
A47: 3.- Enfriar, desmoldar, colocar las bandejas en el coche y rapearlo con el plastico, dejando solamente la bandeja superior en bolsa plastica.
A48: 4, Etiquetar
A55: CONTROL DE CAMBIOS
A56: 2, Se actualizan pesos, datos receta y procedimiento.

Sheet Batido Easy Vainilla 
C1: SERVICIOS DE PASTELERIA S.A. | H1: CÓDIGO: | I1: ESP-RE-BAF-031
C2: ESPECIFICACION DE RECETA | H2: REVISIÓN: | I2: 02
C3: SE00437 Batido Easy Vainilla BC | H3: FECHA DE APROBACIÓN: | I3: 45980
C4: Elaborado | D4: Javier Tong, Chef
C5: Aprobado | D5: Esteban Cartin, Gte Manufactura
A6: AREA QUE PRODUCE: | D6: Batidos | G6: AREA QUE EMPACA: | I6: Batidos
A7: # Código | B7: # Código Netsuite | C7: Descripción del ingrediente | D7: Marca | E7: Unidad Internacional | G7: Medida alternativa | I7: Costo - Referencia
E8: Cantidad | F8: Unidad medida | G8: Cantidad | H8: Unidad medida | I8: Colones
C9: Ensamble
A10: 906000136 | B10: SE00436 | C10: PREMEZCLA EASY VAINILLA BC | D10: FAS | E10: 26860 | F10: g | J10: =+E10/$D$20 -> 0.57763441
A11: 1210482 | B11: MP10005 | C11: HUEVO LIQUIDO ESPECIAL INNOV (CAJA:10 K) | D11: INNOVO | E11: 4700 | F11: g | J11: =+E11/$D$20 -> 0.10107527 | K11: =+J11*1000 -> 101.07527
A12: 10415 | C12: AGUA POTABLE (PLANTA) | D12: FAS | E12: 13395 | F12: g | J12: =+E12/$D$20 -> 0.28806452 | K12: =+J12*1000 -> 288.06452
A13: 10100050 | B13: MP10002 | C13: ACEITE CAPULLO RBD (UND:17 L) | D13: CAPULLO | E13: 1400 | F13: g | J13: =+E13/$D$20 -> 0.030107527 | K13: =+J13*1000 -> 30.107527
A14: 1212437 | B14: MP10315 | C14: PRESERVANTE MIXTO | D14: PURATOS | E14: 370 | F14: g | J14: =+E14/$D$20 -> 0.0079569892 | K14: =+J14*1000 -> 7.9569892
D19: Cantidad | E19: Unidad
A20: PESO TOTAL OBTENIDO | D20: 46500 | E20: g | F20: Tiempo de Horneo:
A21: TIEMPO TOTAL DE PREPARACION | D21: 11 | E21: min | F21: Horno:
A22: CANTIDAD DE PORCIONES OBTENIDAS | D22: 1 | E22: ud | F22: Temperatura de Horneo:
A23: PESO DE CADA PORCIÓN | D23: 46500 | E23: g | F23: Otros
A24: MERMA | D24: 230 | E24: g
A25: PROCEDIMIENTO DE PREPARACION DE LA RECETA
A26: 1.- Agregar todos los liquidos a la batidora, luego todos los polvos. Batir 1 min en velocidada 1. Usar paleta.
A27: 2.- Subir a velocidad 2 y batir por 4 min.
A28: 3.- Dosificar.
A31: CONTROL DE CAMBIOS
A32: Revision #2: Cambio en el peso del huevo y el agua.

Sheet Premezcla Easy Vainilla
C1: SERVICIOS DE PASTELERIA S.A. | H1: CÓDIGO: | I1: ESP-RE-PRES-023
C2: ESPECIFICACION DE RECETA | H2: REVISIÓN: | I2: 03
C3: SE00436 Premezcla Easy vainilla BC | H3: FECHA DE APROBACIÓN: | I3: 45617
C4: Elaborado | D4: Juan Pablo Brenes, Chef
C5: Aprobado | D5: Esteban Cartin, Gte Manufactura
A6: AREA QUE PRODUCE: | D6: Premezclas | G6: AREA QUE EMPACA: | I6: Premezclas
A7: # Código | B7: # Código Netsuite | C7: Descripción del ingrediente | D7: Marca | E7: Unidad Internacional | G7: Medida alternativa | I7: Costo - Referencia
E8: Cantidad | F8: Unidad medida | G8: Cantidad | H8: Unidad medida | I8: Colones
C9: Ensamble
A10: 11200080 | B10: MP10491 | C10: EASY VAINILLA BC | D10: PURATOS | E10: 4600 | F10: g | J10: =+E10/$D$35 -> 0.17125838 | K10: =+J10*1000 -> 171.25838
A11: 510301 | B11: MP10074 | C11: AZUCAR BLANCO INDUSTRIAL (SACO:50 K) | D11: LAYCA | E11: 11000 | F11: g | J11: =+E11/$D$35 -> 0.4095309 | K11: =+J11*1000 -> 409.5309
A12: 11200072 | B12: MP10478 | C12: HARINA SILVER CAKE (SACO: 25K) | D12: FHACASA | E12: 7500 | F12: g | J12: =+E12/$D$35 -> 0.27922561 | K12: =+J12*1000 -> 279.22561
A13: 0510107 | B13: MP10036 | C13: HARINA HARISOL WINTER | D13: FHACASA | E13: 1900 | F13: g | J13: =+E13/$D$35 -> 0.070737156 | K13: =+J13*1000 -> 70.737156
A14: 1212410 | B14: MP10008 | C14: PRESERVANTE 1047S (PAQ=5 KILO) | D14: MAYCA | E14: 50 | F14: g | J14: =+E14/$D$35 -> 0.0018615041 | K14: =+J14*1000 -> 1.8615041
A15: 10100046 | B15: MP10304 | C15: POLVO HORNEAR FLEISHMAN (PAQ:2.5 K) | D15: FLEISHMAN | E15: 150 | F15: g | J15: =+E15/$D$35 -> 0.0055845123 | K15: =+J15*1000 -> 5.5845123
A16: 1210445 | B16: MP10142 | C16: CLARA DE HUEVO DESHIDRATADA | E16: 450 | F16: g | J16: =+E16/$D$35 -> 0.016753537 | K16: =+J16*1000 -> 16.753537
A17: 11300012 | B17: MP10517 | C17: ACTI EGG | D17: PURATOS | E17: 360 | F17: g | J17: =+E17/$D$35 -> 0.013402829 | K17: =+J17*1000 -> 13.402829
B18: MP10481 | C18: Goma Xantana | E18: 60 | F18: g | J18: =+E18/$D$35 -> 0.0022338049 | K18: =+J18*1000 -> 2.2338049
B19: MP10769 | C19: HUEVO EN POLVO | D19: EPKMARKET | E19: 705 | F19: g | J19: =+E19/$D$35 -> 0.026247208 | K19: =+J19*1000 -> 26.247208
C21: Empaque
A22: 1950708 | B22: EM10013 | C22: BOLSA 17x25 TRANSP KILO | E22: 1 | F22: ud
A23: 503000042 | B23: EM10258 | C23: BOLSA TRANSP 20x30x2000 | E23: 1 | F23: ud
A24: 0702123 | B24: EM10011 | C24: ETIQUETA BLANCA 2 5/8X1 15/16 (UND) | E24: 2 | F24: ud
A25: 1950705 | B25: EM10037 | C25: BOLSA 8x12 TRANSPARENTE KILO | E25: 1 | F25: ud
A26: 60100010 | B26: EM10133 | C26: ETIQUETA ROJA LETRA ALERJENO (UND) | E26: 1 | F26: ud
D34: Cantidad | E34: Unidad
A35: PESO TOTAL OBTENIDO | D35: 26860 | E35: g | F35: Tiempo de Horneo:
A36: TIEMPO TOTAL DE PREPARACION | D36: 4 | E36: min | F36: Horno:
A37: CANTIDAD DE PORCIONES OBTENIDAS | D37: 1 | E37: tanda | F37: Temperatura de Horneo:
A38: PESO DE CADA PORCIÓN | D38: 26860 | E38: g | F38: Otros
A39: MERMA | D39: 0 | E39: g
A40: PROCEDIMIENTO DE PREPARACION DE LA RECETA
A41: 1.- En una bolsa 20x30 empacar el nucleo easy con el harina y el actiegg. En una bolsa 17x25 empacar el azucar, y etiquetar.
A42: 2.- En la otra bolsa 8x12 empacar el preservante, polvo de hornear. Colocar en la misma bolsa del harina.
A45: CONTROL DE CAMBIOS
A46: Revision #2: Se baja a la mitad el polvo de hornear y se agrega goma xantana
A47: Revision #3: Actualizacion por adicion de huevo en polvo.

Sheet Empaq relleno fresa Natural 
C1: SERVICIOS DE PASTELERIA S.A. | H1: CÓDIGO: | I1: ESP-RE-EMPS-055
C2: ESPECIFICACION DE RECETA | H2: REVISIÓN: | I2: 01
C3: 90100401(SE00504) Empaque relleno de fresas Natural | H3: FECHA DE APROBACIÓN: | I3: 45610
C4: Elaborado | D4: Javier Tong, Chef
C5: Aprobado | D5: Esteban Cartin, Gte Manufactura
A6: AREA QUE PRODUCE: | D6: Cocina | G6: AREA QUE EMPACA: | I6: Empaque
A7: # Código | B7: # Código Netsuite | C7: Descripción del ingrediente | D7: Marca | E7: Unidad Internacional | G7: Medida alternativa | I7: Costo - Referencia
E8: Cantidad | F8: Unidad medida | G8: Cantidad | H8: Unidad medida | I8: Colones
C9: Ensamble
A10: 90100400 | B10: SE00503 | C10: RELLENO DE FRESA NATURAL | D10: FAS | E10: 5000 | F10: g
C18: Decoración
C24: Empaque
A25: 1950708 | B25: EM10013 | C25: BOLSA 17x25 TRANSP (KILO) | E25: 1 | F25: ud
A26: 702069 | B26: EM10002 | C26: ETIQ.BLANCA 1 1/4 * 3/4 (UND) | D26: CEMUSA | E26: 1 | F26: ud
A27: 702007 | B27: EM10004 | C27: ETIQ.FECHA VENCIMIENTO BLANCO (ROLLO) | D27: ETIPLAST | E27: 1 | F27: ud
D35: Cantidad | E35: Unidad
A36: PESO TOTAL OBTENIDO | D36: 5000 | E36: g | F36: Tiempo de Horneo:
A37: TIEMPO TOTAL DE PREPARACION | D37: 1 | E37: min | F37: Horno:
A38: CANTIDAD DE PORCIONES OBTENIDAS | D38: 1 | E38: bolsa | F38: Temperatura de Horneo:
A39: PESO DE CADA PORCIÓN | D39: 5000 | E39: g | F39: Otros
A40: MERMA | D40: 0 | E40: g
A41: PROCEDIMIENTO DE PREPARACION DE LA RECETA
A42: 1, Empacar 5000g de relleno en una bolsa 17*25.
A43: 2, Cerrar y etiquetar
A51: CONTROL DE CAMBIOS

Sheet Relleno fresa natural 
C1: SERVICIOS DE PASTELERIA S.A. | H1: CÓDIGO: | I1: ESP-RE-COCS-065
C2: ESPECIFICACION DE RECETA | H2: REVISIÓN: | I2: 01
C3: SE00503 Relleno de fresa Natural | H3: FECHA DE APROBACIÓN: | I3: 45609
C4: Elaborado | D4: Javier Tong, Chef
C5: Aprobado | D5: Esteban Cartin, Gte Manufactura
A6: AREA QUE PRODUCE: | D6: Cocina | G6: AREA QUE EMPACA: | I6: Empaque
A7: # Código | B7: # Código Netsuite | C7: Descripción del ingrediente | D7: Marca | E7: Unidad Internacional | G7: Medida alternativa | I7: Costo - Referencia
E8: Cantidad | F8: Unidad medida | G8: Cantidad | H8: Unidad medida | I8: Colones
C9: Ensamble
A10: 101081 | B10: MP10193 | C10: FRESA PICADA (KILO) | D10: BEGRO | E10: 23000 | F10: g
A11: 1212412 | B11: MP10025 | C11: PRESERVANTE 1017S (PAQ=5 KILO) | D11: ASEAL | E11: 62 | F11: g
A12: 510215 | B12: MP10026 | C12: ALMIDON MODIFICADO ( 25 KG ) | D12: ASEAL | E12: 1350 | F12: g
A13: 10400009 | B13: MP10157 | C13: COLORANTE GEL SUPER RED | D13: AMERICOLOR | E13: 10 | F13: g
A14: 10400010 | B14: MP10509 | C14: COLORANTE ROJO (50ML) | D14: ANCLA | E14: 10 | F14: g
A15: 90100131 | B15: SE00016 | C15: AZUCAR BLANCO INDUSTRIAL (BOLSAS:1500g) | D15: FAS | E15: 7130 | F15: g
A16: 908000036 | B16: SE00015 | C16: JUGO LIMON (KILO) | D16: FAS | E16: 920 | F16: g
A17: 10415 | C17: AGUA POTABLE (PLANTA) | D17: FAS | E17: 571 | F17: g
C27: Decoración
C33: Empaque
A34: 702123 | B34: EM10011 | C34: ETIQUETA BLANCA 2 5/8X1 15/16 (UND) | D34: CEMUSA | E34: 1 | F34: ud
D44: Cantidad | E44: Unidad
A45: PESO TOTAL OBTENIDO | D45: 30000 | E45: g | F45: Tiempo de Horneo:
A46: TIEMPO TOTAL DE PREPARACION | D46: 35 | E46: min | F46: Horno:
A47: CANTIDAD DE PORCIONES OBTENIDAS | D47: 6 | E47: bolsas | F47: Temperatura de Horneo:
A48: PESO DE CADA PORCIÓN | D48: 5000 | E48: g | F48: Otros
A49: MERMA | D49: 2470 | E49: g
A50: PROCEDIMIENTO DE PREPARACION DE LA RECETA
A51: 1- Lavar y desinfectar la fresa. Cortar la fresa con la maquina, Colocar la fresa en la olla junto con el azucar, y el colorante. Hervir
A52: 2- Mezclar el almidon con el preservante y el agua, juego de limon .Disolver el la mezcla de Liquidos super bien Agregar a la mezcla anterior. Hervir a Fuego Medio
A53: 3- No Mezclar tanto para no desbaratar la Fresa
A54: 4- Colocar en bandejas y hacer choque termico.
A62: CONTROL DE CAMBIOS

Sheet Crema Beidge
C1: SERVICIOS DE PASTELERIA S.A. | H1: CÓDIGO: | I1: ESP-RE-DES-021
C2: ESPECIFICACION DE RECETA | H2: REVISIÓN: | I2: 03
C3: Crema Beidge SE00069 | H3: FECHA DE APROBACIÓN: | I3: 45663
C4: Elaborado | D4: Javier Tong, Chef
C5: Aprobado | D5: Esteban Cartin, Gte Manufactura
A6: AREA QUE PRODUCE: | D6: Decoración | G6: AREA QUE EMPACA: | I6: Decoracion
A7: # Código | B7: # Código Netsuite | C7: Descripción del ingrediente | D7: Marca | E7: Unidad Internacional | G7: Medida alternativa | I7: Costo - Referencia
E8: Cantidad | F8: Unidad medida | G8: Cantidad | H8: Unidad medida | I8: Colones
C9: Ensamble
B10: SE00670 | C10: CREMA BLANCA SUPREMO | D10: FAS | E10: =16580/16.58 -> 1000 | F10: g
A11: 10400008 | B11: MP10150 | C11: COLORANTE GEL EGG YELLOW (UND= 130 ML) | D11: MASTER PACK | E11: 0.2 | F11: g
C20: Decoración
C29: Empaque
A30: 0702069 | B30: EM10002 | C30: ETIQ.BLANCA 1 1/4 * 3/4 | D30: ETIPLAST | E30: 1 | F30: ud
D40: Cantidad | E40: Unidad
A41: PESO TOTAL OBTENIDO | D41: 1000 | E41: g | F41: Tiempo de Horneo:
A42: TIEMPO TOTAL DE PREPARACION | D42: 3 | E42: Min | F42: Horno:
A43: CANTIDAD DE PORCIONES OBTENIDAS | D43: 1 | E43: Tanda | F43: Temperatura de Horneo:
A44: PESO DE CADA PORCIÓN | D44: 1000 | E44: g | F44: Otros
A45: MERMA | D45: =SUM(E10:E11)-D41 -> 0 | E45: g
A46: PROCEDIMIENTO DE PREPARACION DE LA RECETA
A47: 1, Sacar la crema blanca suprema de la camara (temperatura maxima 18° ya batida).
A48: 2, Agregar el colorantes y mezclar a mano, hasta que este completamente homogeneo.
A49: 3, Colocar plastico para tapar y etiquetar.
A50: 4, Volver a guardar en la camara hasta su uso.
A56: CONTROL DE CAMBIOS
A57: 2, Se actualiza procedimiento y tiempo de preparación
A58: 3, Se actualizan datos de receta y pesos finales

Sheet Crema Blanca supremo
C1: SERVICIOS DE PASTELERIA S.A. | H1: CÓDIGO: | I1: ESP-RE-DES-059
C2: ESPECIFICACION DE RECETA | H2: REVISIÓN: | I2: 04
C3: SE00670 Crema Blanca Supremo | H3: FECHA DE APROBACIÓN: | I3: 45659
C4: Elaborado | D4: Javier Tong, Chef
C5: Aprobado | D5: Esteban Cartin, Gte Manufactura
A6: AREA QUE PRODUCE: | D6: Decoracoración | G6: AREA QUE EMPACA: | I6: Decoración
A7: # Código | B7: # Código Netsuite | C7: Descripción del ingrediente | D7: Marca | E7: Unidad Internacional | G7: Medida alternativa | I7: Costo - Referencia
E8: Cantidad | F8: Unidad medida | G8: Cantidad | H8: Unidad medida | I8: Colones
C9: Ensamble
A10: 310148 | B10: MP10047 | C10: BETTERCREME SUPREMO (UND:4 K) | D10: RICHS | E10: 16150 | F10: g | J10: =+E10/$D$39 -> 0.99299053 | K10: =+J10*1000 -> 992.99053
A11: 10415 | C11: AGUA POTABLE (PLANTA) | D11: AYA | E11: 100 | F11: g | J11: =+E11/$D$39 -> 0.0061485482 | K11: =+J11*1000 -> 6.1485482 | L11: =SUM(E10:E13) -> 16264.002
A12: 1212410 | B12: MP10008 | C12: PRESERVANTE 1047S (PAQ=5 KILO) | D12: ASEAL | E12: 10.002021 | F12: g | J12: =+E12/$D$39 -> 0.00061497906 | K12: =+J12*1000 -> 0.61497906 | L12: =L11-230 -> 16034.002
A13: 10400008 | B13: MP10150 | C13: COLORANTE GEL EGG YELLOW (UND= 130 ML) | D13: MASTER PACK | E13: 4 | F13: g | J13: =+E13/$D$39 -> 0.00024594193 | K13: =+J13*1000 -> 0.24594193
L17: =E10/1000 -> 16.15
C21: Decoración
C28: Empaque
A29: 702123 | B29: EM10011 | C29: ETIQUETA BLANCA 2 5/8X1 15/16 (UND) | D29: Etiplas | E29: 1 | F29: ud
D38: Cantidad | E38: Unidad
A39: PESO TOTAL OBTENIDO | D39: =SUM(E10:E13) -> 16264.002 | E39: g | F39: Tiempo de Horneo:
A40: TIEMPO TOTAL DE PREPARACION | D40: 15 | E40: min | F40: Horno:
A41: CANTIDAD DE PORCIONES OBTENIDAS | D41: 1 | E41: Tanda | F41: Temperatura de Horneo:
A42: PESO DE CADA PORCIÓN | D42: 16263 | E42: g | F42: Otros
A43: MERMA | D43: =SUM(E10:E13)-D39 -> 0 | E43: g
A44: PROCEDIMIENTO DE PREPARACION DE LA RECETA
A45: 1.- Abrir los galones de bettercreme supremo y verter dentro de la top cream, reservando un poco.
A46: 2.- Disolver el preservante con el colorante en el agua, mezclando bien, dejandolo sin grumos (Si hace falta disolver, agregar un poco del bettercream supremo para terminar de disolver)
A47: 3.- Batir por 15 minutos
A48: 4- Una vez lista retirar (Temperatura adecuada 15° a 16°) y colocar en una tina plastica y tapar con plastico
A49: 5.- Etiquetar con nombre y fecha de vencimiento.
A50: 6.- Mantener en refrigeración, hasta su uso.
A56: CONTROL DE CAMBIOS
A57: 2, Se sustituye la crema prestige por crema supremo y procedimiento
A58: 3, Se actualiza tiempo de preparación, se agrega colorante y se actualiza procedimiento.
A59: 4, Se actualiza cantidad de colorante

Sheet Costo Crema Roja Clara Bucca
E1: Precio Local | F1: Costo MP | G1: Costo EM | H1: Costo MO
E2: =IFERROR(O62,"") -> 2901.5753 | F2: =IFERROR(H53,"") -> 2446.9 | G2: =IFERROR(H54,"") -> 10 | H2: =IFERROR(H56,"") -> 214
A5: ESTRUCTURA DE COSTOS
F6: Fecha: | H6: =TODAY() -> 46139
A7: UNIDADES | B7: DESCRIPCION MAT.PRIMA | C7: UNIDADES | D7: UND MEDIDA | E7: COSTO UNITARIO | F7: TOTAL COSTO | G7: % PREC. DEFINIDO | H7: CODIGOS
A8: 15 | B8: =IFERROR(VLOOKUP(H8,'[1]Consolidado MP Planta'!$A$2:$M$823,3,0),"") -> COLORANTE GEL SUPER RED | C8: =+A8 -> 15 | D8: =IFERROR(VLOOKUP(H8,'[1]Consolidado MP Planta'!$A$2:$M$823,13,0),"") -> Mililitros | E8: 18.46 | F8: =IFERROR(C8*E8,"") -> 276.9 | G8: =IFERROR(F8/$F$66,"") -> 0.10410408 | H8: 10400009
B9: =IFERROR(VLOOKUP(H9,'[1]Consolidado MP Planta'!$A$2:$M$823,3,0),"") | C9: =+A9 -> 0 | D9: =IFERROR(VLOOKUP(H9,'[1]Consolidado MP Planta'!$A$2:$M$823,13,0),"") | E9: =IFERROR(VLOOKUP(H9,'[1]Consolidado MP Planta'!$A$2:$M$823,12,0),"") | F9: =IFERROR(C9*E9,"") | G9: =IFERROR(F9/$F$66,"")
B10: =IFERROR(VLOOKUP(H10,'[1]Consolidado MP Planta'!$A$2:$M$823,3,0),"") | C10: =+A10 -> 0 | D10: =IFERROR(VLOOKUP(H10,'[1]Consolidado MP Planta'!$A$2:$M$823,13,0),"") | E10: =IFERROR(VLOOKUP(H10,'[1]Consolidado MP Planta'!$A$2:$M$823,12,0),"") | F10: =IFERROR(C10*E10,"") | G10: =IFERROR(F10/$F$66,"")
B11: =IFERROR(VLOOKUP(H11,'[1]Consolidado MP Planta'!$A$2:$M$823,3,0),"") | C11: =+A11 -> 0 | D11: =IFERROR(VLOOKUP(H11,'[1]Consolidado MP Planta'!$A$2:$M$823,13,0),"") | E11: =IFERROR(VLOOKUP(H11,'[1]Consolidado MP Planta'!$A$2:$M$823,12,0),"") | F11: =IFERROR(C11*E11,"") | G11: =IFERROR(F11/$F$66,"")
B12: =IFERROR(VLOOKUP(H12,'[1]Consolidado MP Planta'!$A$2:$M$823,3,0),"") | C12: =+A12 -> 0 | D12: =IFERROR(VLOOKUP(H12,'[1]Consolidado MP Planta'!$A$2:$M$823,13,0),"") | E12: =IFERROR(VLOOKUP(H12,'[1]Consolidado MP Planta'!$A$2:$M$823,12,0),"") | F12: =IFERROR(C12*E12,"") | G12: =IFERROR(F12/$F$66,"")
B13: =IFERROR(VLOOKUP(H13,'[1]Consolidado MP Planta'!$A$2:$M$823,3,0),"") | C13: =+A13 -> 0 | D13: =IFERROR(VLOOKUP(H13,'[1]Consolidado MP Planta'!$A$2:$M$823,13,0),"") | E13: =IFERROR(VLOOKUP(H13,'[1]Consolidado MP Planta'!$A$2:$M$823,12,0),"") | F13: =IFERROR(C13*E13,"") | G13: =IFERROR(F13/$F$66,"")
B14: =IFERROR(VLOOKUP(H14,'[1]Consolidado MP Planta'!$A$2:$M$823,3,0),"") | C14: =+A14 -> 0 | D14: =IFERROR(VLOOKUP(H14,'[1]Consolidado MP Planta'!$A$2:$M$823,13,0),"") | E14: =IFERROR(VLOOKUP(H14,'[1]Consolidado MP Planta'!$A$2:$M$823,12,0),"") | F14: =IFERROR(C14*E14,"") | G14: =IFERROR(F14/$F$66,"")
B15: =IFERROR(VLOOKUP(H15,[2]Hoja2!$A$2:$G$589,2,0),"")
A16: UNIDADES | B16: MATERIA PRIMA SEMIELABORADOS | C16: UNIDADES | D16: UND MEDIDA | E16: COSTO UNITARIO | F16: TOTAL COSTO | G16: % PREC. DEFINIDO | H16: CODIGOS
A17: 1000 | B17: CREMA BLANCA BUCCA | C17: =+A17 -> 1000 | D17: Gramos | E17: 2.17 | F17: =IFERROR(E17*C17,"") -> 2170 | G17: =IFERROR(F17/$F$66,"") -> 0.81583916 | H17: SE00634
B18: =IFERROR(VLOOKUP(H18,[1]SEMIELABORADOS!$A$2:$M$6000,2,0),"") | C18: =+A18 -> 0 | D18: =IFERROR(VLOOKUP(H18,[1]SEMIELABORADOS!$A$2:$M$6000,6,0),"") | E18: =IFERROR(VLOOKUP(H18,[1]SEMIELABORADOS!$A$2:$H$65536,8,0),"") | F18: =IFERROR(E18*C18,"") | G18: =IFERROR(F18/$F$66,"")
B19: =IFERROR(VLOOKUP(H19,[1]SEMIELABORADOS!$A$2:$M$6000,2,0),"") | C19: =+A19 -> 0 | D19: =IFERROR(VLOOKUP(H19,[1]SEMIELABORADOS!$A$2:$M$6000,6,0),"") | E19: =IFERROR(VLOOKUP(H19,[1]SEMIELABORADOS!$A$2:$H$65536,8,0),"") | F19: =IFERROR(E19*C19,"") | G19: =IFERROR(F19/$F$66,"")
B20: =IFERROR(VLOOKUP(H20,[1]SEMIELABORADOS!$A$2:$M$6000,2,0),"") | C20: =+A20 -> 0 | D20: =IFERROR(VLOOKUP(H20,[1]SEMIELABORADOS!$A$2:$M$6000,6,0),"") | E20: =IFERROR(VLOOKUP(H20,[1]SEMIELABORADOS!$A$2:$H$65536,8,0),"") | F20: =IFERROR(E20*C20,"") | G20: =IFERROR(F20/$F$66,"")
B21: =IFERROR(VLOOKUP(H21,[1]SEMIELABORADOS!$A$2:$M$6000,2,0),"") | C21: =+A21 -> 0 | D21: =IFERROR(VLOOKUP(H21,[1]SEMIELABORADOS!$A$2:$M$6000,6,0),"") | E21: =IFERROR(VLOOKUP(H21,[1]SEMIELABORADOS!$A$2:$H$65536,8,0),"") | F21: =IFERROR(E21*C21,"") | G21: =IFERROR(F21/$F$66,"")
B22: =IFERROR(VLOOKUP(H22,[1]SEMIELABORADOS!$A$2:$M$6000,2,0),"") | C22: =+A22 -> 0 | D22: =IFERROR(VLOOKUP(H22,[1]SEMIELABORADOS!$A$2:$M$6000,6,0),"") | E22: =IFERROR(VLOOKUP(H22,[1]SEMIELABORADOS!$A$2:$H$65536,8,0),"") | F22: =IFERROR(E22*C22,"") | G22: =IFERROR(F22/$F$66,"")
B23: =IFERROR(VLOOKUP(H23,[1]SEMIELABORADOS!$A$2:$M$6000,2,0),"") | C23: =+A23 -> 0 | D23: =IFERROR(VLOOKUP(H23,[1]SEMIELABORADOS!$A$2:$M$6000,6,0),"") | E23: =IFERROR(VLOOKUP(H23,[1]SEMIELABORADOS!$A$2:$H$65536,8,0),"") | F23: =IFERROR(E23*C23,"") | G23: =IFERROR(F23/$F$66,"")
B24: =IFERROR(VLOOKUP(H24,[1]SEMIELABORADOS!$A$2:$M$6000,2,0),"") | C24: =+A24 -> 0 | D24: =IFERROR(VLOOKUP(H24,[1]SEMIELABORADOS!$A$2:$M$6000,6,0),"") | E24: =IFERROR(VLOOKUP(H24,[1]SEMIELABORADOS!$A$2:$H$65536,8,0),"") | F24: =IFERROR(E24*C24,"") | G24: =IFERROR(F24/$F$66,"")
A26: UNIDADES | B26: EMPAQUE | C26: UNIDADES | D26: UND MEDIDA | E26: COSTO UNITARIO | F26: TOTAL COSTO | G26: % PREC. DEFINIDO | H26: CODIGOS
A27: 0 | B27: =IFERROR(VLOOKUP(H27,'[1]Consolidado MP Planta'!$A$2:$M$823,3,0),"") | C27: =+A27 -> 0 | D27: =IFERROR(VLOOKUP(H27,'[1]Consolidado MP Planta'!$A$2:$M$823,13,0),"") | E27: =IFERROR(VLOOKUP(H27,'[1]Consolidado MP Planta'!$A$2:$M$823,12,0),"") | F27: =IFERROR(C27*E27,"") | G27: =IFERROR(F27/$F$66,"")
B28: =IFERROR(VLOOKUP(H28,'[1]Consolidado MP Planta'!$A$2:$M$823,3,0),"") | C28: =+A28 -> 0 | D28: =IFERROR(VLOOKUP(H28,'[1]Consolidado MP Planta'!$A$2:$M$823,13,0),"") | E28: =IFERROR(VLOOKUP(H28,'[1]Consolidado MP Planta'!$A$2:$M$823,12,0),"") | F28: =IFERROR(C28*E28,"") | G28: =IFERROR(F28/$F$66,"")
B29: =IFERROR(VLOOKUP(H29,'[1]Consolidado MP Planta'!$A$2:$M$823,3,0),"") | C29: =+A29 -> 0 | D29: =IFERROR(VLOOKUP(H29,'[1]Consolidado MP Planta'!$A$2:$M$823,13,0),"") | E29: =IFERROR(VLOOKUP(H29,'[1]Consolidado MP Planta'!$A$2:$M$823,12,0),"") | F29: =IFERROR(C29*E29,"") | G29: =IFERROR(F29/$F$66,"")
B30: =IFERROR(VLOOKUP(H30,'[1]Consolidado MP Planta'!$A$2:$M$823,3,0),"") | C30: =+A30 -> 0 | D30: =IFERROR(VLOOKUP(H30,'[1]Consolidado MP Planta'!$A$2:$M$823,13,0),"") | E30: =IFERROR(VLOOKUP(H30,'[1]Consolidado MP Planta'!$A$2:$M$823,12,0),"") | F30: =IFERROR(C30*E30,"") | G30: =IFERROR(F30/$F$66,"")
B31: =IFERROR(VLOOKUP(H31,'[1]Consolidado MP Planta'!$A$2:$M$823,3,0),"") | C31: =+A31 -> 0 | D31: =IFERROR(VLOOKUP(H31,'[1]Consolidado MP Planta'!$A$2:$M$823,13,0),"") | E31: =IFERROR(VLOOKUP(H31,'[1]Consolidado MP Planta'!$A$2:$M$823,12,0),"") | F31: =IFERROR(C31*E31,"") | G31: =IFERROR(F31/$F$66,"")
B32: =IFERROR(VLOOKUP(H32,'[1]Consolidado MP Planta'!$A$2:$M$823,3,0),"") | C32: =+A32 -> 0 | D32: =IFERROR(VLOOKUP(H32,'[1]Consolidado MP Planta'!$A$2:$M$823,13,0),"") | E32: =IFERROR(VLOOKUP(H32,'[1]Consolidado MP Planta'!$A$2:$M$823,12,0),"") | F32: =IFERROR(C32*E32,"") | G32: =IFERROR(F32/$F$66,"")
A34: UNIDADES | B34: EMPAQUE SEMIELABORADOS | C34: UNIDADES | D34: UND MEDIDA | E34: COSTO UNITARIO | F34: TOTAL COSTO | G34: % PREC. DEFINIDO | H34: CODIGOS
A35: =+A17 -> 1000 | B35: CREMA BLANCA BUCCA | C35: =+A35 -> 1000 | D35: Gramos | E35: 0.01 | F35: =IFERROR(E35*C35,"") -> 10 | G35: =IFERROR(F35/$F$66,"") -> 0.0037596275 | H35: SE00634
A36: =+A18 -> 0 | B36: =IFERROR(VLOOKUP(H36,[1]SEMIELABORADOS!$A$2:$M$6000,2,0),"") | C36: =+A36 -> 0 | D36: =IFERROR(VLOOKUP(H36,[1]SEMIELABORADOS!$A$2:$M$6000,6,0),"") | E36: =IFERROR(VLOOKUP(H36,[1]SEMIELABORADOS!$A$2:$M$65536,10,0),"") | F36: =IFERROR(E36*C36,"") | G36: =IFERROR(F36/$F$66,"")
A37: =+A19 -> 0 | B37: =IFERROR(VLOOKUP(H37,[1]SEMIELABORADOS!$A$2:$M$6000,2,0),"") | C37: =+A37 -> 0 | D37: =IFERROR(VLOOKUP(H37,[1]SEMIELABORADOS!$A$2:$M$6000,6,0),"") | E37: =IFERROR(VLOOKUP(H37,[1]SEMIELABORADOS!$A$2:$M$65536,10,0),"") | F37: =IFERROR(E37*C37,"") | G37: =IFERROR(F37/$F$66,"")
A38: =+A20 -> 0 | B38: =IFERROR(VLOOKUP(H38,[1]SEMIELABORADOS!$A$2:$M$6000,2,0),"") | C38: =+A38 -> 0 | D38: =IFERROR(VLOOKUP(H38,[1]SEMIELABORADOS!$A$2:$M$6000,6,0),"") | E38: =IFERROR(VLOOKUP(H38,[1]SEMIELABORADOS!$A$2:$M$65536,10,0),"") | F38: =IFERROR(E38*C38,"") | G38: =IFERROR(F38/$F$66,"")
A39: =+A21 -> 0 | B39: =IFERROR(VLOOKUP(H39,[1]SEMIELABORADOS!$A$2:$M$6000,2,0),"") | C39: =+A39 -> 0 | D39: =IFERROR(VLOOKUP(H39,[1]SEMIELABORADOS!$A$2:$M$6000,6,0),"") | E39: =IFERROR(VLOOKUP(H39,[1]SEMIELABORADOS!$A$2:$M$65536,10,0),"") | F39: =IFERROR(E39*C39,"") | G39: =IFERROR(F39/$F$66,"")
A40: =+A22 -> 0 | B40: =IFERROR(VLOOKUP(H40,[1]SEMIELABORADOS!$A$2:$M$6000,2,0),"") | C40: =+A40 -> 0 | D40: =IFERROR(VLOOKUP(H40,[1]SEMIELABORADOS!$A$2:$M$6000,6,0),"") | E40: =IFERROR(VLOOKUP(H40,[1]SEMIELABORADOS!$A$2:$M$65536,10,0),"") | F40: =IFERROR(E40*C40,"") | G40: =IFERROR(F40/$F$66,"")
A41: =+A23 -> 0 | B41: =IFERROR(VLOOKUP(H41,[1]SEMIELABORADOS!$A$2:$M$6000,2,0),"") | C41: =+A41 -> 0 | D41: =IFERROR(VLOOKUP(H41,[1]SEMIELABORADOS!$A$2:$M$6000,6,0),"") | E41: =IFERROR(VLOOKUP(H41,[1]SEMIELABORADOS!$A$2:$M$65536,10,0),"") | F41: =IFERROR(E41*C41,"") | G41: =IFERROR(F41/$F$66,"")
A43: UNIDADES | B43: MODI | C43: UNIDADES | D43: UND MEDIDA | E43: COSTO UNITARIO | F43: TOTAL COSTO | G43: % PREC. DEFINIDO | H43: CODIGOS
A44: =+A35 -> 1000 | B44: CREMA BLANCA BUCCA | C44: =+A44 -> 1000 | D44: Gramos | E44: 0.06 | F44: =IFERROR(E44*C44,"") -> 60 | G44: =IFERROR(F44/$F$66,"") -> 0.022557765 | H44: SE00634
A45: =+A36 -> 0 | B45: =IFERROR(VLOOKUP(H45,[1]SEMIELABORADOS!$A$2:$M$6000,2,0),"") | C45: =+A45 -> 0 | D45: =IFERROR(VLOOKUP(H45,[1]SEMIELABORADOS!$A$2:$M$6000,6,0),"") | E45: =IFERROR(VLOOKUP(H45,[1]SEMIELABORADOS!$A$2:$M$65536,12,0),"") | F45: =IFERROR(E45*C45,"") | G45: =IFERROR(F45/$F$66,"")
...

Sheet Crema Blanca Bucca
C1: SERVICIOS DE PASTELERIA S.A. | H1: CÓDIGO: | I1: ESP-RE-DEF-026
C2: ESPECIFICACION DE RECETA | H2: REVISIÓN: | I2: 02
C3: SE00634 Crema blanca Bucca | H3: FECHA DE APROBACIÓN: | I3: 45612
C4: Elaborado | D4: Javier Tong, Chef
C5: Aprobado | D5: Esteban Cartin, Gte Manufactura
A6: AREA QUE PRODUCE: | D6: Decoración | G6: AREA QUE EMPACA: | I6: Decoracion
A7: # Código | B7: # Código Netsuite | C7: Descripción del ingrediente | D7: Marca | E7: Unidad Internacional | G7: Medida alternativa | I7: Costo - Referencia
E8: Cantidad | F8: Unidad medida | G8: Cantidad | H8: Unidad medida | I8: Colones
C9: Ensamble
A10: 310148 | B10: MP10047 | C10: BETTERCREME SUPREMO (UND:4 K) | D10: RICHS | E10: 8000 | F10: g | H10: 2 GALON
A11: 11400031 | B11: MP10048 | C11: CREMA PRESTIGE GRAND (UND:4 K) | D11: RICHS | E11: 12000 | F11: g | H11: 3 GALON
A12: 10415 | C12: AGUA POTABLE (PLANTA) | D12: AYA | E12: 50 | F12: g
A13: 1212410 | B13: MP10008 | C13: PRESERVANTE 1047S (PAQ=5 KILO) | D13: ASEAL | E13: 15 | F13: g
C17: Decoración
C26: Empaque
A27: 702123 | B27: EM10011 | C27: ETIQUETA BLANCA 2 5/8X1 15/16 (UND) | D27: ETIPLAST | E27: 1 | F27: ud
D37: Cantidad | E37: Unidad
A38: PESO TOTAL OBTENIDO | D38: 20000 | E38: g | F38: Tiempo de Horneo:
A39: TIEMPO TOTAL DE PREPARACION | D39: 17 | E39: min | F39: Horno:
A40: CANTIDAD DE PORCIONES OBTENIDAS | D40: 1 | E40: Tanda | F40: Temperatura de Horneo:
A41: PESO DE CADA PORCIÓN | D41: 20000 | E41: g | F41: Otros
A42: MERMA | D42: 66 | E42: g
A43: PROCEDIMIENTO DE PREPARACION DE LA RECETA
A44: 1.- Abrir los galones de crema y verter dentro de la top cream (5° en liquido )
A45: 2.- Disolver el preservante en el agua. Agregar a la top cream.
A46: 3.- Batir por 12 a 15 minutos. Colocar en una tina plastica, tapar. (Temperatura de 18°)
A47: 4.- Etiquetar con nombre y fecha de vencimiento.
A48: 5.- Mantener en refrigeración.
A53: CONTROL DE CAMBIOS
A54: Revisión#2, Se actualizan tiempos de preparación y se agrega temperaturas adecuadas.

Sheet Costo Relleno Crema Pinito
E1: Precio Local | F1: Costo MP | G1: Costo EM | H1: Costo MO
E2: =IFERROR(O62,"") -> 37376.922 | F2: =IFERROR(H53,"") -> 35779 | G2: =IFERROR(H54,"") -> 0 | H2: =IFERROR(H56,"") -> 769
A5: ESTRUCTURA DE COSTOS
F6: Fecha: | H6: =TODAY() -> 46139
A7: UNIDADES | B7: DESCRIPCION MAT.PRIMA | C7: UNIDADES | D7: UND MEDIDA | E7: COSTO UNITARIO | F7: TOTAL COSTO | G7: % PREC. DEFINIDO | H7: CODIGOS
A8: 2500 | B8: =IFERROR(VLOOKUP(H8,'[1]Consolidado MP Planta'!$A$2:$M$823,3,0),"") -> LECHE POLVO INDUSTRIAL (SACO:25 KG) | C8: =+A8 -> 2500 | D8: =IFERROR(VLOOKUP(H8,'[1]Consolidado MP Planta'!$A$2:$M$823,13,0),"") -> Gramos | E8: 3.15 | F8: =IFERROR(C8*E8,"") -> 7875 | G8: =IFERROR(F8/$F$66,"") -> 0.2135328 | H8: 0310145
B9: =IFERROR(VLOOKUP(H9,'[1]Consolidado MP Planta'!$A$2:$M$823,3,0),"") | C9: =+A9 -> 0 | D9: =IFERROR(VLOOKUP(H9,'[1]Consolidado MP Planta'!$A$2:$M$823,13,0),"") | E9: =IFERROR(VLOOKUP(H9,'[1]Consolidado MP Planta'!$A$2:$M$823,12,0),"") | F9: =IFERROR(C9*E9,"") | G9: =IFERROR(F9/$F$66,"")
B10: =IFERROR(VLOOKUP(H10,'[1]Consolidado MP Planta'!$A$2:$M$823,3,0),"") | C10: =+A10 -> 0 | D10: =IFERROR(VLOOKUP(H10,'[1]Consolidado MP Planta'!$A$2:$M$823,13,0),"") | E10: =IFERROR(VLOOKUP(H10,'[1]Consolidado MP Planta'!$A$2:$M$823,12,0),"") | F10: =IFERROR(C10*E10,"") | G10: =IFERROR(F10/$F$66,"")
B11: =IFERROR(VLOOKUP(H11,'[1]Consolidado MP Planta'!$A$2:$M$823,3,0),"") | C11: =+A11 -> 0 | D11: =IFERROR(VLOOKUP(H11,'[1]Consolidado MP Planta'!$A$2:$M$823,13,0),"") | E11: =IFERROR(VLOOKUP(H11,'[1]Consolidado MP Planta'!$A$2:$M$823,12,0),"") | F11: =IFERROR(C11*E11,"") | G11: =IFERROR(F11/$F$66,"")
B12: =IFERROR(VLOOKUP(H12,'[1]Consolidado MP Planta'!$A$2:$M$823,3,0),"") | C12: =+A12 -> 0 | D12: =IFERROR(VLOOKUP(H12,'[1]Consolidado MP Planta'!$A$2:$M$823,13,0),"") | E12: =IFERROR(VLOOKUP(H12,'[1]Consolidado MP Planta'!$A$2:$M$823,12,0),"") | F12: =IFERROR(C12*E12,"") | G12: =IFERROR(F12/$F$66,"")
B13: =IFERROR(VLOOKUP(H13,'[1]Consolidado MP Planta'!$A$2:$M$823,3,0),"") | C13: =+A13 -> 0 | D13: =IFERROR(VLOOKUP(H13,'[1]Consolidado MP Planta'!$A$2:$M$823,13,0),"") | E13: =IFERROR(VLOOKUP(H13,'[1]Consolidado MP Planta'!$A$2:$M$823,12,0),"") | F13: =IFERROR(C13*E13,"") | G13: =IFERROR(F13/$F$66,"")
B14: =IFERROR(VLOOKUP(H14,'[1]Consolidado MP Planta'!$A$2:$M$823,3,0),"") | C14: =+A14 -> 0 | D14: =IFERROR(VLOOKUP(H14,'[1]Consolidado MP Planta'!$A$2:$M$823,13,0),"") | E14: =IFERROR(VLOOKUP(H14,'[1]Consolidado MP Planta'!$A$2:$M$823,12,0),"") | F14: =IFERROR(C14*E14,"") | G14: =IFERROR(F14/$F$66,"")
B15: =IFERROR(VLOOKUP(H15,[2]Hoja2!$A$2:$G$589,2,0),"")
A16: UNIDADES | B16: MATERIA PRIMA SEMIELABORADOS | C16: UNIDADES | D16: UND MEDIDA | E16: COSTO UNITARIO | F16: TOTAL COSTO | G16: % PREC. DEFINIDO | H16: CODIGOS
A17: 12800 | B17: Crema Chantilly Blanca (Spoon-Ind) | C17: =+A17 -> 12800 | D17: Gramos | E17: 2.18 | F17: =IFERROR(E17*C17,"") -> 27904 | G17: =IFERROR(F17/$F$66,"") -> 0.75662467 | H17: SE00010
B18: =IFERROR(VLOOKUP(H18,[1]SEMIELABORADOS!$A$2:$M$6000,2,0),"") | C18: =+A18 -> 0 | D18: =IFERROR(VLOOKUP(H18,[1]SEMIELABORADOS!$A$2:$M$6000,6,0),"") | E18: =IFERROR(VLOOKUP(H18,[1]SEMIELABORADOS!$A$2:$H$65536,8,0),"") | F18: =IFERROR(E18*C18,"") | G18: =IFERROR(F18/$F$66,"")
B19: =IFERROR(VLOOKUP(H19,[1]SEMIELABORADOS!$A$2:$M$6000,2,0),"") | C19: =+A19 -> 0 | D19: =IFERROR(VLOOKUP(H19,[1]SEMIELABORADOS!$A$2:$M$6000,6,0),"") | E19: =IFERROR(VLOOKUP(H19,[1]SEMIELABORADOS!$A$2:$H$65536,8,0),"") | F19: =IFERROR(E19*C19,"") | G19: =IFERROR(F19/$F$66,"")
B20: =IFERROR(VLOOKUP(H20,[1]SEMIELABORADOS!$A$2:$M$6000,2,0),"") | C20: =+A20 -> 0 | D20: =IFERROR(VLOOKUP(H20,[1]SEMIELABORADOS!$A$2:$M$6000,6,0),"") | E20: =IFERROR(VLOOKUP(H20,[1]SEMIELABORADOS!$A$2:$H$65536,8,0),"") | F20: =IFERROR(E20*C20,"") | G20: =IFERROR(F20/$F$66,"")
B21: =IFERROR(VLOOKUP(H21,[1]SEMIELABORADOS!$A$2:$M$6000,2,0),"") | C21: =+A21 -> 0 | D21: =IFERROR(VLOOKUP(H21,[1]SEMIELABORADOS!$A$2:$M$6000,6,0),"") | E21: =IFERROR(VLOOKUP(H21,[1]SEMIELABORADOS!$A$2:$H$65536,8,0),"") | F21: =IFERROR(E21*C21,"") | G21: =IFERROR(F21/$F$66,"")
B22: =IFERROR(VLOOKUP(H22,[1]SEMIELABORADOS!$A$2:$M$6000,2,0),"") | C22: =+A22 -> 0 | D22: =IFERROR(VLOOKUP(H22,[1]SEMIELABORADOS!$A$2:$M$6000,6,0),"") | E22: =IFERROR(VLOOKUP(H22,[1]SEMIELABORADOS!$A$2:$H$65536,8,0),"") | F22: =IFERROR(E22*C22,"") | G22: =IFERROR(F22/$F$66,"")
B23: =IFERROR(VLOOKUP(H23,[1]SEMIELABORADOS!$A$2:$M$6000,2,0),"") | C23: =+A23 -> 0 | D23: =IFERROR(VLOOKUP(H23,[1]SEMIELABORADOS!$A$2:$M$6000,6,0),"") | E23: =IFERROR(VLOOKUP(H23,[1]SEMIELABORADOS!$A$2:$H$65536,8,0),"") | F23: =IFERROR(E23*C23,"") | G23: =IFERROR(F23/$F$66,"")
B24: =IFERROR(VLOOKUP(H24,[1]SEMIELABORADOS!$A$2:$M$6000,2,0),"") | C24: =+A24 -> 0 | D24: =IFERROR(VLOOKUP(H24,[1]SEMIELABORADOS!$A$2:$M$6000,6,0),"") | E24: =IFERROR(VLOOKUP(H24,[1]SEMIELABORADOS!$A$2:$H$65536,8,0),"") | F24: =IFERROR(E24*C24,"") | G24: =IFERROR(F24/$F$66,"")
A26: UNIDADES | B26: EMPAQUE | C26: UNIDADES | D26: UND MEDIDA | E26: COSTO UNITARIO | F26: TOTAL COSTO | G26: % PREC. DEFINIDO | H26: CODIGOS
A27: 0 | B27: =IFERROR(VLOOKUP(H27,'[1]Consolidado MP Planta'!$A$2:$M$823,3,0),"") | C27: =+A27 -> 0 | D27: =IFERROR(VLOOKUP(H27,'[1]Consolidado MP Planta'!$A$2:$M$823,13,0),"") | E27: =IFERROR(VLOOKUP(H27,'[1]Consolidado MP Planta'!$A$2:$M$823,12,0),"") | F27: =IFERROR(C27*E27,"") | G27: =IFERROR(F27/$F$66,"")
B28: =IFERROR(VLOOKUP(H28,'[1]Consolidado MP Planta'!$A$2:$M$823,3,0),"") | C28: =+A28 -> 0 | D28: =IFERROR(VLOOKUP(H28,'[1]Consolidado MP Planta'!$A$2:$M$823,13,0),"") | E28: =IFERROR(VLOOKUP(H28,'[1]Consolidado MP Planta'!$A$2:$M$823,12,0),"") | F28: =IFERROR(C28*E28,"") | G28: =IFERROR(F28/$F$66,"")
B29: =IFERROR(VLOOKUP(H29,'[1]Consolidado MP Planta'!$A$2:$M$823,3,0),"") | C29: =+A29 -> 0 | D29: =IFERROR(VLOOKUP(H29,'[1]Consolidado MP Planta'!$A$2:$M$823,13,0),"") | E29: =IFERROR(VLOOKUP(H29,'[1]Consolidado MP Planta'!$A$2:$M$823,12,0),"") | F29: =IFERROR(C29*E29,"") | G29: =IFERROR(F29/$F$66,"")
B30: =IFERROR(VLOOKUP(H30,'[1]Consolidado MP Planta'!$A$2:$M$823,3,0),"") | C30: =+A30 -> 0 | D30: =IFERROR(VLOOKUP(H30,'[1]Consolidado MP Planta'!$A$2:$M$823,13,0),"") | E30: =IFERROR(VLOOKUP(H30,'[1]Consolidado MP Planta'!$A$2:$M$823,12,0),"") | F30: =IFERROR(C30*E30,"") | G30: =IFERROR(F30/$F$66,"")
B31: =IFERROR(VLOOKUP(H31,'[1]Consolidado MP Planta'!$A$2:$M$823,3,0),"") | C31: =+A31 -> 0 | D31: =IFERROR(VLOOKUP(H31,'[1]Consolidado MP Planta'!$A$2:$M$823,13,0),"") | E31: =IFERROR(VLOOKUP(H31,'[1]Consolidado MP Planta'!$A$2:$M$823,12,0),"") | F31: =IFERROR(C31*E31,"") | G31: =IFERROR(F31/$F$66,"")
B32: =IFERROR(VLOOKUP(H32,'[1]Consolidado MP Planta'!$A$2:$M$823,3,0),"") | C32: =+A32 -> 0 | D32: =IFERROR(VLOOKUP(H32,'[1]Consolidado MP Planta'!$A$2:$M$823,13,0),"") | E32: =IFERROR(VLOOKUP(H32,'[1]Consolidado MP Planta'!$A$2:$M$823,12,0),"") | F32: =IFERROR(C32*E32,"") | G32: =IFERROR(F32/$F$66,"")
A34: UNIDADES | B34: EMPAQUE SEMIELABORADOS | C34: UNIDADES | D34: UND MEDIDA | E34: COSTO UNITARIO | F34: TOTAL COSTO | G34: % PREC. DEFINIDO | H34: CODIGOS
A35: =+A17 -> 12800 | B35: Crema Chantilly Blanca (Spoon-Ind) | C35: =+A35 -> 12800 | D35: Gramos | E35: 0 | F35: =IFERROR(E35*C35,"") -> 0 | G35: =IFERROR(F35/$F$66,"") -> 0 | H35: SE00010
A36: =+A18 -> 0 | B36: =IFERROR(VLOOKUP(H36,[1]SEMIELABORADOS!$A$2:$M$6000,2,0),"") | C36: =+A36 -> 0 | D36: =IFERROR(VLOOKUP(H36,[1]SEMIELABORADOS!$A$2:$M$6000,6,0),"") | E36: =IFERROR(VLOOKUP(H36,[1]SEMIELABORADOS!$A$2:$M$65536,10,0),"") | F36: =IFERROR(E36*C36,"") | G36: =IFERROR(F36/$F$66,"")
A37: =+A19 -> 0 | B37: =IFERROR(VLOOKUP(H37,[1]SEMIELABORADOS!$A$2:$M$6000,2,0),"") | C37: =+A37 -> 0 | D37: =IFERROR(VLOOKUP(H37,[1]SEMIELABORADOS!$A$2:$M$6000,6,0),"") | E37: =IFERROR(VLOOKUP(H37,[1]SEMIELABORADOS!$A$2:$M$65536,10,0),"") | F37: =IFERROR(E37*C37,"") | G37: =IFERROR(F37/$F$66,"")
A38: =+A20 -> 0 | B38: =IFERROR(VLOOKUP(H38,[1]SEMIELABORADOS!$A$2:$M$6000,2,0),"") | C38: =+A38 -> 0 | D38: =IFERROR(VLOOKUP(H38,[1]SEMIELABORADOS!$A$2:$M$6000,6,0),"") | E38: =IFERROR(VLOOKUP(H38,[1]SEMIELABORADOS!$A$2:$M$65536,10,0),"") | F38: =IFERROR(E38*C38,"") | G38: =IFERROR(F38/$F$66,"")
A39: =+A21 -> 0 | B39: =IFERROR(VLOOKUP(H39,[1]SEMIELABORADOS!$A$2:$M$6000,2,0),"") | C39: =+A39 -> 0 | D39: =IFERROR(VLOOKUP(H39,[1]SEMIELABORADOS!$A$2:$M$6000,6,0),"") | E39: =IFERROR(VLOOKUP(H39,[1]SEMIELABORADOS!$A$2:$M$65536,10,0),"") | F39: =IFERROR(E39*C39,"") | G39: =IFERROR(F39/$F$66,"")
A40: =+A22 -> 0 | B40: =IFERROR(VLOOKUP(H40,[1]SEMIELABORADOS!$A$2:$M$6000,2,0),"") | C40: =+A40 -> 0 | D40: =IFERROR(VLOOKUP(H40,[1]SEMIELABORADOS!$A$2:$M$6000,6,0),"") | E40: =IFERROR(VLOOKUP(H40,[1]SEMIELABORADOS!$A$2:$M$65536,10,0),"") | F40: =IFERROR(E40*C40,"") | G40: =IFERROR(F40/$F$66,"")
A41: =+A23 -> 0 | B41: =IFERROR(VLOOKUP(H41,[1]SEMIELABORADOS!$A$2:$M$6000,2,0),"") | C41: =+A41 -> 0 | D41: =IFERROR(VLOOKUP(H41,[1]SEMIELABORADOS!$A$2:$M$6000,6,0),"") | E41: =IFERROR(VLOOKUP(H41,[1]SEMIELABORADOS!$A$2:$M$65536,10,0),"") | F41: =IFERROR(E41*C41,"") | G41: =IFERROR(F41/$F$66,"")
A43: UNIDADES | B43: MODI | C43: UNIDADES | D43: UND MEDIDA | E43: COSTO UNITARIO | F43: TOTAL COSTO | G43: % PREC. DEFINIDO | H43: CODIGOS
A44: =+A35 -> 12800 | B44: Crema Chantilly Blanca (Spoon-Ind) | C44: =+A44 -> 12800 | D44: Gramos | E44: 0.03 | F44: =IFERROR(E44*C44,"") -> 384 | G44: =IFERROR(F44/$F$66,"") -> 0.010412266 | H44: SE00010
A45: =+A36 -> 0 | B45: =IFERROR(VLOOKUP(H45,[1]SEMIELABORADOS!$A$2:$M$6000,2,0),"") | C45: =+A45 -> 0 | D45: =IFERROR(VLOOKUP(H45,[1]SEMIELABORADOS!$A$2:$M$6000,6,0),"") | E45: =IFERROR(VLOOKUP(H45,[1]SEMIELABORADOS!$A$2:$M$65536,12,0),"") | F45: =IFERROR(E45*C45,"") | G45: =IFERROR(F45/$F$66,"")
...

Sheet Crema Chantilly Blanca  
C1: SERVICIOS DE PASTELERIA S.A. | H1: CÓDIGO: | I1: ESP-RE-DES-018
C2: ESPECIFICACION DE RECETA | H2: REVISIÓN: | I2: 02
C3: Crema Blanca Spoon (20800g) SE00010 | H3: FECHA DE APROBACIÓN: | I3: 45613
C4: Elaborado | D4: Javier Tong, Chef
C5: Aprobado | D5: Esteban Cartin, Gte Manufactura
A6: AREA QUE PRODUCE: | D6: Decoración | G6: AREA QUE EMPACA: | I6: Decoracion
A7: # Código | B7: # Código Netsuite | C7: Descripción del ingrediente | D7: Marca | E7: Unidad Internacional | G7: Medida alternativa | I7: Costo - Referencia
E8: Cantidad | F8: Unidad medida | G8: Cantidad | H8: Unidad medida | I8: Colones
C9: Ensamble
A10: 310148 | B10: MP10047 | C10: BETTERCREME SUPREMO (UND:4 K) | D10: RICHS | E10: 12800 | F10: g
A11: 11400031 | B11: MP10048 | C11: CREMA PRESTIGE GRAND (UND:4 K) | D11: RICHS | E11: 3200 | F11: g
A12: 10415 | C12: AGUA POTABLE (PLANTA) | D12: AYA | E12: 800 | F12: g
A13: 1212410 | B13: MP10008 | C13: PRESERVANTE 1047S (PAQ=5 KILO) | D13: ASEAL | E13: 12 | F13: g
C20: Decoración
C29: Empaque
A30: 702123 | B30: EM10011 | C30: ETIQUETA BLANCA 2 5/8X1 15/16 (UND) | D30: Etiplas | E30: 1 | F30: ud
D40: Cantidad | E40: Unidad
A41: PESO TOTAL OBTENIDO | D41: 16597 | E41: g | F41: Tiempo de Horneo:
A42: TIEMPO TOTAL DE PREPARACION | D42: 17 | E42: min | F42: Horno:
A43: CANTIDAD DE PORCIONES OBTENIDAS | D43: 1 | E43: Tanda | F43: Temperatura de Horneo:
A44: PESO DE CADA PORCIÓN | D44: 16597 | E44: g | F44: Otros
A45: MERMA | D45: 215 | E45: g
A46: PROCEDIMIENTO DE PREPARACION DE LA RECETA
A47: 1.- Abrir los galones de crema y verter dentro de la top cream. (Temperatura 5° liquida )
A48: 2.- Disolver el preservante en el agua. Agregar a la top cream.
A49: 3.- Batir por 17 minutos. Una ves lista (Temperatura 18° batida) Colocar en una tina plastica, tapar.
A50: 4.- Etiquetar con nombre y fecha de vencimiento.
A51: 5.- Mantener en refrigeración hasta su uso.
A56: CONTROL DE CAMBIOS
A57: 2, Actualización tiempo de preparación y procedimiento

Sheet Relleno Cajeta 
C1: SERVICIOS DE PASTELERIA S.A. | H1: CÓDIGO: | I1: ESP-RE-POF-060
C2: ESPECIFICACION DE RECETA | H2: REVISIÓN: | I2: 03
C3: SE00830 Relleno Cajeta | H3: FECHA DE APROBACIÓN: | I3: 46094
C4: Elaborado | D4: Jose Sanchez Madriz, Chef
C5: Aprobado | D5: Sebastian Díaz, Gte Manufactura
A6: AREA QUE PRODUCE: | D6: Postres | G6: AREA QUE EMPACA: | I6: Postres
A7: # Código | B7: # Código Netsuite | C7: Descripción del ingrediente | D7: Marca | E7: Unidad Internacional | G7: Medida alternativa | I7: Costo - Referencia
E8: Cantidad | F8: Unidad medida | G8: Cantidad | H8: Unidad medida | I8: Colones
C9: Ensamble
B10: MP10940 | C10: Leche en polvo Pinito | D10: PINITO | E10: 3600 | F10: g
B11: MP10941 | C11: Leche Condensada Pinito | D11: PINITO | E11: 11500 | F11: g
C13: DECORACIÓN | P13: =970/397 -> 2.4433249
C15: EMPAQUE
D18: Cantidad | E18: Unidad
A19: PESO TOTAL OBTENIDO | D19: 15000 | E19: g | F19: Tiempo de Horneo:
A20: TIEMPO TOTAL DE PREPARACION | D20: 5 | E20: min | F20: Horno:
A21: CANTIDAD DE PORCIONES OBTENIDAS | D21: 1 | E21: Tanda | F21: Temperatura de Horneo:
A22: PESO DE CADA PORCIÓN | D22: 15000 | E22: g | F22: Otros
A23: MERMA | D23: =SUM(E10:E11)-D19 -> 100 | E23: g
A24: PROCEDIMIENTO DE PREPARACION DE LA RECETA
A25: 1, Colocar en la batidora con ayuda de la paleta, la leche condensada y la leche en polvo y resolver hasta que quede bien incorporado.
A26: 2, Pasar a una tina y guardar.
A28: CONTROL DE CAMBIOS
A29: 2, Cambio leche en polvo por leche en polvo Pinito
A30: Revision #3: Actualizacion de codigos de las leches

Sheet Costo relleno Cajeta
E1: Precio Local | F1: Costo MP | G1: Costo EM | H1: Costo MO
E2: =IFERROR(O62,"") -> 37325 | F2: =IFERROR(H53,"") -> 36525 | G2: =IFERROR(H54,"") -> 0 | H2: =IFERROR(H56,"") -> 385
A5: ESTRUCTURA DE COSTOS
F6: Fecha: | H6: =TODAY() -> 46139
A7: UNIDADES | B7: DESCRIPCION MAT.PRIMA | C7: UNIDADES | D7: UND MEDIDA | E7: COSTO UNITARIO | F7: TOTAL COSTO | G7: % PREC. DEFINIDO | H7: CODIGOS
A8: 3600 | B8: =IFERROR(VLOOKUP(H8,'[1]Consolidado MP Planta'!$A$2:$M$823,3,0),"") -> LECHE POLVO INDUSTRIAL (SACO:25 KG) | C8: =+A8 -> 3600 | D8: =IFERROR(VLOOKUP(H8,'[1]Consolidado MP Planta'!$A$2:$M$823,13,0),"") -> Gramos | E8: 3.15 | F8: =IFERROR(C8*E8,"") -> 11340 | G8: =IFERROR(F8/$F$66,"") -> 0.30127124 | H8: 0310145 | K8: 96
A9: 11500 | B9: Leche Condensada Pinito | C9: =+A9 -> 11500 | D9: Gramos | E9: 2.19 | F9: =IFERROR(C9*E9,"") -> 25185 | G9: =IFERROR(F9/$F$66,"") -> 0.66909313 | K9: 306
B10: =IFERROR(VLOOKUP(H10,'[1]Consolidado MP Planta'!$A$2:$M$823,3,0),"") | C10: =+A10 -> 0 | D10: =IFERROR(VLOOKUP(H10,'[1]Consolidado MP Planta'!$A$2:$M$823,13,0),"") | E10: =IFERROR(VLOOKUP(H10,'[1]Consolidado MP Planta'!$A$2:$M$823,12,0),"") | F10: =IFERROR(C10*E10,"") | G10: =IFERROR(F10/$F$66,"")
B11: =IFERROR(VLOOKUP(H11,'[1]Consolidado MP Planta'!$A$2:$M$823,3,0),"") | C11: =+A11 -> 0 | D11: =IFERROR(VLOOKUP(H11,'[1]Consolidado MP Planta'!$A$2:$M$823,13,0),"") | E11: =IFERROR(VLOOKUP(H11,'[1]Consolidado MP Planta'!$A$2:$M$823,12,0),"") | F11: =IFERROR(C11*E11,"") | G11: =IFERROR(F11/$F$66,"")
B12: =IFERROR(VLOOKUP(H12,'[1]Consolidado MP Planta'!$A$2:$M$823,3,0),"") | C12: =+A12 -> 0 | D12: =IFERROR(VLOOKUP(H12,'[1]Consolidado MP Planta'!$A$2:$M$823,13,0),"") | E12: =IFERROR(VLOOKUP(H12,'[1]Consolidado MP Planta'!$A$2:$M$823,12,0),"") | F12: =IFERROR(C12*E12,"") | G12: =IFERROR(F12/$F$66,"")
B13: =IFERROR(VLOOKUP(H13,'[1]Consolidado MP Planta'!$A$2:$M$823,3,0),"") | C13: =+A13 -> 0 | D13: =IFERROR(VLOOKUP(H13,'[1]Consolidado MP Planta'!$A$2:$M$823,13,0),"") | E13: =IFERROR(VLOOKUP(H13,'[1]Consolidado MP Planta'!$A$2:$M$823,12,0),"") | F13: =IFERROR(C13*E13,"") | G13: =IFERROR(F13/$F$66,"")
B14: =IFERROR(VLOOKUP(H14,'[1]Consolidado MP Planta'!$A$2:$M$823,3,0),"") | C14: =+A14 -> 0 | D14: =IFERROR(VLOOKUP(H14,'[1]Consolidado MP Planta'!$A$2:$M$823,13,0),"") | E14: =IFERROR(VLOOKUP(H14,'[1]Consolidado MP Planta'!$A$2:$M$823,12,0),"") | F14: =IFERROR(C14*E14,"") | G14: =IFERROR(F14/$F$66,"")
B15: =IFERROR(VLOOKUP(H15,[2]Hoja2!$A$2:$G$589,2,0),"")
A16: UNIDADES | B16: MATERIA PRIMA SEMIELABORADOS | C16: UNIDADES | D16: UND MEDIDA | E16: COSTO UNITARIO | F16: TOTAL COSTO | G16: % PREC. DEFINIDO | H16: CODIGOS
B17: =IFERROR(VLOOKUP(H17,[1]SEMIELABORADOS!$A$2:$M$6000,2,0),"") | C17: =+A17 -> 0 | D17: =IFERROR(VLOOKUP(H17,[1]SEMIELABORADOS!$A$2:$M$6000,6,0),"") | E17: =IFERROR(VLOOKUP(H17,[1]SEMIELABORADOS!$A$2:$H$65536,8,0),"") | F17: =IFERROR(E17*C17,"") | G17: =IFERROR(F17/$F$66,"")
B18: =IFERROR(VLOOKUP(H18,[1]SEMIELABORADOS!$A$2:$M$6000,2,0),"") | C18: =+A18 -> 0 | D18: =IFERROR(VLOOKUP(H18,[1]SEMIELABORADOS!$A$2:$M$6000,6,0),"") | E18: =IFERROR(VLOOKUP(H18,[1]SEMIELABORADOS!$A$2:$H$65536,8,0),"") | F18: =IFERROR(E18*C18,"") | G18: =IFERROR(F18/$F$66,"")
B19: =IFERROR(VLOOKUP(H19,[1]SEMIELABORADOS!$A$2:$M$6000,2,0),"") | C19: =+A19 -> 0 | D19: =IFERROR(VLOOKUP(H19,[1]SEMIELABORADOS!$A$2:$M$6000,6,0),"") | E19: =IFERROR(VLOOKUP(H19,[1]SEMIELABORADOS!$A$2:$H$65536,8,0),"") | F19: =IFERROR(E19*C19,"") | G19: =IFERROR(F19/$F$66,"")
B20: =IFERROR(VLOOKUP(H20,[1]SEMIELABORADOS!$A$2:$M$6000,2,0),"") | C20: =+A20 -> 0 | D20: =IFERROR(VLOOKUP(H20,[1]SEMIELABORADOS!$A$2:$M$6000,6,0),"") | E20: =IFERROR(VLOOKUP(H20,[1]SEMIELABORADOS!$A$2:$H$65536,8,0),"") | F20: =IFERROR(E20*C20,"") | G20: =IFERROR(F20/$F$66,"")
B21: =IFERROR(VLOOKUP(H21,[1]SEMIELABORADOS!$A$2:$M$6000,2,0),"") | C21: =+A21 -> 0 | D21: =IFERROR(VLOOKUP(H21,[1]SEMIELABORADOS!$A$2:$M$6000,6,0),"") | E21: =IFERROR(VLOOKUP(H21,[1]SEMIELABORADOS!$A$2:$H$65536,8,0),"") | F21: =IFERROR(E21*C21,"") | G21: =IFERROR(F21/$F$66,"")
B22: =IFERROR(VLOOKUP(H22,[1]SEMIELABORADOS!$A$2:$M$6000,2,0),"") | C22: =+A22 -> 0 | D22: =IFERROR(VLOOKUP(H22,[1]SEMIELABORADOS!$A$2:$M$6000,6,0),"") | E22: =IFERROR(VLOOKUP(H22,[1]SEMIELABORADOS!$A$2:$H$65536,8,0),"") | F22: =IFERROR(E22*C22,"") | G22: =IFERROR(F22/$F$66,"")
B23: =IFERROR(VLOOKUP(H23,[1]SEMIELABORADOS!$A$2:$M$6000,2,0),"") | C23: =+A23 -> 0 | D23: =IFERROR(VLOOKUP(H23,[1]SEMIELABORADOS!$A$2:$M$6000,6,0),"") | E23: =IFERROR(VLOOKUP(H23,[1]SEMIELABORADOS!$A$2:$H$65536,8,0),"") | F23: =IFERROR(E23*C23,"") | G23: =IFERROR(F23/$F$66,"")
B24: =IFERROR(VLOOKUP(H24,[1]SEMIELABORADOS!$A$2:$M$6000,2,0),"") | C24: =+A24 -> 0 | D24: =IFERROR(VLOOKUP(H24,[1]SEMIELABORADOS!$A$2:$M$6000,6,0),"") | E24: =IFERROR(VLOOKUP(H24,[1]SEMIELABORADOS!$A$2:$H$65536,8,0),"") | F24: =IFERROR(E24*C24,"") | G24: =IFERROR(F24/$F$66,"")
A26: UNIDADES | B26: EMPAQUE | C26: UNIDADES | D26: UND MEDIDA | E26: COSTO UNITARIO | F26: TOTAL COSTO | G26: % PREC. DEFINIDO | H26: CODIGOS
A27: 0 | B27: =IFERROR(VLOOKUP(H27,'[1]Consolidado MP Planta'!$A$2:$M$823,3,0),"") | C27: =+A27 -> 0 | D27: =IFERROR(VLOOKUP(H27,'[1]Consolidado MP Planta'!$A$2:$M$823,13,0),"") | E27: =IFERROR(VLOOKUP(H27,'[1]Consolidado MP Planta'!$A$2:$M$823,12,0),"") | F27: =IFERROR(C27*E27,"") | G27: =IFERROR(F27/$F$66,"")
B28: =IFERROR(VLOOKUP(H28,'[1]Consolidado MP Planta'!$A$2:$M$823,3,0),"") | C28: =+A28 -> 0 | D28: =IFERROR(VLOOKUP(H28,'[1]Consolidado MP Planta'!$A$2:$M$823,13,0),"") | E28: =IFERROR(VLOOKUP(H28,'[1]Consolidado MP Planta'!$A$2:$M$823,12,0),"") | F28: =IFERROR(C28*E28,"") | G28: =IFERROR(F28/$F$66,"")
B29: =IFERROR(VLOOKUP(H29,'[1]Consolidado MP Planta'!$A$2:$M$823,3,0),"") | C29: =+A29 -> 0 | D29: =IFERROR(VLOOKUP(H29,'[1]Consolidado MP Planta'!$A$2:$M$823,13,0),"") | E29: =IFERROR(VLOOKUP(H29,'[1]Consolidado MP Planta'!$A$2:$M$823,12,0),"") | F29: =IFERROR(C29*E29,"") | G29: =IFERROR(F29/$F$66,"")
B30: =IFERROR(VLOOKUP(H30,'[1]Consolidado MP Planta'!$A$2:$M$823,3,0),"") | C30: =+A30 -> 0 | D30: =IFERROR(VLOOKUP(H30,'[1]Consolidado MP Planta'!$A$2:$M$823,13,0),"") | E30: =IFERROR(VLOOKUP(H30,'[1]Consolidado MP Planta'!$A$2:$M$823,12,0),"") | F30: =IFERROR(C30*E30,"") | G30: =IFERROR(F30/$F$66,"")
B31: =IFERROR(VLOOKUP(H31,'[1]Consolidado MP Planta'!$A$2:$M$823,3,0),"") | C31: =+A31 -> 0 | D31: =IFERROR(VLOOKUP(H31,'[1]Consolidado MP Planta'!$A$2:$M$823,13,0),"") | E31: =IFERROR(VLOOKUP(H31,'[1]Consolidado MP Planta'!$A$2:$M$823,12,0),"") | F31: =IFERROR(C31*E31,"") | G31: =IFERROR(F31/$F$66,"")
B32: =IFERROR(VLOOKUP(H32,'[1]Consolidado MP Planta'!$A$2:$M$823,3,0),"") | C32: =+A32 -> 0 | D32: =IFERROR(VLOOKUP(H32,'[1]Consolidado MP Planta'!$A$2:$M$823,13,0),"") | E32: =IFERROR(VLOOKUP(H32,'[1]Consolidado MP Planta'!$A$2:$M$823,12,0),"") | F32: =IFERROR(C32*E32,"") | G32: =IFERROR(F32/$F$66,"")
A34: UNIDADES | B34: EMPAQUE SEMIELABORADOS | C34: UNIDADES | D34: UND MEDIDA | E34: COSTO UNITARIO | F34: TOTAL COSTO | G34: % PREC. DEFINIDO | H34: CODIGOS
A35: =+A17 -> 0 | B35: =IFERROR(VLOOKUP(H35,[1]SEMIELABORADOS!$A$2:$M$6000,2,0),"") | C35: =+A35 -> 0 | D35: =IFERROR(VLOOKUP(H35,[1]SEMIELABORADOS!$A$2:$M$6000,6,0),"") | E35: =IFERROR(VLOOKUP(H35,[1]SEMIELABORADOS!$A$2:$M$65536,10,0),"") | F35: =IFERROR(E35*C35,"") | G35: =IFERROR(F35/$F$66,"")
A36: =+A18 -> 0 | B36: =IFERROR(VLOOKUP(H36,[1]SEMIELABORADOS!$A$2:$M$6000,2,0),"") | C36: =+A36 -> 0 | D36: =IFERROR(VLOOKUP(H36,[1]SEMIELABORADOS!$A$2:$M$6000,6,0),"") | E36: =IFERROR(VLOOKUP(H36,[1]SEMIELABORADOS!$A$2:$M$65536,10,0),"") | F36: =IFERROR(E36*C36,"") | G36: =IFERROR(F36/$F$66,"")
A37: =+A19 -> 0 | B37: =IFERROR(VLOOKUP(H37,[1]SEMIELABORADOS!$A$2:$M$6000,2,0),"") | C37: =+A37 -> 0 | D37: =IFERROR(VLOOKUP(H37,[1]SEMIELABORADOS!$A$2:$M$6000,6,0),"") | E37: =IFERROR(VLOOKUP(H37,[1]SEMIELABORADOS!$A$2:$M$65536,10,0),"") | F37: =IFERROR(E37*C37,"") | G37: =IFERROR(F37/$F$66,"")
A38: =+A20 -> 0 | B38: =IFERROR(VLOOKUP(H38,[1]SEMIELABORADOS!$A$2:$M$6000,2,0),"") | C38: =+A38 -> 0 | D38: =IFERROR(VLOOKUP(H38,[1]SEMIELABORADOS!$A$2:$M$6000,6,0),"") | E38: =IFERROR(VLOOKUP(H38,[1]SEMIELABORADOS!$A$2:$M$65536,10,0),"") | F38: =IFERROR(E38*C38,"") | G38: =IFERROR(F38/$F$66,"")
A39: =+A21 -> 0 | B39: =IFERROR(VLOOKUP(H39,[1]SEMIELABORADOS!$A$2:$M$6000,2,0),"") | C39: =+A39 -> 0 | D39: =IFERROR(VLOOKUP(H39,[1]SEMIELABORADOS!$A$2:$M$6000,6,0),"") | E39: =IFERROR(VLOOKUP(H39,[1]SEMIELABORADOS!$A$2:$M$65536,10,0),"") | F39: =IFERROR(E39*C39,"") | G39: =IFERROR(F39/$F$66,"")
A40: =+A22 -> 0 | B40: =IFERROR(VLOOKUP(H40,[1]SEMIELABORADOS!$A$2:$M$6000,2,0),"") | C40: =+A40 -> 0 | D40: =IFERROR(VLOOKUP(H40,[1]SEMIELABORADOS!$A$2:$M$6000,6,0),"") | E40: =IFERROR(VLOOKUP(H40,[1]SEMIELABORADOS!$A$2:$M$65536,10,0),"") | F40: =IFERROR(E40*C40,"") | G40: =IFERROR(F40/$F$66,"")
A41: =+A23 -> 0 | B41: =IFERROR(VLOOKUP(H41,[1]SEMIELABORADOS!$A$2:$M$6000,2,0),"") | C41: =+A41 -> 0 | D41: =IFERROR(VLOOKUP(H41,[1]SEMIELABORADOS!$A$2:$M$6000,6,0),"") | E41: =IFERROR(VLOOKUP(H41,[1]SEMIELABORADOS!$A$2:$M$65536,10,0),"") | F41: =IFERROR(E41*C41,"") | G41: =IFERROR(F41/$F$66,"")
A43: UNIDADES | B43: MODI | C43: UNIDADES | D43: UND MEDIDA | E43: COSTO UNITARIO | F43: TOTAL COSTO | G43: % PREC. DEFINIDO | H43: CODIGOS
