Workbook

Sheet Premezcla
C1: SERVICIOS DE PASTELERIA S.A. | H1: CÓDIGO:
C2: ESPECIFICACION DE RECETA | H2: REVISIÓN:
C3: 904000144(NetSuiteCode) Pre mezcla Brownie Spoon | H3: FECHA DE APROBACIÓN:
C4: Elaborado | D4: Juan Pablo Brenes,chef
C5: Aprobado | D5: Esteban Cartin, Gerente de Manufactura
A7: AREA QUE PRODUCE: | D7: Premezclas | G7: AREA QUE EMPACA: | I7: Premezclas
A8: # Código | B8: # Codigo Netsuite | C8: Descripción del ingrediente | D8: Marca | E8: Unidad Internacional | G8: Medida alternativa | I8: Costo - Referencia
E9: Cantidad | F9: Unidad medida | G9: Cantidad | H9: Unidad medida | I9: Colones
A10: 11200070 | C10: HARINA HARISOL HOJALDRE (SACO: 25 K) | D10: FACHASA | E10: 2250 | F10: g
A11: 512316 | C11: CAFÉ INSTANTANEO (PAQ: 500 G) | D11: Nescafe | E11: 200 | F11: g
A12: 10100098 | C12: SAL REFINADA (PAQ:500g) | D12: Mayca | E12: 50 | F12: g
A13: 1212410 | C13: PRESERVANTE 1047S (PAQ=5 KILO) | D13: Mayca | E13: 20 | F13: g
A14: 512255 | C14: COCOA DUTCH PROCESS (SACO: 25 KG) | D14: Nacional chocolates | E14: 600 | F14: g
A16: 902000149 | C16: PROCESADO DE CHOCOLATE RALLADO OSCURO | D16: FAS | E16: 1000 | F16: g
A17: 1210386 | C17: COBERTURA CHOCOLATE LECHE (PAQ:5 K) | D17: Cordillera | E17: 2000 | F17: g
A19: 510301 | C19: AZUCAR BLANCO INDUSTRIAL (SACO:50 K) | D19: Layca | E19: 7500 | F19: g
A22: 1950702 | C22: BOLSA 12x18 TRANSP KILO | D22: Plasticos P | E22: 2 | F22: ud
A23: 1950708 | C23: BOLSA 17x25 TRANSP KILO | D23: Plasticos P | E23: 1 | F23: ud
A24: 702123 | C24: ETIQUETA BLANCA 2 5/8X1 15/16 (UND) | D24: Etiplast | E24: 1 | F24: ud
A25: 60100010 | C25: ETIQUETA ROJA LETRA ALERJENO (UND) | D25: Etiplast | E25: 1 | F25: ud
D28: Cantidad | E28: Unidad
A29: PESO TOTAL OBTENIDO | D29: 13600 | E29: g
A30: TIEMPO TOTAL DE PREPARACION | D30: 4 | E30: min
A31: CANTIDAD DE PORCIONES OBTENIDAS | D31: =D29/D32 -> 1 | E31: ud
A32: PESO DE CADA PORCIÓN | D32: 13600 | E32: g
A33: MERMA | D33: =SUM(E10:E23)-D29 -> 23 | E33: g
A34: PROCEDIMIENTO DE PREPARACION DE LA RECETA
A35: 1.- Pesar en la bolsa 12x10 la harina, café instantaneo, sal, preservante y cocoa.
A36: 2.- Pesar en la bolsa 12x10 el chocolate rallado oscuro y la cobertura de chocolate leche.
A37: 3.- En la bolsa 17x25 pesar el azucar.
A38: 4.- Etiquetar con nombre y alerjeno.

Sheet COSTO PREMEZCLA 
E1: Precio Local | F1: Costo MP | G1: Costo EM | H1: Costo MO
E2: =IFERROR(O62,"") -> 28706.691 | F2: =IFERROR(H53,"") -> 24406.1 | G2: =IFERROR(H54,"") -> 63.461333 | H2: =IFERROR(H56,"") -> 322
A5: ESTRUCTURA DE COSTOS
F6: Fecha: | H6: =TODAY() -> 46155
A7: UNIDADES | B7: DESCRIPCION MAT.PRIMA | C7: UNIDADES | D7: UND MEDIDA | E7: COSTO UNITARIO | F7: TOTAL COSTO | G7: % PREC. DEFINIDO | H7: CODIGOS
A8: 2850 | B8: HARINA HARISOL HOJALDRE (SACO: 25 K) | C8: =+A8 -> 2850 | D8: Gramos | E8: 0.63 | F8: =IFERROR(C8*E8,"") -> 1795.5 | G8: =IFERROR(F8/$F$66,"") -> 0.071279181 | H8: 11200070
A9: 200 | B9: CAFÉ INSTANTANEO (PAQ: 500 G) | C9: =+A9 -> 200 | D9: Gramos | E9: 18.5 | F9: =IFERROR(C9*E9,"") -> 3700 | G9: =IFERROR(F9/$F$66,"") -> 0.14688553 | H9: 512316
A10: 50 | B10: =IFERROR(VLOOKUP(H10,'[1]Consolidado MP Planta'!$A$2:$M$823,3,0),"") -> SAL REFINADA (PAQ:500g) | C10: =+A10 -> 50 | D10: =IFERROR(VLOOKUP(H10,'[1]Consolidado MP Planta'!$A$2:$M$823,13,0),"") -> Gramos | E10: 0.44 | F10: =IFERROR(C10*E10,"") -> 22 | G10: =IFERROR(F10/$F$66,"") -> 0.00087337342 | H10: 10100098
A11: 20 | B11: =IFERROR(VLOOKUP(H11,'[1]Consolidado MP Planta'!$A$2:$M$823,3,0),"") -> PRESERVANTE 1047S (PAQ=5 KILO) | C11: =+A11 -> 20 | D11: =IFERROR(VLOOKUP(H11,'[1]Consolidado MP Planta'!$A$2:$M$823,13,0),"") -> Gramos | E11: 7.88 | F11: =IFERROR(C11*E11,"") -> 157.6 | G11: =IFERROR(F11/$F$66,"") -> 0.0062565296 | H11: 1212410
A12: 600 | B12: COCOA DUTCH PROCESS (SACO: 25 KG) | C12: =+A12 -> 600 | D12: Gramos | E12: 3.15 | F12: =IFERROR(C12*E12,"") -> 1890 | G12: =IFERROR(F12/$F$66,"") -> 0.075030717 | H12: 512255
A13: 2000 | B13: =IFERROR(VLOOKUP(H13,'[1]Consolidado MP Planta'!$A$2:$M$823,3,0),"") -> COBERTURA CHOCOLATE LECHE (PAQ:5 K) | C13: =+A13 -> 2000 | D13: =IFERROR(VLOOKUP(H13,'[1]Consolidado MP Planta'!$A$2:$M$823,13,0),"") -> Gramos | E13: =IFERROR(VLOOKUP(H13,'[1]Consolidado MP Planta'!$A$2:$M$823,12,0),"") -> 4.468 | F13: =IFERROR(C13*E13,"") -> 8936 | G13: =IFERROR(F13/$F$66,"") -> 0.35474841 | H13: 1210386
A14: 7500 | B14: =IFERROR(VLOOKUP(H14,'[1]Consolidado MP Planta'!$A$2:$M$823,3,0),"") -> AZUCAR BLANCO INDUSTRIAL (SACO:50 K) | C14: =+A14 -> 7500 | D14: =IFERROR(VLOOKUP(H14,'[1]Consolidado MP Planta'!$A$2:$M$823,13,0),"") -> Gramos | E14: 0.43 | F14: =IFERROR(C14*E14,"") -> 3225 | G14: =IFERROR(F14/$F$66,"") -> 0.1280286 | H14: 510301
B15: =IFERROR(VLOOKUP(H15,'[2]ARTICULOS MP PLANTA'!$A$2:$G$589,2,0),"")
A16: UNIDADES | B16: MATERIA PRIMA SEMIELABORADOS | C16: UNIDADES | D16: UND MEDIDA | E16: COSTO UNITARIO | F16: TOTAL COSTO | G16: % PREC. DEFINIDO | H16: CODIGOS
A17: 1000 | B17: PROCESADO DE CHOCOLATE RALLADO OSCURO | C17: =+A17 -> 1000 | D17: Gramos | E17: 4.68 | F17: =IFERROR(E17*C17,"") -> 4680 | G17: =IFERROR(F17/$F$66,"") -> 0.18579035 | H17: 902000149
B18: =IFERROR(VLOOKUP(H18,[1]SEMIELABORADOS!$A$2:$M$6000,2,0),"") | C18: =+A18 -> 0 | D18: =IFERROR(VLOOKUP(H18,[1]SEMIELABORADOS!$A$2:$M$6000,6,0),"") | E18: =IFERROR(VLOOKUP(H18,[1]SEMIELABORADOS!$A$2:$H$65536,8,0),"") | F18: =IFERROR(E18*C18,"") | G18: =IFERROR(F18/$F$66,"")
B19: =IFERROR(VLOOKUP(H19,[1]SEMIELABORADOS!$A$2:$M$6000,2,0),"") | C19: =+A19 -> 0 | D19: =IFERROR(VLOOKUP(H19,[1]SEMIELABORADOS!$A$2:$M$6000,6,0),"") | E19: =IFERROR(VLOOKUP(H19,[1]SEMIELABORADOS!$A$2:$H$65536,8,0),"") | F19: =IFERROR(E19*C19,"") | G19: =IFERROR(F19/$F$66,"")
B20: =IFERROR(VLOOKUP(H20,[1]SEMIELABORADOS!$A$2:$M$6000,2,0),"") | C20: =+A20 -> 0 | D20: =IFERROR(VLOOKUP(H20,[1]SEMIELABORADOS!$A$2:$M$6000,6,0),"") | E20: =IFERROR(VLOOKUP(H20,[1]SEMIELABORADOS!$A$2:$H$65536,8,0),"") | F20: =IFERROR(E20*C20,"") | G20: =IFERROR(F20/$F$66,"")
B21: =IFERROR(VLOOKUP(H21,[1]SEMIELABORADOS!$A$2:$M$6000,2,0),"") | C21: =+A21 -> 0 | D21: =IFERROR(VLOOKUP(H21,[1]SEMIELABORADOS!$A$2:$M$6000,6,0),"") | E21: =IFERROR(VLOOKUP(H21,[1]SEMIELABORADOS!$A$2:$H$65536,8,0),"") | F21: =IFERROR(E21*C21,"") | G21: =IFERROR(F21/$F$66,"")
B22: =IFERROR(VLOOKUP(H22,[1]SEMIELABORADOS!$A$2:$M$6000,2,0),"") | C22: =+A22 -> 0 | D22: =IFERROR(VLOOKUP(H22,[1]SEMIELABORADOS!$A$2:$M$6000,6,0),"") | E22: =IFERROR(VLOOKUP(H22,[1]SEMIELABORADOS!$A$2:$H$65536,8,0),"") | F22: =IFERROR(E22*C22,"") | G22: =IFERROR(F22/$F$66,"")
B23: =IFERROR(VLOOKUP(H23,[1]SEMIELABORADOS!$A$2:$M$6000,2,0),"") | C23: =+A23 -> 0 | D23: =IFERROR(VLOOKUP(H23,[1]SEMIELABORADOS!$A$2:$M$6000,6,0),"") | E23: =IFERROR(VLOOKUP(H23,[1]SEMIELABORADOS!$A$2:$H$65536,8,0),"") | F23: =IFERROR(E23*C23,"") | G23: =IFERROR(F23/$F$66,"")
B24: =IFERROR(VLOOKUP(H24,[1]SEMIELABORADOS!$A$2:$M$6000,2,0),"") | C24: =+A24 -> 0 | D24: =IFERROR(VLOOKUP(H24,[1]SEMIELABORADOS!$A$2:$M$6000,6,0),"") | E24: =IFERROR(VLOOKUP(H24,[1]SEMIELABORADOS!$A$2:$H$65536,8,0),"") | F24: =IFERROR(E24*C24,"") | G24: =IFERROR(F24/$F$66,"")
A26: UNIDADES | B26: EMPAQUE | C26: UNIDADES | D26: UND MEDIDA | E26: COSTO UNITARIO | F26: TOTAL COSTO | G26: % PREC. DEFINIDO | H26: CODIGOS
A27: 2 | B27: =IFERROR(VLOOKUP(H27,'[1]Consolidado MP Planta'!$A$2:$M$823,3,0),"") -> BOLSA 12x18 TRANSP KILO | C27: =+A27 -> 2 | D27: =IFERROR(VLOOKUP(H27,'[1]Consolidado MP Planta'!$A$2:$M$823,13,0),"") -> Und | E27: =IFERROR(VLOOKUP(H27,'[1]Consolidado MP Planta'!$A$2:$M$823,12,0),"") -> 11.2 | F27: =IFERROR(C27*E27,"") -> 22.4 | G27: =IFERROR(F27/$F$66,"") -> 0.00088925294 | H27: 1950702
A28: 1 | B28: =IFERROR(VLOOKUP(H28,'[1]Consolidado MP Planta'!$A$2:$M$823,3,0),"") -> BOLSA 17x25 TRANSP KILO | C28: =+A28 -> 1 | D28: =IFERROR(VLOOKUP(H28,'[1]Consolidado MP Planta'!$A$2:$M$823,13,0),"") -> Und | E28: =IFERROR(VLOOKUP(H28,'[1]Consolidado MP Planta'!$A$2:$M$823,12,0),"") -> 33.333333 | F28: =IFERROR(C28*E28,"") -> 33.333333 | G28: =IFERROR(F28/$F$66,"") -> 0.0013232931 | H28: 1950708
A29: 1 | B29: =IFERROR(VLOOKUP(H29,'[1]Consolidado MP Planta'!$A$2:$M$823,3,0),"") -> ETIQUETA BLANCA 2 5/8X1 15/16 (UND) | C29: =+A29 -> 1 | D29: =IFERROR(VLOOKUP(H29,'[1]Consolidado MP Planta'!$A$2:$M$823,13,0),"") -> Und | E29: =IFERROR(VLOOKUP(H29,'[1]Consolidado MP Planta'!$A$2:$M$823,12,0),"") -> 2.128 | F29: =IFERROR(C29*E29,"") -> 2.128 | G29: =IFERROR(F29/$F$66,"") -> 8.4479029e-05 | H29: 0702123
A30: 1 | B30: =IFERROR(VLOOKUP(H30,'[1]Consolidado MP Planta'!$A$2:$M$823,3,0),"") -> ETIQUETA ROJA LETRA ALERJENO (UND) | C30: =+A30 -> 1 | D30: =IFERROR(VLOOKUP(H30,'[1]Consolidado MP Planta'!$A$2:$M$823,13,0),"") -> Und | E30: =IFERROR(VLOOKUP(H30,'[1]Consolidado MP Planta'!$A$2:$M$823,12,0),"") -> 3.6 | F30: =IFERROR(C30*E30,"") -> 3.6 | G30: =IFERROR(F30/$F$66,"") -> 0.00014291565 | H30: 60100010
B31: =IFERROR(VLOOKUP(H31,'[1]Consolidado MP Planta'!$A$2:$M$823,3,0),"") | C31: =+A31 -> 0 | D31: =IFERROR(VLOOKUP(H31,'[1]Consolidado MP Planta'!$A$2:$M$823,13,0),"") | E31: =IFERROR(VLOOKUP(H31,'[1]Consolidado MP Planta'!$A$2:$M$823,12,0),"") | F31: =IFERROR(C31*E31,"") | G31: =IFERROR(F31/$F$66,"")
B32: =IFERROR(VLOOKUP(H32,'[1]Consolidado MP Planta'!$A$2:$M$823,3,0),"") | C32: =+A32 -> 0 | D32: =IFERROR(VLOOKUP(H32,'[1]Consolidado MP Planta'!$A$2:$M$823,13,0),"") | E32: =IFERROR(VLOOKUP(H32,'[1]Consolidado MP Planta'!$A$2:$M$823,12,0),"") | F32: =IFERROR(C32*E32,"") | G32: =IFERROR(F32/$F$66,"")
A34: UNIDADES | B34: EMPAQUE SEMIELABORADOS | C34: UNIDADES | D34: UND MEDIDA | E34: COSTO UNITARIO | F34: TOTAL COSTO | G34: % PREC. DEFINIDO | H34: CODIGOS
A35: =+A17 -> 1000 | B35: PROCESADO DE CHOCOLATE RALLADO OSCURO | C35: =+A35 -> 1000 | D35: Gramos | E35: 0.002 | F35: =IFERROR(E35*C35,"") -> 2 | G35: =IFERROR(F35/$F$66,"") -> 7.9397584e-05 | H35: 902000149
A36: =+A18 -> 0 | B36: =IFERROR(VLOOKUP(H36,[1]SEMIELABORADOS!$A$2:$M$6000,2,0),"") | C36: =+A36 -> 0 | D36: =IFERROR(VLOOKUP(H36,[1]SEMIELABORADOS!$A$2:$M$6000,6,0),"") | E36: =IFERROR(VLOOKUP(H36,[1]SEMIELABORADOS!$A$2:$M$65536,10,0),"") | F36: =IFERROR(E36*C36,"") | G36: =IFERROR(F36/$F$66,"")
A37: =+A19 -> 0 | B37: =IFERROR(VLOOKUP(H37,[1]SEMIELABORADOS!$A$2:$M$6000,2,0),"") | C37: =+A37 -> 0 | D37: =IFERROR(VLOOKUP(H37,[1]SEMIELABORADOS!$A$2:$M$6000,6,0),"") | E37: =IFERROR(VLOOKUP(H37,[1]SEMIELABORADOS!$A$2:$M$65536,10,0),"") | F37: =IFERROR(E37*C37,"") | G37: =IFERROR(F37/$F$66,"")
A38: =+A20 -> 0 | B38: =IFERROR(VLOOKUP(H38,[1]SEMIELABORADOS!$A$2:$M$6000,2,0),"") | C38: =+A38 -> 0 | D38: =IFERROR(VLOOKUP(H38,[1]SEMIELABORADOS!$A$2:$M$6000,6,0),"") | E38: =IFERROR(VLOOKUP(H38,[1]SEMIELABORADOS!$A$2:$M$65536,10,0),"") | F38: =IFERROR(E38*C38,"") | G38: =IFERROR(F38/$F$66,"")
A39: =+A21 -> 0 | B39: =IFERROR(VLOOKUP(H39,[1]SEMIELABORADOS!$A$2:$M$6000,2,0),"") | C39: =+A39 -> 0 | D39: =IFERROR(VLOOKUP(H39,[1]SEMIELABORADOS!$A$2:$M$6000,6,0),"") | E39: =IFERROR(VLOOKUP(H39,[1]SEMIELABORADOS!$A$2:$M$65536,10,0),"") | F39: =IFERROR(E39*C39,"") | G39: =IFERROR(F39/$F$66,"")
A40: =+A22 -> 0 | B40: =IFERROR(VLOOKUP(H40,[1]SEMIELABORADOS!$A$2:$M$6000,2,0),"") | C40: =+A40 -> 0 | D40: =IFERROR(VLOOKUP(H40,[1]SEMIELABORADOS!$A$2:$M$6000,6,0),"") | E40: =IFERROR(VLOOKUP(H40,[1]SEMIELABORADOS!$A$2:$M$65536,10,0),"") | F40: =IFERROR(E40*C40,"") | G40: =IFERROR(F40/$F$66,"")
A41: =+A23 -> 0 | B41: =IFERROR(VLOOKUP(H41,[1]SEMIELABORADOS!$A$2:$M$6000,2,0),"") | C41: =+A41 -> 0 | D41: =IFERROR(VLOOKUP(H41,[1]SEMIELABORADOS!$A$2:$M$6000,6,0),"") | E41: =IFERROR(VLOOKUP(H41,[1]SEMIELABORADOS!$A$2:$M$65536,10,0),"") | F41: =IFERROR(E41*C41,"") | G41: =IFERROR(F41/$F$66,"")
A43: UNIDADES | B43: MODI | C43: UNIDADES | D43: UND MEDIDA | E43: COSTO UNITARIO | F43: TOTAL COSTO | G43: % PREC. DEFINIDO | H43: CODIGOS
A44: =+A35 -> 1000 | B44: PROCESADO DE CHOCOLATE RALLADO OSCURO | C44: =+A44 -> 1000 | D44: Gramos | E44: 0.09 | F44: =IFERROR(E44*C44,"") -> 90 | G44: =IFERROR(F44/$F$66,"") -> 0.0035728913 | H44: 902000149
A45: =+A36 -> 0 | B45: =IFERROR(VLOOKUP(H45,[1]SEMIELABORADOS!$A$2:$M$6000,2,0),"") | C45: =+A45 -> 0 | D45: =IFERROR(VLOOKUP(H45,[1]SEMIELABORADOS!$A$2:$M$6000,6,0),"") | E45: =IFERROR(VLOOKUP(H45,[1]SEMIELABORADOS!$A$2:$M$65536,12,0),"") | F45: =IFERROR(E45*C45,"") | G45: =IFERROR(F45/$F$66,"")
...

Sheet Batido
B1: SERVICIOS DE PASTELERIA S.A. | G1: CÓDIGO:
B2: ESPECIFICACION DE RECETA | G2: REVISIÓN:
B3: 907000320 Batido Brownie Spoon | G3: FECHA DE APROBACIÓN:
B4: Elaborado | C4: Juan Pablo Brenes,chef
B5: Aprobado | C5: Esteban Cartin, Gerente de Manufactura
A7: AREA QUE PRODUCE: | C7: Batidos | F7: AREA QUE EMPACA: | H7: Batidos
A8: # Código | B8: Descripción del ingrediente | C8: Marca | D8: Unidad Internacional | F8: Medida alternativa | H8: Costo - Referencia
D9: Cantidad | E9: Unidad medida | F9: Cantidad | G9: Unidad medida | H9: Colones
A10: 904000144 | B10: PREMEZCLA BROWNIE SPOON | C10: FAS | D10: 13600 | E10: g
A11: 10415 | B11: AGUA POTABLE (PLANTA) | C11: FAS | D11: 1600 | E11: g
A12: 10100050 | B12: ACEITE CAPULLO RBD (UND:17 L) | C12: CAPULLO | D12: 1400 | E12: g
A13: 10100289 | B13: MARGARINA BAKER TABLETA (CAJA: 25 K) | C13: NUMAR | D13: 600 | E13: g
A14: 118000004 | B14: VAINILLA OSCURA (UND: 3.78 L) | C14: VAINOL | D14: 300 | E14: g
A15: 1210482 | B15: HUEVO ENTERO PASTERI INNOVO (CAJA:10 K) | C15: INNOVO | D15: 1200 | E15: g
A16: 11300011 | B16: YEMA DE HUEVO (UND: 8.34 K) | C16: INNOVO | D16: 400 | E16: g
A17: 11900001 | B17: NUEZ PECANA QUEBRADURA (CAJA:10 Kg) | C17: NUECES INDUSTRIALES | D17: 2000 | E17: G
C19: Cantidad | D19: Unidad
A20: PESO TOTAL OBTENIDO | C20: 20000 | D20: g
A21: TIEMPO TOTAL DE PREPARACION | C21: 0.5 | D21: min
A22: CANTIDAD DE PORCIONES OBTENIDAS | C22: 10 | D22: ud
A23: PESO DE CADA PORCIÓN | C23: 2000 | D23: g
A24: MERMA | C24: =SUM(D10:D17)-C20 -> 1100 | D24: g
A25: PROCEDIMIENTO DE PREPARACION DE LA RECETA
A26: 1.- En el agua hirviendo derretir los chocolates, vainilla, agregar el aceite y la margarina y colocar en la batidora
A27: 2.- Agregar el huevo y la yema y mezclar a velocidad 1 por 1 minuto.
A28: 3.- Luego agregar los ingredientes secos e incorporar a velocidad 2 por 1 minuto.
A29: 4.- Agregar el azucar y la pecana y mezclar a velocidad 1 por 1 minuto.
A30: 5.- Dosificar.

Sheet COSTO BATIDO
E1: Precio Local | F1: Costo MP | G1: Costo EM | H1: Costo MO
E2: =IFERROR(O62,"") -> 61093.891 | F2: =IFERROR(H53,"") -> 52301.1 | G2: =IFERROR(H54,"") -> 63.461333 | H2: =IFERROR(H56,"") -> 351
A5: ESTRUCTURA DE COSTOS
F6: Fecha: | H6: =TODAY() -> 46155
A7: UNIDADES | B7: DESCRIPCION MAT.PRIMA | C7: UNIDADES | D7: UND MEDIDA | E7: COSTO UNITARIO | F7: TOTAL COSTO | G7: % PREC. DEFINIDO | H7: CODIGOS
A8: 1600 | B8: =IFERROR(VLOOKUP(H8,'[1]Consolidado MP Planta'!$A$2:$M$823,3,0),"") -> AGUA PLANTA | C8: =+A8 -> 1600 | D8: =IFERROR(VLOOKUP(H8,'[1]Consolidado MP Planta'!$A$2:$M$823,13,0),"") -> Mililitros | E8: =IFERROR(VLOOKUP(H8,'[1]Consolidado MP Planta'!$A$2:$M$823,12,0),"") -> 0.1 | F8: =IFERROR(C8*E8,"") -> 160 | G8: =IFERROR(F8/$F$66,"") -> 0.0029940353 | H8: 10415
A9: 1400 | B9: =IFERROR(VLOOKUP(H9,'[1]Consolidado MP Planta'!$A$2:$M$823,3,0),"") -> ACEITE CAPULLO RBD (UND:17 L) | C9: =+A9 -> 1400 | D9: =IFERROR(VLOOKUP(H9,'[1]Consolidado MP Planta'!$A$2:$M$823,13,0),"") -> Mililitros | E9: 1.37 | F9: =IFERROR(C9*E9,"") -> 1918 | G9: =IFERROR(F9/$F$66,"") -> 0.035890998 | H9: 10100050
A10: 600 | B10: =IFERROR(VLOOKUP(H10,'[1]Consolidado MP Planta'!$A$2:$M$823,3,0),"") | C10: =+A10 -> 600 | D10: =IFERROR(VLOOKUP(H10,'[1]Consolidado MP Planta'!$A$2:$M$823,13,0),"") | E10: 1.4 | F10: =IFERROR(C10*E10,"") -> 840 | G10: =IFERROR(F10/$F$66,"") -> 0.015718685 | H10: 10100289
A11: 300 | B11: =IFERROR(VLOOKUP(H11,'[1]Consolidado MP Planta'!$A$2:$M$823,3,0),"") -> VAINILLA OSCURA (UND: 3.78 L) | C11: =+A11 -> 300 | D11: =IFERROR(VLOOKUP(H11,'[1]Consolidado MP Planta'!$A$2:$M$823,13,0),"") -> Mililitros | E11: 1.23 | F11: =IFERROR(C11*E11,"") -> 369 | G11: =IFERROR(F11/$F$66,"") -> 0.006904994 | H11: 118000004
A12: 1200 | B12: =IFERROR(VLOOKUP(H12,'[1]Consolidado MP Planta'!$A$2:$M$823,3,0),"") -> HUEVO ENTERO PASTERI INNOVO (CAJA:10 K) | C12: =+A12 -> 1200 | D12: =IFERROR(VLOOKUP(H12,'[1]Consolidado MP Planta'!$A$2:$M$823,13,0),"") -> Gramos | E12: 2.78 | F12: =IFERROR(C12*E12,"") -> 3336 | G12: =IFERROR(F12/$F$66,"") -> 0.062425636 | H12: 1210482
A13: 400 | B13: =IFERROR(VLOOKUP(H13,'[1]Consolidado MP Planta'!$A$2:$M$823,3,0),"") -> YEMA DE HUEVO (UND: 8.34 K) | C13: =+A13 -> 400 | D13: Gramos | E13: 2.73 | F13: =IFERROR(C13*E13,"") -> 1092 | G13: =IFERROR(F13/$F$66,"") -> 0.020434291 | H13: 11300011
A14: 2000 | B14: =IFERROR(VLOOKUP(H14,'[1]Consolidado MP Planta'!$A$2:$M$823,3,0),"") -> NUEZ PECANA QUEBRADURA (CAJA:10 Kg) | C14: =+A14 -> 2000 | D14: =IFERROR(VLOOKUP(H14,'[1]Consolidado MP Planta'!$A$2:$M$823,13,0),"") -> Gramos | E14: 10.09 | F14: =IFERROR(C14*E14,"") -> 20180 | G14: =IFERROR(F14/$F$66,"") -> 0.3776227 | H14: 11900001
B15: =IFERROR(VLOOKUP(H15,'[2]ARTICULOS MP PLANTA'!$A$2:$G$589,2,0),"")
A16: UNIDADES | B16: MATERIA PRIMA SEMIELABORADOS | C16: UNIDADES | D16: UND MEDIDA | E16: COSTO UNITARIO | F16: TOTAL COSTO | G16: % PREC. DEFINIDO | H16: CODIGOS
A17: 14200 | B17: PREMEZCLA BROWNIE SPOON | C17: =+A17 -> 14200 | D17: Gramos | E17: =+'COSTO PREMEZCLA '!E69 -> 1.7187394 | F17: =IFERROR(E17*C17,"") -> 24406.1 | G17: =IFERROR(F17/$F$66,"") -> 0.45670453 | H17: NUEVO
B18: =IFERROR(VLOOKUP(H18,[1]SEMIELABORADOS!$A$2:$M$6000,2,0),"") | C18: =+A18 -> 0 | D18: =IFERROR(VLOOKUP(H18,[1]SEMIELABORADOS!$A$2:$M$6000,6,0),"") | E18: =IFERROR(VLOOKUP(H18,[1]SEMIELABORADOS!$A$2:$H$65536,8,0),"") | F18: =IFERROR(E18*C18,"") | G18: =IFERROR(F18/$F$66,"")
B19: =IFERROR(VLOOKUP(H19,[1]SEMIELABORADOS!$A$2:$M$6000,2,0),"") | C19: =+A19 -> 0 | D19: =IFERROR(VLOOKUP(H19,[1]SEMIELABORADOS!$A$2:$M$6000,6,0),"") | E19: =IFERROR(VLOOKUP(H19,[1]SEMIELABORADOS!$A$2:$H$65536,8,0),"") | F19: =IFERROR(E19*C19,"") | G19: =IFERROR(F19/$F$66,"")
B20: =IFERROR(VLOOKUP(H20,[1]SEMIELABORADOS!$A$2:$M$6000,2,0),"") | C20: =+A20 -> 0 | D20: =IFERROR(VLOOKUP(H20,[1]SEMIELABORADOS!$A$2:$M$6000,6,0),"") | E20: =IFERROR(VLOOKUP(H20,[1]SEMIELABORADOS!$A$2:$H$65536,8,0),"") | F20: =IFERROR(E20*C20,"") | G20: =IFERROR(F20/$F$66,"")
B21: =IFERROR(VLOOKUP(H21,[1]SEMIELABORADOS!$A$2:$M$6000,2,0),"") | C21: =+A21 -> 0 | D21: =IFERROR(VLOOKUP(H21,[1]SEMIELABORADOS!$A$2:$M$6000,6,0),"") | E21: =IFERROR(VLOOKUP(H21,[1]SEMIELABORADOS!$A$2:$H$65536,8,0),"") | F21: =IFERROR(E21*C21,"") | G21: =IFERROR(F21/$F$66,"")
B22: =IFERROR(VLOOKUP(H22,[1]SEMIELABORADOS!$A$2:$M$6000,2,0),"") | C22: =+A22 -> 0 | D22: =IFERROR(VLOOKUP(H22,[1]SEMIELABORADOS!$A$2:$M$6000,6,0),"") | E22: =IFERROR(VLOOKUP(H22,[1]SEMIELABORADOS!$A$2:$H$65536,8,0),"") | F22: =IFERROR(E22*C22,"") | G22: =IFERROR(F22/$F$66,"")
B23: =IFERROR(VLOOKUP(H23,[1]SEMIELABORADOS!$A$2:$M$6000,2,0),"") | C23: =+A23 -> 0 | D23: =IFERROR(VLOOKUP(H23,[1]SEMIELABORADOS!$A$2:$M$6000,6,0),"") | E23: =IFERROR(VLOOKUP(H23,[1]SEMIELABORADOS!$A$2:$H$65536,8,0),"") | F23: =IFERROR(E23*C23,"") | G23: =IFERROR(F23/$F$66,"")
B24: =IFERROR(VLOOKUP(H24,[1]SEMIELABORADOS!$A$2:$M$6000,2,0),"") | C24: =+A24 -> 0 | D24: =IFERROR(VLOOKUP(H24,[1]SEMIELABORADOS!$A$2:$M$6000,6,0),"") | E24: =IFERROR(VLOOKUP(H24,[1]SEMIELABORADOS!$A$2:$H$65536,8,0),"") | F24: =IFERROR(E24*C24,"") | G24: =IFERROR(F24/$F$66,"")
A26: UNIDADES | B26: EMPAQUE | C26: UNIDADES | D26: UND MEDIDA | E26: COSTO UNITARIO | F26: TOTAL COSTO | G26: % PREC. DEFINIDO | H26: CODIGOS
A27: 0 | B27: =IFERROR(VLOOKUP(H27,'[1]Consolidado MP Planta'!$A$2:$M$823,3,0),"") | C27: =+A27 -> 0 | D27: =IFERROR(VLOOKUP(H27,'[1]Consolidado MP Planta'!$A$2:$M$823,13,0),"") | E27: =IFERROR(VLOOKUP(H27,'[1]Consolidado MP Planta'!$A$2:$M$823,12,0),"") | F27: =IFERROR(C27*E27,"") | G27: =IFERROR(F27/$F$66,"")
B28: =IFERROR(VLOOKUP(H28,'[1]Consolidado MP Planta'!$A$2:$M$823,3,0),"") | C28: =+A28 -> 0 | D28: =IFERROR(VLOOKUP(H28,'[1]Consolidado MP Planta'!$A$2:$M$823,13,0),"") | E28: =IFERROR(VLOOKUP(H28,'[1]Consolidado MP Planta'!$A$2:$M$823,12,0),"") | F28: =IFERROR(C28*E28,"") | G28: =IFERROR(F28/$F$66,"")
B29: =IFERROR(VLOOKUP(H29,'[1]Consolidado MP Planta'!$A$2:$M$823,3,0),"") | C29: =+A29 -> 0 | D29: =IFERROR(VLOOKUP(H29,'[1]Consolidado MP Planta'!$A$2:$M$823,13,0),"") | E29: =IFERROR(VLOOKUP(H29,'[1]Consolidado MP Planta'!$A$2:$M$823,12,0),"") | F29: =IFERROR(C29*E29,"") | G29: =IFERROR(F29/$F$66,"")
B30: =IFERROR(VLOOKUP(H30,'[1]Consolidado MP Planta'!$A$2:$M$823,3,0),"") | C30: =+A30 -> 0 | D30: =IFERROR(VLOOKUP(H30,'[1]Consolidado MP Planta'!$A$2:$M$823,13,0),"") | E30: =IFERROR(VLOOKUP(H30,'[1]Consolidado MP Planta'!$A$2:$M$823,12,0),"") | F30: =IFERROR(C30*E30,"") | G30: =IFERROR(F30/$F$66,"")
B31: =IFERROR(VLOOKUP(H31,'[1]Consolidado MP Planta'!$A$2:$M$823,3,0),"") | C31: =+A31 -> 0 | D31: =IFERROR(VLOOKUP(H31,'[1]Consolidado MP Planta'!$A$2:$M$823,13,0),"") | E31: =IFERROR(VLOOKUP(H31,'[1]Consolidado MP Planta'!$A$2:$M$823,12,0),"") | F31: =IFERROR(C31*E31,"") | G31: =IFERROR(F31/$F$66,"")
B32: =IFERROR(VLOOKUP(H32,'[1]Consolidado MP Planta'!$A$2:$M$823,3,0),"") | C32: =+A32 -> 0 | D32: =IFERROR(VLOOKUP(H32,'[1]Consolidado MP Planta'!$A$2:$M$823,13,0),"") | E32: =IFERROR(VLOOKUP(H32,'[1]Consolidado MP Planta'!$A$2:$M$823,12,0),"") | F32: =IFERROR(C32*E32,"") | G32: =IFERROR(F32/$F$66,"")
A34: UNIDADES | B34: EMPAQUE SEMIELABORADOS | C34: UNIDADES | D34: UND MEDIDA | E34: COSTO UNITARIO | F34: TOTAL COSTO | G34: % PREC. DEFINIDO | H34: CODIGOS
A35: =+A17 -> 14200 | B35: PREMEZCLA BROWNIE SPOON | C35: =+A35 -> 14200 | D35: Gramos | E35: =+'COSTO PREMEZCLA '!E76 -> 0.004469108 | F35: =IFERROR(E35*C35,"") -> 63.461333 | G35: =IFERROR(F35/$F$66,"") -> 0.0011875342 | H35: NUEVO
A36: =+A18 -> 0 | B36: =IFERROR(VLOOKUP(H36,[1]SEMIELABORADOS!$A$2:$M$6000,2,0),"") | C36: =+A36 -> 0 | D36: =IFERROR(VLOOKUP(H36,[1]SEMIELABORADOS!$A$2:$M$6000,6,0),"") | E36: =IFERROR(VLOOKUP(H36,[1]SEMIELABORADOS!$A$2:$M$65536,10,0),"") | F36: =IFERROR(E36*C36,"") | G36: =IFERROR(F36/$F$66,"")
A37: =+A19 -> 0 | B37: =IFERROR(VLOOKUP(H37,[1]SEMIELABORADOS!$A$2:$M$6000,2,0),"") | C37: =+A37 -> 0 | D37: =IFERROR(VLOOKUP(H37,[1]SEMIELABORADOS!$A$2:$M$6000,6,0),"") | E37: =IFERROR(VLOOKUP(H37,[1]SEMIELABORADOS!$A$2:$M$65536,10,0),"") | F37: =IFERROR(E37*C37,"") | G37: =IFERROR(F37/$F$66,"")
A38: =+A20 -> 0 | B38: =IFERROR(VLOOKUP(H38,[1]SEMIELABORADOS!$A$2:$M$6000,2,0),"") | C38: =+A38 -> 0 | D38: =IFERROR(VLOOKUP(H38,[1]SEMIELABORADOS!$A$2:$M$6000,6,0),"") | E38: =IFERROR(VLOOKUP(H38,[1]SEMIELABORADOS!$A$2:$M$65536,10,0),"") | F38: =IFERROR(E38*C38,"") | G38: =IFERROR(F38/$F$66,"")
A39: =+A21 -> 0 | B39: =IFERROR(VLOOKUP(H39,[1]SEMIELABORADOS!$A$2:$M$6000,2,0),"") | C39: =+A39 -> 0 | D39: =IFERROR(VLOOKUP(H39,[1]SEMIELABORADOS!$A$2:$M$6000,6,0),"") | E39: =IFERROR(VLOOKUP(H39,[1]SEMIELABORADOS!$A$2:$M$65536,10,0),"") | F39: =IFERROR(E39*C39,"") | G39: =IFERROR(F39/$F$66,"")
A40: =+A22 -> 0 | B40: =IFERROR(VLOOKUP(H40,[1]SEMIELABORADOS!$A$2:$M$6000,2,0),"") | C40: =+A40 -> 0 | D40: =IFERROR(VLOOKUP(H40,[1]SEMIELABORADOS!$A$2:$M$6000,6,0),"") | E40: =IFERROR(VLOOKUP(H40,[1]SEMIELABORADOS!$A$2:$M$65536,10,0),"") | F40: =IFERROR(E40*C40,"") | G40: =IFERROR(F40/$F$66,"")
A41: =+A23 -> 0 | B41: =IFERROR(VLOOKUP(H41,[1]SEMIELABORADOS!$A$2:$M$6000,2,0),"") | C41: =+A41 -> 0 | D41: =IFERROR(VLOOKUP(H41,[1]SEMIELABORADOS!$A$2:$M$6000,6,0),"") | E41: =IFERROR(VLOOKUP(H41,[1]SEMIELABORADOS!$A$2:$M$65536,10,0),"") | F41: =IFERROR(E41*C41,"") | G41: =IFERROR(F41/$F$66,"")
A43: UNIDADES | B43: MODI | C43: UNIDADES | D43: UND MEDIDA | E43: COSTO UNITARIO | F43: TOTAL COSTO | G43: % PREC. DEFINIDO | H43: CODIGOS
A44: =+A35 -> 14200 | B44: PREMEZCLA BROWNIE SPOON | C44: =+A44 -> 14200 | D44: Gramos | E44: =+'COSTO PREMEZCLA '!E74 -> 0.022676056 | F44: =IFERROR(E44*C44,"") -> 322 | G44: =IFERROR(F44/$F$66,"") -> 0.0060254961 | H44: NUEVO
A45: =+A36 -> 0 | B45: =IFERROR(VLOOKUP(H45,[1]SEMIELABORADOS!$A$2:$M$6000,2,0),"") | C45: =+A45 -> 0 | D45: =IFERROR(VLOOKUP(H45,[1]SEMIELABORADOS!$A$2:$M$6000,6,0),"") | E45: =IFERROR(VLOOKUP(H45,[1]SEMIELABORADOS!$A$2:$M$65536,12,0),"") | F45: =IFERROR(E45*C45,"") | G45: =IFERROR(F45/$F$66,"")
...

Sheet COSTO ROSQUETE
E1: Precio Local | F1: Costo MP | G1: Costo EM | H1: Costo MO
E2: =IFERROR(O62,"") -> 6034.8022 | F2: =IFERROR(H53,"") -> 5147.4767 | G2: =IFERROR(H54,"") -> 44.501294 | H2: =IFERROR(H56,"") -> 121.07767
A5: ESTRUCTURA DE COSTOS
F6: Fecha: | H6: =TODAY() -> 46155
A7: UNIDADES | B7: DESCRIPCION MAT.PRIMA | C7: UNIDADES | D7: UND MEDIDA | E7: COSTO UNITARIO | F7: TOTAL COSTO | G7: % PREC. DEFINIDO | H7: CODIGOS
A8: 400 | B8: =IFERROR(VLOOKUP(H8,'[1]Consolidado MP Planta'!$A$2:$M$823,3,0),"") | C8: =+A8 -> 400 | D8: =IFERROR(VLOOKUP(H8,'[1]Consolidado MP Planta'!$A$2:$M$823,13,0),"") | E8: 1.4 | F8: =IFERROR(C8*E8,"") -> 560 | G8: =IFERROR(F8/$F$66,"") -> 0.010405194 | H8: 10100289
A9: 100 | B9: =IFERROR(VLOOKUP(H9,'[1]Consolidado MP Planta'!$A$2:$M$823,3,0),"") -> ACEITE CAPULLO RBD (UND:17 L) | C9: =+A9 -> 100 | D9: =IFERROR(VLOOKUP(H9,'[1]Consolidado MP Planta'!$A$2:$M$823,13,0),"") -> Mililitros | E9: 1.37 | F9: =IFERROR(C9*E9,"") -> 137 | G9: =IFERROR(F9/$F$66,"") -> 0.0025455564 | H9: 10100050
B10: =IFERROR(VLOOKUP(H10,'[1]Consolidado MP Planta'!$A$2:$M$823,3,0),"") | C10: =+A10 -> 0 | D10: =IFERROR(VLOOKUP(H10,'[1]Consolidado MP Planta'!$A$2:$M$823,13,0),"") | E10: =IFERROR(VLOOKUP(H10,'[1]Consolidado MP Planta'!$A$2:$M$823,12,0),"") | F10: =IFERROR(C10*E10,"") | G10: =IFERROR(F10/$F$66,"")
B11: =IFERROR(VLOOKUP(H11,'[1]Consolidado MP Planta'!$A$2:$M$823,3,0),"") | C11: =+A11 -> 0 | D11: =IFERROR(VLOOKUP(H11,'[1]Consolidado MP Planta'!$A$2:$M$823,13,0),"") | E11: =IFERROR(VLOOKUP(H11,'[1]Consolidado MP Planta'!$A$2:$M$823,12,0),"") | F11: =IFERROR(C11*E11,"") | G11: =IFERROR(F11/$F$66,"")
B12: =IFERROR(VLOOKUP(H12,'[1]Consolidado MP Planta'!$A$2:$M$823,3,0),"") | C12: =+A12 -> 0 | D12: =IFERROR(VLOOKUP(H12,'[1]Consolidado MP Planta'!$A$2:$M$823,13,0),"") | E12: =IFERROR(VLOOKUP(H12,'[1]Consolidado MP Planta'!$A$2:$M$823,12,0),"") | F12: =IFERROR(C12*E12,"") | G12: =IFERROR(F12/$F$66,"")
B13: =IFERROR(VLOOKUP(H13,'[1]Consolidado MP Planta'!$A$2:$M$823,3,0),"") | C13: =+A13 -> 0 | D13: =IFERROR(VLOOKUP(H13,'[1]Consolidado MP Planta'!$A$2:$M$823,13,0),"") | E13: =IFERROR(VLOOKUP(H13,'[1]Consolidado MP Planta'!$A$2:$M$823,12,0),"") | F13: =IFERROR(C13*E13,"") | G13: =IFERROR(F13/$F$66,"")
B14: =IFERROR(VLOOKUP(H14,'[1]Consolidado MP Planta'!$A$2:$M$823,3,0),"") | C14: =+A14 -> 0 | D14: =IFERROR(VLOOKUP(H14,'[1]Consolidado MP Planta'!$A$2:$M$823,13,0),"") | E14: =IFERROR(VLOOKUP(H14,'[1]Consolidado MP Planta'!$A$2:$M$823,12,0),"") | F14: =IFERROR(C14*E14,"") | G14: =IFERROR(F14/$F$66,"")
B15: =IFERROR(VLOOKUP(H15,'[2]ARTICULOS MP PLANTA'!$A$2:$G$589,2,0),"")
A16: UNIDADES | B16: MATERIA PRIMA SEMIELABORADOS | C16: UNIDADES | D16: UND MEDIDA | E16: COSTO UNITARIO | F16: TOTAL COSTO | G16: % PREC. DEFINIDO | H16: CODIGOS
A17: 20000 | B17: BATIDO BROWNIE SPOON | C17: =+A17 -> 20000 | D17: Gramos | E17: =+'COSTO BATIDO'!E69 -> 2.5388883 | F17: =IFERROR(E17*C17,"") -> 50777.767 | G17: =IFERROR(F17/$F$66,"") -> 0.94348664 | H17: NUEVO
B18: =IFERROR(VLOOKUP(H18,[1]SEMIELABORADOS!$A$2:$M$6000,2,0),"") | C18: =+A18 -> 0 | D18: =IFERROR(VLOOKUP(H18,[1]SEMIELABORADOS!$A$2:$M$6000,6,0),"") | E18: =IFERROR(VLOOKUP(H18,[1]SEMIELABORADOS!$A$2:$H$65536,8,0),"") | F18: =IFERROR(E18*C18,"") | G18: =IFERROR(F18/$F$66,"")
B19: =IFERROR(VLOOKUP(H19,[1]SEMIELABORADOS!$A$2:$M$6000,2,0),"") | C19: =+A19 -> 0 | D19: =IFERROR(VLOOKUP(H19,[1]SEMIELABORADOS!$A$2:$M$6000,6,0),"") | E19: =IFERROR(VLOOKUP(H19,[1]SEMIELABORADOS!$A$2:$H$65536,8,0),"") | F19: =IFERROR(E19*C19,"") | G19: =IFERROR(F19/$F$66,"")
B20: =IFERROR(VLOOKUP(H20,[1]SEMIELABORADOS!$A$2:$M$6000,2,0),"") | C20: =+A20 -> 0 | D20: =IFERROR(VLOOKUP(H20,[1]SEMIELABORADOS!$A$2:$M$6000,6,0),"") | E20: =IFERROR(VLOOKUP(H20,[1]SEMIELABORADOS!$A$2:$H$65536,8,0),"") | F20: =IFERROR(E20*C20,"") | G20: =IFERROR(F20/$F$66,"")
B21: =IFERROR(VLOOKUP(H21,[1]SEMIELABORADOS!$A$2:$M$6000,2,0),"") | C21: =+A21 -> 0 | D21: =IFERROR(VLOOKUP(H21,[1]SEMIELABORADOS!$A$2:$M$6000,6,0),"") | E21: =IFERROR(VLOOKUP(H21,[1]SEMIELABORADOS!$A$2:$H$65536,8,0),"") | F21: =IFERROR(E21*C21,"") | G21: =IFERROR(F21/$F$66,"")
B22: =IFERROR(VLOOKUP(H22,[1]SEMIELABORADOS!$A$2:$M$6000,2,0),"") | C22: =+A22 -> 0 | D22: =IFERROR(VLOOKUP(H22,[1]SEMIELABORADOS!$A$2:$M$6000,6,0),"") | E22: =IFERROR(VLOOKUP(H22,[1]SEMIELABORADOS!$A$2:$H$65536,8,0),"") | F22: =IFERROR(E22*C22,"") | G22: =IFERROR(F22/$F$66,"")
B23: =IFERROR(VLOOKUP(H23,[1]SEMIELABORADOS!$A$2:$M$6000,2,0),"") | C23: =+A23 -> 0 | D23: =IFERROR(VLOOKUP(H23,[1]SEMIELABORADOS!$A$2:$M$6000,6,0),"") | E23: =IFERROR(VLOOKUP(H23,[1]SEMIELABORADOS!$A$2:$H$65536,8,0),"") | F23: =IFERROR(E23*C23,"") | G23: =IFERROR(F23/$F$66,"")
B24: =IFERROR(VLOOKUP(H24,[1]SEMIELABORADOS!$A$2:$M$6000,2,0),"") | C24: =+A24 -> 0 | D24: =IFERROR(VLOOKUP(H24,[1]SEMIELABORADOS!$A$2:$M$6000,6,0),"") | E24: =IFERROR(VLOOKUP(H24,[1]SEMIELABORADOS!$A$2:$H$65536,8,0),"") | F24: =IFERROR(E24*C24,"") | G24: =IFERROR(F24/$F$66,"")
A26: UNIDADES | B26: EMPAQUE | C26: UNIDADES | D26: UND MEDIDA | E26: COSTO UNITARIO | F26: TOTAL COSTO | G26: % PREC. DEFINIDO | H26: CODIGOS
A27: 5 | B27: =IFERROR(VLOOKUP(H27,'[1]Consolidado MP Planta'!$A$2:$M$823,3,0),"") -> BOLSA TRANSPARENTE 56X96X1.80 KILO | C27: =+A27 -> 5 | D27: =IFERROR(VLOOKUP(H27,'[1]Consolidado MP Planta'!$A$2:$M$823,13,0),"") -> Und | E27: =IFERROR(VLOOKUP(H27,'[1]Consolidado MP Planta'!$A$2:$M$823,12,0),"") -> 50 | F27: =IFERROR(C27*E27,"") -> 250 | G27: =IFERROR(F27/$F$66,"") -> 0.0046451759 | H27: 1950928
A28: 5 | B28: =IFERROR(VLOOKUP(H28,'[1]Consolidado MP Planta'!$A$2:$M$823,3,0),"") | C28: =+A28 -> 5 | D28: =IFERROR(VLOOKUP(H28,'[1]Consolidado MP Planta'!$A$2:$M$823,13,0),"") | E28: =IFERROR(VLOOKUP(H28,'[1]Consolidado MP Planta'!$A$2:$M$823,12,0),"") | F28: =IFERROR(C28*E28,"") | G28: =IFERROR(F28/$F$66,"") | H28: 0702007
A29: 3 | B29: =IFERROR(VLOOKUP(H29,'[1]Consolidado MP Planta'!$A$2:$M$823,3,0),"") -> PAPEL MANTEQUILLA (CAJA= 1000 UND) | C29: =+A29 -> 3 | D29: =IFERROR(VLOOKUP(H29,'[1]Consolidado MP Planta'!$A$2:$M$823,13,0),"") -> Und | E29: 43.5 | F29: =IFERROR(C29*E29,"") -> 130.5 | G29: =IFERROR(F29/$F$66,"") -> 0.0024247818 | H29: 0906036
A30: 5 | B30: =IFERROR(VLOOKUP(H30,'[1]Consolidado MP Planta'!$A$2:$M$823,3,0),"") -> ETIQ.BLANCA 1 1/4 * 3/4 (UND) | C30: =+A30 -> 5 | D30: =IFERROR(VLOOKUP(H30,'[1]Consolidado MP Planta'!$A$2:$M$823,13,0),"") -> Und | E30: =IFERROR(VLOOKUP(H30,'[1]Consolidado MP Planta'!$A$2:$M$823,12,0),"") -> 0.58 | F30: =IFERROR(C30*E30,"") -> 2.9 | G30: =IFERROR(F30/$F$66,"") -> 5.388404e-05 | H30: 0702069
B31: =IFERROR(VLOOKUP(H31,'[1]Consolidado MP Planta'!$A$2:$M$823,3,0),"") | C31: =+A31 -> 0 | D31: =IFERROR(VLOOKUP(H31,'[1]Consolidado MP Planta'!$A$2:$M$823,13,0),"") | E31: =IFERROR(VLOOKUP(H31,'[1]Consolidado MP Planta'!$A$2:$M$823,12,0),"") | F31: =IFERROR(C31*E31,"") | G31: =IFERROR(F31/$F$66,"")
B32: =IFERROR(VLOOKUP(H32,'[1]Consolidado MP Planta'!$A$2:$M$823,3,0),"") | C32: =+A32 -> 0 | D32: =IFERROR(VLOOKUP(H32,'[1]Consolidado MP Planta'!$A$2:$M$823,13,0),"") | E32: =IFERROR(VLOOKUP(H32,'[1]Consolidado MP Planta'!$A$2:$M$823,12,0),"") | F32: =IFERROR(C32*E32,"") | G32: =IFERROR(F32/$F$66,"")
A34: UNIDADES | B34: EMPAQUE SEMIELABORADOS | C34: UNIDADES | D34: UND MEDIDA | E34: COSTO UNITARIO | F34: TOTAL COSTO | G34: % PREC. DEFINIDO | H34: CODIGOS
A35: =+A17 -> 20000 | B35: BATIDO BROWNIE SPOON | C35: =+A35 -> 20000 | D35: Gramos | E35: =+'COSTO BATIDO'!E76 -> 0.0030806472 | F35: =IFERROR(E35*C35,"") -> 61.612945 | G35: =IFERROR(F35/$F$66,"") -> 0.0011448119 | H35: NUEVO
A36: =+A18 -> 0 | B36: =IFERROR(VLOOKUP(H36,[1]SEMIELABORADOS!$A$2:$M$6000,2,0),"") | C36: =+A36 -> 0 | D36: =IFERROR(VLOOKUP(H36,[1]SEMIELABORADOS!$A$2:$M$6000,6,0),"") | E36: =IFERROR(VLOOKUP(H36,[1]SEMIELABORADOS!$A$2:$M$65536,10,0),"") | F36: =IFERROR(E36*C36,"") | G36: =IFERROR(F36/$F$66,"")
A37: =+A19 -> 0 | B37: =IFERROR(VLOOKUP(H37,[1]SEMIELABORADOS!$A$2:$M$6000,2,0),"") | C37: =+A37 -> 0 | D37: =IFERROR(VLOOKUP(H37,[1]SEMIELABORADOS!$A$2:$M$6000,6,0),"") | E37: =IFERROR(VLOOKUP(H37,[1]SEMIELABORADOS!$A$2:$M$65536,10,0),"") | F37: =IFERROR(E37*C37,"") | G37: =IFERROR(F37/$F$66,"")
A38: =+A20 -> 0 | B38: =IFERROR(VLOOKUP(H38,[1]SEMIELABORADOS!$A$2:$M$6000,2,0),"") | C38: =+A38 -> 0 | D38: =IFERROR(VLOOKUP(H38,[1]SEMIELABORADOS!$A$2:$M$6000,6,0),"") | E38: =IFERROR(VLOOKUP(H38,[1]SEMIELABORADOS!$A$2:$M$65536,10,0),"") | F38: =IFERROR(E38*C38,"") | G38: =IFERROR(F38/$F$66,"")
A39: =+A21 -> 0 | B39: =IFERROR(VLOOKUP(H39,[1]SEMIELABORADOS!$A$2:$M$6000,2,0),"") | C39: =+A39 -> 0 | D39: =IFERROR(VLOOKUP(H39,[1]SEMIELABORADOS!$A$2:$M$6000,6,0),"") | E39: =IFERROR(VLOOKUP(H39,[1]SEMIELABORADOS!$A$2:$M$65536,10,0),"") | F39: =IFERROR(E39*C39,"") | G39: =IFERROR(F39/$F$66,"")
A40: =+A22 -> 0 | B40: =IFERROR(VLOOKUP(H40,[1]SEMIELABORADOS!$A$2:$M$6000,2,0),"") | C40: =+A40 -> 0 | D40: =IFERROR(VLOOKUP(H40,[1]SEMIELABORADOS!$A$2:$M$6000,6,0),"") | E40: =IFERROR(VLOOKUP(H40,[1]SEMIELABORADOS!$A$2:$M$65536,10,0),"") | F40: =IFERROR(E40*C40,"") | G40: =IFERROR(F40/$F$66,"")
A41: =+A23 -> 0 | B41: =IFERROR(VLOOKUP(H41,[1]SEMIELABORADOS!$A$2:$M$6000,2,0),"") | C41: =+A41 -> 0 | D41: =IFERROR(VLOOKUP(H41,[1]SEMIELABORADOS!$A$2:$M$6000,6,0),"") | E41: =IFERROR(VLOOKUP(H41,[1]SEMIELABORADOS!$A$2:$M$65536,10,0),"") | F41: =IFERROR(E41*C41,"") | G41: =IFERROR(F41/$F$66,"")
A43: UNIDADES | B43: MODI | C43: UNIDADES | D43: UND MEDIDA | E43: COSTO UNITARIO | F43: TOTAL COSTO | G43: % PREC. DEFINIDO | H43: CODIGOS
A44: =+A35 -> 20000 | B44: BATIDO BROWNIE SPOON | C44: =+A44 -> 20000 | D44: Gramos | E44: =+'COSTO BATIDO'!E74 -> 0.017038835 | F44: =IFERROR(E44*C44,"") -> 340.7767 | G44: =IFERROR(F44/$F$66,"") -> 0.0063318708 | H44: NUEVO
A45: =+A36 -> 0 | B45: =IFERROR(VLOOKUP(H45,[1]SEMIELABORADOS!$A$2:$M$6000,2,0),"") | C45: =+A45 -> 0 | D45: =IFERROR(VLOOKUP(H45,[1]SEMIELABORADOS!$A$2:$M$6000,6,0),"") | E45: =IFERROR(VLOOKUP(H45,[1]SEMIELABORADOS!$A$2:$M$65536,12,0),"") | F45: =IFERROR(E45*C45,"") | G45: =IFERROR(F45/$F$66,"")
...

Sheet Empaque
B1: SERVICIOS DE PASTELERIA S.A. | G1: CÓDIGO:
B2: ESPECIFICACION DE RECETA | G2: REVISIÓN:
B3: Ensamble de Brownie Rectangular Spoon | G3: FECHA DE APROBACIÓN:
B4: Elaborado | C4: Juan Pablo Brenes, Chef
B5: Aprobado | C5: Esteban Cartin, Gte Manufactura
A6: AREA QUE PRODUCE: | C6: Postres | F6: AREA QUE EMPACA: | H6: Postres
A7: # Código | B7: Descripción del ingrediente | C7: Marca | D7: Unidad Internacional | F7: Medida alternativa | H7: Costo - Referencia
D8: Cantidad | E8: Unidad medida | F8: Cantidad | G8: Unidad medida | H8: Colones
B9: ENSAMBLE
A10: NUEVO | B10: ROSQUETE BROWNIE SPOON 2000G | C10: Spoon | D10: 3 | E10: ud | G10: 60 ud 65g | H10: c/u
B12: EMPAQUE
A13: 1950837 | B13: FONDO CAJA BLANCA | C13: Gosaca | D13: 10 | E13: ud
A14: 1950409 | B14: TAPA FONDO CAJA BLANCA | C14: Gosaca | D14: 10 | E14: ud
A15: 702012 | B15: ETIQ.FECHA VENCIMIENTO | C15: Etiplast | D15: 10 | E15: ud
A16: 702069 | B16: ETIQ.BLANCA 1 1/4 * 3/4 | C16: Etiplast | D16: 10 | E16: ud
C19: Cantidad | D19: Unidad
A20: PESO TOTAL OBTENIDO | C20: 3900 | D20: g | E20: Tiempo de Horneo:
A21: TIEMPO TOTAL DE PREPARACION | C21: 20 | D21: min | E21: Horno:
A22: CANTIDAD DE PORCIONES OBTENIDAS | C22: =C20/C23 -> 10 | D22: cajas | E22: Temperatura de Horneo:
A23: PESO DE CADA PORCIÓN | C23: 390 | D23: g | E23: Otros
A24: MERMA | C24: 0 | D24: g
A25: PROCEDIMIENTO DE PREPARACION DE LA RECETA
A26: 1.- Cortar rectangulos de 5cm * 5cm. (de 1 plancha salen el 20 rectangulos). Utilizar un cuchillo con agua caliente para evitar que se pegue.
A27: 2.- Empacar en la caja blanca, 6 ud de brownies
A28: 3.- Tapar, Etiquetar con fecha de vencimiento y etiqueta con nombre
A29: Control de cambios

Sheet Hoja1
C1: SERVICIOS DE PASTELERIA S.A. | H1: CÓDIGO: | I1: ESP-RE-POS-024
C2: ESPECIFICACION DE RECETA | H2: REVISIÓN: | I2: 04
C3: 20500009(PTL00089) Ensamble de Brownie Rectangular Spoon | H3: FECHA DE APROBACIÓN: | I3: 45615
C4: Elaborado | D4: Javier Tong, Chef
C5: Aprobado | D5: Esteban Cartin, Gte Manufactura
A6: AREA QUE PRODUCE: | D6: Postres | G6: AREA QUE EMPACA: | I6: Postres
A7: # Código | B7: # Código Netsuite | C7: Descripción del ingrediente | D7: Marca | E7: Unidad Internacional | G7: Medida alternativa | I7: Costo - Referencia
E8: Cantidad | F8: Unidad medida | G8: Cantidad | H8: Unidad medida | I8: Colones
C9: Ensamble
A10: 903000025 | B10: SE00330 | C10: ROSQUETE BROWNIE CASERO 2000g | D10: FAS | E10: 1 | F10: ud | J10: =+E10/$D$38 -> 0.25
A11: 20100163 | B11: SE00337 | C11: EMPAQUE FUDGE DE CHOCOLATE | D11: FAS | E11: 600 | F11: g | H11: 25 GRAMOS | J11: =+E11/$D$38 -> 150
A12: 10700013 | B12: MP10011 | C12: STICK DORADO | E12: 8 | F12: ud | J12: =+E12/$D$38 -> 2
D15: 2
C16: Decoración
B19: SE00330 | C19: ROSQUETE BROWNIE CASERO 2000g | D19: FAS | E19: 0.02 | F19: ud | H19: MERMA
C22: Empaque
A23: 1950837 | B23: EM10080 | C23: FONDO CAJA BLANCA | D23: GOSACA | E23: 4 | F23: ud
A24: 1950409 | B24: EM10098 | C24: TAPA FONDO CAJA BLANCA | D24: GOSACA | E24: 4 | F24: ud
A25: 702012 | B25: EM10005 | C25: ETIQ.FECHA VENCIMIENTO VERDE | D25: ETIPLAST | E25: 4 | F25: ud
A26: 702069 | B26: EM10002 | C26: ETIQ.BLANCA 1 1/4 * 3/4 | D26: ETIPLAST | E26: 8 | F26: ud
D35: Cantidad | E35: Unidad
A36: PESO TOTAL OBTENIDO | D36: 2500 | E36: g | F36: Tiempo de Horneo:
A37: TIEMPO TOTAL DE PREPARACION | D37: 20 | E37: min | F37: Horno:
A38: CANTIDAD DE PORCIONES OBTENIDAS | D38: 4 | E38: cajas | F38: Temperatura de Horneo:
A39: PESO DE CADA PORCIÓN | D39: 625 | E39: g | F39: Otros
A40: MERMA | D40: 0 | E40: g
A41: PROCEDIMIENTO DE PREPARACION DE LA RECETA
A42: 1.- Cortar rectangulos de 5cm * 5cm. (de 1 plancha salen el 24 rectangulos). Utilizar un cuchillo con agua caliente para evitar que se pegue.
A43: 2.- Empacar en la caja blanca, 6 ud de brownies
A44: 3.- Tapar, Etiquetar con fecha de vencimiento y etiqueta con nombre
A47: CONTROL DE CAMBIOS
A48: 2,Se actualiza Cantidad de etiquetas 11/4*3/4, procedimeinto, cantidad de porciones y pesos finales
A49: Revision #3: Actualizcion del peso total obtenido.
A50: Revision #4: Se agrega cantidad por merma

Sheet Costo Empaque 
E1: Precio Local | F1: Costo MP | G1: Costo EM | H1: Costo MO
E2: =IFERROR(O62,"") -> 2540.5939 | F2: =IFERROR(H53,"") -> 1762.1292 | G2: =IFERROR(H54,"") -> 119.40532 | H2: =IFERROR(H56,"") -> 332.26942
A5: ESTRUCTURA DE COSTOS
F6: Fecha: | H6: =TODAY() -> 46155
A7: UNIDADES | B7: DESCRIPCION MAT.PRIMA | C7: UNIDADES | D7: UND MEDIDA | E7: COSTO UNITARIO | F7: TOTAL COSTO | G7: % PREC. DEFINIDO | H7: CODIGOS
A8: 8 | B8: =IFERROR(VLOOKUP(H8,'[1]Consolidado MP Planta'!$A$2:$M$823,3,0),"") -> STICK DORADO (CAJA:100 UND) | C8: =+A8 -> 8 | D8: =IFERROR(VLOOKUP(H8,'[1]Consolidado MP Planta'!$A$2:$M$823,13,0),"") -> Und | E8: 58.38 | F8: =IFERROR(C8*E8,"") -> 467.04 | G8: =IFERROR(F8/$F$66,"") -> 0.052909739 | H8: 10700013
B9: =IFERROR(VLOOKUP(H9,'[1]Consolidado MP Planta'!$A$2:$M$823,3,0),"") | C9: =+A9 -> 0 | D9: =IFERROR(VLOOKUP(H9,'[1]Consolidado MP Planta'!$A$2:$M$823,13,0),"") | E9: =IFERROR(VLOOKUP(H9,'[1]Consolidado MP Planta'!$A$2:$M$823,12,0),"") | F9: =IFERROR(C9*E9,"") | G9: =IFERROR(F9/$F$66,"")
B10: =IFERROR(VLOOKUP(H10,'[1]Consolidado MP Planta'!$A$2:$M$823,3,0),"") | C10: =+A10 -> 0 | D10: =IFERROR(VLOOKUP(H10,'[1]Consolidado MP Planta'!$A$2:$M$823,13,0),"") | E10: =IFERROR(VLOOKUP(H10,'[1]Consolidado MP Planta'!$A$2:$M$823,12,0),"") | F10: =IFERROR(C10*E10,"") | G10: =IFERROR(F10/$F$66,"")
B11: =IFERROR(VLOOKUP(H11,'[1]Consolidado MP Planta'!$A$2:$M$823,3,0),"") | C11: =+A11 -> 0 | D11: =IFERROR(VLOOKUP(H11,'[1]Consolidado MP Planta'!$A$2:$M$823,13,0),"") | E11: =IFERROR(VLOOKUP(H11,'[1]Consolidado MP Planta'!$A$2:$M$823,12,0),"") | F11: =IFERROR(C11*E11,"") | G11: =IFERROR(F11/$F$66,"")
B12: =IFERROR(VLOOKUP(H12,'[1]Consolidado MP Planta'!$A$2:$M$823,3,0),"") | C12: =+A12 -> 0 | D12: =IFERROR(VLOOKUP(H12,'[1]Consolidado MP Planta'!$A$2:$M$823,13,0),"") | E12: =IFERROR(VLOOKUP(H12,'[1]Consolidado MP Planta'!$A$2:$M$823,12,0),"") | F12: =IFERROR(C12*E12,"") | G12: =IFERROR(F12/$F$66,"")
B13: =IFERROR(VLOOKUP(H13,'[1]Consolidado MP Planta'!$A$2:$M$823,3,0),"") | C13: =+A13 -> 0 | D13: =IFERROR(VLOOKUP(H13,'[1]Consolidado MP Planta'!$A$2:$M$823,13,0),"") | E13: =IFERROR(VLOOKUP(H13,'[1]Consolidado MP Planta'!$A$2:$M$823,12,0),"") | F13: =IFERROR(C13*E13,"") | G13: =IFERROR(F13/$F$66,"")
B14: =IFERROR(VLOOKUP(H14,'[1]Consolidado MP Planta'!$A$2:$M$823,3,0),"") | C14: =+A14 -> 0 | D14: =IFERROR(VLOOKUP(H14,'[1]Consolidado MP Planta'!$A$2:$M$823,13,0),"") | E14: =IFERROR(VLOOKUP(H14,'[1]Consolidado MP Planta'!$A$2:$M$823,12,0),"") | F14: =IFERROR(C14*E14,"") | G14: =IFERROR(F14/$F$66,"")
B15: =IFERROR(VLOOKUP(H15,'[2]ARTICULOS MP PLANTA'!$A$2:$G$589,2,0),"")
A16: UNIDADES | B16: MATERIA PRIMA SEMIELABORADOS | C16: UNIDADES | D16: UND MEDIDA | E16: COSTO UNITARIO | F16: TOTAL COSTO | G16: % PREC. DEFINIDO | H16: CODIGOS
A17: 1 | B17: ROSQUETE BROWNIE SPOON 2000G | C17: =+A17 -> 1 | D17: UND | E17: =+'COSTO ROSQUETE'!H53 -> 5147.4767 | F17: =IFERROR(E17*C17,"") -> 5147.4767 | G17: =IFERROR(F17/$F$66,"") -> 0.58314416
A18: 600 | B18: RELLENO FUDGE (KILO) | C18: =+A18 -> 600 | D18: GRAMOS | E18: 2.39 | F18: =IFERROR(E18*C18,"") -> 1434 | G18: =IFERROR(F18/$F$66,"") -> 0.16245411
B19: =IFERROR(VLOOKUP(H19,[1]SEMIELABORADOS!$A$2:$M$6000,2,0),"") | C19: =+A19 -> 0 | D19: =IFERROR(VLOOKUP(H19,[1]SEMIELABORADOS!$A$2:$M$6000,6,0),"") | E19: =IFERROR(VLOOKUP(H19,[1]SEMIELABORADOS!$A$2:$H$65536,8,0),"") | F19: =IFERROR(E19*C19,"") | G19: =IFERROR(F19/$F$66,"")
B20: =IFERROR(VLOOKUP(H20,[1]SEMIELABORADOS!$A$2:$M$6000,2,0),"") | C20: =+A20 -> 0 | D20: =IFERROR(VLOOKUP(H20,[1]SEMIELABORADOS!$A$2:$M$6000,6,0),"") | E20: =IFERROR(VLOOKUP(H20,[1]SEMIELABORADOS!$A$2:$H$65536,8,0),"") | F20: =IFERROR(E20*C20,"") | G20: =IFERROR(F20/$F$66,"")
B21: =IFERROR(VLOOKUP(H21,[1]SEMIELABORADOS!$A$2:$M$6000,2,0),"") | C21: =+A21 -> 0 | D21: =IFERROR(VLOOKUP(H21,[1]SEMIELABORADOS!$A$2:$M$6000,6,0),"") | E21: =IFERROR(VLOOKUP(H21,[1]SEMIELABORADOS!$A$2:$H$65536,8,0),"") | F21: =IFERROR(E21*C21,"") | G21: =IFERROR(F21/$F$66,"")
B22: =IFERROR(VLOOKUP(H22,[1]SEMIELABORADOS!$A$2:$M$6000,2,0),"") | C22: =+A22 -> 0 | D22: =IFERROR(VLOOKUP(H22,[1]SEMIELABORADOS!$A$2:$M$6000,6,0),"") | E22: =IFERROR(VLOOKUP(H22,[1]SEMIELABORADOS!$A$2:$H$65536,8,0),"") | F22: =IFERROR(E22*C22,"") | G22: =IFERROR(F22/$F$66,"")
B23: =IFERROR(VLOOKUP(H23,[1]SEMIELABORADOS!$A$2:$M$6000,2,0),"") | C23: =+A23 -> 0 | D23: =IFERROR(VLOOKUP(H23,[1]SEMIELABORADOS!$A$2:$M$6000,6,0),"") | E23: =IFERROR(VLOOKUP(H23,[1]SEMIELABORADOS!$A$2:$H$65536,8,0),"") | F23: =IFERROR(E23*C23,"") | G23: =IFERROR(F23/$F$66,"")
B24: =IFERROR(VLOOKUP(H24,[1]SEMIELABORADOS!$A$2:$M$6000,2,0),"") | C24: =+A24 -> 0 | D24: =IFERROR(VLOOKUP(H24,[1]SEMIELABORADOS!$A$2:$M$6000,6,0),"") | E24: =IFERROR(VLOOKUP(H24,[1]SEMIELABORADOS!$A$2:$H$65536,8,0),"") | F24: =IFERROR(E24*C24,"") | G24: =IFERROR(F24/$F$66,"")
A26: UNIDADES | B26: EMPAQUE | C26: UNIDADES | D26: UND MEDIDA | E26: COSTO UNITARIO | F26: TOTAL COSTO | G26: % PREC. DEFINIDO | H26: CODIGOS
A27: 4 | B27: =IFERROR(VLOOKUP(H27,'[1]Consolidado MP Planta'!$A$2:$M$823,3,0),"") -> FONDO P/CAJA BLANCA (PAQ:100 UND) | C27: =+A27 -> 4 | D27: =IFERROR(VLOOKUP(H27,'[1]Consolidado MP Planta'!$A$2:$M$823,13,0),"") -> Und | E27: =IFERROR(VLOOKUP(H27,'[1]Consolidado MP Planta'!$A$2:$M$823,12,0),"") -> 53 | F27: =IFERROR(C27*E27,"") -> 212 | G27: =IFERROR(F27/$F$66,"") -> 0.024016925 | H27: 1950837
A28: 4 | B28: =IFERROR(VLOOKUP(H28,'[1]Consolidado MP Planta'!$A$2:$M$823,3,0),"") -> TAPA P/FONDO CAJA BLANCA (PAQ:100 UND) | C28: =+A28 -> 4 | D28: =IFERROR(VLOOKUP(H28,'[1]Consolidado MP Planta'!$A$2:$M$823,13,0),"") -> Und | E28: =IFERROR(VLOOKUP(H28,'[1]Consolidado MP Planta'!$A$2:$M$823,12,0),"") -> 53 | F28: =IFERROR(C28*E28,"") -> 212 | G28: =IFERROR(F28/$F$66,"") -> 0.024016925 | H28: 1950409
A29: 4 | B29: =IFERROR(VLOOKUP(H29,'[1]Consolidado MP Planta'!$A$2:$M$823,3,0),"") -> ETIQ.FECHA VENCIMIENTO VERDE (ROLLO) | C29: =+A29 -> 4 | D29: =IFERROR(VLOOKUP(H29,'[1]Consolidado MP Planta'!$A$2:$M$823,13,0),"") -> Und | E29: =IFERROR(VLOOKUP(H29,'[1]Consolidado MP Planta'!$A$2:$M$823,12,0),"") -> 0.2 | F29: =IFERROR(C29*E29,"") -> 0.8 | G29: =IFERROR(F29/$F$66,"") -> 9.0629906e-05 | H29: 0702012
A30: 4 | B30: =IFERROR(VLOOKUP(H30,'[1]Consolidado MP Planta'!$A$2:$M$823,3,0),"") -> ETIQ.BLANCA 1 1/4 * 3/4 (UND) | C30: =+A30 -> 4 | D30: =IFERROR(VLOOKUP(H30,'[1]Consolidado MP Planta'!$A$2:$M$823,13,0),"") -> Und | E30: =IFERROR(VLOOKUP(H30,'[1]Consolidado MP Planta'!$A$2:$M$823,12,0),"") -> 0.58 | F30: =IFERROR(C30*E30,"") -> 2.32 | G30: =IFERROR(F30/$F$66,"") -> 0.00026282673 | H30: 0702069
B31: =IFERROR(VLOOKUP(H31,'[1]Consolidado MP Planta'!$A$2:$M$823,3,0),"") | C31: =+A31 -> 0 | D31: =IFERROR(VLOOKUP(H31,'[1]Consolidado MP Planta'!$A$2:$M$823,13,0),"") | E31: =IFERROR(VLOOKUP(H31,'[1]Consolidado MP Planta'!$A$2:$M$823,12,0),"") | F31: =IFERROR(C31*E31,"") | G31: =IFERROR(F31/$F$66,"")
B32: =IFERROR(VLOOKUP(H32,'[1]Consolidado MP Planta'!$A$2:$M$823,3,0),"") | C32: =+A32 -> 0 | D32: =IFERROR(VLOOKUP(H32,'[1]Consolidado MP Planta'!$A$2:$M$823,13,0),"") | E32: =IFERROR(VLOOKUP(H32,'[1]Consolidado MP Planta'!$A$2:$M$823,12,0),"") | F32: =IFERROR(C32*E32,"") | G32: =IFERROR(F32/$F$66,"")
A34: UNIDADES | B34: EMPAQUE SEMIELABORADOS | C34: UNIDADES | D34: UND MEDIDA | E34: COSTO UNITARIO | F34: TOTAL COSTO | G34: % PREC. DEFINIDO | H34: CODIGOS
A35: =+A17 -> 1 | B35: ROSQUETE BROWNIE SPOON 2000G | C35: =+A35 -> 1 | D35: UND | E35: =+'COSTO ROSQUETE'!H54 -> 44.501294 | F35: =IFERROR(E35*C35,"") -> 44.501294 | G35: =IFERROR(F35/$F$66,"") -> 0.0050414352
A36: =+A18 -> 600 | B36: RELLENO FUDGE (KILO) | C36: =+A36 -> 600 | D36: GRAMOS | E36: 0.01 | F36: =IFERROR(E36*C36,"") -> 6 | G36: =IFERROR(F36/$F$66,"") -> 0.0006797243
A37: =+A19 -> 0 | B37: =IFERROR(VLOOKUP(H37,[1]SEMIELABORADOS!$A$2:$M$6000,2,0),"") | C37: =+A37 -> 0 | D37: =IFERROR(VLOOKUP(H37,[1]SEMIELABORADOS!$A$2:$M$6000,6,0),"") | E37: =IFERROR(VLOOKUP(H37,[1]SEMIELABORADOS!$A$2:$M$65536,10,0),"") | F37: =IFERROR(E37*C37,"") | G37: =IFERROR(F37/$F$66,"")
A38: =+A20 -> 0 | B38: =IFERROR(VLOOKUP(H38,[1]SEMIELABORADOS!$A$2:$M$6000,2,0),"") | C38: =+A38 -> 0 | D38: =IFERROR(VLOOKUP(H38,[1]SEMIELABORADOS!$A$2:$M$6000,6,0),"") | E38: =IFERROR(VLOOKUP(H38,[1]SEMIELABORADOS!$A$2:$M$65536,10,0),"") | F38: =IFERROR(E38*C38,"") | G38: =IFERROR(F38/$F$66,"")
A39: =+A21 -> 0 | B39: =IFERROR(VLOOKUP(H39,[1]SEMIELABORADOS!$A$2:$M$6000,2,0),"") | C39: =+A39 -> 0 | D39: =IFERROR(VLOOKUP(H39,[1]SEMIELABORADOS!$A$2:$M$6000,6,0),"") | E39: =IFERROR(VLOOKUP(H39,[1]SEMIELABORADOS!$A$2:$M$65536,10,0),"") | F39: =IFERROR(E39*C39,"") | G39: =IFERROR(F39/$F$66,"")
A40: =+A22 -> 0 | B40: =IFERROR(VLOOKUP(H40,[1]SEMIELABORADOS!$A$2:$M$6000,2,0),"") | C40: =+A40 -> 0 | D40: =IFERROR(VLOOKUP(H40,[1]SEMIELABORADOS!$A$2:$M$6000,6,0),"") | E40: =IFERROR(VLOOKUP(H40,[1]SEMIELABORADOS!$A$2:$M$65536,10,0),"") | F40: =IFERROR(E40*C40,"") | G40: =IFERROR(F40/$F$66,"")
A41: =+A23 -> 0 | B41: =IFERROR(VLOOKUP(H41,[1]SEMIELABORADOS!$A$2:$M$6000,2,0),"") | C41: =+A41 -> 0 | D41: =IFERROR(VLOOKUP(H41,[1]SEMIELABORADOS!$A$2:$M$6000,6,0),"") | E41: =IFERROR(VLOOKUP(H41,[1]SEMIELABORADOS!$A$2:$M$65536,10,0),"") | F41: =IFERROR(E41*C41,"") | G41: =IFERROR(F41/$F$66,"")
A43: UNIDADES | B43: MODI | C43: UNIDADES | D43: UND MEDIDA | E43: COSTO UNITARIO | F43: TOTAL COSTO | G43: % PREC. DEFINIDO | H43: CODIGOS
A44: =+A35 -> 1 | B44: ROSQUETE BROWNIE SPOON 2000G | C44: =+A44 -> 1 | D44: UND | E44: =+'COSTO ROSQUETE'!H56 -> 121.07767 | F44: =IFERROR(E44*C44,"") -> 121.07767 | G44: =IFERROR(F44/$F$66,"") -> 0.013716572
A45: =+A36 -> 600 | B45: RELLENO FUDGE (KILO) | C45: =+A45 -> 600 | D45: GRAMOS | E45: 0.08 | F45: =IFERROR(E45*C45,"") -> 48 | G45: =IFERROR(F45/$F$66,"") -> 0.0054377944
...
